/*
*** MADE BY MITHION'S .SCHEMATIC TO JAVA CONVERTING TOOL v1.6 ***
*/

package xolova.blued00r.divinerpg.generation.vethea.All;
import java.util.Random;

import xolova.blued00r.divinerpg.DivineRPG;

import net.minecraft.world.World;
import net.minecraft.world.gen.feature.WorldGenerator;

public class TreeFloating2 extends WorldGenerator
{
	protected int[] GetValidSpawnBlocks() {
		return new int[] {
		};
	}

	public TreeFloating2() { }

	public boolean generate(World world, Random rand, int i, int j, int k) {

		world.setBlock(i + 0, j + 1, k + 1, DivineRPGTwilight.mintwoodLeaves.blockID);
		world.setBlock(i + 0, j + 1, k + 2, DivineRPGTwilight.mintwoodLeaves.blockID);
		world.setBlock(i + 0, j + 1, k + 8, DivineRPGTwilight.dreamstone.blockID);
		world.setBlock(i + 0, j + 2, k + 2, DivineRPGTwilight.mintwoodLeaves.blockID);
		world.setBlock(i + 0, j + 2, k + 3, DivineRPGTwilight.mintwoodLeaves.blockID);
		world.setBlock(i + 0, j + 2, k + 8, DivineRPGTwilight.dreamstone.blockID);
		world.setBlock(i + 1, j + 0, k + 2, DivineRPGTwilight.mintwoodLeaves.blockID);
		world.setBlock(i + 1, j + 0, k + 8, DivineRPGTwilight.dreamstone.blockID);
		world.setBlock(i + 1, j + 1, k + 0, DivineRPGTwilight.mintwoodLeaves.blockID);
		world.setBlock(i + 1, j + 1, k + 1, DivineRPGTwilight.mintwoodLeaves.blockID);
		world.setBlockAndMetadata(i + 1, j + 1, k + 2, DivineRPGTwilight.mintwood.blockID, 8);
		world.setBlockAndMetadata(i + 1, j + 1, k + 3, DivineRPGTwilight.mintwood.blockID, 8);
		world.setBlockAndMetadata(i + 1, j + 1, k + 4, DivineRPGTwilight.mintwood.blockID, 8);
		world.setBlockAndMetadata(i + 1, j + 1, k + 5, DivineRPGTwilight.mintwood.blockID, 8);
		world.setBlockAndMetadata(i + 1, j + 1, k + 6, DivineRPGTwilight.mintwood.blockID, 8);
		world.setBlock(i + 1, j + 1, k + 7, DivineRPGTwilight.dreamstone.blockID);
		world.setBlock(i + 1, j + 1, k + 8, DivineRPGTwilight.dreamstone.blockID);
		world.setBlock(i + 1, j + 2, k + 1, DivineRPGTwilight.mintwoodLeaves.blockID);
		world.setBlockAndMetadata(i + 1, j + 2, k + 2, DivineRPGTwilight.mintwood.blockID, 8);
		world.setBlockAndMetadata(i + 1, j + 2, k + 3, DivineRPGTwilight.mintwood.blockID, 8);
		world.setBlockAndMetadata(i + 1, j + 2, k + 4, DivineRPGTwilight.mintwood.blockID, 8);
		world.setBlockAndMetadata(i + 1, j + 2, k + 5, DivineRPGTwilight.mintwood.blockID, 8);
		world.setBlockAndMetadata(i + 1, j + 2, k + 6, DivineRPGTwilight.mintwood.blockID, 8);
		world.setBlock(i + 1, j + 2, k + 7, DivineRPGTwilight.dreamstone.blockID);
		world.setBlock(i + 1, j + 2, k + 8, DivineRPGTwilight.dreamstone.blockID);
		world.setBlock(i + 1, j + 3, k + 2, DivineRPGTwilight.mintwoodLeaves.blockID);
		world.setBlock(i + 1, j + 3, k + 3, DivineRPGTwilight.mintwoodLeaves.blockID);
		world.setBlock(i + 1, j + 3, k + 8, DivineRPGTwilight.dreamstone.blockID);
		world.setBlock(i + 2, j + 0, k + 2, DivineRPGTwilight.mintwoodLeaves.blockID);
		world.setBlock(i + 2, j + 0, k + 8, DivineRPGTwilight.dreamstone.blockID);
		world.setBlock(i + 2, j + 1, k + 1, DivineRPGTwilight.mintwoodLeaves.blockID);
		world.setBlockAndMetadata(i + 2, j + 1, k + 2, DivineRPGTwilight.mintwood.blockID, 8);
		world.setBlockAndMetadata(i + 2, j + 1, k + 3, DivineRPGTwilight.mintwood.blockID, 8);
		world.setBlockAndMetadata(i + 2, j + 1, k + 4, DivineRPGTwilight.mintwood.blockID, 8);
		world.setBlockAndMetadata(i + 2, j + 1, k + 5, DivineRPGTwilight.mintwood.blockID, 8);
		world.setBlockAndMetadata(i + 2, j + 1, k + 6, DivineRPGTwilight.mintwood.blockID, 8);
		world.setBlock(i + 2, j + 1, k + 7, DivineRPGTwilight.dreamstone.blockID);
		world.setBlock(i + 2, j + 1, k + 8, DivineRPGTwilight.dreamstone.blockID);
		world.setBlock(i + 2, j + 2, k + 1, DivineRPGTwilight.mintwoodLeaves.blockID);
		world.setBlockAndMetadata(i + 2, j + 2, k + 2, DivineRPGTwilight.mintwood.blockID, 8);
		world.setBlockAndMetadata(i + 2, j + 2, k + 3, DivineRPGTwilight.mintwood.blockID, 8);
		world.setBlockAndMetadata(i + 2, j + 2, k + 4, DivineRPGTwilight.mintwood.blockID, 8);
		world.setBlockAndMetadata(i + 2, j + 2, k + 5, DivineRPGTwilight.mintwood.blockID, 8);
		world.setBlockAndMetadata(i + 2, j + 2, k + 6, DivineRPGTwilight.mintwood.blockID, 8);
		world.setBlock(i + 2, j + 2, k + 7, DivineRPGTwilight.dreamstone.blockID);
		world.setBlock(i + 2, j + 2, k + 8, DivineRPGTwilight.dreamstone.blockID);
		world.setBlock(i + 2, j + 3, k + 2, DivineRPGTwilight.mintwoodLeaves.blockID);
		world.setBlock(i + 2, j + 3, k + 8, DivineRPGTwilight.dreamstone.blockID);
		world.setBlock(i + 3, j + 0, k + 2, DivineRPGTwilight.mintwoodLeaves.blockID);
		world.setBlock(i + 3, j + 1, k + 2, DivineRPGTwilight.mintwoodLeaves.blockID);
		world.setBlock(i + 3, j + 1, k + 8, DivineRPGTwilight.dreamstone.blockID);
		world.setBlock(i + 3, j + 2, k + 2, DivineRPGTwilight.mintwoodLeaves.blockID);
		world.setBlock(i + 3, j + 2, k + 3, DivineRPGTwilight.mintwoodLeaves.blockID);
		world.setBlock(i + 3, j + 2, k + 8, DivineRPGTwilight.dreamstone.blockID);

		return true;
	}
}