/*
*** MADE BY MITHION'S .SCHEMATIC TO JAVA CONVERTING TOOL v1.6 ***
*/

package xolova.divinerpg.worldgen.vethea.layer2;
import java.util.Random;

import net.minecraft.entity.EntityLiving;
import net.minecraft.world.World;
import net.minecraft.world.gen.feature.WorldGenerator;
import xolova.divinerpg.entities.vethea.mobs.EntityTempleGuardian;
import xolova.divinerpg.utils.helpers.block.VetheaBlockHelper;

public class Pyramid2 extends WorldGenerator
{
	protected int[] GetValidSpawnBlocks() {
		return new int[] {
		};
	}

	public Pyramid2() { }

	public boolean generate(World world, Random rand, int i, int j, int k) {

		world.setBlock(i + 0, j + 0, k + 0, 0);
		world.setBlock(i + 0, j + 0, k + 1, 0);
		world.setBlock(i + 0, j + 0, k + 2, VetheaBlockHelper.hungerstone2.blockID);
		world.setBlock(i + 0, j + 0, k + 3, VetheaBlockHelper.hungerstone2.blockID);
		world.setBlock(i + 0, j + 0, k + 4, VetheaBlockHelper.hungerstone2.blockID);
		world.setBlock(i + 0, j + 0, k + 5, VetheaBlockHelper.hungerstone2.blockID);
		world.setBlock(i + 0, j + 0, k + 6, VetheaBlockHelper.hungerstone2.blockID);
		world.setBlock(i + 0, j + 0, k + 7, VetheaBlockHelper.hungerstone2.blockID);
		world.setBlock(i + 0, j + 0, k + 8, VetheaBlockHelper.hungerstone2.blockID);
		world.setBlock(i + 0, j + 0, k + 9, VetheaBlockHelper.hungerstone2.blockID);
		world.setBlock(i + 0, j + 0, k + 10, VetheaBlockHelper.hungerstone2.blockID);
		world.setBlock(i + 0, j + 0, k + 11, VetheaBlockHelper.hungerstone2.blockID);
		world.setBlock(i + 0, j + 0, k + 12, VetheaBlockHelper.hungerstone2.blockID);
		world.setBlock(i + 0, j + 0, k + 13, VetheaBlockHelper.hungerstone2.blockID);
		world.setBlock(i + 0, j + 0, k + 14, VetheaBlockHelper.hungerstone2.blockID);
		world.setBlock(i + 0, j + 0, k + 15, VetheaBlockHelper.hungerstone2.blockID);
		world.setBlock(i + 0, j + 0, k + 16, VetheaBlockHelper.hungerstone2.blockID);
		world.setBlock(i + 0, j + 0, k + 17, VetheaBlockHelper.hungerstone2.blockID);
		world.setBlock(i + 0, j + 0, k + 18, VetheaBlockHelper.hungerstone2.blockID);
		world.setBlock(i + 0, j + 0, k + 19, VetheaBlockHelper.hungerstone2.blockID);
		world.setBlock(i + 0, j + 0, k + 20, VetheaBlockHelper.hungerstone2.blockID);
		world.setBlock(i + 0, j + 0, k + 21, VetheaBlockHelper.hungerstone2.blockID);
		world.setBlock(i + 0, j + 0, k + 22, VetheaBlockHelper.hungerstone2.blockID);
		world.setBlock(i + 0, j + 0, k + 23, VetheaBlockHelper.hungerstone2.blockID);
		world.setBlock(i + 0, j + 0, k + 24, VetheaBlockHelper.hungerstone2.blockID);
		world.setBlock(i + 0, j + 0, k + 25, VetheaBlockHelper.hungerstone2.blockID);
		world.setBlock(i + 0, j + 0, k + 26, VetheaBlockHelper.hungerstone2.blockID);
		world.setBlock(i + 0, j + 0, k + 27, VetheaBlockHelper.hungerstone2.blockID);
		world.setBlock(i + 0, j + 0, k + 28, VetheaBlockHelper.hungerstone2.blockID);
		world.setBlock(i + 0, j + 0, k + 29, VetheaBlockHelper.hungerstone2.blockID);
		world.setBlock(i + 0, j + 0, k + 30, VetheaBlockHelper.hungerstone2.blockID);
		world.setBlock(i + 0, j + 0, k + 31, VetheaBlockHelper.hungerstone2.blockID);
		world.setBlock(i + 0, j + 0, k + 32, VetheaBlockHelper.hungerstone2.blockID);
		world.setBlock(i + 0, j + 0, k + 33, VetheaBlockHelper.hungerstone2.blockID);
		world.setBlock(i + 0, j + 0, k + 34, VetheaBlockHelper.hungerstone2.blockID);
		world.setBlock(i + 0, j + 0, k + 35, VetheaBlockHelper.hungerstone2.blockID);
		world.setBlock(i + 0, j + 0, k + 36, VetheaBlockHelper.hungerstone2.blockID);
		world.setBlock(i + 0, j + 0, k + 37, VetheaBlockHelper.hungerstone2.blockID);
		world.setBlock(i + 0, j + 0, k + 38, VetheaBlockHelper.hungerstone2.blockID);
		world.setBlock(i + 0, j + 0, k + 39, VetheaBlockHelper.hungerstone2.blockID);
		world.setBlock(i + 0, j + 0, k + 40, VetheaBlockHelper.hungerstone2.blockID);
		world.setBlock(i + 0, j + 1, k + 0, 0);
		world.setBlock(i + 0, j + 1, k + 1, 0);
		world.setBlock(i + 0, j + 1, k + 2, VetheaBlockHelper.hungerstone1.blockID);
		world.setBlock(i + 0, j + 1, k + 3, VetheaBlockHelper.hungerstone1.blockID);
		world.setBlock(i + 0, j + 1, k + 4, VetheaBlockHelper.hungerstone1.blockID);
		world.setBlock(i + 0, j + 1, k + 5, VetheaBlockHelper.hungerstone1.blockID);
		world.setBlock(i + 0, j + 1, k + 6, VetheaBlockHelper.hungerstone1.blockID);
		world.setBlock(i + 0, j + 1, k + 7, VetheaBlockHelper.hungerstone1.blockID);
		world.setBlock(i + 0, j + 1, k + 8, VetheaBlockHelper.hungerstone1.blockID);
		world.setBlock(i + 0, j + 1, k + 9, VetheaBlockHelper.hungerstone1.blockID);
		world.setBlock(i + 0, j + 1, k + 10, VetheaBlockHelper.hungerstone1.blockID);
		world.setBlock(i + 0, j + 1, k + 11, VetheaBlockHelper.hungerstone1.blockID);
		world.setBlock(i + 0, j + 1, k + 12, VetheaBlockHelper.hungerstone1.blockID);
		world.setBlock(i + 0, j + 1, k + 13, VetheaBlockHelper.hungerstone1.blockID);
		world.setBlock(i + 0, j + 1, k + 14, VetheaBlockHelper.hungerstone1.blockID);
		world.setBlock(i + 0, j + 1, k + 15, VetheaBlockHelper.hungerstone1.blockID);
		world.setBlock(i + 0, j + 1, k + 16, VetheaBlockHelper.hungerstone1.blockID);
		world.setBlock(i + 0, j + 1, k + 17, VetheaBlockHelper.hungerstone1.blockID);
		world.setBlock(i + 0, j + 1, k + 18, VetheaBlockHelper.hungerstone1.blockID);
		world.setBlock(i + 0, j + 1, k + 19, VetheaBlockHelper.hungerstone1.blockID);
		world.setBlock(i + 0, j + 1, k + 20, VetheaBlockHelper.hungerstone1.blockID);
		world.setBlock(i + 0, j + 1, k + 21, VetheaBlockHelper.hungerstone1.blockID);
		world.setBlock(i + 0, j + 1, k + 22, VetheaBlockHelper.hungerstone1.blockID);
		world.setBlock(i + 0, j + 1, k + 23, VetheaBlockHelper.hungerstone1.blockID);
		world.setBlock(i + 0, j + 1, k + 24, VetheaBlockHelper.hungerstone1.blockID);
		world.setBlock(i + 0, j + 1, k + 25, VetheaBlockHelper.hungerstone1.blockID);
		world.setBlock(i + 0, j + 1, k + 26, VetheaBlockHelper.hungerstone1.blockID);
		world.setBlock(i + 0, j + 1, k + 27, VetheaBlockHelper.hungerstone1.blockID);
		world.setBlock(i + 0, j + 1, k + 28, VetheaBlockHelper.hungerstone1.blockID);
		world.setBlock(i + 0, j + 1, k + 29, VetheaBlockHelper.hungerstone1.blockID);
		world.setBlock(i + 0, j + 1, k + 30, VetheaBlockHelper.hungerstone1.blockID);
		world.setBlock(i + 0, j + 1, k + 31, VetheaBlockHelper.hungerstone1.blockID);
		world.setBlock(i + 0, j + 1, k + 32, VetheaBlockHelper.hungerstone1.blockID);
		world.setBlock(i + 0, j + 1, k + 33, VetheaBlockHelper.hungerstone1.blockID);
		world.setBlock(i + 0, j + 1, k + 34, VetheaBlockHelper.hungerstone1.blockID);
		world.setBlock(i + 0, j + 1, k + 35, VetheaBlockHelper.hungerstone1.blockID);
		world.setBlock(i + 0, j + 1, k + 36, VetheaBlockHelper.hungerstone1.blockID);
		world.setBlock(i + 0, j + 1, k + 37, VetheaBlockHelper.hungerstone1.blockID);
		world.setBlock(i + 0, j + 1, k + 38, VetheaBlockHelper.hungerstone1.blockID);
		world.setBlock(i + 0, j + 1, k + 39, VetheaBlockHelper.hungerstone1.blockID);
		world.setBlock(i + 0, j + 1, k + 40, VetheaBlockHelper.hungerstone1.blockID);
		world.setBlock(i + 0, j + 2, k + 0, 0);
		world.setBlock(i + 0, j + 2, k + 1, 0);
		world.setBlock(i + 0, j + 2, k + 2, 0);
		world.setBlock(i + 0, j + 2, k + 3, 0);
		world.setBlock(i + 0, j + 2, k + 4, 0);
		world.setBlock(i + 0, j + 2, k + 5, 0);
		world.setBlock(i + 0, j + 2, k + 6, 0);
		world.setBlock(i + 0, j + 2, k + 7, 0);
		world.setBlock(i + 0, j + 2, k + 8, 0);
		world.setBlock(i + 0, j + 2, k + 9, 0);
		world.setBlock(i + 0, j + 2, k + 10, 0);
		world.setBlock(i + 0, j + 2, k + 11, 0);
		world.setBlock(i + 0, j + 2, k + 12, 0);
		world.setBlock(i + 0, j + 2, k + 13, 0);
		world.setBlock(i + 0, j + 2, k + 14, 0);
		world.setBlock(i + 0, j + 2, k + 15, 0);
		world.setBlock(i + 0, j + 2, k + 16, 0);
		world.setBlock(i + 0, j + 2, k + 17, 0);
		world.setBlock(i + 0, j + 2, k + 18, 0);
		world.setBlock(i + 0, j + 2, k + 19, 0);
		world.setBlock(i + 0, j + 2, k + 20, 0);
		world.setBlock(i + 0, j + 2, k + 21, 0);
		world.setBlock(i + 0, j + 2, k + 22, 0);
		world.setBlock(i + 0, j + 2, k + 23, 0);
		world.setBlock(i + 0, j + 2, k + 24, 0);
		world.setBlock(i + 0, j + 2, k + 25, 0);
		world.setBlock(i + 0, j + 2, k + 26, 0);
		world.setBlock(i + 0, j + 2, k + 27, 0);
		world.setBlock(i + 0, j + 2, k + 28, 0);
		world.setBlock(i + 0, j + 2, k + 29, 0);
		world.setBlock(i + 0, j + 2, k + 30, 0);
		world.setBlock(i + 0, j + 2, k + 31, 0);
		world.setBlock(i + 0, j + 2, k + 32, 0);
		world.setBlock(i + 0, j + 2, k + 33, 0);
		world.setBlock(i + 0, j + 2, k + 34, 0);
		world.setBlock(i + 0, j + 2, k + 35, 0);
		world.setBlock(i + 0, j + 2, k + 36, 0);
		world.setBlock(i + 0, j + 2, k + 37, 0);
		world.setBlock(i + 0, j + 2, k + 38, 0);
		world.setBlock(i + 0, j + 2, k + 39, 0);
		world.setBlock(i + 0, j + 2, k + 40, 0);
		world.setBlock(i + 0, j + 3, k + 0, 0);
		world.setBlock(i + 0, j + 3, k + 1, 0);
		world.setBlock(i + 0, j + 3, k + 2, 0);
		world.setBlock(i + 0, j + 3, k + 3, 0);
		world.setBlock(i + 0, j + 3, k + 4, 0);
		world.setBlock(i + 0, j + 3, k + 5, 0);
		world.setBlock(i + 0, j + 3, k + 6, 0);
		world.setBlock(i + 0, j + 3, k + 7, 0);
		world.setBlock(i + 0, j + 3, k + 8, 0);
		world.setBlock(i + 0, j + 3, k + 9, 0);
		world.setBlock(i + 0, j + 3, k + 10, 0);
		world.setBlock(i + 0, j + 3, k + 11, 0);
		world.setBlock(i + 0, j + 3, k + 12, 0);
		world.setBlock(i + 0, j + 3, k + 13, 0);
		world.setBlock(i + 0, j + 3, k + 14, 0);
		world.setBlock(i + 0, j + 3, k + 15, 0);
		world.setBlock(i + 0, j + 3, k + 16, 0);
		world.setBlock(i + 0, j + 3, k + 17, 0);
		world.setBlock(i + 0, j + 3, k + 18, 0);
		world.setBlock(i + 0, j + 3, k + 19, 0);
		world.setBlock(i + 0, j + 3, k + 20, 0);
		world.setBlock(i + 0, j + 3, k + 21, 0);
		world.setBlock(i + 0, j + 3, k + 22, 0);
		world.setBlock(i + 0, j + 3, k + 23, 0);
		world.setBlock(i + 0, j + 3, k + 24, 0);
		world.setBlock(i + 0, j + 3, k + 25, 0);
		world.setBlock(i + 0, j + 3, k + 26, 0);
		world.setBlock(i + 0, j + 3, k + 27, 0);
		world.setBlock(i + 0, j + 3, k + 28, 0);
		world.setBlock(i + 0, j + 3, k + 29, 0);
		world.setBlock(i + 0, j + 3, k + 30, 0);
		world.setBlock(i + 0, j + 3, k + 31, 0);
		world.setBlock(i + 0, j + 3, k + 32, 0);
		world.setBlock(i + 0, j + 3, k + 33, 0);
		world.setBlock(i + 0, j + 3, k + 34, 0);
		world.setBlock(i + 0, j + 3, k + 35, 0);
		world.setBlock(i + 0, j + 3, k + 36, 0);
		world.setBlock(i + 0, j + 3, k + 37, 0);
		world.setBlock(i + 0, j + 3, k + 38, 0);
		world.setBlock(i + 0, j + 3, k + 39, 0);
		world.setBlock(i + 0, j + 3, k + 40, 0);
		world.setBlock(i + 0, j + 4, k + 0, 0);
		world.setBlock(i + 0, j + 4, k + 1, 0);
		world.setBlock(i + 0, j + 4, k + 2, 0);
		world.setBlock(i + 0, j + 4, k + 3, 0);
		world.setBlock(i + 0, j + 4, k + 4, 0);
		world.setBlock(i + 0, j + 4, k + 5, 0);
		world.setBlock(i + 0, j + 4, k + 6, 0);
		world.setBlock(i + 0, j + 4, k + 7, 0);
		world.setBlock(i + 0, j + 4, k + 8, 0);
		world.setBlock(i + 0, j + 4, k + 9, 0);
		world.setBlock(i + 0, j + 4, k + 10, 0);
		world.setBlock(i + 0, j + 4, k + 11, 0);
		world.setBlock(i + 0, j + 4, k + 12, 0);
		world.setBlock(i + 0, j + 4, k + 13, 0);
		world.setBlock(i + 0, j + 4, k + 14, 0);
		world.setBlock(i + 0, j + 4, k + 15, 0);
		world.setBlock(i + 0, j + 4, k + 16, 0);
		world.setBlock(i + 0, j + 4, k + 17, 0);
		world.setBlock(i + 0, j + 4, k + 18, 0);
		world.setBlock(i + 0, j + 4, k + 19, 0);
		world.setBlock(i + 0, j + 4, k + 20, 0);
		world.setBlock(i + 0, j + 4, k + 21, 0);
		world.setBlock(i + 0, j + 4, k + 22, 0);
		world.setBlock(i + 0, j + 4, k + 23, 0);
		world.setBlock(i + 0, j + 4, k + 24, 0);
		world.setBlock(i + 0, j + 4, k + 25, 0);
		world.setBlock(i + 0, j + 4, k + 26, 0);
		world.setBlock(i + 0, j + 4, k + 27, 0);
		world.setBlock(i + 0, j + 4, k + 28, 0);
		world.setBlock(i + 0, j + 4, k + 29, 0);
		world.setBlock(i + 0, j + 4, k + 30, 0);
		world.setBlock(i + 0, j + 4, k + 31, 0);
		world.setBlock(i + 0, j + 4, k + 32, 0);
		world.setBlock(i + 0, j + 4, k + 33, 0);
		world.setBlock(i + 0, j + 4, k + 34, 0);
		world.setBlock(i + 0, j + 4, k + 35, 0);
		world.setBlock(i + 0, j + 4, k + 36, 0);
		world.setBlock(i + 0, j + 4, k + 37, 0);
		world.setBlock(i + 0, j + 4, k + 38, 0);
		world.setBlock(i + 0, j + 4, k + 39, 0);
		world.setBlock(i + 0, j + 4, k + 40, 0);
		world.setBlock(i + 0, j + 5, k + 0, 0);
		world.setBlock(i + 0, j + 5, k + 1, 0);
		world.setBlock(i + 0, j + 5, k + 2, 0);
		world.setBlock(i + 0, j + 5, k + 3, 0);
		world.setBlock(i + 0, j + 5, k + 4, 0);
		world.setBlock(i + 0, j + 5, k + 5, 0);
		world.setBlock(i + 0, j + 5, k + 6, 0);
		world.setBlock(i + 0, j + 5, k + 7, 0);
		world.setBlock(i + 0, j + 5, k + 8, 0);
		world.setBlock(i + 0, j + 5, k + 9, 0);
		world.setBlock(i + 0, j + 5, k + 10, 0);
		world.setBlock(i + 0, j + 5, k + 11, 0);
		world.setBlock(i + 0, j + 5, k + 12, 0);
		world.setBlock(i + 0, j + 5, k + 13, 0);
		world.setBlock(i + 0, j + 5, k + 14, 0);
		world.setBlock(i + 0, j + 5, k + 15, 0);
		world.setBlock(i + 0, j + 5, k + 16, 0);
		world.setBlock(i + 0, j + 5, k + 17, 0);
		world.setBlock(i + 0, j + 5, k + 18, 0);
		world.setBlock(i + 0, j + 5, k + 19, 0);
		world.setBlock(i + 0, j + 5, k + 20, 0);
		world.setBlock(i + 0, j + 5, k + 21, 0);
		world.setBlock(i + 0, j + 5, k + 22, 0);
		world.setBlock(i + 0, j + 5, k + 23, 0);
		world.setBlock(i + 0, j + 5, k + 24, 0);
		world.setBlock(i + 0, j + 5, k + 25, 0);
		world.setBlock(i + 0, j + 5, k + 26, 0);
		world.setBlock(i + 0, j + 5, k + 27, 0);
		world.setBlock(i + 0, j + 5, k + 28, 0);
		world.setBlock(i + 0, j + 5, k + 29, 0);
		world.setBlock(i + 0, j + 5, k + 30, 0);
		world.setBlock(i + 0, j + 5, k + 31, 0);
		world.setBlock(i + 0, j + 5, k + 32, 0);
		world.setBlock(i + 0, j + 5, k + 33, 0);
		world.setBlock(i + 0, j + 5, k + 34, 0);
		world.setBlock(i + 0, j + 5, k + 35, 0);
		world.setBlock(i + 0, j + 5, k + 36, 0);
		world.setBlock(i + 0, j + 5, k + 37, 0);
		world.setBlock(i + 0, j + 5, k + 38, 0);
		world.setBlock(i + 0, j + 5, k + 39, 0);
		world.setBlock(i + 0, j + 5, k + 40, 0);
		world.setBlock(i + 0, j + 6, k + 0, 0);
		world.setBlock(i + 0, j + 6, k + 1, 0);
		world.setBlock(i + 0, j + 6, k + 2, 0);
		world.setBlock(i + 0, j + 6, k + 3, 0);
		world.setBlock(i + 0, j + 6, k + 4, 0);
		world.setBlock(i + 0, j + 6, k + 5, 0);
		world.setBlock(i + 0, j + 6, k + 6, 0);
		world.setBlock(i + 0, j + 6, k + 7, 0);
		world.setBlock(i + 0, j + 6, k + 8, 0);
		world.setBlock(i + 0, j + 6, k + 9, 0);
		world.setBlock(i + 0, j + 6, k + 10, 0);
		world.setBlock(i + 0, j + 6, k + 11, 0);
		world.setBlock(i + 0, j + 6, k + 12, 0);
		world.setBlock(i + 0, j + 6, k + 13, 0);
		world.setBlock(i + 0, j + 6, k + 14, 0);
		world.setBlock(i + 0, j + 6, k + 15, 0);
		world.setBlock(i + 0, j + 6, k + 16, 0);
		world.setBlock(i + 0, j + 6, k + 17, 0);
		world.setBlock(i + 0, j + 6, k + 18, 0);
		world.setBlock(i + 0, j + 6, k + 19, 0);
		world.setBlock(i + 0, j + 6, k + 20, 0);
		world.setBlock(i + 0, j + 6, k + 21, 0);
		world.setBlock(i + 0, j + 6, k + 22, 0);
		world.setBlock(i + 0, j + 6, k + 23, 0);
		world.setBlock(i + 0, j + 6, k + 24, 0);
		world.setBlock(i + 0, j + 6, k + 25, 0);
		world.setBlock(i + 0, j + 6, k + 26, 0);
		world.setBlock(i + 0, j + 6, k + 27, 0);
		world.setBlock(i + 0, j + 6, k + 28, 0);
		world.setBlock(i + 0, j + 6, k + 29, 0);
		world.setBlock(i + 0, j + 6, k + 30, 0);
		world.setBlock(i + 0, j + 6, k + 31, 0);
		world.setBlock(i + 0, j + 6, k + 32, 0);
		world.setBlock(i + 0, j + 6, k + 33, 0);
		world.setBlock(i + 0, j + 6, k + 34, 0);
		world.setBlock(i + 0, j + 6, k + 35, 0);
		world.setBlock(i + 0, j + 6, k + 36, 0);
		world.setBlock(i + 0, j + 6, k + 37, 0);
		world.setBlock(i + 0, j + 6, k + 38, 0);
		world.setBlock(i + 0, j + 6, k + 39, 0);
		world.setBlock(i + 0, j + 6, k + 40, 0);
		world.setBlock(i + 0, j + 7, k + 0, 0);
		world.setBlock(i + 0, j + 7, k + 1, 0);
		world.setBlock(i + 0, j + 7, k + 2, 0);
		world.setBlock(i + 0, j + 7, k + 3, 0);
		world.setBlock(i + 0, j + 7, k + 4, 0);
		world.setBlock(i + 0, j + 7, k + 5, 0);
		world.setBlock(i + 0, j + 7, k + 6, 0);
		world.setBlock(i + 0, j + 7, k + 7, 0);
		world.setBlock(i + 0, j + 7, k + 8, 0);
		world.setBlock(i + 0, j + 7, k + 9, 0);
		world.setBlock(i + 0, j + 7, k + 10, 0);
		world.setBlock(i + 0, j + 7, k + 11, 0);
		world.setBlock(i + 0, j + 7, k + 12, 0);
		world.setBlock(i + 0, j + 7, k + 13, 0);
		world.setBlock(i + 0, j + 7, k + 14, 0);
		world.setBlock(i + 0, j + 7, k + 15, 0);
		world.setBlock(i + 0, j + 7, k + 16, 0);
		world.setBlock(i + 0, j + 7, k + 17, 0);
		world.setBlock(i + 0, j + 7, k + 18, 0);
		world.setBlock(i + 0, j + 7, k + 19, 0);
		world.setBlock(i + 0, j + 7, k + 20, 0);
		world.setBlock(i + 0, j + 7, k + 21, 0);
		world.setBlock(i + 0, j + 7, k + 22, 0);
		world.setBlock(i + 0, j + 7, k + 23, 0);
		world.setBlock(i + 0, j + 7, k + 24, 0);
		world.setBlock(i + 0, j + 7, k + 25, 0);
		world.setBlock(i + 0, j + 7, k + 26, 0);
		world.setBlock(i + 0, j + 7, k + 27, 0);
		world.setBlock(i + 0, j + 7, k + 28, 0);
		world.setBlock(i + 0, j + 7, k + 29, 0);
		world.setBlock(i + 0, j + 7, k + 30, 0);
		world.setBlock(i + 0, j + 7, k + 31, 0);
		world.setBlock(i + 0, j + 7, k + 32, 0);
		world.setBlock(i + 0, j + 7, k + 33, 0);
		world.setBlock(i + 0, j + 7, k + 34, 0);
		world.setBlock(i + 0, j + 7, k + 35, 0);
		world.setBlock(i + 0, j + 7, k + 36, 0);
		world.setBlock(i + 0, j + 7, k + 37, 0);
		world.setBlock(i + 0, j + 7, k + 38, 0);
		world.setBlock(i + 0, j + 7, k + 39, 0);
		world.setBlock(i + 0, j + 7, k + 40, 0);
		world.setBlock(i + 0, j + 8, k + 0, 0);
		world.setBlock(i + 0, j + 8, k + 1, 0);
		world.setBlock(i + 0, j + 8, k + 2, 0);
		world.setBlock(i + 0, j + 8, k + 3, 0);
		world.setBlock(i + 0, j + 8, k + 4, 0);
		world.setBlock(i + 0, j + 8, k + 5, 0);
		world.setBlock(i + 0, j + 8, k + 6, 0);
		world.setBlock(i + 0, j + 8, k + 7, 0);
		world.setBlock(i + 0, j + 8, k + 8, 0);
		world.setBlock(i + 0, j + 8, k + 9, 0);
		world.setBlock(i + 0, j + 8, k + 10, 0);
		world.setBlock(i + 0, j + 8, k + 11, 0);
		world.setBlock(i + 0, j + 8, k + 12, 0);
		world.setBlock(i + 0, j + 8, k + 13, 0);
		world.setBlock(i + 0, j + 8, k + 14, 0);
		world.setBlock(i + 0, j + 8, k + 15, 0);
		world.setBlock(i + 0, j + 8, k + 16, 0);
		world.setBlock(i + 0, j + 8, k + 17, 0);
		world.setBlock(i + 0, j + 8, k + 18, 0);
		world.setBlock(i + 0, j + 8, k + 19, 0);
		world.setBlock(i + 0, j + 8, k + 20, 0);
		world.setBlock(i + 0, j + 8, k + 21, 0);
		world.setBlock(i + 0, j + 8, k + 22, 0);
		world.setBlock(i + 0, j + 8, k + 23, 0);
		world.setBlock(i + 0, j + 8, k + 24, 0);
		world.setBlock(i + 0, j + 8, k + 25, 0);
		world.setBlock(i + 0, j + 8, k + 26, 0);
		world.setBlock(i + 0, j + 8, k + 27, 0);
		world.setBlock(i + 0, j + 8, k + 28, 0);
		world.setBlock(i + 0, j + 8, k + 29, 0);
		world.setBlock(i + 0, j + 8, k + 30, 0);
		world.setBlock(i + 0, j + 8, k + 31, 0);
		world.setBlock(i + 0, j + 8, k + 32, 0);
		world.setBlock(i + 0, j + 8, k + 33, 0);
		world.setBlock(i + 0, j + 8, k + 34, 0);
		world.setBlock(i + 0, j + 8, k + 35, 0);
		world.setBlock(i + 0, j + 8, k + 36, 0);
		world.setBlock(i + 0, j + 8, k + 37, 0);
		world.setBlock(i + 0, j + 8, k + 38, 0);
		world.setBlock(i + 0, j + 8, k + 39, 0);
		world.setBlock(i + 0, j + 8, k + 40, 0);
		world.setBlock(i + 0, j + 9, k + 0, 0);
		world.setBlock(i + 0, j + 9, k + 1, 0);
		world.setBlock(i + 0, j + 9, k + 2, 0);
		world.setBlock(i + 0, j + 9, k + 3, 0);
		world.setBlock(i + 0, j + 9, k + 4, 0);
		world.setBlock(i + 0, j + 9, k + 5, 0);
		world.setBlock(i + 0, j + 9, k + 6, 0);
		world.setBlock(i + 0, j + 9, k + 7, 0);
		world.setBlock(i + 0, j + 9, k + 8, 0);
		world.setBlock(i + 0, j + 9, k + 9, 0);
		world.setBlock(i + 0, j + 9, k + 10, 0);
		world.setBlock(i + 0, j + 9, k + 11, 0);
		world.setBlock(i + 0, j + 9, k + 12, 0);
		world.setBlock(i + 0, j + 9, k + 13, 0);
		world.setBlock(i + 0, j + 9, k + 14, 0);
		world.setBlock(i + 0, j + 9, k + 15, 0);
		world.setBlock(i + 0, j + 9, k + 16, 0);
		world.setBlock(i + 0, j + 9, k + 17, 0);
		world.setBlock(i + 0, j + 9, k + 18, 0);
		world.setBlock(i + 0, j + 9, k + 19, 0);
		world.setBlock(i + 0, j + 9, k + 20, 0);
		world.setBlock(i + 0, j + 9, k + 21, 0);
		world.setBlock(i + 0, j + 9, k + 22, 0);
		world.setBlock(i + 0, j + 9, k + 23, 0);
		world.setBlock(i + 0, j + 9, k + 24, 0);
		world.setBlock(i + 0, j + 9, k + 25, 0);
		world.setBlock(i + 0, j + 9, k + 26, 0);
		world.setBlock(i + 0, j + 9, k + 27, 0);
		world.setBlock(i + 0, j + 9, k + 28, 0);
		world.setBlock(i + 0, j + 9, k + 29, 0);
		world.setBlock(i + 0, j + 9, k + 30, 0);
		world.setBlock(i + 0, j + 9, k + 31, 0);
		world.setBlock(i + 0, j + 9, k + 32, 0);
		world.setBlock(i + 0, j + 9, k + 33, 0);
		world.setBlock(i + 0, j + 9, k + 34, 0);
		world.setBlock(i + 0, j + 9, k + 35, 0);
		world.setBlock(i + 0, j + 9, k + 36, 0);
		world.setBlock(i + 0, j + 9, k + 37, 0);
		world.setBlock(i + 0, j + 9, k + 38, 0);
		world.setBlock(i + 0, j + 9, k + 39, 0);
		world.setBlock(i + 0, j + 9, k + 40, 0);
		world.setBlock(i + 0, j + 10, k + 0, 0);
		world.setBlock(i + 0, j + 10, k + 1, 0);
		world.setBlock(i + 0, j + 10, k + 2, 0);
		world.setBlock(i + 0, j + 10, k + 3, 0);
		world.setBlock(i + 0, j + 10, k + 4, 0);
		world.setBlock(i + 0, j + 10, k + 5, 0);
		world.setBlock(i + 0, j + 10, k + 6, 0);
		world.setBlock(i + 0, j + 10, k + 7, 0);
		world.setBlock(i + 0, j + 10, k + 8, 0);
		world.setBlock(i + 0, j + 10, k + 9, 0);
		world.setBlock(i + 0, j + 10, k + 10, 0);
		world.setBlock(i + 0, j + 10, k + 11, 0);
		world.setBlock(i + 0, j + 10, k + 12, 0);
		world.setBlock(i + 0, j + 10, k + 13, 0);
		world.setBlock(i + 0, j + 10, k + 14, 0);
		world.setBlock(i + 0, j + 10, k + 15, 0);
		world.setBlock(i + 0, j + 10, k + 16, 0);
		world.setBlock(i + 0, j + 10, k + 17, 0);
		world.setBlock(i + 0, j + 10, k + 18, 0);
		world.setBlock(i + 0, j + 10, k + 19, 0);
		world.setBlock(i + 0, j + 10, k + 20, 0);
		world.setBlock(i + 0, j + 10, k + 21, 0);
		world.setBlock(i + 0, j + 10, k + 22, 0);
		world.setBlock(i + 0, j + 10, k + 23, 0);
		world.setBlock(i + 0, j + 10, k + 24, 0);
		world.setBlock(i + 0, j + 10, k + 25, 0);
		world.setBlock(i + 0, j + 10, k + 26, 0);
		world.setBlock(i + 0, j + 10, k + 27, 0);
		world.setBlock(i + 0, j + 10, k + 28, 0);
		world.setBlock(i + 0, j + 10, k + 29, 0);
		world.setBlock(i + 0, j + 10, k + 30, 0);
		world.setBlock(i + 0, j + 10, k + 31, 0);
		world.setBlock(i + 0, j + 10, k + 32, 0);
		world.setBlock(i + 0, j + 10, k + 33, 0);
		world.setBlock(i + 0, j + 10, k + 34, 0);
		world.setBlock(i + 0, j + 10, k + 35, 0);
		world.setBlock(i + 0, j + 10, k + 36, 0);
		world.setBlock(i + 0, j + 10, k + 37, 0);
		world.setBlock(i + 0, j + 10, k + 38, 0);
		world.setBlock(i + 0, j + 10, k + 39, 0);
		world.setBlock(i + 0, j + 10, k + 40, 0);
		world.setBlock(i + 0, j + 11, k + 0, 0);
		world.setBlock(i + 0, j + 11, k + 1, 0);
		world.setBlock(i + 0, j + 11, k + 2, 0);
		world.setBlock(i + 0, j + 11, k + 3, 0);
		world.setBlock(i + 0, j + 11, k + 4, 0);
		world.setBlock(i + 0, j + 11, k + 5, 0);
		world.setBlock(i + 0, j + 11, k + 6, 0);
		world.setBlock(i + 0, j + 11, k + 7, 0);
		world.setBlock(i + 0, j + 11, k + 8, 0);
		world.setBlock(i + 0, j + 11, k + 9, 0);
		world.setBlock(i + 0, j + 11, k + 10, 0);
		world.setBlock(i + 0, j + 11, k + 11, 0);
		world.setBlock(i + 0, j + 11, k + 12, 0);
		world.setBlock(i + 0, j + 11, k + 13, 0);
		world.setBlock(i + 0, j + 11, k + 14, 0);
		world.setBlock(i + 0, j + 11, k + 15, 0);
		world.setBlock(i + 0, j + 11, k + 16, 0);
		world.setBlock(i + 0, j + 11, k + 17, 0);
		world.setBlock(i + 0, j + 11, k + 18, 0);
		world.setBlock(i + 0, j + 11, k + 19, 0);
		world.setBlock(i + 0, j + 11, k + 20, 0);
		world.setBlock(i + 0, j + 11, k + 21, 0);
		world.setBlock(i + 0, j + 11, k + 22, 0);
		world.setBlock(i + 0, j + 11, k + 23, 0);
		world.setBlock(i + 0, j + 11, k + 24, 0);
		world.setBlock(i + 0, j + 11, k + 25, 0);
		world.setBlock(i + 0, j + 11, k + 26, 0);
		world.setBlock(i + 0, j + 11, k + 27, 0);
		world.setBlock(i + 0, j + 11, k + 28, 0);
		world.setBlock(i + 0, j + 11, k + 29, 0);
		world.setBlock(i + 0, j + 11, k + 30, 0);
		world.setBlock(i + 0, j + 11, k + 31, 0);
		world.setBlock(i + 0, j + 11, k + 32, 0);
		world.setBlock(i + 0, j + 11, k + 33, 0);
		world.setBlock(i + 0, j + 11, k + 34, 0);
		world.setBlock(i + 0, j + 11, k + 35, 0);
		world.setBlock(i + 0, j + 11, k + 36, 0);
		world.setBlock(i + 0, j + 11, k + 37, 0);
		world.setBlock(i + 0, j + 11, k + 38, 0);
		world.setBlock(i + 0, j + 11, k + 39, 0);
		world.setBlock(i + 0, j + 11, k + 40, 0);
		world.setBlock(i + 0, j + 12, k + 0, 0);
		world.setBlock(i + 0, j + 12, k + 1, 0);
		world.setBlock(i + 0, j + 12, k + 2, 0);
		world.setBlock(i + 0, j + 12, k + 3, 0);
		world.setBlock(i + 0, j + 12, k + 4, 0);
		world.setBlock(i + 0, j + 12, k + 5, 0);
		world.setBlock(i + 0, j + 12, k + 6, 0);
		world.setBlock(i + 0, j + 12, k + 7, 0);
		world.setBlock(i + 0, j + 12, k + 8, 0);
		world.setBlock(i + 0, j + 12, k + 9, 0);
		world.setBlock(i + 0, j + 12, k + 10, 0);
		world.setBlock(i + 0, j + 12, k + 11, 0);
		world.setBlock(i + 0, j + 12, k + 12, 0);
		world.setBlock(i + 0, j + 12, k + 13, 0);
		world.setBlock(i + 0, j + 12, k + 14, 0);
		world.setBlock(i + 0, j + 12, k + 15, 0);
		world.setBlock(i + 0, j + 12, k + 16, 0);
		world.setBlock(i + 0, j + 12, k + 17, 0);
		world.setBlock(i + 0, j + 12, k + 18, 0);
		world.setBlock(i + 0, j + 12, k + 19, 0);
		world.setBlock(i + 0, j + 12, k + 20, 0);
		world.setBlock(i + 0, j + 12, k + 21, 0);
		world.setBlock(i + 0, j + 12, k + 22, 0);
		world.setBlock(i + 0, j + 12, k + 23, 0);
		world.setBlock(i + 0, j + 12, k + 24, 0);
		world.setBlock(i + 0, j + 12, k + 25, 0);
		world.setBlock(i + 0, j + 12, k + 26, 0);
		world.setBlock(i + 0, j + 12, k + 27, 0);
		world.setBlock(i + 0, j + 12, k + 28, 0);
		world.setBlock(i + 0, j + 12, k + 29, 0);
		world.setBlock(i + 0, j + 12, k + 30, 0);
		world.setBlock(i + 0, j + 12, k + 31, 0);
		world.setBlock(i + 0, j + 12, k + 32, 0);
		world.setBlock(i + 0, j + 12, k + 33, 0);
		world.setBlock(i + 0, j + 12, k + 34, 0);
		world.setBlock(i + 0, j + 12, k + 35, 0);
		world.setBlock(i + 0, j + 12, k + 36, 0);
		world.setBlock(i + 0, j + 12, k + 37, 0);
		world.setBlock(i + 0, j + 12, k + 38, 0);
		world.setBlock(i + 0, j + 12, k + 39, 0);
		world.setBlock(i + 0, j + 12, k + 40, 0);
		world.setBlock(i + 0, j + 13, k + 0, 0);
		world.setBlock(i + 0, j + 13, k + 1, 0);
		world.setBlock(i + 0, j + 13, k + 2, 0);
		world.setBlock(i + 0, j + 13, k + 3, 0);
		world.setBlock(i + 0, j + 13, k + 4, 0);
		world.setBlock(i + 0, j + 13, k + 5, 0);
		world.setBlock(i + 0, j + 13, k + 6, 0);
		world.setBlock(i + 0, j + 13, k + 7, 0);
		world.setBlock(i + 0, j + 13, k + 8, 0);
		world.setBlock(i + 0, j + 13, k + 9, 0);
		world.setBlock(i + 0, j + 13, k + 10, 0);
		world.setBlock(i + 0, j + 13, k + 11, 0);
		world.setBlock(i + 0, j + 13, k + 12, 0);
		world.setBlock(i + 0, j + 13, k + 13, 0);
		world.setBlock(i + 0, j + 13, k + 14, 0);
		world.setBlock(i + 0, j + 13, k + 15, 0);
		world.setBlock(i + 0, j + 13, k + 16, 0);
		world.setBlock(i + 0, j + 13, k + 17, 0);
		world.setBlock(i + 0, j + 13, k + 18, 0);
		world.setBlock(i + 0, j + 13, k + 19, 0);
		world.setBlock(i + 0, j + 13, k + 20, 0);
		world.setBlock(i + 0, j + 13, k + 21, 0);
		world.setBlock(i + 0, j + 13, k + 22, 0);
		world.setBlock(i + 0, j + 13, k + 23, 0);
		world.setBlock(i + 0, j + 13, k + 24, 0);
		world.setBlock(i + 0, j + 13, k + 25, 0);
		world.setBlock(i + 0, j + 13, k + 26, 0);
		world.setBlock(i + 0, j + 13, k + 27, 0);
		world.setBlock(i + 0, j + 13, k + 28, 0);
		world.setBlock(i + 0, j + 13, k + 29, 0);
		world.setBlock(i + 0, j + 13, k + 30, 0);
		world.setBlock(i + 0, j + 13, k + 31, 0);
		world.setBlock(i + 0, j + 13, k + 32, 0);
		world.setBlock(i + 0, j + 13, k + 33, 0);
		world.setBlock(i + 0, j + 13, k + 34, 0);
		world.setBlock(i + 0, j + 13, k + 35, 0);
		world.setBlock(i + 0, j + 13, k + 36, 0);
		world.setBlock(i + 0, j + 13, k + 37, 0);
		world.setBlock(i + 0, j + 13, k + 38, 0);
		world.setBlock(i + 0, j + 13, k + 39, 0);
		world.setBlock(i + 0, j + 13, k + 40, 0);
		world.setBlock(i + 0, j + 14, k + 0, 0);
		world.setBlock(i + 0, j + 14, k + 1, 0);
		world.setBlock(i + 0, j + 14, k + 2, 0);
		world.setBlock(i + 0, j + 14, k + 3, 0);
		world.setBlock(i + 0, j + 14, k + 4, 0);
		world.setBlock(i + 0, j + 14, k + 5, 0);
		world.setBlock(i + 0, j + 14, k + 6, 0);
		world.setBlock(i + 0, j + 14, k + 7, 0);
		world.setBlock(i + 0, j + 14, k + 8, 0);
		world.setBlock(i + 0, j + 14, k + 9, 0);
		world.setBlock(i + 0, j + 14, k + 10, 0);
		world.setBlock(i + 0, j + 14, k + 11, 0);
		world.setBlock(i + 0, j + 14, k + 12, 0);
		world.setBlock(i + 0, j + 14, k + 13, 0);
		world.setBlock(i + 0, j + 14, k + 14, 0);
		world.setBlock(i + 0, j + 14, k + 15, 0);
		world.setBlock(i + 0, j + 14, k + 16, 0);
		world.setBlock(i + 0, j + 14, k + 17, 0);
		world.setBlock(i + 0, j + 14, k + 18, 0);
		world.setBlock(i + 0, j + 14, k + 19, 0);
		world.setBlock(i + 0, j + 14, k + 20, 0);
		world.setBlock(i + 0, j + 14, k + 21, 0);
		world.setBlock(i + 0, j + 14, k + 22, 0);
		world.setBlock(i + 0, j + 14, k + 23, 0);
		world.setBlock(i + 0, j + 14, k + 24, 0);
		world.setBlock(i + 0, j + 14, k + 25, 0);
		world.setBlock(i + 0, j + 14, k + 26, 0);
		world.setBlock(i + 0, j + 14, k + 27, 0);
		world.setBlock(i + 0, j + 14, k + 28, 0);
		world.setBlock(i + 0, j + 14, k + 29, 0);
		world.setBlock(i + 0, j + 14, k + 30, 0);
		world.setBlock(i + 0, j + 14, k + 31, 0);
		world.setBlock(i + 0, j + 14, k + 32, 0);
		world.setBlock(i + 0, j + 14, k + 33, 0);
		world.setBlock(i + 0, j + 14, k + 34, 0);
		world.setBlock(i + 0, j + 14, k + 35, 0);
		world.setBlock(i + 0, j + 14, k + 36, 0);
		world.setBlock(i + 0, j + 14, k + 37, 0);
		world.setBlock(i + 0, j + 14, k + 38, 0);
		world.setBlock(i + 0, j + 14, k + 39, 0);
		world.setBlock(i + 0, j + 14, k + 40, 0);
		world.setBlock(i + 0, j + 15, k + 0, 0);
		world.setBlock(i + 0, j + 15, k + 1, 0);
		world.setBlock(i + 0, j + 15, k + 2, 0);
		world.setBlock(i + 0, j + 15, k + 3, 0);
		world.setBlock(i + 0, j + 15, k + 4, 0);
		world.setBlock(i + 0, j + 15, k + 5, 0);
		world.setBlock(i + 0, j + 15, k + 6, 0);
		world.setBlock(i + 0, j + 15, k + 7, 0);
		world.setBlock(i + 0, j + 15, k + 8, 0);
		world.setBlock(i + 0, j + 15, k + 9, 0);
		world.setBlock(i + 0, j + 15, k + 10, 0);
		world.setBlock(i + 0, j + 15, k + 11, 0);
		world.setBlock(i + 0, j + 15, k + 12, 0);
		world.setBlock(i + 0, j + 15, k + 13, 0);
		world.setBlock(i + 0, j + 15, k + 14, 0);
		world.setBlock(i + 0, j + 15, k + 15, 0);
		world.setBlock(i + 0, j + 15, k + 16, 0);
		world.setBlock(i + 0, j + 15, k + 17, 0);
		world.setBlock(i + 0, j + 15, k + 18, 0);
		world.setBlock(i + 0, j + 15, k + 19, 0);
		world.setBlock(i + 0, j + 15, k + 20, 0);
		world.setBlock(i + 0, j + 15, k + 21, 0);
		world.setBlock(i + 0, j + 15, k + 22, 0);
		world.setBlock(i + 0, j + 15, k + 23, 0);
		world.setBlock(i + 0, j + 15, k + 24, 0);
		world.setBlock(i + 0, j + 15, k + 25, 0);
		world.setBlock(i + 0, j + 15, k + 26, 0);
		world.setBlock(i + 0, j + 15, k + 27, 0);
		world.setBlock(i + 0, j + 15, k + 28, 0);
		world.setBlock(i + 0, j + 15, k + 29, 0);
		world.setBlock(i + 0, j + 15, k + 30, 0);
		world.setBlock(i + 0, j + 15, k + 31, 0);
		world.setBlock(i + 0, j + 15, k + 32, 0);
		world.setBlock(i + 0, j + 15, k + 33, 0);
		world.setBlock(i + 0, j + 15, k + 34, 0);
		world.setBlock(i + 0, j + 15, k + 35, 0);
		world.setBlock(i + 0, j + 15, k + 36, 0);
		world.setBlock(i + 0, j + 15, k + 37, 0);
		world.setBlock(i + 0, j + 15, k + 38, 0);
		world.setBlock(i + 0, j + 15, k + 39, 0);
		world.setBlock(i + 0, j + 15, k + 40, 0);
		world.setBlock(i + 0, j + 16, k + 0, 0);
		world.setBlock(i + 0, j + 16, k + 1, 0);
		world.setBlock(i + 0, j + 16, k + 2, 0);
		world.setBlock(i + 0, j + 16, k + 3, 0);
		world.setBlock(i + 0, j + 16, k + 4, 0);
		world.setBlock(i + 0, j + 16, k + 5, 0);
		world.setBlock(i + 0, j + 16, k + 6, 0);
		world.setBlock(i + 0, j + 16, k + 7, 0);
		world.setBlock(i + 0, j + 16, k + 8, 0);
		world.setBlock(i + 0, j + 16, k + 9, 0);
		world.setBlock(i + 0, j + 16, k + 10, 0);
		world.setBlock(i + 0, j + 16, k + 11, 0);
		world.setBlock(i + 0, j + 16, k + 12, 0);
		world.setBlock(i + 0, j + 16, k + 13, 0);
		world.setBlock(i + 0, j + 16, k + 14, 0);
		world.setBlock(i + 0, j + 16, k + 15, 0);
		world.setBlock(i + 0, j + 16, k + 16, 0);
		world.setBlock(i + 0, j + 16, k + 17, 0);
		world.setBlock(i + 0, j + 16, k + 18, 0);
		world.setBlock(i + 0, j + 16, k + 19, 0);
		world.setBlock(i + 0, j + 16, k + 20, 0);
		world.setBlock(i + 0, j + 16, k + 21, 0);
		world.setBlock(i + 0, j + 16, k + 22, 0);
		world.setBlock(i + 0, j + 16, k + 23, 0);
		world.setBlock(i + 0, j + 16, k + 24, 0);
		world.setBlock(i + 0, j + 16, k + 25, 0);
		world.setBlock(i + 0, j + 16, k + 26, 0);
		world.setBlock(i + 0, j + 16, k + 27, 0);
		world.setBlock(i + 0, j + 16, k + 28, 0);
		world.setBlock(i + 0, j + 16, k + 29, 0);
		world.setBlock(i + 0, j + 16, k + 30, 0);
		world.setBlock(i + 0, j + 16, k + 31, 0);
		world.setBlock(i + 0, j + 16, k + 32, 0);
		world.setBlock(i + 0, j + 16, k + 33, 0);
		world.setBlock(i + 0, j + 16, k + 34, 0);
		world.setBlock(i + 0, j + 16, k + 35, 0);
		world.setBlock(i + 0, j + 16, k + 36, 0);
		world.setBlock(i + 0, j + 16, k + 37, 0);
		world.setBlock(i + 0, j + 16, k + 38, 0);
		world.setBlock(i + 0, j + 16, k + 39, 0);
		world.setBlock(i + 0, j + 16, k + 40, 0);
		world.setBlock(i + 0, j + 17, k + 0, 0);
		world.setBlock(i + 0, j + 17, k + 1, 0);
		world.setBlock(i + 0, j + 17, k + 2, 0);
		world.setBlock(i + 0, j + 17, k + 3, 0);
		world.setBlock(i + 0, j + 17, k + 4, 0);
		world.setBlock(i + 0, j + 17, k + 5, 0);
		world.setBlock(i + 0, j + 17, k + 6, 0);
		world.setBlock(i + 0, j + 17, k + 7, 0);
		world.setBlock(i + 0, j + 17, k + 8, 0);
		world.setBlock(i + 0, j + 17, k + 9, 0);
		world.setBlock(i + 0, j + 17, k + 10, 0);
		world.setBlock(i + 0, j + 17, k + 11, 0);
		world.setBlock(i + 0, j + 17, k + 12, 0);
		world.setBlock(i + 0, j + 17, k + 13, 0);
		world.setBlock(i + 0, j + 17, k + 14, 0);
		world.setBlock(i + 0, j + 17, k + 15, 0);
		world.setBlock(i + 0, j + 17, k + 16, 0);
		world.setBlock(i + 0, j + 17, k + 17, 0);
		world.setBlock(i + 0, j + 17, k + 18, 0);
		world.setBlock(i + 0, j + 17, k + 19, 0);
		world.setBlock(i + 0, j + 17, k + 20, 0);
		world.setBlock(i + 0, j + 17, k + 21, 0);
		world.setBlock(i + 0, j + 17, k + 22, 0);
		world.setBlock(i + 0, j + 17, k + 23, 0);
		world.setBlock(i + 0, j + 17, k + 24, 0);
		world.setBlock(i + 0, j + 17, k + 25, 0);
		world.setBlock(i + 0, j + 17, k + 26, 0);
		world.setBlock(i + 0, j + 17, k + 27, 0);
		world.setBlock(i + 0, j + 17, k + 28, 0);
		world.setBlock(i + 0, j + 17, k + 29, 0);
		world.setBlock(i + 0, j + 17, k + 30, 0);
		world.setBlock(i + 0, j + 17, k + 31, 0);
		world.setBlock(i + 0, j + 17, k + 32, 0);
		world.setBlock(i + 0, j + 17, k + 33, 0);
		world.setBlock(i + 0, j + 17, k + 34, 0);
		world.setBlock(i + 0, j + 17, k + 35, 0);
		world.setBlock(i + 0, j + 17, k + 36, 0);
		world.setBlock(i + 0, j + 17, k + 37, 0);
		world.setBlock(i + 0, j + 17, k + 38, 0);
		world.setBlock(i + 0, j + 17, k + 39, 0);
		world.setBlock(i + 0, j + 17, k + 40, 0);
		world.setBlock(i + 0, j + 18, k + 0, 0);
		world.setBlock(i + 0, j + 18, k + 1, 0);
		world.setBlock(i + 0, j + 18, k + 2, 0);
		world.setBlock(i + 0, j + 18, k + 3, 0);
		world.setBlock(i + 0, j + 18, k + 4, 0);
		world.setBlock(i + 0, j + 18, k + 5, 0);
		world.setBlock(i + 0, j + 18, k + 6, 0);
		world.setBlock(i + 0, j + 18, k + 7, 0);
		world.setBlock(i + 0, j + 18, k + 8, 0);
		world.setBlock(i + 0, j + 18, k + 9, 0);
		world.setBlock(i + 0, j + 18, k + 10, 0);
		world.setBlock(i + 0, j + 18, k + 11, 0);
		world.setBlock(i + 0, j + 18, k + 12, 0);
		world.setBlock(i + 0, j + 18, k + 13, 0);
		world.setBlock(i + 0, j + 18, k + 14, 0);
		world.setBlock(i + 0, j + 18, k + 15, 0);
		world.setBlock(i + 0, j + 18, k + 16, 0);
		world.setBlock(i + 0, j + 18, k + 17, 0);
		world.setBlock(i + 0, j + 18, k + 18, 0);
		world.setBlock(i + 0, j + 18, k + 19, 0);
		world.setBlock(i + 0, j + 18, k + 20, 0);
		world.setBlock(i + 0, j + 18, k + 21, 0);
		world.setBlock(i + 0, j + 18, k + 22, 0);
		world.setBlock(i + 0, j + 18, k + 23, 0);
		world.setBlock(i + 0, j + 18, k + 24, 0);
		world.setBlock(i + 0, j + 18, k + 25, 0);
		world.setBlock(i + 0, j + 18, k + 26, 0);
		world.setBlock(i + 0, j + 18, k + 27, 0);
		world.setBlock(i + 0, j + 18, k + 28, 0);
		world.setBlock(i + 0, j + 18, k + 29, 0);
		world.setBlock(i + 0, j + 18, k + 30, 0);
		world.setBlock(i + 0, j + 18, k + 31, 0);
		world.setBlock(i + 0, j + 18, k + 32, 0);
		world.setBlock(i + 0, j + 18, k + 33, 0);
		world.setBlock(i + 0, j + 18, k + 34, 0);
		world.setBlock(i + 0, j + 18, k + 35, 0);
		world.setBlock(i + 0, j + 18, k + 36, 0);
		world.setBlock(i + 0, j + 18, k + 37, 0);
		world.setBlock(i + 0, j + 18, k + 38, 0);
		world.setBlock(i + 0, j + 18, k + 39, 0);
		world.setBlock(i + 0, j + 18, k + 40, 0);
		world.setBlock(i + 0, j + 19, k + 0, 0);
		world.setBlock(i + 0, j + 19, k + 1, 0);
		world.setBlock(i + 0, j + 19, k + 2, 0);
		world.setBlock(i + 0, j + 19, k + 3, 0);
		world.setBlock(i + 0, j + 19, k + 4, 0);
		world.setBlock(i + 0, j + 19, k + 5, 0);
		world.setBlock(i + 0, j + 19, k + 6, 0);
		world.setBlock(i + 0, j + 19, k + 7, 0);
		world.setBlock(i + 0, j + 19, k + 8, 0);
		world.setBlock(i + 0, j + 19, k + 9, 0);
		world.setBlock(i + 0, j + 19, k + 10, 0);
		world.setBlock(i + 0, j + 19, k + 11, 0);
		world.setBlock(i + 0, j + 19, k + 12, 0);
		world.setBlock(i + 0, j + 19, k + 13, 0);
		world.setBlock(i + 0, j + 19, k + 14, 0);
		world.setBlock(i + 0, j + 19, k + 15, 0);
		world.setBlock(i + 0, j + 19, k + 16, 0);
		world.setBlock(i + 0, j + 19, k + 17, 0);
		world.setBlock(i + 0, j + 19, k + 18, 0);
		world.setBlock(i + 0, j + 19, k + 19, 0);
		world.setBlock(i + 0, j + 19, k + 20, 0);
		world.setBlock(i + 0, j + 19, k + 21, 0);
		world.setBlock(i + 0, j + 19, k + 22, 0);
		world.setBlock(i + 0, j + 19, k + 23, 0);
		world.setBlock(i + 0, j + 19, k + 24, 0);
		world.setBlock(i + 0, j + 19, k + 25, 0);
		world.setBlock(i + 0, j + 19, k + 26, 0);
		world.setBlock(i + 0, j + 19, k + 27, 0);
		world.setBlock(i + 0, j + 19, k + 28, 0);
		world.setBlock(i + 0, j + 19, k + 29, 0);
		world.setBlock(i + 0, j + 19, k + 30, 0);
		world.setBlock(i + 0, j + 19, k + 31, 0);
		world.setBlock(i + 0, j + 19, k + 32, 0);
		world.setBlock(i + 0, j + 19, k + 33, 0);
		world.setBlock(i + 0, j + 19, k + 34, 0);
		world.setBlock(i + 0, j + 19, k + 35, 0);
		world.setBlock(i + 0, j + 19, k + 36, 0);
		world.setBlock(i + 0, j + 19, k + 37, 0);
		world.setBlock(i + 0, j + 19, k + 38, 0);
		world.setBlock(i + 0, j + 19, k + 39, 0);
		world.setBlock(i + 0, j + 19, k + 40, 0);
		world.setBlock(i + 0, j + 20, k + 0, 0);
		world.setBlock(i + 0, j + 20, k + 1, 0);
		world.setBlock(i + 0, j + 20, k + 2, 0);
		world.setBlock(i + 0, j + 20, k + 3, 0);
		world.setBlock(i + 0, j + 20, k + 4, 0);
		world.setBlock(i + 0, j + 20, k + 5, 0);
		world.setBlock(i + 0, j + 20, k + 6, 0);
		world.setBlock(i + 0, j + 20, k + 7, 0);
		world.setBlock(i + 0, j + 20, k + 8, 0);
		world.setBlock(i + 0, j + 20, k + 9, 0);
		world.setBlock(i + 0, j + 20, k + 10, 0);
		world.setBlock(i + 0, j + 20, k + 11, 0);
		world.setBlock(i + 0, j + 20, k + 12, 0);
		world.setBlock(i + 0, j + 20, k + 13, 0);
		world.setBlock(i + 0, j + 20, k + 14, 0);
		world.setBlock(i + 0, j + 20, k + 15, 0);
		world.setBlock(i + 0, j + 20, k + 16, 0);
		world.setBlock(i + 0, j + 20, k + 17, 0);
		world.setBlock(i + 0, j + 20, k + 18, 0);
		world.setBlock(i + 0, j + 20, k + 19, 0);
		world.setBlock(i + 0, j + 20, k + 20, 0);
		world.setBlock(i + 0, j + 20, k + 21, 0);
		world.setBlock(i + 0, j + 20, k + 22, 0);
		world.setBlock(i + 0, j + 20, k + 23, 0);
		world.setBlock(i + 0, j + 20, k + 24, 0);
		world.setBlock(i + 0, j + 20, k + 25, 0);
		world.setBlock(i + 0, j + 20, k + 26, 0);
		world.setBlock(i + 0, j + 20, k + 27, 0);
		world.setBlock(i + 0, j + 20, k + 28, 0);
		world.setBlock(i + 0, j + 20, k + 29, 0);
		world.setBlock(i + 0, j + 20, k + 30, 0);
		world.setBlock(i + 0, j + 20, k + 31, 0);
		world.setBlock(i + 0, j + 20, k + 32, 0);
		world.setBlock(i + 0, j + 20, k + 33, 0);
		world.setBlock(i + 0, j + 20, k + 34, 0);
		world.setBlock(i + 0, j + 20, k + 35, 0);
		world.setBlock(i + 0, j + 20, k + 36, 0);
		world.setBlock(i + 0, j + 20, k + 37, 0);
		world.setBlock(i + 0, j + 20, k + 38, 0);
		world.setBlock(i + 0, j + 20, k + 39, 0);
		world.setBlock(i + 0, j + 20, k + 40, 0);
		world.setBlock(i + 1, j + 0, k + 0, 0);
		world.setBlock(i + 1, j + 0, k + 1, 0);
		world.setBlock(i + 1, j + 0, k + 2, VetheaBlockHelper.hungerstone2.blockID);
		world.setBlock(i + 1, j + 0, k + 3, VetheaBlockHelper.hungerstone2.blockID);
		world.setBlock(i + 1, j + 0, k + 4, VetheaBlockHelper.hungerstone2.blockID);
		world.setBlock(i + 1, j + 0, k + 5, VetheaBlockHelper.hungerstone2.blockID);
		world.setBlock(i + 1, j + 0, k + 6, VetheaBlockHelper.hungerstone2.blockID);
		world.setBlock(i + 1, j + 0, k + 7, VetheaBlockHelper.hungerstone2.blockID);
		world.setBlock(i + 1, j + 0, k + 8, VetheaBlockHelper.hungerstone2.blockID);
		world.setBlock(i + 1, j + 0, k + 9, VetheaBlockHelper.hungerstone2.blockID);
		world.setBlock(i + 1, j + 0, k + 10, VetheaBlockHelper.hungerstone2.blockID);
		world.setBlock(i + 1, j + 0, k + 11, VetheaBlockHelper.hungerstone2.blockID);
		world.setBlock(i + 1, j + 0, k + 12, VetheaBlockHelper.hungerstone2.blockID);
		world.setBlock(i + 1, j + 0, k + 13, VetheaBlockHelper.hungerstone2.blockID);
		world.setBlock(i + 1, j + 0, k + 14, VetheaBlockHelper.hungerstone2.blockID);
		world.setBlock(i + 1, j + 0, k + 15, VetheaBlockHelper.hungerstone2.blockID);
		world.setBlock(i + 1, j + 0, k + 16, VetheaBlockHelper.hungerstone2.blockID);
		world.setBlock(i + 1, j + 0, k + 17, VetheaBlockHelper.hungerstone2.blockID);
		world.setBlock(i + 1, j + 0, k + 18, VetheaBlockHelper.hungerstone2.blockID);
		world.setBlock(i + 1, j + 0, k + 19, VetheaBlockHelper.hungerstone2.blockID);
		world.setBlock(i + 1, j + 0, k + 20, VetheaBlockHelper.hungerstone2.blockID);
		world.setBlock(i + 1, j + 0, k + 21, VetheaBlockHelper.hungerstone2.blockID);
		world.setBlock(i + 1, j + 0, k + 22, VetheaBlockHelper.hungerstone2.blockID);
		world.setBlock(i + 1, j + 0, k + 23, VetheaBlockHelper.hungerstone2.blockID);
		world.setBlock(i + 1, j + 0, k + 24, VetheaBlockHelper.hungerstone2.blockID);
		world.setBlock(i + 1, j + 0, k + 25, VetheaBlockHelper.hungerstone2.blockID);
		world.setBlock(i + 1, j + 0, k + 26, VetheaBlockHelper.hungerstone2.blockID);
		world.setBlock(i + 1, j + 0, k + 27, VetheaBlockHelper.hungerstone2.blockID);
		world.setBlock(i + 1, j + 0, k + 28, VetheaBlockHelper.hungerstone2.blockID);
		world.setBlock(i + 1, j + 0, k + 29, VetheaBlockHelper.hungerstone2.blockID);
		world.setBlock(i + 1, j + 0, k + 30, VetheaBlockHelper.hungerstone2.blockID);
		world.setBlock(i + 1, j + 0, k + 31, VetheaBlockHelper.hungerstone2.blockID);
		world.setBlock(i + 1, j + 0, k + 32, VetheaBlockHelper.hungerstone2.blockID);
		world.setBlock(i + 1, j + 0, k + 33, VetheaBlockHelper.hungerstone2.blockID);
		world.setBlock(i + 1, j + 0, k + 34, VetheaBlockHelper.hungerstone2.blockID);
		world.setBlock(i + 1, j + 0, k + 35, VetheaBlockHelper.hungerstone2.blockID);
		world.setBlock(i + 1, j + 0, k + 36, VetheaBlockHelper.hungerstone2.blockID);
		world.setBlock(i + 1, j + 0, k + 37, VetheaBlockHelper.hungerstone2.blockID);
		world.setBlock(i + 1, j + 0, k + 38, VetheaBlockHelper.hungerstone2.blockID);
		world.setBlock(i + 1, j + 0, k + 39, VetheaBlockHelper.hungerstone2.blockID);
		world.setBlock(i + 1, j + 0, k + 40, VetheaBlockHelper.hungerstone2.blockID);
		world.setBlock(i + 1, j + 1, k + 0, 0);
		world.setBlock(i + 1, j + 1, k + 1, 0);
		world.setBlock(i + 1, j + 1, k + 2, VetheaBlockHelper.hungerstone1.blockID);
		world.setBlock(i + 1, j + 1, k + 3, 0);
		world.setBlock(i + 1, j + 1, k + 4, 0);
		world.setBlock(i + 1, j + 1, k + 5, 0);
		world.setBlock(i + 1, j + 1, k + 6, 0);
		world.setBlock(i + 1, j + 1, k + 7, 0);
		world.setBlock(i + 1, j + 1, k + 8, 0);
		world.setBlock(i + 1, j + 1, k + 9, 0);
		world.setBlock(i + 1, j + 1, k + 10, 0);
		world.setBlock(i + 1, j + 1, k + 11, 0);
		world.setBlock(i + 1, j + 1, k + 12, 0);
		world.setBlock(i + 1, j + 1, k + 13, 0);
		world.setBlock(i + 1, j + 1, k + 14, 0);
		world.setBlock(i + 1, j + 1, k + 15, 0);
		world.setBlock(i + 1, j + 1, k + 16, 0);
		world.setBlock(i + 1, j + 1, k + 17, 0);
		world.setBlock(i + 1, j + 1, k + 18, 0);
		world.setBlock(i + 1, j + 1, k + 19, 0);
		world.setBlock(i + 1, j + 1, k + 20, 0);
		world.setBlock(i + 1, j + 1, k + 21, VetheaBlockHelper.hungerstone1.blockID);
		world.setBlock(i + 1, j + 1, k + 22, 0);
		world.setBlock(i + 1, j + 1, k + 23, 0);
		world.setBlock(i + 1, j + 1, k + 24, 0);
		world.setBlock(i + 1, j + 1, k + 25, 0);
		world.setBlock(i + 1, j + 1, k + 26, 0);
		world.setBlock(i + 1, j + 1, k + 27, 0);
		world.setBlock(i + 1, j + 1, k + 28, 0);
		world.setBlock(i + 1, j + 1, k + 29, 0);
		world.setBlock(i + 1, j + 1, k + 30, 0);
		world.setBlock(i + 1, j + 1, k + 31, 0);
		world.setBlock(i + 1, j + 1, k + 32, 0);
		world.setBlock(i + 1, j + 1, k + 33, 0);
		world.setBlock(i + 1, j + 1, k + 34, 0);
		world.setBlock(i + 1, j + 1, k + 35, 0);
		world.setBlock(i + 1, j + 1, k + 36, 0);
		world.setBlock(i + 1, j + 1, k + 37, 0);
		world.setBlock(i + 1, j + 1, k + 38, 0);
		world.setBlock(i + 1, j + 1, k + 39, 0);
		world.setBlock(i + 1, j + 1, k + 40, VetheaBlockHelper.hungerstone1.blockID);
		world.setBlock(i + 1, j + 2, k + 0, 0);
		world.setBlock(i + 1, j + 2, k + 1, 0);
		world.setBlock(i + 1, j + 2, k + 2, 0);
		world.setBlock(i + 1, j + 2, k + 3, VetheaBlockHelper.hungerstone1.blockID);
		world.setBlock(i + 1, j + 2, k + 4, VetheaBlockHelper.hungerstone1.blockID);
		world.setBlock(i + 1, j + 2, k + 5, VetheaBlockHelper.hungerstone1.blockID);
		world.setBlock(i + 1, j + 2, k + 6, VetheaBlockHelper.hungerstone1.blockID);
		world.setBlock(i + 1, j + 2, k + 7, VetheaBlockHelper.hungerstone1.blockID);
		world.setBlock(i + 1, j + 2, k + 8, VetheaBlockHelper.hungerstone1.blockID);
		world.setBlock(i + 1, j + 2, k + 9, VetheaBlockHelper.hungerstone1.blockID);
		world.setBlock(i + 1, j + 2, k + 10, VetheaBlockHelper.hungerstone1.blockID);
		world.setBlock(i + 1, j + 2, k + 11, VetheaBlockHelper.hungerstone1.blockID);
		world.setBlock(i + 1, j + 2, k + 12, VetheaBlockHelper.hungerstone1.blockID);
		world.setBlock(i + 1, j + 2, k + 13, VetheaBlockHelper.hungerstone1.blockID);
		world.setBlock(i + 1, j + 2, k + 14, VetheaBlockHelper.hungerstone1.blockID);
		world.setBlock(i + 1, j + 2, k + 15, VetheaBlockHelper.hungerstone1.blockID);
		world.setBlock(i + 1, j + 2, k + 16, VetheaBlockHelper.hungerstone1.blockID);
		world.setBlock(i + 1, j + 2, k + 17, VetheaBlockHelper.hungerstone1.blockID);
		world.setBlock(i + 1, j + 2, k + 18, VetheaBlockHelper.hungerstone1.blockID);
		world.setBlock(i + 1, j + 2, k + 19, VetheaBlockHelper.hungerstone1.blockID);
		world.setBlock(i + 1, j + 2, k + 20, VetheaBlockHelper.hungerstone1.blockID);
		world.setBlock(i + 1, j + 2, k + 21, VetheaBlockHelper.hungerstone1.blockID);
		world.setBlock(i + 1, j + 2, k + 22, VetheaBlockHelper.hungerstone1.blockID);
		world.setBlock(i + 1, j + 2, k + 23, VetheaBlockHelper.hungerstone1.blockID);
		world.setBlock(i + 1, j + 2, k + 24, VetheaBlockHelper.hungerstone1.blockID);
		world.setBlock(i + 1, j + 2, k + 25, VetheaBlockHelper.hungerstone1.blockID);
		world.setBlock(i + 1, j + 2, k + 26, VetheaBlockHelper.hungerstone1.blockID);
		world.setBlock(i + 1, j + 2, k + 27, VetheaBlockHelper.hungerstone1.blockID);
		world.setBlock(i + 1, j + 2, k + 28, VetheaBlockHelper.hungerstone1.blockID);
		world.setBlock(i + 1, j + 2, k + 29, VetheaBlockHelper.hungerstone1.blockID);
		world.setBlock(i + 1, j + 2, k + 30, VetheaBlockHelper.hungerstone1.blockID);
		world.setBlock(i + 1, j + 2, k + 31, VetheaBlockHelper.hungerstone1.blockID);
		world.setBlock(i + 1, j + 2, k + 32, VetheaBlockHelper.hungerstone1.blockID);
		world.setBlock(i + 1, j + 2, k + 33, VetheaBlockHelper.hungerstone1.blockID);
		world.setBlock(i + 1, j + 2, k + 34, VetheaBlockHelper.hungerstone1.blockID);
		world.setBlock(i + 1, j + 2, k + 35, VetheaBlockHelper.hungerstone1.blockID);
		world.setBlock(i + 1, j + 2, k + 36, VetheaBlockHelper.hungerstone1.blockID);
		world.setBlock(i + 1, j + 2, k + 37, VetheaBlockHelper.hungerstone1.blockID);
		world.setBlock(i + 1, j + 2, k + 38, VetheaBlockHelper.hungerstone1.blockID);
		world.setBlock(i + 1, j + 2, k + 39, VetheaBlockHelper.hungerstone1.blockID);
		world.setBlock(i + 1, j + 2, k + 40, 0);
		world.setBlock(i + 1, j + 3, k + 0, 0);
		world.setBlock(i + 1, j + 3, k + 1, 0);
		world.setBlock(i + 1, j + 3, k + 2, 0);
		world.setBlock(i + 1, j + 3, k + 3, 0);
		world.setBlock(i + 1, j + 3, k + 4, 0);
		world.setBlock(i + 1, j + 3, k + 5, 0);
		world.setBlock(i + 1, j + 3, k + 6, 0);
		world.setBlock(i + 1, j + 3, k + 7, 0);
		world.setBlock(i + 1, j + 3, k + 8, 0);
		world.setBlock(i + 1, j + 3, k + 9, 0);
		world.setBlock(i + 1, j + 3, k + 10, 0);
		world.setBlock(i + 1, j + 3, k + 11, 0);
		world.setBlock(i + 1, j + 3, k + 12, 0);
		world.setBlock(i + 1, j + 3, k + 13, 0);
		world.setBlock(i + 1, j + 3, k + 14, 0);
		world.setBlock(i + 1, j + 3, k + 15, 0);
		world.setBlock(i + 1, j + 3, k + 16, 0);
		world.setBlock(i + 1, j + 3, k + 17, 0);
		world.setBlock(i + 1, j + 3, k + 18, 0);
		world.setBlock(i + 1, j + 3, k + 19, 0);
		world.setBlock(i + 1, j + 3, k + 20, 0);
		world.setBlock(i + 1, j + 3, k + 21, 0);
		world.setBlock(i + 1, j + 3, k + 22, 0);
		world.setBlock(i + 1, j + 3, k + 23, 0);
		world.setBlock(i + 1, j + 3, k + 24, 0);
		world.setBlock(i + 1, j + 3, k + 25, 0);
		world.setBlock(i + 1, j + 3, k + 26, 0);
		world.setBlock(i + 1, j + 3, k + 27, 0);
		world.setBlock(i + 1, j + 3, k + 28, 0);
		world.setBlock(i + 1, j + 3, k + 29, 0);
		world.setBlock(i + 1, j + 3, k + 30, 0);
		world.setBlock(i + 1, j + 3, k + 31, 0);
		world.setBlock(i + 1, j + 3, k + 32, 0);
		world.setBlock(i + 1, j + 3, k + 33, 0);
		world.setBlock(i + 1, j + 3, k + 34, 0);
		world.setBlock(i + 1, j + 3, k + 35, 0);
		world.setBlock(i + 1, j + 3, k + 36, 0);
		world.setBlock(i + 1, j + 3, k + 37, 0);
		world.setBlock(i + 1, j + 3, k + 38, 0);
		world.setBlock(i + 1, j + 3, k + 39, 0);
		world.setBlock(i + 1, j + 3, k + 40, 0);
		world.setBlock(i + 1, j + 4, k + 0, 0);
		world.setBlock(i + 1, j + 4, k + 1, 0);
		world.setBlock(i + 1, j + 4, k + 2, 0);
		world.setBlock(i + 1, j + 4, k + 3, 0);
		world.setBlock(i + 1, j + 4, k + 4, 0);
		world.setBlock(i + 1, j + 4, k + 5, 0);
		world.setBlock(i + 1, j + 4, k + 6, 0);
		world.setBlock(i + 1, j + 4, k + 7, 0);
		world.setBlock(i + 1, j + 4, k + 8, 0);
		world.setBlock(i + 1, j + 4, k + 9, 0);
		world.setBlock(i + 1, j + 4, k + 10, 0);
		world.setBlock(i + 1, j + 4, k + 11, 0);
		world.setBlock(i + 1, j + 4, k + 12, 0);
		world.setBlock(i + 1, j + 4, k + 13, 0);
		world.setBlock(i + 1, j + 4, k + 14, 0);
		world.setBlock(i + 1, j + 4, k + 15, 0);
		world.setBlock(i + 1, j + 4, k + 16, 0);
		world.setBlock(i + 1, j + 4, k + 17, 0);
		world.setBlock(i + 1, j + 4, k + 18, 0);
		world.setBlock(i + 1, j + 4, k + 19, 0);
		world.setBlock(i + 1, j + 4, k + 20, 0);
		world.setBlock(i + 1, j + 4, k + 21, 0);
		world.setBlock(i + 1, j + 4, k + 22, 0);
		world.setBlock(i + 1, j + 4, k + 23, 0);
		world.setBlock(i + 1, j + 4, k + 24, 0);
		world.setBlock(i + 1, j + 4, k + 25, 0);
		world.setBlock(i + 1, j + 4, k + 26, 0);
		world.setBlock(i + 1, j + 4, k + 27, 0);
		world.setBlock(i + 1, j + 4, k + 28, 0);
		world.setBlock(i + 1, j + 4, k + 29, 0);
		world.setBlock(i + 1, j + 4, k + 30, 0);
		world.setBlock(i + 1, j + 4, k + 31, 0);
		world.setBlock(i + 1, j + 4, k + 32, 0);
		world.setBlock(i + 1, j + 4, k + 33, 0);
		world.setBlock(i + 1, j + 4, k + 34, 0);
		world.setBlock(i + 1, j + 4, k + 35, 0);
		world.setBlock(i + 1, j + 4, k + 36, 0);
		world.setBlock(i + 1, j + 4, k + 37, 0);
		world.setBlock(i + 1, j + 4, k + 38, 0);
		world.setBlock(i + 1, j + 4, k + 39, 0);
		world.setBlock(i + 1, j + 4, k + 40, 0);
		world.setBlock(i + 1, j + 5, k + 0, 0);
		world.setBlock(i + 1, j + 5, k + 1, 0);
		world.setBlock(i + 1, j + 5, k + 2, 0);
		world.setBlock(i + 1, j + 5, k + 3, 0);
		world.setBlock(i + 1, j + 5, k + 4, 0);
		world.setBlock(i + 1, j + 5, k + 5, 0);
		world.setBlock(i + 1, j + 5, k + 6, 0);
		world.setBlock(i + 1, j + 5, k + 7, 0);
		world.setBlock(i + 1, j + 5, k + 8, 0);
		world.setBlock(i + 1, j + 5, k + 9, 0);
		world.setBlock(i + 1, j + 5, k + 10, 0);
		world.setBlock(i + 1, j + 5, k + 11, 0);
		world.setBlock(i + 1, j + 5, k + 12, 0);
		world.setBlock(i + 1, j + 5, k + 13, 0);
		world.setBlock(i + 1, j + 5, k + 14, 0);
		world.setBlock(i + 1, j + 5, k + 15, 0);
		world.setBlock(i + 1, j + 5, k + 16, 0);
		world.setBlock(i + 1, j + 5, k + 17, 0);
		world.setBlock(i + 1, j + 5, k + 18, 0);
		world.setBlock(i + 1, j + 5, k + 19, 0);
		world.setBlock(i + 1, j + 5, k + 20, 0);
		world.setBlock(i + 1, j + 5, k + 21, 0);
		world.setBlock(i + 1, j + 5, k + 22, 0);
		world.setBlock(i + 1, j + 5, k + 23, 0);
		world.setBlock(i + 1, j + 5, k + 24, 0);
		world.setBlock(i + 1, j + 5, k + 25, 0);
		world.setBlock(i + 1, j + 5, k + 26, 0);
		world.setBlock(i + 1, j + 5, k + 27, 0);
		world.setBlock(i + 1, j + 5, k + 28, 0);
		world.setBlock(i + 1, j + 5, k + 29, 0);
		world.setBlock(i + 1, j + 5, k + 30, 0);
		world.setBlock(i + 1, j + 5, k + 31, 0);
		world.setBlock(i + 1, j + 5, k + 32, 0);
		world.setBlock(i + 1, j + 5, k + 33, 0);
		world.setBlock(i + 1, j + 5, k + 34, 0);
		world.setBlock(i + 1, j + 5, k + 35, 0);
		world.setBlock(i + 1, j + 5, k + 36, 0);
		world.setBlock(i + 1, j + 5, k + 37, 0);
		world.setBlock(i + 1, j + 5, k + 38, 0);
		world.setBlock(i + 1, j + 5, k + 39, 0);
		world.setBlock(i + 1, j + 5, k + 40, 0);
		world.setBlock(i + 1, j + 6, k + 0, 0);
		world.setBlock(i + 1, j + 6, k + 1, 0);
		world.setBlock(i + 1, j + 6, k + 2, 0);
		world.setBlock(i + 1, j + 6, k + 3, 0);
		world.setBlock(i + 1, j + 6, k + 4, 0);
		world.setBlock(i + 1, j + 6, k + 5, 0);
		world.setBlock(i + 1, j + 6, k + 6, 0);
		world.setBlock(i + 1, j + 6, k + 7, 0);
		world.setBlock(i + 1, j + 6, k + 8, 0);
		world.setBlock(i + 1, j + 6, k + 9, 0);
		world.setBlock(i + 1, j + 6, k + 10, 0);
		world.setBlock(i + 1, j + 6, k + 11, 0);
		world.setBlock(i + 1, j + 6, k + 12, 0);
		world.setBlock(i + 1, j + 6, k + 13, 0);
		world.setBlock(i + 1, j + 6, k + 14, 0);
		world.setBlock(i + 1, j + 6, k + 15, 0);
		world.setBlock(i + 1, j + 6, k + 16, 0);
		world.setBlock(i + 1, j + 6, k + 17, 0);
		world.setBlock(i + 1, j + 6, k + 18, 0);
		world.setBlock(i + 1, j + 6, k + 19, 0);
		world.setBlock(i + 1, j + 6, k + 20, 0);
		world.setBlock(i + 1, j + 6, k + 21, 0);
		world.setBlock(i + 1, j + 6, k + 22, 0);
		world.setBlock(i + 1, j + 6, k + 23, 0);
		world.setBlock(i + 1, j + 6, k + 24, 0);
		world.setBlock(i + 1, j + 6, k + 25, 0);
		world.setBlock(i + 1, j + 6, k + 26, 0);
		world.setBlock(i + 1, j + 6, k + 27, 0);
		world.setBlock(i + 1, j + 6, k + 28, 0);
		world.setBlock(i + 1, j + 6, k + 29, 0);
		world.setBlock(i + 1, j + 6, k + 30, 0);
		world.setBlock(i + 1, j + 6, k + 31, 0);
		world.setBlock(i + 1, j + 6, k + 32, 0);
		world.setBlock(i + 1, j + 6, k + 33, 0);
		world.setBlock(i + 1, j + 6, k + 34, 0);
		world.setBlock(i + 1, j + 6, k + 35, 0);
		world.setBlock(i + 1, j + 6, k + 36, 0);
		world.setBlock(i + 1, j + 6, k + 37, 0);
		world.setBlock(i + 1, j + 6, k + 38, 0);
		world.setBlock(i + 1, j + 6, k + 39, 0);
		world.setBlock(i + 1, j + 6, k + 40, 0);
		world.setBlock(i + 1, j + 7, k + 0, 0);
		world.setBlock(i + 1, j + 7, k + 1, 0);
		world.setBlock(i + 1, j + 7, k + 2, 0);
		world.setBlock(i + 1, j + 7, k + 3, 0);
		world.setBlock(i + 1, j + 7, k + 4, 0);
		world.setBlock(i + 1, j + 7, k + 5, 0);
		world.setBlock(i + 1, j + 7, k + 6, 0);
		world.setBlock(i + 1, j + 7, k + 7, 0);
		world.setBlock(i + 1, j + 7, k + 8, 0);
		world.setBlock(i + 1, j + 7, k + 9, 0);
		world.setBlock(i + 1, j + 7, k + 10, 0);
		world.setBlock(i + 1, j + 7, k + 11, 0);
		world.setBlock(i + 1, j + 7, k + 12, 0);
		world.setBlock(i + 1, j + 7, k + 13, 0);
		world.setBlock(i + 1, j + 7, k + 14, 0);
		world.setBlock(i + 1, j + 7, k + 15, 0);
		world.setBlock(i + 1, j + 7, k + 16, 0);
		world.setBlock(i + 1, j + 7, k + 17, 0);
		world.setBlock(i + 1, j + 7, k + 18, 0);
		world.setBlock(i + 1, j + 7, k + 19, 0);
		world.setBlock(i + 1, j + 7, k + 20, 0);
		world.setBlock(i + 1, j + 7, k + 21, 0);
		world.setBlock(i + 1, j + 7, k + 22, 0);
		world.setBlock(i + 1, j + 7, k + 23, 0);
		world.setBlock(i + 1, j + 7, k + 24, 0);
		world.setBlock(i + 1, j + 7, k + 25, 0);
		world.setBlock(i + 1, j + 7, k + 26, 0);
		world.setBlock(i + 1, j + 7, k + 27, 0);
		world.setBlock(i + 1, j + 7, k + 28, 0);
		world.setBlock(i + 1, j + 7, k + 29, 0);
		world.setBlock(i + 1, j + 7, k + 30, 0);
		world.setBlock(i + 1, j + 7, k + 31, 0);
		world.setBlock(i + 1, j + 7, k + 32, 0);
		world.setBlock(i + 1, j + 7, k + 33, 0);
		world.setBlock(i + 1, j + 7, k + 34, 0);
		world.setBlock(i + 1, j + 7, k + 35, 0);
		world.setBlock(i + 1, j + 7, k + 36, 0);
		world.setBlock(i + 1, j + 7, k + 37, 0);
		world.setBlock(i + 1, j + 7, k + 38, 0);
		world.setBlock(i + 1, j + 7, k + 39, 0);
		world.setBlock(i + 1, j + 7, k + 40, 0);
		world.setBlock(i + 1, j + 8, k + 0, 0);
		world.setBlock(i + 1, j + 8, k + 1, 0);
		world.setBlock(i + 1, j + 8, k + 2, 0);
		world.setBlock(i + 1, j + 8, k + 3, 0);
		world.setBlock(i + 1, j + 8, k + 4, 0);
		world.setBlock(i + 1, j + 8, k + 5, 0);
		world.setBlock(i + 1, j + 8, k + 6, 0);
		world.setBlock(i + 1, j + 8, k + 7, 0);
		world.setBlock(i + 1, j + 8, k + 8, 0);
		world.setBlock(i + 1, j + 8, k + 9, 0);
		world.setBlock(i + 1, j + 8, k + 10, 0);
		world.setBlock(i + 1, j + 8, k + 11, 0);
		world.setBlock(i + 1, j + 8, k + 12, 0);
		world.setBlock(i + 1, j + 8, k + 13, 0);
		world.setBlock(i + 1, j + 8, k + 14, 0);
		world.setBlock(i + 1, j + 8, k + 15, 0);
		world.setBlock(i + 1, j + 8, k + 16, 0);
		world.setBlock(i + 1, j + 8, k + 17, 0);
		world.setBlock(i + 1, j + 8, k + 18, 0);
		world.setBlock(i + 1, j + 8, k + 19, 0);
		world.setBlock(i + 1, j + 8, k + 20, 0);
		world.setBlock(i + 1, j + 8, k + 21, 0);
		world.setBlock(i + 1, j + 8, k + 22, 0);
		world.setBlock(i + 1, j + 8, k + 23, 0);
		world.setBlock(i + 1, j + 8, k + 24, 0);
		world.setBlock(i + 1, j + 8, k + 25, 0);
		world.setBlock(i + 1, j + 8, k + 26, 0);
		world.setBlock(i + 1, j + 8, k + 27, 0);
		world.setBlock(i + 1, j + 8, k + 28, 0);
		world.setBlock(i + 1, j + 8, k + 29, 0);
		world.setBlock(i + 1, j + 8, k + 30, 0);
		world.setBlock(i + 1, j + 8, k + 31, 0);
		world.setBlock(i + 1, j + 8, k + 32, 0);
		world.setBlock(i + 1, j + 8, k + 33, 0);
		world.setBlock(i + 1, j + 8, k + 34, 0);
		world.setBlock(i + 1, j + 8, k + 35, 0);
		world.setBlock(i + 1, j + 8, k + 36, 0);
		world.setBlock(i + 1, j + 8, k + 37, 0);
		world.setBlock(i + 1, j + 8, k + 38, 0);
		world.setBlock(i + 1, j + 8, k + 39, 0);
		world.setBlock(i + 1, j + 8, k + 40, 0);
		world.setBlock(i + 1, j + 9, k + 0, 0);
		world.setBlock(i + 1, j + 9, k + 1, 0);
		world.setBlock(i + 1, j + 9, k + 2, 0);
		world.setBlock(i + 1, j + 9, k + 3, 0);
		world.setBlock(i + 1, j + 9, k + 4, 0);
		world.setBlock(i + 1, j + 9, k + 5, 0);
		world.setBlock(i + 1, j + 9, k + 6, 0);
		world.setBlock(i + 1, j + 9, k + 7, 0);
		world.setBlock(i + 1, j + 9, k + 8, 0);
		world.setBlock(i + 1, j + 9, k + 9, 0);
		world.setBlock(i + 1, j + 9, k + 10, 0);
		world.setBlock(i + 1, j + 9, k + 11, 0);
		world.setBlock(i + 1, j + 9, k + 12, 0);
		world.setBlock(i + 1, j + 9, k + 13, 0);
		world.setBlock(i + 1, j + 9, k + 14, 0);
		world.setBlock(i + 1, j + 9, k + 15, 0);
		world.setBlock(i + 1, j + 9, k + 16, 0);
		world.setBlock(i + 1, j + 9, k + 17, 0);
		world.setBlock(i + 1, j + 9, k + 18, 0);
		world.setBlock(i + 1, j + 9, k + 19, 0);
		world.setBlock(i + 1, j + 9, k + 20, 0);
		world.setBlock(i + 1, j + 9, k + 21, 0);
		world.setBlock(i + 1, j + 9, k + 22, 0);
		world.setBlock(i + 1, j + 9, k + 23, 0);
		world.setBlock(i + 1, j + 9, k + 24, 0);
		world.setBlock(i + 1, j + 9, k + 25, 0);
		world.setBlock(i + 1, j + 9, k + 26, 0);
		world.setBlock(i + 1, j + 9, k + 27, 0);
		world.setBlock(i + 1, j + 9, k + 28, 0);
		world.setBlock(i + 1, j + 9, k + 29, 0);
		world.setBlock(i + 1, j + 9, k + 30, 0);
		world.setBlock(i + 1, j + 9, k + 31, 0);
		world.setBlock(i + 1, j + 9, k + 32, 0);
		world.setBlock(i + 1, j + 9, k + 33, 0);
		world.setBlock(i + 1, j + 9, k + 34, 0);
		world.setBlock(i + 1, j + 9, k + 35, 0);
		world.setBlock(i + 1, j + 9, k + 36, 0);
		world.setBlock(i + 1, j + 9, k + 37, 0);
		world.setBlock(i + 1, j + 9, k + 38, 0);
		world.setBlock(i + 1, j + 9, k + 39, 0);
		world.setBlock(i + 1, j + 9, k + 40, 0);
		world.setBlock(i + 1, j + 10, k + 0, 0);
		world.setBlock(i + 1, j + 10, k + 1, 0);
		world.setBlock(i + 1, j + 10, k + 2, 0);
		world.setBlock(i + 1, j + 10, k + 3, 0);
		world.setBlock(i + 1, j + 10, k + 4, 0);
		world.setBlock(i + 1, j + 10, k + 5, 0);
		world.setBlock(i + 1, j + 10, k + 6, 0);
		world.setBlock(i + 1, j + 10, k + 7, 0);
		world.setBlock(i + 1, j + 10, k + 8, 0);
		world.setBlock(i + 1, j + 10, k + 9, 0);
		world.setBlock(i + 1, j + 10, k + 10, 0);
		world.setBlock(i + 1, j + 10, k + 11, 0);
		world.setBlock(i + 1, j + 10, k + 12, 0);
		world.setBlock(i + 1, j + 10, k + 13, 0);
		world.setBlock(i + 1, j + 10, k + 14, 0);
		world.setBlock(i + 1, j + 10, k + 15, 0);
		world.setBlock(i + 1, j + 10, k + 16, 0);
		world.setBlock(i + 1, j + 10, k + 17, 0);
		world.setBlock(i + 1, j + 10, k + 18, 0);
		world.setBlock(i + 1, j + 10, k + 19, 0);
		world.setBlock(i + 1, j + 10, k + 20, 0);
		world.setBlock(i + 1, j + 10, k + 21, 0);
		world.setBlock(i + 1, j + 10, k + 22, 0);
		world.setBlock(i + 1, j + 10, k + 23, 0);
		world.setBlock(i + 1, j + 10, k + 24, 0);
		world.setBlock(i + 1, j + 10, k + 25, 0);
		world.setBlock(i + 1, j + 10, k + 26, 0);
		world.setBlock(i + 1, j + 10, k + 27, 0);
		world.setBlock(i + 1, j + 10, k + 28, 0);
		world.setBlock(i + 1, j + 10, k + 29, 0);
		world.setBlock(i + 1, j + 10, k + 30, 0);
		world.setBlock(i + 1, j + 10, k + 31, 0);
		world.setBlock(i + 1, j + 10, k + 32, 0);
		world.setBlock(i + 1, j + 10, k + 33, 0);
		world.setBlock(i + 1, j + 10, k + 34, 0);
		world.setBlock(i + 1, j + 10, k + 35, 0);
		world.setBlock(i + 1, j + 10, k + 36, 0);
		world.setBlock(i + 1, j + 10, k + 37, 0);
		world.setBlock(i + 1, j + 10, k + 38, 0);
		world.setBlock(i + 1, j + 10, k + 39, 0);
		world.setBlock(i + 1, j + 10, k + 40, 0);
		world.setBlock(i + 1, j + 11, k + 0, 0);
		world.setBlock(i + 1, j + 11, k + 1, 0);
		world.setBlock(i + 1, j + 11, k + 2, 0);
		world.setBlock(i + 1, j + 11, k + 3, 0);
		world.setBlock(i + 1, j + 11, k + 4, 0);
		world.setBlock(i + 1, j + 11, k + 5, 0);
		world.setBlock(i + 1, j + 11, k + 6, 0);
		world.setBlock(i + 1, j + 11, k + 7, 0);
		world.setBlock(i + 1, j + 11, k + 8, 0);
		world.setBlock(i + 1, j + 11, k + 9, 0);
		world.setBlock(i + 1, j + 11, k + 10, 0);
		world.setBlock(i + 1, j + 11, k + 11, 0);
		world.setBlock(i + 1, j + 11, k + 12, 0);
		world.setBlock(i + 1, j + 11, k + 13, 0);
		world.setBlock(i + 1, j + 11, k + 14, 0);
		world.setBlock(i + 1, j + 11, k + 15, 0);
		world.setBlock(i + 1, j + 11, k + 16, 0);
		world.setBlock(i + 1, j + 11, k + 17, 0);
		world.setBlock(i + 1, j + 11, k + 18, 0);
		world.setBlock(i + 1, j + 11, k + 19, 0);
		world.setBlock(i + 1, j + 11, k + 20, 0);
		world.setBlock(i + 1, j + 11, k + 21, 0);
		world.setBlock(i + 1, j + 11, k + 22, 0);
		world.setBlock(i + 1, j + 11, k + 23, 0);
		world.setBlock(i + 1, j + 11, k + 24, 0);
		world.setBlock(i + 1, j + 11, k + 25, 0);
		world.setBlock(i + 1, j + 11, k + 26, 0);
		world.setBlock(i + 1, j + 11, k + 27, 0);
		world.setBlock(i + 1, j + 11, k + 28, 0);
		world.setBlock(i + 1, j + 11, k + 29, 0);
		world.setBlock(i + 1, j + 11, k + 30, 0);
		world.setBlock(i + 1, j + 11, k + 31, 0);
		world.setBlock(i + 1, j + 11, k + 32, 0);
		world.setBlock(i + 1, j + 11, k + 33, 0);
		world.setBlock(i + 1, j + 11, k + 34, 0);
		world.setBlock(i + 1, j + 11, k + 35, 0);
		world.setBlock(i + 1, j + 11, k + 36, 0);
		world.setBlock(i + 1, j + 11, k + 37, 0);
		world.setBlock(i + 1, j + 11, k + 38, 0);
		world.setBlock(i + 1, j + 11, k + 39, 0);
		world.setBlock(i + 1, j + 11, k + 40, 0);
		world.setBlock(i + 1, j + 12, k + 0, 0);
		world.setBlock(i + 1, j + 12, k + 1, 0);
		world.setBlock(i + 1, j + 12, k + 2, 0);
		world.setBlock(i + 1, j + 12, k + 3, 0);
		world.setBlock(i + 1, j + 12, k + 4, 0);
		world.setBlock(i + 1, j + 12, k + 5, 0);
		world.setBlock(i + 1, j + 12, k + 6, 0);
		world.setBlock(i + 1, j + 12, k + 7, 0);
		world.setBlock(i + 1, j + 12, k + 8, 0);
		world.setBlock(i + 1, j + 12, k + 9, 0);
		world.setBlock(i + 1, j + 12, k + 10, 0);
		world.setBlock(i + 1, j + 12, k + 11, 0);
		world.setBlock(i + 1, j + 12, k + 12, 0);
		world.setBlock(i + 1, j + 12, k + 13, 0);
		world.setBlock(i + 1, j + 12, k + 14, 0);
		world.setBlock(i + 1, j + 12, k + 15, 0);
		world.setBlock(i + 1, j + 12, k + 16, 0);
		world.setBlock(i + 1, j + 12, k + 17, 0);
		world.setBlock(i + 1, j + 12, k + 18, 0);
		world.setBlock(i + 1, j + 12, k + 19, 0);
		world.setBlock(i + 1, j + 12, k + 20, 0);
		world.setBlock(i + 1, j + 12, k + 21, 0);
		world.setBlock(i + 1, j + 12, k + 22, 0);
		world.setBlock(i + 1, j + 12, k + 23, 0);
		world.setBlock(i + 1, j + 12, k + 24, 0);
		world.setBlock(i + 1, j + 12, k + 25, 0);
		world.setBlock(i + 1, j + 12, k + 26, 0);
		world.setBlock(i + 1, j + 12, k + 27, 0);
		world.setBlock(i + 1, j + 12, k + 28, 0);
		world.setBlock(i + 1, j + 12, k + 29, 0);
		world.setBlock(i + 1, j + 12, k + 30, 0);
		world.setBlock(i + 1, j + 12, k + 31, 0);
		world.setBlock(i + 1, j + 12, k + 32, 0);
		world.setBlock(i + 1, j + 12, k + 33, 0);
		world.setBlock(i + 1, j + 12, k + 34, 0);
		world.setBlock(i + 1, j + 12, k + 35, 0);
		world.setBlock(i + 1, j + 12, k + 36, 0);
		world.setBlock(i + 1, j + 12, k + 37, 0);
		world.setBlock(i + 1, j + 12, k + 38, 0);
		world.setBlock(i + 1, j + 12, k + 39, 0);
		world.setBlock(i + 1, j + 12, k + 40, 0);
		world.setBlock(i + 1, j + 13, k + 0, 0);
		world.setBlock(i + 1, j + 13, k + 1, 0);
		world.setBlock(i + 1, j + 13, k + 2, 0);
		world.setBlock(i + 1, j + 13, k + 3, 0);
		world.setBlock(i + 1, j + 13, k + 4, 0);
		world.setBlock(i + 1, j + 13, k + 5, 0);
		world.setBlock(i + 1, j + 13, k + 6, 0);
		world.setBlock(i + 1, j + 13, k + 7, 0);
		world.setBlock(i + 1, j + 13, k + 8, 0);
		world.setBlock(i + 1, j + 13, k + 9, 0);
		world.setBlock(i + 1, j + 13, k + 10, 0);
		world.setBlock(i + 1, j + 13, k + 11, 0);
		world.setBlock(i + 1, j + 13, k + 12, 0);
		world.setBlock(i + 1, j + 13, k + 13, 0);
		world.setBlock(i + 1, j + 13, k + 14, 0);
		world.setBlock(i + 1, j + 13, k + 15, 0);
		world.setBlock(i + 1, j + 13, k + 16, 0);
		world.setBlock(i + 1, j + 13, k + 17, 0);
		world.setBlock(i + 1, j + 13, k + 18, 0);
		world.setBlock(i + 1, j + 13, k + 19, 0);
		world.setBlock(i + 1, j + 13, k + 20, 0);
		world.setBlock(i + 1, j + 13, k + 21, 0);
		world.setBlock(i + 1, j + 13, k + 22, 0);
		world.setBlock(i + 1, j + 13, k + 23, 0);
		world.setBlock(i + 1, j + 13, k + 24, 0);
		world.setBlock(i + 1, j + 13, k + 25, 0);
		world.setBlock(i + 1, j + 13, k + 26, 0);
		world.setBlock(i + 1, j + 13, k + 27, 0);
		world.setBlock(i + 1, j + 13, k + 28, 0);
		world.setBlock(i + 1, j + 13, k + 29, 0);
		world.setBlock(i + 1, j + 13, k + 30, 0);
		world.setBlock(i + 1, j + 13, k + 31, 0);
		world.setBlock(i + 1, j + 13, k + 32, 0);
		world.setBlock(i + 1, j + 13, k + 33, 0);
		world.setBlock(i + 1, j + 13, k + 34, 0);
		world.setBlock(i + 1, j + 13, k + 35, 0);
		world.setBlock(i + 1, j + 13, k + 36, 0);
		world.setBlock(i + 1, j + 13, k + 37, 0);
		world.setBlock(i + 1, j + 13, k + 38, 0);
		world.setBlock(i + 1, j + 13, k + 39, 0);
		world.setBlock(i + 1, j + 13, k + 40, 0);
		world.setBlock(i + 1, j + 14, k + 0, 0);
		world.setBlock(i + 1, j + 14, k + 1, 0);
		world.setBlock(i + 1, j + 14, k + 2, 0);
		world.setBlock(i + 1, j + 14, k + 3, 0);
		world.setBlock(i + 1, j + 14, k + 4, 0);
		world.setBlock(i + 1, j + 14, k + 5, 0);
		world.setBlock(i + 1, j + 14, k + 6, 0);
		world.setBlock(i + 1, j + 14, k + 7, 0);
		world.setBlock(i + 1, j + 14, k + 8, 0);
		world.setBlock(i + 1, j + 14, k + 9, 0);
		world.setBlock(i + 1, j + 14, k + 10, 0);
		world.setBlock(i + 1, j + 14, k + 11, 0);
		world.setBlock(i + 1, j + 14, k + 12, 0);
		world.setBlock(i + 1, j + 14, k + 13, 0);
		world.setBlock(i + 1, j + 14, k + 14, 0);
		world.setBlock(i + 1, j + 14, k + 15, 0);
		world.setBlock(i + 1, j + 14, k + 16, 0);
		world.setBlock(i + 1, j + 14, k + 17, 0);
		world.setBlock(i + 1, j + 14, k + 18, 0);
		world.setBlock(i + 1, j + 14, k + 19, 0);
		world.setBlock(i + 1, j + 14, k + 20, 0);
		world.setBlock(i + 1, j + 14, k + 21, 0);
		world.setBlock(i + 1, j + 14, k + 22, 0);
		world.setBlock(i + 1, j + 14, k + 23, 0);
		world.setBlock(i + 1, j + 14, k + 24, 0);
		world.setBlock(i + 1, j + 14, k + 25, 0);
		world.setBlock(i + 1, j + 14, k + 26, 0);
		world.setBlock(i + 1, j + 14, k + 27, 0);
		world.setBlock(i + 1, j + 14, k + 28, 0);
		world.setBlock(i + 1, j + 14, k + 29, 0);
		world.setBlock(i + 1, j + 14, k + 30, 0);
		world.setBlock(i + 1, j + 14, k + 31, 0);
		world.setBlock(i + 1, j + 14, k + 32, 0);
		world.setBlock(i + 1, j + 14, k + 33, 0);
		world.setBlock(i + 1, j + 14, k + 34, 0);
		world.setBlock(i + 1, j + 14, k + 35, 0);
		world.setBlock(i + 1, j + 14, k + 36, 0);
		world.setBlock(i + 1, j + 14, k + 37, 0);
		world.setBlock(i + 1, j + 14, k + 38, 0);
		world.setBlock(i + 1, j + 14, k + 39, 0);
		world.setBlock(i + 1, j + 14, k + 40, 0);
		world.setBlock(i + 1, j + 15, k + 0, 0);
		world.setBlock(i + 1, j + 15, k + 1, 0);
		world.setBlock(i + 1, j + 15, k + 2, 0);
		world.setBlock(i + 1, j + 15, k + 3, 0);
		world.setBlock(i + 1, j + 15, k + 4, 0);
		world.setBlock(i + 1, j + 15, k + 5, 0);
		world.setBlock(i + 1, j + 15, k + 6, 0);
		world.setBlock(i + 1, j + 15, k + 7, 0);
		world.setBlock(i + 1, j + 15, k + 8, 0);
		world.setBlock(i + 1, j + 15, k + 9, 0);
		world.setBlock(i + 1, j + 15, k + 10, 0);
		world.setBlock(i + 1, j + 15, k + 11, 0);
		world.setBlock(i + 1, j + 15, k + 12, 0);
		world.setBlock(i + 1, j + 15, k + 13, 0);
		world.setBlock(i + 1, j + 15, k + 14, 0);
		world.setBlock(i + 1, j + 15, k + 15, 0);
		world.setBlock(i + 1, j + 15, k + 16, 0);
		world.setBlock(i + 1, j + 15, k + 17, 0);
		world.setBlock(i + 1, j + 15, k + 18, 0);
		world.setBlock(i + 1, j + 15, k + 19, 0);
		world.setBlock(i + 1, j + 15, k + 20, 0);
		world.setBlock(i + 1, j + 15, k + 21, 0);
		world.setBlock(i + 1, j + 15, k + 22, 0);
		world.setBlock(i + 1, j + 15, k + 23, 0);

		generate2(world, rand, i, j, k);
		return true;
	}

	public boolean generate2(World world, Random rand, int i, int j, int k) {
		world.setBlock(i + 1, j + 15, k + 24, 0);
		world.setBlock(i + 1, j + 15, k + 25, 0);
		world.setBlock(i + 1, j + 15, k + 26, 0);
		world.setBlock(i + 1, j + 15, k + 27, 0);
		world.setBlock(i + 1, j + 15, k + 28, 0);
		world.setBlock(i + 1, j + 15, k + 29, 0);
		world.setBlock(i + 1, j + 15, k + 30, 0);
		world.setBlock(i + 1, j + 15, k + 31, 0);
		world.setBlock(i + 1, j + 15, k + 32, 0);
		world.setBlock(i + 1, j + 15, k + 33, 0);
		world.setBlock(i + 1, j + 15, k + 34, 0);
		world.setBlock(i + 1, j + 15, k + 35, 0);
		world.setBlock(i + 1, j + 15, k + 36, 0);
		world.setBlock(i + 1, j + 15, k + 37, 0);
		world.setBlock(i + 1, j + 15, k + 38, 0);
		world.setBlock(i + 1, j + 15, k + 39, 0);
		world.setBlock(i + 1, j + 15, k + 40, 0);
		world.setBlock(i + 1, j + 16, k + 0, 0);
		world.setBlock(i + 1, j + 16, k + 1, 0);
		world.setBlock(i + 1, j + 16, k + 2, 0);
		world.setBlock(i + 1, j + 16, k + 3, 0);
		world.setBlock(i + 1, j + 16, k + 4, 0);
		world.setBlock(i + 1, j + 16, k + 5, 0);
		world.setBlock(i + 1, j + 16, k + 6, 0);
		world.setBlock(i + 1, j + 16, k + 7, 0);
		world.setBlock(i + 1, j + 16, k + 8, 0);
		world.setBlock(i + 1, j + 16, k + 9, 0);
		world.setBlock(i + 1, j + 16, k + 10, 0);
		world.setBlock(i + 1, j + 16, k + 11, 0);
		world.setBlock(i + 1, j + 16, k + 12, 0);
		world.setBlock(i + 1, j + 16, k + 13, 0);
		world.setBlock(i + 1, j + 16, k + 14, 0);
		world.setBlock(i + 1, j + 16, k + 15, 0);
		world.setBlock(i + 1, j + 16, k + 16, 0);
		world.setBlock(i + 1, j + 16, k + 17, 0);
		world.setBlock(i + 1, j + 16, k + 18, 0);
		world.setBlock(i + 1, j + 16, k + 19, 0);
		world.setBlock(i + 1, j + 16, k + 20, 0);
		world.setBlock(i + 1, j + 16, k + 21, 0);
		world.setBlock(i + 1, j + 16, k + 22, 0);
		world.setBlock(i + 1, j + 16, k + 23, 0);
		world.setBlock(i + 1, j + 16, k + 24, 0);
		world.setBlock(i + 1, j + 16, k + 25, 0);
		world.setBlock(i + 1, j + 16, k + 26, 0);
		world.setBlock(i + 1, j + 16, k + 27, 0);
		world.setBlock(i + 1, j + 16, k + 28, 0);
		world.setBlock(i + 1, j + 16, k + 29, 0);
		world.setBlock(i + 1, j + 16, k + 30, 0);
		world.setBlock(i + 1, j + 16, k + 31, 0);
		world.setBlock(i + 1, j + 16, k + 32, 0);
		world.setBlock(i + 1, j + 16, k + 33, 0);
		world.setBlock(i + 1, j + 16, k + 34, 0);
		world.setBlock(i + 1, j + 16, k + 35, 0);
		world.setBlock(i + 1, j + 16, k + 36, 0);
		world.setBlock(i + 1, j + 16, k + 37, 0);
		world.setBlock(i + 1, j + 16, k + 38, 0);
		world.setBlock(i + 1, j + 16, k + 39, 0);
		world.setBlock(i + 1, j + 16, k + 40, 0);
		world.setBlock(i + 1, j + 17, k + 0, 0);
		world.setBlock(i + 1, j + 17, k + 1, 0);
		world.setBlock(i + 1, j + 17, k + 2, 0);
		world.setBlock(i + 1, j + 17, k + 3, 0);
		world.setBlock(i + 1, j + 17, k + 4, 0);
		world.setBlock(i + 1, j + 17, k + 5, 0);
		world.setBlock(i + 1, j + 17, k + 6, 0);
		world.setBlock(i + 1, j + 17, k + 7, 0);
		world.setBlock(i + 1, j + 17, k + 8, 0);
		world.setBlock(i + 1, j + 17, k + 9, 0);
		world.setBlock(i + 1, j + 17, k + 10, 0);
		world.setBlock(i + 1, j + 17, k + 11, 0);
		world.setBlock(i + 1, j + 17, k + 12, 0);
		world.setBlock(i + 1, j + 17, k + 13, 0);
		world.setBlock(i + 1, j + 17, k + 14, 0);
		world.setBlock(i + 1, j + 17, k + 15, 0);
		world.setBlock(i + 1, j + 17, k + 16, 0);
		world.setBlock(i + 1, j + 17, k + 17, 0);
		world.setBlock(i + 1, j + 17, k + 18, 0);
		world.setBlock(i + 1, j + 17, k + 19, 0);
		world.setBlock(i + 1, j + 17, k + 20, 0);
		world.setBlock(i + 1, j + 17, k + 21, 0);
		world.setBlock(i + 1, j + 17, k + 22, 0);
		world.setBlock(i + 1, j + 17, k + 23, 0);
		world.setBlock(i + 1, j + 17, k + 24, 0);
		world.setBlock(i + 1, j + 17, k + 25, 0);
		world.setBlock(i + 1, j + 17, k + 26, 0);
		world.setBlock(i + 1, j + 17, k + 27, 0);
		world.setBlock(i + 1, j + 17, k + 28, 0);
		world.setBlock(i + 1, j + 17, k + 29, 0);
		world.setBlock(i + 1, j + 17, k + 30, 0);
		world.setBlock(i + 1, j + 17, k + 31, 0);
		world.setBlock(i + 1, j + 17, k + 32, 0);
		world.setBlock(i + 1, j + 17, k + 33, 0);
		world.setBlock(i + 1, j + 17, k + 34, 0);
		world.setBlock(i + 1, j + 17, k + 35, 0);
		world.setBlock(i + 1, j + 17, k + 36, 0);
		world.setBlock(i + 1, j + 17, k + 37, 0);
		world.setBlock(i + 1, j + 17, k + 38, 0);
		world.setBlock(i + 1, j + 17, k + 39, 0);
		world.setBlock(i + 1, j + 17, k + 40, 0);
		world.setBlock(i + 1, j + 18, k + 0, 0);
		world.setBlock(i + 1, j + 18, k + 1, 0);
		world.setBlock(i + 1, j + 18, k + 2, 0);
		world.setBlock(i + 1, j + 18, k + 3, 0);
		world.setBlock(i + 1, j + 18, k + 4, 0);
		world.setBlock(i + 1, j + 18, k + 5, 0);
		world.setBlock(i + 1, j + 18, k + 6, 0);
		world.setBlock(i + 1, j + 18, k + 7, 0);
		world.setBlock(i + 1, j + 18, k + 8, 0);
		world.setBlock(i + 1, j + 18, k + 9, 0);
		world.setBlock(i + 1, j + 18, k + 10, 0);
		world.setBlock(i + 1, j + 18, k + 11, 0);
		world.setBlock(i + 1, j + 18, k + 12, 0);
		world.setBlock(i + 1, j + 18, k + 13, 0);
		world.setBlock(i + 1, j + 18, k + 14, 0);
		world.setBlock(i + 1, j + 18, k + 15, 0);
		world.setBlock(i + 1, j + 18, k + 16, 0);
		world.setBlock(i + 1, j + 18, k + 17, 0);
		world.setBlock(i + 1, j + 18, k + 18, 0);
		world.setBlock(i + 1, j + 18, k + 19, 0);
		world.setBlock(i + 1, j + 18, k + 20, 0);
		world.setBlock(i + 1, j + 18, k + 21, 0);
		world.setBlock(i + 1, j + 18, k + 22, 0);
		world.setBlock(i + 1, j + 18, k + 23, 0);
		world.setBlock(i + 1, j + 18, k + 24, 0);
		world.setBlock(i + 1, j + 18, k + 25, 0);
		world.setBlock(i + 1, j + 18, k + 26, 0);
		world.setBlock(i + 1, j + 18, k + 27, 0);
		world.setBlock(i + 1, j + 18, k + 28, 0);
		world.setBlock(i + 1, j + 18, k + 29, 0);
		world.setBlock(i + 1, j + 18, k + 30, 0);
		world.setBlock(i + 1, j + 18, k + 31, 0);
		world.setBlock(i + 1, j + 18, k + 32, 0);
		world.setBlock(i + 1, j + 18, k + 33, 0);
		world.setBlock(i + 1, j + 18, k + 34, 0);
		world.setBlock(i + 1, j + 18, k + 35, 0);
		world.setBlock(i + 1, j + 18, k + 36, 0);
		world.setBlock(i + 1, j + 18, k + 37, 0);
		world.setBlock(i + 1, j + 18, k + 38, 0);
		world.setBlock(i + 1, j + 18, k + 39, 0);
		world.setBlock(i + 1, j + 18, k + 40, 0);
		world.setBlock(i + 1, j + 19, k + 0, 0);
		world.setBlock(i + 1, j + 19, k + 1, 0);
		world.setBlock(i + 1, j + 19, k + 2, 0);
		world.setBlock(i + 1, j + 19, k + 3, 0);
		world.setBlock(i + 1, j + 19, k + 4, 0);
		world.setBlock(i + 1, j + 19, k + 5, 0);
		world.setBlock(i + 1, j + 19, k + 6, 0);
		world.setBlock(i + 1, j + 19, k + 7, 0);
		world.setBlock(i + 1, j + 19, k + 8, 0);
		world.setBlock(i + 1, j + 19, k + 9, 0);
		world.setBlock(i + 1, j + 19, k + 10, 0);
		world.setBlock(i + 1, j + 19, k + 11, 0);
		world.setBlock(i + 1, j + 19, k + 12, 0);
		world.setBlock(i + 1, j + 19, k + 13, 0);
		world.setBlock(i + 1, j + 19, k + 14, 0);
		world.setBlock(i + 1, j + 19, k + 15, 0);
		world.setBlock(i + 1, j + 19, k + 16, 0);
		world.setBlock(i + 1, j + 19, k + 17, 0);
		world.setBlock(i + 1, j + 19, k + 18, 0);
		world.setBlock(i + 1, j + 19, k + 19, 0);
		world.setBlock(i + 1, j + 19, k + 20, 0);
		world.setBlock(i + 1, j + 19, k + 21, 0);
		world.setBlock(i + 1, j + 19, k + 22, 0);
		world.setBlock(i + 1, j + 19, k + 23, 0);
		world.setBlock(i + 1, j + 19, k + 24, 0);
		world.setBlock(i + 1, j + 19, k + 25, 0);
		world.setBlock(i + 1, j + 19, k + 26, 0);
		world.setBlock(i + 1, j + 19, k + 27, 0);
		world.setBlock(i + 1, j + 19, k + 28, 0);
		world.setBlock(i + 1, j + 19, k + 29, 0);
		world.setBlock(i + 1, j + 19, k + 30, 0);
		world.setBlock(i + 1, j + 19, k + 31, 0);
		world.setBlock(i + 1, j + 19, k + 32, 0);
		world.setBlock(i + 1, j + 19, k + 33, 0);
		world.setBlock(i + 1, j + 19, k + 34, 0);
		world.setBlock(i + 1, j + 19, k + 35, 0);
		world.setBlock(i + 1, j + 19, k + 36, 0);
		world.setBlock(i + 1, j + 19, k + 37, 0);
		world.setBlock(i + 1, j + 19, k + 38, 0);
		world.setBlock(i + 1, j + 19, k + 39, 0);
		world.setBlock(i + 1, j + 19, k + 40, 0);
		world.setBlock(i + 1, j + 20, k + 0, 0);
		world.setBlock(i + 1, j + 20, k + 1, 0);
		world.setBlock(i + 1, j + 20, k + 2, 0);
		world.setBlock(i + 1, j + 20, k + 3, 0);
		world.setBlock(i + 1, j + 20, k + 4, 0);
		world.setBlock(i + 1, j + 20, k + 5, 0);
		world.setBlock(i + 1, j + 20, k + 6, 0);
		world.setBlock(i + 1, j + 20, k + 7, 0);
		world.setBlock(i + 1, j + 20, k + 8, 0);
		world.setBlock(i + 1, j + 20, k + 9, 0);
		world.setBlock(i + 1, j + 20, k + 10, 0);
		world.setBlock(i + 1, j + 20, k + 11, 0);
		world.setBlock(i + 1, j + 20, k + 12, 0);
		world.setBlock(i + 1, j + 20, k + 13, 0);
		world.setBlock(i + 1, j + 20, k + 14, 0);
		world.setBlock(i + 1, j + 20, k + 15, 0);
		world.setBlock(i + 1, j + 20, k + 16, 0);
		world.setBlock(i + 1, j + 20, k + 17, 0);
		world.setBlock(i + 1, j + 20, k + 18, 0);
		world.setBlock(i + 1, j + 20, k + 19, 0);
		world.setBlock(i + 1, j + 20, k + 20, 0);
		world.setBlock(i + 1, j + 20, k + 21, 0);
		world.setBlock(i + 1, j + 20, k + 22, 0);
		world.setBlock(i + 1, j + 20, k + 23, 0);
		world.setBlock(i + 1, j + 20, k + 24, 0);
		world.setBlock(i + 1, j + 20, k + 25, 0);
		world.setBlock(i + 1, j + 20, k + 26, 0);
		world.setBlock(i + 1, j + 20, k + 27, 0);
		world.setBlock(i + 1, j + 20, k + 28, 0);
		world.setBlock(i + 1, j + 20, k + 29, 0);
		world.setBlock(i + 1, j + 20, k + 30, 0);
		world.setBlock(i + 1, j + 20, k + 31, 0);
		world.setBlock(i + 1, j + 20, k + 32, 0);
		world.setBlock(i + 1, j + 20, k + 33, 0);
		world.setBlock(i + 1, j + 20, k + 34, 0);
		world.setBlock(i + 1, j + 20, k + 35, 0);
		world.setBlock(i + 1, j + 20, k + 36, 0);
		world.setBlock(i + 1, j + 20, k + 37, 0);
		world.setBlock(i + 1, j + 20, k + 38, 0);
		world.setBlock(i + 1, j + 20, k + 39, 0);
		world.setBlock(i + 1, j + 20, k + 40, 0);
		world.setBlock(i + 2, j + 0, k + 0, 0);
		world.setBlock(i + 2, j + 0, k + 1, 0);
		world.setBlock(i + 2, j + 0, k + 2, VetheaBlockHelper.hungerstone2.blockID);
		world.setBlock(i + 2, j + 0, k + 3, VetheaBlockHelper.hungerstone2.blockID);
		world.setBlock(i + 2, j + 0, k + 4, VetheaBlockHelper.hungerstone2.blockID);
		world.setBlock(i + 2, j + 0, k + 5, VetheaBlockHelper.hungerstone2.blockID);
		world.setBlock(i + 2, j + 0, k + 6, VetheaBlockHelper.hungerstone2.blockID);
		world.setBlock(i + 2, j + 0, k + 7, VetheaBlockHelper.hungerstone2.blockID);
		world.setBlock(i + 2, j + 0, k + 8, VetheaBlockHelper.hungerstone2.blockID);
		world.setBlock(i + 2, j + 0, k + 9, VetheaBlockHelper.hungerstone2.blockID);
		world.setBlock(i + 2, j + 0, k + 10, VetheaBlockHelper.hungerstone2.blockID);
		world.setBlock(i + 2, j + 0, k + 11, VetheaBlockHelper.hungerstone2.blockID);
		world.setBlock(i + 2, j + 0, k + 12, VetheaBlockHelper.hungerstone2.blockID);
		world.setBlock(i + 2, j + 0, k + 13, VetheaBlockHelper.hungerstone2.blockID);
		world.setBlock(i + 2, j + 0, k + 14, VetheaBlockHelper.hungerstone2.blockID);
		world.setBlock(i + 2, j + 0, k + 15, VetheaBlockHelper.hungerstone2.blockID);
		world.setBlock(i + 2, j + 0, k + 16, VetheaBlockHelper.hungerstone2.blockID);
		world.setBlock(i + 2, j + 0, k + 17, VetheaBlockHelper.hungerstone2.blockID);
		world.setBlock(i + 2, j + 0, k + 18, VetheaBlockHelper.hungerstone2.blockID);
		world.setBlock(i + 2, j + 0, k + 19, VetheaBlockHelper.hungerstone2.blockID);
		world.setBlock(i + 2, j + 0, k + 20, VetheaBlockHelper.hungerstone2.blockID);
		world.setBlock(i + 2, j + 0, k + 21, VetheaBlockHelper.hungerstone2.blockID);
		world.setBlock(i + 2, j + 0, k + 22, VetheaBlockHelper.hungerstone2.blockID);
		world.setBlock(i + 2, j + 0, k + 23, VetheaBlockHelper.hungerstone2.blockID);
		world.setBlock(i + 2, j + 0, k + 24, VetheaBlockHelper.hungerstone2.blockID);
		world.setBlock(i + 2, j + 0, k + 25, VetheaBlockHelper.hungerstone2.blockID);
		world.setBlock(i + 2, j + 0, k + 26, VetheaBlockHelper.hungerstone2.blockID);
		world.setBlock(i + 2, j + 0, k + 27, VetheaBlockHelper.hungerstone2.blockID);
		world.setBlock(i + 2, j + 0, k + 28, VetheaBlockHelper.hungerstone2.blockID);
		world.setBlock(i + 2, j + 0, k + 29, VetheaBlockHelper.hungerstone2.blockID);
		world.setBlock(i + 2, j + 0, k + 30, VetheaBlockHelper.hungerstone2.blockID);
		world.setBlock(i + 2, j + 0, k + 31, VetheaBlockHelper.hungerstone2.blockID);
		world.setBlock(i + 2, j + 0, k + 32, VetheaBlockHelper.hungerstone2.blockID);
		world.setBlock(i + 2, j + 0, k + 33, VetheaBlockHelper.hungerstone2.blockID);
		world.setBlock(i + 2, j + 0, k + 34, VetheaBlockHelper.hungerstone2.blockID);
		world.setBlock(i + 2, j + 0, k + 35, VetheaBlockHelper.hungerstone2.blockID);
		world.setBlock(i + 2, j + 0, k + 36, VetheaBlockHelper.hungerstone2.blockID);
		world.setBlock(i + 2, j + 0, k + 37, VetheaBlockHelper.hungerstone2.blockID);
		world.setBlock(i + 2, j + 0, k + 38, VetheaBlockHelper.hungerstone2.blockID);
		world.setBlock(i + 2, j + 0, k + 39, VetheaBlockHelper.hungerstone2.blockID);
		world.setBlock(i + 2, j + 0, k + 40, VetheaBlockHelper.hungerstone2.blockID);
		world.setBlock(i + 2, j + 1, k + 0, 0);
		world.setBlock(i + 2, j + 1, k + 1, 0);
		world.setBlock(i + 2, j + 1, k + 2, VetheaBlockHelper.hungerstone1.blockID);
		world.setBlock(i + 2, j + 1, k + 3, 0);
		world.setBlock(i + 2, j + 1, k + 4, 0);
		world.setBlock(i + 2, j + 1, k + 5, 0);
		world.setBlock(i + 2, j + 1, k + 6, 0);
		world.setBlock(i + 2, j + 1, k + 7, 0);
		world.setBlock(i + 2, j + 1, k + 8, 0);
		world.setBlock(i + 2, j + 1, k + 9, 0);
		world.setBlock(i + 2, j + 1, k + 10, 0);
		world.setBlock(i + 2, j + 1, k + 11, 0);
		world.setBlock(i + 2, j + 1, k + 12, 0);
		world.setBlock(i + 2, j + 1, k + 13, 0);
		world.setBlock(i + 2, j + 1, k + 14, 0);
		world.setBlock(i + 2, j + 1, k + 15, 0);
		world.setBlock(i + 2, j + 1, k + 16, 0);
		world.setBlock(i + 2, j + 1, k + 17, 0);
		world.setBlock(i + 2, j + 1, k + 18, 0);
		world.setBlock(i + 2, j + 1, k + 19, 0);
		world.setBlock(i + 2, j + 1, k + 20, 0);
		world.setBlock(i + 2, j + 1, k + 21, VetheaBlockHelper.hungerstone1.blockID);
		world.setBlock(i + 2, j + 1, k + 22, 0);
		world.setBlock(i + 2, j + 1, k + 23, 0);
		world.setBlock(i + 2, j + 1, k + 24, 0);
		world.setBlock(i + 2, j + 1, k + 25, 0);
		world.setBlock(i + 2, j + 1, k + 26, 0);
		world.setBlock(i + 2, j + 1, k + 27, 0);
		world.setBlock(i + 2, j + 1, k + 28, 0);
		world.setBlock(i + 2, j + 1, k + 29, 0);
		world.setBlock(i + 2, j + 1, k + 30, 0);
		world.setBlock(i + 2, j + 1, k + 31, 0);
		world.setBlock(i + 2, j + 1, k + 32, 0);
		world.setBlock(i + 2, j + 1, k + 33, 0);
		world.setBlock(i + 2, j + 1, k + 34, 0);
		world.setBlock(i + 2, j + 1, k + 35, 0);
		world.setBlock(i + 2, j + 1, k + 36, 0);
		world.setBlock(i + 2, j + 1, k + 37, 0);
		world.setBlock(i + 2, j + 1, k + 38, 0);
		world.setBlock(i + 2, j + 1, k + 39, 0);
		world.setBlock(i + 2, j + 1, k + 40, VetheaBlockHelper.hungerstone1.blockID);
		world.setBlock(i + 2, j + 2, k + 0, 0);
		world.setBlock(i + 2, j + 2, k + 1, 0);
		world.setBlock(i + 2, j + 2, k + 2, 0);
		world.setBlock(i + 2, j + 2, k + 3, VetheaBlockHelper.hungerstone1.blockID);
		world.setBlock(i + 2, j + 2, k + 4, 0);
		world.setBlock(i + 2, j + 2, k + 5, 0);
		world.setBlock(i + 2, j + 2, k + 6, 0);
		world.setBlock(i + 2, j + 2, k + 7, 0);
		world.setBlock(i + 2, j + 2, k + 8, 0);
		world.setBlock(i + 2, j + 2, k + 9, 0);
		world.setBlock(i + 2, j + 2, k + 10, 0);
		world.setBlock(i + 2, j + 2, k + 11, 0);
		world.setBlock(i + 2, j + 2, k + 12, 0);
		world.setBlock(i + 2, j + 2, k + 13, 0);
		world.setBlock(i + 2, j + 2, k + 14, 0);
		world.setBlock(i + 2, j + 2, k + 15, 0);
		world.setBlock(i + 2, j + 2, k + 16, 0);
		world.setBlock(i + 2, j + 2, k + 17, 0);
		world.setBlock(i + 2, j + 2, k + 18, 0);
		world.setBlock(i + 2, j + 2, k + 19, 0);
		world.setBlock(i + 2, j + 2, k + 20, 0);
		world.setBlock(i + 2, j + 2, k + 21, VetheaBlockHelper.hungerstone1.blockID);
		world.setBlock(i + 2, j + 2, k + 22, 0);
		world.setBlock(i + 2, j + 2, k + 23, 0);
		world.setBlock(i + 2, j + 2, k + 24, 0);
		world.setBlock(i + 2, j + 2, k + 25, 0);
		world.setBlock(i + 2, j + 2, k + 26, 0);
		world.setBlock(i + 2, j + 2, k + 27, 0);
		world.setBlock(i + 2, j + 2, k + 28, 0);
		world.setBlock(i + 2, j + 2, k + 29, 0);
		world.setBlock(i + 2, j + 2, k + 30, 0);
		world.setBlock(i + 2, j + 2, k + 31, 0);
		world.setBlock(i + 2, j + 2, k + 32, 0);
		world.setBlock(i + 2, j + 2, k + 33, 0);
		world.setBlock(i + 2, j + 2, k + 34, 0);
		world.setBlock(i + 2, j + 2, k + 35, 0);
		world.setBlock(i + 2, j + 2, k + 36, 0);
		world.setBlock(i + 2, j + 2, k + 37, 0);
		world.setBlock(i + 2, j + 2, k + 38, 0);
		world.setBlock(i + 2, j + 2, k + 39, VetheaBlockHelper.hungerstone1.blockID);
		world.setBlock(i + 2, j + 2, k + 40, 0);
		world.setBlock(i + 2, j + 3, k + 0, 0);
		world.setBlock(i + 2, j + 3, k + 1, 0);
		world.setBlock(i + 2, j + 3, k + 2, 0);
		world.setBlock(i + 2, j + 3, k + 3, 0);
		world.setBlock(i + 2, j + 3, k + 4, VetheaBlockHelper.hungerstone1.blockID);
		world.setBlock(i + 2, j + 3, k + 5, VetheaBlockHelper.hungerstone1.blockID);
		world.setBlock(i + 2, j + 3, k + 6, VetheaBlockHelper.hungerstone1.blockID);
		world.setBlock(i + 2, j + 3, k + 7, VetheaBlockHelper.hungerstone1.blockID);
		world.setBlock(i + 2, j + 3, k + 8, VetheaBlockHelper.hungerstone1.blockID);
		world.setBlock(i + 2, j + 3, k + 9, VetheaBlockHelper.hungerstone1.blockID);
		world.setBlock(i + 2, j + 3, k + 10, VetheaBlockHelper.hungerstone1.blockID);
		world.setBlock(i + 2, j + 3, k + 11, VetheaBlockHelper.hungerstone1.blockID);
		world.setBlock(i + 2, j + 3, k + 12, VetheaBlockHelper.hungerstone1.blockID);
		world.setBlock(i + 2, j + 3, k + 13, VetheaBlockHelper.hungerstone1.blockID);
		world.setBlock(i + 2, j + 3, k + 14, VetheaBlockHelper.hungerstone1.blockID);
		world.setBlock(i + 2, j + 3, k + 15, VetheaBlockHelper.hungerstone1.blockID);
		world.setBlock(i + 2, j + 3, k + 16, VetheaBlockHelper.hungerstone1.blockID);
		world.setBlock(i + 2, j + 3, k + 17, VetheaBlockHelper.hungerstone1.blockID);
		world.setBlock(i + 2, j + 3, k + 18, VetheaBlockHelper.hungerstone1.blockID);
		world.setBlock(i + 2, j + 3, k + 19, VetheaBlockHelper.hungerstone1.blockID);
		world.setBlock(i + 2, j + 3, k + 20, VetheaBlockHelper.hungerstone1.blockID);
		world.setBlock(i + 2, j + 3, k + 21, VetheaBlockHelper.hungerstone1.blockID);
		world.setBlock(i + 2, j + 3, k + 22, VetheaBlockHelper.hungerstone1.blockID);
		world.setBlock(i + 2, j + 3, k + 23, VetheaBlockHelper.hungerstone1.blockID);
		world.setBlock(i + 2, j + 3, k + 24, VetheaBlockHelper.hungerstone1.blockID);
		world.setBlock(i + 2, j + 3, k + 25, VetheaBlockHelper.hungerstone1.blockID);
		world.setBlock(i + 2, j + 3, k + 26, VetheaBlockHelper.hungerstone1.blockID);
		world.setBlock(i + 2, j + 3, k + 27, VetheaBlockHelper.hungerstone1.blockID);
		world.setBlock(i + 2, j + 3, k + 28, VetheaBlockHelper.hungerstone1.blockID);
		world.setBlock(i + 2, j + 3, k + 29, VetheaBlockHelper.hungerstone1.blockID);
		world.setBlock(i + 2, j + 3, k + 30, VetheaBlockHelper.hungerstone1.blockID);
		world.setBlock(i + 2, j + 3, k + 31, VetheaBlockHelper.hungerstone1.blockID);
		world.setBlock(i + 2, j + 3, k + 32, VetheaBlockHelper.hungerstone1.blockID);
		world.setBlock(i + 2, j + 3, k + 33, VetheaBlockHelper.hungerstone1.blockID);
		world.setBlock(i + 2, j + 3, k + 34, VetheaBlockHelper.hungerstone1.blockID);
		world.setBlock(i + 2, j + 3, k + 35, VetheaBlockHelper.hungerstone1.blockID);
		world.setBlock(i + 2, j + 3, k + 36, VetheaBlockHelper.hungerstone1.blockID);
		world.setBlock(i + 2, j + 3, k + 37, VetheaBlockHelper.hungerstone1.blockID);
		world.setBlock(i + 2, j + 3, k + 38, VetheaBlockHelper.hungerstone1.blockID);
		world.setBlock(i + 2, j + 3, k + 39, 0);
		world.setBlock(i + 2, j + 3, k + 40, 0);
		world.setBlock(i + 2, j + 4, k + 0, 0);
		world.setBlock(i + 2, j + 4, k + 1, 0);
		world.setBlock(i + 2, j + 4, k + 2, 0);
		world.setBlock(i + 2, j + 4, k + 3, 0);
		world.setBlock(i + 2, j + 4, k + 4, 0);
		world.setBlock(i + 2, j + 4, k + 5, 0);
		world.setBlock(i + 2, j + 4, k + 6, 0);
		world.setBlock(i + 2, j + 4, k + 7, 0);
		world.setBlock(i + 2, j + 4, k + 8, 0);
		world.setBlock(i + 2, j + 4, k + 9, 0);
		world.setBlock(i + 2, j + 4, k + 10, 0);
		world.setBlock(i + 2, j + 4, k + 11, 0);
		world.setBlock(i + 2, j + 4, k + 12, 0);
		world.setBlock(i + 2, j + 4, k + 13, 0);
		world.setBlock(i + 2, j + 4, k + 14, 0);
		world.setBlock(i + 2, j + 4, k + 15, 0);
		world.setBlock(i + 2, j + 4, k + 16, 0);
		world.setBlock(i + 2, j + 4, k + 17, 0);
		world.setBlock(i + 2, j + 4, k + 18, 0);
		world.setBlock(i + 2, j + 4, k + 19, 0);
		world.setBlock(i + 2, j + 4, k + 20, 0);
		world.setBlock(i + 2, j + 4, k + 21, 0);
		world.setBlock(i + 2, j + 4, k + 22, 0);
		world.setBlock(i + 2, j + 4, k + 23, 0);
		world.setBlock(i + 2, j + 4, k + 24, 0);
		world.setBlock(i + 2, j + 4, k + 25, 0);
		world.setBlock(i + 2, j + 4, k + 26, 0);
		world.setBlock(i + 2, j + 4, k + 27, 0);
		world.setBlock(i + 2, j + 4, k + 28, 0);
		world.setBlock(i + 2, j + 4, k + 29, 0);
		world.setBlock(i + 2, j + 4, k + 30, 0);
		world.setBlock(i + 2, j + 4, k + 31, 0);
		world.setBlock(i + 2, j + 4, k + 32, 0);
		world.setBlock(i + 2, j + 4, k + 33, 0);
		world.setBlock(i + 2, j + 4, k + 34, 0);
		world.setBlock(i + 2, j + 4, k + 35, 0);
		world.setBlock(i + 2, j + 4, k + 36, 0);
		world.setBlock(i + 2, j + 4, k + 37, 0);
		world.setBlock(i + 2, j + 4, k + 38, 0);
		world.setBlock(i + 2, j + 4, k + 39, 0);
		world.setBlock(i + 2, j + 4, k + 40, 0);
		world.setBlock(i + 2, j + 5, k + 0, 0);
		world.setBlock(i + 2, j + 5, k + 1, 0);
		world.setBlock(i + 2, j + 5, k + 2, 0);
		world.setBlock(i + 2, j + 5, k + 3, 0);
		world.setBlock(i + 2, j + 5, k + 4, 0);
		world.setBlock(i + 2, j + 5, k + 5, 0);
		world.setBlock(i + 2, j + 5, k + 6, 0);
		world.setBlock(i + 2, j + 5, k + 7, 0);
		world.setBlock(i + 2, j + 5, k + 8, 0);
		world.setBlock(i + 2, j + 5, k + 9, 0);
		world.setBlock(i + 2, j + 5, k + 10, 0);
		world.setBlock(i + 2, j + 5, k + 11, 0);
		world.setBlock(i + 2, j + 5, k + 12, 0);
		world.setBlock(i + 2, j + 5, k + 13, 0);
		world.setBlock(i + 2, j + 5, k + 14, 0);
		world.setBlock(i + 2, j + 5, k + 15, 0);
		world.setBlock(i + 2, j + 5, k + 16, 0);
		world.setBlock(i + 2, j + 5, k + 17, 0);
		world.setBlock(i + 2, j + 5, k + 18, 0);
		world.setBlock(i + 2, j + 5, k + 19, 0);
		world.setBlock(i + 2, j + 5, k + 20, 0);
		world.setBlock(i + 2, j + 5, k + 21, 0);
		world.setBlock(i + 2, j + 5, k + 22, 0);
		world.setBlock(i + 2, j + 5, k + 23, 0);
		world.setBlock(i + 2, j + 5, k + 24, 0);
		world.setBlock(i + 2, j + 5, k + 25, 0);
		world.setBlock(i + 2, j + 5, k + 26, 0);
		world.setBlock(i + 2, j + 5, k + 27, 0);
		world.setBlock(i + 2, j + 5, k + 28, 0);
		world.setBlock(i + 2, j + 5, k + 29, 0);
		world.setBlock(i + 2, j + 5, k + 30, 0);
		world.setBlock(i + 2, j + 5, k + 31, 0);
		world.setBlock(i + 2, j + 5, k + 32, 0);
		world.setBlock(i + 2, j + 5, k + 33, 0);
		world.setBlock(i + 2, j + 5, k + 34, 0);
		world.setBlock(i + 2, j + 5, k + 35, 0);
		world.setBlock(i + 2, j + 5, k + 36, 0);
		world.setBlock(i + 2, j + 5, k + 37, 0);
		world.setBlock(i + 2, j + 5, k + 38, 0);
		world.setBlock(i + 2, j + 5, k + 39, 0);
		world.setBlock(i + 2, j + 5, k + 40, 0);
		world.setBlock(i + 2, j + 6, k + 0, 0);
		world.setBlock(i + 2, j + 6, k + 1, 0);
		world.setBlock(i + 2, j + 6, k + 2, 0);
		world.setBlock(i + 2, j + 6, k + 3, 0);
		world.setBlock(i + 2, j + 6, k + 4, 0);
		world.setBlock(i + 2, j + 6, k + 5, 0);
		world.setBlock(i + 2, j + 6, k + 6, 0);
		world.setBlock(i + 2, j + 6, k + 7, 0);
		world.setBlock(i + 2, j + 6, k + 8, 0);
		world.setBlock(i + 2, j + 6, k + 9, 0);
		world.setBlock(i + 2, j + 6, k + 10, 0);
		world.setBlock(i + 2, j + 6, k + 11, 0);
		world.setBlock(i + 2, j + 6, k + 12, 0);
		world.setBlock(i + 2, j + 6, k + 13, 0);
		world.setBlock(i + 2, j + 6, k + 14, 0);
		world.setBlock(i + 2, j + 6, k + 15, 0);
		world.setBlock(i + 2, j + 6, k + 16, 0);
		world.setBlock(i + 2, j + 6, k + 17, 0);
		world.setBlock(i + 2, j + 6, k + 18, 0);
		world.setBlock(i + 2, j + 6, k + 19, 0);
		world.setBlock(i + 2, j + 6, k + 20, 0);
		world.setBlock(i + 2, j + 6, k + 21, 0);
		world.setBlock(i + 2, j + 6, k + 22, 0);
		world.setBlock(i + 2, j + 6, k + 23, 0);
		world.setBlock(i + 2, j + 6, k + 24, 0);
		world.setBlock(i + 2, j + 6, k + 25, 0);
		world.setBlock(i + 2, j + 6, k + 26, 0);
		world.setBlock(i + 2, j + 6, k + 27, 0);
		world.setBlock(i + 2, j + 6, k + 28, 0);
		world.setBlock(i + 2, j + 6, k + 29, 0);
		world.setBlock(i + 2, j + 6, k + 30, 0);
		world.setBlock(i + 2, j + 6, k + 31, 0);
		world.setBlock(i + 2, j + 6, k + 32, 0);
		world.setBlock(i + 2, j + 6, k + 33, 0);
		world.setBlock(i + 2, j + 6, k + 34, 0);
		world.setBlock(i + 2, j + 6, k + 35, 0);
		world.setBlock(i + 2, j + 6, k + 36, 0);
		world.setBlock(i + 2, j + 6, k + 37, 0);
		world.setBlock(i + 2, j + 6, k + 38, 0);
		world.setBlock(i + 2, j + 6, k + 39, 0);
		world.setBlock(i + 2, j + 6, k + 40, 0);
		world.setBlock(i + 2, j + 7, k + 0, 0);
		world.setBlock(i + 2, j + 7, k + 1, 0);
		world.setBlock(i + 2, j + 7, k + 2, 0);
		world.setBlock(i + 2, j + 7, k + 3, 0);
		world.setBlock(i + 2, j + 7, k + 4, 0);
		world.setBlock(i + 2, j + 7, k + 5, 0);
		world.setBlock(i + 2, j + 7, k + 6, 0);
		world.setBlock(i + 2, j + 7, k + 7, 0);
		world.setBlock(i + 2, j + 7, k + 8, 0);
		world.setBlock(i + 2, j + 7, k + 9, 0);
		world.setBlock(i + 2, j + 7, k + 10, 0);
		world.setBlock(i + 2, j + 7, k + 11, 0);
		world.setBlock(i + 2, j + 7, k + 12, 0);
		world.setBlock(i + 2, j + 7, k + 13, 0);
		world.setBlock(i + 2, j + 7, k + 14, 0);
		world.setBlock(i + 2, j + 7, k + 15, 0);
		world.setBlock(i + 2, j + 7, k + 16, 0);
		world.setBlock(i + 2, j + 7, k + 17, 0);
		world.setBlock(i + 2, j + 7, k + 18, 0);
		world.setBlock(i + 2, j + 7, k + 19, 0);
		world.setBlock(i + 2, j + 7, k + 20, 0);
		world.setBlock(i + 2, j + 7, k + 21, 0);
		world.setBlock(i + 2, j + 7, k + 22, 0);
		world.setBlock(i + 2, j + 7, k + 23, 0);
		world.setBlock(i + 2, j + 7, k + 24, 0);
		world.setBlock(i + 2, j + 7, k + 25, 0);
		world.setBlock(i + 2, j + 7, k + 26, 0);
		world.setBlock(i + 2, j + 7, k + 27, 0);
		world.setBlock(i + 2, j + 7, k + 28, 0);
		world.setBlock(i + 2, j + 7, k + 29, 0);
		world.setBlock(i + 2, j + 7, k + 30, 0);
		world.setBlock(i + 2, j + 7, k + 31, 0);
		world.setBlock(i + 2, j + 7, k + 32, 0);
		world.setBlock(i + 2, j + 7, k + 33, 0);
		world.setBlock(i + 2, j + 7, k + 34, 0);
		world.setBlock(i + 2, j + 7, k + 35, 0);
		world.setBlock(i + 2, j + 7, k + 36, 0);
		world.setBlock(i + 2, j + 7, k + 37, 0);
		world.setBlock(i + 2, j + 7, k + 38, 0);
		world.setBlock(i + 2, j + 7, k + 39, 0);
		world.setBlock(i + 2, j + 7, k + 40, 0);
		world.setBlock(i + 2, j + 8, k + 0, 0);
		world.setBlock(i + 2, j + 8, k + 1, 0);
		world.setBlock(i + 2, j + 8, k + 2, 0);
		world.setBlock(i + 2, j + 8, k + 3, 0);
		world.setBlock(i + 2, j + 8, k + 4, 0);
		world.setBlock(i + 2, j + 8, k + 5, 0);
		world.setBlock(i + 2, j + 8, k + 6, 0);
		world.setBlock(i + 2, j + 8, k + 7, 0);
		world.setBlock(i + 2, j + 8, k + 8, 0);
		world.setBlock(i + 2, j + 8, k + 9, 0);
		world.setBlock(i + 2, j + 8, k + 10, 0);
		world.setBlock(i + 2, j + 8, k + 11, 0);
		world.setBlock(i + 2, j + 8, k + 12, 0);
		world.setBlock(i + 2, j + 8, k + 13, 0);
		world.setBlock(i + 2, j + 8, k + 14, 0);
		world.setBlock(i + 2, j + 8, k + 15, 0);
		world.setBlock(i + 2, j + 8, k + 16, 0);
		world.setBlock(i + 2, j + 8, k + 17, 0);
		world.setBlock(i + 2, j + 8, k + 18, 0);
		world.setBlock(i + 2, j + 8, k + 19, 0);
		world.setBlock(i + 2, j + 8, k + 20, 0);
		world.setBlock(i + 2, j + 8, k + 21, 0);
		world.setBlock(i + 2, j + 8, k + 22, 0);
		world.setBlock(i + 2, j + 8, k + 23, 0);
		world.setBlock(i + 2, j + 8, k + 24, 0);
		world.setBlock(i + 2, j + 8, k + 25, 0);
		world.setBlock(i + 2, j + 8, k + 26, 0);
		world.setBlock(i + 2, j + 8, k + 27, 0);
		world.setBlock(i + 2, j + 8, k + 28, 0);
		world.setBlock(i + 2, j + 8, k + 29, 0);
		world.setBlock(i + 2, j + 8, k + 30, 0);
		world.setBlock(i + 2, j + 8, k + 31, 0);
		world.setBlock(i + 2, j + 8, k + 32, 0);
		world.setBlock(i + 2, j + 8, k + 33, 0);
		world.setBlock(i + 2, j + 8, k + 34, 0);
		world.setBlock(i + 2, j + 8, k + 35, 0);
		world.setBlock(i + 2, j + 8, k + 36, 0);
		world.setBlock(i + 2, j + 8, k + 37, 0);
		world.setBlock(i + 2, j + 8, k + 38, 0);
		world.setBlock(i + 2, j + 8, k + 39, 0);
		world.setBlock(i + 2, j + 8, k + 40, 0);
		world.setBlock(i + 2, j + 9, k + 0, 0);
		world.setBlock(i + 2, j + 9, k + 1, 0);
		world.setBlock(i + 2, j + 9, k + 2, 0);
		world.setBlock(i + 2, j + 9, k + 3, 0);
