/*
*** MADE BY MITHION'S .SCHEMATIC TO JAVA CONVERTING TOOL v1.6 ***
*/

package xolova.divinerpg.worldgen.arcana;
import java.util.Random;

import net.minecraft.world.World;
import net.minecraft.world.gen.feature.WorldGenerator;
import xolova.divinerpg.utils.helpers.block.ArcanaBlockHelper;

public class DungeonComponent20 extends WorldGenerator
{
    protected int[] GetValidSpawnBlocks()
    {
        return new int[]
                {
                    0
                };
    }

    public boolean LocationIsValidSpawn(World world, int i, int j, int k)
    {
        int blockID = world.getBlockId(i, j, k);

        for (int x : GetValidSpawnBlocks())
        {
            if (blockID == x)
            {
                return true;
            }
        }

        return false;
    }

    public DungeonComponent20() { }

    public boolean generate(World world, Random rand, int i, int j, int k)
    {
        //check that each corner is one of the valid spawn blocks
    	if (!LocationIsValidSpawn(world, i, j, k) || !LocationIsValidSpawn(world, i + 16, j, k + 16) || !LocationIsValidSpawn(world, i, j + 8, k) || !LocationIsValidSpawn(world, i + 16, j + 8, k + 16) || !LocationIsValidSpawn(world, i, j + 8, k) || !LocationIsValidSpawn(world, i + 15, j + 8, k + 15) || !LocationIsValidSpawn(world, i, j, k) || !LocationIsValidSpawn(world, i + 15, j, k + 15))
        {
            return false;
        }

        world.setBlock(i + 0, j + 0, k + 0, ArcanaBlockHelper.ancientBricks.blockID);
        world.setBlock(i + 0, j + 0, k + 1, ArcanaBlockHelper.ancientBricks.blockID);
        world.setBlock(i + 0, j + 0, k + 2, ArcanaBlockHelper.ancientBricks.blockID);
        world.setBlock(i + 0, j + 0, k + 3, ArcanaBlockHelper.ancientBricks.blockID);
        world.setBlock(i + 0, j + 0, k + 4, ArcanaBlockHelper.ancientBricks.blockID);
        world.setBlock(i + 0, j + 0, k + 5, ArcanaBlockHelper.ancientBricks.blockID);
        world.setBlock(i + 0, j + 0, k + 6, ArcanaBlockHelper.ancientBricks.blockID);
        world.setBlock(i + 0, j + 0, k + 7, ArcanaBlockHelper.ancientBricks.blockID);
        world.setBlock(i + 0, j + 0, k + 8, ArcanaBlockHelper.ancientBricks.blockID);
        world.setBlock(i + 0, j + 0, k + 9, ArcanaBlockHelper.ancientBricks.blockID);
        world.setBlock(i + 0, j + 0, k + 10, ArcanaBlockHelper.ancientBricks.blockID);
        world.setBlock(i + 0, j + 0, k + 11, ArcanaBlockHelper.ancientBricks.blockID);
        world.setBlock(i + 0, j + 0, k + 12, ArcanaBlockHelper.ancientBricks.blockID);
        world.setBlock(i + 0, j + 0, k + 13, ArcanaBlockHelper.ancientBricks.blockID);
        world.setBlock(i + 0, j + 0, k + 14, ArcanaBlockHelper.ancientBricks.blockID);
        world.setBlock(i + 0, j + 0, k + 15, ArcanaBlockHelper.ancientBricks.blockID);
        world.setBlock(i + 0, j + 0, k + 16, ArcanaBlockHelper.ancientBricks.blockID);
        world.setBlock(i + 0, j + 0, k + 17, ArcanaBlockHelper.ancientBricks.blockID);
        world.setBlock(i + 0, j + 0, k + 18, ArcanaBlockHelper.ancientBricks.blockID);
        world.setBlock(i + 0, j + 0, k + 19, ArcanaBlockHelper.ancientBricks.blockID);
        world.setBlock(i + 0, j + 0, k + 20, ArcanaBlockHelper.ancientBricks.blockID);
        world.setBlock(i + 0, j + 0, k + 21, ArcanaBlockHelper.ancientBricks.blockID);
        world.setBlock(i + 0, j + 0, k + 22, ArcanaBlockHelper.ancientBricks.blockID);
        world.setBlock(i + 0, j + 0, k + 23, ArcanaBlockHelper.ancientBricks.blockID);
        world.setBlock(i + 0, j + 0, k + 24, ArcanaBlockHelper.ancientBricks.blockID);
        world.setBlock(i + 0, j + 0, k + 25, ArcanaBlockHelper.ancientBricks.blockID);
        world.setBlock(i + 0, j + 0, k + 26, ArcanaBlockHelper.ancientBricks.blockID);
        world.setBlock(i + 0, j + 0, k + 27, ArcanaBlockHelper.ancientBricks.blockID);
        world.setBlock(i + 0, j + 0, k + 28, ArcanaBlockHelper.ancientBricks.blockID);
        world.setBlock(i + 0, j + 0, k + 29, ArcanaBlockHelper.ancientBricks.blockID);
        world.setBlock(i + 0, j + 0, k + 30, ArcanaBlockHelper.ancientBricks.blockID);
        world.setBlock(i + 0, j + 0, k + 31, ArcanaBlockHelper.ancientBricks.blockID);
        world.setBlock(i + 0, j + 1, k + 0, ArcanaBlockHelper.ancientBricks.blockID);
        world.setBlock(i + 0, j + 1, k + 1, ArcanaBlockHelper.ancientBricks.blockID);
        world.setBlock(i + 0, j + 1, k + 2, ArcanaBlockHelper.ancientBricks.blockID);
        world.setBlock(i + 0, j + 1, k + 3, ArcanaBlockHelper.ancientBricks.blockID);
        world.setBlock(i + 0, j + 1, k + 4, ArcanaBlockHelper.ancientBricks.blockID);
        world.setBlock(i + 0, j + 1, k + 5, ArcanaBlockHelper.ancientBricks.blockID);
        world.setBlock(i + 0, j + 1, k + 6, ArcanaBlockHelper.ancientBricks.blockID);
        world.setBlock(i + 0, j + 1, k + 7, ArcanaBlockHelper.ancientBricks.blockID);
        world.setBlock(i + 0, j + 1, k + 8, ArcanaBlockHelper.ancientBricks.blockID);
        world.setBlock(i + 0, j + 1, k + 9, ArcanaBlockHelper.ancientBricks.blockID);
        world.setBlock(i + 0, j + 1, k + 10, ArcanaBlockHelper.ancientBricks.blockID);
        world.setBlock(i + 0, j + 1, k + 11, ArcanaBlockHelper.ancientBricks.blockID);
        world.setBlock(i + 0, j + 1, k + 12, ArcanaBlockHelper.ancientBricks.blockID);
        world.setBlock(i + 0, j + 1, k + 13, ArcanaBlockHelper.ancientBricks.blockID);
        world.setBlock(i + 0, j + 1, k + 14, ArcanaBlockHelper.ancientBricks.blockID);
        world.setBlock(i + 0, j + 1, k + 15, ArcanaBlockHelper.ancientBricks.blockID);
        world.setBlock(i + 0, j + 1, k + 16, ArcanaBlockHelper.ancientBricks.blockID);
        world.setBlock(i + 0, j + 1, k + 17, ArcanaBlockHelper.ancientBricks.blockID);
        world.setBlock(i + 0, j + 1, k + 18, ArcanaBlockHelper.ancientBricks.blockID);
        world.setBlock(i + 0, j + 1, k + 19, ArcanaBlockHelper.ancientBricks.blockID);
        world.setBlock(i + 0, j + 1, k + 20, ArcanaBlockHelper.ancientBricks.blockID);
        world.setBlock(i + 0, j + 1, k + 21, ArcanaBlockHelper.ancientBricks.blockID);
        world.setBlock(i + 0, j + 1, k + 22, ArcanaBlockHelper.arcaniteMetal.blockID);
        world.setBlock(i + 0, j + 1, k + 25, ArcanaBlockHelper.arcaniteMetal.blockID);
        world.setBlock(i + 0, j + 1, k + 26, ArcanaBlockHelper.ancientBricks.blockID);
        world.setBlock(i + 0, j + 1, k + 27, ArcanaBlockHelper.ancientBricks.blockID);
        world.setBlock(i + 0, j + 1, k + 28, ArcanaBlockHelper.ancientBricks.blockID);
        world.setBlock(i + 0, j + 1, k + 29, ArcanaBlockHelper.ancientBricks.blockID);
        world.setBlock(i + 0, j + 1, k + 30, ArcanaBlockHelper.ancientBricks.blockID);
        world.setBlock(i + 0, j + 1, k + 31, ArcanaBlockHelper.ancientBricks.blockID);
        world.setBlock(i + 0, j + 2, k + 0, ArcanaBlockHelper.ancientBricks.blockID);
        world.setBlock(i + 0, j + 2, k + 1, ArcanaBlockHelper.ancientBricks.blockID);
        world.setBlock(i + 0, j + 2, k + 2, ArcanaBlockHelper.ancientBricks.blockID);
        world.setBlock(i + 0, j + 2, k + 3, ArcanaBlockHelper.ancientBricks.blockID);
        world.setBlock(i + 0, j + 2, k + 4, ArcanaBlockHelper.ancientBricks.blockID);
        world.setBlock(i + 0, j + 2, k + 5, ArcanaBlockHelper.ancientBricks.blockID);
        world.setBlock(i + 0, j + 2, k + 6, ArcanaBlockHelper.ancientBricks.blockID);
        world.setBlock(i + 0, j + 2, k + 7, ArcanaBlockHelper.ancientBricks.blockID);
        world.setBlock(i + 0, j + 2, k + 8, ArcanaBlockHelper.ancientBricks.blockID);
        world.setBlock(i + 0, j + 2, k + 9, ArcanaBlockHelper.ancientBricks.blockID);
        world.setBlock(i + 0, j + 2, k + 10, ArcanaBlockHelper.ancientBricks.blockID);
        world.setBlock(i + 0, j + 2, k + 11, ArcanaBlockHelper.ancientBricks.blockID);
        world.setBlock(i + 0, j + 2, k + 12, ArcanaBlockHelper.ancientBricks.blockID);
        world.setBlock(i + 0, j + 2, k + 13, ArcanaBlockHelper.ancientBricks.blockID);
        world.setBlock(i + 0, j + 2, k + 14, ArcanaBlockHelper.ancientBricks.blockID);
        world.setBlock(i + 0, j + 2, k + 15, ArcanaBlockHelper.ancientBricks.blockID);
        world.setBlock(i + 0, j + 2, k + 16, ArcanaBlockHelper.ancientBricks.blockID);
        world.setBlock(i + 0, j + 2, k + 17, ArcanaBlockHelper.ancientBricks.blockID);
        world.setBlock(i + 0, j + 2, k + 18, ArcanaBlockHelper.ancientBricks.blockID);
        world.setBlock(i + 0, j + 2, k + 19, ArcanaBlockHelper.ancientBricks.blockID);
        world.setBlock(i + 0, j + 2, k + 20, ArcanaBlockHelper.ancientBricks.blockID);
        world.setBlock(i + 0, j + 2, k + 21, ArcanaBlockHelper.ancientBricks.blockID);
        world.setBlock(i + 0, j + 2, k + 22, ArcanaBlockHelper.arcaniteMetal.blockID);
        world.setBlock(i + 0, j + 2, k + 25, ArcanaBlockHelper.arcaniteMetal.blockID);
        world.setBlock(i + 0, j + 2, k + 26, ArcanaBlockHelper.ancientBricks.blockID);
        world.setBlock(i + 0, j + 2, k + 27, ArcanaBlockHelper.ancientBricks.blockID);
        world.setBlock(i + 0, j + 2, k + 28, ArcanaBlockHelper.ancientBricks.blockID);
        world.setBlock(i + 0, j + 2, k + 29, ArcanaBlockHelper.ancientBricks.blockID);
        world.setBlock(i + 0, j + 2, k + 30, ArcanaBlockHelper.ancientBricks.blockID);
        world.setBlock(i + 0, j + 2, k + 31, ArcanaBlockHelper.ancientBricks.blockID);
        world.setBlock(i + 0, j + 3, k + 0, ArcanaBlockHelper.ancientBricks.blockID);
        world.setBlock(i + 0, j + 3, k + 1, ArcanaBlockHelper.ancientBricks.blockID);
        world.setBlock(i + 0, j + 3, k + 2, ArcanaBlockHelper.ancientBricks.blockID);
        world.setBlock(i + 0, j + 3, k + 3, ArcanaBlockHelper.ancientBricks.blockID);
        world.setBlock(i + 0, j + 3, k + 4, ArcanaBlockHelper.ancientBricks.blockID);
        world.setBlock(i + 0, j + 3, k + 5, ArcanaBlockHelper.ancientBricks.blockID);
        world.setBlock(i + 0, j + 3, k + 6, ArcanaBlockHelper.ancientBricks.blockID);
        world.setBlock(i + 0, j + 3, k + 7, ArcanaBlockHelper.ancientBricks.blockID);
        world.setBlock(i + 0, j + 3, k + 8, ArcanaBlockHelper.ancientBricks.blockID);
        world.setBlock(i + 0, j + 3, k + 9, ArcanaBlockHelper.ancientBricks.blockID);
        world.setBlock(i + 0, j + 3, k + 10, ArcanaBlockHelper.ancientBricks.blockID);
        world.setBlock(i + 0, j + 3, k + 11, ArcanaBlockHelper.ancientBricks.blockID);
        world.setBlock(i + 0, j + 3, k + 12, ArcanaBlockHelper.ancientBricks.blockID);
        world.setBlock(i + 0, j + 3, k + 13, ArcanaBlockHelper.ancientBricks.blockID);
        world.setBlock(i + 0, j + 3, k + 14, ArcanaBlockHelper.ancientBricks.blockID);
        world.setBlock(i + 0, j + 3, k + 15, ArcanaBlockHelper.ancientBricks.blockID);
        world.setBlock(i + 0, j + 3, k + 16, ArcanaBlockHelper.ancientBricks.blockID);
        world.setBlock(i + 0, j + 3, k + 17, ArcanaBlockHelper.ancientBricks.blockID);
        world.setBlock(i + 0, j + 3, k + 18, ArcanaBlockHelper.ancientBricks.blockID);
        world.setBlock(i + 0, j + 3, k + 19, ArcanaBlockHelper.ancientBricks.blockID);
        world.setBlock(i + 0, j + 3, k + 20, ArcanaBlockHelper.ancientBricks.blockID);
        world.setBlock(i + 0, j + 3, k + 21, ArcanaBlockHelper.ancientBricks.blockID);
        world.setBlock(i + 0, j + 3, k + 22, ArcanaBlockHelper.arcaniteMetal.blockID);
        world.setBlock(i + 0, j + 3, k + 23, ArcanaBlockHelper.arcaniumPower.blockID);
        world.setBlock(i + 0, j + 3, k + 24, ArcanaBlockHelper.arcaniumPower.blockID);
        world.setBlock(i + 0, j + 3, k + 25, ArcanaBlockHelper.arcaniteMetal.blockID);
        world.setBlock(i + 0, j + 3, k + 26, ArcanaBlockHelper.ancientBricks.blockID);
        world.setBlock(i + 0, j + 3, k + 27, ArcanaBlockHelper.ancientBricks.blockID);
        world.setBlock(i + 0, j + 3, k + 28, ArcanaBlockHelper.ancientBricks.blockID);
        world.setBlock(i + 0, j + 3, k + 29, ArcanaBlockHelper.ancientBricks.blockID);
        world.setBlock(i + 0, j + 3, k + 30, ArcanaBlockHelper.ancientBricks.blockID);
        world.setBlock(i + 0, j + 3, k + 31, ArcanaBlockHelper.ancientBricks.blockID);
        world.setBlock(i + 0, j + 4, k + 0, ArcanaBlockHelper.ancientBricks.blockID);
        world.setBlock(i + 0, j + 4, k + 1, ArcanaBlockHelper.ancientBricks.blockID);
        world.setBlock(i + 0, j + 4, k + 2, ArcanaBlockHelper.ancientBricks.blockID);
        world.setBlock(i + 0, j + 4, k + 3, ArcanaBlockHelper.ancientBricks.blockID);
        world.setBlock(i + 0, j + 4, k + 4, ArcanaBlockHelper.ancientBricks.blockID);
        world.setBlock(i + 0, j + 4, k + 5, ArcanaBlockHelper.ancientBricks.blockID);
        world.setBlock(i + 0, j + 4, k + 6, ArcanaBlockHelper.ancientBricks.blockID);
        world.setBlock(i + 0, j + 4, k + 7, ArcanaBlockHelper.ancientBricks.blockID);
        world.setBlock(i + 0, j + 4, k + 8, ArcanaBlockHelper.ancientBricks.blockID);
        world.setBlock(i + 0, j + 4, k + 9, ArcanaBlockHelper.ancientBricks.blockID);
        world.setBlock(i + 0, j + 4, k + 10, ArcanaBlockHelper.ancientBricks.blockID);
        world.setBlock(i + 0, j + 4, k + 11, ArcanaBlockHelper.ancientBricks.blockID);
        world.setBlock(i + 0, j + 4, k + 12, ArcanaBlockHelper.ancientBricks.blockID);
        world.setBlock(i + 0, j + 4, k + 13, ArcanaBlockHelper.ancientBricks.blockID);
        world.setBlock(i + 0, j + 4, k + 14, ArcanaBlockHelper.ancientBricks.blockID);
        world.setBlock(i + 0, j + 4, k + 15, ArcanaBlockHelper.ancientBricks.blockID);
        world.setBlock(i + 0, j + 4, k + 16, ArcanaBlockHelper.ancientBricks.blockID);
        world.setBlock(i + 0, j + 4, k + 17, ArcanaBlockHelper.ancientBricks.blockID);
        world.setBlock(i + 0, j + 4, k + 18, ArcanaBlockHelper.ancientBricks.blockID);
        world.setBlock(i + 0, j + 4, k + 19, ArcanaBlockHelper.ancientBricks.blockID);
        world.setBlock(i + 0, j + 4, k + 20, ArcanaBlockHelper.ancientBricks.blockID);
        world.setBlock(i + 0, j + 4, k + 21, ArcanaBlockHelper.ancientBricks.blockID);
        world.setBlock(i + 0, j + 4, k + 22, ArcanaBlockHelper.ancientBricks.blockID);
        world.setBlock(i + 0, j + 4, k + 23, ArcanaBlockHelper.ancientBricks.blockID);
        world.setBlock(i + 0, j + 4, k + 24, ArcanaBlockHelper.ancientBricks.blockID);
        world.setBlock(i + 0, j + 4, k + 25, ArcanaBlockHelper.ancientBricks.blockID);
        world.setBlock(i + 0, j + 4, k + 26, ArcanaBlockHelper.ancientBricks.blockID);
        world.setBlock(i + 0, j + 4, k + 27, ArcanaBlockHelper.ancientBricks.blockID);
        world.setBlock(i + 0, j + 4, k + 28, ArcanaBlockHelper.ancientBricks.blockID);
        world.setBlock(i + 0, j + 4, k + 29, ArcanaBlockHelper.ancientBricks.blockID);
        world.setBlock(i + 0, j + 4, k + 30, ArcanaBlockHelper.ancientBricks.blockID);
        world.setBlock(i + 0, j + 4, k + 31, ArcanaBlockHelper.ancientBricks.blockID);
        world.setBlock(i + 0, j + 5, k + 0, ArcanaBlockHelper.ancientBricks.blockID);
        world.setBlock(i + 0, j + 5, k + 1, ArcanaBlockHelper.ancientBricks.blockID);
        world.setBlock(i + 0, j + 5, k + 2, ArcanaBlockHelper.ancientBricks.blockID);
        world.setBlock(i + 0, j + 5, k + 3, ArcanaBlockHelper.ancientBricks.blockID);
        world.setBlock(i + 0, j + 5, k + 4, ArcanaBlockHelper.ancientBricks.blockID);
        world.setBlock(i + 0, j + 5, k + 5, ArcanaBlockHelper.ancientBricks.blockID);
        world.setBlock(i + 0, j + 5, k + 6, ArcanaBlockHelper.ancientBricks.blockID);
        world.setBlock(i + 0, j + 5, k + 7, ArcanaBlockHelper.ancientBricks.blockID);
        world.setBlock(i + 0, j + 5, k + 8, ArcanaBlockHelper.ancientBricks.blockID);
        world.setBlock(i + 0, j + 5, k + 9, ArcanaBlockHelper.ancientBricks.blockID);
        world.setBlock(i + 0, j + 5, k + 10, ArcanaBlockHelper.ancientBricks.blockID);
        world.setBlock(i + 0, j + 5, k + 11, ArcanaBlockHelper.ancientBricks.blockID);
        world.setBlock(i + 0, j + 5, k + 12, ArcanaBlockHelper.ancientBricks.blockID);
        world.setBlock(i + 0, j + 5, k + 13, ArcanaBlockHelper.ancientBricks.blockID);
        world.setBlock(i + 0, j + 5, k + 14, ArcanaBlockHelper.ancientBricks.blockID);
        world.setBlock(i + 0, j + 5, k + 15, ArcanaBlockHelper.ancientBricks.blockID);
        world.setBlock(i + 0, j + 5, k + 16, ArcanaBlockHelper.ancientBricks.blockID);
        world.setBlock(i + 0, j + 5, k + 17, ArcanaBlockHelper.ancientBricks.blockID);
        world.setBlock(i + 0, j + 5, k + 18, ArcanaBlockHelper.ancientBricks.blockID);
        world.setBlock(i + 0, j + 5, k + 19, ArcanaBlockHelper.ancientBricks.blockID);
        world.setBlock(i + 0, j + 5, k + 20, ArcanaBlockHelper.ancientBricks.blockID);
        world.setBlock(i + 0, j + 5, k + 21, ArcanaBlockHelper.ancientBricks.blockID);
        world.setBlock(i + 0, j + 5, k + 22, ArcanaBlockHelper.ancientBricks.blockID);
        world.setBlock(i + 0, j + 5, k + 23, ArcanaBlockHelper.ancientBricks.blockID);
        world.setBlock(i + 0, j + 5, k + 24, ArcanaBlockHelper.ancientBricks.blockID);
        world.setBlock(i + 0, j + 5, k + 25, ArcanaBlockHelper.ancientBricks.blockID);
        world.setBlock(i + 0, j + 5, k + 26, ArcanaBlockHelper.ancientBricks.blockID);
        world.setBlock(i + 0, j + 5, k + 27, ArcanaBlockHelper.ancientBricks.blockID);
        world.setBlock(i + 0, j + 5, k + 28, ArcanaBlockHelper.ancientBricks.blockID);
        world.setBlock(i + 0, j + 5, k + 29, ArcanaBlockHelper.ancientBricks.blockID);
        world.setBlock(i + 0, j + 5, k + 30, ArcanaBlockHelper.ancientBricks.blockID);
        world.setBlock(i + 0, j + 5, k + 31, ArcanaBlockHelper.ancientBricks.blockID);
        world.setBlock(i + 0, j + 6, k + 0, ArcanaBlockHelper.ancientBricks.blockID);
        world.setBlock(i + 0, j + 6, k + 1, ArcanaBlockHelper.ancientBricks.blockID);
        world.setBlock(i + 0, j + 6, k + 2, ArcanaBlockHelper.ancientBricks.blockID);
        world.setBlock(i + 0, j + 6, k + 3, ArcanaBlockHelper.ancientBricks.blockID);
        world.setBlock(i + 0, j + 6, k + 4, ArcanaBlockHelper.ancientBricks.blockID);
        world.setBlock(i + 0, j + 6, k + 5, ArcanaBlockHelper.ancientBricks.blockID);
        world.setBlock(i + 0, j + 6, k + 6, ArcanaBlockHelper.ancientBricks.blockID);
        world.setBlock(i + 0, j + 6, k + 7, ArcanaBlockHelper.ancientBricks.blockID);
        world.setBlock(i + 0, j + 6, k + 8, ArcanaBlockHelper.ancientBricks.blockID);
        world.setBlock(i + 0, j + 6, k + 9, ArcanaBlockHelper.ancientBricks.blockID);
        world.setBlock(i + 0, j + 6, k + 10, ArcanaBlockHelper.ancientBricks.blockID);
        world.setBlock(i + 0, j + 6, k + 11, ArcanaBlockHelper.ancientBricks.blockID);
        world.setBlock(i + 0, j + 6, k + 12, ArcanaBlockHelper.ancientBricks.blockID);
        world.setBlock(i + 0, j + 6, k + 13, ArcanaBlockHelper.ancientBricks.blockID);
        world.setBlock(i + 0, j + 6, k + 14, ArcanaBlockHelper.ancientBricks.blockID);
        world.setBlock(i + 0, j + 6, k + 15, ArcanaBlockHelper.ancientBricks.blockID);
        world.setBlock(i + 0, j + 6, k + 16, ArcanaBlockHelper.ancientBricks.blockID);
        world.setBlock(i + 0, j + 6, k + 17, ArcanaBlockHelper.ancientBricks.blockID);
        world.setBlock(i + 0, j + 6, k + 18, ArcanaBlockHelper.ancientBricks.blockID);
        world.setBlock(i + 0, j + 6, k + 19, ArcanaBlockHelper.ancientBricks.blockID);
        world.setBlock(i + 0, j + 6, k + 20, ArcanaBlockHelper.ancientBricks.blockID);
        world.setBlock(i + 0, j + 6, k + 21, ArcanaBlockHelper.ancientBricks.blockID);
        world.setBlock(i + 0, j + 6, k + 22, ArcanaBlockHelper.ancientBricks.blockID);
        world.setBlock(i + 0, j + 6, k + 23, ArcanaBlockHelper.ancientBricks.blockID);
        world.setBlock(i + 0, j + 6, k + 24, ArcanaBlockHelper.ancientBricks.blockID);
        world.setBlock(i + 0, j + 6, k + 25, ArcanaBlockHelper.ancientBricks.blockID);
        world.setBlock(i + 0, j + 6, k + 26, ArcanaBlockHelper.ancientBricks.blockID);
        world.setBlock(i + 0, j + 6, k + 27, ArcanaBlockHelper.ancientBricks.blockID);
        world.setBlock(i + 0, j + 6, k + 28, ArcanaBlockHelper.ancientBricks.blockID);
        world.setBlock(i + 0, j + 6, k + 29, ArcanaBlockHelper.ancientBricks.blockID);
        world.setBlock(i + 0, j + 6, k + 30, ArcanaBlockHelper.ancientBricks.blockID);
        world.setBlock(i + 0, j + 6, k + 31, ArcanaBlockHelper.ancientBricks.blockID);
        world.setBlock(i + 0, j + 7, k + 0, ArcanaBlockHelper.ancientBricks.blockID);
        world.setBlock(i + 0, j + 7, k + 1, ArcanaBlockHelper.ancientBricks.blockID);
        world.setBlock(i + 0, j + 7, k + 2, ArcanaBlockHelper.ancientBricks.blockID);
        world.setBlock(i + 0, j + 7, k + 3, ArcanaBlockHelper.ancientBricks.blockID);
        world.setBlock(i + 0, j + 7, k + 4, ArcanaBlockHelper.ancientBricks.blockID);
        world.setBlock(i + 0, j + 7, k + 5, ArcanaBlockHelper.ancientBricks.blockID);
        world.setBlock(i + 0, j + 7, k + 6, ArcanaBlockHelper.ancientBricks.blockID);
        world.setBlock(i + 0, j + 7, k + 7, ArcanaBlockHelper.ancientBricks.blockID);
        world.setBlock(i + 0, j + 7, k + 8, ArcanaBlockHelper.ancientBricks.blockID);
        world.setBlock(i + 0, j + 7, k + 9, ArcanaBlockHelper.ancientBricks.blockID);
        world.setBlock(i + 0, j + 7, k + 10, ArcanaBlockHelper.ancientBricks.blockID);
        world.setBlock(i + 0, j + 7, k + 11, ArcanaBlockHelper.ancientBricks.blockID);
        world.setBlock(i + 0, j + 7, k + 12, ArcanaBlockHelper.ancientBricks.blockID);
        world.setBlock(i + 0, j + 7, k + 13, ArcanaBlockHelper.ancientBricks.blockID);
        world.setBlock(i + 0, j + 7, k + 14, ArcanaBlockHelper.ancientBricks.blockID);
        world.setBlock(i + 0, j + 7, k + 15, ArcanaBlockHelper.ancientBricks.blockID);
        world.setBlock(i + 0, j + 7, k + 16, ArcanaBlockHelper.ancientBricks.blockID);
        world.setBlock(i + 0, j + 7, k + 17, ArcanaBlockHelper.ancientBricks.blockID);
        world.setBlock(i + 0, j + 7, k + 18, ArcanaBlockHelper.ancientBricks.blockID);
        world.setBlock(i + 0, j + 7, k + 19, ArcanaBlockHelper.ancientBricks.blockID);
        world.setBlock(i + 0, j + 7, k + 20, ArcanaBlockHelper.ancientBricks.blockID);
        world.setBlock(i + 0, j + 7, k + 21, ArcanaBlockHelper.ancientBricks.blockID);
        world.setBlock(i + 0, j + 7, k + 22, ArcanaBlockHelper.ancientBricks.blockID);
        world.setBlock(i + 0, j + 7, k + 23, ArcanaBlockHelper.ancientBricks.blockID);
        world.setBlock(i + 0, j + 7, k + 24, ArcanaBlockHelper.ancientBricks.blockID);
        world.setBlock(i + 0, j + 7, k + 25, ArcanaBlockHelper.ancientBricks.blockID);
        world.setBlock(i + 0, j + 7, k + 26, ArcanaBlockHelper.ancientBricks.blockID);
        world.setBlock(i + 0, j + 7, k + 27, ArcanaBlockHelper.ancientBricks.blockID);
        world.setBlock(i + 0, j + 7, k + 28, ArcanaBlockHelper.ancientBricks.blockID);
        world.setBlock(i + 0, j + 7, k + 29, ArcanaBlockHelper.ancientBricks.blockID);
        world.setBlock(i + 0, j + 7, k + 30, ArcanaBlockHelper.ancientBricks.blockID);
        world.setBlock(i + 0, j + 7, k + 31, ArcanaBlockHelper.ancientBricks.blockID);
        world.setBlock(i + 0, j + 8, k + 0, ArcanaBlockHelper.degradedBricks.blockID);
        world.setBlock(i + 0, j + 8, k + 1, ArcanaBlockHelper.degradedBricks.blockID);
        world.setBlock(i + 0, j + 8, k + 2, ArcanaBlockHelper.degradedBricks.blockID);
        world.setBlock(i + 0, j + 8, k + 3, ArcanaBlockHelper.degradedBricks.blockID);
        world.setBlock(i + 0, j + 8, k + 4, ArcanaBlockHelper.degradedBricks.blockID);
        world.setBlock(i + 0, j + 8, k + 5, ArcanaBlockHelper.degradedBricks.blockID);
        world.setBlock(i + 0, j + 8, k + 6, ArcanaBlockHelper.degradedBricks.blockID);
        world.setBlock(i + 0, j + 8, k + 7, ArcanaBlockHelper.degradedBricks.blockID);
        world.setBlock(i + 0, j + 8, k + 8, ArcanaBlockHelper.degradedBricks.blockID);
        world.setBlock(i + 0, j + 8, k + 9, ArcanaBlockHelper.degradedBricks.blockID);
        world.setBlock(i + 0, j + 8, k + 10, ArcanaBlockHelper.degradedBricks.blockID);
        world.setBlock(i + 0, j + 8, k + 11, ArcanaBlockHelper.degradedBricks.blockID);
        world.setBlock(i + 0, j + 8, k + 12, ArcanaBlockHelper.degradedBricks.blockID);
        world.setBlock(i + 0, j + 8, k + 13, ArcanaBlockHelper.degradedBricks.blockID);
        world.setBlock(i + 0, j + 8, k + 14, ArcanaBlockHelper.degradedBricks.blockID);
        world.setBlock(i + 0, j + 8, k + 15, ArcanaBlockHelper.degradedBricks.blockID);
        world.setBlock(i + 0, j + 8, k + 16, ArcanaBlockHelper.degradedBricks.blockID);
        world.setBlock(i + 0, j + 8, k + 17, ArcanaBlockHelper.degradedBricks.blockID);
        world.setBlock(i + 0, j + 8, k + 18, ArcanaBlockHelper.degradedBricks.blockID);
        world.setBlock(i + 0, j + 8, k + 19, ArcanaBlockHelper.degradedBricks.blockID);
        world.setBlock(i + 0, j + 8, k + 20, ArcanaBlockHelper.degradedBricks.blockID);
        world.setBlock(i + 0, j + 8, k + 21, ArcanaBlockHelper.degradedBricks.blockID);
        world.setBlock(i + 0, j + 8, k + 22, ArcanaBlockHelper.degradedBricks.blockID);
        world.setBlock(i + 0, j + 8, k + 23, ArcanaBlockHelper.degradedBricks.blockID);
        world.setBlock(i + 0, j + 8, k + 24, ArcanaBlockHelper.degradedBricks.blockID);
        world.setBlock(i + 0, j + 8, k + 25, ArcanaBlockHelper.degradedBricks.blockID);
        world.setBlock(i + 0, j + 8, k + 26, ArcanaBlockHelper.degradedBricks.blockID);
        world.setBlock(i + 0, j + 8, k + 27, ArcanaBlockHelper.degradedBricks.blockID);
        world.setBlock(i + 0, j + 8, k + 28, ArcanaBlockHelper.degradedBricks.blockID);
        world.setBlock(i + 0, j + 8, k + 29, ArcanaBlockHelper.degradedBricks.blockID);
        world.setBlock(i + 0, j + 8, k + 30, ArcanaBlockHelper.degradedBricks.blockID);
        world.setBlock(i + 0, j + 8, k + 31, ArcanaBlockHelper.degradedBricks.blockID);
        world.setBlock(i + 0, j + 9, k + 0, ArcanaBlockHelper.ancientBricks.blockID);
        world.setBlock(i + 0, j + 9, k + 1, ArcanaBlockHelper.ancientBricks.blockID);
        world.setBlock(i + 0, j + 9, k + 2, ArcanaBlockHelper.degradedBricks.blockID);
        world.setBlock(i + 0, j + 9, k + 3, ArcanaBlockHelper.ancientBricks.blockID);
        world.setBlock(i + 0, j + 9, k + 4, ArcanaBlockHelper.ancientBricks.blockID);
        world.setBlock(i + 0, j + 9, k + 5, ArcanaBlockHelper.ancientBricks.blockID);
        world.setBlock(i + 0, j + 9, k + 6, ArcanaBlockHelper.ancientBricks.blockID);
        world.setBlock(i + 0, j + 9, k + 7, ArcanaBlockHelper.ancientBricks.blockID);
        world.setBlock(i + 0, j + 9, k + 8, ArcanaBlockHelper.ancientBricks.blockID);
        world.setBlock(i + 0, j + 9, k + 9, ArcanaBlockHelper.ancientBricks.blockID);
        world.setBlock(i + 0, j + 9, k + 10, ArcanaBlockHelper.ancientBricks.blockID);
        world.setBlock(i + 0, j + 9, k + 11, ArcanaBlockHelper.ancientBricks.blockID);
        world.setBlock(i + 0, j + 9, k + 12, ArcanaBlockHelper.ancientBricks.blockID);
        world.setBlock(i + 0, j + 9, k + 13, ArcanaBlockHelper.ancientBricks.blockID);
        world.setBlock(i + 0, j + 9, k + 14, ArcanaBlockHelper.ancientBricks.blockID);
        world.setBlock(i + 0, j + 9, k + 15, ArcanaBlockHelper.ancientBricks.blockID);
        world.setBlock(i + 0, j + 9, k + 16, ArcanaBlockHelper.ancientBricks.blockID);
        world.setBlock(i + 0, j + 9, k + 17, ArcanaBlockHelper.ancientBricks.blockID);
        world.setBlock(i + 0, j + 9, k + 18, ArcanaBlockHelper.ancientBricks.blockID);
        world.setBlock(i + 0, j + 9, k + 19, ArcanaBlockHelper.ancientBricks.blockID);
        world.setBlock(i + 0, j + 9, k + 20, ArcanaBlockHelper.ancientBricks.blockID);
        world.setBlock(i + 0, j + 9, k + 21, ArcanaBlockHelper.ancientBricks.blockID);
        world.setBlock(i + 0, j + 9, k + 22, ArcanaBlockHelper.arcaniteMetal.blockID);
        world.setBlock(i + 0, j + 9, k + 25, ArcanaBlockHelper.arcaniteMetal.blockID);
        world.setBlock(i + 0, j + 9, k + 26, ArcanaBlockHelper.ancientBricks.blockID);
        world.setBlock(i + 0, j + 9, k + 27, ArcanaBlockHelper.ancientBricks.blockID);
        world.setBlock(i + 0, j + 9, k + 28, ArcanaBlockHelper.ancientBricks.blockID);
        world.setBlock(i + 0, j + 9, k + 29, ArcanaBlockHelper.degradedBricks.blockID);
        world.setBlock(i + 0, j + 9, k + 30, ArcanaBlockHelper.ancientBricks.blockID);
        world.setBlock(i + 0, j + 9, k + 31, ArcanaBlockHelper.ancientBricks.blockID);
        world.setBlock(i + 0, j + 10, k + 0, ArcanaBlockHelper.ancientBricks.blockID);
        world.setBlock(i + 0, j + 10, k + 1, ArcanaBlockHelper.ancientBricks.blockID);
        world.setBlock(i + 0, j + 10, k + 2, ArcanaBlockHelper.degradedBricks.blockID);
        world.setBlock(i + 0, j + 10, k + 3, ArcanaBlockHelper.degradedBricks.blockID);
        world.setBlock(i + 0, j + 10, k + 4, ArcanaBlockHelper.ancientBricks.blockID);
        world.setBlock(i + 0, j + 10, k + 5, ArcanaBlockHelper.ancientBricks.blockID);
        world.setBlock(i + 0, j + 10, k + 6, ArcanaBlockHelper.ancientBricks.blockID);
        world.setBlock(i + 0, j + 10, k + 7, ArcanaBlockHelper.ancientBricks.blockID);
        world.setBlock(i + 0, j + 10, k + 8, ArcanaBlockHelper.ancientBricks.blockID);
        world.setBlock(i + 0, j + 10, k + 9, ArcanaBlockHelper.ancientBricks.blockID);
        world.setBlock(i + 0, j + 10, k + 10, ArcanaBlockHelper.ancientBricks.blockID);
        world.setBlock(i + 0, j + 10, k + 11, ArcanaBlockHelper.ancientBricks.blockID);
        world.setBlock(i + 0, j + 10, k + 12, ArcanaBlockHelper.ancientBricks.blockID);
        world.setBlock(i + 0, j + 10, k + 13, ArcanaBlockHelper.ancientBricks.blockID);
        world.setBlock(i + 0, j + 10, k + 14, ArcanaBlockHelper.ancientBricks.blockID);
        world.setBlock(i + 0, j + 10, k + 15, ArcanaBlockHelper.ancientBricks.blockID);
        world.setBlock(i + 0, j + 10, k + 16, ArcanaBlockHelper.ancientBricks.blockID);
        world.setBlock(i + 0, j + 10, k + 17, ArcanaBlockHelper.ancientBricks.blockID);
        world.setBlock(i + 0, j + 10, k + 18, ArcanaBlockHelper.ancientBricks.blockID);
        world.setBlock(i + 0, j + 10, k + 19, ArcanaBlockHelper.ancientBricks.blockID);
        world.setBlock(i + 0, j + 10, k + 20, ArcanaBlockHelper.ancientBricks.blockID);
        world.setBlock(i + 0, j + 10, k + 21, ArcanaBlockHelper.ancientBricks.blockID);
        world.setBlock(i + 0, j + 10, k + 22, ArcanaBlockHelper.arcaniteMetal.blockID);
        world.setBlock(i + 0, j + 10, k + 25, ArcanaBlockHelper.arcaniteMetal.blockID);
        world.setBlock(i + 0, j + 10, k + 26, ArcanaBlockHelper.ancientBricks.blockID);
        world.setBlock(i + 0, j + 10, k + 27, ArcanaBlockHelper.ancientBricks.blockID);
        world.setBlock(i + 0, j + 10, k + 28, ArcanaBlockHelper.degradedBricks.blockID);
        world.setBlock(i + 0, j + 10, k + 29, ArcanaBlockHelper.degradedBricks.blockID);
        world.setBlock(i + 0, j + 10, k + 30, ArcanaBlockHelper.ancientBricks.blockID);
        world.setBlock(i + 0, j + 10, k + 31, ArcanaBlockHelper.ancientBricks.blockID);
        world.setBlock(i + 0, j + 11, k + 0, ArcanaBlockHelper.ancientBricks.blockID);
        world.setBlock(i + 0, j + 11, k + 1, ArcanaBlockHelper.ancientBricks.blockID);
        world.setBlock(i + 0, j + 11, k + 2, ArcanaBlockHelper.ancientBricks.blockID);
        world.setBlock(i + 0, j + 11, k + 3, ArcanaBlockHelper.degradedBricks.blockID);
        world.setBlock(i + 0, j + 11, k + 4, ArcanaBlockHelper.ancientBricks.blockID);
        world.setBlock(i + 0, j + 11, k + 5, ArcanaBlockHelper.ancientBricks.blockID);
        world.setBlock(i + 0, j + 11, k + 6, ArcanaBlockHelper.ancientBricks.blockID);
        world.setBlock(i + 0, j + 11, k + 7, ArcanaBlockHelper.ancientBricks.blockID);
        world.setBlock(i + 0, j + 11, k + 8, ArcanaBlockHelper.ancientBricks.blockID);
        world.setBlock(i + 0, j + 11, k + 9, ArcanaBlockHelper.ancientBricks.blockID);
        world.setBlock(i + 0, j + 11, k + 10, ArcanaBlockHelper.ancientBricks.blockID);
        world.setBlock(i + 0, j + 11, k + 11, ArcanaBlockHelper.ancientBricks.blockID);
        world.setBlock(i + 0, j + 11, k + 12, ArcanaBlockHelper.ancientBricks.blockID);
        world.setBlock(i + 0, j + 11, k + 13, ArcanaBlockHelper.ancientBricks.blockID);
        world.setBlock(i + 0, j + 11, k + 14, ArcanaBlockHelper.ancientBricks.blockID);
        world.setBlock(i + 0, j + 11, k + 15, ArcanaBlockHelper.ancientBricks.blockID);
        world.setBlock(i + 0, j + 11, k + 16, ArcanaBlockHelper.ancientBricks.blockID);
        world.setBlock(i + 0, j + 11, k + 17, ArcanaBlockHelper.ancientBricks.blockID);
        world.setBlock(i + 0, j + 11, k + 18, ArcanaBlockHelper.ancientBricks.blockID);
        world.setBlock(i + 0, j + 11, k + 19, ArcanaBlockHelper.ancientBricks.blockID);
        world.setBlock(i + 0, j + 11, k + 20, ArcanaBlockHelper.ancientBricks.blockID);
        world.setBlock(i + 0, j + 11, k + 21, ArcanaBlockHelper.ancientBricks.blockID);
        world.setBlock(i + 0, j + 11, k + 22, ArcanaBlockHelper.arcaniteMetal.blockID);
        world.setBlock(i + 0, j + 11, k + 23, ArcanaBlockHelper.arcaniumPower.blockID);
        world.setBlock(i + 0, j + 11, k + 24, ArcanaBlockHelper.arcaniumPower.blockID);
        world.setBlock(i + 0, j + 11, k + 25, ArcanaBlockHelper.arcaniteMetal.blockID);
        world.setBlock(i + 0, j + 11, k + 26, ArcanaBlockHelper.ancientBricks.blockID);
        world.setBlock(i + 0, j + 11, k + 27, ArcanaBlockHelper.ancientBricks.blockID);
        world.setBlock(i + 0, j + 11, k + 28, ArcanaBlockHelper.degradedBricks.blockID);
        world.setBlock(i + 0, j + 11, k + 29, ArcanaBlockHelper.ancientBricks.blockID);
        world.setBlock(i + 0, j + 11, k + 30, ArcanaBlockHelper.ancientBricks.blockID);
        world.setBlock(i + 0, j + 11, k + 31, ArcanaBlockHelper.ancientBricks.blockID);
        world.setBlock(i + 0, j + 12, k + 0, ArcanaBlockHelper.ancientBricks.blockID);
        world.setBlock(i + 0, j + 12, k + 1, ArcanaBlockHelper.ancientBricks.blockID);
        world.setBlock(i + 0, j + 12, k + 2, ArcanaBlockHelper.ancientBricks.blockID);
        world.setBlock(i + 0, j + 12, k + 3, ArcanaBlockHelper.degradedBricks.blockID);
        world.setBlock(i + 0, j + 12, k + 4, ArcanaBlockHelper.degradedBricks.blockID);
        world.setBlock(i + 0, j + 12, k + 5, ArcanaBlockHelper.ancientBricks.blockID);
        world.setBlock(i + 0, j + 12, k + 6, ArcanaBlockHelper.ancientBricks.blockID);
        world.setBlock(i + 0, j + 12, k + 7, ArcanaBlockHelper.ancientBricks.blockID);
        world.setBlock(i + 0, j + 12, k + 8, ArcanaBlockHelper.ancientBricks.blockID);
        world.setBlock(i + 0, j + 12, k + 9, ArcanaBlockHelper.ancientBricks.blockID);
        world.setBlock(i + 0, j + 12, k + 10, ArcanaBlockHelper.ancientBricks.blockID);
        world.setBlock(i + 0, j + 12, k + 11, ArcanaBlockHelper.ancientBricks.blockID);
        world.setBlock(i + 0, j + 12, k + 12, ArcanaBlockHelper.ancientBricks.blockID);
        world.setBlock(i + 0, j + 12, k + 13, ArcanaBlockHelper.ancientBricks.blockID);
        world.setBlock(i + 0, j + 12, k + 14, ArcanaBlockHelper.ancientBricks.blockID);
        world.setBlock(i + 0, j + 12, k + 15, ArcanaBlockHelper.ancientBricks.blockID);
        world.setBlock(i + 0, j + 12, k + 16, ArcanaBlockHelper.ancientBricks.blockID);
        world.setBlock(i + 0, j + 12, k + 17, ArcanaBlockHelper.ancientBricks.blockID);
        world.setBlock(i + 0, j + 12, k + 18, ArcanaBlockHelper.ancientBricks.blockID);
        world.setBlock(i + 0, j + 12, k + 19, ArcanaBlockHelper.ancientBricks.blockID);
        world.setBlock(i + 0, j + 12, k + 20, ArcanaBlockHelper.ancientBricks.blockID);
        world.setBlock(i + 0, j + 12, k + 21, ArcanaBlockHelper.ancientBricks.blockID);
        world.setBlock(i + 0, j + 12, k + 22, ArcanaBlockHelper.ancientBricks.blockID);
        world.setBlock(i + 0, j + 12, k + 23, ArcanaBlockHelper.ancientBricks.blockID);
        world.setBlock(i + 0, j + 12, k + 24, ArcanaBlockHelper.ancientBricks.blockID);
        world.setBlock(i + 0, j + 12, k + 25, ArcanaBlockHelper.ancientBricks.blockID);
        world.setBlock(i + 0, j + 12, k + 26, ArcanaBlockHelper.ancientBricks.blockID);
        world.setBlock(i + 0, j + 12, k + 27, ArcanaBlockHelper.degradedBricks.blockID);
        world.setBlock(i + 0, j + 12, k + 28, ArcanaBlockHelper.degradedBricks.blockID);
        world.setBlock(i + 0, j + 12, k + 29, ArcanaBlockHelper.ancientBricks.blockID);
        world.setBlock(i + 0, j + 12, k + 30, ArcanaBlockHelper.ancientBricks.blockID);
        world.setBlock(i + 0, j + 12, k + 31, ArcanaBlockHelper.ancientBricks.blockID);
        world.setBlock(i + 0, j + 13, k + 0, ArcanaBlockHelper.ancientBricks.blockID);
        world.setBlock(i + 0, j + 13, k + 1, ArcanaBlockHelper.ancientBricks.blockID);
        world.setBlock(i + 0, j + 13, k + 2, ArcanaBlockHelper.ancientBricks.blockID);
        world.setBlock(i + 0, j + 13, k + 3, ArcanaBlockHelper.ancientBricks.blockID);
        world.setBlock(i + 0, j + 13, k + 4, ArcanaBlockHelper.degradedBricks.blockID);
        world.setBlock(i + 0, j + 13, k + 5, ArcanaBlockHelper.ancientBricks.blockID);
        world.setBlock(i + 0, j + 13, k + 6, ArcanaBlockHelper.ancientBricks.blockID);
        world.setBlock(i + 0, j + 13, k + 7, ArcanaBlockHelper.ancientBricks.blockID);
        world.setBlock(i + 0, j + 13, k + 8, ArcanaBlockHelper.ancientBricks.blockID);
        world.setBlock(i + 0, j + 13, k + 9, ArcanaBlockHelper.ancientBricks.blockID);
        world.setBlock(i + 0, j + 13, k + 10, ArcanaBlockHelper.ancientBricks.blockID);
        world.setBlock(i + 0, j + 13, k + 11, ArcanaBlockHelper.ancientBricks.blockID);
        world.setBlock(i + 0, j + 13, k + 12, ArcanaBlockHelper.ancientBricks.blockID);
        world.setBlock(i + 0, j + 13, k + 13, ArcanaBlockHelper.ancientBricks.blockID);
        world.setBlock(i + 0, j + 13, k + 14, ArcanaBlockHelper.ancientBricks.blockID);
        world.setBlock(i + 0, j + 13, k + 15, ArcanaBlockHelper.ancientBricks.blockID);
        world.setBlock(i + 0, j + 13, k + 16, ArcanaBlockHelper.ancientBricks.blockID);
        world.setBlock(i + 0, j + 13, k + 17, ArcanaBlockHelper.ancientBricks.blockID);
        world.setBlock(i + 0, j + 13, k + 18, ArcanaBlockHelper.ancientBricks.blockID);
        world.setBlock(i + 0, j + 13, k + 19, ArcanaBlockHelper.ancientBricks.blockID);
        world.setBlock(i + 0, j + 13, k + 20, ArcanaBlockHelper.ancientBricks.blockID);
        world.setBlock(i + 0, j + 13, k + 21, ArcanaBlockHelper.ancientBricks.blockID);
        world.setBlock(i + 0, j + 13, k + 22, ArcanaBlockHelper.ancientBricks.blockID);
        world.setBlock(i + 0, j + 13, k + 23, ArcanaBlockHelper.ancientBricks.blockID);
        world.setBlock(i + 0, j + 13, k + 24, ArcanaBlockHelper.ancientBricks.blockID);
        world.setBlock(i + 0, j + 13, k + 25, ArcanaBlockHelper.ancientBricks.blockID);
        world.setBlock(i + 0, j + 13, k + 26, ArcanaBlockHelper.ancientBricks.blockID);
        world.setBlock(i + 0, j + 13, k + 27, ArcanaBlockHelper.degradedBricks.blockID);
        world.setBlock(i + 0, j + 13, k + 28, ArcanaBlockHelper.ancientBricks.blockID);
        world.setBlock(i + 0, j + 13, k + 29, ArcanaBlockHelper.ancientBricks.blockID);
        world.setBlock(i + 0, j + 13, k + 30, ArcanaBlockHelper.ancientBricks.blockID);
        world.setBlock(i + 0, j + 13, k + 31, ArcanaBlockHelper.ancientBricks.blockID);
        world.setBlock(i + 0, j + 14, k + 0, ArcanaBlockHelper.ancientBricks.blockID);
        world.setBlock(i + 0, j + 14, k + 1, ArcanaBlockHelper.ancientBricks.blockID);
        world.setBlock(i + 0, j + 14, k + 2, ArcanaBlockHelper.ancientBricks.blockID);
        world.setBlock(i + 0, j + 14, k + 3, ArcanaBlockHelper.ancientBricks.blockID);
        world.setBlock(i + 0, j + 14, k + 4, ArcanaBlockHelper.degradedBricks.blockID);
        world.setBlock(i + 0, j + 14, k + 5, ArcanaBlockHelper.degradedBricks.blockID);
        world.setBlock(i + 0, j + 14, k + 6, ArcanaBlockHelper.ancientBricks.blockID);
        world.setBlock(i + 0, j + 14, k + 7, ArcanaBlockHelper.ancientBricks.blockID);
        world.setBlock(i + 0, j + 14, k + 8, ArcanaBlockHelper.degradedBricks.blockID);
        world.setBlock(i + 0, j + 14, k + 9, ArcanaBlockHelper.degradedBricks.blockID);
        world.setBlock(i + 0, j + 14, k + 10, ArcanaBlockHelper.degradedBricks.blockID);
        world.setBlock(i + 0, j + 14, k + 11, ArcanaBlockHelper.degradedBricks.blockID);
        world.setBlock(i + 0, j + 14, k + 12, ArcanaBlockHelper.degradedBricks.blockID);
        world.setBlock(i + 0, j + 14, k + 13, ArcanaBlockHelper.degradedBricks.blockID);
        world.setBlock(i + 0, j + 14, k + 14, ArcanaBlockHelper.degradedBricks.blockID);
        world.setBlock(i + 0, j + 14, k + 15, ArcanaBlockHelper.degradedBricks.blockID);
        world.setBlock(i + 0, j + 14, k + 16, ArcanaBlockHelper.degradedBricks.blockID);
        world.setBlock(i + 0, j + 14, k + 17, ArcanaBlockHelper.degradedBricks.blockID);
        world.setBlock(i + 0, j + 14, k + 18, ArcanaBlockHelper.degradedBricks.blockID);
        world.setBlock(i + 0, j + 14, k + 19, ArcanaBlockHelper.degradedBricks.blockID);
        world.setBlock(i + 0, j + 14, k + 20, ArcanaBlockHelper.degradedBricks.blockID);
        world.setBlock(i + 0, j + 14, k + 21, ArcanaBlockHelper.degradedBricks.blockID);
        world.setBlock(i + 0, j + 14, k + 22, ArcanaBlockHelper.degradedBricks.blockID);
        world.setBlock(i + 0, j + 14, k + 23, ArcanaBlockHelper.degradedBricks.blockID);
        world.setBlock(i + 0, j + 14, k + 24, ArcanaBlockHelper.ancientBricks.blockID);
        world.setBlock(i + 0, j + 14, k + 25, ArcanaBlockHelper.ancientBricks.blockID);
        world.setBlock(i + 0, j + 14, k + 26, ArcanaBlockHelper.degradedBricks.blockID);
        world.setBlock(i + 0, j + 14, k + 27, ArcanaBlockHelper.degradedBricks.blockID);
        world.setBlock(i + 0, j + 14, k + 28, ArcanaBlockHelper.ancientBricks.blockID);
        world.setBlock(i + 0, j + 14, k + 29, ArcanaBlockHelper.ancientBricks.blockID);
        world.setBlock(i + 0, j + 14, k + 30, ArcanaBlockHelper.ancientBricks.blockID);
        world.setBlock(i + 0, j + 14, k + 31, ArcanaBlockHelper.ancientBricks.blockID);
        world.setBlock(i + 0, j + 15, k + 0, ArcanaBlockHelper.ancientBricks.blockID);
        world.setBlock(i + 0, j + 15, k + 1, ArcanaBlockHelper.ancientBricks.blockID);
        world.setBlock(i + 0, j + 15, k + 2, ArcanaBlockHelper.ancientBricks.blockID);
        world.setBlock(i + 0, j + 15, k + 3, ArcanaBlockHelper.ancientBricks.blockID);
        world.setBlock(i + 0, j + 15, k + 4, ArcanaBlockHelper.ancientBricks.blockID);
        world.setBlock(i + 0, j + 15, k + 5, ArcanaBlockHelper.dungeonLamp.blockID);
        world.setBlock(i + 0, j + 15, k + 6, ArcanaBlockHelper.ancientBricks.blockID);
        world.setBlock(i + 0, j + 15, k + 7, ArcanaBlockHelper.ancientBricks.blockID);
        world.setBlock(i + 0, j + 15, k + 8, ArcanaBlockHelper.degradedBricks.blockID);
        world.setBlock(i + 0, j + 15, k + 9, ArcanaBlockHelper.ancientBricks.blockID);
        world.setBlock(i + 0, j + 15, k + 10, ArcanaBlockHelper.ancientBricks.blockID);
        world.setBlock(i + 0, j + 15, k + 11, ArcanaBlockHelper.ancientBricks.blockID);
        world.setBlock(i + 0, j + 15, k + 12, ArcanaBlockHelper.ancientBricks.blockID);
        world.setBlock(i + 0, j + 15, k + 13, ArcanaBlockHelper.ancientBricks.blockID);
        world.setBlock(i + 0, j + 15, k + 14, ArcanaBlockHelper.ancientBricks.blockID);
        world.setBlock(i + 0, j + 15, k + 15, ArcanaBlockHelper.ancientBricks.blockID);
        world.setBlock(i + 0, j + 15, k + 16, ArcanaBlockHelper.ancientBricks.blockID);
        world.setBlock(i + 0, j + 15, k + 17, ArcanaBlockHelper.ancientBricks.blockID);
        world.setBlock(i + 0, j + 15, k + 18, ArcanaBlockHelper.ancientBricks.blockID);
        world.setBlock(i + 0, j + 15, k + 19, ArcanaBlockHelper.ancientBricks.blockID);
        world.setBlock(i + 0, j + 15, k + 20, ArcanaBlockHelper.ancientBricks.blockID);
        world.setBlock(i + 0, j + 15, k + 21, ArcanaBlockHelper.ancientBricks.blockID);
        world.setBlock(i + 0, j + 15, k + 22, ArcanaBlockHelper.ancientBricks.blockID);
        world.setBlock(i + 0, j + 15, k + 23, ArcanaBlockHelper.degradedBricks.blockID);
        world.setBlock(i + 0, j + 15, k + 24, ArcanaBlockHelper.ancientBricks.blockID);
        world.setBlock(i + 0, j + 15, k + 25, ArcanaBlockHelper.ancientBricks.blockID);
        world.setBlock(i + 0, j + 15, k + 26, ArcanaBlockHelper.dungeonLamp.blockID);
        world.setBlock(i + 0, j + 15, k + 27, ArcanaBlockHelper.ancientBricks.blockID);
        world.setBlock(i + 0, j + 15, k + 28, ArcanaBlockHelper.ancientBricks.blockID);
        world.setBlock(i + 0, j + 15, k + 29, ArcanaBlockHelper.ancientBricks.blockID);
        world.setBlock(i + 0, j + 15, k + 30, ArcanaBlockHelper.ancientBricks.blockID);
        world.setBlock(i + 0, j + 15, k + 31, ArcanaBlockHelper.ancientBricks.blockID);
        world.setBlock(i + 1, j + 0, k + 0, ArcanaBlockHelper.ancientBricks.blockID);
        world.setBlock(i + 1, j + 0, k + 1, ArcanaBlockHelper.ancientBricks.blockID);
        world.setBlock(i + 1, j + 0, k + 2, ArcanaBlockHelper.ancientBricks.blockID);
        world.setBlock(i + 1, j + 0, k + 3, ArcanaBlockHelper.ancientBricks.blockID);
        world.setBlock(i + 1, j + 0, k + 4, ArcanaBlockHelper.ancientBricks.blockID);
        world.setBlock(i + 1, j + 0, k + 5, ArcanaBlockHelper.ancientBricks.blockID);
        world.setBlock(i + 1, j + 0, k + 6, ArcanaBlockHelper.ancientBricks.blockID);
        world.setBlock(i + 1, j + 0, k + 7, ArcanaBlockHelper.ancientBricks.blockID);
        world.setBlock(i + 1, j + 0, k + 8, ArcanaBlockHelper.ancientBricks.blockID);
        world.setBlock(i + 1, j + 0, k + 9, ArcanaBlockHelper.ancientBricks.blockID);
        world.setBlock(i + 1, j + 0, k + 10, ArcanaBlockHelper.ancientBricks.blockID);
        world.setBlock(i + 1, j + 0, k + 11, ArcanaBlockHelper.ancientBricks.blockID);
        world.setBlock(i + 1, j + 0, k + 12, ArcanaBlockHelper.ancientBricks.blockID);
        world.setBlock(i + 1, j + 0, k + 13, ArcanaBlockHelper.ancientBricks.blockID);
        world.setBlock(i + 1, j + 0, k + 14, ArcanaBlockHelper.ancientBricks.blockID);
        world.setBlock(i + 1, j + 0, k + 15, ArcanaBlockHelper.ancientBricks.blockID);
        world.setBlock(i + 1, j + 0, k + 16, ArcanaBlockHelper.ancientBricks.blockID);
        world.setBlock(i + 1, j + 0, k + 17, ArcanaBlockHelper.ancientBricks.blockID);
        world.setBlock(i + 1, j + 0, k + 18, ArcanaBlockHelper.ancientBricks.blockID);
        world.setBlock(i + 1, j + 0, k + 19, ArcanaBlockHelper.ancientBricks.blockID);
        world.setBlock(i + 1, j + 0, k + 20, ArcanaBlockHelper.ancientBricks.blockID);
        world.setBlock(i + 1, j + 0, k + 21, ArcanaBlockHelper.ancientBricks.blockID);
        world.setBlock(i + 1, j + 0, k + 22, ArcanaBlockHelper.ancientBricks.blockID);
        world.setBlock(i + 1, j + 0, k + 23, ArcanaBlockHelper.ancientBricks.blockID);
        world.setBlock(i + 1, j + 0, k + 24, ArcanaBlockHelper.ancientBricks.blockID);
        world.setBlock(i + 1, j + 0, k + 25, ArcanaBlockHelper.ancientBricks.blockID);
        world.setBlock(i + 1, j + 0, k + 26, ArcanaBlockHelper.ancientBricks.blockID);
        world.setBlock(i + 1, j + 0, k + 27, ArcanaBlockHelper.ancientBricks.blockID);
        world.setBlock(i + 1, j + 0, k + 28, ArcanaBlockHelper.ancientBricks.blockID);
        world.setBlock(i + 1, j + 0, k + 29, ArcanaBlockHelper.ancientBricks.blockID);
        world.setBlock(i + 1, j + 0, k + 30, ArcanaBlockHelper.ancientBricks.blockID);
        world.setBlock(i + 1, j + 0, k + 31, ArcanaBlockHelper.ancientBricks.blockID);
        world.setBlock(i + 1, j + 1, k + 0, ArcanaBlockHelper.ancientBricks.blockID);
        world.setBlock(i + 1, j + 1, k + 31, ArcanaBlockHelper.ancientBricks.blockID);
        world.setBlock(i + 1, j + 2, k + 0, ArcanaBlockHelper.ancientBricks.blockID);
        world.setBlock(i + 1, j + 2, k + 31, ArcanaBlockHelper.ancientBricks.blockID);
        world.setBlock(i + 1, j + 3, k + 0, ArcanaBlockHelper.ancientBricks.blockID);
        world.setBlock(i + 1, j + 3, k + 31, ArcanaBlockHelper.ancientBricks.blockID);
        world.setBlock(i + 1, j + 4, k + 0, ArcanaBlockHelper.ancientBricks.blockID);
        world.setBlock(i + 1, j + 4, k + 31, ArcanaBlockHelper.ancientBricks.blockID);
        world.setBlock(i + 1, j + 5, k + 0, ArcanaBlockHelper.ancientBricks.blockID);
        world.setBlock(i + 1, j + 5, k + 31, ArcanaBlockHelper.ancientBricks.blockID);
        world.setBlock(i + 1, j + 6, k + 0, ArcanaBlockHelper.ancientBricks.blockID);
        world.setBlock(i + 1, j + 6, k + 16, ArcanaBlockHelper.ancientBricks.blockID);
        world.setBlock(i + 1, j + 6, k + 17, ArcanaBlockHelper.degradedBricks.blockID);
        world.setBlock(i + 1, j + 6, k + 18, ArcanaBlockHelper.degradedBricks.blockID);
        world.setBlock(i + 1, j + 6, k + 19, ArcanaBlockHelper.ancientBricks.blockID);
        world.setBlock(i + 1, j + 6, k + 31, ArcanaBlockHelper.ancientBricks.blockID);
        world.setBlock(i + 1, j + 7, k + 0, ArcanaBlockHelper.ancientBricks.blockID);
        world.setBlock(i + 1, j + 7, k + 31, ArcanaBlockHelper.ancientBricks.blockID);
        world.setBlock(i + 1, j + 8, k + 0, ArcanaBlockHelper.degradedBricks.blockID);
        world.setBlock(i + 1, j + 8, k + 22, ArcanaBlockHelper.ancientBricks.blockID);
        world.setBlock(i + 1, j + 8, k + 23, ArcanaBlockHelper.degradedBricks.blockID);
        world.setBlock(i + 1, j + 8, k + 24, ArcanaBlockHelper.degradedBricks.blockID);
        world.setBlock(i + 1, j + 8, k + 25, ArcanaBlockHelper.ancientBricks.blockID);
        world.setBlock(i + 1, j + 8, k + 31, ArcanaBlockHelper.degradedBricks.blockID);
        world.setBlock(i + 1, j + 9, k + 0, ArcanaBlockHelper.ancientBricks.blockID);
        world.setBlock(i + 1, j + 9, k + 31, ArcanaBlockHelper.ancientBricks.blockID);
        world.setBlock(i + 1, j + 10, k + 0, ArcanaBlockHelper.ancientBricks.blockID);
        world.setBlock(i + 1, j + 10, k + 31, ArcanaBlockHelper.ancientBricks.blockID);
        world.setBlock(i + 1, j + 11, k + 0, ArcanaBlockHelper.ancientBricks.blockID);
        world.setBlock(i + 1, j + 11, k + 31, ArcanaBlockHelper.ancientBricks.blockID);
        world.setBlock(i + 1, j + 12, k + 0, ArcanaBlockHelper.ancientBricks.blockID);
        world.setBlock(i + 1, j + 12, k + 31, ArcanaBlockHelper.ancientBricks.blockID);
        world.setBlock(i + 1, j + 13, k + 0, ArcanaBlockHelper.ancientBricks.blockID);
        world.setBlock(i + 1, j + 13, k + 31, ArcanaBlockHelper.ancientBricks.blockID);
        world.setBlock(i + 1, j + 14, k + 0, ArcanaBlockHelper.ancientBricks.blockID);
        world.setBlock(i + 1, j + 14, k + 31, ArcanaBlockHelper.ancientBricks.blockID);
        world.setBlock(i + 1, j + 15, k + 0, ArcanaBlockHelper.ancientBricks.blockID);
        world.setBlock(i + 1, j + 15, k + 31, ArcanaBlockHelper.ancientBricks.blockID);
        world.setBlock(i + 2, j + 0, k + 0, ArcanaBlockHelper.ancientBricks.blockID);
        world.setBlock(i + 2, j + 0, k + 1, ArcanaBlockHelper.ancientBricks.blockID);
        world.setBlock(i + 2, j + 0, k + 2, ArcanaBlockHelper.ancientBricks.blockID);
        world.setBlock(i + 2, j + 0, k + 3, ArcanaBlockHelper.ancientBricks.blockID);
        world.setBlock(i + 2, j + 0, k + 4, ArcanaBlockHelper.ancientBricks.blockID);
        world.setBlock(i + 2, j + 0, k + 5, ArcanaBlockHelper.ancientBricks.blockID);
        world.setBlock(i + 2, j + 0, k + 6, ArcanaBlockHelper.ancientBricks.blockID);
        world.setBlock(i + 2, j + 0, k + 7, ArcanaBlockHelper.ancientBricks.blockID);
        world.setBlock(i + 2, j + 0, k + 8, ArcanaBlockHelper.ancientBricks.blockID);
        world.setBlock(i + 2, j + 0, k + 9, ArcanaBlockHelper.ancientBricks.blockID);
        world.setBlock(i + 2, j + 0, k + 10, ArcanaBlockHelper.ancientBricks.blockID);
        world.setBlock(i + 2, j + 0, k + 11, ArcanaBlockHelper.ancientBricks.blockID);
        world.setBlock(i + 2, j + 0, k + 12, ArcanaBlockHelper.ancientBricks.blockID);
        world.setBlock(i + 2, j + 0, k + 13, ArcanaBlockHelper.ancientBricks.blockID);
        world.setBlock(i + 2, j + 0, k + 14, ArcanaBlockHelper.ancientBricks.blockID);
        world.setBlock(i + 2, j + 0, k + 15, ArcanaBlockHelper.ancientBricks.blockID);
        world.setBlock(i + 2, j + 0, k + 16, ArcanaBlockHelper.ancientBricks.blockID);
        world.setBlock(i + 2, j + 0, k + 17, ArcanaBlockHelper.ancientBricks.blockID);
        world.setBlock(i + 2, j + 0, k + 18, ArcanaBlockHelper.ancientBricks.blockID);
        world.setBlock(i + 2, j + 0, k + 19, ArcanaBlockHelper.ancientBricks.blockID);
        world.setBlock(i + 2, j + 0, k + 20, ArcanaBlockHelper.ancientBricks.blockID);
        world.setBlock(i + 2, j + 0, k + 21, ArcanaBlockHelper.ancientBricks.blockID);
        world.setBlock(i + 2, j + 0, k + 22, ArcanaBlockHelper.ancientBricks.blockID);
        world.setBlock(i + 2, j + 0, k + 23, ArcanaBlockHelper.ancientBricks.blockID);
        world.setBlock(i + 2, j + 0, k + 24, ArcanaBlockHelper.ancientBricks.blockID);
        world.setBlock(i + 2, j + 0, k + 25, ArcanaBlockHelper.ancientBricks.blockID);
        world.setBlock(i + 2, j + 0, k + 26, ArcanaBlockHelper.ancientBricks.blockID);
        world.setBlock(i + 2, j + 0, k + 27, ArcanaBlockHelper.ancientBricks.blockID);
        world.setBlock(i + 2, j + 0, k + 28, ArcanaBlockHelper.ancientBricks.blockID);
        world.setBlock(i + 2, j + 0, k + 29, ArcanaBlockHelper.ancientBricks.blockID);
        world.setBlock(i + 2, j + 0, k + 30, ArcanaBlockHelper.ancientBricks.blockID);
        world.setBlock(i + 2, j + 0, k + 31, ArcanaBlockHelper.ancientBricks.blockID);
        world.setBlock(i + 2, j + 1, k + 0, ArcanaBlockHelper.ancientBricks.blockID);
        world.setBlock(i + 2, j + 1, k + 31, ArcanaBlockHelper.ancientBricks.blockID);
        world.setBlock(i + 2, j + 2, k + 0, ArcanaBlockHelper.ancientBricks.blockID);
        world.setBlock(i + 2, j + 2, k + 31, ArcanaBlockHelper.ancientBricks.blockID);
        world.setBlock(i + 2, j + 3, k + 0, ArcanaBlockHelper.ancientBricks.blockID);
        world.setBlock(i + 2, j + 3, k + 31, ArcanaBlockHelper.ancientBricks.blockID);
        world.setBlock(i + 2, j + 4, k + 0, ArcanaBlockHelper.ancientBricks.blockID);
        world.setBlock(i + 2, j + 4, k + 31, ArcanaBlockHelper.ancientBricks.blockID);
        world.setBlock(i + 2, j + 5, k + 0, ArcanaBlockHelper.ancientBricks.blockID);
        world.setBlock(i + 2, j + 5, k + 31, ArcanaBlockHelper.ancientBricks.blockID);
        world.setBlock(i + 2, j + 6, k + 0, ArcanaBlockHelper.ancientBricks.blockID);
        world.setBlock(i + 2, j + 6, k + 16, ArcanaBlockHelper.ancientBricks.blockID);
        world.setBlock(i + 2, j + 6, k + 17, ArcanaBlockHelper.degradedBricks.blockID);
        world.setBlock(i + 2, j + 6, k + 18, ArcanaBlockHelper.degradedBricks.blockID);
        world.setBlock(i + 2, j + 6, k + 19, ArcanaBlockHelper.ancientBricks.blockID);
        world.setBlock(i + 2, j + 6, k + 31, ArcanaBlockHelper.ancientBricks.blockID);
        world.setBlock(i + 2, j + 7, k + 0, ArcanaBlockHelper.ancientBricks.blockID);
        world.setBlock(i + 2, j + 7, k + 31, ArcanaBlockHelper.ancientBricks.blockID);
        world.setBlock(i + 2, j + 8, k + 0, ArcanaBlockHelper.degradedBricks.blockID);
        world.setBlock(i + 2, j + 8, k + 22, ArcanaBlockHelper.ancientBricks.blockID);
        world.setBlock(i + 2, j + 8, k + 23, ArcanaBlockHelper.degradedBricks.blockID);
        world.setBlock(i + 2, j + 8, k + 24, ArcanaBlockHelper.degradedBricks.blockID);
        world.setBlock(i + 2, j + 8, k + 25, ArcanaBlockHelper.ancientBricks.blockID);
        world.setBlock(i + 2, j + 8, k + 31, ArcanaBlockHelper.degradedBricks.blockID);
        world.setBlock(i + 2, j + 9, k + 0, ArcanaBlockHelper.degradedBricks.blockID);
        world.setBlock(i + 2, j + 9, k + 31, ArcanaBlockHelper.degradedBricks.blockID);
        world.setBlock(i + 2, j + 10, k + 0, ArcanaBlockHelper.degradedBricks.blockID);
        world.setBlock(i + 2, j + 10, k + 31, ArcanaBlockHelper.degradedBricks.blockID);
        world.setBlock(i + 2, j + 11, k + 0, ArcanaBlockHelper.ancientBricks.blockID);
        world.setBlock(i + 2, j + 11, k + 31, ArcanaBlockHelper.ancientBricks.blockID);
        world.setBlock(i + 2, j + 12, k + 0, ArcanaBlockHelper.ancientBricks.blockID);
        world.setBlock(i + 2, j + 12, k + 31, ArcanaBlockHelper.ancientBricks.blockID);
        world.setBlock(i + 2, j + 13, k + 0, ArcanaBlockHelper.ancientBricks.blockID);
        world.setBlock(i + 2, j + 13, k + 31, ArcanaBlockHelper.ancientBricks.blockID);
        world.setBlock(i + 2, j + 14, k + 0, ArcanaBlockHelper.ancientBricks.blockID);
        world.setBlock(i + 2, j + 14, k + 31, ArcanaBlockHelper.ancientBricks.blockID);
        world.setBlock(i + 2, j + 15, k + 0, ArcanaBlockHelper.ancientBricks.blockID);
        world.setBlock(i + 2, j + 15, k + 31, ArcanaBlockHelper.ancientBricks.blockID);
        world.setBlock(i + 3, j + 0, k + 0, ArcanaBlockHelper.ancientBricks.blockID);
        world.setBlock(i + 3, j + 0, k + 1, ArcanaBlockHelper.ancientBricks.blockID);
        world.setBlock(i + 3, j + 0, k + 2, ArcanaBlockHelper.ancientBricks.blockID);
        world.setBlock(i + 3, j + 0, k + 3, ArcanaBlockHelper.ancientBricks.blockID);
        world.setBlock(i + 3, j + 0, k + 4, ArcanaBlockHelper.ancientBricks.blockID);
        world.setBlock(i + 3, j + 0, k + 5, ArcanaBlockHelper.ancientBricks.blockID);
        world.setBlock(i + 3, j + 0, k + 6, ArcanaBlockHelper.ancientBricks.blockID);
        world.setBlock(i + 3, j + 0, k + 7, ArcanaBlockHelper.ancientBricks.blockID);
        world.setBlock(i + 3, j + 0, k + 8, ArcanaBlockHelper.ancientBricks.blockID);
        world.setBlock(i + 3, j + 0, k + 9, ArcanaBlockHelper.ancientBricks.blockID);
        world.setBlock(i + 3, j + 0, k + 10, ArcanaBlockHelper.ancientBricks.blockID);
        world.setBlock(i + 3, j + 0, k + 11, ArcanaBlockHelper.ancientBricks.blockID);
        world.setBlock(i + 3, j + 0, k + 12, ArcanaBlockHelper.ancientBricks.blockID);
        world.setBlock(i + 3, j + 0, k + 13, ArcanaBlockHelper.ancientBricks.blockID);
        world.setBlock(i + 3, j + 0, k + 14, ArcanaBlockHelper.ancientBricks.blockID);
        world.setBlock(i + 3, j + 0, k + 15, ArcanaBlockHelper.ancientBricks.blockID);
        world.setBlock(i + 3, j + 0, k + 16, ArcanaBlockHelper.ancientBricks.blockID);
        world.setBlock(i + 3, j + 0, k + 17, ArcanaBlockHelper.ancientBricks.blockID);
        world.setBlock(i + 3, j + 0, k + 18, ArcanaBlockHelper.ancientBricks.blockID);
        world.setBlock(i + 3, j + 0, k + 19, ArcanaBlockHelper.ancientBricks.blockID);
        world.setBlock(i + 3, j + 0, k + 20, ArcanaBlockHelper.ancientBricks.blockID);
        world.setBlock(i + 3, j + 0, k + 21, ArcanaBlockHelper.ancientBricks.blockID);
        world.setBlock(i + 3, j + 0, k + 22, ArcanaBlockHelper.ancientBricks.blockID);
        world.setBlock(i + 3, j + 0, k + 23, ArcanaBlockHelper.ancientBricks.blockID);
        world.setBlock(i + 3, j + 0, k + 24, ArcanaBlockHelper.ancientBricks.blockID);
        world.setBlock(i + 3, j + 0, k + 25, ArcanaBlockHelper.ancientBricks.blockID);
        world.setBlock(i + 3, j + 0, k + 26, ArcanaBlockHelper.ancientBricks.blockID);
        world.setBlock(i + 3, j + 0, k + 27, ArcanaBlockHelper.ancientBricks.blockID);
        world.setBlock(i + 3, j + 0, k + 28, ArcanaBlockHelper.ancientBricks.blockID);
        world.setBlock(i + 3, j + 0, k + 29, ArcanaBlockHelper.ancientBricks.blockID);
        world.setBlock(i + 3, j + 0, k + 30, ArcanaBlockHelper.ancientBricks.blockID);
        world.setBlock(i + 3, j + 0, k + 31, ArcanaBlockHelper.ancientBricks.blockID);
        world.setBlock(i + 3, j + 1, k + 0, ArcanaBlockHelper.ancientBricks.blockID);
        world.setBlock(i + 3, j + 1, k + 31, ArcanaBlockHelper.ancientBricks.blockID);
        world.setBlock(i + 3, j + 2, k + 0, ArcanaBlockHelper.ancientBricks.blockID);
        world.setBlock(i + 3, j + 2, k + 31, ArcanaBlockHelper.ancientBricks.blockID);
        world.setBlock(i + 3, j + 3, k + 0, ArcanaBlockHelper.ancientBricks.blockID);
        world.setBlock(i + 3, j + 3, k + 31, ArcanaBlockHelper.ancientBricks.blockID);
        world.setBlock(i + 3, j + 4, k + 0, ArcanaBlockHelper.ancientBricks.blockID);
        world.setBlock(i + 3, j + 4, k + 31, ArcanaBlockHelper.ancientBricks.blockID);
        world.setBlock(i + 3, j + 5, k + 0, ArcanaBlockHelper.ancientBricks.blockID);
        world.setBlock(i + 3, j + 5, k + 31, ArcanaBlockHelper.ancientBricks.blockID);
        world.setBlock(i + 3, j + 6, k + 0, ArcanaBlockHelper.ancientBricks.blockID);
        world.setBlock(i + 3, j + 6, k + 16, ArcanaBlockHelper.ancientBricks.blockID);
        world.setBlock(i + 3, j + 6, k + 17, ArcanaBlockHelper.ancientBricks.blockID);
        world.setBlock(i + 3, j + 6, k + 18, ArcanaBlockHelper.ancientBricks.blockID);
        world.setBlock(i + 3, j + 6, k + 19, ArcanaBlockHelper.ancientBricks.blockID);
        world.setBlock(i + 3, j + 6, k + 31, ArcanaBlockHelper.ancientBricks.blockID);
        world.setBlock(i + 3, j + 7, k + 0, ArcanaBlockHelper.ancientBricks.blockID);
        world.setBlock(i + 3, j + 7, k + 31, ArcanaBlockHelper.ancientBricks.blockID);
        world.setBlock(i + 3, j + 8, k + 0, ArcanaBlockHelper.degradedBricks.blockID);
        world.setBlock(i + 3, j + 8, k + 22, ArcanaBlockHelper.ancientBricks.blockID);
        world.setBlock(i + 3, j + 8, k + 23, ArcanaBlockHelper.degradedBricks.blockID);
        world.setBlock(i + 3, j + 8, k + 24, ArcanaBlockHelper.degradedBricks.blockID);
        world.setBlock(i + 3, j + 8, k + 25, ArcanaBlockHelper.ancientBricks.blockID);
        world.setBlock(i + 3, j + 8, k + 31, ArcanaBlockHelper.degradedBricks.blockID);
        world.setBlock(i + 3, j + 9, k + 0, ArcanaBlockHelper.ancientBricks.blockID);
        world.setBlock(i + 3, j + 9, k + 31, ArcanaBlockHelper.ancientBricks.blockID);
        world.setBlock(i + 3, j + 10, k + 0, ArcanaBlockHelper.degradedBricks.blockID);
        world.setBlock(i + 3, j + 10, k + 31, ArcanaBlockHelper.degradedBricks.blockID);
        world.setBlock(i + 3, j + 11, k + 0, ArcanaBlockHelper.degradedBricks.blockID);
        world.setBlock(i + 3, j + 11, k + 31, ArcanaBlockHelper.degradedBricks.blockID);
        world.setBlock(i + 3, j + 12, k + 0, ArcanaBlockHelper.degradedBricks.blockID);
        world.setBlock(i + 3, j + 12, k + 31, ArcanaBlockHelper.degradedBricks.blockID);
        world.setBlock(i + 3, j + 13, k + 0, ArcanaBlockHelper.ancientBricks.blockID);
        world.setBlock(i + 3, j + 13, k + 31, ArcanaBlockHelper.ancientBricks.blockID);
        world.setBlock(i + 3, j + 14, k + 0, ArcanaBlockHelper.ancientBricks.blockID);
        world.setBlock(i + 3, j + 14, k + 31, ArcanaBlockHelper.ancientBricks.blockID);
        world.setBlock(i + 3, j + 15, k + 0, ArcanaBlockHelper.ancientBricks.blockID);
        world.setBlock(i + 3, j + 15, k + 31, ArcanaBlockHelper.ancientBricks.blockID);
        world.setBlock(i + 4, j + 0, k + 0, ArcanaBlockHelper.ancientBricks.blockID);
        world.setBlock(i + 4, j + 0, k + 1, ArcanaBlockHelper.ancientBricks.blockID);
        world.setBlock(i + 4, j + 0, k + 2, ArcanaBlockHelper.ancientBricks.blockID);
        world.setBlock(i + 4, j + 0, k + 3, ArcanaBlockHelper.ancientBricks.blockID);
        world.setBlock(i + 4, j + 0, k + 4, ArcanaBlockHelper.ancientBricks.blockID);
        world.setBlock(i + 4, j + 0, k + 5, ArcanaBlockHelper.ancientBricks.blockID);
        world.setBlock(i + 4, j + 0, k + 6, ArcanaBlockHelper.ancientBricks.blockID);
        world.setBlock(i + 4, j + 0, k + 7, ArcanaBlockHelper.ancientBricks.blockID);
        world.setBlock(i + 4, j + 0, k + 8, ArcanaBlockHelper.ancientBricks.blockID);
        world.setBlock(i + 4, j + 0, k + 9, ArcanaBlockHelper.ancientBricks.blockID);
        world.setBlock(i + 4, j + 0, k + 10, ArcanaBlockHelper.ancientBricks.blockID);
        world.setBlock(i + 4, j + 0, k + 11, ArcanaBlockHelper.ancientBricks.blockID);
        world.setBlock(i + 4, j + 0, k + 12, ArcanaBlockHelper.ancientBricks.blockID);
        world.setBlock(i + 4, j + 0, k + 13, ArcanaBlockHelper.ancientBricks.blockID);
        world.setBlock(i + 4, j + 0, k + 14, ArcanaBlockHelper.ancientBricks.blockID);
        world.setBlock(i + 4, j + 0, k + 15, ArcanaBlockHelper.ancientBricks.blockID);
        world.setBlock(i + 4, j + 0, k + 16, ArcanaBlockHelper.ancientBricks.blockID);
        world.setBlock(i + 4, j + 0, k + 17, ArcanaBlockHelper.ancientBricks.blockID);
        world.setBlock(i + 4, j + 0, k + 18, ArcanaBlockHelper.ancientBricks.blockID);
        world.setBlock(i + 4, j + 0, k + 19, ArcanaBlockHelper.ancientBricks.blockID);
        world.setBlock(i + 4, j + 0, k + 20, ArcanaBlockHelper.ancientBricks.blockID);
        world.setBlock(i + 4, j + 0, k + 21, ArcanaBlockHelper.ancientBricks.blockID);
        world.setBlock(i + 4, j + 0, k + 22, ArcanaBlockHelper.ancientBricks.blockID);
        world.setBlock(i + 4, j + 0, k + 23, ArcanaBlockHelper.ancientBricks.blockID);
        world.setBlock(i + 4, j + 0, k + 24, ArcanaBlockHelper.ancientBricks.blockID);
        world.setBlock(i + 4, j + 0, k + 25, ArcanaBlockHelper.ancientBricks.blockID);
        world.setBlock(i + 4, j + 0, k + 26, ArcanaBlockHelper.ancientBricks.blockID);
        world.setBlock(i + 4, j + 0, k + 27, ArcanaBlockHelper.ancientBricks.blockID);
        world.setBlock(i + 4, j + 0, k + 28, ArcanaBlockHelper.ancientBricks.blockID);
        world.setBlock(i + 4, j + 0, k + 29, ArcanaBlockHelper.ancientBricks.blockID);
        world.setBlock(i + 4, j + 0, k + 30, ArcanaBlockHelper.ancientBricks.blockID);
        world.setBlock(i + 4, j + 0, k + 31, ArcanaBlockHelper.ancientBricks.blockID);
        world.setBlock(i + 4, j + 1, k + 0, ArcanaBlockHelper.ancientBricks.blockID);
        world.setBlock(i + 4, j + 1, k + 31, ArcanaBlockHelper.ancientBricks.blockID);
        world.setBlock(i + 4, j + 2, k + 0, ArcanaBlockHelper.ancientBricks.blockID);
        world.setBlock(i + 4, j + 2, k + 31, ArcanaBlockHelper.ancientBricks.blockID);
        world.setBlock(i + 4, j + 3, k + 0, ArcanaBlockHelper.ancientBricks.blockID);
        world.setBlock(i + 4, j + 3, k + 31, ArcanaBlockHelper.ancientBricks.blockID);
        world.setBlock(i + 4, j + 4, k + 0, ArcanaBlockHelper.ancientBricks.blockID);
        world.setBlock(i + 4, j + 4, k + 31, ArcanaBlockHelper.ancientBricks.blockID);
        world.setBlock(i + 4, j + 5, k + 0, ArcanaBlockHelper.ancientBricks.blockID);
        world.setBlock(i + 4, j + 5, k + 31, ArcanaBlockHelper.ancientBricks.blockID);
        world.setBlock(i + 4, j + 6, k + 0, ArcanaBlockHelper.ancientBricks.blockID);
        world.setBlock(i + 4, j + 6, k + 31, ArcanaBlockHelper.ancientBricks.blockID);
        world.setBlock(i + 4, j + 7, k + 0, ArcanaBlockHelper.ancientBricks.blockID);
        world.setBlock(i + 4, j + 7, k + 31, ArcanaBlockHelper.ancientBricks.blockID);
        world.setBlock(i + 4, j + 8, k + 0, ArcanaBlockHelper.degradedBricks.blockID);
        world.setBlock(i + 4, j + 8, k + 22, ArcanaBlockHelper.ancientBricks.blockID);
        world.setBlock(i + 4, j + 8, k + 23, ArcanaBlockHelper.ancientBricks.blockID);
        world.setBlock(i + 4, j + 8, k + 24, ArcanaBlockHelper.ancientBricks.blockID);
        world.setBlock(i + 4, j + 8, k + 25, ArcanaBlockHelper.ancientBricks.blockID);
        world.setBlock(i + 4, j + 8, k + 31, ArcanaBlockHelper.degradedBricks.blockID);
        world.setBlock(i + 4, j + 9, k + 0, ArcanaBlockHelper.ancientBricks.blockID);
        world.setBlock(i + 4, j + 9, k + 31, ArcanaBlockHelper.ancientBricks.blockID);
        world.setBlock(i + 4, j + 10, k + 0, ArcanaBlockHelper.ancientBricks.blockID);
        world.setBlock(i + 4, j + 10, k + 31, ArcanaBlockHelper.ancientBricks.blockID);
        world.setBlock(i + 4, j + 11, k + 0, ArcanaBlockHelper.ancientBricks.blockID);
        world.setBlock(i + 4, j + 11, k + 31, ArcanaBlockHelper.ancientBricks.blockID);
        world.setBlock(i + 4, j + 12, k + 0, ArcanaBlockHelper.degradedBricks.blockID);
        world.setBlock(i + 4, j + 12, k + 31, ArcanaBlockHelper.degradedBricks.blockID);
        world.setBlock(i + 4, j + 13, k + 0, ArcanaBlockHelper.degradedBricks.blockID);
        world.setBlock(i + 4, j + 13, k + 31, ArcanaBlockHelper.degradedBricks.blockID);
        world.setBlock(i + 4, j + 14, k + 0, ArcanaBlockHelper.degradedBricks.blockID);
        world.setBlock(i + 4, j + 14, k + 31, ArcanaBlockHelper.degradedBricks.blockID);
        world.setBlock(i + 4, j + 15, k + 0, ArcanaBlockHelper.ancientBricks.blockID);
        world.setBlock(i + 4, j + 15, k + 31, ArcanaBlockHelper.ancientBricks.blockID);
        world.setBlock(i + 5, j + 0, k + 0, ArcanaBlockHelper.ancientBricks.blockID);
        world.setBlock(i + 5, j + 0, k + 1, ArcanaBlockHelper.ancientBricks.blockID);
        world.setBlock(i + 5, j + 0, k + 2, ArcanaBlockHelper.ancientBricks.blockID);
        world.setBlock(i + 5, j + 0, k + 3, ArcanaBlockHelper.ancientBricks.blockID);
        world.setBlock(i + 5, j + 0, k + 4, ArcanaBlockHelper.ancientBricks.blockID);
        world.setBlock(i + 5, j + 0, k + 5, ArcanaBlockHelper.ancientBricks.blockID);
        world.setBlock(i + 5, j + 0, k + 6, ArcanaBlockHelper.ancientBricks.blockID);
        world.setBlock(i + 5, j + 0, k + 7, ArcanaBlockHelper.ancientBricks.blockID);
        world.setBlock(i + 5, j + 0, k + 8, ArcanaBlockHelper.ancientBricks.blockID);
        world.setBlock(i + 5, j + 0, k + 9, ArcanaBlockHelper.ancientBricks.blockID);
        world.setBlock(i + 5, j + 0, k + 10, ArcanaBlockHelper.ancientBricks.blockID);
        world.setBlock(i + 5, j + 0, k + 11, ArcanaBlockHelper.ancientBricks.blockID);
        world.setBlock(i + 5, j + 0, k + 12, ArcanaBlockHelper.ancientBricks.blockID);
        world.setBlock(i + 5, j + 0, k + 13, ArcanaBlockHelper.ancientBricks.blockID);
        world.setBlock(i + 5, j + 0, k + 14, ArcanaBlockHelper.ancientBricks.blockID);
        world.setBlock(i + 5, j + 0, k + 15, ArcanaBlockHelper.ancientBricks.blockID);
        world.setBlock(i + 5, j + 0, k + 16, ArcanaBlockHelper.ancientBricks.blockID);
        world.setBlock(i + 5, j + 0, k + 17, ArcanaBlockHelper.ancientBricks.blockID);
        world.setBlock(i + 5, j + 0, k + 18, ArcanaBlockHelper.ancientBricks.blockID);
        world.setBlock(i + 5, j + 0, k + 19, ArcanaBlockHelper.ancientBricks.blockID);
        world.setBlock(i + 5, j + 0, k + 20, ArcanaBlockHelper.ancientBricks.blockID);
        world.setBlock(i + 5, j + 0, k + 21, ArcanaBlockHelper.ancientBricks.blockID);
        world.setBlock(i + 5, j + 0, k + 22, ArcanaBlockHelper.ancientBricks.blockID);
        world.setBlock(i + 5, j + 0, k + 23, ArcanaBlockHelper.ancientBricks.blockID);
        world.setBlock(i + 5, j + 0, k + 24, ArcanaBlockHelper.ancientBricks.blockID);
        world.setBlock(i + 5, j + 0, k + 25, ArcanaBlockHelper.ancientBricks.blockID);
        world.setBlock(i + 5, j + 0, k + 26, ArcanaBlockHelper.ancientBricks.blockID);
        world.setBlock(i + 5, j + 0, k + 27, ArcanaBlockHelper.ancientBricks.blockID);
        world.setBlock(i + 5, j + 0, k + 28, ArcanaBlockHelper.ancientBricks.blockID);
        world.setBlock(i + 5, j + 0, k + 29, ArcanaBlockHelper.ancientBricks.blockID);
        world.setBlock(i + 5, j + 0, k + 30, ArcanaBlockHelper.ancientBricks.blockID);
        world.setBlock(i + 5, j + 0, k + 31, ArcanaBlockHelper.ancientBricks.blockID);
        world.setBlock(i + 5, j + 1, k + 0, ArcanaBlockHelper.ancientBricks.blockID);
        world.setBlock(i + 5, j + 1, k + 31, ArcanaBlockHelper.ancientBricks.blockID);
        world.setBlock(i + 5, j + 2, k + 0, ArcanaBlockHelper.ancientBricks.blockID);
        world.setBlock(i + 5, j + 2, k + 31, ArcanaBlockHelper.ancientBricks.blockID);
        world.setBlock(i + 5, j + 3, k + 0, ArcanaBlockHelper.ancientBricks.blockID);
        world.setBlock(i + 5, j + 3, k + 31, ArcanaBlockHelper.ancientBricks.blockID);
        world.setBlock(i + 5, j + 4, k + 0, ArcanaBlockHelper.ancientBricks.blockID);
        world.setBlock(i + 5, j + 4, k + 31, ArcanaBlockHelper.ancientBricks.blockID);
        world.setBlock(i + 5, j + 5, k + 0, ArcanaBlockHelper.ancientBricks.blockID);
        world.setBlock(i + 5, j + 5, k + 31, ArcanaBlockHelper.ancientBricks.blockID);
        world.setBlock(i + 5, j + 6, k + 0, ArcanaBlockHelper.ancientBricks.blockID);
        world.setBlock(i + 5, j + 6, k + 31, ArcanaBlockHelper.ancientBricks.blockID);
        world.setBlock(i + 5, j + 7, k + 0, ArcanaBlockHelper.ancientBricks.blockID);
        world.setBlock(i + 5, j + 7, k + 12, ArcanaBlockHelper.ancientBricks.blockID);
        world.setBlock(i + 5, j + 7, k + 13, ArcanaBlockHelper.ancientBricks.blockID);
        world.setBlock(i + 5, j + 7, k + 14, ArcanaBlockHelper.ancientBricks.blockID);
        world.setBlock(i + 5, j + 7, k + 31, ArcanaBlockHelper.ancientBricks.blockID);
        world.setBlock(i + 5, j + 8, k + 0, ArcanaBlockHelper.degradedBricks.blockID);
        world.setBlock(i + 5, j + 8, k + 31, ArcanaBlockHelper.degradedBricks.blockID);
        world.setBlock(i + 5, j + 9, k + 0, ArcanaBlockHelper.ancientBricks.blockID);
        world.setBlock(i + 5, j + 9, k + 31, ArcanaBlockHelper.ancientBricks.blockID);
        world.setBlock(i + 5, j + 10, k + 0, ArcanaBlockHelper.ancientBricks.blockID);
        world.setBlock(i + 5, j + 10, k + 31, ArcanaBlockHelper.ancientBricks.blockID);
        world.setBlock(i + 5, j + 11, k + 0, ArcanaBlockHelper.ancientBricks.blockID);
        world.setBlock(i + 5, j + 11, k + 31, ArcanaBlockHelper.ancientBricks.blockID);
        world.setBlock(i + 5, j + 12, k + 0, ArcanaBlockHelper.ancientBricks.blockID);
        world.setBlock(i + 5, j + 12, k + 31, ArcanaBlockHelper.ancientBricks.blockID);
        world.setBlock(i + 5, j + 13, k + 0, ArcanaBlockHelper.ancientBricks.blockID);
        world.setBlock(i + 5, j + 13, k + 31, ArcanaBlockHelper.ancientBricks.blockID);
        world.setBlock(i + 5, j + 14, k + 0, ArcanaBlockHelper.degradedBricks.blockID);
        world.setBlock(i + 5, j + 14, k + 31, ArcanaBlockHelper.degradedBricks.blockID);
        world.setBlock(i + 5, j + 15, k + 0, ArcanaBlockHelper.dungeonLamp.blockID);
        world.setBlock(i + 5, j + 15, k + 31, ArcanaBlockHelper.dungeonLamp.blockID);
        world.setBlock(i + 6, j + 0, k + 0, ArcanaBlockHelper.ancientBricks.blockID);
        world.setBlock(i + 6, j + 0, k + 1, ArcanaBlockHelper.ancientBricks.blockID);
        world.setBlock(i + 6, j + 0, k + 2, ArcanaBlockHelper.ancientBricks.blockID);
        world.setBlock(i + 6, j + 0, k + 3, ArcanaBlockHelper.ancientBricks.blockID);
        world.setBlock(i + 6, j + 0, k + 4, ArcanaBlockHelper.ancientBricks.blockID);
        world.setBlock(i + 6, j + 0, k + 5, ArcanaBlockHelper.ancientBricks.blockID);
        world.setBlock(i + 6, j + 0, k + 6, ArcanaBlockHelper.ancientBricks.blockID);
        world.setBlock(i + 6, j + 0, k + 7, ArcanaBlockHelper.ancientBricks.blockID);
        world.setBlock(i + 6, j + 0, k + 8, ArcanaBlockHelper.ancientBricks.blockID);
        world.setBlock(i + 6, j + 0, k + 9, ArcanaBlockHelper.ancientBricks.blockID);
        world.setBlock(i + 6, j + 0, k + 10, ArcanaBlockHelper.ancientBricks.blockID);
        world.setBlock(i + 6, j + 0, k + 11, ArcanaBlockHelper.ancientBricks.blockID);
        world.setBlock(i + 6, j + 0, k + 12, ArcanaBlockHelper.ancientBricks.blockID);
        world.setBlock(i + 6, j + 0, k + 13, ArcanaBlockHelper.ancientBricks.blockID);
        world.setBlock(i + 6, j + 0, k + 14, ArcanaBlockHelper.ancientBricks.blockID);
        world.setBlock(i + 6, j + 0, k + 15, ArcanaBlockHelper.ancientBricks.blockID);
        world.setBlock(i + 6, j + 0, k + 16, ArcanaBlockHelper.ancientBricks.blockID);
        world.setBlock(i + 6, j + 0, k + 17, ArcanaBlockHelper.ancientBricks.blockID);
        world.setBlock(i + 6, j + 0, k + 18, ArcanaBlockHelper.ancientBricks.blockID);
        world.setBlock(i + 6, j + 0, k + 19, ArcanaBlockHelper.ancientBricks.blockID);
        world.setBlock(i + 6, j + 0, k + 20, ArcanaBlockHelper.ancientBricks.blockID);
        world.setBlock(i + 6, j + 0, k + 21, ArcanaBlockHelper.ancientBricks.blockID);
        world.setBlock(i + 6, j + 0, k + 22, ArcanaBlockHelper.ancientBricks.blockID);
        world.setBlock(i + 6, j + 0, k + 23, ArcanaBlockHelper.ancientBricks.blockID);
        world.setBlock(i + 6, j + 0, k + 24, ArcanaBlockHelper.ancientBricks.blockID);
        world.setBlock(i + 6, j + 0, k + 25, ArcanaBlockHelper.ancientBricks.blockID);
        world.setBlock(i + 6, j + 0, k + 26, ArcanaBlockHelper.ancientBricks.blockID);
        world.setBlock(i + 6, j + 0, k + 27, ArcanaBlockHelper.ancientBricks.blockID);
        world.setBlock(i + 6, j + 0, k + 28, ArcanaBlockHelper.ancientBricks.blockID);
        world.setBlock(i + 6, j + 0, k + 29, ArcanaBlockHelper.ancientBricks.blockID);
        world.setBlock(i + 6, j + 0, k + 30, ArcanaBlockHelper.ancientBricks.blockID);
        world.setBlock(i + 6, j + 0, k + 31, ArcanaBlockHelper.ancientBricks.blockID);
        world.setBlock(i + 6, j + 1, k + 0, ArcanaBlockHelper.ancientBricks.blockID);
        world.setBlock(i + 6, j + 1, k + 31, ArcanaBlockHelper.ancientBricks.blockID);
        world.setBlock(i + 6, j + 2, k + 0, ArcanaBlockHelper.ancientBricks.blockID);
        world.setBlock(i + 6, j + 2, k + 31, ArcanaBlockHelper.ancientBricks.blockID);
        world.setBlock(i + 6, j + 3, k + 0, ArcanaBlockHelper.ancientBricks.blockID);
        world.setBlock(i + 6, j + 3, k + 31, ArcanaBlockHelper.ancientBricks.blockID);
        world.setBlock(i + 6, j + 4, k + 0, ArcanaBlockHelper.ancientBricks.blockID);
        world.setBlock(i + 6, j + 4, k + 31, ArcanaBlockHelper.ancientBricks.blockID);
        world.setBlock(i + 6, j + 5, k + 0, ArcanaBlockHelper.ancientBricks.blockID);
        world.setBlock(i + 6, j + 5, k + 31, ArcanaBlockHelper.ancientBricks.blockID);
        world.setBlock(i + 6, j + 6, k + 0, ArcanaBlockHelper.ancientBricks.blockID);
        world.setBlock(i + 6, j + 6, k + 31, ArcanaBlockHelper.ancientBricks.blockID);
        world.setBlock(i + 6, j + 7, k + 0, ArcanaBlockHelper.ancientBricks.blockID);
        world.setBlock(i + 6, j + 7, k + 12, ArcanaBlockHelper.ancientBricks.blockID);
        world.setBlock(i + 6, j + 7, k + 13, ArcanaBlockHelper.degradedBricks.blockID);
        world.setBlock(i + 6, j + 7, k + 14, ArcanaBlockHelper.ancientBricks.blockID);
        world.setBlock(i + 6, j + 7, k + 31, ArcanaBlockHelper.ancientBricks.blockID);
        world.setBlock(i + 6, j + 8, k + 0, ArcanaBlockHelper.degradedBricks.blockID);
        world.setBlock(i + 6, j + 8, k + 31, ArcanaBlockHelper.degradedBricks.blockID);
        world.setBlock(i + 6, j + 9, k + 0, ArcanaBlockHelper.ancientBricks.blockID);
        world.setBlock(i + 6, j + 9, k + 31, ArcanaBlockHelper.ancientBricks.blockID);
        world.setBlock(i + 6, j + 10, k + 0, ArcanaBlockHelper.ancientBricks.blockID);
        world.setBlock(i + 6, j + 10, k + 31, ArcanaBlockHelper.ancientBricks.blockID);
        world.setBlock(i + 6, j + 11, k + 0, ArcanaBlockHelper.ancientBricks.blockID);
        world.setBlock(i + 6, j + 11, k + 31, ArcanaBlockHelper.ancientBricks.blockID);
        world.setBlock(i + 6, j + 12, k + 0, ArcanaBlockHelper.ancientBricks.blockID);
        world.setBlock(i + 6, j + 12, k + 31, ArcanaBlockHelper.ancientBricks.blockID);
        world.setBlock(i + 6, j + 13, k + 0, ArcanaBlockHelper.ancientBricks.blockID);
        world.setBlock(i + 6, j + 13, k + 31, ArcanaBlockHelper.ancientBricks.blockID);
        world.setBlock(i + 6, j + 14, k + 0, ArcanaBlockHelper.ancientBricks.blockID);
        world.setBlock(i + 6, j + 14, k + 31, ArcanaBlockHelper.ancientBricks.blockID);
        world.setBlock(i + 6, j + 15, k + 0, ArcanaBlockHelper.ancientBricks.blockID);
        world.setBlock(i + 6, j + 15, k + 31, ArcanaBlockHelper.ancientBricks.blockID);
        world.setBlock(i + 7, j + 0, k + 0, ArcanaBlockHelper.ancientBricks.blockID);
        world.setBlock(i + 7, j + 0, k + 1, ArcanaBlockHelper.ancientBricks.blockID);
        world.setBlock(i + 7, j + 0, k + 2, ArcanaBlockHelper.ancientBricks.blockID);
        world.setBlock(i + 7, j + 0, k + 3, ArcanaBlockHelper.degradedBricks.blockID);
        world.setBlock(i + 7, j + 0, k + 4, ArcanaBlockHelper.degradedBricks.blockID);
        world.setBlock(i + 7, j + 0, k + 5, ArcanaBlockHelper.degradedBricks.blockID);
        world.setBlock(i + 7, j + 0, k + 6, ArcanaBlockHelper.ancientBricks.blockID);
        world.setBlock(i + 7, j + 0, k + 7, ArcanaBlockHelper.ancientBricks.blockID);
        world.setBlock(i + 7, j + 0, k + 8, ArcanaBlockHelper.ancientBricks.blockID);
        world.setBlock(i + 7, j + 0, k + 9, ArcanaBlockHelper.ancientBricks.blockID);
        world.setBlock(i + 7, j + 0, k + 10, ArcanaBlockHelper.ancientBricks.blockID);
        world.setBlock(i + 7, j + 0, k + 11, ArcanaBlockHelper.ancientBricks.blockID);
        world.setBlock(i + 7, j + 0, k + 12, ArcanaBlockHelper.ancientBricks.blockID);
        world.setBlock(i + 7, j + 0, k + 13, ArcanaBlockHelper.ancientBricks.blockID);
        world.setBlock(i + 7, j + 0, k + 14, ArcanaBlockHelper.ancientBricks.blockID);
        world.setBlock(i + 7, j + 0, k + 15, ArcanaBlockHelper.ancientBricks.blockID);
        world.setBlock(i + 7, j + 0, k + 16, ArcanaBlockHelper.ancientBricks.blockID);
        world.setBlock(i + 7, j + 0, k + 17, ArcanaBlockHelper.ancientBricks.blockID);
        world.setBlock(i + 7, j + 0, k + 18, ArcanaBlockHelper.ancientBricks.blockID);
        world.setBlock(i + 7, j + 0, k + 19, ArcanaBlockHelper.ancientBricks.blockID);
        world.setBlock(i + 7, j + 0, k + 20, ArcanaBlockHelper.ancientBricks.blockID);
        world.setBlock(i + 7, j + 0, k + 21, ArcanaBlockHelper.ancientBricks.blockID);
        world.setBlock(i + 7, j + 0, k + 22, ArcanaBlockHelper.ancientBricks.blockID);
        world.setBlock(i + 7, j + 0, k + 23, ArcanaBlockHelper.ancientBricks.blockID);
        world.setBlock(i + 7, j + 0, k + 24, ArcanaBlockHelper.ancientBricks.blockID);
        world.setBlock(i + 7, j + 0, k + 25, ArcanaBlockHelper.ancientBricks.blockID);
        world.setBlock(i + 7, j + 0, k + 26, ArcanaBlockHelper.degradedBricks.blockID);
        world.setBlock(i + 7, j + 0, k + 27, ArcanaBlockHelper.degradedBricks.blockID);
        world.setBlock(i + 7, j + 0, k + 28, ArcanaBlockHelper.degradedBricks.blockID);
        world.setBlock(i + 7, j + 0, k + 29, ArcanaBlockHelper.ancientBricks.blockID);
        world.setBlock(i + 7, j + 0, k + 30, ArcanaBlockHelper.ancientBricks.blockID);
        world.setBlock(i + 7, j + 0, k + 31, ArcanaBlockHelper.ancientBricks.blockID);
        world.setBlock(i + 7, j + 1, k + 0, ArcanaBlockHelper.ancientBricks.blockID);
        world.setBlock(i + 7, j + 1, k + 31, ArcanaBlockHelper.ancientBricks.blockID);
        world.setBlock(i + 7, j + 2, k + 0, ArcanaBlockHelper.ancientBricks.blockID);
        world.setBlock(i + 7, j + 2, k + 31, ArcanaBlockHelper.ancientBricks.blockID);
        world.setBlock(i + 7, j + 3, k + 0, ArcanaBlockHelper.ancientBricks.blockID);
        world.setBlock(i + 7, j + 3, k + 31, ArcanaBlockHelper.ancientBricks.blockID);
        world.setBlock(i + 7, j + 4, k + 0, ArcanaBlockHelper.ancientBricks.blockID);
        world.setBlock(i + 7, j + 4, k + 31, ArcanaBlockHelper.ancientBricks.blockID);
        world.setBlock(i + 7, j + 5, k + 0, ArcanaBlockHelper.ancientBricks.blockID);
        world.setBlock(i + 7, j + 5, k + 31, ArcanaBlockHelper.ancientBricks.blockID);
        world.setBlock(i + 7, j + 6, k + 0, ArcanaBlockHelper.ancientBricks.blockID);
        world.setBlock(i + 7, j + 6, k + 5, ArcanaBlockHelper.ancientBricks.blockID);
        world.setBlock(i + 7, j + 6, k + 6, ArcanaBlockHelper.ancientBricks.blockID);
        world.setBlock(i + 7, j + 6, k + 7, ArcanaBlockHelper.ancientBricks.blockID);
        world.setBlock(i + 7, j + 6, k + 8, ArcanaBlockHelper.ancientBricks.blockID);
        world.setBlock(i + 7, j + 6, k + 31, ArcanaBlockHelper.ancientBricks.blockID);
        world.setBlock(i + 7, j + 7, k + 0, ArcanaBlockHelper.ancientBricks.blockID);
        world.setBlock(i + 7, j + 7, k + 12, ArcanaBlockHelper.ancientBricks.blockID);
        world.setBlock(i + 7, j + 7, k + 13, ArcanaBlockHelper.ancientBricks.blockID);
        world.setBlock(i + 7, j + 7, k + 14, ArcanaBlockHelper.ancientBricks.blockID);
        world.setBlock(i + 7, j + 7, k + 25, ArcanaBlockHelper.ancientBricks.blockID);
        world.setBlock(i + 7, j + 7, k + 26, ArcanaBlockHelper.ancientBricks.blockID);
        world.setBlock(i + 7, j + 7, k + 27, ArcanaBlockHelper.ancientBricks.blockID);
        world.setBlock(i + 7, j + 7, k + 31, ArcanaBlockHelper.ancientBricks.blockID);
        world.setBlock(i + 7, j + 8, k + 0, ArcanaBlockHelper.degradedBricks.blockID);
        world.setBlock(i + 7, j + 8, k + 31, ArcanaBlockHelper.degradedBricks.blockID);
        world.setBlock(i + 7, j + 9, k + 0, ArcanaBlockHelper.ancientBricks.blockID);
        world.setBlock(i + 7, j + 9, k + 31, ArcanaBlockHelper.ancientBricks.blockID);
        world.setBlock(i + 7, j + 10, k + 0, ArcanaBlockHelper.ancientBricks.blockID);
        world.setBlock(i + 7, j + 10, k + 31, ArcanaBlockHelper.ancientBricks.blockID);
        world.setBlock(i + 7, j + 11, k + 0, ArcanaBlockHelper.ancientBricks.blockID);
        world.setBlock(i + 7, j + 11, k + 31, ArcanaBlockHelper.ancientBricks.blockID);
        world.setBlock(i + 7, j + 12, k + 0, ArcanaBlockHelper.ancientBricks.blockID);
        world.setBlock(i + 7, j + 12, k + 31, ArcanaBlockHelper.ancientBricks.blockID);
        world.setBlock(i + 7, j + 13, k + 0, ArcanaBlockHelper.ancientBricks.blockID);
        world.setBlock(i + 7, j + 13, k + 31, ArcanaBlockHelper.ancientBricks.blockID);
        world.setBlock(i + 7, j + 14, k + 0, ArcanaBlockHelper.ancientBricks.blockID);
        world.setBlock(i + 7, j + 14, k + 31, ArcanaBlockHelper.ancientBricks.blockID);
        world.setBlock(i + 7, j + 15, k + 0, ArcanaBlockHelper.ancientBricks.blockID);
        world.setBlock(i + 7, j + 15, k + 31, ArcanaBlockHelper.ancientBricks.blockID);
        world.setBlock(i + 8, j + 0, k + 0, ArcanaBlockHelper.ancientBricks.blockID);
        world.setBlock(i + 8, j + 0, k + 1, ArcanaBlockHelper.ancientBricks.blockID);
        world.setBlock(i + 8, j + 0, k + 2, ArcanaBlockHelper.heatTraps.blockID);
        world.setBlock(i + 8, j + 0, k + 3, ArcanaBlockHelper.soulStone.blockID);
        world.setBlock(i + 8, j + 0, k + 4, ArcanaBlockHelper.soulStone.blockID);
        world.setBlock(i + 8, j + 0, k + 5, ArcanaBlockHelper.soulStone.blockID);
        world.setBlock(i + 8, j + 0, k + 6, ArcanaBlockHelper.degradedBricks.blockID);
        world.setBlock(i + 8, j + 0, k + 7, ArcanaBlockHelper.ancientBricks.blockID);
        world.setBlock(i + 8, j + 0, k + 8, ArcanaBlockHelper.ancientBricks.blockID);
        world.setBlock(i + 8, j + 0, k + 9, ArcanaBlockHelper.ancientBricks.blockID);
        world.setBlock(i + 8, j + 0, k + 10, ArcanaBlockHelper.ancientBricks.blockID);
        world.setBlock(i + 8, j + 0, k + 11, ArcanaBlockHelper.ancientBricks.blockID);
        world.setBlock(i + 8, j + 0, k + 12, ArcanaBlockHelper.ancientBricks.blockID);
        world.setBlock(i + 8, j + 0, k + 13, ArcanaBlockHelper.ancientBricks.blockID);
        world.setBlock(i + 8, j + 0, k + 14, ArcanaBlockHelper.soulStone.blockID);
        world.setBlock(i + 8, j + 0, k + 15, ArcanaBlockHelper.soulStone.blockID);
        world.setBlock(i + 8, j + 0, k + 16, ArcanaBlockHelper.soulStone.blockID);
        world.setBlock(i + 8, j + 0, k + 17, ArcanaBlockHelper.soulStone.blockID);
        world.setBlock(i + 8, j + 0, k + 18, ArcanaBlockHelper.ancientBricks.blockID);
        world.setBlock(i + 8, j + 0, k + 19, ArcanaBlockHelper.ancientBricks.blockID);
        world.setBlock(i + 8, j + 0, k + 20, ArcanaBlockHelper.ancientBricks.blockID);
        world.setBlock(i + 8, j + 0, k + 21, ArcanaBlockHelper.ancientBricks.blockID);
        world.setBlock(i + 8, j + 0, k + 22, ArcanaBlockHelper.ancientBricks.blockID);
        world.setBlock(i + 8, j + 0, k + 23, ArcanaBlockHelper.ancientBricks.blockID);
        world.setBlock(i + 8, j + 0, k + 24, ArcanaBlockHelper.ancientBricks.blockID);
        world.setBlock(i + 8, j + 0, k + 25, ArcanaBlockHelper.degradedBricks.blockID);
        world.setBlock(i + 8, j + 0, k + 26, ArcanaBlockHelper.soulStone.blockID);
        world.setBlock(i + 8, j + 0, k + 27, ArcanaBlockHelper.soulStone.blockID);
        world.setBlock(i + 8, j + 0, k + 28, ArcanaBlockHelper.soulStone.blockID);
        world.setBlock(i + 8, j + 0, k + 29, ArcanaBlockHelper.heatTraps.blockID);
        world.setBlock(i + 8, j + 0, k + 30, ArcanaBlockHelper.ancientBricks.blockID);
        world.setBlock(i + 8, j + 0, k + 31, ArcanaBlockHelper.ancientBricks.blockID);
        world.setBlock(i + 8, j + 1, k + 0, ArcanaBlockHelper.ancientBricks.blockID);
        world.setBlock(i + 8, j + 1, k + 31, ArcanaBlockHelper.ancientBricks.blockID);
        world.setBlock(i + 8, j + 2, k + 0, ArcanaBlockHelper.ancientBricks.blockID);
        world.setBlock(i + 8, j + 2, k + 31, ArcanaBlockHelper.ancientBricks.blockID);
        world.setBlock(i + 8, j + 3, k + 0, ArcanaBlockHelper.ancientBricks.blockID);
        world.setBlock(i + 8, j + 3, k + 31, ArcanaBlockHelper.ancientBricks.blockID);
        world.setBlock(i + 8, j + 4, k + 0, ArcanaBlockHelper.ancientBricks.blockID);
        world.setBlock(i + 8, j + 4, k + 31, ArcanaBlockHelper.ancientBricks.blockID);
        world.setBlock(i + 8, j + 5, k + 0, ArcanaBlockHelper.ancientBricks.blockID);
        world.setBlock(i + 8, j + 5, k + 31, ArcanaBlockHelper.ancientBricks.blockID);
        world.setBlock(i + 8, j + 6, k + 0, ArcanaBlockHelper.ancientBricks.blockID);
        world.setBlock(i + 8, j + 6, k + 5, ArcanaBlockHelper.ancientBricks.blockID);
        world.setBlock(i + 8, j + 6, k + 6, ArcanaBlockHelper.degradedBricks.blockID);
        world.setBlock(i + 8, j + 6, k + 7, ArcanaBlockHelper.degradedBricks.blockID);
        world.setBlock(i + 8, j + 6, k + 8, ArcanaBlockHelper.ancientBricks.blockID);
        world.setBlock(i + 8, j + 6, k + 31, ArcanaBlockHelper.ancientBricks.blockID);
        world.setBlock(i + 8, j + 7, k + 0, ArcanaBlockHelper.ancientBricks.blockID);
        world.setBlock(i + 8, j + 7, k + 25, ArcanaBlockHelper.ancientBricks.blockID);
        world.setBlock(i + 8, j + 7, k + 26, ArcanaBlockHelper.degradedBricks.blockID);
        world.setBlock(i + 8, j + 7, k + 27, ArcanaBlockHelper.ancientBricks.blockID);
        world.setBlock(i + 8, j + 7, k + 31, ArcanaBlockHelper.ancientBricks.blockID);
        world.setBlock(i + 8, j + 8, k + 0, ArcanaBlockHelper.degradedBricks.blockID);
        world.setBlock(i + 8, j + 8, k + 31, ArcanaBlockHelper.degradedBricks.blockID);
        world.setBlock(i + 8, j + 9, k + 0, ArcanaBlockHelper.ancientBricks.blockID);
        world.setBlock(i + 8, j + 9, k + 31, ArcanaBlockHelper.ancientBricks.blockID);
        world.setBlock(i + 8, j + 10, k + 0, ArcanaBlockHelper.ancientBricks.blockID);
        world.setBlock(i + 8, j + 10, k + 31, ArcanaBlockHelper.ancientBricks.blockID);
        world.setBlock(i + 8, j + 11, k + 0, ArcanaBlockHelper.ancientBricks.blockID);
        world.setBlock(i + 8, j + 11, k + 31, ArcanaBlockHelper.ancientBricks.blockID);
        world.setBlock(i + 8, j + 12, k + 0, ArcanaBlockHelper.ancientBricks.blockID);
        world.setBlock(i + 8, j + 12, k + 31, ArcanaBlockHelper.ancientBricks.blockID);
        world.setBlock(i + 8, j + 13, k + 0, ArcanaBlockHelper.ancientBricks.blockID);
        world.setBlock(i + 8, j + 13, k + 31, ArcanaBlockHelper.ancientBricks.blockID);
        world.setBlock(i + 8, j + 14, k + 0, ArcanaBlockHelper.degradedBricks.blockID);
        world.setBlock(i + 8, j + 14, k + 31, ArcanaBlockHelper.degradedBricks.blockID);
        world.setBlock(i + 8, j + 15, k + 0, ArcanaBlockHelper.degradedBricks.blockID);
        world.setBlock(i + 8, j + 15, k + 31, ArcanaBlockHelper.degradedBricks.blockID);
        world.setBlock(i + 9, j + 0, k + 0, ArcanaBlockHelper.ancientBricks.blockID);
        world.setBlock(i + 9, j + 0, k + 1, ArcanaBlockHelper.ancientBricks.blockID);
        world.setBlock(i + 9, j + 0, k + 2, ArcanaBlockHelper.heatTraps.blockID);
        world.setBlock(i + 9, j + 0, k + 3, ArcanaBlockHelper.soulStone.blockID);
        world.setBlock(i + 9, j + 0, k + 4, ArcanaBlockHelper.soulStone.blockID);
        world.setBlock(i + 9, j + 0, k + 5, ArcanaBlockHelper.soulStone.blockID);
        world.setBlock(i + 9, j + 0, k + 6, ArcanaBlockHelper.soulStone.blockID);
        world.setBlock(i + 9, j + 0, k + 7, ArcanaBlockHelper.degradedBricks.blockID);
        world.setBlock(i + 9, j + 0, k + 8, ArcanaBlockHelper.ancientBricks.blockID);
        world.setBlock(i + 9, j + 0, k + 9, ArcanaBlockHelper.ancientBricks.blockID);
        world.setBlock(i + 9, j + 0, k + 10, ArcanaBlockHelper.ancientBricks.blockID);
        world.setBlock(i + 9, j + 0, k + 11, ArcanaBlockHelper.ancientBricks.blockID);
        world.setBlock(i + 9, j + 0, k + 12, ArcanaBlockHelper.ancientBricks.blockID);
        world.setBlock(i + 9, j + 0, k + 13, ArcanaBlockHelper.ancientBricks.blockID);
        world.setBlock(i + 9, j + 0, k + 14, ArcanaBlockHelper.soulStone.blockID);
        world.setBlock(i + 9, j + 0, k + 15, ArcanaBlockHelper.soulStone.blockID);
        world.setBlock(i + 9, j + 0, k + 16, ArcanaBlockHelper.dungeonLamp.blockID);
        world.setBlock(i + 9, j + 0, k + 17, ArcanaBlockHelper.soulStone.blockID);
        world.setBlock(i + 9, j + 0, k + 18, ArcanaBlockHelper.soulStone.blockID);
        world.setBlock(i + 9, j + 0, k + 19, ArcanaBlockHelper.ancientBricks.blockID);
        world.setBlock(i + 9, j + 0, k + 20, ArcanaBlockHelper.ancientBricks.blockID);
        world.setBlock(i + 9, j + 0, k + 21, ArcanaBlockHelper.ancientBricks.blockID);
        world.setBlock(i + 9, j + 0, k + 22, ArcanaBlockHelper.ancientBricks.blockID);
        world.setBlock(i + 9, j + 0, k + 23, ArcanaBlockHelper.ancientBricks.blockID);
        world.setBlock(i + 9, j + 0, k + 24, ArcanaBlockHelper.degradedBricks.blockID);
        world.setBlock(i + 9, j + 0, k + 25, ArcanaBlockHelper.soulStone.blockID);
        world.setBlock(i + 9, j + 0, k + 26, ArcanaBlockHelper.soulStone.blockID);
        world.setBlock(i + 9, j + 0, k + 27, ArcanaBlockHelper.soulStone.blockID);
        world.setBlock(i + 9, j + 0, k + 28, ArcanaBlockHelper.soulStone.blockID);
        world.setBlock(i + 9, j + 0, k + 29, ArcanaBlockHelper.heatTraps.blockID);
        world.setBlock(i + 9, j + 0, k + 30, ArcanaBlockHelper.ancientBricks.blockID);
        world.setBlock(i + 9, j + 0, k + 31, ArcanaBlockHelper.ancientBricks.blockID);
        world.setBlock(i + 9, j + 1, k + 0, ArcanaBlockHelper.ancientBricks.blockID);
        world.setBlock(i + 9, j + 1, k + 31, ArcanaBlockHelper.ancientBricks.blockID);
        world.setBlock(i + 9, j + 2, k + 0, ArcanaBlockHelper.ancientBricks.blockID);
        world.setBlock(i + 9, j + 2, k + 31, ArcanaBlockHelper.ancientBricks.blockID);
        world.setBlock(i + 9, j + 3, k + 0, ArcanaBlockHelper.ancientBricks.blockID);
        world.setBlock(i + 9, j + 3, k + 31, ArcanaBlockHelper.ancientBricks.blockID);
        world.setBlock(i + 9, j + 4, k + 0, ArcanaBlockHelper.ancientBricks.blockID);
        world.setBlock(i + 9, j + 4, k + 31, ArcanaBlockHelper.ancientBricks.blockID);
        world.setBlock(i + 9, j + 5, k + 0, ArcanaBlockHelper.ancientBricks.blockID);
        world.setBlock(i + 9, j + 5, k + 31, ArcanaBlockHelper.ancientBricks.blockID);
        world.setBlock(i + 9, j + 6, k + 0, ArcanaBlockHelper.ancientBricks.blockID);
        world.setBlock(i + 9, j + 6, k + 5, ArcanaBlockHelper.ancientBricks.blockID);
        world.setBlock(i + 9, j + 6, k + 6, ArcanaBlockHelper.ancientBricks.blockID);
        world.setBlock(i + 9, j + 6, k + 7, ArcanaBlockHelper.ancientBricks.blockID);
        world.setBlock(i + 9, j + 6, k + 8, ArcanaBlockHelper.ancientBricks.blockID);
        world.setBlock(i + 9, j + 6, k + 31, ArcanaBlockHelper.ancientBricks.blockID);
        world.setBlock(i + 9, j + 7, k + 0, ArcanaBlockHelper.ancientBricks.blockID);
        world.setBlock(i + 9, j + 7, k + 25, ArcanaBlockHelper.ancientBricks.blockID);
        world.setBlock(i + 9, j + 7, k + 26, ArcanaBlockHelper.ancientBricks.blockID);
        world.setBlock(i + 9, j + 7, k + 27, ArcanaBlockHelper.ancientBricks.blockID);
        world.setBlock(i + 9, j + 7, k + 31, ArcanaBlockHelper.ancientBricks.blockID);
        world.setBlock(i + 9, j + 8, k + 0, ArcanaBlockHelper.degradedBricks.blockID);
        world.setBlock(i + 9, j + 8, k + 31, ArcanaBlockHelper.degradedBricks.blockID);
        world.setBlock(i + 9, j + 9, k + 0, ArcanaBlockHelper.ancientBricks.blockID);
        world.setBlock(i + 9, j + 9, k + 31, ArcanaBlockHelper.ancientBricks.blockID);
        world.setBlock(i + 9, j + 10, k + 0, ArcanaBlockHelper.ancientBricks.blockID);
        world.setBlock(i + 9, j + 10, k + 31, ArcanaBlockHelper.ancientBricks.blockID);
        world.setBlock(i + 9, j + 11, k + 0, ArcanaBlockHelper.ancientBricks.blockID);
        world.setBlock(i + 9, j + 11, k + 31, ArcanaBlockHelper.ancientBricks.blockID);
        world.setBlock(i + 9, j + 12, k + 0, ArcanaBlockHelper.ancientBricks.blockID);
        world.setBlock(i + 9, j + 12, k + 31, ArcanaBlockHelper.ancientBricks.blockID);
        world.setBlock(i + 9, j + 13, k + 0, ArcanaBlockHelper.ancientBricks.blockID);
        world.setBlock(i + 9, j + 13, k + 31, ArcanaBlockHelper.ancientBricks.blockID);
        world.setBlock(i + 9, j + 14, k + 0, ArcanaBlockHelper.degradedBricks.blockID);
        world.setBlock(i + 9, j + 14, k + 31, ArcanaBlockHelper.degradedBricks.blockID);
        world.setBlock(i + 9, j + 15, k + 0, ArcanaBlockHelper.ancientBricks.blockID);
        world.setBlock(i + 9, j + 15, k + 31, ArcanaBlockHelper.ancientBricks.blockID);
        world.setBlock(i + 10, j + 0, k + 0, ArcanaBlockHelper.ancientBricks.blockID);
        world.setBlock(i + 10, j + 0, k + 1, ArcanaBlockHelper.ancientBricks.blockID);
        world.setBlock(i + 10, j + 0, k + 2, ArcanaBlockHelper.ancientBricks.blockID);
        world.setBlock(i + 10, j + 0, k + 3, ArcanaBlockHelper.heatTraps.blockID);
        world.setBlock(i + 10, j + 0, k + 4, ArcanaBlockHelper.soulStone.blockID);
        world.setBlock(i + 10, j + 0, k + 5, ArcanaBlockHelper.soulStone.blockID);
        world.setBlock(i + 10, j + 0, k + 6, ArcanaBlockHelper.soulStone.blockID);
        world.setBlock(i + 10, j + 0, k + 7, ArcanaBlockHelper.soulStone.blockID);
        world.setBlock(i + 10, j + 0, k + 8, ArcanaBlockHelper.degradedBricks.blockID);
        world.setBlock(i + 10, j + 0, k + 9, ArcanaBlockHelper.ancientBricks.blockID);
        world.setBlock(i + 10, j + 0, k + 10, ArcanaBlockHelper.ancientBricks.blockID);
        world.setBlock(i + 10, j + 0, k + 11, ArcanaBlockHelper.ancientBricks.blockID);
        world.setBlock(i + 10, j + 0, k + 12, ArcanaBlockHelper.ancientBricks.blockID);
        world.setBlock(i + 10, j + 0, k + 13, ArcanaBlockHelper.ancientBricks.blockID);
