/*
*** MADE BY MITHION'S .SCHEMATIC TO JAVA CONVERTING TOOL v1.6 ***
*/

package net.divinerpg.worldgen.vethea.layer1;
import java.util.Random;

import net.divinerpg.entities.vethea.mobs.EntityCryptKeeper;
import net.divinerpg.utils.helpers.block.VetheaBlockHelper;
import net.minecraft.entity.EntityLiving;
import net.minecraft.world.World;
import net.minecraft.world.gen.feature.WorldGenerator;

public class Crypt2 extends WorldGenerator
{
	protected int[] GetValidSpawnBlocks() {
		return new int[] {
		};
	}

	public Crypt2() { }

	public boolean generate(World world, Random rand, int i, int j, int k) {

		world.setBlock(i + 0, j + 0, k + 0, VetheaBlockHelper.dreamdirt.blockID);
		world.setBlock(i + 0, j + 0, k + 1, VetheaBlockHelper.dreamdirt.blockID);
		world.setBlock(i + 0, j + 0, k + 2, VetheaBlockHelper.dreamdirt.blockID);
		world.setBlock(i + 0, j + 0, k + 3, VetheaBlockHelper.dreamdirt.blockID);
		world.setBlock(i + 0, j + 0, k + 4, VetheaBlockHelper.dreamdirt.blockID);
		world.setBlock(i + 0, j + 0, k + 5, VetheaBlockHelper.dreamdirt.blockID);
		world.setBlock(i + 0, j + 0, k + 6, VetheaBlockHelper.dreamdirt.blockID);
		world.setBlock(i + 0, j + 0, k + 7, VetheaBlockHelper.dreamdirt.blockID);
		world.setBlock(i + 0, j + 0, k + 8, VetheaBlockHelper.dreamdirt.blockID);
		world.setBlock(i + 0, j + 0, k + 9, VetheaBlockHelper.dreamdirt.blockID);
		world.setBlock(i + 0, j + 0, k + 10, VetheaBlockHelper.dreamdirt.blockID);
		world.setBlock(i + 0, j + 1, k + 0, VetheaBlockHelper.dreamdirt.blockID);
		world.setBlock(i + 0, j + 1, k + 1, VetheaBlockHelper.dreamdirt.blockID);
		world.setBlock(i + 0, j + 1, k + 2, VetheaBlockHelper.dreamdirt.blockID);
		world.setBlock(i + 0, j + 1, k + 3, VetheaBlockHelper.dreamdirt.blockID);
		world.setBlock(i + 0, j + 1, k + 4, VetheaBlockHelper.cryptWall.blockID);
		world.setBlock(i + 0, j + 1, k + 5, VetheaBlockHelper.cryptWall.blockID);
		world.setBlock(i + 0, j + 1, k + 6, VetheaBlockHelper.cryptWall.blockID);
		world.setBlock(i + 0, j + 1, k + 7, VetheaBlockHelper.cryptWall.blockID);
		world.setBlock(i + 0, j + 1, k + 8, VetheaBlockHelper.cryptWall.blockID);
		world.setBlock(i + 0, j + 1, k + 9, VetheaBlockHelper.dreamdirt.blockID);
		world.setBlock(i + 0, j + 1, k + 10, VetheaBlockHelper.dreamdirt.blockID);
		world.setBlock(i + 0, j + 2, k + 0, VetheaBlockHelper.dreamdirt.blockID);
		world.setBlock(i + 0, j + 2, k + 1, VetheaBlockHelper.dreamdirt.blockID);
		world.setBlock(i + 0, j + 2, k + 2, VetheaBlockHelper.dreamdirt.blockID);
		world.setBlock(i + 0, j + 2, k + 3, VetheaBlockHelper.dreamdirt.blockID);
		world.setBlock(i + 0, j + 2, k + 4, VetheaBlockHelper.cryptWall.blockID);
		world.setBlock(i + 0, j + 2, k + 5, VetheaBlockHelper.cryptWall.blockID);
		world.setBlock(i + 0, j + 2, k + 6, VetheaBlockHelper.cryptWall.blockID);
		world.setBlock(i + 0, j + 2, k + 7, VetheaBlockHelper.cryptWall.blockID);
		world.setBlock(i + 0, j + 2, k + 8, VetheaBlockHelper.cryptWall.blockID);
		world.setBlock(i + 0, j + 2, k + 9, VetheaBlockHelper.dreamdirt.blockID);
		world.setBlock(i + 0, j + 2, k + 10, VetheaBlockHelper.dreamdirt.blockID);
		world.setBlock(i + 0, j + 3, k + 0, VetheaBlockHelper.dreamdirt.blockID);
		world.setBlock(i + 0, j + 3, k + 1, VetheaBlockHelper.dreamdirt.blockID);
		world.setBlock(i + 0, j + 3, k + 2, VetheaBlockHelper.dreamdirt.blockID);
		world.setBlock(i + 0, j + 3, k + 3, VetheaBlockHelper.dreamdirt.blockID);
		world.setBlock(i + 0, j + 3, k + 4, VetheaBlockHelper.hungerstone2.blockID);
		world.setBlock(i + 0, j + 3, k + 5, VetheaBlockHelper.hungerstone2.blockID);
		world.setBlock(i + 0, j + 3, k + 6, VetheaBlockHelper.dreamdirt.blockID);
		world.setBlock(i + 0, j + 3, k + 7, VetheaBlockHelper.dreamdirt.blockID);
		world.setBlock(i + 0, j + 3, k + 8, VetheaBlockHelper.dreamdirt.blockID);
		world.setBlock(i + 0, j + 3, k + 9, VetheaBlockHelper.dreamdirt.blockID);
		world.setBlock(i + 0, j + 3, k + 10, VetheaBlockHelper.dreamdirt.blockID);
		world.setBlock(i + 0, j + 4, k + 0, VetheaBlockHelper.dreamdirt.blockID);
		world.setBlock(i + 0, j + 4, k + 1, VetheaBlockHelper.dreamdirt.blockID);
		world.setBlock(i + 0, j + 4, k + 2, VetheaBlockHelper.dreamdirt.blockID);
		world.setBlock(i + 0, j + 4, k + 3, VetheaBlockHelper.dreamdirt.blockID);
		world.setBlock(i + 0, j + 4, k + 4, VetheaBlockHelper.dreamdirt.blockID);
		world.setBlock(i + 0, j + 4, k + 5, VetheaBlockHelper.dreamdirt.blockID);
		world.setBlock(i + 0, j + 4, k + 6, VetheaBlockHelper.dreamdirt.blockID);
		world.setBlock(i + 0, j + 4, k + 7, VetheaBlockHelper.dreamdirt.blockID);
		world.setBlock(i + 0, j + 4, k + 8, VetheaBlockHelper.dreamdirt.blockID);
		world.setBlock(i + 0, j + 4, k + 9, VetheaBlockHelper.dreamdirt.blockID);
		world.setBlock(i + 0, j + 4, k + 10, VetheaBlockHelper.dreamdirt.blockID);
		world.setBlock(i + 0, j + 5, k + 0, VetheaBlockHelper.metalCaging.blockID);
		world.setBlock(i + 0, j + 5, k + 1, VetheaBlockHelper.metalCaging.blockID);
		world.setBlock(i + 0, j + 5, k + 2, VetheaBlockHelper.metalCaging.blockID);
		world.setBlock(i + 0, j + 5, k + 3, VetheaBlockHelper.metalCaging.blockID);
		world.setBlock(i + 0, j + 5, k + 4, VetheaBlockHelper.metalCaging.blockID);
		world.setBlock(i + 0, j + 5, k + 5, VetheaBlockHelper.metalCaging.blockID);
		world.setBlock(i + 0, j + 5, k + 6, VetheaBlockHelper.metalCaging.blockID);
		world.setBlock(i + 0, j + 5, k + 7, VetheaBlockHelper.metalCaging.blockID);
		world.setBlock(i + 0, j + 5, k + 8, VetheaBlockHelper.metalCaging.blockID);
		world.setBlock(i + 0, j + 5, k + 9, VetheaBlockHelper.metalCaging.blockID);
		world.setBlock(i + 0, j + 5, k + 10, VetheaBlockHelper.metalCaging.blockID);
		world.setBlock(i + 0, j + 6, k + 0, VetheaBlockHelper.hungerstone1.blockID);
		world.setBlock(i + 0, j + 6, k + 1, VetheaBlockHelper.hungerstone1.blockID);
		world.setBlock(i + 0, j + 6, k + 2, VetheaBlockHelper.hungerstone1.blockID);
		world.setBlock(i + 0, j + 6, k + 3, VetheaBlockHelper.hungerstone1.blockID);
		world.setBlock(i + 0, j + 6, k + 4, VetheaBlockHelper.hungerstone1.blockID);
		world.setBlock(i + 0, j + 6, k + 5, VetheaBlockHelper.hungerstone1.blockID);
		world.setBlock(i + 0, j + 6, k + 6, VetheaBlockHelper.hungerstone1.blockID);
		world.setBlock(i + 0, j + 6, k + 7, VetheaBlockHelper.hungerstone1.blockID);
		world.setBlock(i + 0, j + 6, k + 8, VetheaBlockHelper.hungerstone1.blockID);
		world.setBlock(i + 0, j + 6, k + 9, VetheaBlockHelper.hungerstone1.blockID);
		world.setBlock(i + 0, j + 6, k + 10, VetheaBlockHelper.hungerstone1.blockID);
		world.setBlock(i + 0, j + 7, k + 0, 0);
		world.setBlock(i + 0, j + 7, k + 1, 0);
		world.setBlock(i + 0, j + 7, k + 2, 0);
		world.setBlock(i + 0, j + 7, k + 3, 0);
		world.setBlock(i + 0, j + 7, k + 4, 0);
		world.setBlock(i + 0, j + 7, k + 5, 0);
		world.setBlock(i + 0, j + 7, k + 6, 0);
		world.setBlock(i + 0, j + 7, k + 7, 0);
		world.setBlock(i + 0, j + 7, k + 8, 0);
		world.setBlock(i + 0, j + 7, k + 9, 0);
		world.setBlock(i + 0, j + 7, k + 10, 0);
		world.setBlock(i + 0, j + 8, k + 0, 0);
		world.setBlock(i + 0, j + 8, k + 1, 0);
		world.setBlock(i + 0, j + 8, k + 2, 0);
		world.setBlock(i + 0, j + 8, k + 3, 0);
		world.setBlock(i + 0, j + 8, k + 4, 0);
		world.setBlock(i + 0, j + 8, k + 5, 0);
		world.setBlock(i + 0, j + 8, k + 6, 0);
		world.setBlock(i + 0, j + 8, k + 7, 0);
		world.setBlock(i + 0, j + 8, k + 8, 0);
		world.setBlock(i + 0, j + 8, k + 9, 0);
		world.setBlock(i + 0, j + 8, k + 10, 0);
		world.setBlock(i + 0, j + 9, k + 0, 0);
		world.setBlock(i + 0, j + 9, k + 1, 0);
		world.setBlock(i + 0, j + 9, k + 2, 0);
		world.setBlock(i + 0, j + 9, k + 3, 0);
		world.setBlock(i + 0, j + 9, k + 4, 0);
		world.setBlock(i + 0, j + 9, k + 5, 0);
		world.setBlock(i + 0, j + 9, k + 6, 0);
		world.setBlock(i + 0, j + 9, k + 7, 0);
		world.setBlock(i + 0, j + 9, k + 8, 0);
		world.setBlock(i + 0, j + 9, k + 9, 0);
		world.setBlock(i + 0, j + 9, k + 10, 0);
		world.setBlock(i + 0, j + 10, k + 0, 0);
		world.setBlock(i + 0, j + 10, k + 1, 0);
		world.setBlock(i + 0, j + 10, k + 2, 0);
		world.setBlock(i + 0, j + 10, k + 3, 0);
		world.setBlock(i + 0, j + 10, k + 4, 0);
		world.setBlock(i + 0, j + 10, k + 5, 0);
		world.setBlock(i + 0, j + 10, k + 6, 0);
		world.setBlock(i + 0, j + 10, k + 7, 0);
		world.setBlock(i + 0, j + 10, k + 8, 0);
		world.setBlock(i + 0, j + 10, k + 9, 0);
		world.setBlock(i + 0, j + 10, k + 10, 0);
		world.setBlock(i + 1, j + 0, k + 0, VetheaBlockHelper.dreamdirt.blockID);
		world.setBlock(i + 1, j + 0, k + 1, VetheaBlockHelper.dreamdirt.blockID);
		world.setBlock(i + 1, j + 0, k + 2, VetheaBlockHelper.dreamdirt.blockID);
		world.setBlock(i + 1, j + 0, k + 3, VetheaBlockHelper.dreamdirt.blockID);
		world.setBlock(i + 1, j + 0, k + 4, VetheaBlockHelper.cryptFloor.blockID);
		world.setBlock(i + 1, j + 0, k + 5, VetheaBlockHelper.cryptFloor.blockID);
		world.setBlock(i + 1, j + 0, k + 6, VetheaBlockHelper.cryptFloor.blockID);
		world.setBlock(i + 1, j + 0, k + 7, VetheaBlockHelper.cryptFloor.blockID);
		world.setBlock(i + 1, j + 0, k + 8, VetheaBlockHelper.cryptFloor.blockID);
		world.setBlock(i + 1, j + 0, k + 9, VetheaBlockHelper.dreamdirt.blockID);
		world.setBlock(i + 1, j + 0, k + 10, VetheaBlockHelper.dreamdirt.blockID);
		world.setBlock(i + 1, j + 1, k + 0, VetheaBlockHelper.dreamdirt.blockID);
		world.setBlock(i + 1, j + 1, k + 1, VetheaBlockHelper.dreamdirt.blockID);
		world.setBlock(i + 1, j + 1, k + 2, VetheaBlockHelper.dreamdirt.blockID);
		world.setBlock(i + 1, j + 1, k + 3, VetheaBlockHelper.cryptWall.blockID);
		world.setBlock(i + 1, j + 1, k + 4, 0);
		world.setBlock(i + 1, j + 1, k + 5, 0);
		world.setBlock(i + 1, j + 1, k + 6, 0);
		world.setBlock(i + 1, j + 1, k + 7, 0);
		world.setBlock(i + 1, j + 1, k + 8, 0);
		world.setBlock(i + 1, j + 1, k + 9, VetheaBlockHelper.cryptWall.blockID);
		world.setBlock(i + 1, j + 1, k + 10, VetheaBlockHelper.dreamdirt.blockID);
		world.setBlock(i + 1, j + 2, k + 0, VetheaBlockHelper.dreamdirt.blockID);
		world.setBlock(i + 1, j + 2, k + 1, VetheaBlockHelper.dreamdirt.blockID);
		world.setBlock(i + 1, j + 2, k + 2, VetheaBlockHelper.dreamdirt.blockID);
		world.setBlock(i + 1, j + 2, k + 3, VetheaBlockHelper.cryptWall.blockID);
		world.setBlock(i + 1, j + 2, k + 4, 0);
		world.setBlock(i + 1, j + 2, k + 5, 0);
		world.setBlock(i + 1, j + 2, k + 6, 0);
		world.setBlock(i + 1, j + 2, k + 7, 0);
		world.setBlock(i + 1, j + 2, k + 8, 0);
		world.setBlock(i + 1, j + 2, k + 9, VetheaBlockHelper.cryptWall.blockID);
		world.setBlock(i + 1, j + 2, k + 10, VetheaBlockHelper.dreamdirt.blockID);
		world.setBlock(i + 1, j + 3, k + 0, VetheaBlockHelper.dreamdirt.blockID);
		world.setBlock(i + 1, j + 3, k + 1, VetheaBlockHelper.dreamdirt.blockID);
		world.setBlock(i + 1, j + 3, k + 2, VetheaBlockHelper.dreamdirt.blockID);
		world.setBlock(i + 1, j + 3, k + 3, VetheaBlockHelper.hungerstone2.blockID);
		world.setBlock(i + 1, j + 3, k + 4, VetheaBlockHelper.hungerstone2.blockID);
		world.setBlock(i + 1, j + 3, k + 5, VetheaBlockHelper.hungerstone2.blockID);
		world.setBlock(i + 1, j + 3, k + 6, VetheaBlockHelper.hungerstone2.blockID);
		world.setBlock(i + 1, j + 3, k + 7, VetheaBlockHelper.hungerstone2.blockID);
		world.setBlock(i + 1, j + 3, k + 8, VetheaBlockHelper.hungerstone2.blockID);
		world.setBlock(i + 1, j + 3, k + 9, VetheaBlockHelper.dreamdirt.blockID);
		world.setBlock(i + 1, j + 3, k + 10, VetheaBlockHelper.dreamdirt.blockID);
		world.setBlock(i + 1, j + 4, k + 0, VetheaBlockHelper.dreamdirt.blockID);
		world.setBlock(i + 1, j + 4, k + 1, VetheaBlockHelper.dreamdirt.blockID);
		world.setBlock(i + 1, j + 4, k + 2, VetheaBlockHelper.dreamdirt.blockID);
		world.setBlock(i + 1, j + 4, k + 3, VetheaBlockHelper.dreamdirt.blockID);
		world.setBlock(i + 1, j + 4, k + 4, VetheaBlockHelper.dreamdirt.blockID);
		world.setBlock(i + 1, j + 4, k + 5, VetheaBlockHelper.dreamdirt.blockID);
		world.setBlock(i + 1, j + 4, k + 6, VetheaBlockHelper.dreamdirt.blockID);
		world.setBlock(i + 1, j + 4, k + 7, VetheaBlockHelper.dreamdirt.blockID);
		world.setBlock(i + 1, j + 4, k + 8, VetheaBlockHelper.dreamdirt.blockID);
		world.setBlock(i + 1, j + 4, k + 9, VetheaBlockHelper.dreamdirt.blockID);
		world.setBlock(i + 1, j + 4, k + 10, VetheaBlockHelper.dreamdirt.blockID);
		world.setBlock(i + 1, j + 5, k + 0, VetheaBlockHelper.metalCaging.blockID);
		world.setBlock(i + 1, j + 5, k + 1, 0);
		world.setBlock(i + 1, j + 5, k + 2, 0);
		world.setBlock(i + 1, j + 5, k + 3, 0);
		world.setBlock(i + 1, j + 5, k + 4, 0);
		world.setBlock(i + 1, j + 5, k + 5, 0);
		world.setBlock(i + 1, j + 5, k + 6, 0);
		world.setBlock(i + 1, j + 5, k + 7, 0);
		world.setBlock(i + 1, j + 5, k + 8, 0);
		world.setBlock(i + 1, j + 5, k + 9, 0);
		world.setBlock(i + 1, j + 5, k + 10, VetheaBlockHelper.metalCaging.blockID);
		world.setBlock(i + 1, j + 6, k + 0, VetheaBlockHelper.hungerstone1.blockID);
		world.setBlock(i + 1, j + 6, k + 1, 0);
		world.setBlock(i + 1, j + 6, k + 2, 0);
		world.setBlock(i + 1, j + 6, k + 3, 0);
		world.setBlock(i + 1, j + 6, k + 4, 0);
		world.setBlock(i + 1, j + 6, k + 5, 0);
		world.setBlock(i + 1, j + 6, k + 6, 0);
		world.setBlock(i + 1, j + 6, k + 7, 0);
		world.setBlock(i + 1, j + 6, k + 8, 0);
		world.setBlock(i + 1, j + 6, k + 9, 0);
		world.setBlock(i + 1, j + 6, k + 10, VetheaBlockHelper.hungerstone1.blockID);
		world.setBlock(i + 1, j + 7, k + 0, 0);
		world.setBlock(i + 1, j + 7, k + 1, 0);
		world.setBlock(i + 1, j + 7, k + 2, 0);
		world.setBlock(i + 1, j + 7, k + 3, 0);
		world.setBlock(i + 1, j + 7, k + 4, 0);
		world.setBlock(i + 1, j + 7, k + 5, 0);
		world.setBlock(i + 1, j + 7, k + 6, 0);
		world.setBlock(i + 1, j + 7, k + 7, 0);
		world.setBlock(i + 1, j + 7, k + 8, 0);
		world.setBlock(i + 1, j + 7, k + 9, 0);
		world.setBlock(i + 1, j + 7, k + 10, 0);
		world.setBlock(i + 1, j + 8, k + 0, 0);
		world.setBlock(i + 1, j + 8, k + 1, 0);
		world.setBlock(i + 1, j + 8, k + 2, 0);
		world.setBlock(i + 1, j + 8, k + 3, 0);
		world.setBlock(i + 1, j + 8, k + 4, 0);
		world.setBlock(i + 1, j + 8, k + 5, 0);
		world.setBlock(i + 1, j + 8, k + 6, 0);
		world.setBlock(i + 1, j + 8, k + 7, 0);
		world.setBlock(i + 1, j + 8, k + 8, 0);
		world.setBlock(i + 1, j + 8, k + 9, 0);
		world.setBlock(i + 1, j + 8, k + 10, 0);
		world.setBlock(i + 1, j + 9, k + 0, 0);
		world.setBlock(i + 1, j + 9, k + 1, 0);
		world.setBlock(i + 1, j + 9, k + 2, 0);
		world.setBlock(i + 1, j + 9, k + 3, 0);
		world.setBlock(i + 1, j + 9, k + 4, 0);
		world.setBlock(i + 1, j + 9, k + 5, 0);
		world.setBlock(i + 1, j + 9, k + 6, 0);
		world.setBlock(i + 1, j + 9, k + 7, 0);
		world.setBlock(i + 1, j + 9, k + 8, 0);
		world.setBlock(i + 1, j + 9, k + 9, 0);
		world.setBlock(i + 1, j + 9, k + 10, 0);
		world.setBlock(i + 1, j + 10, k + 0, 0);
		world.setBlock(i + 1, j + 10, k + 1, 0);
		world.setBlock(i + 1, j + 10, k + 2, 0);
		world.setBlock(i + 1, j + 10, k + 3, 0);
		world.setBlock(i + 1, j + 10, k + 4, 0);
		world.setBlock(i + 1, j + 10, k + 5, 0);
		world.setBlock(i + 1, j + 10, k + 6, 0);
		world.setBlock(i + 1, j + 10, k + 7, 0);
		world.setBlock(i + 1, j + 10, k + 8, 0);
		world.setBlock(i + 1, j + 10, k + 9, 0);
		world.setBlock(i + 1, j + 10, k + 10, 0);
		world.setBlock(i + 2, j + 0, k + 0, VetheaBlockHelper.dreamdirt.blockID);
		world.setBlock(i + 2, j + 0, k + 1, VetheaBlockHelper.dreamdirt.blockID);
		world.setBlock(i + 2, j + 0, k + 2, VetheaBlockHelper.dreamdirt.blockID);
		world.setBlock(i + 2, j + 0, k + 3, VetheaBlockHelper.dreamdirt.blockID);
		world.setBlock(i + 2, j + 0, k + 4, VetheaBlockHelper.cryptFloor.blockID);
		world.setBlock(i + 2, j + 0, k + 5, VetheaBlockHelper.cryptFloor.blockID);
		world.setBlock(i + 2, j + 0, k + 6, VetheaBlockHelper.cryptFloor.blockID);
		world.setBlock(i + 2, j + 0, k + 7, VetheaBlockHelper.cryptFloor.blockID);
		world.setBlock(i + 2, j + 0, k + 8, VetheaBlockHelper.cryptFloor.blockID);
		world.setBlock(i + 2, j + 0, k + 9, VetheaBlockHelper.dreamdirt.blockID);
		world.setBlock(i + 2, j + 0, k + 10, VetheaBlockHelper.dreamdirt.blockID);
		world.setBlock(i + 2, j + 1, k + 0, VetheaBlockHelper.dreamdirt.blockID);
		world.setBlock(i + 2, j + 1, k + 1, VetheaBlockHelper.dreamdirt.blockID);
		world.setBlock(i + 2, j + 1, k + 2, VetheaBlockHelper.dreamdirt.blockID);
		world.setBlock(i + 2, j + 1, k + 3, VetheaBlockHelper.cryptWall.blockID);
		world.setBlock(i + 2, j + 1, k + 4, 0);
		world.setBlock(i + 2, j + 1, k + 5, 0);
		world.setBlock(i + 2, j + 1, k + 6, 0);
		world.setBlock(i + 2, j + 1, k + 7, 0);
		world.setBlock(i + 2, j + 1, k + 8, 0);
		world.setBlock(i + 2, j + 1, k + 9, VetheaBlockHelper.cryptWall.blockID);
		world.setBlock(i + 2, j + 1, k + 10, VetheaBlockHelper.dreamdirt.blockID);
		world.setBlock(i + 2, j + 2, k + 0, VetheaBlockHelper.dreamdirt.blockID);
		world.setBlock(i + 2, j + 2, k + 1, VetheaBlockHelper.dreamdirt.blockID);
		world.setBlock(i + 2, j + 2, k + 2, VetheaBlockHelper.dreamdirt.blockID);
		world.setBlock(i + 2, j + 2, k + 3, VetheaBlockHelper.cryptWall.blockID);
		world.setBlock(i + 2, j + 2, k + 4, 0);
		world.setBlock(i + 2, j + 2, k + 5, 0);
		world.setBlock(i + 2, j + 2, k + 6, 0);
		world.setBlock(i + 2, j + 2, k + 7, 0);
		world.setBlock(i + 2, j + 2, k + 8, 0);
		world.setBlock(i + 2, j + 2, k + 9, VetheaBlockHelper.cryptWall.blockID);
		world.setBlock(i + 2, j + 2, k + 10, VetheaBlockHelper.dreamdirt.blockID);
		world.setBlock(i + 2, j + 3, k + 0, VetheaBlockHelper.dreamdirt.blockID);
		world.setBlock(i + 2, j + 3, k + 1, VetheaBlockHelper.dreamdirt.blockID);
		world.setBlock(i + 2, j + 3, k + 2, VetheaBlockHelper.dreamdirt.blockID);
		world.setBlock(i + 2, j + 3, k + 3, VetheaBlockHelper.hungerstone2.blockID);
		world.setBlock(i + 2, j + 3, k + 4, 0);
		world.setBlock(i + 2, j + 3, k + 5, 0);
		world.setBlock(i + 2, j + 3, k + 6, VetheaBlockHelper.hungerstone2.blockID);
		world.setBlock(i + 2, j + 3, k + 7, VetheaBlockHelper.hungerstone2.blockID);
		world.setBlock(i + 2, j + 3, k + 8, VetheaBlockHelper.hungerstone2.blockID);
		world.setBlock(i + 2, j + 3, k + 9, VetheaBlockHelper.dreamdirt.blockID);
		world.setBlock(i + 2, j + 3, k + 10, VetheaBlockHelper.dreamdirt.blockID);
		world.setBlock(i + 2, j + 4, k + 0, VetheaBlockHelper.dreamdirt.blockID);
		world.setBlock(i + 2, j + 4, k + 1, VetheaBlockHelper.dreamdirt.blockID);
		world.setBlock(i + 2, j + 4, k + 2, VetheaBlockHelper.dreamdirt.blockID);
		world.setBlock(i + 2, j + 4, k + 3, VetheaBlockHelper.hungerstone2.blockID);
		world.setBlock(i + 2, j + 4, k + 4, VetheaBlockHelper.hungerstone2.blockID);
		world.setBlock(i + 2, j + 4, k + 5, VetheaBlockHelper.hungerstone2.blockID);
		world.setBlock(i + 2, j + 4, k + 6, VetheaBlockHelper.hungerstone2.blockID);
		world.setBlock(i + 2, j + 4, k + 7, VetheaBlockHelper.dreamdirt.blockID);
		world.setBlock(i + 2, j + 4, k + 8, VetheaBlockHelper.dreamdirt.blockID);
		world.setBlock(i + 2, j + 4, k + 9, VetheaBlockHelper.dreamdirt.blockID);
		world.setBlock(i + 2, j + 4, k + 10, VetheaBlockHelper.dreamdirt.blockID);
		world.setBlock(i + 2, j + 5, k + 0, VetheaBlockHelper.metalCaging.blockID);
		world.setBlock(i + 2, j + 5, k + 1, 0);
		world.setBlock(i + 2, j + 5, k + 2, 0);
		world.setBlock(i + 2, j + 5, k + 3, VetheaBlockHelper.hungerstone1.blockID);
		world.setBlock(i + 2, j + 5, k + 4, VetheaBlockHelper.hungerstone1.blockID);
		world.setBlock(i + 2, j + 5, k + 5, VetheaBlockHelper.hungerstone1.blockID);
		world.setBlock(i + 2, j + 5, k + 6, VetheaBlockHelper.hungerstone1.blockID);
		world.setBlock(i + 2, j + 5, k + 7, 0);
		world.setBlock(i + 2, j + 5, k + 8, 0);
		world.setBlock(i + 2, j + 5, k + 9, 0);
		world.setBlock(i + 2, j + 5, k + 10, VetheaBlockHelper.metalCaging.blockID);
		world.setBlock(i + 2, j + 6, k + 0, VetheaBlockHelper.hungerstone1.blockID);
		world.setBlock(i + 2, j + 6, k + 1, 0);
		world.setBlock(i + 2, j + 6, k + 2, 0);
		world.setBlock(i + 2, j + 6, k + 3, VetheaBlockHelper.hungerstone2.blockID);
		world.setBlock(i + 2, j + 6, k + 4, VetheaBlockHelper.hungerstone2.blockID);
		world.setBlock(i + 2, j + 6, k + 5, VetheaBlockHelper.hungerstone2.blockID);
		world.setBlock(i + 2, j + 6, k + 6, VetheaBlockHelper.hungerstone2.blockID);
		world.setBlock(i + 2, j + 6, k + 7, 0);
		world.setBlock(i + 2, j + 6, k + 8, 0);
		world.setBlock(i + 2, j + 6, k + 9, 0);
		world.setBlock(i + 2, j + 6, k + 10, VetheaBlockHelper.hungerstone1.blockID);
		world.setBlock(i + 2, j + 7, k + 0, 0);
		world.setBlock(i + 2, j + 7, k + 1, 0);
		world.setBlock(i + 2, j + 7, k + 2, 0);
		world.setBlock(i + 2, j + 7, k + 3, 0);
		world.setBlock(i + 2, j + 7, k + 4, 0);
		world.setBlock(i + 2, j + 7, k + 5, 0);
		world.setBlock(i + 2, j + 7, k + 6, 0);
		world.setBlock(i + 2, j + 7, k + 7, 0);
		world.setBlock(i + 2, j + 7, k + 8, 0);
		world.setBlock(i + 2, j + 7, k + 9, 0);
		world.setBlock(i + 2, j + 7, k + 10, 0);
		world.setBlock(i + 2, j + 8, k + 0, 0);
		world.setBlock(i + 2, j + 8, k + 1, 0);
		world.setBlock(i + 2, j + 8, k + 2, 0);
		world.setBlock(i + 2, j + 8, k + 3, 0);
		world.setBlock(i + 2, j + 8, k + 4, 0);
		world.setBlock(i + 2, j + 8, k + 5, 0);
		world.setBlock(i + 2, j + 8, k + 6, 0);
		world.setBlock(i + 2, j + 8, k + 7, 0);
		world.setBlock(i + 2, j + 8, k + 8, 0);
		world.setBlock(i + 2, j + 8, k + 9, 0);
		world.setBlock(i + 2, j + 8, k + 10, 0);
		world.setBlock(i + 2, j + 9, k + 0, 0);
		world.setBlock(i + 2, j + 9, k + 1, 0);
		world.setBlock(i + 2, j + 9, k + 2, 0);
		world.setBlock(i + 2, j + 9, k + 3, 0);
		world.setBlock(i + 2, j + 9, k + 4, 0);
		world.setBlock(i + 2, j + 9, k + 5, 0);
		world.setBlock(i + 2, j + 9, k + 6, 0);
		world.setBlock(i + 2, j + 9, k + 7, 0);
		world.setBlock(i + 2, j + 9, k + 8, 0);
		world.setBlock(i + 2, j + 9, k + 9, 0);
		world.setBlock(i + 2, j + 9, k + 10, 0);
		world.setBlock(i + 2, j + 10, k + 0, 0);
		world.setBlock(i + 2, j + 10, k + 1, 0);
		world.setBlock(i + 2, j + 10, k + 2, 0);
		world.setBlock(i + 2, j + 10, k + 3, 0);
		world.setBlock(i + 2, j + 10, k + 4, 0);
		world.setBlock(i + 2, j + 10, k + 5, 0);
		world.setBlock(i + 2, j + 10, k + 6, 0);
		world.setBlock(i + 2, j + 10, k + 7, 0);
		world.setBlock(i + 2, j + 10, k + 8, 0);
		world.setBlock(i + 2, j + 10, k + 9, 0);
		world.setBlock(i + 2, j + 10, k + 10, 0);
		world.setBlock(i + 3, j + 0, k + 0, VetheaBlockHelper.dreamdirt.blockID);
		world.setBlock(i + 3, j + 0, k + 1, VetheaBlockHelper.dreamdirt.blockID);
		world.setBlock(i + 3, j + 0, k + 2, VetheaBlockHelper.dreamdirt.blockID);
		world.setBlock(i + 3, j + 0, k + 3, VetheaBlockHelper.dreamdirt.blockID);
		world.setBlock(i + 3, j + 0, k + 4, VetheaBlockHelper.cryptFloor.blockID);
		world.setBlock(i + 3, j + 0, k + 5, VetheaBlockHelper.cryptFloor.blockID);
		world.setBlock(i + 3, j + 0, k + 6, VetheaBlockHelper.dreamdirt.blockID);
		world.setBlock(i + 3, j + 0, k + 7, VetheaBlockHelper.cryptFloor.blockID);
		world.setBlock(i + 3, j + 0, k + 8, VetheaBlockHelper.cryptFloor.blockID);
		world.setBlock(i + 3, j + 0, k + 9, VetheaBlockHelper.dreamdirt.blockID);
		world.setBlock(i + 3, j + 0, k + 10, VetheaBlockHelper.dreamdirt.blockID);
		world.setBlock(i + 3, j + 1, k + 0, VetheaBlockHelper.dreamdirt.blockID);
		world.setBlock(i + 3, j + 1, k + 1, VetheaBlockHelper.dreamdirt.blockID);
		world.setBlock(i + 3, j + 1, k + 2, VetheaBlockHelper.dreamdirt.blockID);
		world.setBlock(i + 3, j + 1, k + 3, VetheaBlockHelper.cryptWall.blockID);
		world.setBlock(i + 3, j + 1, k + 4, 0);
		world.setBlock(i + 3, j + 1, k + 5, 0);
		world.setBlock(i + 3, j + 1, k + 6, VetheaBlockHelper.cryptWall.blockID);
		world.setBlock(i + 3, j + 1, k + 7, 0);
		world.setBlock(i + 3, j + 1, k + 8, 0);
		world.setBlock(i + 3, j + 1, k + 9, VetheaBlockHelper.cryptWall.blockID);
		world.setBlock(i + 3, j + 1, k + 10, VetheaBlockHelper.dreamdirt.blockID);
		world.setBlock(i + 3, j + 2, k + 0, VetheaBlockHelper.dreamdirt.blockID);
		world.setBlock(i + 3, j + 2, k + 1, VetheaBlockHelper.dreamdirt.blockID);
		world.setBlock(i + 3, j + 2, k + 2, VetheaBlockHelper.dreamdirt.blockID);
		world.setBlock(i + 3, j + 2, k + 3, VetheaBlockHelper.cryptWall.blockID);
		world.setBlock(i + 3, j + 2, k + 4, 0);
		world.setBlock(i + 3, j + 2, k + 5, 0);
		world.setBlock(i + 3, j + 2, k + 6, VetheaBlockHelper.cryptWall.blockID);
		world.setBlock(i + 3, j + 2, k + 7, 0);
		world.setBlock(i + 3, j + 2, k + 8, 0);
		world.setBlock(i + 3, j + 2, k + 9, VetheaBlockHelper.cryptWall.blockID);
		world.setBlock(i + 3, j + 2, k + 10, VetheaBlockHelper.dreamdirt.blockID);
		world.setBlock(i + 3, j + 3, k + 0, VetheaBlockHelper.dreamdirt.blockID);
		world.setBlock(i + 3, j + 3, k + 1, VetheaBlockHelper.dreamdirt.blockID);
		world.setBlock(i + 3, j + 3, k + 2, VetheaBlockHelper.dreamdirt.blockID);
		world.setBlock(i + 3, j + 3, k + 3, VetheaBlockHelper.hungerstone2.blockID);
		world.setBlock(i + 3, j + 3, k + 4, 0);
		world.setBlock(i + 3, j + 3, k + 5, 0);
		world.setBlock(i + 3, j + 3, k + 6, VetheaBlockHelper.hungerstone2.blockID);
		world.setBlock(i + 3, j + 3, k + 7, VetheaBlockHelper.hungerstone2.blockID);
		world.setBlock(i + 3, j + 3, k + 8, VetheaBlockHelper.hungerstone2.blockID);
		world.setBlock(i + 3, j + 3, k + 9, VetheaBlockHelper.dreamdirt.blockID);
		world.setBlock(i + 3, j + 3, k + 10, VetheaBlockHelper.dreamdirt.blockID);
		world.setBlock(i + 3, j + 4, k + 0, VetheaBlockHelper.dreamdirt.blockID);
		world.setBlock(i + 3, j + 4, k + 1, VetheaBlockHelper.dreamdirt.blockID);
		world.setBlock(i + 3, j + 4, k + 2, VetheaBlockHelper.dreamdirt.blockID);
		world.setBlock(i + 3, j + 4, k + 3, VetheaBlockHelper.hungerstone2.blockID);
		world.setBlock(i + 3, j + 4, k + 4, 0);
		world.setBlock(i + 3, j + 4, k + 5, 0);
		world.setBlock(i + 3, j + 4, k + 6, VetheaBlockHelper.hungerstone2.blockID);
		world.setBlock(i + 3, j + 4, k + 7, VetheaBlockHelper.dreamdirt.blockID);
		world.setBlock(i + 3, j + 4, k + 8, VetheaBlockHelper.dreamdirt.blockID);
		world.setBlock(i + 3, j + 4, k + 9, VetheaBlockHelper.dreamdirt.blockID);
		world.setBlock(i + 3, j + 4, k + 10, VetheaBlockHelper.dreamdirt.blockID);
		world.setBlock(i + 3, j + 5, k + 0, VetheaBlockHelper.metalCaging.blockID);
		world.setBlock(i + 3, j + 5, k + 1, 0);
		world.setBlock(i + 3, j + 5, k + 2, 0);
		world.setBlock(i + 3, j + 5, k + 3, VetheaBlockHelper.hungerstone1.blockID);
		world.setBlock(i + 3, j + 5, k + 4, 0);
		world.setBlock(i + 3, j + 5, k + 5, 0);
		world.setBlock(i + 3, j + 5, k + 6, VetheaBlockHelper.hungerstone1.blockID);
		world.setBlock(i + 3, j + 5, k + 7, 0);
		world.setBlock(i + 3, j + 5, k + 8, 0);
		world.setBlock(i + 3, j + 5, k + 9, 0);
		world.setBlock(i + 3, j + 5, k + 10, VetheaBlockHelper.metalCaging.blockID);
		world.setBlock(i + 3, j + 6, k + 0, VetheaBlockHelper.hungerstone1.blockID);
		world.setBlock(i + 3, j + 6, k + 1, 0);
		world.setBlock(i + 3, j + 6, k + 2, 0);
		world.setBlock(i + 3, j + 6, k + 3, VetheaBlockHelper.hungerstone2.blockID);
		world.setBlock(i + 3, j + 6, k + 4, 0);
		world.setBlock(i + 3, j + 6, k + 5, 0);
		world.setBlock(i + 3, j + 6, k + 6, VetheaBlockHelper.hungerstone2.blockID);
		world.setBlock(i + 3, j + 6, k + 7, 0);
		world.setBlock(i + 3, j + 6, k + 8, 0);
		world.setBlock(i + 3, j + 6, k + 9, 0);
		world.setBlock(i + 3, j + 6, k + 10, VetheaBlockHelper.hungerstone1.blockID);
		world.setBlock(i + 3, j + 7, k + 0, 0);
		world.setBlock(i + 3, j + 7, k + 1, 0);
		world.setBlock(i + 3, j + 7, k + 2, 0);
		world.setBlock(i + 3, j + 7, k + 3, 0);
		world.setBlock(i + 3, j + 7, k + 4, VetheaBlockHelper.hungerstone1.blockID);
		world.setBlock(i + 3, j + 7, k + 5, VetheaBlockHelper.hungerstone1.blockID);
		world.setBlock(i + 3, j + 7, k + 6, 0);
		world.setBlock(i + 3, j + 7, k + 7, 0);
		world.setBlock(i + 3, j + 7, k + 8, 0);
		world.setBlock(i + 3, j + 7, k + 9, 0);
		world.setBlock(i + 3, j + 7, k + 10, 0);
		world.setBlock(i + 3, j + 8, k + 0, 0);
		world.setBlock(i + 3, j + 8, k + 1, 0);
		world.setBlock(i + 3, j + 8, k + 2, 0);
		world.setBlock(i + 3, j + 8, k + 3, 0);
		world.setBlock(i + 3, j + 8, k + 4, 0);
		world.setBlock(i + 3, j + 8, k + 5, 0);
		world.setBlock(i + 3, j + 8, k + 6, 0);
		world.setBlock(i + 3, j + 8, k + 7, 0);
		world.setBlock(i + 3, j + 8, k + 8, 0);
		world.setBlock(i + 3, j + 8, k + 9, 0);
		world.setBlock(i + 3, j + 8, k + 10, 0);
		world.setBlock(i + 3, j + 9, k + 0, 0);
		world.setBlock(i + 3, j + 9, k + 1, 0);
		world.setBlock(i + 3, j + 9, k + 2, 0);
		world.setBlock(i + 3, j + 9, k + 3, 0);
		world.setBlock(i + 3, j + 9, k + 4, 0);
		world.setBlock(i + 3, j + 9, k + 5, 0);
		world.setBlock(i + 3, j + 9, k + 6, 0);
		world.setBlock(i + 3, j + 9, k + 7, 0);
		world.setBlock(i + 3, j + 9, k + 8, 0);
		world.setBlock(i + 3, j + 9, k + 9, 0);
		world.setBlock(i + 3, j + 9, k + 10, 0);
		world.setBlock(i + 3, j + 10, k + 0, 0);
		world.setBlock(i + 3, j + 10, k + 1, 0);
		world.setBlock(i + 3, j + 10, k + 2, 0);
		world.setBlock(i + 3, j + 10, k + 3, 0);
		world.setBlock(i + 3, j + 10, k + 4, 0);
		world.setBlock(i + 3, j + 10, k + 5, 0);
		world.setBlock(i + 3, j + 10, k + 6, 0);
		world.setBlock(i + 3, j + 10, k + 7, 0);
		world.setBlock(i + 3, j + 10, k + 8, 0);
		world.setBlock(i + 3, j + 10, k + 9, 0);
		world.setBlock(i + 3, j + 10, k + 10, 0);
		world.setBlock(i + 4, j + 0, k + 0, VetheaBlockHelper.dreamdirt.blockID);
		world.setBlock(i + 4, j + 0, k + 1, VetheaBlockHelper.dreamdirt.blockID);
		world.setBlock(i + 4, j + 0, k + 2, VetheaBlockHelper.dreamdirt.blockID);
		world.setBlock(i + 4, j + 0, k + 3, VetheaBlockHelper.dreamdirt.blockID);
		world.setBlock(i + 4, j + 0, k + 4, VetheaBlockHelper.dreamdirt.blockID);
		world.setBlock(i + 4, j + 0, k + 5, VetheaBlockHelper.dreamdirt.blockID);
		world.setBlock(i + 4, j + 0, k + 6, VetheaBlockHelper.dreamdirt.blockID);
		world.setBlock(i + 4, j + 0, k + 7, VetheaBlockHelper.cryptFloor.blockID);
		world.setBlock(i + 4, j + 0, k + 8, VetheaBlockHelper.cryptFloor.blockID);
		world.setBlock(i + 4, j + 0, k + 9, VetheaBlockHelper.dreamdirt.blockID);
		world.setBlock(i + 4, j + 0, k + 10, VetheaBlockHelper.dreamdirt.blockID);
		world.setBlock(i + 4, j + 1, k + 0, VetheaBlockHelper.dreamdirt.blockID);
		world.setBlock(i + 4, j + 1, k + 1, VetheaBlockHelper.dreamdirt.blockID);
		world.setBlock(i + 4, j + 1, k + 2, VetheaBlockHelper.dreamdirt.blockID);
		world.setBlock(i + 4, j + 1, k + 3, VetheaBlockHelper.cryptWall.blockID);
		world.setBlock(i + 4, j + 1, k + 4, VetheaBlockHelper.cryptWall.blockID);
		world.setBlock(i + 4, j + 1, k + 5, VetheaBlockHelper.cryptWall.blockID);
		world.setBlock(i + 4, j + 1, k + 6, VetheaBlockHelper.cryptWall.blockID);
		world.setBlock(i + 4, j + 1, k + 7, 0);
		world.setBlock(i + 4, j + 1, k + 8, 0);
		world.setBlock(i + 4, j + 1, k + 9, VetheaBlockHelper.cryptWall.blockID);
		world.setBlock(i + 4, j + 1, k + 10, VetheaBlockHelper.dreamdirt.blockID);
		world.setBlock(i + 4, j + 2, k + 0, VetheaBlockHelper.dreamdirt.blockID);
		world.setBlock(i + 4, j + 2, k + 1, VetheaBlockHelper.dreamdirt.blockID);
		world.setBlock(i + 4, j + 2, k + 2, VetheaBlockHelper.dreamdirt.blockID);
		world.setBlock(i + 4, j + 2, k + 3, VetheaBlockHelper.cryptWall.blockID);
		world.setBlock(i + 4, j + 2, k + 4, 0);
		world.setBlock(i + 4, j + 2, k + 5, 0);
		world.setBlock(i + 4, j + 2, k + 6, VetheaBlockHelper.cryptWall.blockID);
		world.setBlock(i + 4, j + 2, k + 7, 0);
		world.setBlock(i + 4, j + 2, k + 8, 0);
		world.setBlock(i + 4, j + 2, k + 9, VetheaBlockHelper.cryptWall.blockID);
		world.setBlock(i + 4, j + 2, k + 10, VetheaBlockHelper.dreamdirt.blockID);
		world.setBlock(i + 4, j + 3, k + 0, VetheaBlockHelper.dreamdirt.blockID);
		world.setBlock(i + 4, j + 3, k + 1, VetheaBlockHelper.dreamdirt.blockID);
		world.setBlock(i + 4, j + 3, k + 2, VetheaBlockHelper.dreamdirt.blockID);
		world.setBlock(i + 4, j + 3, k + 3, VetheaBlockHelper.hungerstone2.blockID);
		world.setBlock(i + 4, j + 3, k + 4, 0);
		world.setBlock(i + 4, j + 3, k + 5, 0);
		world.setBlock(i + 4, j + 3, k + 6, VetheaBlockHelper.hungerstone2.blockID);
		world.setBlock(i + 4, j + 3, k + 7, VetheaBlockHelper.hungerstone2.blockID);
		world.setBlock(i + 4, j + 3, k + 8, VetheaBlockHelper.hungerstone2.blockID);
		world.setBlock(i + 4, j + 3, k + 9, VetheaBlockHelper.dreamdirt.blockID);
		world.setBlock(i + 4, j + 3, k + 10, VetheaBlockHelper.dreamdirt.blockID);
		world.setBlock(i + 4, j + 4, k + 0, VetheaBlockHelper.dreamdirt.blockID);
		world.setBlock(i + 4, j + 4, k + 1, VetheaBlockHelper.dreamdirt.blockID);
		world.setBlock(i + 4, j + 4, k + 2, VetheaBlockHelper.dreamdirt.blockID);
		world.setBlock(i + 4, j + 4, k + 3, VetheaBlockHelper.hungerstone2.blockID);
		world.setBlock(i + 4, j + 4, k + 4, 0);
		world.setBlock(i + 4, j + 4, k + 5, 0);
		world.setBlock(i + 4, j + 4, k + 6, VetheaBlockHelper.hungerstone2.blockID);
		world.setBlock(i + 4, j + 4, k + 7, VetheaBlockHelper.dreamdirt.blockID);
		world.setBlock(i + 4, j + 4, k + 8, VetheaBlockHelper.dreamdirt.blockID);
		world.setBlock(i + 4, j + 4, k + 9, VetheaBlockHelper.dreamdirt.blockID);
		world.setBlock(i + 4, j + 4, k + 10, VetheaBlockHelper.dreamdirt.blockID);
		world.setBlock(i + 4, j + 5, k + 0, VetheaBlockHelper.metalCaging.blockID);
		world.setBlock(i + 4, j + 5, k + 1, 0);
		world.setBlock(i + 4, j + 5, k + 2, 0);
		world.setBlock(i + 4, j + 5, k + 3, VetheaBlockHelper.hungerstone1.blockID);
		world.setBlock(i + 4, j + 5, k + 4, 0);
		world.setBlock(i + 4, j + 5, k + 5, 0);
		world.setBlock(i + 4, j + 5, k + 6, VetheaBlockHelper.hungerstone1.blockID);
		world.setBlock(i + 4, j + 5, k + 7, 0);
		world.setBlock(i + 4, j + 5, k + 8, 0);
		world.setBlock(i + 4, j + 5, k + 9, 0);
		world.setBlock(i + 4, j + 5, k + 10, VetheaBlockHelper.metalCaging.blockID);
		world.setBlock(i + 4, j + 6, k + 0, VetheaBlockHelper.hungerstone1.blockID);
		world.setBlock(i + 4, j + 6, k + 1, 0);
		world.setBlock(i + 4, j + 6, k + 2, 0);
		world.setBlock(i + 4, j + 6, k + 3, VetheaBlockHelper.hungerstone2.blockID);
		world.setBlock(i + 4, j + 6, k + 4, 0);
		world.setBlock(i + 4, j + 6, k + 5, 0);
		world.setBlock(i + 4, j + 6, k + 6, VetheaBlockHelper.hungerstone2.blockID);
		world.setBlock(i + 4, j + 6, k + 7, 0);
		world.setBlock(i + 4, j + 6, k + 8, 0);
		world.setBlock(i + 4, j + 6, k + 9, 0);
		world.setBlock(i + 4, j + 6, k + 10, VetheaBlockHelper.hungerstone1.blockID);
		world.setBlock(i + 4, j + 7, k + 0, 0);
		world.setBlock(i + 4, j + 7, k + 1, 0);
		world.setBlock(i + 4, j + 7, k + 2, 0);
		world.setBlock(i + 4, j + 7, k + 3, 0);
		world.setBlock(i + 4, j + 7, k + 4, VetheaBlockHelper.hungerstone1.blockID);
		world.setBlock(i + 4, j + 7, k + 5, VetheaBlockHelper.hungerstone1.blockID);
		world.setBlock(i + 4, j + 7, k + 6, 0);
		world.setBlock(i + 4, j + 7, k + 7, 0);
		world.setBlock(i + 4, j + 7, k + 8, 0);
		world.setBlock(i + 4, j + 7, k + 9, 0);
		world.setBlock(i + 4, j + 7, k + 10, 0);
		world.setBlock(i + 4, j + 8, k + 0, 0);
		world.setBlock(i + 4, j + 8, k + 1, 0);
		world.setBlock(i + 4, j + 8, k + 2, 0);
		world.setBlock(i + 4, j + 8, k + 3, 0);
		world.setBlock(i + 4, j + 8, k + 4, 0);
		world.setBlock(i + 4, j + 8, k + 5, 0);
		world.setBlock(i + 4, j + 8, k + 6, 0);
		world.setBlock(i + 4, j + 8, k + 7, 0);
		world.setBlock(i + 4, j + 8, k + 8, 0);
		world.setBlock(i + 4, j + 8, k + 9, 0);
		world.setBlock(i + 4, j + 8, k + 10, 0);
		world.setBlock(i + 4, j + 9, k + 0, 0);
		world.setBlock(i + 4, j + 9, k + 1, 0);
		world.setBlock(i + 4, j + 9, k + 2, 0);
		world.setBlock(i + 4, j + 9, k + 3, 0);
		world.setBlock(i + 4, j + 9, k + 4, 0);
		world.setBlock(i + 4, j + 9, k + 5, 0);
		world.setBlock(i + 4, j + 9, k + 6, 0);
		world.setBlock(i + 4, j + 9, k + 7, 0);
		world.setBlock(i + 4, j + 9, k + 8, 0);
		world.setBlock(i + 4, j + 9, k + 9, 0);
		world.setBlock(i + 4, j + 9, k + 10, 0);
		world.setBlock(i + 4, j + 10, k + 0, 0);
		world.setBlock(i + 4, j + 10, k + 1, 0);
		world.setBlock(i + 4, j + 10, k + 2, 0);
		world.setBlock(i + 4, j + 10, k + 3, 0);
		world.setBlock(i + 4, j + 10, k + 4, 0);
		world.setBlock(i + 4, j + 10, k + 5, 0);
		world.setBlock(i + 4, j + 10, k + 6, 0);
		world.setBlock(i + 4, j + 10, k + 7, 0);
		world.setBlock(i + 4, j + 10, k + 8, 0);
		world.setBlock(i + 4, j + 10, k + 9, 0);
		world.setBlock(i + 4, j + 10, k + 10, 0);
		world.setBlock(i + 5, j + 0, k + 0, VetheaBlockHelper.dreamdirt.blockID);
		world.setBlock(i + 5, j + 0, k + 1, VetheaBlockHelper.dreamdirt.blockID);
		world.setBlock(i + 5, j + 0, k + 2, VetheaBlockHelper.dreamdirt.blockID);
		world.setBlock(i + 5, j + 0, k + 3, VetheaBlockHelper.dreamdirt.blockID);
		world.setBlock(i + 5, j + 0, k + 4, VetheaBlockHelper.dreamdirt.blockID);
		world.setBlock(i + 5, j + 0, k + 5, VetheaBlockHelper.dreamdirt.blockID);
		world.setBlock(i + 5, j + 0, k + 6, VetheaBlockHelper.dreamdirt.blockID);
		world.setBlock(i + 5, j + 0, k + 7, VetheaBlockHelper.cryptFloor.blockID);
		world.setBlock(i + 5, j + 0, k + 8, VetheaBlockHelper.cryptFloor.blockID);
		world.setBlock(i + 5, j + 0, k + 9, VetheaBlockHelper.dreamdirt.blockID);
		world.setBlock(i + 5, j + 0, k + 10, VetheaBlockHelper.dreamdirt.blockID);
		world.setBlock(i + 5, j + 1, k + 0, VetheaBlockHelper.dreamdirt.blockID);
		world.setBlock(i + 5, j + 1, k + 1, VetheaBlockHelper.dreamdirt.blockID);
		world.setBlock(i + 5, j + 1, k + 2, VetheaBlockHelper.dreamdirt.blockID);
		world.setBlock(i + 5, j + 1, k + 3, VetheaBlockHelper.dreamdirt.blockID);
		world.setBlock(i + 5, j + 1, k + 4, VetheaBlockHelper.dreamdirt.blockID);
		world.setBlock(i + 5, j + 1, k + 5, VetheaBlockHelper.dreamdirt.blockID);
		world.setBlock(i + 5, j + 1, k + 6, VetheaBlockHelper.cryptWall.blockID);
		world.setBlock(i + 5, j + 1, k + 7, 0);
		world.setBlock(i + 5, j + 1, k + 8, 0);
		world.setBlock(i + 5, j + 1, k + 9, VetheaBlockHelper.cryptWall.blockID);
		world.setBlock(i + 5, j + 1, k + 10, VetheaBlockHelper.dreamdirt.blockID);
		world.setBlock(i + 5, j + 2, k + 0, VetheaBlockHelper.dreamdirt.blockID);
		world.setBlock(i + 5, j + 2, k + 1, VetheaBlockHelper.dreamdirt.blockID);
		world.setBlock(i + 5, j + 2, k + 2, VetheaBlockHelper.dreamdirt.blockID);
		world.setBlock(i + 5, j + 2, k + 3, VetheaBlockHelper.cryptWall.blockID);
		world.setBlock(i + 5, j + 2, k + 4, VetheaBlockHelper.cryptWall.blockID);
		world.setBlock(i + 5, j + 2, k + 5, VetheaBlockHelper.cryptWall.blockID);
		world.setBlock(i + 5, j + 2, k + 6, VetheaBlockHelper.cryptWall.blockID);
		world.setBlock(i + 5, j + 2, k + 7, 0);
		world.setBlock(i + 5, j + 2, k + 8, 0);
		world.setBlock(i + 5, j + 2, k + 9, VetheaBlockHelper.cryptWall.blockID);
		world.setBlock(i + 5, j + 2, k + 10, VetheaBlockHelper.dreamdirt.blockID);
		world.setBlock(i + 5, j + 3, k + 0, VetheaBlockHelper.dreamdirt.blockID);
		world.setBlock(i + 5, j + 3, k + 1, VetheaBlockHelper.dreamdirt.blockID);
		world.setBlock(i + 5, j + 3, k + 2, VetheaBlockHelper.dreamdirt.blockID);
		world.setBlock(i + 5, j + 3, k + 3, VetheaBlockHelper.hungerstone2.blockID);
		world.setBlock(i + 5, j + 3, k + 4, 0);
		world.setBlock(i + 5, j + 3, k + 5, 0);
		world.setBlock(i + 5, j + 3, k + 6, VetheaBlockHelper.hungerstone2.blockID);
		world.setBlock(i + 5, j + 3, k + 7, VetheaBlockHelper.hungerstone2.blockID);
		world.setBlock(i + 5, j + 3, k + 8, VetheaBlockHelper.hungerstone2.blockID);
		world.setBlock(i + 5, j + 3, k + 9, VetheaBlockHelper.dreamdirt.blockID);
		world.setBlock(i + 5, j + 3, k + 10, VetheaBlockHelper.dreamdirt.blockID);
		world.setBlock(i + 5, j + 4, k + 0, VetheaBlockHelper.dreamdirt.blockID);
		world.setBlock(i + 5, j + 4, k + 1, VetheaBlockHelper.dreamdirt.blockID);
		world.setBlock(i + 5, j + 4, k + 2, VetheaBlockHelper.dreamdirt.blockID);
		world.setBlock(i + 5, j + 4, k + 3, VetheaBlockHelper.hungerstone2.blockID);
		world.setBlock(i + 5, j + 4, k + 4, 0);
		world.setBlock(i + 5, j + 4, k + 5, 0);
		world.setBlock(i + 5, j + 4, k + 6, VetheaBlockHelper.hungerstone2.blockID);
		world.setBlock(i + 5, j + 4, k + 7, VetheaBlockHelper.dreamdirt.blockID);
		world.setBlock(i + 5, j + 4, k + 8, VetheaBlockHelper.dreamdirt.blockID);
		world.setBlock(i + 5, j + 4, k + 9, VetheaBlockHelper.dreamdirt.blockID);
		world.setBlock(i + 5, j + 4, k + 10, VetheaBlockHelper.dreamdirt.blockID);
		world.setBlock(i + 5, j + 5, k + 0, VetheaBlockHelper.metalCaging.blockID);
		world.setBlock(i + 5, j + 5, k + 1, 0);
		world.setBlock(i + 5, j + 5, k + 2, 0);
		world.setBlock(i + 5, j + 5, k + 3, VetheaBlockHelper.hungerstone1.blockID);
		world.setBlock(i + 5, j + 5, k + 4, 0);
		world.setBlock(i + 5, j + 5, k + 5, 0);
		world.setBlock(i + 5, j + 5, k + 6, VetheaBlockHelper.hungerstone1.blockID);
		world.setBlock(i + 5, j + 5, k + 7, 0);
		world.setBlock(i + 5, j + 5, k + 8, 0);
		world.setBlock(i + 5, j + 5, k + 9, 0);
		world.setBlock(i + 5, j + 5, k + 10, VetheaBlockHelper.metalCaging.blockID);
		world.setBlock(i + 5, j + 6, k + 0, VetheaBlockHelper.hungerstone1.blockID);
		world.setBlock(i + 5, j + 6, k + 1, 0);
		world.setBlock(i + 5, j + 6, k + 2, 0);
		world.setBlock(i + 5, j + 6, k + 3, VetheaBlockHelper.hungerstone2.blockID);
		world.setBlock(i + 5, j + 6, k + 4, 0);
		world.setBlock(i + 5, j + 6, k + 5, 0);
		world.setBlock(i + 5, j + 6, k + 6, VetheaBlockHelper.hungerstone2.blockID);
		world.setBlock(i + 5, j + 6, k + 7, 0);
		world.setBlock(i + 5, j + 6, k + 8, 0);
		world.setBlock(i + 5, j + 6, k + 9, 0);
		world.setBlock(i + 5, j + 6, k + 10, VetheaBlockHelper.hungerstone1.blockID);
		world.setBlock(i + 5, j + 7, k + 0, 0);
		world.setBlock(i + 5, j + 7, k + 1, 0);
		world.setBlock(i + 5, j + 7, k + 2, 0);
		world.setBlock(i + 5, j + 7, k + 3, 0);
		world.setBlock(i + 5, j + 7, k + 4, VetheaBlockHelper.hungerstone1.blockID);
		world.setBlock(i + 5, j + 7, k + 5, VetheaBlockHelper.hungerstone1.blockID);
		world.setBlock(i + 5, j + 7, k + 6, 0);
		world.setBlock(i + 5, j + 7, k + 7, 0);
		world.setBlock(i + 5, j + 7, k + 8, 0);
		world.setBlock(i + 5, j + 7, k + 9, 0);
		world.setBlock(i + 5, j + 7, k + 10, 0);
		world.setBlock(i + 5, j + 8, k + 0, 0);
		world.setBlock(i + 5, j + 8, k + 1, 0);
		world.setBlock(i + 5, j + 8, k + 2, 0);
		world.setBlock(i + 5, j + 8, k + 3, 0);
		world.setBlock(i + 5, j + 8, k + 4, 0);
		world.setBlock(i + 5, j + 8, k + 5, 0);
		world.setBlock(i + 5, j + 8, k + 6, 0);
		world.setBlock(i + 5, j + 8, k + 7, 0);
		world.setBlock(i + 5, j + 8, k + 8, 0);
		world.setBlock(i + 5, j + 8, k + 9, 0);
		world.setBlock(i + 5, j + 8, k + 10, 0);
		world.setBlock(i + 5, j + 9, k + 0, 0);
		world.setBlock(i + 5, j + 9, k + 1, 0);
		world.setBlock(i + 5, j + 9, k + 2, 0);
		world.setBlock(i + 5, j + 9, k + 3, 0);
		world.setBlock(i + 5, j + 9, k + 4, 0);
		world.setBlock(i + 5, j + 9, k + 5, 0);
		world.setBlock(i + 5, j + 9, k + 6, 0);
		world.setBlock(i + 5, j + 9, k + 7, 0);
		world.setBlock(i + 5, j + 9, k + 8, 0);
		world.setBlock(i + 5, j + 9, k + 9, 0);
		world.setBlock(i + 5, j + 9, k + 10, 0);
		world.setBlock(i + 5, j + 10, k + 0, 0);
		world.setBlock(i + 5, j + 10, k + 1, 0);
		world.setBlock(i + 5, j + 10, k + 2, 0);
		world.setBlock(i + 5, j + 10, k + 3, 0);
		world.setBlock(i + 5, j + 10, k + 4, 0);
		world.setBlock(i + 5, j + 10, k + 5, 0);
		world.setBlock(i + 5, j + 10, k + 6, 0);
		world.setBlock(i + 5, j + 10, k + 7, 0);
		world.setBlock(i + 5, j + 10, k + 8, 0);
		world.setBlock(i + 5, j + 10, k + 9, 0);
		world.setBlock(i + 5, j + 10, k + 10, 0);
		world.setBlock(i + 6, j + 0, k + 0, VetheaBlockHelper.dreamdirt.blockID);
		world.setBlock(i + 6, j + 0, k + 1, VetheaBlockHelper.dreamdirt.blockID);
		world.setBlock(i + 6, j + 0, k + 2, VetheaBlockHelper.dreamdirt.blockID);
		world.setBlock(i + 6, j + 0, k + 3, VetheaBlockHelper.dreamdirt.blockID);
		world.setBlock(i + 6, j + 0, k + 4, VetheaBlockHelper.dreamdirt.blockID);
		world.setBlock(i + 6, j + 0, k + 5, VetheaBlockHelper.dreamdirt.blockID);
		world.setBlock(i + 6, j + 0, k + 6, VetheaBlockHelper.dreamdirt.blockID);
		world.setBlock(i + 6, j + 0, k + 7, VetheaBlockHelper.cryptFloor.blockID);
		world.setBlock(i + 6, j + 0, k + 8, VetheaBlockHelper.cryptFloor.blockID);
		world.setBlock(i + 6, j + 0, k + 9, VetheaBlockHelper.dreamdirt.blockID);
		world.setBlock(i + 6, j + 0, k + 10, VetheaBlockHelper.dreamdirt.blockID);
		world.setBlock(i + 6, j + 1, k + 0, VetheaBlockHelper.dreamdirt.blockID);
		world.setBlock(i + 6, j + 1, k + 1, VetheaBlockHelper.dreamdirt.blockID);
		world.setBlock(i + 6, j + 1, k + 2, VetheaBlockHelper.dreamdirt.blockID);
		world.setBlock(i + 6, j + 1, k + 3, VetheaBlockHelper.dreamdirt.blockID);
		world.setBlock(i + 6, j + 1, k + 4, VetheaBlockHelper.dreamdirt.blockID);
		world.setBlock(i + 6, j + 1, k + 5, VetheaBlockHelper.dreamdirt.blockID);
		world.setBlock(i + 6, j + 1, k + 6, VetheaBlockHelper.cryptWall.blockID);
		world.setBlock(i + 6, j + 1, k + 7, 0);
		world.setBlock(i + 6, j + 1, k + 8, 0);
		world.setBlock(i + 6, j + 1, k + 9, VetheaBlockHelper.cryptWall.blockID);
		world.setBlock(i + 6, j + 1, k + 10, VetheaBlockHelper.dreamdirt.blockID);
		world.setBlock(i + 6, j + 2, k + 0, VetheaBlockHelper.dreamdirt.blockID);
		world.setBlock(i + 6, j + 2, k + 1, VetheaBlockHelper.dreamdirt.blockID);
		world.setBlock(i + 6, j + 2, k + 2, VetheaBlockHelper.dreamdirt.blockID);
		world.setBlock(i + 6, j + 2, k + 3, VetheaBlockHelper.dreamdirt.blockID);
		world.setBlock(i + 6, j + 2, k + 4, VetheaBlockHelper.dreamdirt.blockID);
		world.setBlock(i + 6, j + 2, k + 5, VetheaBlockHelper.dreamdirt.blockID);
		world.setBlock(i + 6, j + 2, k + 6, VetheaBlockHelper.cryptWall.blockID);
		world.setBlock(i + 6, j + 2, k + 7, 0);
		world.setBlock(i + 6, j + 2, k + 8, 0);
		world.setBlock(i + 6, j + 2, k + 9, VetheaBlockHelper.cryptWall.blockID);
		world.setBlock(i + 6, j + 2, k + 10, VetheaBlockHelper.dreamdirt.blockID);
		world.setBlock(i + 6, j + 3, k + 0, VetheaBlockHelper.dreamdirt.blockID);
		world.setBlock(i + 6, j + 3, k + 1, VetheaBlockHelper.dreamdirt.blockID);
		world.setBlock(i + 6, j + 3, k + 2, VetheaBlockHelper.dreamdirt.blockID);
		world.setBlock(i + 6, j + 3, k + 3, VetheaBlockHelper.dreamdirt.blockID);
		world.setBlock(i + 6, j + 3, k + 4, VetheaBlockHelper.cryptWall.blockID);
		world.setBlock(i + 6, j + 3, k + 5, VetheaBlockHelper.cryptWall.blockID);
		world.setBlock(i + 6, j + 3, k + 6, VetheaBlockHelper.dreamdirt.blockID);
		world.setBlock(i + 6, j + 3, k + 7, VetheaBlockHelper.hungerstone2.blockID);
		world.setBlock(i + 6, j + 3, k + 8, VetheaBlockHelper.hungerstone2.blockID);
		world.setBlock(i + 6, j + 3, k + 9, VetheaBlockHelper.dreamdirt.blockID);
		world.setBlock(i + 6, j + 3, k + 10, VetheaBlockHelper.dreamdirt.blockID);
		world.setBlock(i + 6, j + 4, k + 0, VetheaBlockHelper.dreamdirt.blockID);
		world.setBlock(i + 6, j + 4, k + 1, VetheaBlockHelper.dreamdirt.blockID);
		world.setBlock(i + 6, j + 4, k + 2, VetheaBlockHelper.dreamdirt.blockID);
		world.setBlock(i + 6, j + 4, k + 3, VetheaBlockHelper.hungerstone2.blockID);
		world.setBlock(i + 6, j + 4, k + 4, 0);
		world.setBlock(i + 6, j + 4, k + 5, 0);
		world.setBlock(i + 6, j + 4, k + 6, VetheaBlockHelper.hungerstone2.blockID);
		world.setBlock(i + 6, j + 4, k + 7, VetheaBlockHelper.dreamdirt.blockID);
		world.setBlock(i + 6, j + 4, k + 8, VetheaBlockHelper.dreamdirt.blockID);
		world.setBlock(i + 6, j + 4, k + 9, VetheaBlockHelper.dreamdirt.blockID);
		world.setBlock(i + 6, j + 4, k + 10, VetheaBlockHelper.dreamdirt.blockID);
		world.setBlock(i + 6, j + 5, k + 0, VetheaBlockHelper.metalCaging.blockID);
		world.setBlock(i + 6, j + 5, k + 1, 0);
		world.setBlock(i + 6, j + 5, k + 2, 0);
		world.setBlock(i + 6, j + 5, k + 3, VetheaBlockHelper.hungerstone1.blockID);
		world.setBlock(i + 6, j + 5, k + 4, 0);
		world.setBlock(i + 6, j + 5, k + 5, 0);
		world.setBlock(i + 6, j + 5, k + 6, VetheaBlockHelper.hungerstone1.blockID);
		world.setBlock(i + 6, j + 5, k + 7, 0);
		world.setBlock(i + 6, j + 5, k + 8, 0);
		world.setBlock(i + 6, j + 5, k + 9, 0);
		world.setBlock(i + 6, j + 5, k + 10, VetheaBlockHelper.metalCaging.blockID);
		world.setBlock(i + 6, j + 6, k + 0, VetheaBlockHelper.hungerstone1.blockID);
		world.setBlock(i + 6, j + 6, k + 1, 0);
		world.setBlock(i + 6, j + 6, k + 2, 0);
		world.setBlock(i + 6, j + 6, k + 3, VetheaBlockHelper.hungerstone2.blockID);
		world.setBlock(i + 6, j + 6, k + 4, 0);
		world.setBlock(i + 6, j + 6, k + 5, 0);
		world.setBlock(i + 6, j + 6, k + 6, VetheaBlockHelper.hungerstone2.blockID);
		world.setBlock(i + 6, j + 6, k + 7, 0);
		world.setBlock(i + 6, j + 6, k + 8, 0);
		world.setBlock(i + 6, j + 6, k + 9, 0);
		world.setBlock(i + 6, j + 6, k + 10, VetheaBlockHelper.hungerstone1.blockID);
		world.setBlock(i + 6, j + 7, k + 0, 0);
		world.setBlock(i + 6, j + 7, k + 1, 0);
		world.setBlock(i + 6, j + 7, k + 2, 0);
		world.setBlock(i + 6, j + 7, k + 3, 0);
		world.setBlock(i + 6, j + 7, k + 4, VetheaBlockHelper.hungerstone1.blockID);
		world.setBlock(i + 6, j + 7, k + 5, VetheaBlockHelper.hungerstone1.blockID);
		world.setBlock(i + 6, j + 7, k + 6, 0);
		world.setBlock(i + 6, j + 7, k + 7, 0);
		world.setBlock(i + 6, j + 7, k + 8, 0);
		world.setBlock(i + 6, j + 7, k + 9, 0);
		world.setBlock(i + 6, j + 7, k + 10, 0);
		world.setBlock(i + 6, j + 8, k + 0, 0);
		world.setBlock(i + 6, j + 8, k + 1, 0);
		world.setBlock(i + 6, j + 8, k + 2, 0);
		world.setBlock(i + 6, j + 8, k + 3, 0);
		world.setBlock(i + 6, j + 8, k + 4, 0);
		world.setBlock(i + 6, j + 8, k + 5, 0);
		world.setBlock(i + 6, j + 8, k + 6, 0);
		world.setBlock(i + 6, j + 8, k + 7, 0);
		world.setBlock(i + 6, j + 8, k + 8, 0);
		world.setBlock(i + 6, j + 8, k + 9, 0);
		world.setBlock(i + 6, j + 8, k + 10, 0);
		world.setBlock(i + 6, j + 9, k + 0, 0);
		world.setBlock(i + 6, j + 9, k + 1, 0);
		world.setBlock(i + 6, j + 9, k + 2, 0);
		world.setBlock(i + 6, j + 9, k + 3, 0);
		world.setBlock(i + 6, j + 9, k + 4, 0);
		world.setBlock(i + 6, j + 9, k + 5, 0);
		world.setBlock(i + 6, j + 9, k + 6, 0);
		world.setBlock(i + 6, j + 9, k + 7, 0);
		world.setBlock(i + 6, j + 9, k + 8, 0);
		world.setBlock(i + 6, j + 9, k + 9, 0);
		world.setBlock(i + 6, j + 9, k + 10, 0);
		world.setBlock(i + 6, j + 10, k + 0, 0);
		world.setBlock(i + 6, j + 10, k + 1, 0);
		world.setBlock(i + 6, j + 10, k + 2, 0);
		world.setBlock(i + 6, j + 10, k + 3, 0);
		world.setBlock(i + 6, j + 10, k + 4, 0);
		world.setBlock(i + 6, j + 10, k + 5, 0);
		world.setBlock(i + 6, j + 10, k + 6, 0);
		world.setBlock(i + 6, j + 10, k + 7, 0);
		world.setBlock(i + 6, j + 10, k + 8, 0);
		world.setBlock(i + 6, j + 10, k + 9, 0);
		world.setBlock(i + 6, j + 10, k + 10, 0);
		world.setBlock(i + 7, j + 0, k + 0, VetheaBlockHelper.dreamdirt.blockID);
		world.setBlock(i + 7, j + 0, k + 1, VetheaBlockHelper.dreamdirt.blockID);
		world.setBlock(i + 7, j + 0, k + 2, VetheaBlockHelper.dreamdirt.blockID);
		world.setBlock(i + 7, j + 0, k + 3, VetheaBlockHelper.dreamdirt.blockID);
		world.setBlock(i + 7, j + 0, k + 4, VetheaBlockHelper.dreamdirt.blockID);
		world.setBlock(i + 7, j + 0, k + 5, VetheaBlockHelper.dreamdirt.blockID);
		world.setBlock(i + 7, j + 0, k + 6, VetheaBlockHelper.dreamdirt.blockID);
		world.setBlock(i + 7, j + 0, k + 7, VetheaBlockHelper.cryptFloor.blockID);
		world.setBlock(i + 7, j + 0, k + 8, VetheaBlockHelper.cryptFloor.blockID);
		world.setBlock(i + 7, j + 0, k + 9, VetheaBlockHelper.dreamdirt.blockID);
		world.setBlock(i + 7, j + 0, k + 10, VetheaBlockHelper.dreamdirt.blockID);
		world.setBlock(i + 7, j + 1, k + 0, VetheaBlockHelper.dreamdirt.blockID);
		world.setBlock(i + 7, j + 1, k + 1, VetheaBlockHelper.dreamdirt.blockID);
		world.setBlock(i + 7, j + 1, k + 2, VetheaBlockHelper.dreamdirt.blockID);
		world.setBlock(i + 7, j + 1, k + 3, VetheaBlockHelper.dreamdirt.blockID);
		world.setBlock(i + 7, j + 1, k + 4, VetheaBlockHelper.dreamdirt.blockID);
		world.setBlock(i + 7, j + 1, k + 5, VetheaBlockHelper.cryptWall.blockID);
		world.setBlock(i + 7, j + 1, k + 6, VetheaBlockHelper.cryptWall.blockID);
		world.setBlock(i + 7, j + 1, k + 7, 0);
		world.setBlock(i + 7, j + 1, k + 8, 0);
		world.setBlock(i + 7, j + 1, k + 9, VetheaBlockHelper.cryptWall.blockID);
		world.setBlock(i + 7, j + 1, k + 10, VetheaBlockHelper.dreamdirt.blockID);
		world.setBlock(i + 7, j + 2, k + 0, VetheaBlockHelper.dreamdirt.blockID);
		world.setBlock(i + 7, j + 2, k + 1, VetheaBlockHelper.dreamdirt.blockID);
		world.setBlock(i + 7, j + 2, k + 2, VetheaBlockHelper.dreamdirt.blockID);
		world.setBlock(i + 7, j + 2, k + 3, VetheaBlockHelper.dreamdirt.blockID);
		world.setBlock(i + 7, j + 2, k + 4, VetheaBlockHelper.dreamdirt.blockID);
		world.setBlock(i + 7, j + 2, k + 5, VetheaBlockHelper.cryptWall.blockID);
		world.setBlock(i + 7, j + 2, k + 6, VetheaBlockHelper.firecrystal.blockID);
		world.setBlock(i + 7, j + 2, k + 7, 0);
		world.setBlock(i + 7, j + 2, k + 8, 0);
		world.setBlock(i + 7, j + 2, k + 9, VetheaBlockHelper.cryptWall.blockID);
		world.setBlock(i + 7, j + 2, k + 10, VetheaBlockHelper.dreamdirt.blockID);
		world.setBlock(i + 7, j + 3, k + 0, VetheaBlockHelper.dreamdirt.blockID);
		world.setBlock(i + 7, j + 3, k + 1, VetheaBlockHelper.dreamdirt.blockID);
		world.setBlock(i + 7, j + 3, k + 2, VetheaBlockHelper.dreamdirt.blockID);
		world.setBlock(i + 7, j + 3, k + 3, VetheaBlockHelper.dreamdirt.blockID);
		world.setBlock(i + 7, j + 3, k + 4, VetheaBlockHelper.dreamdirt.blockID);
		world.setBlock(i + 7, j + 3, k + 5, VetheaBlockHelper.dreamdirt.blockID);
		world.setBlock(i + 7, j + 3, k + 6, VetheaBlockHelper.dreamdirt.blockID);
		world.setBlock(i + 7, j + 3, k + 7, VetheaBlockHelper.hungerstone2.blockID);
		world.setBlock(i + 7, j + 3, k + 8, VetheaBlockHelper.hungerstone2.blockID);
		world.setBlock(i + 7, j + 3, k + 9, VetheaBlockHelper.dreamdirt.blockID);
		world.setBlock(i + 7, j + 3, k + 10, VetheaBlockHelper.dreamdirt.blockID);
		world.setBlock(i + 7, j + 4, k + 0, VetheaBlockHelper.dreamdirt.blockID);
		world.setBlock(i + 7, j + 4, k + 1, VetheaBlockHelper.dreamdirt.blockID);
		world.setBlock(i + 7, j + 4, k + 2, VetheaBlockHelper.dreamdirt.blockID);
		world.setBlock(i + 7, j + 4, k + 3, VetheaBlockHelper.hungerstone2.blockID);
		world.setBlock(i + 7, j + 4, k + 4, VetheaBlockHelper.cryptWall.blockID);
		world.setBlock(i + 7, j + 4, k + 5, VetheaBlockHelper.cryptWall.blockID);
		world.setBlock(i + 7, j + 4, k + 6, VetheaBlockHelper.hungerstone2.blockID);
		world.setBlock(i + 7, j + 4, k + 7, VetheaBlockHelper.dreamdirt.blockID);
		world.setBlock(i + 7, j + 4, k + 8, VetheaBlockHelper.dreamdirt.blockID);
		world.setBlock(i + 7, j + 4, k + 9, VetheaBlockHelper.dreamdirt.blockID);
		world.setBlock(i + 7, j + 4, k + 10, VetheaBlockHelper.dreamdirt.blockID);
		world.setBlock(i + 7, j + 5, k + 0, VetheaBlockHelper.metalCaging.blockID);
		world.setBlock(i + 7, j + 5, k + 1, 0);
		world.setBlock(i + 7, j + 5, k + 2, 0);
		world.setBlock(i + 7, j + 5, k + 3, VetheaBlockHelper.hungerstone1.blockID);
		world.setBlock(i + 7, j + 5, k + 4, 0);
		world.setBlock(i + 7, j + 5, k + 5, 0);
		world.setBlock(i + 7, j + 5, k + 6, VetheaBlockHelper.hungerstone1.blockID);
		world.setBlock(i + 7, j + 5, k + 7, 0);
		world.setBlock(i + 7, j + 5, k + 8, 0);
		world.setBlock(i + 7, j + 5, k + 9, 0);
		world.setBlock(i + 7, j + 5, k + 10, VetheaBlockHelper.metalCaging.blockID);
		world.setBlock(i + 7, j + 6, k + 0, VetheaBlockHelper.hungerstone1.blockID);
		world.setBlock(i + 7, j + 6, k + 1, 0);
		world.setBlock(i + 7, j + 6, k + 2, VetheaBlockHelper.firecrystal.blockID);
		world.setBlock(i + 7, j + 6, k + 3, VetheaBlockHelper.hungerstone2.blockID);
		world.setBlock(i + 7, j + 6, k + 4, 0);
		world.setBlock(i + 7, j + 6, k + 5, 0);
		world.setBlock(i + 7, j + 6, k + 6, VetheaBlockHelper.hungerstone2.blockID);
		world.setBlock(i + 7, j + 6, k + 7, VetheaBlockHelper.firecrystal.blockID);
		world.setBlock(i + 7, j + 6, k + 8, 0);
		world.setBlock(i + 7, j + 6, k + 9, 0);
		world.setBlock(i + 7, j + 6, k + 10, VetheaBlockHelper.hungerstone1.blockID);
		world.setBlock(i + 7, j + 7, k + 0, 0);
		world.setBlock(i + 7, j + 7, k + 1, 0);
		world.setBlock(i + 7, j + 7, k + 2, VetheaBlockHelper.hungerstone2.blockID);
		world.setBlock(i + 7, j + 7, k + 3, VetheaBlockHelper.hungerstone2.blockID);
		world.setBlock(i + 7, j + 7, k + 4, VetheaBlockHelper.hungerstone1.blockID);
		world.setBlock(i + 7, j + 7, k + 5, VetheaBlockHelper.hungerstone1.blockID);
		world.setBlock(i + 7, j + 7, k + 6, VetheaBlockHelper.hungerstone2.blockID);
		world.setBlock(i + 7, j + 7, k + 7, VetheaBlockHelper.hungerstone2.blockID);
		world.setBlock(i + 7, j + 7, k + 8, 0);
		world.setBlock(i + 7, j + 7, k + 9, 0);
		world.setBlock(i + 7, j + 7, k + 10, 0);
		world.setBlock(i + 7, j + 8, k + 0, 0);
		world.setBlock(i + 7, j + 8, k + 1, 0);
		world.setBlock(i + 7, j + 8, k + 2, 0);
		world.setBlock(i + 7, j + 8, k + 3, 0);
		world.setBlock(i + 7, j + 8, k + 4, 0);
		world.setBlock(i + 7, j + 8, k + 5, 0);
		world.setBlock(i + 7, j + 8, k + 6, 0);
		world.setBlock(i + 7, j + 8, k + 7, 0);
		world.setBlock(i + 7, j + 8, k + 8, 0);
		world.setBlock(i + 7, j + 8, k + 9, 0);
		world.setBlock(i + 7, j + 8, k + 10, 0);
		world.setBlock(i + 7, j + 9, k + 0, 0);
		world.setBlock(i + 7, j + 9, k + 1, 0);
		world.setBlock(i + 7, j + 9, k + 2, 0);
		world.setBlock(i + 7, j + 9, k + 3, 0);
		world.setBlock(i + 7, j + 9, k + 4, 0);
		world.setBlock(i + 7, j + 9, k + 5, 0);
		world.setBlock(i + 7, j + 9, k + 6, 0);
		world.setBlock(i + 7, j + 9, k + 7, 0);
		world.setBlock(i + 7, j + 9, k + 8, 0);
		world.setBlock(i + 7, j + 9, k + 9, 0);
		world.setBlock(i + 7, j + 9, k + 10, 0);
		world.setBlock(i + 7, j + 10, k + 0, 0);
		world.setBlock(i + 7, j + 10, k + 1, 0);
		world.setBlock(i + 7, j + 10, k + 2, 0);
		world.setBlock(i + 7, j + 10, k + 3, 0);
		world.setBlock(i + 7, j + 10, k + 4, 0);
		world.setBlock(i + 7, j + 10, k + 5, 0);
		world.setBlock(i + 7, j + 10, k + 6, 0);
		world.setBlock(i + 7, j + 10, k + 7, 0);
		world.setBlock(i + 7, j + 10, k + 8, 0);
		world.setBlock(i + 7, j + 10, k + 9, 0);
		world.setBlock(i + 7, j + 10, k + 10, 0);
		world.setBlock(i + 8, j + 0, k + 0, VetheaBlockHelper.dreamdirt.blockID);
		world.setBlock(i + 8, j + 0, k + 1, VetheaBlockHelper.dreamdirt.blockID);
		world.setBlock(i + 8, j + 0, k + 2, VetheaBlockHelper.dreamdirt.blockID);
		world.setBlock(i + 8, j + 0, k + 3, VetheaBlockHelper.dreamdirt.blockID);
		world.setBlock(i + 8, j + 0, k + 4, VetheaBlockHelper.dreamdirt.blockID);
		world.setBlock(i + 8, j + 0, k + 5, VetheaBlockHelper.cryptFloor.blockID);
		world.setBlock(i + 8, j + 0, k + 6, VetheaBlockHelper.cryptFloor.blockID);
		world.setBlock(i + 8, j + 0, k + 7, VetheaBlockHelper.cryptFloor.blockID);
		world.setBlock(i + 8, j + 0, k + 8, VetheaBlockHelper.cryptFloor.blockID);
		world.setBlock(i + 8, j + 0, k + 9, VetheaBlockHelper.dreamdirt.blockID);
		world.setBlock(i + 8, j + 0, k + 10, VetheaBlockHelper.dreamdirt.blockID);
		world.setBlock(i + 8, j + 1, k + 0, VetheaBlockHelper.dreamdirt.blockID);
		world.setBlock(i + 8, j + 1, k + 1, VetheaBlockHelper.dreamdirt.blockID);
		world.setBlock(i + 8, j + 1, k + 2, VetheaBlockHelper.dreamdirt.blockID);
		world.setBlock(i + 8, j + 1, k + 3, VetheaBlockHelper.dreamdirt.blockID);
		world.setBlock(i + 8, j + 1, k + 4, VetheaBlockHelper.cryptWall.blockID);
		world.setBlock(i + 8, j + 1, k + 5, VetheaBlockHelper.vermenousSpawner.blockID);
		world.setBlock(i + 8, j + 1, k + 6, 0);
		world.setBlock(i + 8, j + 1, k + 7, 0);
		world.setBlock(i + 8, j + 1, k + 8, 0);
		world.setBlock(i + 8, j + 1, k + 9, VetheaBlockHelper.cryptWall.blockID);
		world.setBlock(i + 8, j + 1, k + 10, VetheaBlockHelper.dreamdirt.blockID);
		world.setBlock(i + 8, j + 2, k + 0, VetheaBlockHelper.dreamdirt.blockID);
		world.setBlock(i + 8, j + 2, k + 1, VetheaBlockHelper.dreamdirt.blockID);
		world.setBlock(i + 8, j + 2, k + 2, VetheaBlockHelper.dreamdirt.blockID);
		world.setBlock(i + 8, j + 2, k + 3, VetheaBlockHelper.dreamdirt.blockID);
		world.setBlock(i + 8, j + 2, k + 4, VetheaBlockHelper.cryptWall.blockID);
		world.setBlock(i + 8, j + 2, k + 5, 0);
		world.setBlock(i + 8, j + 2, k + 6, 0);
		world.setBlock(i + 8, j + 2, k + 7, 0);
		world.setBlock(i + 8, j + 2, k + 8, 0);
		world.setBlock(i + 8, j + 2, k + 9, VetheaBlockHelper.cryptWall.blockID);
		world.setBlock(i + 8, j + 2, k + 10, VetheaBlockHelper.dreamdirt.blockID);
		world.setBlock(i + 8, j + 3, k + 0, VetheaBlockHelper.dreamdirt.blockID);
		world.setBlock(i + 8, j + 3, k + 1, VetheaBlockHelper.dreamdirt.blockID);
		world.setBlock(i + 8, j + 3, k + 2, VetheaBlockHelper.dreamdirt.blockID);
		world.setBlock(i + 8, j + 3, k + 3, VetheaBlockHelper.dreamdirt.blockID);
		world.setBlock(i + 8, j + 3, k + 4, VetheaBlockHelper.dreamdirt.blockID);
		world.setBlock(i + 8, j + 3, k + 5, VetheaBlockHelper.hungerstone2.blockID);
		world.setBlock(i + 8, j + 3, k + 6, VetheaBlockHelper.hungerstone2.blockID);
		world.setBlock(i + 8, j + 3, k + 7, VetheaBlockHelper.hungerstone2.blockID);
		world.setBlock(i + 8, j + 3, k + 8, VetheaBlockHelper.hungerstone2.blockID);
		world.setBlock(i + 8, j + 3, k + 9, VetheaBlockHelper.dreamdirt.blockID);
		world.setBlock(i + 8, j + 3, k + 10, VetheaBlockHelper.dreamdirt.blockID);
		world.setBlock(i + 8, j + 4, k + 0, VetheaBlockHelper.dreamdirt.blockID);
		world.setBlock(i + 8, j + 4, k + 1, VetheaBlockHelper.dreamdirt.blockID);
		world.setBlock(i + 8, j + 4, k + 2, VetheaBlockHelper.dreamdirt.blockID);
		world.setBlock(i + 8, j + 4, k + 3, VetheaBlockHelper.dreamdirt.blockID);
		world.setBlock(i + 8, j + 4, k + 4, VetheaBlockHelper.cryptWall.blockID);
		world.setBlock(i + 8, j + 4, k + 5, VetheaBlockHelper.cryptWall.blockID);
		world.setBlock(i + 8, j + 4, k + 6, VetheaBlockHelper.dreamdirt.blockID);
		world.setBlock(i + 8, j + 4, k + 7, VetheaBlockHelper.dreamdirt.blockID);
		world.setBlock(i + 8, j + 4, k + 8, VetheaBlockHelper.dreamdirt.blockID);
		world.setBlock(i + 8, j + 4, k + 9, VetheaBlockHelper.dreamdirt.blockID);
		world.setBlock(i + 8, j + 4, k + 10, VetheaBlockHelper.dreamdirt.blockID);
		world.setBlock(i + 8, j + 5, k + 0, VetheaBlockHelper.metalCaging.blockID);
		world.setBlock(i + 8, j + 5, k + 1, 0);
		world.setBlock(i + 8, j + 5, k + 2, 0);
		world.setBlock(i + 8, j + 5, k + 3, VetheaBlockHelper.hungerstone1.blockID);
		world.setBlock(i + 8, j + 5, k + 4, 0);
		world.setBlock(i + 8, j + 5, k + 5, 0);
		world.setBlock(i + 8, j + 5, k + 6, VetheaBlockHelper.hungerstone1.blockID);
		world.setBlock(i + 8, j + 5, k + 7, 0);
		world.setBlock(i + 8, j + 5, k + 8, 0);
		world.setBlock(i + 8, j + 5, k + 9, 0);
		world.setBlock(i + 8, j + 5, k + 10, VetheaBlockHelper.metalCaging.blockID);
		world.setBlock(i + 8, j + 6, k + 0, VetheaBlockHelper.hungerstone1.blockID);
		world.setBlock(i + 8, j + 6, k + 1, 0);
		world.setBlock(i + 8, j + 6, k + 2, 0);
		world.setBlock(i + 8, j + 6, k + 3, 0);
		world.setBlock(i + 8, j + 6, k + 4, 0);
		world.setBlock(i + 8, j + 6, k + 5, 0);
		world.setBlock(i + 8, j + 6, k + 6, 0);
		world.setBlock(i + 8, j + 6, k + 7, 0);
		world.setBlock(i + 8, j + 6, k + 8, 0);
		world.setBlock(i + 8, j + 6, k + 9, 0);
		world.setBlock(i + 8, j + 6, k + 10, VetheaBlockHelper.hungerstone1.blockID);
		world.setBlock(i + 8, j + 7, k + 0, 0);
		world.setBlock(i + 8, j + 7, k + 1, 0);
		world.setBlock(i + 8, j + 7, k + 2, 0);
		world.setBlock(i + 8, j + 7, k + 3, 0);
		world.setBlock(i + 8, j + 7, k + 4, VetheaBlockHelper.hungerstone1.blockID);
		world.setBlock(i + 8, j + 7, k + 5, VetheaBlockHelper.hungerstone1.blockID);
		world.setBlock(i + 8, j + 7, k + 6, 0);
		world.setBlock(i + 8, j + 7, k + 7, 0);
		world.setBlock(i + 8, j + 7, k + 8, 0);
		world.setBlock(i + 8, j + 7, k + 9, 0);
		world.setBlock(i + 8, j + 7, k + 10, 0);
		world.setBlock(i + 8, j + 8, k + 0, 0);
		world.setBlock(i + 8, j + 8, k + 1, 0);
		world.setBlock(i + 8, j + 8, k + 2, 0);
		world.setBlock(i + 8, j + 8, k + 3, 0);
		world.setBlock(i + 8, j + 8, k + 4, 0);
		world.setBlock(i + 8, j + 8, k + 5, 0);
		world.setBlock(i + 8, j + 8, k + 6, 0);
		world.setBlock(i + 8, j + 8, k + 7, 0);
		world.setBlock(i + 8, j + 8, k + 8, 0);
		world.setBlock(i + 8, j + 8, k + 9, 0);
		world.setBlock(i + 8, j + 8, k + 10, 0);
		world.setBlock(i + 8, j + 9, k + 0, 0);
		world.setBlock(i + 8, j + 9, k + 1, 0);
		world.setBlock(i + 8, j + 9, k + 2, 0);
		world.setBlock(i + 8, j + 9, k + 3, 0);
		world.setBlock(i + 8, j + 9, k + 4, 0);
		world.setBlock(i + 8, j + 9, k + 5, 0);
		world.setBlock(i + 8, j + 9, k + 6, 0);
		world.setBlock(i + 8, j + 9, k + 7, 0);
		world.setBlock(i + 8, j + 9, k + 8, 0);
		world.setBlock(i + 8, j + 9, k + 9, 0);
		world.setBlock(i + 8, j + 9, k + 10, 0);
		world.setBlock(i + 8, j + 10, k + 0, 0);
		world.setBlock(i + 8, j + 10, k + 1, 0);
		world.setBlock(i + 8, j + 10, k + 2, 0);
		world.setBlock(i + 8, j + 10, k + 3, 0);
		world.setBlock(i + 8, j + 10, k + 4, 0);
		world.setBlock(i + 8, j + 10, k + 5, 0);
		world.setBlock(i + 8, j + 10, k + 6, 0);
		world.setBlock(i + 8, j + 10, k + 7, 0);
		world.setBlock(i + 8, j + 10, k + 8, 0);
		world.setBlock(i + 8, j + 10, k + 9, 0);
		world.setBlock(i + 8, j + 10, k + 10, 0);
		world.setBlock(i + 9, j + 0, k + 0, VetheaBlockHelper.dreamdirt.blockID);
		world.setBlock(i + 9, j + 0, k + 1, VetheaBlockHelper.dreamdirt.blockID);
		world.setBlock(i + 9, j + 0, k + 2, VetheaBlockHelper.dreamdirt.blockID);
		world.setBlock(i + 9, j + 0, k + 3, VetheaBlockHelper.dreamdirt.blockID);
		world.setBlock(i + 9, j + 0, k + 4, VetheaBlockHelper.dreamdirt.blockID);
		world.setBlock(i + 9, j + 0, k + 5, VetheaBlockHelper.cryptFloor.blockID);
		world.setBlock(i + 9, j + 0, k + 6, VetheaBlockHelper.cryptFloor.blockID);
		world.setBlock(i + 9, j + 0, k + 7, VetheaBlockHelper.cryptFloor.blockID);
		world.setBlock(i + 9, j + 0, k + 8, VetheaBlockHelper.cryptFloor.blockID);
		world.setBlock(i + 9, j + 0, k + 9, VetheaBlockHelper.dreamdirt.blockID);
		world.setBlock(i + 9, j + 0, k + 10, VetheaBlockHelper.dreamdirt.blockID);
		world.setBlock(i + 9, j + 1, k + 0, VetheaBlockHelper.dreamdirt.blockID);
		world.setBlock(i + 9, j + 1, k + 1, VetheaBlockHelper.dreamdirt.blockID);
		world.setBlock(i + 9, j + 1, k + 2, VetheaBlockHelper.dreamdirt.blockID);
		world.setBlock(i + 9, j + 1, k + 3, VetheaBlockHelper.dreamdirt.blockID);
		world.setBlock(i + 9, j + 1, k + 4, VetheaBlockHelper.cryptWall.blockID);
		world.setBlock(i + 9, j + 1, k + 5, 0);
		world.setBlock(i + 9, j + 1, k + 6, 0);
		world.setBlock(i + 9, j + 1, k + 7, 0);
		world.setBlock(i + 9, j + 1, k + 8, 0);
		world.setBlock(i + 9, j + 1, k + 9, VetheaBlockHelper.cryptWall.blockID);
		world.setBlock(i + 9, j + 1, k + 10, VetheaBlockHelper.dreamdirt.blockID);
		world.setBlock(i + 9, j + 2, k + 0, VetheaBlockHelper.dreamdirt.blockID);
		world.setBlock(i + 9, j + 2, k + 1, VetheaBlockHelper.dreamdirt.blockID);
		world.setBlock(i + 9, j + 2, k + 2, VetheaBlockHelper.dreamdirt.blockID);
		world.setBlock(i + 9, j + 2, k + 3, VetheaBlockHelper.dreamdirt.blockID);
		world.setBlock(i + 9, j + 2, k + 4, VetheaBlockHelper.cryptWall.blockID);
		world.setBlock(i + 9, j + 2, k + 5, 0);
		world.setBlock(i + 9, j + 2, k + 6, 0);
		world.setBlock(i + 9, j + 2, k + 7, 0);
		world.setBlock(i + 9, j + 2, k + 8, 0);
		world.setBlock(i + 9, j + 2, k + 9, VetheaBlockHelper.cryptWall.blockID);
		world.setBlock(i + 9, j + 2, k + 10, VetheaBlockHelper.dreamdirt.blockID);
		world.setBlock(i + 9, j + 3, k + 0, VetheaBlockHelper.dreamdirt.blockID);
		world.setBlock(i + 9, j + 3, k + 1, VetheaBlockHelper.dreamdirt.blockID);
		world.setBlock(i + 9, j + 3, k + 2, VetheaBlockHelper.dreamdirt.blockID);
		world.setBlock(i + 9, j + 3, k + 3, VetheaBlockHelper.dreamdirt.blockID);
		world.setBlock(i + 9, j + 3, k + 4, VetheaBlockHelper.dreamdirt.blockID);
		world.setBlock(i + 9, j + 3, k + 5, VetheaBlockHelper.hungerstone2.blockID);
		world.setBlock(i + 9, j + 3, k + 6, VetheaBlockHelper.hungerstone2.blockID);
		world.setBlock(i + 9, j + 3, k + 7, VetheaBlockHelper.hungerstone2.blockID);
		world.setBlock(i + 9, j + 3, k + 8, VetheaBlockHelper.hungerstone2.blockID);
		world.setBlock(i + 9, j + 3, k + 9, VetheaBlockHelper.dreamdirt.blockID);
		world.setBlock(i + 9, j + 3, k + 10, VetheaBlockHelper.dreamdirt.blockID);
		world.setBlock(i + 9, j + 4, k + 0, VetheaBlockHelper.dreamdirt.blockID);
		world.setBlock(i + 9, j + 4, k + 1, VetheaBlockHelper.dreamdirt.blockID);
		world.setBlock(i + 9, j + 4, k + 2, VetheaBlockHelper.dreamdirt.blockID);
		world.setBlock(i + 9, j + 4, k + 3, VetheaBlockHelper.dreamdirt.blockID);
		world.setBlock(i + 9, j + 4, k + 4, VetheaBlockHelper.cryptWall.blockID);
		world.setBlock(i + 9, j + 4, k + 5, VetheaBlockHelper.cryptWall.blockID);
		world.setBlock(i + 9, j + 4, k + 6, VetheaBlockHelper.dreamdirt.blockID);
		world.setBlock(i + 9, j + 4, k + 7, VetheaBlockHelper.dreamdirt.blockID);
		world.setBlock(i + 9, j + 4, k + 8, VetheaBlockHelper.dreamdirt.blockID);
		world.setBlock(i + 9, j + 4, k + 9, VetheaBlockHelper.dreamdirt.blockID);
		world.setBlock(i + 9, j + 4, k + 10, VetheaBlockHelper.dreamdirt.blockID);
		world.setBlock(i + 9, j + 5, k + 0, VetheaBlockHelper.metalCaging.blockID);
		world.setBlock(i + 9, j + 5, k + 1, 0);
		world.setBlock(i + 9, j + 5, k + 2, 0);
		world.setBlock(i + 9, j + 5, k + 3, 0);
		world.setBlock(i + 9, j + 5, k + 4, 0);
		world.setBlock(i + 9, j + 5, k + 5, 0);
		world.setBlock(i + 9, j + 5, k + 6, 0);
		world.setBlock(i + 9, j + 5, k + 7, 0);
		world.setBlock(i + 9, j + 5, k + 8, 0);
		world.setBlock(i + 9, j + 5, k + 9, 0);
		world.setBlock(i + 9, j + 5, k + 10, VetheaBlockHelper.metalCaging.blockID);
		world.setBlock(i + 9, j + 6, k + 0, VetheaBlockHelper.hungerstone1.blockID);
		world.setBlock(i + 9, j + 6, k + 1, 0);
		world.setBlock(i + 9, j + 6, k + 2, 0);
		world.setBlock(i + 9, j + 6, k + 3, 0);
		world.setBlock(i + 9, j + 6, k + 4, 0);
		world.setBlock(i + 9, j + 6, k + 5, 0);
		world.setBlock(i + 9, j + 6, k + 6, 0);
		world.setBlock(i + 9, j + 6, k + 7, 0);
		world.setBlock(i + 9, j + 6, k + 8, 0);
		world.setBlock(i + 9, j + 6, k + 9, 0);
		world.setBlock(i + 9, j + 6, k + 10, VetheaBlockHelper.hungerstone1.blockID);
		world.setBlock(i + 9, j + 7, k + 0, 0);
		world.setBlock(i + 9, j + 7, k + 1, 0);
		world.setBlock(i + 9, j + 7, k + 2, 0);
		world.setBlock(i + 9, j + 7, k + 3, 0);
		world.setBlock(i + 9, j + 7, k + 4, 0);
		world.setBlock(i + 9, j + 7, k + 5, 0);
		world.setBlock(i + 9, j + 7, k + 6, 0);
		world.setBlock(i + 9, j + 7, k + 7, 0);
		world.setBlock(i + 9, j + 7, k + 8, 0);
		world.setBlock(i + 9, j + 7, k + 9, 0);
		world.setBlock(i + 9, j + 7, k + 10, 0);
		world.setBlock(i + 9, j + 8, k + 0, 0);
		world.setBlock(i + 9, j + 8, k + 1, 0);
		world.setBlock(i + 9, j + 8, k + 2, 0);
		world.setBlock(i + 9, j + 8, k + 3, 0);
		world.setBlock(i + 9, j + 8, k + 4, 0);
		world.setBlock(i + 9, j + 8, k + 5, 0);
		world.setBlock(i + 9, j + 8, k + 6, 0);
		world.setBlock(i + 9, j + 8, k + 7, 0);
		world.setBlock(i + 9, j + 8, k + 8, 0);
		world.setBlock(i + 9, j + 8, k + 9, 0);
		world.setBlock(i + 9, j + 8, k + 10, 0);
		world.setBlock(i + 9, j + 9, k + 0, 0);
		world.setBlock(i + 9, j + 9, k + 1, 0);
		world.setBlock(i + 9, j + 9, k + 2, 0);
		world.setBlock(i + 9, j + 9, k + 3, 0);
		world.setBlock(i + 9, j + 9, k + 4, 0);
		world.setBlock(i + 9, j + 9, k + 5, 0);
		world.setBlock(i + 9, j + 9, k + 6, 0);
		world.setBlock(i + 9, j + 9, k + 7, 0);
		world.setBlock(i + 9, j + 9, k + 8, 0);
		world.setBlock(i + 9, j + 9, k + 9, 0);
		world.setBlock(i + 9, j + 9, k + 10, 0);
		world.setBlock(i + 9, j + 10, k + 0, 0);
		world.setBlock(i + 9, j + 10, k + 1, 0);
		world.setBlock(i + 9, j + 10, k + 2, 0);
		world.setBlock(i + 9, j + 10, k + 3, 0);
		world.setBlock(i + 9, j + 10, k + 4, 0);
		world.setBlock(i + 9, j + 10, k + 5, 0);
		world.setBlock(i + 9, j + 10, k + 6, 0);
		world.setBlock(i + 9, j + 10, k + 7, 0);
		world.setBlock(i + 9, j + 10, k + 8, 0);
		world.setBlock(i + 9, j + 10, k + 9, 0);
		world.setBlock(i + 9, j + 10, k + 10, 0);
		world.setBlock(i + 10, j + 0, k + 0, VetheaBlockHelper.dreamdirt.blockID);
		world.setBlock(i + 10, j + 0, k + 1, VetheaBlockHelper.dreamdirt.blockID);
		world.setBlock(i + 10, j + 0, k + 2, VetheaBlockHelper.dreamdirt.blockID);
		world.setBlock(i + 10, j + 0, k + 3, VetheaBlockHelper.dreamdirt.blockID);
		world.setBlock(i + 10, j + 0, k + 4, VetheaBlockHelper.dreamdirt.blockID);
		world.setBlock(i + 10, j + 0, k + 5, VetheaBlockHelper.cryptFloor.blockID);
		world.setBlock(i + 10, j + 0, k + 6, VetheaBlockHelper.cryptFloor.blockID);
		world.setBlock(i + 10, j + 0, k + 7, VetheaBlockHelper.cryptFloor.blockID);
		world.setBlock(i + 10, j + 0, k + 8, VetheaBlockHelper.cryptFloor.blockID);
		world.setBlock(i + 10, j + 0, k + 9, VetheaBlockHelper.dreamdirt.blockID);
		world.setBlock(i + 10, j + 0, k + 10, VetheaBlockHelper.dreamdirt.blockID);
		world.setBlock(i + 10, j + 1, k + 0, VetheaBlockHelper.dreamdirt.blockID);
		world.setBlock(i + 10, j + 1, k + 1, VetheaBlockHelper.dreamdirt.blockID);
		world.setBlock(i + 10, j + 1, k + 2, VetheaBlockHelper.dreamdirt.blockID);
		world.setBlock(i + 10, j + 1, k + 3, VetheaBlockHelper.dreamdirt.blockID);
		world.setBlock(i + 10, j + 1, k + 4, VetheaBlockHelper.cryptWall.blockID);
		world.setBlock(i + 10, j + 1, k + 5, 0);
		world.setBlock(i + 10, j + 1, k + 6, 0);
		world.setBlock(i + 10, j + 1, k + 7, 0);
		world.setBlock(i + 10, j + 1, k + 8, 0);
		world.setBlock(i + 10, j + 1, k + 9, VetheaBlockHelper.cryptWall.blockID);
		world.setBlock(i + 10, j + 1, k + 10, VetheaBlockHelper.dreamdirt.blockID);
		world.setBlock(i + 10, j + 2, k + 0, VetheaBlockHelper.dreamdirt.blockID);
		world.setBlock(i + 10, j + 2, k + 1, VetheaBlockHelper.dreamdirt.blockID);
		world.setBlock(i + 10, j + 2, k + 2, VetheaBlockHelper.dreamdirt.blockID);
		world.setBlock(i + 10, j + 2, k + 3, VetheaBlockHelper.dreamdirt.blockID);
		world.setBlock(i + 10, j + 2, k + 4, VetheaBlockHelper.cryptWall.blockID);
		world.setBlock(i + 10, j + 2, k + 5, 0);
		world.setBlock(i + 10, j + 2, k + 6, 0);
		world.setBlock(i + 10, j + 2, k + 7, 0);
		world.setBlock(i + 10, j + 2, k + 8, 0);
		world.setBlock(i + 10, j + 2, k + 9, VetheaBlockHelper.cryptWall.blockID);
		world.setBlock(i + 10, j + 2, k + 10, VetheaBlockHelper.dreamdirt.blockID);
		world.setBlock(i + 10, j + 3, k + 0, VetheaBlockHelper.dreamdirt.blockID);
		world.setBlock(i + 10, j + 3, k + 1, VetheaBlockHelper.dreamdirt.blockID);
		world.setBlock(i + 10, j + 3, k + 2, VetheaBlockHelper.dreamdirt.blockID);
		world.setBlock(i + 10, j + 3, k + 3, VetheaBlockHelper.dreamdirt.blockID);
		world.setBlock(i + 10, j + 3, k + 4, VetheaBlockHelper.dreamdirt.blockID);
		world.setBlock(i + 10, j + 3, k + 5, VetheaBlockHelper.hungerstone2.blockID);
		world.setBlock(i + 10, j + 3, k + 6, VetheaBlockHelper.hungerstone2.blockID);
		world.setBlock(i + 10, j + 3, k + 7, VetheaBlockHelper.hungerstone2.blockID);
		world.setBlock(i + 10, j + 3, k + 8, VetheaBlockHelper.hungerstone2.blockID);
		world.setBlock(i + 10, j + 3, k + 9, VetheaBlockHelper.dreamdirt.blockID);
		world.setBlock(i + 10, j + 3, k + 10, VetheaBlockHelper.dreamdirt.blockID);
		world.setBlock(i + 10, j + 4, k + 0, VetheaBlockHelper.dreamdirt.blockID);
		world.setBlock(i + 10, j + 4, k + 1, VetheaBlockHelper.dreamdirt.blockID);
		world.setBlock(i + 10, j + 4, k + 2, VetheaBlockHelper.dreamdirt.blockID);
		world.setBlock(i + 10, j + 4, k + 3, VetheaBlockHelper.dreamdirt.blockID);
		world.setBlock(i + 10, j + 4, k + 4, VetheaBlockHelper.cryptWall.blockID);
		world.setBlock(i + 10, j + 4, k + 5, VetheaBlockHelper.cryptWall.blockID);
		world.setBlock(i + 10, j + 4, k + 6, VetheaBlockHelper.cryptWall.blockID);
		world.setBlock(i + 10, j + 4, k + 7, VetheaBlockHelper.cryptWall.blockID);
		world.setBlock(i + 10, j + 4, k + 8, VetheaBlockHelper.cryptWall.blockID);
		world.setBlock(i + 10, j + 4, k + 9, VetheaBlockHelper.dreamdirt.blockID);
		world.setBlock(i + 10, j + 4, k + 10, VetheaBlockHelper.dreamdirt.blockID);
		world.setBlock(i + 10, j + 5, k + 0, VetheaBlockHelper.metalCaging.blockID);
		world.setBlock(i + 10, j + 5, k + 1, 0);
		world.setBlock(i + 10, j + 5, k + 2, 0);
		world.setBlock(i + 10, j + 5, k + 3, 0);
		world.setBlock(i + 10, j + 5, k + 4, 0);
		world.setBlock(i + 10, j + 5, k + 5, 0);
		world.setBlock(i + 10, j + 5, k + 6, 0);
		world.setBlock(i + 10, j + 5, k + 7, 0);
		world.setBlock(i + 10, j + 5, k + 8, 0);
		world.setBlock(i + 10, j + 5, k + 9, 0);
		world.setBlock(i + 10, j + 5, k + 10, VetheaBlockHelper.metalCaging.blockID);
		world.setBlock(i + 10, j + 6, k + 0, VetheaBlockHelper.hungerstone1.blockID);
		world.setBlock(i + 10, j + 6, k + 1, 0);
		world.setBlock(i + 10, j + 6, k + 2, 0);
		world.setBlock(i + 10, j + 6, k + 3, 0);
		world.setBlock(i + 10, j + 6, k + 4, 0);
		world.setBlock(i + 10, j + 6, k + 5, 0);
		world.setBlock(i + 10, j + 6, k + 6, 0);
		world.setBlock(i + 10, j + 6, k + 7, 0);
		world.setBlock(i + 10, j + 6, k + 8, 0);
		world.setBlock(i + 10, j + 6, k + 9, 0);
		world.setBlock(i + 10, j + 6, k + 10, VetheaBlockHelper.hungerstone1.blockID);
		world.setBlock(i + 10, j + 7, k + 0, 0);
		world.setBlock(i + 10, j + 7, k + 1, 0);
		world.setBlock(i + 10, j + 7, k + 2, 0);
		world.setBlock(i + 10, j + 7, k + 3, 0);
		world.setBlock(i + 10, j + 7, k + 4, 0);
		world.setBlock(i + 10, j + 7, k + 5, 0);
		world.setBlock(i + 10, j + 7, k + 6, 0);
		world.setBlock(i + 10, j + 7, k + 7, 0);
		world.setBlock(i + 10, j + 7, k + 8, 0);
		world.setBlock(i + 10, j + 7, k + 9, 0);
		world.setBlock(i + 10, j + 7, k + 10, 0);
		world.setBlock(i + 10, j + 8, k + 0, 0);
		world.setBlock(i + 10, j + 8, k + 1, 0);
		world.setBlock(i + 10, j + 8, k + 2, 0);
		world.setBlock(i + 10, j + 8, k + 3, 0);
		world.setBlock(i + 10, j + 8, k + 4, 0);
		world.setBlock(i + 10, j + 8, k + 5, 0);
		world.setBlock(i + 10, j + 8, k + 6, 0);
		world.setBlock(i + 10, j + 8, k + 7, 0);
		world.setBlock(i + 10, j + 8, k + 8, 0);
		world.setBlock(i + 10, j + 8, k + 9, 0);
		world.setBlock(i + 10, j + 8, k + 10, 0);
		world.setBlock(i + 10, j + 9, k + 0, 0);
		world.setBlock(i + 10, j + 9, k + 1, 0);
		world.setBlock(i + 10, j + 9, k + 2, 0);
		world.setBlock(i + 10, j + 9, k + 3, 0);
		world.setBlock(i + 10, j + 9, k + 4, 0);
		world.setBlock(i + 10, j + 9, k + 5, 0);
		world.setBlock(i + 10, j + 9, k + 6, 0);
		world.setBlock(i + 10, j + 9, k + 7, 0);
		world.setBlock(i + 10, j + 9, k + 8, 0);
		world.setBlock(i + 10, j + 9, k + 9, 0);
		world.setBlock(i + 10, j + 9, k + 10, 0);
		world.setBlock(i + 10, j + 10, k + 0, 0);
		world.setBlock(i + 10, j + 10, k + 1, 0);
		world.setBlock(i + 10, j + 10, k + 2, 0);
		world.setBlock(i + 10, j + 10, k + 3, 0);
		world.setBlock(i + 10, j + 10, k + 4, 0);
		world.setBlock(i + 10, j + 10, k + 5, 0);
		world.setBlock(i + 10, j + 10, k + 6, 0);
		world.setBlock(i + 10, j + 10, k + 7, 0);
		world.setBlock(i + 10, j + 10, k + 8, 0);
		world.setBlock(i + 10, j + 10, k + 9, 0);
		world.setBlock(i + 10, j + 10, k + 10, 0);
		world.setBlock(i + 11, j + 0, k + 0, VetheaBlockHelper.dreamdirt.blockID);
		world.setBlock(i + 11, j + 0, k + 1, VetheaBlockHelper.dreamdirt.blockID);
		world.setBlock(i + 11, j + 0, k + 2, VetheaBlockHelper.dreamdirt.blockID);
		world.setBlock(i + 11, j + 0, k + 3, VetheaBlockHelper.dreamdirt.blockID);
		world.setBlock(i + 11, j + 0, k + 4, VetheaBlockHelper.dreamdirt.blockID);
		world.setBlock(i + 11, j + 0, k + 5, VetheaBlockHelper.cryptFloor.blockID);
		world.setBlock(i + 11, j + 0, k + 6, VetheaBlockHelper.cryptFloor.blockID);
		world.setBlock(i + 11, j + 0, k + 7, VetheaBlockHelper.cryptFloor.blockID);
		world.setBlock(i + 11, j + 0, k + 8, VetheaBlockHelper.cryptFloor.blockID);
		world.setBlock(i + 11, j + 0, k + 9, VetheaBlockHelper.dreamdirt.blockID);
		world.setBlock(i + 11, j + 0, k + 10, VetheaBlockHelper.dreamdirt.blockID);
		world.setBlock(i + 11, j + 1, k + 0, VetheaBlockHelper.dreamdirt.blockID);
		world.setBlock(i + 11, j + 1, k + 1, VetheaBlockHelper.dreamdirt.blockID);
		world.setBlock(i + 11, j + 1, k + 2, 0);
		world.setBlock(i + 11, j + 1, k + 3, VetheaBlockHelper.dreamdirt.blockID);
		world.setBlock(i + 11, j + 1, k + 4, VetheaBlockHelper.cryptWall.blockID);
		world.setBlock(i + 11, j + 1, k + 5, 0);
		world.setBlock(i + 11, j + 1, k + 6, 0);
		world.setBlock(i + 11, j + 1, k + 7, 0);
		world.setBlock(i + 11, j + 1, k + 8, 0);
		world.setBlock(i + 11, j + 1, k + 9, VetheaBlockHelper.cryptWall.blockID);
		world.setBlock(i + 11, j + 1, k + 10, VetheaBlockHelper.dreamdirt.blockID);
		world.setBlock(i + 11, j + 2, k + 0, VetheaBlockHelper.dreamdirt.blockID);
		world.setBlock(i + 11, j + 2, k + 1, VetheaBlockHelper.dreamdirt.blockID);
		world.setBlock(i + 11, j + 2, k + 2, VetheaBlockHelper.dreamdirt.blockID);
		world.setBlock(i + 11, j + 2, k + 3, VetheaBlockHelper.dreamdirt.blockID);
		world.setBlock(i + 11, j + 2, k + 4, VetheaBlockHelper.cryptWall.blockID);
		world.setBlock(i + 11, j + 2, k + 5, 0);
		world.setBlock(i + 11, j + 2, k + 6, 0);
		world.setBlock(i + 11, j + 2, k + 7, 0);
		world.setBlock(i + 11, j + 2, k + 8, 0);
		world.setBlock(i + 11, j + 2, k + 9, VetheaBlockHelper.cryptWall.blockID);
		world.setBlock(i + 11, j + 2, k + 10, VetheaBlockHelper.dreamdirt.blockID);
		world.setBlock(i + 11, j + 3, k + 0, VetheaBlockHelper.dreamdirt.blockID);
		world.setBlock(i + 11, j + 3, k + 1, VetheaBlockHelper.dreamdirt.blockID);
		world.setBlock(i + 11, j + 3, k + 2, VetheaBlockHelper.dreamdirt.blockID);
		world.setBlock(i + 11, j + 3, k + 3, VetheaBlockHelper.dreamdirt.blockID);
		world.setBlock(i + 11, j + 3, k + 4, VetheaBlockHelper.dreamdirt.blockID);
		world.setBlock(i + 11, j + 3, k + 5, VetheaBlockHelper.hungerstone2.blockID);
		world.setBlock(i + 11, j + 3, k + 6, VetheaBlockHelper.hungerstone2.blockID);
		world.setBlock(i + 11, j + 3, k + 7, VetheaBlockHelper.hungerstone2.blockID);
		world.setBlock(i + 11, j + 3, k + 8, VetheaBlockHelper.hungerstone2.blockID);
		world.setBlock(i + 11, j + 3, k + 9, VetheaBlockHelper.dreamdirt.blockID);
		world.setBlock(i + 11, j + 3, k + 10, VetheaBlockHelper.dreamdirt.blockID);
		world.setBlock(i + 11, j + 4, k + 0, VetheaBlockHelper.dreamdirt.blockID);
		world.setBlock(i + 11, j + 4, k + 1, VetheaBlockHelper.dreamdirt.blockID);
		world.setBlock(i + 11, j + 4, k + 2, VetheaBlockHelper.dreamdirt.blockID);
		world.setBlock(i + 11, j + 4, k + 3, VetheaBlockHelper.dreamdirt.blockID);
		world.setBlock(i + 11, j + 4, k + 4, VetheaBlockHelper.cryptWall.blockID);
		world.setBlock(i + 11, j + 4, k + 5, VetheaBlockHelper.cryptWall.blockID);
		world.setBlock(i + 11, j + 4, k + 6, VetheaBlockHelper.cryptWall.blockID);
		world.setBlock(i + 11, j + 4, k + 7, VetheaBlockHelper.cryptWall.blockID);
		world.setBlock(i + 11, j + 4, k + 8, VetheaBlockHelper.cryptWall.blockID);
		world.setBlock(i + 11, j + 4, k + 9, VetheaBlockHelper.dreamdirt.blockID);
		world.setBlock(i + 11, j + 4, k + 10, VetheaBlockHelper.dreamdirt.blockID);
		world.setBlock(i + 11, j + 5, k + 0, VetheaBlockHelper.metalCaging.blockID);
		world.setBlock(i + 11, j + 5, k + 1, 0);
		world.setBlock(i + 11, j + 5, k + 2, 0);
		world.setBlock(i + 11, j + 5, k + 3, 0);
		world.setBlock(i + 11, j + 5, k + 4, 0);
		world.setBlock(i + 11, j + 5, k + 5, 0);
		world.setBlock(i + 11, j + 5, k + 6, 0);
		world.setBlock(i + 11, j + 5, k + 7, 0);
		world.setBlock(i + 11, j + 5, k + 8, 0);
		world.setBlock(i + 11, j + 5, k + 9, 0);
		world.setBlock(i + 11, j + 5, k + 10, VetheaBlockHelper.metalCaging.blockID);
		world.setBlock(i + 11, j + 6, k + 0, VetheaBlockHelper.hungerstone1.blockID);
		world.setBlock(i + 11, j + 6, k + 1, 0);
		world.setBlock(i + 11, j + 6, k + 2, 0);
		world.setBlock(i + 11, j + 6, k + 3, 0);
		world.setBlock(i + 11, j + 6, k + 4, 0);
		world.setBlock(i + 11, j + 6, k + 5, 0);
		world.setBlock(i + 11, j + 6, k + 6, 0);
		world.setBlock(i + 11, j + 6, k + 7, 0);
		world.setBlock(i + 11, j + 6, k + 8, 0);
		world.setBlock(i + 11, j + 6, k + 9, 0);
		world.setBlock(i + 11, j + 6, k + 10, VetheaBlockHelper.hungerstone1.blockID);
		world.setBlock(i + 11, j + 7, k + 0, 0);
		world.setBlock(i + 11, j + 7, k + 1, 0);
		world.setBlock(i + 11, j + 7, k + 2, 0);
		world.setBlock(i + 11, j + 7, k + 3, 0);
		world.setBlock(i + 11, j + 7, k + 4, 0);
		world.setBlock(i + 11, j + 7, k + 5, 0);
		world.setBlock(i + 11, j + 7, k + 6, 0);
		world.setBlock(i + 11, j + 7, k + 7, 0);
		world.setBlock(i + 11, j + 7, k + 8, 0);
		world.setBlock(i + 11, j + 7, k + 9, 0);
		world.setBlock(i + 11, j + 7, k + 10, 0);
		world.setBlock(i + 11, j + 8, k + 0, 0);
		world.setBlock(i + 11, j + 8, k + 1, 0);
		world.setBlock(i + 11, j + 8, k + 2, 0);
		world.setBlock(i + 11, j + 8, k + 3, 0);
		world.setBlock(i + 11, j + 8, k + 4, 0);
		world.setBlock(i + 11, j + 8, k + 5, 0);
		world.setBlock(i + 11, j + 8, k + 6, 0);
		world.setBlock(i + 11, j + 8, k + 7, 0);
		world.setBlock(i + 11, j + 8, k + 8, 0);
		world.setBlock(i + 11, j + 8, k + 9, 0);
		world.setBlock(i + 11, j + 8, k + 10, 0);
		world.setBlock(i + 11, j + 9, k + 0, 0);
		world.setBlock(i + 11, j + 9, k + 1, 0);
		world.setBlock(i + 11, j + 9, k + 2, 0);
		world.setBlock(i + 11, j + 9, k + 3, 0);
		world.setBlock(i + 11, j + 9, k + 4, 0);
		world.setBlock(i + 11, j + 9, k + 5, 0);
		world.setBlock(i + 11, j + 9, k + 6, 0);
		world.setBlock(i + 11, j + 9, k + 7, 0);
		world.setBlock(i + 11, j + 9, k + 8, 0);
		world.setBlock(i + 11, j + 9, k + 9, 0);
		world.setBlock(i + 11, j + 9, k + 10, 0);
		world.setBlock(i + 11, j + 10, k + 0, 0);
		world.setBlock(i + 11, j + 10, k + 1, 0);
		world.setBlock(i + 11, j + 10, k + 2, 0);
		world.setBlock(i + 11, j + 10, k + 3, 0);
		world.setBlock(i + 11, j + 10, k + 4, 0);
		world.setBlock(i + 11, j + 10, k + 5, 0);
		world.setBlock(i + 11, j + 10, k + 6, 0);
		world.setBlock(i + 11, j + 10, k + 7, 0);
		world.setBlock(i + 11, j + 10, k + 8, 0);
		world.setBlock(i + 11, j + 10, k + 9, 0);
		world.setBlock(i + 11, j + 10, k + 10, 0);
		world.setBlock(i + 12, j + 0, k + 0, VetheaBlockHelper.dreamdirt.blockID);
		world.setBlock(i + 12, j + 0, k + 1, VetheaBlockHelper.dreamdirt.blockID);
		world.setBlock(i + 12, j + 0, k + 2, VetheaBlockHelper.dreamdirt.blockID);
		world.setBlock(i + 12, j + 0, k + 3, VetheaBlockHelper.dreamdirt.blockID);
		world.setBlock(i + 12, j + 0, k + 4, VetheaBlockHelper.dreamdirt.blockID);
		world.setBlock(i + 12, j + 0, k + 5, VetheaBlockHelper.cryptFloor.blockID);
		world.setBlock(i + 12, j + 0, k + 6, VetheaBlockHelper.cryptFloor.blockID);
		world.setBlock(i + 12, j + 0, k + 7, VetheaBlockHelper.cryptFloor.blockID);
		world.setBlock(i + 12, j + 0, k + 8, VetheaBlockHelper.cryptFloor.blockID);
		world.setBlock(i + 12, j + 0, k + 9, VetheaBlockHelper.dreamdirt.blockID);
		world.setBlock(i + 12, j + 0, k + 10, VetheaBlockHelper.dreamdirt.blockID);
		world.setBlock(i + 12, j + 1, k + 0, VetheaBlockHelper.dreamdirt.blockID);
		world.setBlock(i + 12, j + 1, k + 1, VetheaBlockHelper.cryptWall.blockID);
		world.setBlock(i + 12, j + 1, k + 2, VetheaBlockHelper.cryptWall.blockID);
		world.setBlock(i + 12, j + 1, k + 3, VetheaBlockHelper.cryptWall.blockID);
		world.setBlock(i + 12, j + 1, k + 4, VetheaBlockHelper.cryptWall.blockID);
		world.setBlock(i + 12, j + 1, k + 5, 0);
		world.setBlock(i + 12, j + 1, k + 6, 0);
		world.setBlock(i + 12, j + 1, k + 7, 0);
		world.setBlock(i + 12, j + 1, k + 8, 0);
		world.setBlock(i + 12, j + 1, k + 9, VetheaBlockHelper.cryptWall.blockID);
		world.setBlock(i + 12, j + 1, k + 10, VetheaBlockHelper.dreamdirt.blockID);
		world.setBlock(i + 12, j + 2, k + 0, VetheaBlockHelper.dreamdirt.blockID);
		world.setBlock(i + 12, j + 2, k + 1, VetheaBlockHelper.cryptWall.blockID);
		world.setBlock(i + 12, j + 2, k + 2, VetheaBlockHelper.cryptWall.blockID);
		world.setBlock(i + 12, j + 2, k + 3, VetheaBlockHelper.cryptWall.blockID);
		world.setBlock(i + 12, j + 2, k + 4, VetheaBlockHelper.cryptWall.blockID);
		world.setBlock(i + 12, j + 2, k + 5, 0);
		world.setBlock(i + 12, j + 2, k + 6, 0);
		world.setBlock(i + 12, j + 2, k + 7, 0);
		world.setBlock(i + 12, j + 2, k + 8, 0);
		world.setBlock(i + 12, j + 2, k + 9, VetheaBlockHelper.cryptWall.blockID);
		world.setBlock(i + 12, j + 2, k + 10, VetheaBlockHelper.dreamdirt.blockID);
		world.setBlock(i + 12, j + 3, k + 0, VetheaBlockHelper.dreamdirt.blockID);
		world.setBlock(i + 12, j + 3, k + 1, VetheaBlockHelper.dreamdirt.blockID);
		world.setBlock(i + 12, j + 3, k + 2, VetheaBlockHelper.dreamdirt.blockID);
		world.setBlock(i + 12, j + 3, k + 3, VetheaBlockHelper.dreamdirt.blockID);
		world.setBlock(i + 12, j + 3, k + 4, VetheaBlockHelper.dreamdirt.blockID);
		world.setBlock(i + 12, j + 3, k + 5, VetheaBlockHelper.hungerstone2.blockID);
		world.setBlock(i + 12, j + 3, k + 6, VetheaBlockHelper.hungerstone2.blockID);
		world.setBlock(i + 12, j + 3, k + 7, VetheaBlockHelper.hungerstone2.blockID);
		world.setBlock(i + 12, j + 3, k + 8, VetheaBlockHelper.hungerstone2.blockID);
		world.setBlock(i + 12, j + 3, k + 9, VetheaBlockHelper.dreamdirt.blockID);
		world.setBlock(i + 12, j + 3, k + 10, VetheaBlockHelper.dreamdirt.blockID);
		world.setBlock(i + 12, j + 4, k + 0, VetheaBlockHelper.dreamdirt.blockID);
		world.setBlock(i + 12, j + 4, k + 1, VetheaBlockHelper.dreamdirt.blockID);
		world.setBlock(i + 12, j + 4, k + 2, VetheaBlockHelper.dreamdirt.blockID);
		world.setBlock(i + 12, j + 4, k + 3, VetheaBlockHelper.dreamdirt.blockID);

		generate2(world, rand, i, j, k);
		return true;
	}

	public boolean generate2(World world, Random rand, int i, int j, int k) {
		world.setBlock(i + 12, j + 4, k + 4, VetheaBlockHelper.dreamdirt.blockID);
		world.setBlock(i + 12, j + 4, k + 5, VetheaBlockHelper.dreamdirt.blockID);
		world.setBlock(i + 12, j + 4, k + 6, VetheaBlockHelper.dreamdirt.blockID);
		world.setBlock(i + 12, j + 4, k + 7, VetheaBlockHelper.cryptWall.blockID);
		world.setBlock(i + 12, j + 4, k + 8, VetheaBlockHelper.cryptWall.blockID);
		world.setBlock(i + 12, j + 4, k + 9, VetheaBlockHelper.dreamdirt.blockID);
		world.setBlock(i + 12, j + 4, k + 10, VetheaBlockHelper.dreamdirt.blockID);
		world.setBlock(i + 12, j + 5, k + 0, VetheaBlockHelper.metalCaging.blockID);
		world.setBlock(i + 12, j + 5, k + 1, 0);
		world.setBlock(i + 12, j + 5, k + 2, 0);
		world.setBlock(i + 12, j + 5, k + 3, 0);
		world.setBlock(i + 12, j + 5, k + 4, 0);
		world.setBlock(i + 12, j + 5, k + 5, 0);
		world.setBlock(i + 12, j + 5, k + 6, 0);
		world.setBlock(i + 12, j + 5, k + 7, 0);
		world.setBlock(i + 12, j + 5, k + 8, 0);
		world.setBlock(i + 12, j + 5, k + 9, 0);
		world.setBlock(i + 12, j + 5, k + 10, VetheaBlockHelper.metalCaging.blockID);
		world.setBlock(i + 12, j + 6, k + 0, VetheaBlockHelper.hungerstone1.blockID);
		world.setBlock(i + 12, j + 6, k + 1, 0);
		world.setBlock(i + 12, j + 6, k + 2, 0);
		world.setBlock(i + 12, j + 6, k + 3, 0);
		world.setBlock(i + 12, j + 6, k + 4, 0);
		world.setBlock(i + 12, j + 6, k + 5, 0);
		world.setBlock(i + 12, j + 6, k + 6, 0);
		world.setBlock(i + 12, j + 6, k + 7, 0);
		world.setBlock(i + 12, j + 6, k + 8, 0);
		world.setBlock(i + 12, j + 6, k + 9, 0);
		world.setBlock(i + 12, j + 6, k + 10, VetheaBlockHelper.hungerstone1.blockID);
		world.setBlock(i + 12, j + 7, k + 0, 0);
		world.setBlock(i + 12, j + 7, k + 1, 0);
		world.setBlock(i + 12, j + 7, k + 2, 0);
		world.setBlock(i + 12, j + 7, k + 3, 0);
		world.setBlock(i + 12, j + 7, k + 4, 0);
		world.setBlock(i + 12, j + 7, k + 5, 0);
		world.setBlock(i + 12, j + 7, k + 6, 0);
		world.setBlock(i + 12, j + 7, k + 7, 0);
		world.setBlock(i + 12, j + 7, k + 8, 0);
		world.setBlock(i + 12, j + 7, k + 9, 0);
		world.setBlock(i + 12, j + 7, k + 10, 0);
		world.setBlock(i + 12, j + 8, k + 0, 0);
		world.setBlock(i + 12, j + 8, k + 1, 0);
		world.setBlock(i + 12, j + 8, k + 2, 0);
		world.setBlock(i + 12, j + 8, k + 3, 0);
		world.setBlock(i + 12, j + 8, k + 4, 0);
		world.setBlock(i + 12, j + 8, k + 5, 0);
		world.setBlock(i + 12, j + 8, k + 6, 0);
		world.setBlock(i + 12, j + 8, k + 7, 0);
		world.setBlock(i + 12, j + 8, k + 8, 0);
		world.setBlock(i + 12, j + 8, k + 9, 0);
		world.setBlock(i + 12, j + 8, k + 10, 0);
		world.setBlock(i + 12, j + 9, k + 0, 0);
		world.setBlock(i + 12, j + 9, k + 1, 0);
		world.setBlock(i + 12, j + 9, k + 2, 0);
		world.setBlock(i + 12, j + 9, k + 3, 0);
		world.setBlock(i + 12, j + 9, k + 4, 0);
		world.setBlock(i + 12, j + 9, k + 5, 0);
		world.setBlock(i + 12, j + 9, k + 6, 0);
		world.setBlock(i + 12, j + 9, k + 7, 0);
		world.setBlock(i + 12, j + 9, k + 8, 0);
		world.setBlock(i + 12, j + 9, k + 9, 0);
		world.setBlock(i + 12, j + 9, k + 10, 0);
		world.setBlock(i + 12, j + 10, k + 0, 0);
		world.setBlock(i + 12, j + 10, k + 1, 0);
		world.setBlock(i + 12, j + 10, k + 2, 0);
		world.setBlock(i + 12, j + 10, k + 3, 0);
		world.setBlock(i + 12, j + 10, k + 4, 0);
		world.setBlock(i + 12, j + 10, k + 5, 0);
		world.setBlock(i + 12, j + 10, k + 6, 0);
		world.setBlock(i + 12, j + 10, k + 7, 0);
		world.setBlock(i + 12, j + 10, k + 8, 0);
		world.setBlock(i + 12, j + 10, k + 9, 0);
		world.setBlock(i + 12, j + 10, k + 10, 0);
		world.setBlock(i + 13, j + 0, k + 0, VetheaBlockHelper.dreamdirt.blockID);
		world.setBlock(i + 13, j + 0, k + 1, VetheaBlockHelper.cryptFloor.blockID);
		world.setBlock(i + 13, j + 0, k + 2, VetheaBlockHelper.cryptFloor.blockID);
		world.setBlock(i + 13, j + 0, k + 3, VetheaBlockHelper.cryptFloor.blockID);
		world.setBlock(i + 13, j + 0, k + 4, VetheaBlockHelper.cryptFloor.blockID);
		world.setBlock(i + 13, j + 0, k + 5, VetheaBlockHelper.cryptFloor.blockID);
		world.setBlock(i + 13, j + 0, k + 6, VetheaBlockHelper.cryptFloor.blockID);
		world.setBlock(i + 13, j + 0, k + 7, VetheaBlockHelper.cryptFloor.blockID);
		world.setBlock(i + 13, j + 0, k + 8, VetheaBlockHelper.cryptFloor.blockID);
		world.setBlock(i + 13, j + 0, k + 9, VetheaBlockHelper.dreamdirt.blockID);
		world.setBlock(i + 13, j + 0, k + 10, VetheaBlockHelper.dreamdirt.blockID);
		world.setBlock(i + 13, j + 1, k + 0, VetheaBlockHelper.cryptWall.blockID);
		world.setBlock(i + 13, j + 1, k + 1, 0);
		world.setBlock(i + 13, j + 1, k + 2, 0);
		world.setBlock(i + 13, j + 1, k + 3, 0);
		world.setBlock(i + 13, j + 1, k + 4, 0);
		world.setBlock(i + 13, j + 1, k + 5, 0);
		world.setBlock(i + 13, j + 1, k + 6, 0);
		world.setBlock(i + 13, j + 1, k + 7, 0);
		world.setBlock(i + 13, j + 1, k + 8, 0);
		world.setBlock(i + 13, j + 1, k + 9, VetheaBlockHelper.cryptWall.blockID);
		world.setBlock(i + 13, j + 1, k + 10, VetheaBlockHelper.dreamdirt.blockID);
		world.setBlock(i + 13, j + 2, k + 0, VetheaBlockHelper.cryptWall.blockID);
		world.setBlock(i + 13, j + 2, k + 1, 0);
		world.setBlock(i + 13, j + 2, k + 2, 0);
		world.setBlock(i + 13, j + 2, k + 3, 0);
		world.setBlock(i + 13, j + 2, k + 4, 0);
		world.setBlock(i + 13, j + 2, k + 5, 0);
		world.setBlock(i + 13, j + 2, k + 6, 0);
		world.setBlock(i + 13, j + 2, k + 7, 0);
		world.setBlock(i + 13, j + 2, k + 8, 0);
		world.setBlock(i + 13, j + 2, k + 9, VetheaBlockHelper.cryptWall.blockID);
		world.setBlock(i + 13, j + 2, k + 10, VetheaBlockHelper.dreamdirt.blockID);
		world.setBlock(i + 13, j + 3, k + 0, VetheaBlockHelper.dreamdirt.blockID);
		world.setBlock(i + 13, j + 3, k + 1, VetheaBlockHelper.hungerstone2.blockID);
		world.setBlock(i + 13, j + 3, k + 2, VetheaBlockHelper.hungerstone2.blockID);
		world.setBlock(i + 13, j + 3, k + 3, VetheaBlockHelper.hungerstone2.blockID);
		world.setBlock(i + 13, j + 3, k + 4, VetheaBlockHelper.hungerstone2.blockID);
		world.setBlock(i + 13, j + 3, k + 5, VetheaBlockHelper.hungerstone2.blockID);
		world.setBlock(i + 13, j + 3, k + 6, VetheaBlockHelper.hungerstone2.blockID);
		world.setBlock(i + 13, j + 3, k + 7, VetheaBlockHelper.hungerstone2.blockID);
		world.setBlock(i + 13, j + 3, k + 8, VetheaBlockHelper.hungerstone2.blockID);
		world.setBlock(i + 13, j + 3, k + 9, VetheaBlockHelper.dreamdirt.blockID);
		world.setBlock(i + 13, j + 3, k + 10, VetheaBlockHelper.dreamdirt.blockID);
		world.setBlock(i + 13, j + 4, k + 0, VetheaBlockHelper.dreamdirt.blockID);
		world.setBlock(i + 13, j + 4, k + 1, VetheaBlockHelper.dreamdirt.blockID);
		world.setBlock(i + 13, j + 4, k + 2, VetheaBlockHelper.dreamdirt.blockID);
		world.setBlock(i + 13, j + 4, k + 3, VetheaBlockHelper.dreamdirt.blockID);
		world.setBlock(i + 13, j + 4, k + 4, VetheaBlockHelper.dreamdirt.blockID);
		world.setBlock(i + 13, j + 4, k + 5, VetheaBlockHelper.dreamdirt.blockID);
		world.setBlock(i + 13, j + 4, k + 6, VetheaBlockHelper.dreamdirt.blockID);
		world.setBlock(i + 13, j + 4, k + 7, VetheaBlockHelper.cryptWall.blockID);
		world.setBlock(i + 13, j + 4, k + 8, VetheaBlockHelper.cryptWall.blockID);
		world.setBlock(i + 13, j + 4, k + 9, VetheaBlockHelper.dreamdirt.blockID);
		world.setBlock(i + 13, j + 4, k + 10, VetheaBlockHelper.dreamdirt.blockID);
		world.setBlock(i + 13, j + 5, k + 0, VetheaBlockHelper.metalCaging.blockID);
		world.setBlock(i + 13, j + 5, k + 1, 0);
		world.setBlock(i + 13, j + 5, k + 2, 0);
		world.setBlock(i + 13, j + 5, k + 3, VetheaBlockHelper.hungerstone1.blockID);
		world.setBlock(i + 13, j + 5, k + 4, VetheaBlockHelper.hungerstone1.blockID);
		world.setBlock(i + 13, j + 5, k + 5, VetheaBlockHelper.hungerstone1.blockID);
		world.setBlock(i + 13, j + 5, k + 6, 0);
		world.setBlock(i + 13, j + 5, k + 7, 0);
		world.setBlock(i + 13, j + 5, k + 8, 0);
		world.setBlock(i + 13, j + 5, k + 9, 0);
		world.setBlock(i + 13, j + 5, k + 10, VetheaBlockHelper.metalCaging.blockID);
		world.setBlock(i + 13, j + 6, k + 0, VetheaBlockHelper.hungerstone1.blockID);
		world.setBlock(i + 13, j + 6, k + 1, 0);
		world.setBlock(i + 13, j + 6, k + 2, 0);
		world.setBlock(i + 13, j + 6, k + 3, 0);
		world.setBlock(i + 13, j + 6, k + 4, 0);
		world.setBlock(i + 13, j + 6, k + 5, 0);
		world.setBlock(i + 13, j + 6, k + 6, 0);
		world.setBlock(i + 13, j + 6, k + 7, 0);
		world.setBlock(i + 13, j + 6, k + 8, 0);
		world.setBlock(i + 13, j + 6, k + 9, 0);
		world.setBlock(i + 13, j + 6, k + 10, VetheaBlockHelper.hungerstone1.blockID);
		world.setBlock(i + 13, j + 7, k + 0, 0);
		world.setBlock(i + 13, j + 7, k + 1, 0);
		world.setBlock(i + 13, j + 7, k + 2, 0);
		world.setBlock(i + 13, j + 7, k + 3, 0);
		world.setBlock(i + 13, j + 7, k + 4, 0);
		world.setBlock(i + 13, j + 7, k + 5, 0);
		world.setBlock(i + 13, j + 7, k + 6, 0);
		world.setBlock(i + 13, j + 7, k + 7, 0);
		world.setBlock(i + 13, j + 7, k + 8, 0);
		world.setBlock(i + 13, j + 7, k + 9, 0);
		world.setBlock(i + 13, j + 7, k + 10, 0);
		world.setBlock(i + 13, j + 8, k + 0, 0);
		world.setBlock(i + 13, j + 8, k + 1, 0);
		world.setBlock(i + 13, j + 8, k + 2, 0);
		world.setBlock(i + 13, j + 8, k + 3, 0);
		world.setBlock(i + 13, j + 8, k + 4, 0);
		world.setBlock(i + 13, j + 8, k + 5, 0);
		world.setBlock(i + 13, j + 8, k + 6, 0);
		world.setBlock(i + 13, j + 8, k + 7, 0);
		world.setBlock(i + 13, j + 8, k + 8, 0);
		world.setBlock(i + 13, j + 8, k + 9, 0);
		world.setBlock(i + 13, j + 8, k + 10, 0);
		world.setBlock(i + 13, j + 9, k + 0, 0);
		world.setBlock(i + 13, j + 9, k + 1, 0);
		world.setBlock(i + 13, j + 9, k + 2, 0);
		world.setBlock(i + 13, j + 9, k + 3, 0);
		world.setBlock(i + 13, j + 9, k + 4, 0);
		world.setBlock(i + 13, j + 9, k + 5, 0);
		world.setBlock(i + 13, j + 9, k + 6, 0);
		world.setBlock(i + 13, j + 9, k + 7, 0);
		world.setBlock(i + 13, j + 9, k + 8, 0);
		world.setBlock(i + 13, j + 9, k + 9, 0);
		world.setBlock(i + 13, j + 9, k + 10, 0);
		world.setBlock(i + 13, j + 10, k + 0, 0);
		world.setBlock(i + 13, j + 10, k + 1, 0);
		world.setBlock(i + 13, j + 10, k + 2, 0);
		world.setBlock(i + 13, j + 10, k + 3, 0);
		world.setBlock(i + 13, j + 10, k + 4, 0);
		world.setBlock(i + 13, j + 10, k + 5, 0);
		world.setBlock(i + 13, j + 10, k + 6, 0);
		world.setBlock(i + 13, j + 10, k + 7, 0);
		world.setBlock(i + 13, j + 10, k + 8, 0);
		world.setBlock(i + 13, j + 10, k + 9, 0);
		world.setBlock(i + 13, j + 10, k + 10, 0);
		world.setBlock(i + 14, j + 0, k + 0, VetheaBlockHelper.dreamdirt.blockID);
		world.setBlock(i + 14, j + 0, k + 1, VetheaBlockHelper.cryptFloor.blockID);
		world.setBlock(i + 14, j + 0, k + 2, VetheaBlockHelper.dreamdirt.blockID);
