/*
*** MADE BY MITHION'S .SCHEMATIC TO JAVA CONVERTING TOOL v1.6 ***
*/

package xolova.blued00r.divinerpg.generation.vethea.layer1;
import java.util.Random;

import net.minecraft.block.Block;
import net.minecraft.entity.EntityLiving;
import net.minecraft.world.World;
import net.minecraft.world.gen.feature.WorldGenerator;
import xolova.blued00r.divinerpg.DivineRPG;
import xolova.blued00r.divinerpg.entities.mobs.vethea.EntityCryptKeeper;

public class Crypt1 extends WorldGenerator
{
	public Crypt1() { }

	public boolean generate(World world, Random rand, int i, int j, int k) {		
		world.setBlock(i + 0, j + 0, k + 0, DivineRPGTwilight.dreamdirt.blockID);
		world.setBlock(i + 0, j + 0, k + 1, DivineRPGTwilight.dreamdirt.blockID);
		world.setBlock(i + 0, j + 0, k + 2, DivineRPGTwilight.dreamdirt.blockID);
		world.setBlock(i + 0, j + 0, k + 3, DivineRPGTwilight.dreamdirt.blockID);
		world.setBlock(i + 0, j + 0, k + 4, DivineRPGTwilight.dreamdirt.blockID);
		world.setBlock(i + 0, j + 0, k + 5, DivineRPGTwilight.dreamdirt.blockID);
		world.setBlock(i + 0, j + 0, k + 6, DivineRPGTwilight.dreamdirt.blockID);
		world.setBlock(i + 0, j + 0, k + 7, DivineRPGTwilight.dreamdirt.blockID);
		world.setBlock(i + 0, j + 0, k + 8, DivineRPGTwilight.dreamdirt.blockID);
		world.setBlock(i + 0, j + 0, k + 9, DivineRPGTwilight.dreamdirt.blockID);
		world.setBlock(i + 0, j + 0, k + 10, DivineRPGTwilight.dreamdirt.blockID);
		world.setBlock(i + 0, j + 0, k + 11, DivineRPGTwilight.dreamdirt.blockID);
		world.setBlock(i + 0, j + 0, k + 12, DivineRPGTwilight.dreamdirt.blockID);
		world.setBlock(i + 0, j + 0, k + 13, DivineRPGTwilight.dreamdirt.blockID);
		world.setBlock(i + 0, j + 0, k + 14, DivineRPGTwilight.dreamdirt.blockID);
		world.setBlock(i + 0, j + 0, k + 15, DivineRPGTwilight.dreamdirt.blockID);
		world.setBlock(i + 0, j + 0, k + 16, DivineRPGTwilight.dreamdirt.blockID);
		world.setBlock(i + 0, j + 0, k + 17, DivineRPGTwilight.dreamdirt.blockID);
		world.setBlock(i + 0, j + 0, k + 18, DivineRPGTwilight.dreamdirt.blockID);
		world.setBlock(i + 0, j + 0, k + 19, DivineRPGTwilight.dreamdirt.blockID);
		world.setBlock(i + 0, j + 1, k + 0, DivineRPGTwilight.dreamdirt.blockID);
		world.setBlock(i + 0, j + 1, k + 1, DivineRPGTwilight.dreamdirt.blockID);
		world.setBlock(i + 0, j + 1, k + 2, DivineRPGTwilight.dreamdirt.blockID);
		world.setBlock(i + 0, j + 1, k + 3, DivineRPGTwilight.dreamdirt.blockID);
		world.setBlock(i + 0, j + 1, k + 4, DivineRPGTwilight.dreamdirt.blockID);
		world.setBlock(i + 0, j + 1, k + 5, DivineRPGTwilight.dreamdirt.blockID);
		world.setBlock(i + 0, j + 1, k + 6, DivineRPGTwilight.dreamdirt.blockID);
		world.setBlock(i + 0, j + 1, k + 7, DivineRPGTwilight.dreamdirt.blockID);
		world.setBlock(i + 0, j + 1, k + 8, DivineRPGTwilight.dreamdirt.blockID);
		world.setBlock(i + 0, j + 1, k + 9, DivineRPGTwilight.dreamdirt.blockID);
		world.setBlock(i + 0, j + 1, k + 10, DivineRPGTwilight.dreamdirt.blockID);
		world.setBlock(i + 0, j + 1, k + 11, DivineRPGTwilight.dreamdirt.blockID);
		world.setBlock(i + 0, j + 1, k + 12, DivineRPGTwilight.dreamdirt.blockID);
		world.setBlock(i + 0, j + 1, k + 13, DivineRPGTwilight.dreamdirt.blockID);
		world.setBlock(i + 0, j + 1, k + 14, DivineRPGTwilight.dreamdirt.blockID);
		world.setBlock(i + 0, j + 1, k + 15, DivineRPGTwilight.dreamdirt.blockID);
		world.setBlock(i + 0, j + 1, k + 16, DivineRPGTwilight.dreamdirt.blockID);
		world.setBlock(i + 0, j + 1, k + 17, DivineRPGTwilight.dreamdirt.blockID);
		world.setBlock(i + 0, j + 1, k + 18, DivineRPGTwilight.dreamdirt.blockID);
		world.setBlock(i + 0, j + 1, k + 19, DivineRPGTwilight.dreamdirt.blockID);
		world.setBlock(i + 0, j + 2, k + 0, DivineRPGTwilight.dreamdirt.blockID);
		world.setBlock(i + 0, j + 2, k + 1, DivineRPGTwilight.dreamdirt.blockID);
		world.setBlock(i + 0, j + 2, k + 2, DivineRPGTwilight.dreamdirt.blockID);
		world.setBlock(i + 0, j + 2, k + 3, DivineRPGTwilight.dreamdirt.blockID);
		world.setBlock(i + 0, j + 2, k + 4, DivineRPGTwilight.dreamdirt.blockID);
		world.setBlock(i + 0, j + 2, k + 5, DivineRPGTwilight.dreamdirt.blockID);
		world.setBlock(i + 0, j + 2, k + 6, DivineRPGTwilight.dreamdirt.blockID);
		world.setBlock(i + 0, j + 2, k + 7, DivineRPGTwilight.dreamdirt.blockID);
		world.setBlock(i + 0, j + 2, k + 8, DivineRPGTwilight.dreamdirt.blockID);
		world.setBlock(i + 0, j + 2, k + 9, DivineRPGTwilight.dreamdirt.blockID);
		world.setBlock(i + 0, j + 2, k + 10, DivineRPGTwilight.dreamdirt.blockID);
		world.setBlock(i + 0, j + 2, k + 11, DivineRPGTwilight.dreamdirt.blockID);
		world.setBlock(i + 0, j + 2, k + 12, DivineRPGTwilight.dreamdirt.blockID);
		world.setBlock(i + 0, j + 2, k + 13, DivineRPGTwilight.dreamdirt.blockID);
		world.setBlock(i + 0, j + 2, k + 14, DivineRPGTwilight.dreamdirt.blockID);
		world.setBlock(i + 0, j + 2, k + 15, DivineRPGTwilight.dreamdirt.blockID);
		world.setBlock(i + 0, j + 2, k + 16, DivineRPGTwilight.dreamdirt.blockID);
		world.setBlock(i + 0, j + 2, k + 17, DivineRPGTwilight.dreamdirt.blockID);
		world.setBlock(i + 0, j + 2, k + 18, DivineRPGTwilight.dreamdirt.blockID);
		world.setBlock(i + 0, j + 2, k + 19, DivineRPGTwilight.dreamdirt.blockID);
		world.setBlock(i + 0, j + 3, k + 0, DivineRPGTwilight.dreamdirt.blockID);
		world.setBlock(i + 0, j + 3, k + 1, DivineRPGTwilight.dreamdirt.blockID);
		world.setBlock(i + 0, j + 3, k + 2, DivineRPGTwilight.dreamdirt.blockID);
		world.setBlock(i + 0, j + 3, k + 3, DivineRPGTwilight.dreamdirt.blockID);
		world.setBlock(i + 0, j + 3, k + 4, DivineRPGTwilight.dreamdirt.blockID);
		world.setBlock(i + 0, j + 3, k + 5, DivineRPGTwilight.dreamdirt.blockID);
		world.setBlock(i + 0, j + 3, k + 6, DivineRPGTwilight.dreamdirt.blockID);
		world.setBlock(i + 0, j + 3, k + 7, DivineRPGTwilight.dreamdirt.blockID);
		world.setBlock(i + 0, j + 3, k + 8, DivineRPGTwilight.dreamdirt.blockID);
		world.setBlock(i + 0, j + 3, k + 9, DivineRPGTwilight.dreamdirt.blockID);
		world.setBlock(i + 0, j + 3, k + 10, DivineRPGTwilight.dreamdirt.blockID);
		world.setBlock(i + 0, j + 3, k + 11, DivineRPGTwilight.dreamdirt.blockID);
		world.setBlock(i + 0, j + 3, k + 12, DivineRPGTwilight.dreamdirt.blockID);
		world.setBlock(i + 0, j + 3, k + 13, DivineRPGTwilight.dreamdirt.blockID);
		world.setBlock(i + 0, j + 3, k + 14, DivineRPGTwilight.dreamdirt.blockID);
		world.setBlock(i + 0, j + 3, k + 15, DivineRPGTwilight.dreamdirt.blockID);
		world.setBlock(i + 0, j + 3, k + 16, DivineRPGTwilight.dreamdirt.blockID);
		world.setBlock(i + 0, j + 3, k + 17, DivineRPGTwilight.dreamdirt.blockID);
		world.setBlock(i + 0, j + 3, k + 18, DivineRPGTwilight.dreamdirt.blockID);
		world.setBlock(i + 0, j + 3, k + 19, DivineRPGTwilight.dreamdirt.blockID);
		world.setBlock(i + 0, j + 4, k + 0, DivineRPGTwilight.dreamdirt.blockID);
		world.setBlock(i + 0, j + 4, k + 1, DivineRPGTwilight.dreamdirt.blockID);
		world.setBlock(i + 0, j + 4, k + 2, DivineRPGTwilight.dreamdirt.blockID);
		world.setBlock(i + 0, j + 4, k + 3, DivineRPGTwilight.dreamdirt.blockID);
		world.setBlock(i + 0, j + 4, k + 4, DivineRPGTwilight.dreamdirt.blockID);
		world.setBlock(i + 0, j + 4, k + 5, DivineRPGTwilight.dreamdirt.blockID);
		world.setBlock(i + 0, j + 4, k + 6, DivineRPGTwilight.dreamdirt.blockID);
		world.setBlock(i + 0, j + 4, k + 7, DivineRPGTwilight.dreamdirt.blockID);
		world.setBlock(i + 0, j + 4, k + 8, DivineRPGTwilight.dreamdirt.blockID);
		world.setBlock(i + 0, j + 4, k + 9, DivineRPGTwilight.dreamdirt.blockID);
		world.setBlock(i + 0, j + 4, k + 10, DivineRPGTwilight.dreamdirt.blockID);
		world.setBlock(i + 0, j + 4, k + 11, DivineRPGTwilight.dreamdirt.blockID);
		world.setBlock(i + 0, j + 4, k + 12, DivineRPGTwilight.dreamdirt.blockID);
		world.setBlock(i + 0, j + 4, k + 13, DivineRPGTwilight.dreamdirt.blockID);
		world.setBlock(i + 0, j + 4, k + 14, DivineRPGTwilight.dreamdirt.blockID);
		world.setBlock(i + 0, j + 4, k + 15, DivineRPGTwilight.dreamdirt.blockID);
		world.setBlock(i + 0, j + 4, k + 16, DivineRPGTwilight.dreamdirt.blockID);
		world.setBlock(i + 0, j + 4, k + 17, DivineRPGTwilight.dreamdirt.blockID);
		world.setBlock(i + 0, j + 4, k + 18, DivineRPGTwilight.dreamdirt.blockID);
		world.setBlock(i + 0, j + 4, k + 19, DivineRPGTwilight.dreamdirt.blockID);
		world.setBlock(i + 0, j + 5, k + 0, DivineRPGTwilight.dreamdirt.blockID);
		world.setBlock(i + 0, j + 5, k + 1, DivineRPGTwilight.dreamdirt.blockID);
		world.setBlock(i + 0, j + 5, k + 2, DivineRPGTwilight.dreamdirt.blockID);
		world.setBlock(i + 0, j + 5, k + 3, DivineRPGTwilight.cryptWall.blockID);
		world.setBlock(i + 0, j + 5, k + 4, DivineRPGTwilight.cryptWall.blockID);
		world.setBlock(i + 0, j + 5, k + 5, DivineRPGTwilight.dreamdirt.blockID);
		world.setBlock(i + 0, j + 5, k + 6, DivineRPGTwilight.dreamdirt.blockID);
		world.setBlock(i + 0, j + 5, k + 7, DivineRPGTwilight.dreamdirt.blockID);
		world.setBlock(i + 0, j + 5, k + 8, DivineRPGTwilight.dreamdirt.blockID);
		world.setBlock(i + 0, j + 5, k + 9, DivineRPGTwilight.dreamdirt.blockID);
		world.setBlock(i + 0, j + 5, k + 10, DivineRPGTwilight.dreamdirt.blockID);
		world.setBlock(i + 0, j + 5, k + 11, DivineRPGTwilight.dreamdirt.blockID);
		world.setBlock(i + 0, j + 5, k + 12, DivineRPGTwilight.dreamdirt.blockID);
		world.setBlock(i + 0, j + 5, k + 13, DivineRPGTwilight.dreamdirt.blockID);
		world.setBlock(i + 0, j + 5, k + 14, DivineRPGTwilight.cryptWall.blockID);
		world.setBlock(i + 0, j + 5, k + 15, DivineRPGTwilight.cryptWall.blockID);
		world.setBlock(i + 0, j + 5, k + 16, DivineRPGTwilight.dreamdirt.blockID);
		world.setBlock(i + 0, j + 5, k + 17, DivineRPGTwilight.dreamdirt.blockID);
		world.setBlock(i + 0, j + 5, k + 18, DivineRPGTwilight.dreamdirt.blockID);
		world.setBlock(i + 0, j + 5, k + 19, DivineRPGTwilight.dreamdirt.blockID);
		world.setBlock(i + 0, j + 6, k + 0, DivineRPGTwilight.metalCaging.blockID);
		world.setBlock(i + 0, j + 6, k + 1, DivineRPGTwilight.metalCaging.blockID);
		world.setBlock(i + 0, j + 6, k + 2, DivineRPGTwilight.hungerstone1.blockID);
		world.setBlock(i + 0, j + 6, k + 3, 0);
		world.setBlock(i + 0, j + 6, k + 4, 0);
		world.setBlock(i + 0, j + 6, k + 5, DivineRPGTwilight.hungerstone1.blockID);
		world.setBlock(i + 0, j + 6, k + 6, DivineRPGTwilight.metalCaging.blockID);
		world.setBlock(i + 0, j + 6, k + 7, DivineRPGTwilight.metalCaging.blockID);
		world.setBlock(i + 0, j + 6, k + 8, DivineRPGTwilight.metalCaging.blockID);
		world.setBlock(i + 0, j + 6, k + 9, DivineRPGTwilight.metalCaging.blockID);
		world.setBlock(i + 0, j + 6, k + 10, DivineRPGTwilight.metalCaging.blockID);
		world.setBlock(i + 0, j + 6, k + 11, DivineRPGTwilight.metalCaging.blockID);
		world.setBlock(i + 0, j + 6, k + 12, DivineRPGTwilight.metalCaging.blockID);
		world.setBlock(i + 0, j + 6, k + 13, DivineRPGTwilight.hungerstone1.blockID);
		world.setBlock(i + 0, j + 6, k + 14, 0);
		world.setBlock(i + 0, j + 6, k + 15, 0);
		world.setBlock(i + 0, j + 6, k + 16, DivineRPGTwilight.hungerstone1.blockID);
		world.setBlock(i + 0, j + 6, k + 17, DivineRPGTwilight.metalCaging.blockID);
		world.setBlock(i + 0, j + 6, k + 18, DivineRPGTwilight.metalCaging.blockID);
		world.setBlock(i + 0, j + 6, k + 19, DivineRPGTwilight.metalCaging.blockID);
		world.setBlock(i + 0, j + 7, k + 0, DivineRPGTwilight.hungerstone1.blockID);
		world.setBlock(i + 0, j + 7, k + 1, DivineRPGTwilight.hungerstone1.blockID);
		world.setBlock(i + 0, j + 7, k + 2, DivineRPGTwilight.hungerstone1.blockID);
		world.setBlock(i + 0, j + 7, k + 3, 0);
		world.setBlock(i + 0, j + 7, k + 4, 0);
		world.setBlock(i + 0, j + 7, k + 5, DivineRPGTwilight.hungerstone1.blockID);
		world.setBlock(i + 0, j + 7, k + 6, DivineRPGTwilight.hungerstone1.blockID);
		world.setBlock(i + 0, j + 7, k + 7, DivineRPGTwilight.hungerstone1.blockID);
		world.setBlock(i + 0, j + 7, k + 8, DivineRPGTwilight.hungerstone1.blockID);
		world.setBlock(i + 0, j + 7, k + 9, DivineRPGTwilight.hungerstone1.blockID);
		world.setBlock(i + 0, j + 7, k + 10, DivineRPGTwilight.hungerstone1.blockID);
		world.setBlock(i + 0, j + 7, k + 11, DivineRPGTwilight.hungerstone1.blockID);
		world.setBlock(i + 0, j + 7, k + 12, DivineRPGTwilight.hungerstone1.blockID);
		world.setBlock(i + 0, j + 7, k + 13, DivineRPGTwilight.hungerstone1.blockID);
		world.setBlock(i + 0, j + 7, k + 14, 0);
		world.setBlock(i + 0, j + 7, k + 15, 0);
		world.setBlock(i + 0, j + 7, k + 16, DivineRPGTwilight.hungerstone1.blockID);
		world.setBlock(i + 0, j + 7, k + 17, DivineRPGTwilight.hungerstone1.blockID);
		world.setBlock(i + 0, j + 7, k + 18, DivineRPGTwilight.hungerstone1.blockID);
		world.setBlock(i + 0, j + 7, k + 19, DivineRPGTwilight.hungerstone1.blockID);
		world.setBlock(i + 0, j + 8, k + 0, 0);
		world.setBlock(i + 0, j + 8, k + 1, 0);
		world.setBlock(i + 0, j + 8, k + 2, DivineRPGTwilight.hungerstone1.blockID);
		world.setBlock(i + 0, j + 8, k + 3, DivineRPGTwilight.hungerstone1.blockID);
		world.setBlock(i + 0, j + 8, k + 4, DivineRPGTwilight.hungerstone1.blockID);
		world.setBlock(i + 0, j + 8, k + 5, DivineRPGTwilight.hungerstone1.blockID);
		world.setBlock(i + 0, j + 8, k + 6, 0);
		world.setBlock(i + 0, j + 8, k + 7, 0);
		world.setBlock(i + 0, j + 8, k + 8, 0);
		world.setBlock(i + 0, j + 8, k + 9, 0);
		world.setBlock(i + 0, j + 8, k + 10, 0);
		world.setBlock(i + 0, j + 8, k + 11, 0);
		world.setBlock(i + 0, j + 8, k + 12, 0);
		world.setBlock(i + 0, j + 8, k + 13, DivineRPGTwilight.hungerstone1.blockID);
		world.setBlock(i + 0, j + 8, k + 14, DivineRPGTwilight.hungerstone1.blockID);
		world.setBlock(i + 0, j + 8, k + 15, DivineRPGTwilight.hungerstone1.blockID);
		world.setBlock(i + 0, j + 8, k + 16, DivineRPGTwilight.hungerstone1.blockID);
		world.setBlock(i + 0, j + 8, k + 17, 0);
		world.setBlock(i + 0, j + 8, k + 18, 0);
		world.setBlock(i + 0, j + 8, k + 19, 0);
		world.setBlock(i + 0, j + 9, k + 0, 0);
		world.setBlock(i + 0, j + 9, k + 1, 0);
		world.setBlock(i + 0, j + 9, k + 2, 0);
		world.setBlock(i + 0, j + 9, k + 3, 0);
		world.setBlock(i + 0, j + 9, k + 4, 0);
		world.setBlock(i + 0, j + 9, k + 5, 0);
		world.setBlock(i + 0, j + 9, k + 6, 0);
		world.setBlock(i + 0, j + 9, k + 7, 0);
		world.setBlock(i + 0, j + 9, k + 8, 0);
		world.setBlock(i + 0, j + 9, k + 9, 0);
		world.setBlock(i + 0, j + 9, k + 10, 0);
		world.setBlock(i + 0, j + 9, k + 11, 0);
		world.setBlock(i + 0, j + 9, k + 12, 0);
		world.setBlock(i + 0, j + 9, k + 13, 0);
		world.setBlock(i + 0, j + 9, k + 14, 0);
		world.setBlock(i + 0, j + 9, k + 15, 0);
		world.setBlock(i + 0, j + 9, k + 16, 0);
		world.setBlock(i + 0, j + 9, k + 17, 0);
		world.setBlock(i + 0, j + 9, k + 18, 0);
		world.setBlock(i + 0, j + 9, k + 19, 0);
		world.setBlock(i + 0, j + 10, k + 0, 0);
		world.setBlock(i + 0, j + 10, k + 1, 0);
		world.setBlock(i + 0, j + 10, k + 2, 0);
		world.setBlock(i + 0, j + 10, k + 3, 0);
		world.setBlock(i + 0, j + 10, k + 4, 0);
		world.setBlock(i + 0, j + 10, k + 5, 0);
		world.setBlock(i + 0, j + 10, k + 6, 0);
		world.setBlock(i + 0, j + 10, k + 7, 0);
		world.setBlock(i + 0, j + 10, k + 8, 0);
		world.setBlock(i + 0, j + 10, k + 9, 0);
		world.setBlock(i + 0, j + 10, k + 10, 0);
		world.setBlock(i + 0, j + 10, k + 11, 0);
		world.setBlock(i + 0, j + 10, k + 12, 0);
		world.setBlock(i + 0, j + 10, k + 13, 0);
		world.setBlock(i + 0, j + 10, k + 14, 0);
		world.setBlock(i + 0, j + 10, k + 15, 0);
		world.setBlock(i + 0, j + 10, k + 16, 0);
		world.setBlock(i + 0, j + 10, k + 17, 0);
		world.setBlock(i + 0, j + 10, k + 18, 0);
		world.setBlock(i + 0, j + 10, k + 19, 0);
		world.setBlock(i + 1, j + 0, k + 0, DivineRPGTwilight.dreamdirt.blockID);
		world.setBlock(i + 1, j + 0, k + 1, DivineRPGTwilight.dreamdirt.blockID);
		world.setBlock(i + 1, j + 0, k + 2, DivineRPGTwilight.dreamdirt.blockID);
		world.setBlock(i + 1, j + 0, k + 3, DivineRPGTwilight.dreamdirt.blockID);
		world.setBlock(i + 1, j + 0, k + 4, DivineRPGTwilight.dreamdirt.blockID);
		world.setBlock(i + 1, j + 0, k + 5, DivineRPGTwilight.dreamdirt.blockID);
		world.setBlock(i + 1, j + 0, k + 6, DivineRPGTwilight.dreamdirt.blockID);
		world.setBlock(i + 1, j + 0, k + 7, DivineRPGTwilight.dreamdirt.blockID);
		world.setBlock(i + 1, j + 0, k + 8, DivineRPGTwilight.dreamdirt.blockID);
		world.setBlock(i + 1, j + 0, k + 9, DivineRPGTwilight.dreamdirt.blockID);
		world.setBlock(i + 1, j + 0, k + 10, DivineRPGTwilight.cryptWall.blockID);
		world.setBlock(i + 1, j + 0, k + 11, DivineRPGTwilight.cryptWall.blockID);
		world.setBlock(i + 1, j + 0, k + 12, DivineRPGTwilight.cryptWall.blockID);
		world.setBlock(i + 1, j + 0, k + 13, DivineRPGTwilight.dreamdirt.blockID);
		world.setBlock(i + 1, j + 0, k + 14, DivineRPGTwilight.dreamdirt.blockID);
		world.setBlock(i + 1, j + 0, k + 15, DivineRPGTwilight.dreamdirt.blockID);
		world.setBlock(i + 1, j + 0, k + 16, DivineRPGTwilight.dreamdirt.blockID);
		world.setBlock(i + 1, j + 0, k + 17, DivineRPGTwilight.dreamdirt.blockID);
		world.setBlock(i + 1, j + 0, k + 18, DivineRPGTwilight.dreamdirt.blockID);
		world.setBlock(i + 1, j + 0, k + 19, DivineRPGTwilight.dreamdirt.blockID);
		world.setBlock(i + 1, j + 1, k + 0, DivineRPGTwilight.dreamdirt.blockID);
		world.setBlock(i + 1, j + 1, k + 1, DivineRPGTwilight.dreamdirt.blockID);
		world.setBlock(i + 1, j + 1, k + 2, DivineRPGTwilight.dreamdirt.blockID);
		world.setBlock(i + 1, j + 1, k + 3, DivineRPGTwilight.dreamdirt.blockID);
		world.setBlock(i + 1, j + 1, k + 4, DivineRPGTwilight.dreamdirt.blockID);
		world.setBlock(i + 1, j + 1, k + 5, DivineRPGTwilight.dreamdirt.blockID);
		world.setBlock(i + 1, j + 1, k + 6, DivineRPGTwilight.dreamdirt.blockID);
		world.setBlock(i + 1, j + 1, k + 7, DivineRPGTwilight.dreamdirt.blockID);
		world.setBlock(i + 1, j + 1, k + 8, DivineRPGTwilight.dreamdirt.blockID);
		world.setBlock(i + 1, j + 1, k + 9, DivineRPGTwilight.dreamdirt.blockID);
		world.setBlock(i + 1, j + 1, k + 10, DivineRPGTwilight.cryptWall.blockID);
		world.setBlock(i + 1, j + 1, k + 11, DivineRPGTwilight.cryptWall.blockID);
		world.setBlock(i + 1, j + 1, k + 12, DivineRPGTwilight.cryptWall.blockID);
		world.setBlock(i + 1, j + 1, k + 13, DivineRPGTwilight.cryptWall.blockID);
		world.setBlock(i + 1, j + 1, k + 14, DivineRPGTwilight.cryptWall.blockID);
		world.setBlock(i + 1, j + 1, k + 15, DivineRPGTwilight.cryptWall.blockID);
		world.setBlock(i + 1, j + 1, k + 16, DivineRPGTwilight.dreamdirt.blockID);
		world.setBlock(i + 1, j + 1, k + 17, DivineRPGTwilight.dreamdirt.blockID);
		world.setBlock(i + 1, j + 1, k + 18, DivineRPGTwilight.dreamdirt.blockID);
		world.setBlock(i + 1, j + 1, k + 19, DivineRPGTwilight.dreamdirt.blockID);
		world.setBlock(i + 1, j + 2, k + 0, DivineRPGTwilight.dreamdirt.blockID);
		world.setBlock(i + 1, j + 2, k + 1, DivineRPGTwilight.dreamdirt.blockID);
		world.setBlock(i + 1, j + 2, k + 2, DivineRPGTwilight.dreamdirt.blockID);
		world.setBlock(i + 1, j + 2, k + 3, DivineRPGTwilight.dreamdirt.blockID);
		world.setBlock(i + 1, j + 2, k + 4, DivineRPGTwilight.dreamdirt.blockID);
		world.setBlock(i + 1, j + 2, k + 5, DivineRPGTwilight.dreamdirt.blockID);
		world.setBlock(i + 1, j + 2, k + 6, DivineRPGTwilight.dreamdirt.blockID);
		world.setBlock(i + 1, j + 2, k + 7, DivineRPGTwilight.dreamdirt.blockID);
		world.setBlock(i + 1, j + 2, k + 8, DivineRPGTwilight.dreamdirt.blockID);
		world.setBlock(i + 1, j + 2, k + 9, DivineRPGTwilight.dreamdirt.blockID);
		world.setBlock(i + 1, j + 2, k + 10, DivineRPGTwilight.cryptWall.blockID);
		world.setBlock(i + 1, j + 2, k + 11, DivineRPGTwilight.cryptWall.blockID);
		world.setBlock(i + 1, j + 2, k + 12, DivineRPGTwilight.cryptWall.blockID);
		world.setBlock(i + 1, j + 2, k + 13, DivineRPGTwilight.cryptWall.blockID);
		world.setBlock(i + 1, j + 2, k + 14, DivineRPGTwilight.cryptWall.blockID);
		world.setBlock(i + 1, j + 2, k + 15, DivineRPGTwilight.cryptWall.blockID);
		world.setBlock(i + 1, j + 2, k + 16, DivineRPGTwilight.dreamdirt.blockID);
		world.setBlock(i + 1, j + 2, k + 17, DivineRPGTwilight.dreamdirt.blockID);
		world.setBlock(i + 1, j + 2, k + 18, DivineRPGTwilight.dreamdirt.blockID);
		world.setBlock(i + 1, j + 2, k + 19, DivineRPGTwilight.dreamdirt.blockID);
		world.setBlock(i + 1, j + 3, k + 0, DivineRPGTwilight.dreamdirt.blockID);
		world.setBlock(i + 1, j + 3, k + 1, DivineRPGTwilight.dreamdirt.blockID);
		world.setBlock(i + 1, j + 3, k + 2, DivineRPGTwilight.dreamdirt.blockID);
		world.setBlock(i + 1, j + 3, k + 3, DivineRPGTwilight.dreamdirt.blockID);
		world.setBlock(i + 1, j + 3, k + 4, DivineRPGTwilight.dreamdirt.blockID);
		world.setBlock(i + 1, j + 3, k + 5, DivineRPGTwilight.dreamdirt.blockID);
		world.setBlock(i + 1, j + 3, k + 6, DivineRPGTwilight.dreamdirt.blockID);
		world.setBlock(i + 1, j + 3, k + 7, DivineRPGTwilight.dreamdirt.blockID);
		world.setBlock(i + 1, j + 3, k + 8, DivineRPGTwilight.dreamdirt.blockID);
		world.setBlock(i + 1, j + 3, k + 9, DivineRPGTwilight.dreamdirt.blockID);
		world.setBlock(i + 1, j + 3, k + 10, DivineRPGTwilight.cryptWall.blockID);
		world.setBlock(i + 1, j + 3, k + 11, DivineRPGTwilight.cryptWall.blockID);
		world.setBlock(i + 1, j + 3, k + 12, DivineRPGTwilight.cryptWall.blockID);
		world.setBlock(i + 1, j + 3, k + 13, DivineRPGTwilight.cryptWall.blockID);
		world.setBlock(i + 1, j + 3, k + 14, DivineRPGTwilight.cryptWall.blockID);
		world.setBlock(i + 1, j + 3, k + 15, DivineRPGTwilight.cryptWall.blockID);
		world.setBlock(i + 1, j + 3, k + 16, DivineRPGTwilight.dreamdirt.blockID);
		world.setBlock(i + 1, j + 3, k + 17, DivineRPGTwilight.dreamdirt.blockID);
		world.setBlock(i + 1, j + 3, k + 18, DivineRPGTwilight.dreamdirt.blockID);
		world.setBlock(i + 1, j + 3, k + 19, DivineRPGTwilight.dreamdirt.blockID);
		world.setBlock(i + 1, j + 4, k + 0, DivineRPGTwilight.dreamdirt.blockID);
		world.setBlock(i + 1, j + 4, k + 1, DivineRPGTwilight.dreamdirt.blockID);
		world.setBlock(i + 1, j + 4, k + 2, DivineRPGTwilight.dreamdirt.blockID);
		world.setBlock(i + 1, j + 4, k + 3, DivineRPGTwilight.dreamdirt.blockID);
		world.setBlock(i + 1, j + 4, k + 4, DivineRPGTwilight.dreamdirt.blockID);
		world.setBlock(i + 1, j + 4, k + 5, DivineRPGTwilight.dreamdirt.blockID);
		world.setBlock(i + 1, j + 4, k + 6, DivineRPGTwilight.dreamdirt.blockID);
		world.setBlock(i + 1, j + 4, k + 7, DivineRPGTwilight.dreamdirt.blockID);
		world.setBlock(i + 1, j + 4, k + 8, DivineRPGTwilight.dreamdirt.blockID);
		world.setBlock(i + 1, j + 4, k + 9, DivineRPGTwilight.dreamdirt.blockID);
		world.setBlock(i + 1, j + 4, k + 10, DivineRPGTwilight.dreamdirt.blockID);
		world.setBlock(i + 1, j + 4, k + 11, DivineRPGTwilight.dreamdirt.blockID);
		world.setBlock(i + 1, j + 4, k + 12, DivineRPGTwilight.dreamdirt.blockID);
		world.setBlock(i + 1, j + 4, k + 13, DivineRPGTwilight.dreamdirt.blockID);
		world.setBlock(i + 1, j + 4, k + 14, DivineRPGTwilight.dreamdirt.blockID);
		world.setBlock(i + 1, j + 4, k + 15, DivineRPGTwilight.dreamdirt.blockID);
		world.setBlock(i + 1, j + 4, k + 16, DivineRPGTwilight.dreamdirt.blockID);
		world.setBlock(i + 1, j + 4, k + 17, DivineRPGTwilight.dreamdirt.blockID);
		world.setBlock(i + 1, j + 4, k + 18, DivineRPGTwilight.dreamdirt.blockID);
		world.setBlock(i + 1, j + 4, k + 19, DivineRPGTwilight.dreamdirt.blockID);
		world.setBlock(i + 1, j + 5, k + 0, DivineRPGTwilight.dreamdirt.blockID);
		world.setBlock(i + 1, j + 5, k + 1, DivineRPGTwilight.dreamdirt.blockID);
		world.setBlock(i + 1, j + 5, k + 2, DivineRPGTwilight.dreamdirt.blockID);
		world.setBlock(i + 1, j + 5, k + 3, DivineRPGTwilight.cryptWall.blockID);
		world.setBlock(i + 1, j + 5, k + 4, DivineRPGTwilight.cryptWall.blockID);
		world.setBlock(i + 1, j + 5, k + 5, DivineRPGTwilight.dreamdirt.blockID);
		world.setBlock(i + 1, j + 5, k + 6, DivineRPGTwilight.dreamdirt.blockID);
		world.setBlock(i + 1, j + 5, k + 7, DivineRPGTwilight.dreamdirt.blockID);
		world.setBlock(i + 1, j + 5, k + 8, DivineRPGTwilight.dreamdirt.blockID);
		world.setBlock(i + 1, j + 5, k + 9, DivineRPGTwilight.dreamdirt.blockID);
		world.setBlock(i + 1, j + 5, k + 10, DivineRPGTwilight.dreamdirt.blockID);
		world.setBlock(i + 1, j + 5, k + 11, DivineRPGTwilight.dreamdirt.blockID);
		world.setBlock(i + 1, j + 5, k + 12, DivineRPGTwilight.dreamdirt.blockID);
		world.setBlock(i + 1, j + 5, k + 13, DivineRPGTwilight.dreamdirt.blockID);
		world.setBlock(i + 1, j + 5, k + 14, DivineRPGTwilight.cryptWall.blockID);
		world.setBlock(i + 1, j + 5, k + 15, DivineRPGTwilight.cryptWall.blockID);
		world.setBlock(i + 1, j + 5, k + 16, DivineRPGTwilight.dreamdirt.blockID);
		world.setBlock(i + 1, j + 5, k + 17, DivineRPGTwilight.dreamdirt.blockID);
		world.setBlock(i + 1, j + 5, k + 18, DivineRPGTwilight.dreamdirt.blockID);
		world.setBlock(i + 1, j + 5, k + 19, DivineRPGTwilight.dreamdirt.blockID);
		world.setBlock(i + 1, j + 6, k + 0, DivineRPGTwilight.metalCaging.blockID);
		world.setBlock(i + 1, j + 6, k + 1, 0);
		world.setBlock(i + 1, j + 6, k + 2, 0);
		world.setBlock(i + 1, j + 6, k + 3, 0);
		world.setBlock(i + 1, j + 6, k + 4, 0);
		world.setBlock(i + 1, j + 6, k + 5, 0);
		world.setBlock(i + 1, j + 6, k + 6, 0);
		world.setBlock(i + 1, j + 6, k + 7, 0);
		world.setBlock(i + 1, j + 6, k + 8, 0);
		world.setBlock(i + 1, j + 6, k + 9, 0);
		world.setBlock(i + 1, j + 6, k + 10, 0);
		world.setBlock(i + 1, j + 6, k + 11, 0);
		world.setBlock(i + 1, j + 6, k + 12, 0);
		world.setBlock(i + 1, j + 6, k + 13, 0);
		world.setBlock(i + 1, j + 6, k + 14, 0);
		world.setBlock(i + 1, j + 6, k + 15, 0);
		world.setBlock(i + 1, j + 6, k + 16, 0);
		world.setBlock(i + 1, j + 6, k + 17, 0);
		world.setBlock(i + 1, j + 6, k + 18, 0);
		world.setBlock(i + 1, j + 6, k + 19, DivineRPGTwilight.metalCaging.blockID);
		world.setBlock(i + 1, j + 7, k + 0, DivineRPGTwilight.hungerstone1.blockID);
		world.setBlock(i + 1, j + 7, k + 1, 0);
		world.setBlock(i + 1, j + 7, k + 2, 0);
		world.setBlock(i + 1, j + 7, k + 3, 0);
		world.setBlock(i + 1, j + 7, k + 4, 0);
		world.setBlock(i + 1, j + 7, k + 5, 0);
		world.setBlock(i + 1, j + 7, k + 6, 0);
		world.setBlock(i + 1, j + 7, k + 7, 0);
		world.setBlock(i + 1, j + 7, k + 8, 0);
		world.setBlock(i + 1, j + 7, k + 9, 0);
		world.setBlock(i + 1, j + 7, k + 10, 0);
		world.setBlock(i + 1, j + 7, k + 11, 0);
		world.setBlock(i + 1, j + 7, k + 12, 0);
		world.setBlock(i + 1, j + 7, k + 13, 0);
		world.setBlock(i + 1, j + 7, k + 14, 0);
		world.setBlock(i + 1, j + 7, k + 15, 0);
		world.setBlock(i + 1, j + 7, k + 16, 0);
		world.setBlock(i + 1, j + 7, k + 17, 0);
		world.setBlock(i + 1, j + 7, k + 18, 0);
		world.setBlock(i + 1, j + 7, k + 19, DivineRPGTwilight.hungerstone1.blockID);
		world.setBlock(i + 1, j + 8, k + 0, 0);
		world.setBlock(i + 1, j + 8, k + 1, 0);
		world.setBlock(i + 1, j + 8, k + 2, 0);
		world.setBlock(i + 1, j + 8, k + 3, 0);
		world.setBlock(i + 1, j + 8, k + 4, 0);
		world.setBlock(i + 1, j + 8, k + 5, 0);
		world.setBlock(i + 1, j + 8, k + 6, 0);
		world.setBlock(i + 1, j + 8, k + 7, 0);
		world.setBlock(i + 1, j + 8, k + 8, 0);
		world.setBlock(i + 1, j + 8, k + 9, 0);
		world.setBlock(i + 1, j + 8, k + 10, 0);
		world.setBlock(i + 1, j + 8, k + 11, 0);
		world.setBlock(i + 1, j + 8, k + 12, 0);
		world.setBlock(i + 1, j + 8, k + 13, 0);
		world.setBlock(i + 1, j + 8, k + 14, 0);
		world.setBlock(i + 1, j + 8, k + 15, 0);
		world.setBlock(i + 1, j + 8, k + 16, 0);
		world.setBlock(i + 1, j + 8, k + 17, 0);
		world.setBlock(i + 1, j + 8, k + 18, 0);
		world.setBlock(i + 1, j + 8, k + 19, 0);
		world.setBlock(i + 1, j + 9, k + 0, 0);
		world.setBlock(i + 1, j + 9, k + 1, 0);
		world.setBlock(i + 1, j + 9, k + 2, 0);
		world.setBlock(i + 1, j + 9, k + 3, 0);
		world.setBlock(i + 1, j + 9, k + 4, 0);
		world.setBlock(i + 1, j + 9, k + 5, 0);
		world.setBlock(i + 1, j + 9, k + 6, 0);
		world.setBlock(i + 1, j + 9, k + 7, 0);
		world.setBlock(i + 1, j + 9, k + 8, 0);
		world.setBlock(i + 1, j + 9, k + 9, 0);
		world.setBlock(i + 1, j + 9, k + 10, 0);
		world.setBlock(i + 1, j + 9, k + 11, 0);
		world.setBlock(i + 1, j + 9, k + 12, 0);
		world.setBlock(i + 1, j + 9, k + 13, 0);
		world.setBlock(i + 1, j + 9, k + 14, 0);
		world.setBlock(i + 1, j + 9, k + 15, 0);
		world.setBlock(i + 1, j + 9, k + 16, 0);
		world.setBlock(i + 1, j + 9, k + 17, 0);
		world.setBlock(i + 1, j + 9, k + 18, 0);
		world.setBlock(i + 1, j + 9, k + 19, 0);
		world.setBlock(i + 1, j + 10, k + 0, 0);
		world.setBlock(i + 1, j + 10, k + 1, 0);
		world.setBlock(i + 1, j + 10, k + 2, 0);
		world.setBlock(i + 1, j + 10, k + 3, 0);
		world.setBlock(i + 1, j + 10, k + 4, 0);
		world.setBlock(i + 1, j + 10, k + 5, 0);
		world.setBlock(i + 1, j + 10, k + 6, 0);
		world.setBlock(i + 1, j + 10, k + 7, 0);
		world.setBlock(i + 1, j + 10, k + 8, 0);
		world.setBlock(i + 1, j + 10, k + 9, 0);
		world.setBlock(i + 1, j + 10, k + 10, 0);
		world.setBlock(i + 1, j + 10, k + 11, 0);
		world.setBlock(i + 1, j + 10, k + 12, 0);
		world.setBlock(i + 1, j + 10, k + 13, 0);
		world.setBlock(i + 1, j + 10, k + 14, 0);
		world.setBlock(i + 1, j + 10, k + 15, 0);
		world.setBlock(i + 1, j + 10, k + 16, 0);
		world.setBlock(i + 1, j + 10, k + 17, 0);
		world.setBlock(i + 1, j + 10, k + 18, 0);
		world.setBlock(i + 1, j + 10, k + 19, 0);
		world.setBlock(i + 2, j + 0, k + 0, DivineRPGTwilight.dreamdirt.blockID);
		world.setBlock(i + 2, j + 0, k + 1, DivineRPGTwilight.cryptWall.blockID);
		world.setBlock(i + 2, j + 0, k + 2, DivineRPGTwilight.cryptWall.blockID);
		world.setBlock(i + 2, j + 0, k + 3, DivineRPGTwilight.cryptWall.blockID);
		world.setBlock(i + 2, j + 0, k + 4, DivineRPGTwilight.cryptWall.blockID);
		world.setBlock(i + 2, j + 0, k + 5, DivineRPGTwilight.cryptWall.blockID);
		world.setBlock(i + 2, j + 0, k + 6, DivineRPGTwilight.cryptWall.blockID);
		world.setBlock(i + 2, j + 0, k + 7, DivineRPGTwilight.cryptWall.blockID);
		world.setBlock(i + 2, j + 0, k + 8, DivineRPGTwilight.cryptWall.blockID);
		world.setBlock(i + 2, j + 0, k + 9, DivineRPGTwilight.cryptWall.blockID);
		world.setBlock(i + 2, j + 0, k + 10, 0);
		world.setBlock(i + 2, j + 0, k + 11, 0);
		world.setBlock(i + 2, j + 0, k + 12, 0);
		world.setBlock(i + 2, j + 0, k + 13, DivineRPGTwilight.cryptFloor.blockID);
		world.setBlock(i + 2, j + 0, k + 14, DivineRPGTwilight.cryptFloor.blockID);
		world.setBlock(i + 2, j + 0, k + 15, DivineRPGTwilight.cryptFloor.blockID);
		world.setBlock(i + 2, j + 0, k + 16, DivineRPGTwilight.dreamdirt.blockID);
		world.setBlock(i + 2, j + 0, k + 17, DivineRPGTwilight.dreamdirt.blockID);
		world.setBlock(i + 2, j + 0, k + 18, DivineRPGTwilight.dreamdirt.blockID);
		world.setBlock(i + 2, j + 0, k + 19, DivineRPGTwilight.dreamdirt.blockID);
		world.setBlock(i + 2, j + 1, k + 0, DivineRPGTwilight.dreamdirt.blockID);
		world.setBlock(i + 2, j + 1, k + 1, DivineRPGTwilight.cryptWall.blockID);
		world.setBlock(i + 2, j + 1, k + 2, DivineRPGTwilight.cryptWall.blockID);
		world.setBlock(i + 2, j + 1, k + 3, DivineRPGTwilight.cryptWall.blockID);
		world.setBlock(i + 2, j + 1, k + 4, DivineRPGTwilight.cryptWall.blockID);
		world.setBlock(i + 2, j + 1, k + 5, DivineRPGTwilight.cryptWall.blockID);
		world.setBlock(i + 2, j + 1, k + 6, DivineRPGTwilight.cryptWall.blockID);
		world.setBlock(i + 2, j + 1, k + 7, DivineRPGTwilight.cryptWall.blockID);
		world.setBlock(i + 2, j + 1, k + 8, DivineRPGTwilight.cryptWall.blockID);
		world.setBlock(i + 2, j + 1, k + 9, DivineRPGTwilight.cryptWall.blockID);
		world.setBlock(i + 2, j + 1, k + 10, 0);
		world.setBlock(i + 2, j + 1, k + 11, 0);
		world.setBlock(i + 2, j + 1, k + 12, 0);
		world.setBlock(i + 2, j + 1, k + 13, 0);
		world.setBlock(i + 2, j + 1, k + 14, 0);
		world.setBlock(i + 2, j + 1, k + 15, DivineRPGTwilight.biphronSpawner.blockID);
		world.setBlock(i + 2, j + 1, k + 16, DivineRPGTwilight.cryptWall.blockID);
		world.setBlock(i + 2, j + 1, k + 17, DivineRPGTwilight.dreamdirt.blockID);
		world.setBlock(i + 2, j + 1, k + 18, DivineRPGTwilight.dreamdirt.blockID);
		world.setBlock(i + 2, j + 1, k + 19, DivineRPGTwilight.dreamdirt.blockID);
		world.setBlock(i + 2, j + 2, k + 0, DivineRPGTwilight.dreamdirt.blockID);
		world.setBlock(i + 2, j + 2, k + 1, DivineRPGTwilight.cryptWall.blockID);
		world.setBlock(i + 2, j + 2, k + 2, DivineRPGTwilight.cryptWall.blockID);
		world.setBlock(i + 2, j + 2, k + 3, DivineRPGTwilight.cryptWall.blockID);
		world.setBlock(i + 2, j + 2, k + 4, DivineRPGTwilight.cryptWall.blockID);
		world.setBlock(i + 2, j + 2, k + 5, DivineRPGTwilight.cryptWall.blockID);
		world.setBlock(i + 2, j + 2, k + 6, DivineRPGTwilight.cryptWall.blockID);
		world.setBlock(i + 2, j + 2, k + 7, DivineRPGTwilight.cryptWall.blockID);
		world.setBlock(i + 2, j + 2, k + 8, DivineRPGTwilight.cryptWall.blockID);
		world.setBlock(i + 2, j + 2, k + 9, DivineRPGTwilight.cryptWall.blockID);
		world.setBlock(i + 2, j + 2, k + 10, 0);
		world.setBlock(i + 2, j + 2, k + 11, 0);
		world.setBlock(i + 2, j + 2, k + 12, 0);
		world.setBlock(i + 2, j + 2, k + 13, 0);
		world.setBlock(i + 2, j + 2, k + 14, 0);
		world.setBlock(i + 2, j + 2, k + 15, 0);
		world.setBlock(i + 2, j + 2, k + 16, DivineRPGTwilight.cryptWall.blockID);
		world.setBlock(i + 2, j + 2, k + 17, DivineRPGTwilight.dreamdirt.blockID);
		world.setBlock(i + 2, j + 2, k + 18, DivineRPGTwilight.dreamdirt.blockID);
		world.setBlock(i + 2, j + 2, k + 19, DivineRPGTwilight.dreamdirt.blockID);
		world.setBlock(i + 2, j + 3, k + 0, DivineRPGTwilight.dreamdirt.blockID);
		world.setBlock(i + 2, j + 3, k + 1, DivineRPGTwilight.dreamdirt.blockID);
		world.setBlock(i + 2, j + 3, k + 2, DivineRPGTwilight.dreamdirt.blockID);
		world.setBlock(i + 2, j + 3, k + 3, DivineRPGTwilight.dreamdirt.blockID);
		world.setBlock(i + 2, j + 3, k + 4, DivineRPGTwilight.dreamdirt.blockID);
		world.setBlock(i + 2, j + 3, k + 5, DivineRPGTwilight.dreamdirt.blockID);
		world.setBlock(i + 2, j + 3, k + 6, DivineRPGTwilight.dreamdirt.blockID);
		world.setBlock(i + 2, j + 3, k + 7, DivineRPGTwilight.dreamdirt.blockID);
		world.setBlock(i + 2, j + 3, k + 8, DivineRPGTwilight.dreamdirt.blockID);
		world.setBlock(i + 2, j + 3, k + 9, DivineRPGTwilight.cryptWall.blockID);
		world.setBlock(i + 2, j + 3, k + 10, 0);
		world.setBlock(i + 2, j + 3, k + 11, 0);
		world.setBlock(i + 2, j + 3, k + 12, 0);
		world.setBlock(i + 2, j + 3, k + 13, 0);
		world.setBlock(i + 2, j + 3, k + 14, 0);
		world.setBlock(i + 2, j + 3, k + 15, 0);
		world.setBlock(i + 2, j + 3, k + 16, DivineRPGTwilight.cryptWall.blockID);
		world.setBlock(i + 2, j + 3, k + 17, DivineRPGTwilight.dreamdirt.blockID);
		world.setBlock(i + 2, j + 3, k + 18, DivineRPGTwilight.dreamdirt.blockID);
		world.setBlock(i + 2, j + 3, k + 19, DivineRPGTwilight.dreamdirt.blockID);
		world.setBlock(i + 2, j + 4, k + 0, DivineRPGTwilight.dreamdirt.blockID);
		world.setBlock(i + 2, j + 4, k + 1, DivineRPGTwilight.dreamdirt.blockID);
		world.setBlock(i + 2, j + 4, k + 2, DivineRPGTwilight.dreamdirt.blockID);
		world.setBlock(i + 2, j + 4, k + 3, DivineRPGTwilight.dreamdirt.blockID);
		world.setBlock(i + 2, j + 4, k + 4, DivineRPGTwilight.dreamdirt.blockID);
		world.setBlock(i + 2, j + 4, k + 5, DivineRPGTwilight.dreamdirt.blockID);
		world.setBlock(i + 2, j + 4, k + 6, DivineRPGTwilight.dreamdirt.blockID);
		world.setBlock(i + 2, j + 4, k + 7, DivineRPGTwilight.dreamdirt.blockID);
		world.setBlock(i + 2, j + 4, k + 8, DivineRPGTwilight.dreamdirt.blockID);
		world.setBlock(i + 2, j + 4, k + 9, DivineRPGTwilight.dreamdirt.blockID);
		world.setBlock(i + 2, j + 4, k + 10, DivineRPGTwilight.hungerstone2.blockID);
		world.setBlock(i + 2, j + 4, k + 11, DivineRPGTwilight.hungerstone2.blockID);
		world.setBlock(i + 2, j + 4, k + 12, DivineRPGTwilight.hungerstone2.blockID);
		world.setBlock(i + 2, j + 4, k + 13, DivineRPGTwilight.hungerstone2.blockID);
		world.setBlock(i + 2, j + 4, k + 14, DivineRPGTwilight.hungerstone2.blockID);
		world.setBlock(i + 2, j + 4, k + 15, DivineRPGTwilight.hungerstone2.blockID);
		world.setBlock(i + 2, j + 4, k + 16, DivineRPGTwilight.dreamdirt.blockID);
		world.setBlock(i + 2, j + 4, k + 17, DivineRPGTwilight.dreamdirt.blockID);
		world.setBlock(i + 2, j + 4, k + 18, DivineRPGTwilight.dreamdirt.blockID);
		world.setBlock(i + 2, j + 4, k + 19, DivineRPGTwilight.dreamdirt.blockID);
		world.setBlock(i + 2, j + 5, k + 0, DivineRPGTwilight.dreamdirt.blockID);
		world.setBlock(i + 2, j + 5, k + 1, DivineRPGTwilight.dreamdirt.blockID);
		world.setBlock(i + 2, j + 5, k + 2, DivineRPGTwilight.dreamdirt.blockID);
		world.setBlock(i + 2, j + 5, k + 3, DivineRPGTwilight.cryptWall.blockID);
		world.setBlock(i + 2, j + 5, k + 4, DivineRPGTwilight.cryptWall.blockID);
		world.setBlock(i + 2, j + 5, k + 5, DivineRPGTwilight.dreamdirt.blockID);
		world.setBlock(i + 2, j + 5, k + 6, DivineRPGTwilight.dreamdirt.blockID);
		world.setBlock(i + 2, j + 5, k + 7, DivineRPGTwilight.dreamdirt.blockID);
		world.setBlock(i + 2, j + 5, k + 8, DivineRPGTwilight.dreamdirt.blockID);
		world.setBlock(i + 2, j + 5, k + 9, DivineRPGTwilight.dreamdirt.blockID);
		world.setBlock(i + 2, j + 5, k + 10, DivineRPGTwilight.dreamdirt.blockID);
		world.setBlock(i + 2, j + 5, k + 11, DivineRPGTwilight.dreamdirt.blockID);
		world.setBlock(i + 2, j + 5, k + 12, DivineRPGTwilight.dreamdirt.blockID);
		world.setBlock(i + 2, j + 5, k + 13, DivineRPGTwilight.dreamdirt.blockID);
		world.setBlock(i + 2, j + 5, k + 14, DivineRPGTwilight.cryptWall.blockID);
		world.setBlock(i + 2, j + 5, k + 15, DivineRPGTwilight.cryptWall.blockID);
		world.setBlock(i + 2, j + 5, k + 16, DivineRPGTwilight.dreamdirt.blockID);
		world.setBlock(i + 2, j + 5, k + 17, DivineRPGTwilight.dreamdirt.blockID);
		world.setBlock(i + 2, j + 5, k + 18, DivineRPGTwilight.dreamdirt.blockID);
		world.setBlock(i + 2, j + 5, k + 19, DivineRPGTwilight.dreamdirt.blockID);
		world.setBlock(i + 2, j + 6, k + 0, DivineRPGTwilight.metalCaging.blockID);
		world.setBlock(i + 2, j + 6, k + 1, 0);
		world.setBlock(i + 2, j + 6, k + 2, 0);
		world.setBlock(i + 2, j + 6, k + 3, 0);
		world.setBlock(i + 2, j + 6, k + 4, 0);
		world.setBlock(i + 2, j + 6, k + 5, 0);
		world.setBlock(i + 2, j + 6, k + 6, 0);
		world.setBlock(i + 2, j + 6, k + 7, 0);
		world.setBlock(i + 2, j + 6, k + 8, 0);
		world.setBlock(i + 2, j + 6, k + 9, 0);
		world.setBlock(i + 2, j + 6, k + 10, 0);
		world.setBlock(i + 2, j + 6, k + 11, 0);
		world.setBlock(i + 2, j + 6, k + 12, 0);
		world.setBlock(i + 2, j + 6, k + 13, 0);
		world.setBlock(i + 2, j + 6, k + 14, 0);
		world.setBlock(i + 2, j + 6, k + 15, 0);
		world.setBlock(i + 2, j + 6, k + 16, 0);
		world.setBlock(i + 2, j + 6, k + 17, 0);
		world.setBlock(i + 2, j + 6, k + 18, 0);
		world.setBlock(i + 2, j + 6, k + 19, DivineRPGTwilight.metalCaging.blockID);
		world.setBlock(i + 2, j + 7, k + 0, DivineRPGTwilight.hungerstone1.blockID);
		world.setBlock(i + 2, j + 7, k + 1, 0);
		world.setBlock(i + 2, j + 7, k + 2, 0);
		world.setBlock(i + 2, j + 7, k + 3, 0);
		world.setBlock(i + 2, j + 7, k + 4, 0);
		world.setBlock(i + 2, j + 7, k + 5, 0);
		world.setBlock(i + 2, j + 7, k + 6, 0);
		world.setBlock(i + 2, j + 7, k + 7, 0);
		world.setBlock(i + 2, j + 7, k + 8, 0);
		world.setBlock(i + 2, j + 7, k + 9, 0);
		world.setBlock(i + 2, j + 7, k + 10, 0);
		world.setBlock(i + 2, j + 7, k + 11, 0);
		world.setBlock(i + 2, j + 7, k + 12, 0);
		world.setBlock(i + 2, j + 7, k + 13, 0);
		world.setBlock(i + 2, j + 7, k + 14, 0);
		world.setBlock(i + 2, j + 7, k + 15, 0);
		world.setBlock(i + 2, j + 7, k + 16, 0);
		world.setBlock(i + 2, j + 7, k + 17, 0);
		world.setBlock(i + 2, j + 7, k + 18, 0);
		world.setBlock(i + 2, j + 7, k + 19, DivineRPGTwilight.hungerstone1.blockID);
		world.setBlock(i + 2, j + 8, k + 0, 0);
		world.setBlock(i + 2, j + 8, k + 1, 0);
		world.setBlock(i + 2, j + 8, k + 2, 0);
		world.setBlock(i + 2, j + 8, k + 3, 0);
		world.setBlock(i + 2, j + 8, k + 4, 0);
		world.setBlock(i + 2, j + 8, k + 5, 0);
		world.setBlock(i + 2, j + 8, k + 6, 0);
		world.setBlock(i + 2, j + 8, k + 7, 0);
		world.setBlock(i + 2, j + 8, k + 8, 0);
		world.setBlock(i + 2, j + 8, k + 9, 0);
		world.setBlock(i + 2, j + 8, k + 10, 0);
		world.setBlock(i + 2, j + 8, k + 11, 0);
		world.setBlock(i + 2, j + 8, k + 12, 0);
		world.setBlock(i + 2, j + 8, k + 13, 0);
		world.setBlock(i + 2, j + 8, k + 14, 0);
		world.setBlock(i + 2, j + 8, k + 15, 0);
		world.setBlock(i + 2, j + 8, k + 16, 0);
		world.setBlock(i + 2, j + 8, k + 17, 0);
		world.setBlock(i + 2, j + 8, k + 18, 0);
		world.setBlock(i + 2, j + 8, k + 19, 0);
		world.setBlock(i + 2, j + 9, k + 0, 0);
		world.setBlock(i + 2, j + 9, k + 1, 0);
		world.setBlock(i + 2, j + 9, k + 2, 0);
		world.setBlock(i + 2, j + 9, k + 3, 0);
		world.setBlock(i + 2, j + 9, k + 4, 0);
		world.setBlock(i + 2, j + 9, k + 5, 0);
		world.setBlock(i + 2, j + 9, k + 6, 0);
		world.setBlock(i + 2, j + 9, k + 7, 0);
		world.setBlock(i + 2, j + 9, k + 8, 0);
		world.setBlock(i + 2, j + 9, k + 9, 0);
		world.setBlock(i + 2, j + 9, k + 10, 0);
		world.setBlock(i + 2, j + 9, k + 11, 0);
		world.setBlock(i + 2, j + 9, k + 12, 0);
		world.setBlock(i + 2, j + 9, k + 13, 0);
		world.setBlock(i + 2, j + 9, k + 14, 0);
		world.setBlock(i + 2, j + 9, k + 15, 0);
		world.setBlock(i + 2, j + 9, k + 16, 0);
		world.setBlock(i + 2, j + 9, k + 17, 0);
		world.setBlock(i + 2, j + 9, k + 18, 0);
		world.setBlock(i + 2, j + 9, k + 19, 0);
		world.setBlock(i + 2, j + 10, k + 0, 0);
		world.setBlock(i + 2, j + 10, k + 1, 0);
		world.setBlock(i + 2, j + 10, k + 2, 0);
		world.setBlock(i + 2, j + 10, k + 3, 0);
		world.setBlock(i + 2, j + 10, k + 4, 0);
		world.setBlock(i + 2, j + 10, k + 5, 0);
		world.setBlock(i + 2, j + 10, k + 6, 0);
		world.setBlock(i + 2, j + 10, k + 7, 0);
		world.setBlock(i + 2, j + 10, k + 8, 0);
		world.setBlock(i + 2, j + 10, k + 9, 0);
		world.setBlock(i + 2, j + 10, k + 10, 0);
		world.setBlock(i + 2, j + 10, k + 11, 0);
		world.setBlock(i + 2, j + 10, k + 12, 0);
		world.setBlock(i + 2, j + 10, k + 13, 0);
		world.setBlock(i + 2, j + 10, k + 14, 0);
		world.setBlock(i + 2, j + 10, k + 15, 0);
		world.setBlock(i + 2, j + 10, k + 16, 0);
		world.setBlock(i + 2, j + 10, k + 17, 0);
		world.setBlock(i + 2, j + 10, k + 18, 0);
		world.setBlock(i + 2, j + 10, k + 19, 0);
		world.setBlock(i + 3, j + 0, k + 0, DivineRPGTwilight.cryptWall.blockID);
		world.setBlock(i + 3, j + 0, k + 1, 0);
		world.setBlock(i + 3, j + 0, k + 2, 0);
		world.setBlock(i + 3, j + 0, k + 3, 0);
		world.setBlock(i + 3, j + 0, k + 4, 0);
		world.setBlock(i + 3, j + 0, k + 5, 0);
		world.setBlock(i + 3, j + 0, k + 6, 0);
		world.setBlock(i + 3, j + 0, k + 7, 0);
		world.setBlock(i + 3, j + 0, k + 8, 0);
		world.setBlock(i + 3, j + 0, k + 9, 0);
		world.setBlock(i + 3, j + 0, k + 10, 0);
		world.setBlock(i + 3, j + 0, k + 11, 0);
		world.setBlock(i + 3, j + 0, k + 12, 0);
		world.setBlock(i + 3, j + 0, k + 13, DivineRPGTwilight.cryptFloor.blockID);
		world.setBlock(i + 3, j + 0, k + 14, DivineRPGTwilight.cryptFloor.blockID);
		world.setBlock(i + 3, j + 0, k + 15, DivineRPGTwilight.cryptFloor.blockID);
		world.setBlock(i + 3, j + 0, k + 16, DivineRPGTwilight.dreamdirt.blockID);
		world.setBlock(i + 3, j + 0, k + 17, DivineRPGTwilight.dreamdirt.blockID);
		world.setBlock(i + 3, j + 0, k + 18, DivineRPGTwilight.dreamdirt.blockID);
		world.setBlock(i + 3, j + 0, k + 19, DivineRPGTwilight.dreamdirt.blockID);
		world.setBlock(i + 3, j + 1, k + 0, DivineRPGTwilight.cryptWall.blockID);
		world.setBlock(i + 3, j + 1, k + 1, 0);
		world.setBlock(i + 3, j + 1, k + 2, 0);
		world.setBlock(i + 3, j + 1, k + 3, 0);
		world.setBlock(i + 3, j + 1, k + 4, 0);
		world.setBlock(i + 3, j + 1, k + 5, 0);
		world.setBlock(i + 3, j + 1, k + 6, 0);
		world.setBlock(i + 3, j + 1, k + 7, 0);
		world.setBlock(i + 3, j + 1, k + 8, 0);
		world.setBlock(i + 3, j + 1, k + 9, 0);
		world.setBlock(i + 3, j + 1, k + 10, 0);
		world.setBlock(i + 3, j + 1, k + 11, 0);
		world.setBlock(i + 3, j + 1, k + 12, 0);
		world.setBlock(i + 3, j + 1, k + 13, 0);
		world.setBlock(i + 3, j + 1, k + 14, 0);
		world.setBlock(i + 3, j + 1, k + 15, 0);
		world.setBlock(i + 3, j + 1, k + 16, DivineRPGTwilight.cryptWall.blockID);
		world.setBlock(i + 3, j + 1, k + 17, DivineRPGTwilight.dreamdirt.blockID);
		world.setBlock(i + 3, j + 1, k + 18, DivineRPGTwilight.dreamdirt.blockID);
		world.setBlock(i + 3, j + 1, k + 19, DivineRPGTwilight.dreamdirt.blockID);
		world.setBlock(i + 3, j + 2, k + 0, DivineRPGTwilight.cryptWall.blockID);
		world.setBlock(i + 3, j + 2, k + 1, 0);
		world.setBlock(i + 3, j + 2, k + 2, 0);
		world.setBlock(i + 3, j + 2, k + 3, 0);
		world.setBlock(i + 3, j + 2, k + 4, 0);
		world.setBlock(i + 3, j + 2, k + 5, 0);
		world.setBlock(i + 3, j + 2, k + 6, 0);
		world.setBlock(i + 3, j + 2, k + 7, 0);
		world.setBlock(i + 3, j + 2, k + 8, 0);
		world.setBlock(i + 3, j + 2, k + 9, 0);
		world.setBlock(i + 3, j + 2, k + 10, 0);
		world.setBlock(i + 3, j + 2, k + 11, 0);
		world.setBlock(i + 3, j + 2, k + 12, 0);
		world.setBlock(i + 3, j + 2, k + 13, 0);
		world.setBlock(i + 3, j + 2, k + 14, 0);
		world.setBlock(i + 3, j + 2, k + 15, 0);
		world.setBlock(i + 3, j + 2, k + 16, DivineRPGTwilight.cryptWall.blockID);
		world.setBlock(i + 3, j + 2, k + 17, DivineRPGTwilight.dreamdirt.blockID);
		world.setBlock(i + 3, j + 2, k + 18, DivineRPGTwilight.dreamdirt.blockID);
		world.setBlock(i + 3, j + 2, k + 19, DivineRPGTwilight.dreamdirt.blockID);
		world.setBlock(i + 3, j + 3, k + 0, DivineRPGTwilight.dreamdirt.blockID);
		world.setBlock(i + 3, j + 3, k + 1, DivineRPGTwilight.hungerstone2.blockID);
		world.setBlock(i + 3, j + 3, k + 2, DivineRPGTwilight.hungerstone2.blockID);
		world.setBlock(i + 3, j + 3, k + 3, DivineRPGTwilight.hungerstone2.blockID);
		world.setBlock(i + 3, j + 3, k + 4, DivineRPGTwilight.hungerstone2.blockID);
		world.setBlock(i + 3, j + 3, k + 5, DivineRPGTwilight.hungerstone2.blockID);
		world.setBlock(i + 3, j + 3, k + 6, DivineRPGTwilight.hungerstone2.blockID);
		world.setBlock(i + 3, j + 3, k + 7, DivineRPGTwilight.hungerstone2.blockID);
		world.setBlock(i + 3, j + 3, k + 8, DivineRPGTwilight.hungerstone2.blockID);
		world.setBlock(i + 3, j + 3, k + 9, DivineRPGTwilight.cryptWall.blockID);
		world.setBlock(i + 3, j + 3, k + 10, 0);
		world.setBlock(i + 3, j + 3, k + 11, 0);
		world.setBlock(i + 3, j + 3, k + 12, 0);
		world.setBlock(i + 3, j + 3, k + 13, 0);
		world.setBlock(i + 3, j + 3, k + 14, 0);
		world.setBlock(i + 3, j + 3, k + 15, 0);
		world.setBlock(i + 3, j + 3, k + 16, DivineRPGTwilight.cryptWall.blockID);
		world.setBlock(i + 3, j + 3, k + 17, DivineRPGTwilight.dreamdirt.blockID);
		world.setBlock(i + 3, j + 3, k + 18, DivineRPGTwilight.dreamdirt.blockID);
		world.setBlock(i + 3, j + 3, k + 19, DivineRPGTwilight.dreamdirt.blockID);
		world.setBlock(i + 3, j + 4, k + 0, DivineRPGTwilight.dreamdirt.blockID);
		world.setBlock(i + 3, j + 4, k + 1, DivineRPGTwilight.dreamdirt.blockID);
		world.setBlock(i + 3, j + 4, k + 2, DivineRPGTwilight.dreamdirt.blockID);
		world.setBlock(i + 3, j + 4, k + 3, DivineRPGTwilight.dreamdirt.blockID);
		world.setBlock(i + 3, j + 4, k + 4, DivineRPGTwilight.dreamdirt.blockID);
		world.setBlock(i + 3, j + 4, k + 5, DivineRPGTwilight.dreamdirt.blockID);
		world.setBlock(i + 3, j + 4, k + 6, DivineRPGTwilight.dreamdirt.blockID);
		world.setBlock(i + 3, j + 4, k + 7, 0);
		world.setBlock(i + 3, j + 4, k + 8, DivineRPGTwilight.dreamdirt.blockID);
		world.setBlock(i + 3, j + 4, k + 9, DivineRPGTwilight.dreamdirt.blockID);
		world.setBlock(i + 3, j + 4, k + 10, DivineRPGTwilight.hungerstone2.blockID);
		world.setBlock(i + 3, j + 4, k + 11, DivineRPGTwilight.hungerstone2.blockID);
		world.setBlock(i + 3, j + 4, k + 12, DivineRPGTwilight.hungerstone2.blockID);
		world.setBlock(i + 3, j + 4, k + 13, DivineRPGTwilight.hungerstone2.blockID);
		world.setBlock(i + 3, j + 4, k + 14, DivineRPGTwilight.hungerstone2.blockID);
		world.setBlock(i + 3, j + 4, k + 15, DivineRPGTwilight.hungerstone2.blockID);
		world.setBlock(i + 3, j + 4, k + 16, DivineRPGTwilight.dreamdirt.blockID);
		world.setBlock(i + 3, j + 4, k + 17, DivineRPGTwilight.dreamdirt.blockID);
		world.setBlock(i + 3, j + 4, k + 18, DivineRPGTwilight.dreamdirt.blockID);
		world.setBlock(i + 3, j + 4, k + 19, DivineRPGTwilight.dreamdirt.blockID);
		world.setBlock(i + 3, j + 5, k + 0, DivineRPGTwilight.dreamdirt.blockID);
		world.setBlock(i + 3, j + 5, k + 1, DivineRPGTwilight.dreamdirt.blockID);
		world.setBlock(i + 3, j + 5, k + 2, DivineRPGTwilight.dreamdirt.blockID);
		world.setBlock(i + 3, j + 5, k + 3, DivineRPGTwilight.cryptWall.blockID);
		world.setBlock(i + 3, j + 5, k + 4, DivineRPGTwilight.cryptWall.blockID);
		world.setBlock(i + 3, j + 5, k + 5, DivineRPGTwilight.dreamdirt.blockID);
		world.setBlock(i + 3, j + 5, k + 6, DivineRPGTwilight.dreamdirt.blockID);
		world.setBlock(i + 3, j + 5, k + 7, DivineRPGTwilight.dreamdirt.blockID);
		world.setBlock(i + 3, j + 5, k + 8, DivineRPGTwilight.dreamdirt.blockID);
		world.setBlock(i + 3, j + 5, k + 9, DivineRPGTwilight.dreamdirt.blockID);
		world.setBlock(i + 3, j + 5, k + 10, DivineRPGTwilight.dreamdirt.blockID);
		world.setBlock(i + 3, j + 5, k + 11, DivineRPGTwilight.dreamdirt.blockID);
		world.setBlock(i + 3, j + 5, k + 12, DivineRPGTwilight.dreamdirt.blockID);
		world.setBlock(i + 3, j + 5, k + 13, DivineRPGTwilight.dreamdirt.blockID);
		world.setBlock(i + 3, j + 5, k + 14, DivineRPGTwilight.cryptWall.blockID);
		world.setBlock(i + 3, j + 5, k + 15, DivineRPGTwilight.cryptWall.blockID);
		world.setBlock(i + 3, j + 5, k + 16, DivineRPGTwilight.dreamdirt.blockID);
		world.setBlock(i + 3, j + 5, k + 17, DivineRPGTwilight.dreamdirt.blockID);
		world.setBlock(i + 3, j + 5, k + 18, DivineRPGTwilight.dreamdirt.blockID);
		world.setBlock(i + 3, j + 5, k + 19, DivineRPGTwilight.dreamdirt.blockID);
		world.setBlock(i + 3, j + 6, k + 0, DivineRPGTwilight.metalCaging.blockID);
		world.setBlock(i + 3, j + 6, k + 1, 0);
		world.setBlock(i + 3, j + 6, k + 2, 0);
		world.setBlock(i + 3, j + 6, k + 3, 0);
		world.setBlock(i + 3, j + 6, k + 4, 0);
		world.setBlock(i + 3, j + 6, k + 5, 0);
		world.setBlock(i + 3, j + 6, k + 6, 0);
		world.setBlock(i + 3, j + 6, k + 7, 0);
		world.setBlock(i + 3, j + 6, k + 8, 0);
		world.setBlock(i + 3, j + 6, k + 9, 0);
		world.setBlock(i + 3, j + 6, k + 10, 0);
		world.setBlock(i + 3, j + 6, k + 11, DivineRPGTwilight.hungerstone1.blockID);
		world.setBlock(i + 3, j + 6, k + 12, DivineRPGTwilight.hungerstone1.blockID);
		world.setBlock(i + 3, j + 6, k + 13, DivineRPGTwilight.hungerstone1.blockID);
		world.setBlock(i + 3, j + 6, k + 14, 0);
		world.setBlock(i + 3, j + 6, k + 15, 0);
		world.setBlock(i + 3, j + 6, k + 16, 0);
		world.setBlock(i + 3, j + 6, k + 17, 0);
		world.setBlock(i + 3, j + 6, k + 18, 0);
		world.setBlock(i + 3, j + 6, k + 19, DivineRPGTwilight.metalCaging.blockID);
		world.setBlock(i + 3, j + 7, k + 0, DivineRPGTwilight.hungerstone1.blockID);
		world.setBlock(i + 3, j + 7, k + 1, 0);
		world.setBlock(i + 3, j + 7, k + 2, 0);
		world.setBlock(i + 3, j + 7, k + 3, 0);
		world.setBlock(i + 3, j + 7, k + 4, 0);
		world.setBlock(i + 3, j + 7, k + 5, 0);
		world.setBlock(i + 3, j + 7, k + 6, 0);
		world.setBlock(i + 3, j + 7, k + 7, 0);
		world.setBlock(i + 3, j + 7, k + 8, 0);
		world.setBlock(i + 3, j + 7, k + 9, 0);
		world.setBlock(i + 3, j + 7, k + 10, 0);
		world.setBlock(i + 3, j + 7, k + 11, 0);
		world.setBlock(i + 3, j + 7, k + 12, 0);
		world.setBlock(i + 3, j + 7, k + 13, 0);
		world.setBlock(i + 3, j + 7, k + 14, 0);
		world.setBlock(i + 3, j + 7, k + 15, 0);
		world.setBlock(i + 3, j + 7, k + 16, 0);
		world.setBlock(i + 3, j + 7, k + 17, 0);
		world.setBlock(i + 3, j + 7, k + 18, 0);
		world.setBlock(i + 3, j + 7, k + 19, DivineRPGTwilight.hungerstone1.blockID);
		world.setBlock(i + 3, j + 8, k + 0, 0);
		world.setBlock(i + 3, j + 8, k + 1, 0);
		world.setBlock(i + 3, j + 8, k + 2, 0);
		world.setBlock(i + 3, j + 8, k + 3, 0);
		world.setBlock(i + 3, j + 8, k + 4, 0);
		world.setBlock(i + 3, j + 8, k + 5, 0);
		world.setBlock(i + 3, j + 8, k + 6, 0);
		world.setBlock(i + 3, j + 8, k + 7, 0);
		world.setBlock(i + 3, j + 8, k + 8, 0);
		world.setBlock(i + 3, j + 8, k + 9, 0);
		world.setBlock(i + 3, j + 8, k + 10, 0);
		world.setBlock(i + 3, j + 8, k + 11, 0);
		world.setBlock(i + 3, j + 8, k + 12, 0);
		world.setBlock(i + 3, j + 8, k + 13, 0);
		world.setBlock(i + 3, j + 8, k + 14, 0);
		world.setBlock(i + 3, j + 8, k + 15, 0);
		world.setBlock(i + 3, j + 8, k + 16, 0);
		world.setBlock(i + 3, j + 8, k + 17, 0);
		world.setBlock(i + 3, j + 8, k + 18, 0);
		world.setBlock(i + 3, j + 8, k + 19, 0);
		world.setBlock(i + 3, j + 9, k + 0, 0);
		world.setBlock(i + 3, j + 9, k + 1, 0);
		world.setBlock(i + 3, j + 9, k + 2, 0);
		world.setBlock(i + 3, j + 9, k + 3, 0);
		world.setBlock(i + 3, j + 9, k + 4, 0);
		world.setBlock(i + 3, j + 9, k + 5, 0);
		world.setBlock(i + 3, j + 9, k + 6, 0);
		world.setBlock(i + 3, j + 9, k + 7, 0);
		world.setBlock(i + 3, j + 9, k + 8, 0);
		world.setBlock(i + 3, j + 9, k + 9, 0);
		world.setBlock(i + 3, j + 9, k + 10, 0);
		world.setBlock(i + 3, j + 9, k + 11, 0);
		world.setBlock(i + 3, j + 9, k + 12, 0);
		world.setBlock(i + 3, j + 9, k + 13, 0);
		world.setBlock(i + 3, j + 9, k + 14, 0);
		world.setBlock(i + 3, j + 9, k + 15, 0);
		world.setBlock(i + 3, j + 9, k + 16, 0);
		world.setBlock(i + 3, j + 9, k + 17, 0);
		world.setBlock(i + 3, j + 9, k + 18, 0);
		world.setBlock(i + 3, j + 9, k + 19, 0);
		world.setBlock(i + 3, j + 10, k + 0, 0);
		world.setBlock(i + 3, j + 10, k + 1, 0);
		world.setBlock(i + 3, j + 10, k + 2, 0);
		world.setBlock(i + 3, j + 10, k + 3, 0);
		world.setBlock(i + 3, j + 10, k + 4, 0);
		world.setBlock(i + 3, j + 10, k + 5, 0);
		world.setBlock(i + 3, j + 10, k + 6, 0);
		world.setBlock(i + 3, j + 10, k + 7, 0);
		world.setBlock(i + 3, j + 10, k + 8, 0);
		world.setBlock(i + 3, j + 10, k + 9, 0);
		world.setBlock(i + 3, j + 10, k + 10, 0);
		world.setBlock(i + 3, j + 10, k + 11, 0);
		world.setBlock(i + 3, j + 10, k + 12, 0);
		world.setBlock(i + 3, j + 10, k + 13, 0);
		world.setBlock(i + 3, j + 10, k + 14, 0);
		world.setBlock(i + 3, j + 10, k + 15, 0);
		world.setBlock(i + 3, j + 10, k + 16, 0);
		world.setBlock(i + 3, j + 10, k + 17, 0);
		world.setBlock(i + 3, j + 10, k + 18, 0);
		world.setBlock(i + 3, j + 10, k + 19, 0);
		world.setBlock(i + 4, j + 0, k + 0, DivineRPGTwilight.cryptWall.blockID);
		world.setBlock(i + 4, j + 0, k + 1, 0);
		world.setBlock(i + 4, j + 0, k + 2, DivineRPGTwilight.cryptWall.blockID);
		world.setBlock(i + 4, j + 0, k + 3, DivineRPGTwilight.cryptWall.blockID);
		world.setBlock(i + 4, j + 0, k + 4, DivineRPGTwilight.cryptWall.blockID);
		world.setBlock(i + 4, j + 0, k + 5, DivineRPGTwilight.cryptWall.blockID);
		world.setBlock(i + 4, j + 0, k + 6, DivineRPGTwilight.cryptWall.blockID);
		world.setBlock(i + 4, j + 0, k + 7, DivineRPGTwilight.cryptWall.blockID);
		world.setBlock(i + 4, j + 0, k + 8, DivineRPGTwilight.cryptWall.blockID);
		world.setBlock(i + 4, j + 0, k + 9, DivineRPGTwilight.cryptWall.blockID);
		world.setBlock(i + 4, j + 0, k + 10, 0);
		world.setBlock(i + 4, j + 0, k + 11, 0);
		world.setBlock(i + 4, j + 0, k + 12, 0);
		world.setBlock(i + 4, j + 0, k + 13, DivineRPGTwilight.cryptFloor.blockID);
		world.setBlock(i + 4, j + 0, k + 14, DivineRPGTwilight.cryptFloor.blockID);
		world.setBlock(i + 4, j + 0, k + 15, DivineRPGTwilight.cryptFloor.blockID);
		world.setBlock(i + 4, j + 0, k + 16, DivineRPGTwilight.dreamdirt.blockID);
		world.setBlock(i + 4, j + 0, k + 17, DivineRPGTwilight.dreamdirt.blockID);
		world.setBlock(i + 4, j + 0, k + 18, DivineRPGTwilight.dreamdirt.blockID);
		world.setBlock(i + 4, j + 0, k + 19, DivineRPGTwilight.dreamdirt.blockID);
		world.setBlock(i + 4, j + 1, k + 0, DivineRPGTwilight.cryptWall.blockID);
		world.setBlock(i + 4, j + 1, k + 1, 0);
		world.setBlock(i + 4, j + 1, k + 2, DivineRPGTwilight.cryptWall.blockID);
		world.setBlock(i + 4, j + 1, k + 3, DivineRPGTwilight.cryptWall.blockID);
		world.setBlock(i + 4, j + 1, k + 4, DivineRPGTwilight.cryptWall.blockID);
		world.setBlock(i + 4, j + 1, k + 5, DivineRPGTwilight.cryptWall.blockID);
		world.setBlock(i + 4, j + 1, k + 6, DivineRPGTwilight.cryptWall.blockID);
		world.setBlock(i + 4, j + 1, k + 7, DivineRPGTwilight.cryptWall.blockID);
		world.setBlock(i + 4, j + 1, k + 8, DivineRPGTwilight.cryptWall.blockID);
		world.setBlock(i + 4, j + 1, k + 9, DivineRPGTwilight.cryptWall.blockID);
		world.setBlock(i + 4, j + 1, k + 10, 0);
		world.setBlock(i + 4, j + 1, k + 11, 0);
		world.setBlock(i + 4, j + 1, k + 12, 0);
		world.setBlock(i + 4, j + 1, k + 13, 0);
		world.setBlock(i + 4, j + 1, k + 14, 0);
		world.setBlock(i + 4, j + 1, k + 15, 0);
		world.setBlock(i + 4, j + 1, k + 16, DivineRPGTwilight.cryptWall.blockID);
		world.setBlock(i + 4, j + 1, k + 17, DivineRPGTwilight.dreamdirt.blockID);
		world.setBlock(i + 4, j + 1, k + 18, DivineRPGTwilight.dreamdirt.blockID);
		world.setBlock(i + 4, j + 1, k + 19, DivineRPGTwilight.dreamdirt.blockID);
		world.setBlock(i + 4, j + 2, k + 0, DivineRPGTwilight.cryptWall.blockID);
		world.setBlock(i + 4, j + 2, k + 1, 0);
		world.setBlock(i + 4, j + 2, k + 2, DivineRPGTwilight.cryptWall.blockID);
		world.setBlock(i + 4, j + 2, k + 3, DivineRPGTwilight.cryptWall.blockID);
		world.setBlock(i + 4, j + 2, k + 4, DivineRPGTwilight.cryptWall.blockID);
		world.setBlock(i + 4, j + 2, k + 5, DivineRPGTwilight.cryptWall.blockID);
		world.setBlock(i + 4, j + 2, k + 6, DivineRPGTwilight.cryptWall.blockID);
		world.setBlock(i + 4, j + 2, k + 7, DivineRPGTwilight.cryptWall.blockID);
		world.setBlock(i + 4, j + 2, k + 8, DivineRPGTwilight.cryptWall.blockID);
		world.setBlock(i + 4, j + 2, k + 9, DivineRPGTwilight.cryptWall.blockID);
		world.setBlock(i + 4, j + 2, k + 10, 0);
		world.setBlock(i + 4, j + 2, k + 11, 0);
		world.setBlock(i + 4, j + 2, k + 12, 0);
		world.setBlock(i + 4, j + 2, k + 13, 0);
		world.setBlock(i + 4, j + 2, k + 14, 0);
		world.setBlock(i + 4, j + 2, k + 15, 0);
		world.setBlock(i + 4, j + 2, k + 16, DivineRPGTwilight.cryptWall.blockID);
		world.setBlock(i + 4, j + 2, k + 17, DivineRPGTwilight.dreamdirt.blockID);
		world.setBlock(i + 4, j + 2, k + 18, DivineRPGTwilight.dreamdirt.blockID);
		world.setBlock(i + 4, j + 2, k + 19, DivineRPGTwilight.dreamdirt.blockID);
		world.setBlock(i + 4, j + 3, k + 0, DivineRPGTwilight.dreamdirt.blockID);
		world.setBlock(i + 4, j + 3, k + 1, DivineRPGTwilight.hungerstone2.blockID);
		world.setBlock(i + 4, j + 3, k + 2, DivineRPGTwilight.dreamdirt.blockID);
		world.setBlock(i + 4, j + 3, k + 3, DivineRPGTwilight.dreamdirt.blockID);
		world.setBlock(i + 4, j + 3, k + 4, DivineRPGTwilight.dreamdirt.blockID);
		world.setBlock(i + 4, j + 3, k + 5, DivineRPGTwilight.dreamdirt.blockID);
		world.setBlock(i + 4, j + 3, k + 6, DivineRPGTwilight.dreamdirt.blockID);
		world.setBlock(i + 4, j + 3, k + 7, DivineRPGTwilight.dreamdirt.blockID);
		world.setBlock(i + 4, j + 3, k + 8, DivineRPGTwilight.dreamdirt.blockID);
		world.setBlock(i + 4, j + 3, k + 9, DivineRPGTwilight.cryptWall.blockID);
		world.setBlock(i + 4, j + 3, k + 10, 0);
		world.setBlock(i + 4, j + 3, k + 11, 0);
		world.setBlock(i + 4, j + 3, k + 12, 0);
		world.setBlock(i + 4, j + 3, k + 13, 0);
		world.setBlock(i + 4, j + 3, k + 14, 0);
		world.setBlock(i + 4, j + 3, k + 15, 0);
		world.setBlock(i + 4, j + 3, k + 16, DivineRPGTwilight.cryptWall.blockID);
		world.setBlock(i + 4, j + 3, k + 17, DivineRPGTwilight.dreamdirt.blockID);
		world.setBlock(i + 4, j + 3, k + 18, DivineRPGTwilight.dreamdirt.blockID);
		world.setBlock(i + 4, j + 3, k + 19, DivineRPGTwilight.dreamdirt.blockID);
		world.setBlock(i + 4, j + 4, k + 0, DivineRPGTwilight.dreamdirt.blockID);
		world.setBlock(i + 4, j + 4, k + 1, DivineRPGTwilight.dreamdirt.blockID);
		world.setBlock(i + 4, j + 4, k + 2, DivineRPGTwilight.dreamdirt.blockID);
		world.setBlock(i + 4, j + 4, k + 3, DivineRPGTwilight.dreamdirt.blockID);
		world.setBlock(i + 4, j + 4, k + 4, DivineRPGTwilight.dreamdirt.blockID);
		world.setBlock(i + 4, j + 4, k + 5, DivineRPGTwilight.dreamdirt.blockID);
		world.setBlock(i + 4, j + 4, k + 6, DivineRPGTwilight.dreamdirt.blockID);
		world.setBlock(i + 4, j + 4, k + 7, DivineRPGTwilight.dreamdirt.blockID);
		world.setBlock(i + 4, j + 4, k + 8, DivineRPGTwilight.dreamdirt.blockID);
		world.setBlock(i + 4, j + 4, k + 9, DivineRPGTwilight.dreamdirt.blockID);
		world.setBlock(i + 4, j + 4, k + 10, DivineRPGTwilight.hungerstone2.blockID);
		world.setBlock(i + 4, j + 4, k + 11, DivineRPGTwilight.hungerstone2.blockID);
		world.setBlock(i + 4, j + 4, k + 12, DivineRPGTwilight.hungerstone2.blockID);
		world.setBlock(i + 4, j + 4, k + 13, DivineRPGTwilight.hungerstone2.blockID);
		world.setBlock(i + 4, j + 4, k + 14, DivineRPGTwilight.hungerstone2.blockID);
		world.setBlock(i + 4, j + 4, k + 15, DivineRPGTwilight.hungerstone2.blockID);
		world.setBlock(i + 4, j + 4, k + 16, DivineRPGTwilight.dreamdirt.blockID);
		world.setBlock(i + 4, j + 4, k + 17, DivineRPGTwilight.dreamdirt.blockID);
		world.setBlock(i + 4, j + 4, k + 18, DivineRPGTwilight.dreamdirt.blockID);
		world.setBlock(i + 4, j + 4, k + 19, DivineRPGTwilight.dreamdirt.blockID);
		world.setBlock(i + 4, j + 5, k + 0, DivineRPGTwilight.dreamdirt.blockID);
		world.setBlock(i + 4, j + 5, k + 1, DivineRPGTwilight.dreamdirt.blockID);
		world.setBlock(i + 4, j + 5, k + 2, DivineRPGTwilight.dreamdirt.blockID);
		world.setBlock(i + 4, j + 5, k + 3, DivineRPGTwilight.cryptWall.blockID);
		world.setBlock(i + 4, j + 5, k + 4, DivineRPGTwilight.cryptWall.blockID);
		world.setBlock(i + 4, j + 5, k + 5, DivineRPGTwilight.dreamdirt.blockID);
		world.setBlock(i + 4, j + 5, k + 6, DivineRPGTwilight.dreamdirt.blockID);
		world.setBlock(i + 4, j + 5, k + 7, DivineRPGTwilight.dreamdirt.blockID);
		world.setBlock(i + 4, j + 5, k + 8, DivineRPGTwilight.dreamdirt.blockID);
		world.setBlock(i + 4, j + 5, k + 9, DivineRPGTwilight.dreamdirt.blockID);
		world.setBlock(i + 4, j + 5, k + 10, DivineRPGTwilight.dreamdirt.blockID);
		world.setBlock(i + 4, j + 5, k + 11, DivineRPGTwilight.dreamdirt.blockID);
		world.setBlock(i + 4, j + 5, k + 12, DivineRPGTwilight.dreamdirt.blockID);
		world.setBlock(i + 4, j + 5, k + 13, DivineRPGTwilight.dreamdirt.blockID);
		world.setBlock(i + 4, j + 5, k + 14, DivineRPGTwilight.cryptWall.blockID);
		world.setBlock(i + 4, j + 5, k + 15, DivineRPGTwilight.cryptWall.blockID);
		world.setBlock(i + 4, j + 5, k + 16, DivineRPGTwilight.dreamdirt.blockID);
		world.setBlock(i + 4, j + 5, k + 17, DivineRPGTwilight.dreamdirt.blockID);
		world.setBlock(i + 4, j + 5, k + 18, DivineRPGTwilight.dreamdirt.blockID);
		world.setBlock(i + 4, j + 5, k + 19, DivineRPGTwilight.dreamdirt.blockID);
		world.setBlock(i + 4, j + 6, k + 0, DivineRPGTwilight.metalCaging.blockID);
		world.setBlock(i + 4, j + 6, k + 1, 0);
		world.setBlock(i + 4, j + 6, k + 2, 0);
		world.setBlock(i + 4, j + 6, k + 3, 0);
		world.setBlock(i + 4, j + 6, k + 4, 0);
		world.setBlock(i + 4, j + 6, k + 5, 0);
		world.setBlock(i + 4, j + 6, k + 6, 0);
		world.setBlock(i + 4, j + 6, k + 7, 0);
		world.setBlock(i + 4, j + 6, k + 8, 0);
		world.setBlock(i + 4, j + 6, k + 9, 0);
		world.setBlock(i + 4, j + 6, k + 10, 0);
		world.setBlock(i + 4, j + 6, k + 11, DivineRPGTwilight.hungerstone1.blockID);
		world.setBlock(i + 4, j + 6, k + 12, DivineRPGTwilight.hungerstone1.blockID);
		world.setBlock(i + 4, j + 6, k + 13, DivineRPGTwilight.hungerstone1.blockID);
		world.setBlock(i + 4, j + 6, k + 14, 0);
		world.setBlock(i + 4, j + 6, k + 15, 0);
		world.setBlock(i + 4, j + 6, k + 16, 0);
		world.setBlock(i + 4, j + 6, k + 17, 0);
		world.setBlock(i + 4, j + 6, k + 18, 0);
		world.setBlock(i + 4, j + 6, k + 19, DivineRPGTwilight.metalCaging.blockID);
		world.setBlock(i + 4, j + 7, k + 0, DivineRPGTwilight.hungerstone1.blockID);
		world.setBlock(i + 4, j + 7, k + 1, 0);
		world.setBlock(i + 4, j + 7, k + 2, 0);
		world.setBlock(i + 4, j + 7, k + 3, 0);
		world.setBlock(i + 4, j + 7, k + 4, 0);
		world.setBlock(i + 4, j + 7, k + 5, 0);
		world.setBlock(i + 4, j + 7, k + 6, 0);
		world.setBlock(i + 4, j + 7, k + 7, 0);
		world.setBlock(i + 4, j + 7, k + 8, 0);
		world.setBlock(i + 4, j + 7, k + 9, 0);
		world.setBlock(i + 4, j + 7, k + 10, 0);
		world.setBlock(i + 4, j + 7, k + 11, 0);
		world.setBlock(i + 4, j + 7, k + 12, DivineRPGTwilight.hungerstone1.blockID);
		world.setBlock(i + 4, j + 7, k + 13, 0);
		world.setBlock(i + 4, j + 7, k + 14, 0);
		world.setBlock(i + 4, j + 7, k + 15, 0);
		world.setBlock(i + 4, j + 7, k + 16, 0);
		world.setBlock(i + 4, j + 7, k + 17, 0);
		world.setBlock(i + 4, j + 7, k + 18, 0);
		world.setBlock(i + 4, j + 7, k + 19, DivineRPGTwilight.hungerstone1.blockID);
		world.setBlock(i + 4, j + 8, k + 0, 0);
		world.setBlock(i + 4, j + 8, k + 1, 0);
		world.setBlock(i + 4, j + 8, k + 2, 0);
		world.setBlock(i + 4, j + 8, k + 3, 0);
		world.setBlock(i + 4, j + 8, k + 4, 0);
		world.setBlock(i + 4, j + 8, k + 5, 0);
		world.setBlock(i + 4, j + 8, k + 6, 0);
		world.setBlock(i + 4, j + 8, k + 7, 0);
		world.setBlock(i + 4, j + 8, k + 8, 0);
		world.setBlock(i + 4, j + 8, k + 9, 0);
		world.setBlock(i + 4, j + 8, k + 10, 0);
		world.setBlock(i + 4, j + 8, k + 11, 0);
		world.setBlock(i + 4, j + 8, k + 12, DivineRPGTwilight.firecrystal.blockID);
		world.setBlock(i + 4, j + 8, k + 13, 0);
		world.setBlock(i + 4, j + 8, k + 14, 0);
		world.setBlock(i + 4, j + 8, k + 15, 0);
		world.setBlock(i + 4, j + 8, k + 16, 0);
		world.setBlock(i + 4, j + 8, k + 17, 0);
		world.setBlock(i + 4, j + 8, k + 18, 0);
		world.setBlock(i + 4, j + 8, k + 19, 0);
		world.setBlock(i + 4, j + 9, k + 0, 0);
		world.setBlock(i + 4, j + 9, k + 1, 0);
		world.setBlock(i + 4, j + 9, k + 2, 0);
		world.setBlock(i + 4, j + 9, k + 3, 0);
		world.setBlock(i + 4, j + 9, k + 4, 0);
		world.setBlock(i + 4, j + 9, k + 5, 0);
		world.setBlock(i + 4, j + 9, k + 6, 0);
		world.setBlock(i + 4, j + 9, k + 7, 0);
		world.setBlock(i + 4, j + 9, k + 8, 0);
		world.setBlock(i + 4, j + 9, k + 9, 0);
		world.setBlock(i + 4, j + 9, k + 10, 0);
		world.setBlock(i + 4, j + 9, k + 11, 0);
		world.setBlock(i + 4, j + 9, k + 12, 0);
		world.setBlock(i + 4, j + 9, k + 13, 0);
		world.setBlock(i + 4, j + 9, k + 14, 0);
		world.setBlock(i + 4, j + 9, k + 15, 0);
		world.setBlock(i + 4, j + 9, k + 16, 0);
		world.setBlock(i + 4, j + 9, k + 17, 0);
		world.setBlock(i + 4, j + 9, k + 18, 0);
		world.setBlock(i + 4, j + 9, k + 19, 0);
		world.setBlock(i + 4, j + 10, k + 0, 0);
		world.setBlock(i + 4, j + 10, k + 1, 0);
		world.setBlock(i + 4, j + 10, k + 2, 0);
		world.setBlock(i + 4, j + 10, k + 3, 0);
		world.setBlock(i + 4, j + 10, k + 4, 0);
		world.setBlock(i + 4, j + 10, k + 5, 0);
		world.setBlock(i + 4, j + 10, k + 6, 0);
		world.setBlock(i + 4, j + 10, k + 7, 0);
		world.setBlock(i + 4, j + 10, k + 8, 0);
		world.setBlock(i + 4, j + 10, k + 9, 0);
		world.setBlock(i + 4, j + 10, k + 10, 0);
		world.setBlock(i + 4, j + 10, k + 11, 0);
		world.setBlock(i + 4, j + 10, k + 12, 0);
		world.setBlock(i + 4, j + 10, k + 13, 0);
		world.setBlock(i + 4, j + 10, k + 14, 0);
		world.setBlock(i + 4, j + 10, k + 15, 0);
		world.setBlock(i + 4, j + 10, k + 16, 0);
		world.setBlock(i + 4, j + 10, k + 17, 0);
		world.setBlock(i + 4, j + 10, k + 18, 0);
		world.setBlock(i + 4, j + 10, k + 19, 0);
		world.setBlock(i + 5, j + 0, k + 0, DivineRPGTwilight.cryptWall.blockID);
		world.setBlock(i + 5, j + 0, k + 1, 0);
		world.setBlock(i + 5, j + 0, k + 2, DivineRPGTwilight.cryptWall.blockID);
		world.setBlock(i + 5, j + 0, k + 3, DivineRPGTwilight.dreamdirt.blockID);
		world.setBlock(i + 5, j + 0, k + 4, DivineRPGTwilight.dreamdirt.blockID);
		world.setBlock(i + 5, j + 0, k + 5, DivineRPGTwilight.dreamdirt.blockID);
		world.setBlock(i + 5, j + 0, k + 6, DivineRPGTwilight.dreamdirt.blockID);
		world.setBlock(i + 5, j + 0, k + 7, DivineRPGTwilight.dreamdirt.blockID);
		world.setBlock(i + 5, j + 0, k + 8, DivineRPGTwilight.dreamdirt.blockID);
		world.setBlock(i + 5, j + 0, k + 9, DivineRPGTwilight.dreamdirt.blockID);
		world.setBlock(i + 5, j + 0, k + 10, DivineRPGTwilight.cryptFloor.blockID);
		world.setBlock(i + 5, j + 0, k + 11, DivineRPGTwilight.cryptFloor.blockID);
		world.setBlock(i + 5, j + 0, k + 12, DivineRPGTwilight.cryptFloor.blockID);
		world.setBlock(i + 5, j + 0, k + 13, DivineRPGTwilight.cryptFloor.blockID);
		world.setBlock(i + 5, j + 0, k + 14, DivineRPGTwilight.cryptFloor.blockID);
		world.setBlock(i + 5, j + 0, k + 15, DivineRPGTwilight.cryptFloor.blockID);
		world.setBlock(i + 5, j + 0, k + 16, DivineRPGTwilight.dreamdirt.blockID);
		world.setBlock(i + 5, j + 0, k + 17, DivineRPGTwilight.dreamdirt.blockID);
		world.setBlock(i + 5, j + 0, k + 18, DivineRPGTwilight.dreamdirt.blockID);
		world.setBlock(i + 5, j + 0, k + 19, DivineRPGTwilight.dreamdirt.blockID);
		world.setBlock(i + 5, j + 1, k + 0, DivineRPGTwilight.cryptWall.blockID);
		world.setBlock(i + 5, j + 1, k + 1, 0);
		world.setBlock(i + 5, j + 1, k + 2, DivineRPGTwilight.cryptWall.blockID);
		world.setBlock(i + 5, j + 1, k + 3, DivineRPGTwilight.dreamdirt.blockID);
		world.setBlock(i + 5, j + 1, k + 4, DivineRPGTwilight.dreamdirt.blockID);
		world.setBlock(i + 5, j + 1, k + 5, DivineRPGTwilight.dreamdirt.blockID);
		world.setBlock(i + 5, j + 1, k + 6, DivineRPGTwilight.dreamdirt.blockID);
		world.setBlock(i + 5, j + 1, k + 7, DivineRPGTwilight.dreamdirt.blockID);
		world.setBlock(i + 5, j + 1, k + 8, DivineRPGTwilight.dreamdirt.blockID);
		world.setBlock(i + 5, j + 1, k + 9, DivineRPGTwilight.cryptWall.blockID);
		world.setBlock(i + 5, j + 1, k + 10, 0);
		world.setBlock(i + 5, j + 1, k + 11, 0);
		world.setBlock(i + 5, j + 1, k + 12, 0);
		world.setBlock(i + 5, j + 1, k + 13, 0);
		world.setBlock(i + 5, j + 1, k + 14, 0);
		world.setBlock(i + 5, j + 1, k + 15, 0);
		world.setBlock(i + 5, j + 1, k + 16, DivineRPGTwilight.cryptWall.blockID);
		world.setBlock(i + 5, j + 1, k + 17, DivineRPGTwilight.dreamdirt.blockID);
		world.setBlock(i + 5, j + 1, k + 18, DivineRPGTwilight.dreamdirt.blockID);
		world.setBlock(i + 5, j + 1, k + 19, DivineRPGTwilight.dreamdirt.blockID);
		world.setBlock(i + 5, j + 2, k + 0, DivineRPGTwilight.cryptWall.blockID);
		world.setBlock(i + 5, j + 2, k + 1, 0);
		world.setBlock(i + 5, j + 2, k + 2, DivineRPGTwilight.cryptWall.blockID);
		world.setBlock(i + 5, j + 2, k + 3, DivineRPGTwilight.dreamdirt.blockID);
		world.setBlock(i + 5, j + 2, k + 4, DivineRPGTwilight.dreamdirt.blockID);
		world.setBlock(i + 5, j + 2, k + 5, DivineRPGTwilight.dreamdirt.blockID);
		world.setBlock(i + 5, j + 2, k + 6, DivineRPGTwilight.dreamdirt.blockID);
		world.setBlock(i + 5, j + 2, k + 7, DivineRPGTwilight.dreamdirt.blockID);
		world.setBlock(i + 5, j + 2, k + 8, DivineRPGTwilight.dreamdirt.blockID);
		world.setBlock(i + 5, j + 2, k + 9, DivineRPGTwilight.cryptWall.blockID);
		world.setBlock(i + 5, j + 2, k + 10, 0);
		world.setBlock(i + 5, j + 2, k + 11, 0);
		world.setBlock(i + 5, j + 2, k + 12, 0);
		world.setBlock(i + 5, j + 2, k + 13, 0);
		world.setBlock(i + 5, j + 2, k + 14, 0);
		world.setBlock(i + 5, j + 2, k + 15, 0);
		world.setBlock(i + 5, j + 2, k + 16, DivineRPGTwilight.cryptWall.blockID);
		world.setBlock(i + 5, j + 2, k + 17, DivineRPGTwilight.dreamdirt.blockID);
		world.setBlock(i + 5, j + 2, k + 18, DivineRPGTwilight.dreamdirt.blockID);
		world.setBlock(i + 5, j + 2, k + 19, DivineRPGTwilight.dreamdirt.blockID);
		world.setBlock(i + 5, j + 3, k + 0, DivineRPGTwilight.dreamdirt.blockID);
		world.setBlock(i + 5, j + 3, k + 1, DivineRPGTwilight.hungerstone2.blockID);
		world.setBlock(i + 5, j + 3, k + 2, DivineRPGTwilight.dreamdirt.blockID);
		world.setBlock(i + 5, j + 3, k + 3, DivineRPGTwilight.dreamdirt.blockID);
		world.setBlock(i + 5, j + 3, k + 4, DivineRPGTwilight.dreamdirt.blockID);
		world.setBlock(i + 5, j + 3, k + 5, DivineRPGTwilight.dreamdirt.blockID);
		world.setBlock(i + 5, j + 3, k + 6, DivineRPGTwilight.dreamdirt.blockID);
		world.setBlock(i + 5, j + 3, k + 7, DivineRPGTwilight.dreamdirt.blockID);
		world.setBlock(i + 5, j + 3, k + 8, DivineRPGTwilight.dreamdirt.blockID);
		world.setBlock(i + 5, j + 3, k + 9, DivineRPGTwilight.cryptWall.blockID);
		world.setBlock(i + 5, j + 3, k + 10, 0);
		world.setBlock(i + 5, j + 3, k + 11, 0);
		world.setBlock(i + 5, j + 3, k + 12, 0);
		world.setBlock(i + 5, j + 3, k + 13, 0);
		world.setBlock(i + 5, j + 3, k + 14, 0);
		world.setBlock(i + 5, j + 3, k + 15, 0);
		world.setBlock(i + 5, j + 3, k + 16, DivineRPGTwilight.cryptWall.blockID);
		world.setBlock(i + 5, j + 3, k + 17, DivineRPGTwilight.dreamdirt.blockID);
		world.setBlock(i + 5, j + 3, k + 18, DivineRPGTwilight.dreamdirt.blockID);
		world.setBlock(i + 5, j + 3, k + 19, DivineRPGTwilight.dreamdirt.blockID);
		world.setBlock(i + 5, j + 4, k + 0, DivineRPGTwilight.dreamdirt.blockID);
		world.setBlock(i + 5, j + 4, k + 1, DivineRPGTwilight.dreamdirt.blockID);
		world.setBlock(i + 5, j + 4, k + 2, DivineRPGTwilight.dreamdirt.blockID);
		world.setBlock(i + 5, j + 4, k + 3, DivineRPGTwilight.dreamdirt.blockID);
		world.setBlock(i + 5, j + 4, k + 4, DivineRPGTwilight.dreamdirt.blockID);
		world.setBlock(i + 5, j + 4, k + 5, DivineRPGTwilight.dreamdirt.blockID);
		world.setBlock(i + 5, j + 4, k + 6, DivineRPGTwilight.dreamdirt.blockID);
		world.setBlock(i + 5, j + 4, k + 7, DivineRPGTwilight.dreamdirt.blockID);
		world.setBlock(i + 5, j + 4, k + 8, DivineRPGTwilight.dreamdirt.blockID);
		world.setBlock(i + 5, j + 4, k + 9, DivineRPGTwilight.dreamdirt.blockID);
		world.setBlock(i + 5, j + 4, k + 10, DivineRPGTwilight.hungerstone2.blockID);
		world.setBlock(i + 5, j + 4, k + 11, DivineRPGTwilight.hungerstone2.blockID);
		world.setBlock(i + 5, j + 4, k + 12, DivineRPGTwilight.hungerstone2.blockID);
		world.setBlock(i + 5, j + 4, k + 13, DivineRPGTwilight.hungerstone2.blockID);
		world.setBlock(i + 5, j + 4, k + 14, DivineRPGTwilight.hungerstone2.blockID);
		world.setBlock(i + 5, j + 4, k + 15, DivineRPGTwilight.hungerstone2.blockID);
		world.setBlock(i + 5, j + 4, k + 16, DivineRPGTwilight.dreamdirt.blockID);
		world.setBlock(i + 5, j + 4, k + 17, DivineRPGTwilight.dreamdirt.blockID);
		world.setBlock(i + 5, j + 4, k + 18, DivineRPGTwilight.dreamdirt.blockID);
		world.setBlock(i + 5, j + 4, k + 19, DivineRPGTwilight.dreamdirt.blockID);
		world.setBlock(i + 5, j + 5, k + 0, DivineRPGTwilight.dreamdirt.blockID);
		world.setBlock(i + 5, j + 5, k + 1, DivineRPGTwilight.dreamdirt.blockID);
		world.setBlock(i + 5, j + 5, k + 2, DivineRPGTwilight.dreamdirt.blockID);
		world.setBlock(i + 5, j + 5, k + 3, DivineRPGTwilight.cryptWall.blockID);
		world.setBlock(i + 5, j + 5, k + 4, DivineRPGTwilight.cryptWall.blockID);
		world.setBlock(i + 5, j + 5, k + 5, DivineRPGTwilight.dreamdirt.blockID);
		world.setBlock(i + 5, j + 5, k + 6, DivineRPGTwilight.dreamdirt.blockID);
		world.setBlock(i + 5, j + 5, k + 7, DivineRPGTwilight.dreamdirt.blockID);
		world.setBlock(i + 5, j + 5, k + 8, DivineRPGTwilight.dreamdirt.blockID);
		world.setBlock(i + 5, j + 5, k + 9, DivineRPGTwilight.dreamdirt.blockID);
		world.setBlock(i + 5, j + 5, k + 10, DivineRPGTwilight.dreamdirt.blockID);
		world.setBlock(i + 5, j + 5, k + 11, DivineRPGTwilight.dreamdirt.blockID);
		world.setBlock(i + 5, j + 5, k + 12, DivineRPGTwilight.dreamdirt.blockID);
		world.setBlock(i + 5, j + 5, k + 13, DivineRPGTwilight.dreamdirt.blockID);
		world.setBlock(i + 5, j + 5, k + 14, DivineRPGTwilight.cryptWall.blockID);
		world.setBlock(i + 5, j + 5, k + 15, DivineRPGTwilight.cryptWall.blockID);
		world.setBlock(i + 5, j + 5, k + 16, DivineRPGTwilight.dreamdirt.blockID);
		world.setBlock(i + 5, j + 5, k + 17, DivineRPGTwilight.dreamdirt.blockID);
		world.setBlock(i + 5, j + 5, k + 18, DivineRPGTwilight.dreamdirt.blockID);
		world.setBlock(i + 5, j + 5, k + 19, DivineRPGTwilight.dreamdirt.blockID);
		world.setBlock(i + 5, j + 6, k + 0, DivineRPGTwilight.hungerstone1.blockID);
		world.setBlock(i + 5, j + 6, k + 1, 0);
		world.setBlock(i + 5, j + 6, k + 2, 0);
		world.setBlock(i + 5, j + 6, k + 3, 0);
		world.setBlock(i + 5, j + 6, k + 4, 0);
		world.setBlock(i + 5, j + 6, k + 5, 0);
		world.setBlock(i + 5, j + 6, k + 6, 0);
		world.setBlock(i + 5, j + 6, k + 7, 0);
		world.setBlock(i + 5, j + 6, k + 8, 0);
		world.setBlock(i + 5, j + 6, k + 9, 0);
		world.setBlock(i + 5, j + 6, k + 10, 0);
		world.setBlock(i + 5, j + 6, k + 11, DivineRPGTwilight.hungerstone1.blockID);
		world.setBlock(i + 5, j + 6, k + 12, DivineRPGTwilight.hungerstone1.blockID);
		world.setBlock(i + 5, j + 6, k + 13, DivineRPGTwilight.hungerstone1.blockID);
		world.setBlock(i + 5, j + 6, k + 14, 0);
		world.setBlock(i + 5, j + 6, k + 15, 0);
		world.setBlock(i + 5, j + 6, k + 16, 0);
		world.setBlock(i + 5, j + 6, k + 17, 0);
		world.setBlock(i + 5, j + 6, k + 18, 0);
		world.setBlock(i + 5, j + 6, k + 19, DivineRPGTwilight.hungerstone1.blockID);
		world.setBlock(i + 5, j + 7, k + 0, DivineRPGTwilight.hungerstone1.blockID);
		world.setBlock(i + 5, j + 7, k + 1, 0);
		world.setBlock(i + 5, j + 7, k + 2, 0);
		world.setBlock(i + 5, j + 7, k + 3, 0);
		world.setBlock(i + 5, j + 7, k + 4, 0);
		world.setBlock(i + 5, j + 7, k + 5, 0);
		world.setBlock(i + 5, j + 7, k + 6, 0);
		world.setBlock(i + 5, j + 7, k + 7, 0);
		world.setBlock(i + 5, j + 7, k + 8, 0);
		world.setBlock(i + 5, j + 7, k + 9, 0);
		world.setBlock(i + 5, j + 7, k + 10, 0);
		world.setBlock(i + 5, j + 7, k + 11, 0);
		world.setBlock(i + 5, j + 7, k + 12, 0);
		world.setBlock(i + 5, j + 7, k + 13, 0);
		world.setBlock(i + 5, j + 7, k + 14, 0);
		world.setBlock(i + 5, j + 7, k + 15, 0);
		world.setBlock(i + 5, j + 7, k + 16, 0);
		world.setBlock(i + 5, j + 7, k + 17, 0);
		world.setBlock(i + 5, j + 7, k + 18, 0);
		world.setBlock(i + 5, j + 7, k + 19, DivineRPGTwilight.hungerstone1.blockID);
		world.setBlock(i + 5, j + 8, k + 0, DivineRPGTwilight.hungerstone1.blockID);
		world.setBlock(i + 5, j + 8, k + 1, 0);
		world.setBlock(i + 5, j + 8, k + 2, 0);
		world.setBlock(i + 5, j + 8, k + 3, 0);
		world.setBlock(i + 5, j + 8, k + 4, 0);
		world.setBlock(i + 5, j + 8, k + 5, 0);
		world.setBlock(i + 5, j + 8, k + 6, 0);
		world.setBlock(i + 5, j + 8, k + 7, 0);
		world.setBlock(i + 5, j + 8, k + 8, 0);
		world.setBlock(i + 5, j + 8, k + 9, 0);
		world.setBlock(i + 5, j + 8, k + 10, 0);
		world.setBlock(i + 5, j + 8, k + 11, 0);
		world.setBlock(i + 5, j + 8, k + 12, 0);
		world.setBlock(i + 5, j + 8, k + 13, 0);
		world.setBlock(i + 5, j + 8, k + 14, 0);
		world.setBlock(i + 5, j + 8, k + 15, 0);
		world.setBlock(i + 5, j + 8, k + 16, 0);
		world.setBlock(i + 5, j + 8, k + 17, 0);
		world.setBlock(i + 5, j + 8, k + 18, 0);
		world.setBlock(i + 5, j + 8, k + 19, DivineRPGTwilight.hungerstone1.blockID);
		world.setBlock(i + 5, j + 9, k + 0, 0);
		world.setBlock(i + 5, j + 9, k + 1, 0);
		world.setBlock(i + 5, j + 9, k + 2, 0);
		world.setBlock(i + 5, j + 9, k + 3, 0);
		world.setBlock(i + 5, j + 9, k + 4, 0);
		world.setBlock(i + 5, j + 9, k + 5, 0);
		world.setBlock(i + 5, j + 9, k + 6, 0);
		world.setBlock(i + 5, j + 9, k + 7, 0);
		world.setBlock(i + 5, j + 9, k + 8, 0);
		world.setBlock(i + 5, j + 9, k + 9, 0);
		world.setBlock(i + 5, j + 9, k + 10, 0);
		world.setBlock(i + 5, j + 9, k + 11, 0);
		world.setBlock(i + 5, j + 9, k + 12, 0);
		world.setBlock(i + 5, j + 9, k + 13, 0);
		world.setBlock(i + 5, j + 9, k + 14, 0);
		world.setBlock(i + 5, j + 9, k + 15, 0);
		world.setBlock(i + 5, j + 9, k + 16, 0);
		world.setBlock(i + 5, j + 9, k + 17, 0);
		world.setBlock(i + 5, j + 9, k + 18, 0);
		world.setBlock(i + 5, j + 9, k + 19, 0);
		world.setBlock(i + 5, j + 10, k + 0, 0);
		world.setBlock(i + 5, j + 10, k + 1, 0);
		world.setBlock(i + 5, j + 10, k + 2, 0);
		world.setBlock(i + 5, j + 10, k + 3, 0);
		world.setBlock(i + 5, j + 10, k + 4, 0);
		world.setBlock(i + 5, j + 10, k + 5, 0);
		world.setBlock(i + 5, j + 10, k + 6, 0);
		world.setBlock(i + 5, j + 10, k + 7, 0);
		world.setBlock(i + 5, j + 10, k + 8, 0);
		world.setBlock(i + 5, j + 10, k + 9, 0);
		world.setBlock(i + 5, j + 10, k + 10, 0);
		world.setBlock(i + 5, j + 10, k + 11, 0);
		world.setBlock(i + 5, j + 10, k + 12, 0);
		world.setBlock(i + 5, j + 10, k + 13, 0);
		world.setBlock(i + 5, j + 10, k + 14, 0);
		world.setBlock(i + 5, j + 10, k + 15, 0);
		world.setBlock(i + 5, j + 10, k + 16, 0);
		world.setBlock(i + 5, j + 10, k + 17, 0);
		world.setBlock(i + 5, j + 10, k + 18, 0);
		world.setBlock(i + 5, j + 10, k + 19, 0);
		world.setBlock(i + 6, j + 0, k + 0, DivineRPGTwilight.cryptWall.blockID);
		world.setBlock(i + 6, j + 0, k + 1, 0);
		world.setBlock(i + 6, j + 0, k + 2, DivineRPGTwilight.cryptWall.blockID);
		world.setBlock(i + 6, j + 0, k + 3, DivineRPGTwilight.cryptWall.blockID);
		world.setBlock(i + 6, j + 0, k + 4, DivineRPGTwilight.cryptWall.blockID);
		world.setBlock(i + 6, j + 0, k + 5, DivineRPGTwilight.dreamdirt.blockID);
		world.setBlock(i + 6, j + 0, k + 6, DivineRPGTwilight.dreamdirt.blockID);
		world.setBlock(i + 6, j + 0, k + 7, DivineRPGTwilight.dreamdirt.blockID);
		world.setBlock(i + 6, j + 0, k + 8, DivineRPGTwilight.dreamdirt.blockID);
		world.setBlock(i + 6, j + 0, k + 9, DivineRPGTwilight.dreamdirt.blockID);
		world.setBlock(i + 6, j + 0, k + 10, DivineRPGTwilight.cryptFloor.blockID);
		world.setBlock(i + 6, j + 0, k + 11, DivineRPGTwilight.cryptFloor.blockID);
		world.setBlock(i + 6, j + 0, k + 12, DivineRPGTwilight.cryptFloor.blockID);
		world.setBlock(i + 6, j + 0, k + 13, DivineRPGTwilight.cryptFloor.blockID);
		world.setBlock(i + 6, j + 0, k + 14, DivineRPGTwilight.cryptFloor.blockID);
		world.setBlock(i + 6, j + 0, k + 15, DivineRPGTwilight.cryptFloor.blockID);
		world.setBlock(i + 6, j + 0, k + 16, DivineRPGTwilight.dreamdirt.blockID);
		world.setBlock(i + 6, j + 0, k + 17, DivineRPGTwilight.dreamdirt.blockID);
		world.setBlock(i + 6, j + 0, k + 18, DivineRPGTwilight.dreamdirt.blockID);
		world.setBlock(i + 6, j + 0, k + 19, DivineRPGTwilight.dreamdirt.blockID);
		world.setBlock(i + 6, j + 1, k + 0, DivineRPGTwilight.cryptWall.blockID);
		world.setBlock(i + 6, j + 1, k + 1, 0);
		world.setBlock(i + 6, j + 1, k + 2, DivineRPGTwilight.firecrystal.blockID);
		world.setBlock(i + 6, j + 1, k + 3, DivineRPGTwilight.cryptWall.blockID);
		world.setBlock(i + 6, j + 1, k + 4, DivineRPGTwilight.cryptWall.blockID);
		world.setBlock(i + 6, j + 1, k + 5, DivineRPGTwilight.dreamdirt.blockID);
		world.setBlock(i + 6, j + 1, k + 6, DivineRPGTwilight.dreamdirt.blockID);
		world.setBlock(i + 6, j + 1, k + 7, DivineRPGTwilight.dreamdirt.blockID);
		world.setBlock(i + 6, j + 1, k + 8, DivineRPGTwilight.dreamdirt.blockID);
		world.setBlock(i + 6, j + 1, k + 9, DivineRPGTwilight.cryptWall.blockID);
		world.setBlock(i + 6, j + 1, k + 10, 0);
		world.setBlock(i + 6, j + 1, k + 11, 0);
		world.setBlock(i + 6, j + 1, k + 12, 0);
		world.setBlock(i + 6, j + 1, k + 13, 0);
		world.setBlock(i + 6, j + 1, k + 14, 0);
		world.setBlock(i + 6, j + 1, k + 15, 0);
		world.setBlock(i + 6, j + 1, k + 16, DivineRPGTwilight.cryptWall.blockID);
		world.setBlock(i + 6, j + 1, k + 17, DivineRPGTwilight.dreamdirt.blockID);
		world.setBlock(i + 6, j + 1, k + 18, DivineRPGTwilight.dreamdirt.blockID);
		world.setBlock(i + 6, j + 1, k + 19, DivineRPGTwilight.dreamdirt.blockID);
		world.setBlock(i + 6, j + 2, k + 0, DivineRPGTwilight.cryptWall.blockID);
		world.setBlock(i + 6, j + 2, k + 1, 0);
		world.setBlock(i + 6, j + 2, k + 2, DivineRPGTwilight.cryptWall.blockID);
		world.setBlock(i + 6, j + 2, k + 3, DivineRPGTwilight.cryptWall.blockID);
		world.setBlock(i + 6, j + 2, k + 4, DivineRPGTwilight.cryptWall.blockID);
		world.setBlock(i + 6, j + 2, k + 5, DivineRPGTwilight.dreamdirt.blockID);
		world.setBlock(i + 6, j + 2, k + 6, DivineRPGTwilight.dreamdirt.blockID);
		world.setBlock(i + 6, j + 2, k + 7, DivineRPGTwilight.dreamdirt.blockID);
		world.setBlock(i + 6, j + 2, k + 8, DivineRPGTwilight.dreamdirt.blockID);
		world.setBlock(i + 6, j + 2, k + 9, DivineRPGTwilight.cryptWall.blockID);
		world.setBlock(i + 6, j + 2, k + 10, 0);
		world.setBlock(i + 6, j + 2, k + 11, 0);
		world.setBlock(i + 6, j + 2, k + 12, 0);
		world.setBlock(i + 6, j + 2, k + 13, 0);
		world.setBlock(i + 6, j + 2, k + 14, 0);
		world.setBlock(i + 6, j + 2, k + 15, 0);
		world.setBlock(i + 6, j + 2, k + 16, DivineRPGTwilight.cryptWall.blockID);
		world.setBlock(i + 6, j + 2, k + 17, DivineRPGTwilight.dreamdirt.blockID);
		world.setBlock(i + 6, j + 2, k + 18, DivineRPGTwilight.dreamdirt.blockID);
		world.setBlock(i + 6, j + 2, k + 19, DivineRPGTwilight.dreamdirt.blockID);
		world.setBlock(i + 6, j + 3, k + 0, DivineRPGTwilight.dreamdirt.blockID);
		world.setBlock(i + 6, j + 3, k + 1, DivineRPGTwilight.cryptWall.blockID);
		world.setBlock(i + 6, j + 3, k + 2, DivineRPGTwilight.cryptWall.blockID);
		world.setBlock(i + 6, j + 3, k + 3, DivineRPGTwilight.cryptWall.blockID);
		world.setBlock(i + 6, j + 3, k + 4, DivineRPGTwilight.cryptWall.blockID);
		world.setBlock(i + 6, j + 3, k + 5, DivineRPGTwilight.dreamdirt.blockID);
		world.setBlock(i + 6, j + 3, k + 6, DivineRPGTwilight.dreamdirt.blockID);
		world.setBlock(i + 6, j + 3, k + 7, DivineRPGTwilight.dreamdirt.blockID);
		world.setBlock(i + 6, j + 3, k + 8, DivineRPGTwilight.dreamdirt.blockID);
		world.setBlock(i + 6, j + 3, k + 9, DivineRPGTwilight.cryptWall.blockID);
		world.setBlock(i + 6, j + 3, k + 10, 0);
		world.setBlock(i + 6, j + 3, k + 11, 0);
		world.setBlock(i + 6, j + 3, k + 12, 0);
		world.setBlock(i + 6, j + 3, k + 13, 0);
		world.setBlock(i + 6, j + 3, k + 14, 0);
		world.setBlock(i + 6, j + 3, k + 15, 0);
		world.setBlock(i + 6, j + 3, k + 16, DivineRPGTwilight.cryptWall.blockID);
		world.setBlock(i + 6, j + 3, k + 17, DivineRPGTwilight.dreamdirt.blockID);
		world.setBlock(i + 6, j + 3, k + 18, DivineRPGTwilight.dreamdirt.blockID);
		world.setBlock(i + 6, j + 3, k + 19, DivineRPGTwilight.dreamdirt.blockID);
		world.setBlock(i + 6, j + 4, k + 0, DivineRPGTwilight.dreamdirt.blockID);
		world.setBlock(i + 6, j + 4, k + 1, DivineRPGTwilight.dreamdirt.blockID);
		world.setBlock(i + 6, j + 4, k + 2, DivineRPGTwilight.dreamdirt.blockID);
		world.setBlock(i + 6, j + 4, k + 3, DivineRPGTwilight.dreamdirt.blockID);
		world.setBlock(i + 6, j + 4, k + 4, DivineRPGTwilight.dreamdirt.blockID);
		world.setBlock(i + 6, j + 4, k + 5, DivineRPGTwilight.dreamdirt.blockID);
		world.setBlock(i + 6, j + 4, k + 6, DivineRPGTwilight.dreamdirt.blockID);
		world.setBlock(i + 6, j + 4, k + 7, DivineRPGTwilight.dreamdirt.blockID);
		world.setBlock(i + 6, j + 4, k + 8, DivineRPGTwilight.dreamdirt.blockID);
		world.setBlock(i + 6, j + 4, k + 9, DivineRPGTwilight.dreamdirt.blockID);
		world.setBlock(i + 6, j + 4, k + 10, DivineRPGTwilight.hungerstone2.blockID);
		world.setBlock(i + 6, j + 4, k + 11, DivineRPGTwilight.hungerstone2.blockID);
		world.setBlock(i + 6, j + 4, k + 12, DivineRPGTwilight.hungerstone2.blockID);
		world.setBlock(i + 6, j + 4, k + 13, DivineRPGTwilight.hungerstone2.blockID);
		world.setBlock(i + 6, j + 4, k + 14, DivineRPGTwilight.hungerstone2.blockID);
		world.setBlock(i + 6, j + 4, k + 15, DivineRPGTwilight.hungerstone2.blockID);
		world.setBlock(i + 6, j + 4, k + 16, DivineRPGTwilight.dreamdirt.blockID);
		world.setBlock(i + 6, j + 4, k + 17, DivineRPGTwilight.dreamdirt.blockID);
		world.setBlock(i + 6, j + 4, k + 18, DivineRPGTwilight.dreamdirt.blockID);
		world.setBlock(i + 6, j + 4, k + 19, DivineRPGTwilight.dreamdirt.blockID);
		world.setBlock(i + 6, j + 5, k + 0, DivineRPGTwilight.cryptWall.blockID);
		world.setBlock(i + 6, j + 5, k + 1, DivineRPGTwilight.cryptWall.blockID);
		world.setBlock(i + 6, j + 5, k + 2, DivineRPGTwilight.cryptWall.blockID);
		world.setBlock(i + 6, j + 5, k + 3, DivineRPGTwilight.cryptWall.blockID);
		world.setBlock(i + 6, j + 5, k + 4, DivineRPGTwilight.cryptWall.blockID);
		world.setBlock(i + 6, j + 5, k + 5, DivineRPGTwilight.cryptWall.blockID);
		world.setBlock(i + 6, j + 5, k + 6, DivineRPGTwilight.cryptWall.blockID);
		world.setBlock(i + 6, j + 5, k + 7, DivineRPGTwilight.cryptWall.blockID);
		world.setBlock(i + 6, j + 5, k + 8, DivineRPGTwilight.cryptWall.blockID);
		world.setBlock(i + 6, j + 5, k + 9, DivineRPGTwilight.cryptWall.blockID);
		world.setBlock(i + 6, j + 5, k + 10, DivineRPGTwilight.cryptWall.blockID);
		world.setBlock(i + 6, j + 5, k + 11, DivineRPGTwilight.cryptWall.blockID);
		world.setBlock(i + 6, j + 5, k + 12, DivineRPGTwilight.cryptWall.blockID);
		world.setBlock(i + 6, j + 5, k + 13, DivineRPGTwilight.cryptWall.blockID);
		world.setBlock(i + 6, j + 5, k + 14, DivineRPGTwilight.cryptWall.blockID);
		world.setBlock(i + 6, j + 5, k + 15, DivineRPGTwilight.cryptWall.blockID);
		world.setBlock(i + 6, j + 5, k + 16, DivineRPGTwilight.cryptWall.blockID);
		world.setBlock(i + 6, j + 5, k + 17, DivineRPGTwilight.cryptWall.blockID);
		world.setBlock(i + 6, j + 5, k + 18, DivineRPGTwilight.cryptWall.blockID);
		world.setBlock(i + 6, j + 5, k + 19, DivineRPGTwilight.cryptWall.blockID);
		world.setBlock(i + 6, j + 6, k + 0, 0);
		world.setBlock(i + 6, j + 6, k + 1, 0);
		world.setBlock(i + 6, j + 6, k + 2, 0);
		world.setBlock(i + 6, j + 6, k + 3, 0);
		world.setBlock(i + 6, j + 6, k + 4, 0);
		world.setBlock(i + 6, j + 6, k + 5, 0);
		world.setBlock(i + 6, j + 6, k + 6, 0);
		world.setBlock(i + 6, j + 6, k + 7, 0);
		world.setBlock(i + 6, j + 6, k + 8, 0);
		world.setBlock(i + 6, j + 6, k + 9, 0);
		world.setBlock(i + 6, j + 6, k + 10, 0);
		world.setBlock(i + 6, j + 6, k + 11, 0);
		world.setBlock(i + 6, j + 6, k + 12, 0);
		world.setBlock(i + 6, j + 6, k + 13, 0);
		world.setBlock(i + 6, j + 6, k + 14, 0);
		world.setBlock(i + 6, j + 6, k + 15, 0);
		world.setBlock(i + 6, j + 6, k + 16, 0);
		world.setBlock(i + 6, j + 6, k + 17, 0);
		world.setBlock(i + 6, j + 6, k + 18, 0);
		world.setBlock(i + 6, j + 6, k + 19, 0);
		world.setBlock(i + 6, j + 7, k + 0, 0);
		world.setBlock(i + 6, j + 7, k + 1, 0);
		world.setBlock(i + 6, j + 7, k + 2, 0);
		world.setBlock(i + 6, j + 7, k + 3, 0);
		world.setBlock(i + 6, j + 7, k + 4, 0);
		world.setBlock(i + 6, j + 7, k + 5, 0);
		world.setBlock(i + 6, j + 7, k + 6, 0);
		world.setBlock(i + 6, j + 7, k + 7, 0);
		world.setBlock(i + 6, j + 7, k + 8, 0);
		world.setBlock(i + 6, j + 7, k + 9, 0);
		world.setBlock(i + 6, j + 7, k + 10, 0);
		world.setBlock(i + 6, j + 7, k + 11, 0);
		world.setBlock(i + 6, j + 7, k + 12, 0);
		world.setBlock(i + 6, j + 7, k + 13, 0);
		world.setBlock(i + 6, j + 7, k + 14, 0);
		world.setBlock(i + 6, j + 7, k + 15, 0);
		world.setBlock(i + 6, j + 7, k + 16, 0);
		world.setBlock(i + 6, j + 7, k + 17, 0);
		world.setBlock(i + 6, j + 7, k + 18, 0);
		world.setBlock(i + 6, j + 7, k + 19, 0);
		world.setBlock(i + 6, j + 8, k + 0, DivineRPGTwilight.hungerstone1.blockID);
		world.setBlock(i + 6, j + 8, k + 1, 0);
		world.setBlock(i + 6, j + 8, k + 2, 0);
		world.setBlock(i + 6, j + 8, k + 3, 0);
		world.setBlock(i + 6, j + 8, k + 4, 0);
		world.setBlock(i + 6, j + 8, k + 5, 0);
		world.setBlock(i + 6, j + 8, k + 6, 0);
		world.setBlock(i + 6, j + 8, k + 7, 0);
		world.setBlock(i + 6, j + 8, k + 8, 0);
		world.setBlock(i + 6, j + 8, k + 9, 0);
		world.setBlock(i + 6, j + 8, k + 10, 0);
		world.setBlock(i + 6, j + 8, k + 11, 0);
		world.setBlock(i + 6, j + 8, k + 12, 0);
		world.setBlock(i + 6, j + 8, k + 13, 0);
		world.setBlock(i + 6, j + 8, k + 14, 0);
		world.setBlock(i + 6, j + 8, k + 15, 0);
		world.setBlock(i + 6, j + 8, k + 16, 0);
		world.setBlock(i + 6, j + 8, k + 17, 0);
		world.setBlock(i + 6, j + 8, k + 18, 0);
		world.setBlock(i + 6, j + 8, k + 19, DivineRPGTwilight.hungerstone1.blockID);

		generate2(world, rand, i, j, k);
		return true;
	}

	public boolean generate2(World world, Random rand, int i, int j, int k) {
		world.setBlock(i + 6, j + 9, k + 0, 0);
		world.setBlock(i + 6, j + 9, k + 1, 0);
		world.setBlock(i + 6, j + 9, k + 2, 0);
		world.setBlock(i + 6, j + 9, k + 3, 0);
		world.setBlock(i + 6, j + 9, k + 4, 0);
		world.setBlock(i + 6, j + 9, k + 5, 0);
		world.setBlock(i + 6, j + 9, k + 6, 0);
		world.setBlock(i + 6, j + 9, k + 7, 0);
		world.setBlock(i + 6, j + 9, k + 8, 0);
		world.setBlock(i + 6, j + 9, k + 9, 0);
		world.setBlock(i + 6, j + 9, k + 10, 0);
		world.setBlock(i + 6, j + 9, k + 11, 0);
		world.setBlock(i + 6, j + 9, k + 12, 0);
		world.setBlock(i + 6, j + 9, k + 13, 0);
		world.setBlock(i + 6, j + 9, k + 14, 0);
		world.setBlock(i + 6, j + 9, k + 15, 0);
		world.setBlock(i + 6, j + 9, k + 16, 0);
		world.setBlock(i + 6, j + 9, k + 17, 0);
		world.setBlock(i + 6, j + 9, k + 18, 0);
		world.setBlock(i + 6, j + 9, k + 19, 0);
		world.setBlock(i + 6, j + 10, k + 0, 0);
		world.setBlock(i + 6, j + 10, k + 1, 0);
		world.setBlock(i + 6, j + 10, k + 2, 0);
		world.setBlock(i + 6, j + 10, k + 3, 0);
		world.setBlock(i + 6, j + 10, k + 4, 0);
		world.setBlock(i + 6, j + 10, k + 5, 0);
		world.setBlock(i + 6, j + 10, k + 6, 0);
		world.setBlock(i + 6, j + 10, k + 7, 0);
		world.setBlock(i + 6, j + 10, k + 8, 0);
		world.setBlock(i + 6, j + 10, k + 9, 0);
		world.setBlock(i + 6, j + 10, k + 10, 0);
		world.setBlock(i + 6, j + 10, k + 11, 0);
		world.setBlock(i + 6, j + 10, k + 12, 0);
		world.setBlock(i + 6, j + 10, k + 13, 0);
		world.setBlock(i + 6, j + 10, k + 14, 0);
		world.setBlock(i + 6, j + 10, k + 15, 0);
		world.setBlock(i + 6, j + 10, k + 16, 0);
		world.setBlock(i + 6, j + 10, k + 17, 0);
		world.setBlock(i + 6, j + 10, k + 18, 0);
		world.setBlock(i + 6, j + 10, k + 19, 0);
		world.setBlock(i + 7, j + 0, k + 0, DivineRPGTwilight.cryptWall.blockID);
		world.setBlock(i + 7, j + 0, k + 1, 0);
		world.setBlock(i + 7, j + 0, k + 2, 0);
		world.setBlock(i + 7, j + 0, k + 3, 0);
		world.setBlock(i + 7, j + 0, k + 4, 0);
		world.setBlock(i + 7, j + 0, k + 5, DivineRPGTwilight.cryptWall.blockID);
		world.setBlock(i + 7, j + 0, k + 6, DivineRPGTwilight.dreamdirt.blockID);
		world.setBlock(i + 7, j + 0, k + 7, DivineRPGTwilight.dreamdirt.blockID);
		world.setBlock(i + 7, j + 0, k + 8, DivineRPGTwilight.dreamdirt.blockID);
		world.setBlock(i + 7, j + 0, k + 9, DivineRPGTwilight.dreamdirt.blockID);
		world.setBlock(i + 7, j + 0, k + 10, DivineRPGTwilight.cryptFloor.blockID);
		world.setBlock(i + 7, j + 0, k + 11, DivineRPGTwilight.cryptFloor.blockID);
		world.setBlock(i + 7, j + 0, k + 12, DivineRPGTwilight.cryptFloor.blockID);
		world.setBlock(i + 7, j + 0, k + 13, DivineRPGTwilight.cryptFloor.blockID);
		world.setBlock(i + 7, j + 0, k + 14, DivineRPGTwilight.cryptFloor.blockID);
		world.setBlock(i + 7, j + 0, k + 15, DivineRPGTwilight.cryptFloor.blockID);
		world.setBlock(i + 7, j + 0, k + 16, DivineRPGTwilight.dreamdirt.blockID);
		world.setBlock(i + 7, j + 0, k + 17, DivineRPGTwilight.dreamdirt.blockID);
		world.setBlock(i + 7, j + 0, k + 18, DivineRPGTwilight.dreamdirt.blockID);
		world.setBlock(i + 7, j + 0, k + 19, DivineRPGTwilight.dreamdirt.blockID);
		world.setBlock(i + 7, j + 1, k + 0, DivineRPGTwilight.cryptWall.blockID);
		world.setBlock(i + 7, j + 1, k + 1, 0);
		world.setBlock(i + 7, j + 1, k + 2, 0);
		world.setBlock(i + 7, j + 1, k + 3, 0);
		world.setBlock(i + 7, j + 1, k + 4, 0);
		world.setBlock(i + 7, j + 1, k + 5, DivineRPGTwilight.cryptWall.blockID);
		world.setBlock(i + 7, j + 1, k + 6, DivineRPGTwilight.dreamdirt.blockID);
		world.setBlock(i + 7, j + 1, k + 7, DivineRPGTwilight.dreamdirt.blockID);
		world.setBlock(i + 7, j + 1, k + 8, DivineRPGTwilight.dreamdirt.blockID);
		world.setBlock(i + 7, j + 1, k + 9, DivineRPGTwilight.cryptWall.blockID);
		world.setBlock(i + 7, j + 1, k + 10, 0);
		world.setBlock(i + 7, j + 1, k + 11, 0);
		world.setBlock(i + 7, j + 1, k + 12, 0);
		world.setBlock(i + 7, j + 1, k + 13, 0);
		world.setBlock(i + 7, j + 1, k + 14, 0);
		world.setBlock(i + 7, j + 1, k + 15, 0);
		world.setBlock(i + 7, j + 1, k + 16, DivineRPGTwilight.cryptWall.blockID);
		world.setBlock(i + 7, j + 1, k + 17, DivineRPGTwilight.dreamdirt.blockID);
		world.setBlock(i + 7, j + 1, k + 18, DivineRPGTwilight.dreamdirt.blockID);
		world.setBlock(i + 7, j + 1, k + 19, DivineRPGTwilight.dreamdirt.blockID);
		world.setBlock(i + 7, j + 2, k + 0, DivineRPGTwilight.cryptWall.blockID);
		world.setBlock(i + 7, j + 2, k + 1, 0);
		world.setBlock(i + 7, j + 2, k + 2, 0);
		world.setBlock(i + 7, j + 2, k + 3, 0);
		world.setBlock(i + 7, j + 2, k + 4, 0);
		world.setBlock(i + 7, j + 2, k + 5, DivineRPGTwilight.cryptWall.blockID);
		world.setBlock(i + 7, j + 2, k + 6, DivineRPGTwilight.dreamdirt.blockID);
		world.setBlock(i + 7, j + 2, k + 7, DivineRPGTwilight.dreamdirt.blockID);
		world.setBlock(i + 7, j + 2, k + 8, DivineRPGTwilight.dreamdirt.blockID);
		world.setBlock(i + 7, j + 2, k + 9, DivineRPGTwilight.cryptWall.blockID);
		world.setBlock(i + 7, j + 2, k + 10, 0);
		world.setBlock(i + 7, j + 2, k + 11, 0);
		world.setBlock(i + 7, j + 2, k + 12, 0);
		world.setBlock(i + 7, j + 2, k + 13, 0);
		world.setBlock(i + 7, j + 2, k + 14, 0);
		world.setBlock(i + 7, j + 2, k + 15, 0);
		world.setBlock(i + 7, j + 2, k + 16, DivineRPGTwilight.cryptWall.blockID);
		world.setBlock(i + 7, j + 2, k + 17, DivineRPGTwilight.dreamdirt.blockID);
		world.setBlock(i + 7, j + 2, k + 18, DivineRPGTwilight.dreamdirt.blockID);
		world.setBlock(i + 7, j + 2, k + 19, DivineRPGTwilight.dreamdirt.blockID);
		world.setBlock(i + 7, j + 3, k + 0, DivineRPGTwilight.cryptWall.blockID);
		world.setBlock(i + 7, j + 3, k + 1, 0);
		world.setBlock(i + 7, j + 3, k + 2, 0);
		world.setBlock(i + 7, j + 3, k + 3, 0);
		world.setBlock(i + 7, j + 3, k + 4, 0);
		world.setBlock(i + 7, j + 3, k + 5, DivineRPGTwilight.cryptWall.blockID);
		world.setBlock(i + 7, j + 3, k + 6, DivineRPGTwilight.dreamdirt.blockID);
		world.setBlock(i + 7, j + 3, k + 7, DivineRPGTwilight.dreamdirt.blockID);
		world.setBlock(i + 7, j + 3, k + 8, DivineRPGTwilight.dreamdirt.blockID);
		world.setBlock(i + 7, j + 3, k + 9, DivineRPGTwilight.cryptWall.blockID);
		world.setBlock(i + 7, j + 3, k + 10, 0);
		world.setBlock(i + 7, j + 3, k + 11, 0);
		world.setBlock(i + 7, j + 3, k + 12, 0);
		world.setBlock(i + 7, j + 3, k + 13, 0);
		world.setBlock(i + 7, j + 3, k + 14, 0);
		world.setBlock(i + 7, j + 3, k + 15, 0);
		world.setBlock(i + 7, j + 3, k + 16, DivineRPGTwilight.cryptWall.blockID);
		world.setBlock(i + 7, j + 3, k + 17, DivineRPGTwilight.dreamdirt.blockID);
		world.setBlock(i + 7, j + 3, k + 18, DivineRPGTwilight.dreamdirt.blockID);
		world.setBlock(i + 7, j + 3, k + 19, DivineRPGTwilight.dreamdirt.blockID);
		world.setBlock(i + 7, j + 4, k + 0, DivineRPGTwilight.dreamdirt.blockID);
		world.setBlock(i + 7, j + 4, k + 1, DivineRPGTwilight.hungerstone2.blockID);
		world.setBlock(i + 7, j + 4, k + 2, DivineRPGTwilight.hungerstone2.blockID);
		world.setBlock(i + 7, j + 4, k + 3, DivineRPGTwilight.hungerstone2.blockID);
		world.setBlock(i + 7, j + 4, k + 4, DivineRPGTwilight.hungerstone2.blockID);
		world.setBlock(i + 7, j + 4, k + 5, DivineRPGTwilight.dreamdirt.blockID);
		world.setBlock(i + 7, j + 4, k + 6, DivineRPGTwilight.dreamdirt.blockID);
		world.setBlock(i + 7, j + 4, k + 7, DivineRPGTwilight.dreamdirt.blockID);
		world.setBlock(i + 7, j + 4, k + 8, DivineRPGTwilight.dreamdirt.blockID);
		world.setBlock(i + 7, j + 4, k + 9, DivineRPGTwilight.dreamdirt.blockID);
		world.setBlock(i + 7, j + 4, k + 10, DivineRPGTwilight.hungerstone2.blockID);
		world.setBlock(i + 7, j + 4, k + 11, DivineRPGTwilight.hungerstone2.blockID);
		world.setBlock(i + 7, j + 4, k + 12, DivineRPGTwilight.hungerstone2.blockID);
		world.setBlock(i + 7, j + 4, k + 13, DivineRPGTwilight.hungerstone2.blockID);
		world.setBlock(i + 7, j + 4, k + 14, DivineRPGTwilight.hungerstone2.blockID);
		world.setBlock(i + 7, j + 4, k + 15, DivineRPGTwilight.hungerstone2.blockID);
		world.setBlock(i + 7, j + 4, k + 16, DivineRPGTwilight.dreamdirt.blockID);
		world.setBlock(i + 7, j + 4, k + 17, DivineRPGTwilight.dreamdirt.blockID);
		world.setBlock(i + 7, j + 4, k + 18, DivineRPGTwilight.dreamdirt.blockID);
		world.setBlock(i + 7, j + 4, k + 19, DivineRPGTwilight.dreamdirt.blockID);
		world.setBlock(i + 7, j + 5, k + 0, DivineRPGTwilight.cryptWall.blockID);
		world.setBlock(i + 7, j + 5, k + 1, DivineRPGTwilight.cryptWall.blockID);
		world.setBlock(i + 7, j + 5, k + 2, DivineRPGTwilight.cryptWall.blockID);
