/*
*** MADE BY MITHION'S .SCHEMATIC TO JAVA CONVERTING TOOL v1.6 ***
*/

package xolova.blued00r.divinerpg.generation.vethea.layer1;
import java.util.Random;

import net.minecraft.block.Block;
import net.minecraft.entity.EntityLiving;
import net.minecraft.world.World;
import net.minecraft.world.gen.feature.WorldGenerator;
import xolova.blued00r.divinerpg.DivineRPG;
import xolova.blued00r.divinerpg.entities.mobs.vethea.EntityCryptKeeper;

public class Crypt2 extends WorldGenerator
{
	protected int[] GetValidSpawnBlocks() {
		return new int[] {
		};
	}

	public Crypt2() { }

	public boolean generate(World world, Random rand, int i, int j, int k) {

		world.setBlock(i + 0, j + 0, k + 0, DivineRPGTwilight.dreamdirt.blockID);
		world.setBlock(i + 0, j + 0, k + 1, DivineRPGTwilight.dreamdirt.blockID);
		world.setBlock(i + 0, j + 0, k + 2, DivineRPGTwilight.dreamdirt.blockID);
		world.setBlock(i + 0, j + 0, k + 3, DivineRPGTwilight.dreamdirt.blockID);
		world.setBlock(i + 0, j + 0, k + 4, DivineRPGTwilight.dreamdirt.blockID);
		world.setBlock(i + 0, j + 0, k + 5, DivineRPGTwilight.dreamdirt.blockID);
		world.setBlock(i + 0, j + 0, k + 6, DivineRPGTwilight.dreamdirt.blockID);
		world.setBlock(i + 0, j + 0, k + 7, DivineRPGTwilight.dreamdirt.blockID);
		world.setBlock(i + 0, j + 0, k + 8, DivineRPGTwilight.dreamdirt.blockID);
		world.setBlock(i + 0, j + 0, k + 9, DivineRPGTwilight.dreamdirt.blockID);
		world.setBlock(i + 0, j + 0, k + 10, DivineRPGTwilight.dreamdirt.blockID);
		world.setBlock(i + 0, j + 1, k + 0, DivineRPGTwilight.dreamdirt.blockID);
		world.setBlock(i + 0, j + 1, k + 1, DivineRPGTwilight.dreamdirt.blockID);
		world.setBlock(i + 0, j + 1, k + 2, DivineRPGTwilight.dreamdirt.blockID);
		world.setBlock(i + 0, j + 1, k + 3, DivineRPGTwilight.dreamdirt.blockID);
		world.setBlock(i + 0, j + 1, k + 4, DivineRPGTwilight.cryptWall.blockID);
		world.setBlock(i + 0, j + 1, k + 5, DivineRPGTwilight.cryptWall.blockID);
		world.setBlock(i + 0, j + 1, k + 6, DivineRPGTwilight.cryptWall.blockID);
		world.setBlock(i + 0, j + 1, k + 7, DivineRPGTwilight.cryptWall.blockID);
		world.setBlock(i + 0, j + 1, k + 8, DivineRPGTwilight.cryptWall.blockID);
		world.setBlock(i + 0, j + 1, k + 9, DivineRPGTwilight.dreamdirt.blockID);
		world.setBlock(i + 0, j + 1, k + 10, DivineRPGTwilight.dreamdirt.blockID);
		world.setBlock(i + 0, j + 2, k + 0, DivineRPGTwilight.dreamdirt.blockID);
		world.setBlock(i + 0, j + 2, k + 1, DivineRPGTwilight.dreamdirt.blockID);
		world.setBlock(i + 0, j + 2, k + 2, DivineRPGTwilight.dreamdirt.blockID);
		world.setBlock(i + 0, j + 2, k + 3, DivineRPGTwilight.dreamdirt.blockID);
		world.setBlock(i + 0, j + 2, k + 4, DivineRPGTwilight.cryptWall.blockID);
		world.setBlock(i + 0, j + 2, k + 5, DivineRPGTwilight.cryptWall.blockID);
		world.setBlock(i + 0, j + 2, k + 6, DivineRPGTwilight.cryptWall.blockID);
		world.setBlock(i + 0, j + 2, k + 7, DivineRPGTwilight.cryptWall.blockID);
		world.setBlock(i + 0, j + 2, k + 8, DivineRPGTwilight.cryptWall.blockID);
		world.setBlock(i + 0, j + 2, k + 9, DivineRPGTwilight.dreamdirt.blockID);
		world.setBlock(i + 0, j + 2, k + 10, DivineRPGTwilight.dreamdirt.blockID);
		world.setBlock(i + 0, j + 3, k + 0, DivineRPGTwilight.dreamdirt.blockID);
		world.setBlock(i + 0, j + 3, k + 1, DivineRPGTwilight.dreamdirt.blockID);
		world.setBlock(i + 0, j + 3, k + 2, DivineRPGTwilight.dreamdirt.blockID);
		world.setBlock(i + 0, j + 3, k + 3, DivineRPGTwilight.dreamdirt.blockID);
		world.setBlock(i + 0, j + 3, k + 4, DivineRPGTwilight.hungerstone2.blockID);
		world.setBlock(i + 0, j + 3, k + 5, DivineRPGTwilight.hungerstone2.blockID);
		world.setBlock(i + 0, j + 3, k + 6, DivineRPGTwilight.dreamdirt.blockID);
		world.setBlock(i + 0, j + 3, k + 7, DivineRPGTwilight.dreamdirt.blockID);
		world.setBlock(i + 0, j + 3, k + 8, DivineRPGTwilight.dreamdirt.blockID);
		world.setBlock(i + 0, j + 3, k + 9, DivineRPGTwilight.dreamdirt.blockID);
		world.setBlock(i + 0, j + 3, k + 10, DivineRPGTwilight.dreamdirt.blockID);
		world.setBlock(i + 0, j + 4, k + 0, DivineRPGTwilight.dreamdirt.blockID);
		world.setBlock(i + 0, j + 4, k + 1, DivineRPGTwilight.dreamdirt.blockID);
		world.setBlock(i + 0, j + 4, k + 2, DivineRPGTwilight.dreamdirt.blockID);
		world.setBlock(i + 0, j + 4, k + 3, DivineRPGTwilight.dreamdirt.blockID);
		world.setBlock(i + 0, j + 4, k + 4, DivineRPGTwilight.dreamdirt.blockID);
		world.setBlock(i + 0, j + 4, k + 5, DivineRPGTwilight.dreamdirt.blockID);
		world.setBlock(i + 0, j + 4, k + 6, DivineRPGTwilight.dreamdirt.blockID);
		world.setBlock(i + 0, j + 4, k + 7, DivineRPGTwilight.dreamdirt.blockID);
		world.setBlock(i + 0, j + 4, k + 8, DivineRPGTwilight.dreamdirt.blockID);
		world.setBlock(i + 0, j + 4, k + 9, DivineRPGTwilight.dreamdirt.blockID);
		world.setBlock(i + 0, j + 4, k + 10, DivineRPGTwilight.dreamdirt.blockID);
		world.setBlock(i + 0, j + 5, k + 0, DivineRPGTwilight.metalCaging.blockID);
		world.setBlock(i + 0, j + 5, k + 1, DivineRPGTwilight.metalCaging.blockID);
		world.setBlock(i + 0, j + 5, k + 2, DivineRPGTwilight.metalCaging.blockID);
		world.setBlock(i + 0, j + 5, k + 3, DivineRPGTwilight.metalCaging.blockID);
		world.setBlock(i + 0, j + 5, k + 4, DivineRPGTwilight.metalCaging.blockID);
		world.setBlock(i + 0, j + 5, k + 5, DivineRPGTwilight.metalCaging.blockID);
		world.setBlock(i + 0, j + 5, k + 6, DivineRPGTwilight.metalCaging.blockID);
		world.setBlock(i + 0, j + 5, k + 7, DivineRPGTwilight.metalCaging.blockID);
		world.setBlock(i + 0, j + 5, k + 8, DivineRPGTwilight.metalCaging.blockID);
		world.setBlock(i + 0, j + 5, k + 9, DivineRPGTwilight.metalCaging.blockID);
		world.setBlock(i + 0, j + 5, k + 10, DivineRPGTwilight.metalCaging.blockID);
		world.setBlock(i + 0, j + 6, k + 0, DivineRPGTwilight.hungerstone1.blockID);
		world.setBlock(i + 0, j + 6, k + 1, DivineRPGTwilight.hungerstone1.blockID);
		world.setBlock(i + 0, j + 6, k + 2, DivineRPGTwilight.hungerstone1.blockID);
		world.setBlock(i + 0, j + 6, k + 3, DivineRPGTwilight.hungerstone1.blockID);
		world.setBlock(i + 0, j + 6, k + 4, DivineRPGTwilight.hungerstone1.blockID);
		world.setBlock(i + 0, j + 6, k + 5, DivineRPGTwilight.hungerstone1.blockID);
		world.setBlock(i + 0, j + 6, k + 6, DivineRPGTwilight.hungerstone1.blockID);
		world.setBlock(i + 0, j + 6, k + 7, DivineRPGTwilight.hungerstone1.blockID);
		world.setBlock(i + 0, j + 6, k + 8, DivineRPGTwilight.hungerstone1.blockID);
		world.setBlock(i + 0, j + 6, k + 9, DivineRPGTwilight.hungerstone1.blockID);
		world.setBlock(i + 0, j + 6, k + 10, DivineRPGTwilight.hungerstone1.blockID);
		world.setBlock(i + 0, j + 7, k + 0, 0);
		world.setBlock(i + 0, j + 7, k + 1, 0);
		world.setBlock(i + 0, j + 7, k + 2, 0);
		world.setBlock(i + 0, j + 7, k + 3, 0);
		world.setBlock(i + 0, j + 7, k + 4, 0);
		world.setBlock(i + 0, j + 7, k + 5, 0);
		world.setBlock(i + 0, j + 7, k + 6, 0);
		world.setBlock(i + 0, j + 7, k + 7, 0);
		world.setBlock(i + 0, j + 7, k + 8, 0);
		world.setBlock(i + 0, j + 7, k + 9, 0);
		world.setBlock(i + 0, j + 7, k + 10, 0);
		world.setBlock(i + 0, j + 8, k + 0, 0);
		world.setBlock(i + 0, j + 8, k + 1, 0);
		world.setBlock(i + 0, j + 8, k + 2, 0);
		world.setBlock(i + 0, j + 8, k + 3, 0);
		world.setBlock(i + 0, j + 8, k + 4, 0);
		world.setBlock(i + 0, j + 8, k + 5, 0);
		world.setBlock(i + 0, j + 8, k + 6, 0);
		world.setBlock(i + 0, j + 8, k + 7, 0);
		world.setBlock(i + 0, j + 8, k + 8, 0);
		world.setBlock(i + 0, j + 8, k + 9, 0);
		world.setBlock(i + 0, j + 8, k + 10, 0);
		world.setBlock(i + 0, j + 9, k + 0, 0);
		world.setBlock(i + 0, j + 9, k + 1, 0);
		world.setBlock(i + 0, j + 9, k + 2, 0);
		world.setBlock(i + 0, j + 9, k + 3, 0);
		world.setBlock(i + 0, j + 9, k + 4, 0);
		world.setBlock(i + 0, j + 9, k + 5, 0);
		world.setBlock(i + 0, j + 9, k + 6, 0);
		world.setBlock(i + 0, j + 9, k + 7, 0);
		world.setBlock(i + 0, j + 9, k + 8, 0);
		world.setBlock(i + 0, j + 9, k + 9, 0);
		world.setBlock(i + 0, j + 9, k + 10, 0);
		world.setBlock(i + 0, j + 10, k + 0, 0);
		world.setBlock(i + 0, j + 10, k + 1, 0);
		world.setBlock(i + 0, j + 10, k + 2, 0);
		world.setBlock(i + 0, j + 10, k + 3, 0);
		world.setBlock(i + 0, j + 10, k + 4, 0);
		world.setBlock(i + 0, j + 10, k + 5, 0);
		world.setBlock(i + 0, j + 10, k + 6, 0);
		world.setBlock(i + 0, j + 10, k + 7, 0);
		world.setBlock(i + 0, j + 10, k + 8, 0);
		world.setBlock(i + 0, j + 10, k + 9, 0);
		world.setBlock(i + 0, j + 10, k + 10, 0);
		world.setBlock(i + 1, j + 0, k + 0, DivineRPGTwilight.dreamdirt.blockID);
		world.setBlock(i + 1, j + 0, k + 1, DivineRPGTwilight.dreamdirt.blockID);
		world.setBlock(i + 1, j + 0, k + 2, DivineRPGTwilight.dreamdirt.blockID);
		world.setBlock(i + 1, j + 0, k + 3, DivineRPGTwilight.dreamdirt.blockID);
		world.setBlock(i + 1, j + 0, k + 4, DivineRPGTwilight.cryptFloor.blockID);
		world.setBlock(i + 1, j + 0, k + 5, DivineRPGTwilight.cryptFloor.blockID);
		world.setBlock(i + 1, j + 0, k + 6, DivineRPGTwilight.cryptFloor.blockID);
		world.setBlock(i + 1, j + 0, k + 7, DivineRPGTwilight.cryptFloor.blockID);
		world.setBlock(i + 1, j + 0, k + 8, DivineRPGTwilight.cryptFloor.blockID);
		world.setBlock(i + 1, j + 0, k + 9, DivineRPGTwilight.dreamdirt.blockID);
		world.setBlock(i + 1, j + 0, k + 10, DivineRPGTwilight.dreamdirt.blockID);
		world.setBlock(i + 1, j + 1, k + 0, DivineRPGTwilight.dreamdirt.blockID);
		world.setBlock(i + 1, j + 1, k + 1, DivineRPGTwilight.dreamdirt.blockID);
		world.setBlock(i + 1, j + 1, k + 2, DivineRPGTwilight.dreamdirt.blockID);
		world.setBlock(i + 1, j + 1, k + 3, DivineRPGTwilight.cryptWall.blockID);
		world.setBlock(i + 1, j + 1, k + 4, 0);
		world.setBlock(i + 1, j + 1, k + 5, 0);
		world.setBlock(i + 1, j + 1, k + 6, 0);
		world.setBlock(i + 1, j + 1, k + 7, 0);
		world.setBlock(i + 1, j + 1, k + 8, 0);
		world.setBlock(i + 1, j + 1, k + 9, DivineRPGTwilight.cryptWall.blockID);
		world.setBlock(i + 1, j + 1, k + 10, DivineRPGTwilight.dreamdirt.blockID);
		world.setBlock(i + 1, j + 2, k + 0, DivineRPGTwilight.dreamdirt.blockID);
		world.setBlock(i + 1, j + 2, k + 1, DivineRPGTwilight.dreamdirt.blockID);
		world.setBlock(i + 1, j + 2, k + 2, DivineRPGTwilight.dreamdirt.blockID);
		world.setBlock(i + 1, j + 2, k + 3, DivineRPGTwilight.cryptWall.blockID);
		world.setBlock(i + 1, j + 2, k + 4, 0);
		world.setBlock(i + 1, j + 2, k + 5, 0);
		world.setBlock(i + 1, j + 2, k + 6, 0);
		world.setBlock(i + 1, j + 2, k + 7, 0);
		world.setBlock(i + 1, j + 2, k + 8, 0);
		world.setBlock(i + 1, j + 2, k + 9, DivineRPGTwilight.cryptWall.blockID);
		world.setBlock(i + 1, j + 2, k + 10, DivineRPGTwilight.dreamdirt.blockID);
		world.setBlock(i + 1, j + 3, k + 0, DivineRPGTwilight.dreamdirt.blockID);
		world.setBlock(i + 1, j + 3, k + 1, DivineRPGTwilight.dreamdirt.blockID);
		world.setBlock(i + 1, j + 3, k + 2, DivineRPGTwilight.dreamdirt.blockID);
		world.setBlock(i + 1, j + 3, k + 3, DivineRPGTwilight.hungerstone2.blockID);
		world.setBlock(i + 1, j + 3, k + 4, DivineRPGTwilight.hungerstone2.blockID);
		world.setBlock(i + 1, j + 3, k + 5, DivineRPGTwilight.hungerstone2.blockID);
		world.setBlock(i + 1, j + 3, k + 6, DivineRPGTwilight.hungerstone2.blockID);
		world.setBlock(i + 1, j + 3, k + 7, DivineRPGTwilight.hungerstone2.blockID);
		world.setBlock(i + 1, j + 3, k + 8, DivineRPGTwilight.hungerstone2.blockID);
		world.setBlock(i + 1, j + 3, k + 9, DivineRPGTwilight.dreamdirt.blockID);
		world.setBlock(i + 1, j + 3, k + 10, DivineRPGTwilight.dreamdirt.blockID);
		world.setBlock(i + 1, j + 4, k + 0, DivineRPGTwilight.dreamdirt.blockID);
		world.setBlock(i + 1, j + 4, k + 1, DivineRPGTwilight.dreamdirt.blockID);
		world.setBlock(i + 1, j + 4, k + 2, DivineRPGTwilight.dreamdirt.blockID);
		world.setBlock(i + 1, j + 4, k + 3, DivineRPGTwilight.dreamdirt.blockID);
		world.setBlock(i + 1, j + 4, k + 4, DivineRPGTwilight.dreamdirt.blockID);
		world.setBlock(i + 1, j + 4, k + 5, DivineRPGTwilight.dreamdirt.blockID);
		world.setBlock(i + 1, j + 4, k + 6, DivineRPGTwilight.dreamdirt.blockID);
		world.setBlock(i + 1, j + 4, k + 7, DivineRPGTwilight.dreamdirt.blockID);
		world.setBlock(i + 1, j + 4, k + 8, DivineRPGTwilight.dreamdirt.blockID);
		world.setBlock(i + 1, j + 4, k + 9, DivineRPGTwilight.dreamdirt.blockID);
		world.setBlock(i + 1, j + 4, k + 10, DivineRPGTwilight.dreamdirt.blockID);
		world.setBlock(i + 1, j + 5, k + 0, DivineRPGTwilight.metalCaging.blockID);
		world.setBlock(i + 1, j + 5, k + 1, 0);
		world.setBlock(i + 1, j + 5, k + 2, 0);
		world.setBlock(i + 1, j + 5, k + 3, 0);
		world.setBlock(i + 1, j + 5, k + 4, 0);
		world.setBlock(i + 1, j + 5, k + 5, 0);
		world.setBlock(i + 1, j + 5, k + 6, 0);
		world.setBlock(i + 1, j + 5, k + 7, 0);
		world.setBlock(i + 1, j + 5, k + 8, 0);
		world.setBlock(i + 1, j + 5, k + 9, 0);
		world.setBlock(i + 1, j + 5, k + 10, DivineRPGTwilight.metalCaging.blockID);
		world.setBlock(i + 1, j + 6, k + 0, DivineRPGTwilight.hungerstone1.blockID);
		world.setBlock(i + 1, j + 6, k + 1, 0);
		world.setBlock(i + 1, j + 6, k + 2, 0);
		world.setBlock(i + 1, j + 6, k + 3, 0);
		world.setBlock(i + 1, j + 6, k + 4, 0);
		world.setBlock(i + 1, j + 6, k + 5, 0);
		world.setBlock(i + 1, j + 6, k + 6, 0);
		world.setBlock(i + 1, j + 6, k + 7, 0);
		world.setBlock(i + 1, j + 6, k + 8, 0);
		world.setBlock(i + 1, j + 6, k + 9, 0);
		world.setBlock(i + 1, j + 6, k + 10, DivineRPGTwilight.hungerstone1.blockID);
		world.setBlock(i + 1, j + 7, k + 0, 0);
		world.setBlock(i + 1, j + 7, k + 1, 0);
		world.setBlock(i + 1, j + 7, k + 2, 0);
		world.setBlock(i + 1, j + 7, k + 3, 0);
		world.setBlock(i + 1, j + 7, k + 4, 0);
		world.setBlock(i + 1, j + 7, k + 5, 0);
		world.setBlock(i + 1, j + 7, k + 6, 0);
		world.setBlock(i + 1, j + 7, k + 7, 0);
		world.setBlock(i + 1, j + 7, k + 8, 0);
		world.setBlock(i + 1, j + 7, k + 9, 0);
		world.setBlock(i + 1, j + 7, k + 10, 0);
		world.setBlock(i + 1, j + 8, k + 0, 0);
		world.setBlock(i + 1, j + 8, k + 1, 0);
		world.setBlock(i + 1, j + 8, k + 2, 0);
		world.setBlock(i + 1, j + 8, k + 3, 0);
		world.setBlock(i + 1, j + 8, k + 4, 0);
		world.setBlock(i + 1, j + 8, k + 5, 0);
		world.setBlock(i + 1, j + 8, k + 6, 0);
		world.setBlock(i + 1, j + 8, k + 7, 0);
		world.setBlock(i + 1, j + 8, k + 8, 0);
		world.setBlock(i + 1, j + 8, k + 9, 0);
		world.setBlock(i + 1, j + 8, k + 10, 0);
		world.setBlock(i + 1, j + 9, k + 0, 0);
		world.setBlock(i + 1, j + 9, k + 1, 0);
		world.setBlock(i + 1, j + 9, k + 2, 0);
		world.setBlock(i + 1, j + 9, k + 3, 0);
		world.setBlock(i + 1, j + 9, k + 4, 0);
		world.setBlock(i + 1, j + 9, k + 5, 0);
		world.setBlock(i + 1, j + 9, k + 6, 0);
		world.setBlock(i + 1, j + 9, k + 7, 0);
		world.setBlock(i + 1, j + 9, k + 8, 0);
		world.setBlock(i + 1, j + 9, k + 9, 0);
		world.setBlock(i + 1, j + 9, k + 10, 0);
		world.setBlock(i + 1, j + 10, k + 0, 0);
		world.setBlock(i + 1, j + 10, k + 1, 0);
		world.setBlock(i + 1, j + 10, k + 2, 0);
		world.setBlock(i + 1, j + 10, k + 3, 0);
		world.setBlock(i + 1, j + 10, k + 4, 0);
		world.setBlock(i + 1, j + 10, k + 5, 0);
		world.setBlock(i + 1, j + 10, k + 6, 0);
		world.setBlock(i + 1, j + 10, k + 7, 0);
		world.setBlock(i + 1, j + 10, k + 8, 0);
		world.setBlock(i + 1, j + 10, k + 9, 0);
		world.setBlock(i + 1, j + 10, k + 10, 0);
		world.setBlock(i + 2, j + 0, k + 0, DivineRPGTwilight.dreamdirt.blockID);
		world.setBlock(i + 2, j + 0, k + 1, DivineRPGTwilight.dreamdirt.blockID);
		world.setBlock(i + 2, j + 0, k + 2, DivineRPGTwilight.dreamdirt.blockID);
		world.setBlock(i + 2, j + 0, k + 3, DivineRPGTwilight.dreamdirt.blockID);
		world.setBlock(i + 2, j + 0, k + 4, DivineRPGTwilight.cryptFloor.blockID);
		world.setBlock(i + 2, j + 0, k + 5, DivineRPGTwilight.cryptFloor.blockID);
		world.setBlock(i + 2, j + 0, k + 6, DivineRPGTwilight.cryptFloor.blockID);
		world.setBlock(i + 2, j + 0, k + 7, DivineRPGTwilight.cryptFloor.blockID);
		world.setBlock(i + 2, j + 0, k + 8, DivineRPGTwilight.cryptFloor.blockID);
		world.setBlock(i + 2, j + 0, k + 9, DivineRPGTwilight.dreamdirt.blockID);
		world.setBlock(i + 2, j + 0, k + 10, DivineRPGTwilight.dreamdirt.blockID);
		world.setBlock(i + 2, j + 1, k + 0, DivineRPGTwilight.dreamdirt.blockID);
		world.setBlock(i + 2, j + 1, k + 1, DivineRPGTwilight.dreamdirt.blockID);
		world.setBlock(i + 2, j + 1, k + 2, DivineRPGTwilight.dreamdirt.blockID);
		world.setBlock(i + 2, j + 1, k + 3, DivineRPGTwilight.cryptWall.blockID);
		world.setBlock(i + 2, j + 1, k + 4, 0);
		world.setBlock(i + 2, j + 1, k + 5, 0);
		world.setBlock(i + 2, j + 1, k + 6, 0);
		world.setBlock(i + 2, j + 1, k + 7, 0);
		world.setBlock(i + 2, j + 1, k + 8, 0);
		world.setBlock(i + 2, j + 1, k + 9, DivineRPGTwilight.cryptWall.blockID);
		world.setBlock(i + 2, j + 1, k + 10, DivineRPGTwilight.dreamdirt.blockID);
		world.setBlock(i + 2, j + 2, k + 0, DivineRPGTwilight.dreamdirt.blockID);
		world.setBlock(i + 2, j + 2, k + 1, DivineRPGTwilight.dreamdirt.blockID);
		world.setBlock(i + 2, j + 2, k + 2, DivineRPGTwilight.dreamdirt.blockID);
		world.setBlock(i + 2, j + 2, k + 3, DivineRPGTwilight.cryptWall.blockID);
		world.setBlock(i + 2, j + 2, k + 4, 0);
		world.setBlock(i + 2, j + 2, k + 5, 0);
		world.setBlock(i + 2, j + 2, k + 6, 0);
		world.setBlock(i + 2, j + 2, k + 7, 0);
		world.setBlock(i + 2, j + 2, k + 8, 0);
		world.setBlock(i + 2, j + 2, k + 9, DivineRPGTwilight.cryptWall.blockID);
		world.setBlock(i + 2, j + 2, k + 10, DivineRPGTwilight.dreamdirt.blockID);
		world.setBlock(i + 2, j + 3, k + 0, DivineRPGTwilight.dreamdirt.blockID);
		world.setBlock(i + 2, j + 3, k + 1, DivineRPGTwilight.dreamdirt.blockID);
		world.setBlock(i + 2, j + 3, k + 2, DivineRPGTwilight.dreamdirt.blockID);
		world.setBlock(i + 2, j + 3, k + 3, DivineRPGTwilight.hungerstone2.blockID);
		world.setBlock(i + 2, j + 3, k + 4, 0);
		world.setBlock(i + 2, j + 3, k + 5, 0);
		world.setBlock(i + 2, j + 3, k + 6, DivineRPGTwilight.hungerstone2.blockID);
		world.setBlock(i + 2, j + 3, k + 7, DivineRPGTwilight.hungerstone2.blockID);
		world.setBlock(i + 2, j + 3, k + 8, DivineRPGTwilight.hungerstone2.blockID);
		world.setBlock(i + 2, j + 3, k + 9, DivineRPGTwilight.dreamdirt.blockID);
		world.setBlock(i + 2, j + 3, k + 10, DivineRPGTwilight.dreamdirt.blockID);
		world.setBlock(i + 2, j + 4, k + 0, DivineRPGTwilight.dreamdirt.blockID);
		world.setBlock(i + 2, j + 4, k + 1, DivineRPGTwilight.dreamdirt.blockID);
		world.setBlock(i + 2, j + 4, k + 2, DivineRPGTwilight.dreamdirt.blockID);
		world.setBlock(i + 2, j + 4, k + 3, DivineRPGTwilight.hungerstone2.blockID);
		world.setBlock(i + 2, j + 4, k + 4, DivineRPGTwilight.hungerstone2.blockID);
		world.setBlock(i + 2, j + 4, k + 5, DivineRPGTwilight.hungerstone2.blockID);
		world.setBlock(i + 2, j + 4, k + 6, DivineRPGTwilight.hungerstone2.blockID);
		world.setBlock(i + 2, j + 4, k + 7, DivineRPGTwilight.dreamdirt.blockID);
		world.setBlock(i + 2, j + 4, k + 8, DivineRPGTwilight.dreamdirt.blockID);
		world.setBlock(i + 2, j + 4, k + 9, DivineRPGTwilight.dreamdirt.blockID);
		world.setBlock(i + 2, j + 4, k + 10, DivineRPGTwilight.dreamdirt.blockID);
		world.setBlock(i + 2, j + 5, k + 0, DivineRPGTwilight.metalCaging.blockID);
		world.setBlock(i + 2, j + 5, k + 1, 0);
		world.setBlock(i + 2, j + 5, k + 2, 0);
		world.setBlock(i + 2, j + 5, k + 3, DivineRPGTwilight.hungerstone1.blockID);
		world.setBlock(i + 2, j + 5, k + 4, DivineRPGTwilight.hungerstone1.blockID);
		world.setBlock(i + 2, j + 5, k + 5, DivineRPGTwilight.hungerstone1.blockID);
		world.setBlock(i + 2, j + 5, k + 6, DivineRPGTwilight.hungerstone1.blockID);
		world.setBlock(i + 2, j + 5, k + 7, 0);
		world.setBlock(i + 2, j + 5, k + 8, 0);
		world.setBlock(i + 2, j + 5, k + 9, 0);
		world.setBlock(i + 2, j + 5, k + 10, DivineRPGTwilight.metalCaging.blockID);
		world.setBlock(i + 2, j + 6, k + 0, DivineRPGTwilight.hungerstone1.blockID);
		world.setBlock(i + 2, j + 6, k + 1, 0);
		world.setBlock(i + 2, j + 6, k + 2, 0);
		world.setBlock(i + 2, j + 6, k + 3, DivineRPGTwilight.hungerstone2.blockID);
		world.setBlock(i + 2, j + 6, k + 4, DivineRPGTwilight.hungerstone2.blockID);
		world.setBlock(i + 2, j + 6, k + 5, DivineRPGTwilight.hungerstone2.blockID);
		world.setBlock(i + 2, j + 6, k + 6, DivineRPGTwilight.hungerstone2.blockID);
		world.setBlock(i + 2, j + 6, k + 7, 0);
		world.setBlock(i + 2, j + 6, k + 8, 0);
		world.setBlock(i + 2, j + 6, k + 9, 0);
		world.setBlock(i + 2, j + 6, k + 10, DivineRPGTwilight.hungerstone1.blockID);
		world.setBlock(i + 2, j + 7, k + 0, 0);
		world.setBlock(i + 2, j + 7, k + 1, 0);
		world.setBlock(i + 2, j + 7, k + 2, 0);
		world.setBlock(i + 2, j + 7, k + 3, 0);
		world.setBlock(i + 2, j + 7, k + 4, 0);
		world.setBlock(i + 2, j + 7, k + 5, 0);
		world.setBlock(i + 2, j + 7, k + 6, 0);
		world.setBlock(i + 2, j + 7, k + 7, 0);
		world.setBlock(i + 2, j + 7, k + 8, 0);
		world.setBlock(i + 2, j + 7, k + 9, 0);
		world.setBlock(i + 2, j + 7, k + 10, 0);
		world.setBlock(i + 2, j + 8, k + 0, 0);
		world.setBlock(i + 2, j + 8, k + 1, 0);
		world.setBlock(i + 2, j + 8, k + 2, 0);
		world.setBlock(i + 2, j + 8, k + 3, 0);
		world.setBlock(i + 2, j + 8, k + 4, 0);
		world.setBlock(i + 2, j + 8, k + 5, 0);
		world.setBlock(i + 2, j + 8, k + 6, 0);
		world.setBlock(i + 2, j + 8, k + 7, 0);
		world.setBlock(i + 2, j + 8, k + 8, 0);
		world.setBlock(i + 2, j + 8, k + 9, 0);
		world.setBlock(i + 2, j + 8, k + 10, 0);
		world.setBlock(i + 2, j + 9, k + 0, 0);
		world.setBlock(i + 2, j + 9, k + 1, 0);
		world.setBlock(i + 2, j + 9, k + 2, 0);
		world.setBlock(i + 2, j + 9, k + 3, 0);
		world.setBlock(i + 2, j + 9, k + 4, 0);
		world.setBlock(i + 2, j + 9, k + 5, 0);
		world.setBlock(i + 2, j + 9, k + 6, 0);
		world.setBlock(i + 2, j + 9, k + 7, 0);
		world.setBlock(i + 2, j + 9, k + 8, 0);
		world.setBlock(i + 2, j + 9, k + 9, 0);
		world.setBlock(i + 2, j + 9, k + 10, 0);
		world.setBlock(i + 2, j + 10, k + 0, 0);
		world.setBlock(i + 2, j + 10, k + 1, 0);
		world.setBlock(i + 2, j + 10, k + 2, 0);
		world.setBlock(i + 2, j + 10, k + 3, 0);
		world.setBlock(i + 2, j + 10, k + 4, 0);
		world.setBlock(i + 2, j + 10, k + 5, 0);
		world.setBlock(i + 2, j + 10, k + 6, 0);
		world.setBlock(i + 2, j + 10, k + 7, 0);
		world.setBlock(i + 2, j + 10, k + 8, 0);
		world.setBlock(i + 2, j + 10, k + 9, 0);
		world.setBlock(i + 2, j + 10, k + 10, 0);
		world.setBlock(i + 3, j + 0, k + 0, DivineRPGTwilight.dreamdirt.blockID);
		world.setBlock(i + 3, j + 0, k + 1, DivineRPGTwilight.dreamdirt.blockID);
		world.setBlock(i + 3, j + 0, k + 2, DivineRPGTwilight.dreamdirt.blockID);
		world.setBlock(i + 3, j + 0, k + 3, DivineRPGTwilight.dreamdirt.blockID);
		world.setBlock(i + 3, j + 0, k + 4, DivineRPGTwilight.cryptFloor.blockID);
		world.setBlock(i + 3, j + 0, k + 5, DivineRPGTwilight.cryptFloor.blockID);
		world.setBlock(i + 3, j + 0, k + 6, DivineRPGTwilight.dreamdirt.blockID);
		world.setBlock(i + 3, j + 0, k + 7, DivineRPGTwilight.cryptFloor.blockID);
		world.setBlock(i + 3, j + 0, k + 8, DivineRPGTwilight.cryptFloor.blockID);
		world.setBlock(i + 3, j + 0, k + 9, DivineRPGTwilight.dreamdirt.blockID);
		world.setBlock(i + 3, j + 0, k + 10, DivineRPGTwilight.dreamdirt.blockID);
		world.setBlock(i + 3, j + 1, k + 0, DivineRPGTwilight.dreamdirt.blockID);
		world.setBlock(i + 3, j + 1, k + 1, DivineRPGTwilight.dreamdirt.blockID);
		world.setBlock(i + 3, j + 1, k + 2, DivineRPGTwilight.dreamdirt.blockID);
		world.setBlock(i + 3, j + 1, k + 3, DivineRPGTwilight.cryptWall.blockID);
		world.setBlock(i + 3, j + 1, k + 4, 0);
		world.setBlock(i + 3, j + 1, k + 5, 0);
		world.setBlock(i + 3, j + 1, k + 6, DivineRPGTwilight.cryptWall.blockID);
		world.setBlock(i + 3, j + 1, k + 7, 0);
		world.setBlock(i + 3, j + 1, k + 8, 0);
		world.setBlock(i + 3, j + 1, k + 9, DivineRPGTwilight.cryptWall.blockID);
		world.setBlock(i + 3, j + 1, k + 10, DivineRPGTwilight.dreamdirt.blockID);
		world.setBlock(i + 3, j + 2, k + 0, DivineRPGTwilight.dreamdirt.blockID);
		world.setBlock(i + 3, j + 2, k + 1, DivineRPGTwilight.dreamdirt.blockID);
		world.setBlock(i + 3, j + 2, k + 2, DivineRPGTwilight.dreamdirt.blockID);
		world.setBlock(i + 3, j + 2, k + 3, DivineRPGTwilight.cryptWall.blockID);
		world.setBlock(i + 3, j + 2, k + 4, 0);
		world.setBlock(i + 3, j + 2, k + 5, 0);
		world.setBlock(i + 3, j + 2, k + 6, DivineRPGTwilight.cryptWall.blockID);
		world.setBlock(i + 3, j + 2, k + 7, 0);
		world.setBlock(i + 3, j + 2, k + 8, 0);
		world.setBlock(i + 3, j + 2, k + 9, DivineRPGTwilight.cryptWall.blockID);
		world.setBlock(i + 3, j + 2, k + 10, DivineRPGTwilight.dreamdirt.blockID);
		world.setBlock(i + 3, j + 3, k + 0, DivineRPGTwilight.dreamdirt.blockID);
		world.setBlock(i + 3, j + 3, k + 1, DivineRPGTwilight.dreamdirt.blockID);
		world.setBlock(i + 3, j + 3, k + 2, DivineRPGTwilight.dreamdirt.blockID);
		world.setBlock(i + 3, j + 3, k + 3, DivineRPGTwilight.hungerstone2.blockID);
		world.setBlock(i + 3, j + 3, k + 4, 0);
		world.setBlock(i + 3, j + 3, k + 5, 0);
		world.setBlock(i + 3, j + 3, k + 6, DivineRPGTwilight.hungerstone2.blockID);
		world.setBlock(i + 3, j + 3, k + 7, DivineRPGTwilight.hungerstone2.blockID);
		world.setBlock(i + 3, j + 3, k + 8, DivineRPGTwilight.hungerstone2.blockID);
		world.setBlock(i + 3, j + 3, k + 9, DivineRPGTwilight.dreamdirt.blockID);
		world.setBlock(i + 3, j + 3, k + 10, DivineRPGTwilight.dreamdirt.blockID);
		world.setBlock(i + 3, j + 4, k + 0, DivineRPGTwilight.dreamdirt.blockID);
		world.setBlock(i + 3, j + 4, k + 1, DivineRPGTwilight.dreamdirt.blockID);
		world.setBlock(i + 3, j + 4, k + 2, DivineRPGTwilight.dreamdirt.blockID);
		world.setBlock(i + 3, j + 4, k + 3, DivineRPGTwilight.hungerstone2.blockID);
		world.setBlock(i + 3, j + 4, k + 4, 0);
		world.setBlock(i + 3, j + 4, k + 5, 0);
		world.setBlock(i + 3, j + 4, k + 6, DivineRPGTwilight.hungerstone2.blockID);
		world.setBlock(i + 3, j + 4, k + 7, DivineRPGTwilight.dreamdirt.blockID);
		world.setBlock(i + 3, j + 4, k + 8, DivineRPGTwilight.dreamdirt.blockID);
		world.setBlock(i + 3, j + 4, k + 9, DivineRPGTwilight.dreamdirt.blockID);
		world.setBlock(i + 3, j + 4, k + 10, DivineRPGTwilight.dreamdirt.blockID);
		world.setBlock(i + 3, j + 5, k + 0, DivineRPGTwilight.metalCaging.blockID);
		world.setBlock(i + 3, j + 5, k + 1, 0);
		world.setBlock(i + 3, j + 5, k + 2, 0);
		world.setBlock(i + 3, j + 5, k + 3, DivineRPGTwilight.hungerstone1.blockID);
		world.setBlock(i + 3, j + 5, k + 4, 0);
		world.setBlock(i + 3, j + 5, k + 5, 0);
		world.setBlock(i + 3, j + 5, k + 6, DivineRPGTwilight.hungerstone1.blockID);
		world.setBlock(i + 3, j + 5, k + 7, 0);
		world.setBlock(i + 3, j + 5, k + 8, 0);
		world.setBlock(i + 3, j + 5, k + 9, 0);
		world.setBlock(i + 3, j + 5, k + 10, DivineRPGTwilight.metalCaging.blockID);
		world.setBlock(i + 3, j + 6, k + 0, DivineRPGTwilight.hungerstone1.blockID);
		world.setBlock(i + 3, j + 6, k + 1, 0);
		world.setBlock(i + 3, j + 6, k + 2, 0);
		world.setBlock(i + 3, j + 6, k + 3, DivineRPGTwilight.hungerstone2.blockID);
		world.setBlock(i + 3, j + 6, k + 4, 0);
		world.setBlock(i + 3, j + 6, k + 5, 0);
		world.setBlock(i + 3, j + 6, k + 6, DivineRPGTwilight.hungerstone2.blockID);
		world.setBlock(i + 3, j + 6, k + 7, 0);
		world.setBlock(i + 3, j + 6, k + 8, 0);
		world.setBlock(i + 3, j + 6, k + 9, 0);
		world.setBlock(i + 3, j + 6, k + 10, DivineRPGTwilight.hungerstone1.blockID);
		world.setBlock(i + 3, j + 7, k + 0, 0);
		world.setBlock(i + 3, j + 7, k + 1, 0);
		world.setBlock(i + 3, j + 7, k + 2, 0);
		world.setBlock(i + 3, j + 7, k + 3, 0);
		world.setBlock(i + 3, j + 7, k + 4, DivineRPGTwilight.hungerstone1.blockID);
		world.setBlock(i + 3, j + 7, k + 5, DivineRPGTwilight.hungerstone1.blockID);
		world.setBlock(i + 3, j + 7, k + 6, 0);
		world.setBlock(i + 3, j + 7, k + 7, 0);
		world.setBlock(i + 3, j + 7, k + 8, 0);
		world.setBlock(i + 3, j + 7, k + 9, 0);
		world.setBlock(i + 3, j + 7, k + 10, 0);
		world.setBlock(i + 3, j + 8, k + 0, 0);
		world.setBlock(i + 3, j + 8, k + 1, 0);
		world.setBlock(i + 3, j + 8, k + 2, 0);
		world.setBlock(i + 3, j + 8, k + 3, 0);
		world.setBlock(i + 3, j + 8, k + 4, 0);
		world.setBlock(i + 3, j + 8, k + 5, 0);
		world.setBlock(i + 3, j + 8, k + 6, 0);
		world.setBlock(i + 3, j + 8, k + 7, 0);
		world.setBlock(i + 3, j + 8, k + 8, 0);
		world.setBlock(i + 3, j + 8, k + 9, 0);
		world.setBlock(i + 3, j + 8, k + 10, 0);
		world.setBlock(i + 3, j + 9, k + 0, 0);
		world.setBlock(i + 3, j + 9, k + 1, 0);
		world.setBlock(i + 3, j + 9, k + 2, 0);
		world.setBlock(i + 3, j + 9, k + 3, 0);
		world.setBlock(i + 3, j + 9, k + 4, 0);
		world.setBlock(i + 3, j + 9, k + 5, 0);
		world.setBlock(i + 3, j + 9, k + 6, 0);
		world.setBlock(i + 3, j + 9, k + 7, 0);
		world.setBlock(i + 3, j + 9, k + 8, 0);
		world.setBlock(i + 3, j + 9, k + 9, 0);
		world.setBlock(i + 3, j + 9, k + 10, 0);
		world.setBlock(i + 3, j + 10, k + 0, 0);
		world.setBlock(i + 3, j + 10, k + 1, 0);
		world.setBlock(i + 3, j + 10, k + 2, 0);
		world.setBlock(i + 3, j + 10, k + 3, 0);
		world.setBlock(i + 3, j + 10, k + 4, 0);
		world.setBlock(i + 3, j + 10, k + 5, 0);
		world.setBlock(i + 3, j + 10, k + 6, 0);
		world.setBlock(i + 3, j + 10, k + 7, 0);
		world.setBlock(i + 3, j + 10, k + 8, 0);
		world.setBlock(i + 3, j + 10, k + 9, 0);
		world.setBlock(i + 3, j + 10, k + 10, 0);
		world.setBlock(i + 4, j + 0, k + 0, DivineRPGTwilight.dreamdirt.blockID);
		world.setBlock(i + 4, j + 0, k + 1, DivineRPGTwilight.dreamdirt.blockID);
		world.setBlock(i + 4, j + 0, k + 2, DivineRPGTwilight.dreamdirt.blockID);
		world.setBlock(i + 4, j + 0, k + 3, DivineRPGTwilight.dreamdirt.blockID);
		world.setBlock(i + 4, j + 0, k + 4, DivineRPGTwilight.dreamdirt.blockID);
		world.setBlock(i + 4, j + 0, k + 5, DivineRPGTwilight.dreamdirt.blockID);
		world.setBlock(i + 4, j + 0, k + 6, DivineRPGTwilight.dreamdirt.blockID);
		world.setBlock(i + 4, j + 0, k + 7, DivineRPGTwilight.cryptFloor.blockID);
		world.setBlock(i + 4, j + 0, k + 8, DivineRPGTwilight.cryptFloor.blockID);
		world.setBlock(i + 4, j + 0, k + 9, DivineRPGTwilight.dreamdirt.blockID);
		world.setBlock(i + 4, j + 0, k + 10, DivineRPGTwilight.dreamdirt.blockID);
		world.setBlock(i + 4, j + 1, k + 0, DivineRPGTwilight.dreamdirt.blockID);
		world.setBlock(i + 4, j + 1, k + 1, DivineRPGTwilight.dreamdirt.blockID);
		world.setBlock(i + 4, j + 1, k + 2, DivineRPGTwilight.dreamdirt.blockID);
		world.setBlock(i + 4, j + 1, k + 3, DivineRPGTwilight.cryptWall.blockID);
		world.setBlock(i + 4, j + 1, k + 4, DivineRPGTwilight.cryptWall.blockID);
		world.setBlock(i + 4, j + 1, k + 5, DivineRPGTwilight.cryptWall.blockID);
		world.setBlock(i + 4, j + 1, k + 6, DivineRPGTwilight.cryptWall.blockID);
		world.setBlock(i + 4, j + 1, k + 7, 0);
		world.setBlock(i + 4, j + 1, k + 8, 0);
		world.setBlock(i + 4, j + 1, k + 9, DivineRPGTwilight.cryptWall.blockID);
		world.setBlock(i + 4, j + 1, k + 10, DivineRPGTwilight.dreamdirt.blockID);
		world.setBlock(i + 4, j + 2, k + 0, DivineRPGTwilight.dreamdirt.blockID);
		world.setBlock(i + 4, j + 2, k + 1, DivineRPGTwilight.dreamdirt.blockID);
		world.setBlock(i + 4, j + 2, k + 2, DivineRPGTwilight.dreamdirt.blockID);
		world.setBlock(i + 4, j + 2, k + 3, DivineRPGTwilight.cryptWall.blockID);
		world.setBlock(i + 4, j + 2, k + 4, 0);
		world.setBlock(i + 4, j + 2, k + 5, 0);
		world.setBlock(i + 4, j + 2, k + 6, DivineRPGTwilight.cryptWall.blockID);
		world.setBlock(i + 4, j + 2, k + 7, 0);
		world.setBlock(i + 4, j + 2, k + 8, 0);
		world.setBlock(i + 4, j + 2, k + 9, DivineRPGTwilight.cryptWall.blockID);
		world.setBlock(i + 4, j + 2, k + 10, DivineRPGTwilight.dreamdirt.blockID);
		world.setBlock(i + 4, j + 3, k + 0, DivineRPGTwilight.dreamdirt.blockID);
		world.setBlock(i + 4, j + 3, k + 1, DivineRPGTwilight.dreamdirt.blockID);
		world.setBlock(i + 4, j + 3, k + 2, DivineRPGTwilight.dreamdirt.blockID);
		world.setBlock(i + 4, j + 3, k + 3, DivineRPGTwilight.hungerstone2.blockID);
		world.setBlock(i + 4, j + 3, k + 4, 0);
		world.setBlock(i + 4, j + 3, k + 5, 0);
		world.setBlock(i + 4, j + 3, k + 6, DivineRPGTwilight.hungerstone2.blockID);
		world.setBlock(i + 4, j + 3, k + 7, DivineRPGTwilight.hungerstone2.blockID);
		world.setBlock(i + 4, j + 3, k + 8, DivineRPGTwilight.hungerstone2.blockID);
		world.setBlock(i + 4, j + 3, k + 9, DivineRPGTwilight.dreamdirt.blockID);
		world.setBlock(i + 4, j + 3, k + 10, DivineRPGTwilight.dreamdirt.blockID);
		world.setBlock(i + 4, j + 4, k + 0, DivineRPGTwilight.dreamdirt.blockID);
		world.setBlock(i + 4, j + 4, k + 1, DivineRPGTwilight.dreamdirt.blockID);
		world.setBlock(i + 4, j + 4, k + 2, DivineRPGTwilight.dreamdirt.blockID);
		world.setBlock(i + 4, j + 4, k + 3, DivineRPGTwilight.hungerstone2.blockID);
		world.setBlock(i + 4, j + 4, k + 4, 0);
		world.setBlock(i + 4, j + 4, k + 5, 0);
		world.setBlock(i + 4, j + 4, k + 6, DivineRPGTwilight.hungerstone2.blockID);
		world.setBlock(i + 4, j + 4, k + 7, DivineRPGTwilight.dreamdirt.blockID);
		world.setBlock(i + 4, j + 4, k + 8, DivineRPGTwilight.dreamdirt.blockID);
		world.setBlock(i + 4, j + 4, k + 9, DivineRPGTwilight.dreamdirt.blockID);
		world.setBlock(i + 4, j + 4, k + 10, DivineRPGTwilight.dreamdirt.blockID);
		world.setBlock(i + 4, j + 5, k + 0, DivineRPGTwilight.metalCaging.blockID);
		world.setBlock(i + 4, j + 5, k + 1, 0);
		world.setBlock(i + 4, j + 5, k + 2, 0);
		world.setBlock(i + 4, j + 5, k + 3, DivineRPGTwilight.hungerstone1.blockID);
		world.setBlock(i + 4, j + 5, k + 4, 0);
		world.setBlock(i + 4, j + 5, k + 5, 0);
		world.setBlock(i + 4, j + 5, k + 6, DivineRPGTwilight.hungerstone1.blockID);
		world.setBlock(i + 4, j + 5, k + 7, 0);
		world.setBlock(i + 4, j + 5, k + 8, 0);
		world.setBlock(i + 4, j + 5, k + 9, 0);
		world.setBlock(i + 4, j + 5, k + 10, DivineRPGTwilight.metalCaging.blockID);
		world.setBlock(i + 4, j + 6, k + 0, DivineRPGTwilight.hungerstone1.blockID);
		world.setBlock(i + 4, j + 6, k + 1, 0);
		world.setBlock(i + 4, j + 6, k + 2, 0);
		world.setBlock(i + 4, j + 6, k + 3, DivineRPGTwilight.hungerstone2.blockID);
		world.setBlock(i + 4, j + 6, k + 4, 0);
		world.setBlock(i + 4, j + 6, k + 5, 0);
		world.setBlock(i + 4, j + 6, k + 6, DivineRPGTwilight.hungerstone2.blockID);
		world.setBlock(i + 4, j + 6, k + 7, 0);
		world.setBlock(i + 4, j + 6, k + 8, 0);
		world.setBlock(i + 4, j + 6, k + 9, 0);
		world.setBlock(i + 4, j + 6, k + 10, DivineRPGTwilight.hungerstone1.blockID);
		world.setBlock(i + 4, j + 7, k + 0, 0);
		world.setBlock(i + 4, j + 7, k + 1, 0);
		world.setBlock(i + 4, j + 7, k + 2, 0);
		world.setBlock(i + 4, j + 7, k + 3, 0);
		world.setBlock(i + 4, j + 7, k + 4, DivineRPGTwilight.hungerstone1.blockID);
		world.setBlock(i + 4, j + 7, k + 5, DivineRPGTwilight.hungerstone1.blockID);
		world.setBlock(i + 4, j + 7, k + 6, 0);
		world.setBlock(i + 4, j + 7, k + 7, 0);
		world.setBlock(i + 4, j + 7, k + 8, 0);
		world.setBlock(i + 4, j + 7, k + 9, 0);
		world.setBlock(i + 4, j + 7, k + 10, 0);
		world.setBlock(i + 4, j + 8, k + 0, 0);
		world.setBlock(i + 4, j + 8, k + 1, 0);
		world.setBlock(i + 4, j + 8, k + 2, 0);
		world.setBlock(i + 4, j + 8, k + 3, 0);
		world.setBlock(i + 4, j + 8, k + 4, 0);
		world.setBlock(i + 4, j + 8, k + 5, 0);
		world.setBlock(i + 4, j + 8, k + 6, 0);
		world.setBlock(i + 4, j + 8, k + 7, 0);
		world.setBlock(i + 4, j + 8, k + 8, 0);
		world.setBlock(i + 4, j + 8, k + 9, 0);
		world.setBlock(i + 4, j + 8, k + 10, 0);
		world.setBlock(i + 4, j + 9, k + 0, 0);
		world.setBlock(i + 4, j + 9, k + 1, 0);
		world.setBlock(i + 4, j + 9, k + 2, 0);
		world.setBlock(i + 4, j + 9, k + 3, 0);
		world.setBlock(i + 4, j + 9, k + 4, 0);
		world.setBlock(i + 4, j + 9, k + 5, 0);
		world.setBlock(i + 4, j + 9, k + 6, 0);
		world.setBlock(i + 4, j + 9, k + 7, 0);
		world.setBlock(i + 4, j + 9, k + 8, 0);
		world.setBlock(i + 4, j + 9, k + 9, 0);
		world.setBlock(i + 4, j + 9, k + 10, 0);
		world.setBlock(i + 4, j + 10, k + 0, 0);
		world.setBlock(i + 4, j + 10, k + 1, 0);
		world.setBlock(i + 4, j + 10, k + 2, 0);
		world.setBlock(i + 4, j + 10, k + 3, 0);
		world.setBlock(i + 4, j + 10, k + 4, 0);
		world.setBlock(i + 4, j + 10, k + 5, 0);
		world.setBlock(i + 4, j + 10, k + 6, 0);
		world.setBlock(i + 4, j + 10, k + 7, 0);
		world.setBlock(i + 4, j + 10, k + 8, 0);
		world.setBlock(i + 4, j + 10, k + 9, 0);
		world.setBlock(i + 4, j + 10, k + 10, 0);
		world.setBlock(i + 5, j + 0, k + 0, DivineRPGTwilight.dreamdirt.blockID);
		world.setBlock(i + 5, j + 0, k + 1, DivineRPGTwilight.dreamdirt.blockID);
		world.setBlock(i + 5, j + 0, k + 2, DivineRPGTwilight.dreamdirt.blockID);
		world.setBlock(i + 5, j + 0, k + 3, DivineRPGTwilight.dreamdirt.blockID);
		world.setBlock(i + 5, j + 0, k + 4, DivineRPGTwilight.dreamdirt.blockID);
		world.setBlock(i + 5, j + 0, k + 5, DivineRPGTwilight.dreamdirt.blockID);
		world.setBlock(i + 5, j + 0, k + 6, DivineRPGTwilight.dreamdirt.blockID);
		world.setBlock(i + 5, j + 0, k + 7, DivineRPGTwilight.cryptFloor.blockID);
		world.setBlock(i + 5, j + 0, k + 8, DivineRPGTwilight.cryptFloor.blockID);
		world.setBlock(i + 5, j + 0, k + 9, DivineRPGTwilight.dreamdirt.blockID);
		world.setBlock(i + 5, j + 0, k + 10, DivineRPGTwilight.dreamdirt.blockID);
		world.setBlock(i + 5, j + 1, k + 0, DivineRPGTwilight.dreamdirt.blockID);
		world.setBlock(i + 5, j + 1, k + 1, DivineRPGTwilight.dreamdirt.blockID);
		world.setBlock(i + 5, j + 1, k + 2, DivineRPGTwilight.dreamdirt.blockID);
		world.setBlock(i + 5, j + 1, k + 3, DivineRPGTwilight.dreamdirt.blockID);
		world.setBlock(i + 5, j + 1, k + 4, DivineRPGTwilight.dreamdirt.blockID);
		world.setBlock(i + 5, j + 1, k + 5, DivineRPGTwilight.dreamdirt.blockID);
		world.setBlock(i + 5, j + 1, k + 6, DivineRPGTwilight.cryptWall.blockID);
		world.setBlock(i + 5, j + 1, k + 7, 0);
		world.setBlock(i + 5, j + 1, k + 8, 0);
		world.setBlock(i + 5, j + 1, k + 9, DivineRPGTwilight.cryptWall.blockID);
		world.setBlock(i + 5, j + 1, k + 10, DivineRPGTwilight.dreamdirt.blockID);
		world.setBlock(i + 5, j + 2, k + 0, DivineRPGTwilight.dreamdirt.blockID);
		world.setBlock(i + 5, j + 2, k + 1, DivineRPGTwilight.dreamdirt.blockID);
		world.setBlock(i + 5, j + 2, k + 2, DivineRPGTwilight.dreamdirt.blockID);
		world.setBlock(i + 5, j + 2, k + 3, DivineRPGTwilight.cryptWall.blockID);
		world.setBlock(i + 5, j + 2, k + 4, DivineRPGTwilight.cryptWall.blockID);
		world.setBlock(i + 5, j + 2, k + 5, DivineRPGTwilight.cryptWall.blockID);
		world.setBlock(i + 5, j + 2, k + 6, DivineRPGTwilight.cryptWall.blockID);
		world.setBlock(i + 5, j + 2, k + 7, 0);
		world.setBlock(i + 5, j + 2, k + 8, 0);
		world.setBlock(i + 5, j + 2, k + 9, DivineRPGTwilight.cryptWall.blockID);
		world.setBlock(i + 5, j + 2, k + 10, DivineRPGTwilight.dreamdirt.blockID);
		world.setBlock(i + 5, j + 3, k + 0, DivineRPGTwilight.dreamdirt.blockID);
		world.setBlock(i + 5, j + 3, k + 1, DivineRPGTwilight.dreamdirt.blockID);
		world.setBlock(i + 5, j + 3, k + 2, DivineRPGTwilight.dreamdirt.blockID);
		world.setBlock(i + 5, j + 3, k + 3, DivineRPGTwilight.hungerstone2.blockID);
		world.setBlock(i + 5, j + 3, k + 4, 0);
		world.setBlock(i + 5, j + 3, k + 5, 0);
		world.setBlock(i + 5, j + 3, k + 6, DivineRPGTwilight.hungerstone2.blockID);
		world.setBlock(i + 5, j + 3, k + 7, DivineRPGTwilight.hungerstone2.blockID);
		world.setBlock(i + 5, j + 3, k + 8, DivineRPGTwilight.hungerstone2.blockID);
		world.setBlock(i + 5, j + 3, k + 9, DivineRPGTwilight.dreamdirt.blockID);
		world.setBlock(i + 5, j + 3, k + 10, DivineRPGTwilight.dreamdirt.blockID);
		world.setBlock(i + 5, j + 4, k + 0, DivineRPGTwilight.dreamdirt.blockID);
		world.setBlock(i + 5, j + 4, k + 1, DivineRPGTwilight.dreamdirt.blockID);
		world.setBlock(i + 5, j + 4, k + 2, DivineRPGTwilight.dreamdirt.blockID);
		world.setBlock(i + 5, j + 4, k + 3, DivineRPGTwilight.hungerstone2.blockID);
		world.setBlock(i + 5, j + 4, k + 4, 0);
		world.setBlock(i + 5, j + 4, k + 5, 0);
		world.setBlock(i + 5, j + 4, k + 6, DivineRPGTwilight.hungerstone2.blockID);
		world.setBlock(i + 5, j + 4, k + 7, DivineRPGTwilight.dreamdirt.blockID);
		world.setBlock(i + 5, j + 4, k + 8, DivineRPGTwilight.dreamdirt.blockID);
		world.setBlock(i + 5, j + 4, k + 9, DivineRPGTwilight.dreamdirt.blockID);
		world.setBlock(i + 5, j + 4, k + 10, DivineRPGTwilight.dreamdirt.blockID);
		world.setBlock(i + 5, j + 5, k + 0, DivineRPGTwilight.metalCaging.blockID);
		world.setBlock(i + 5, j + 5, k + 1, 0);
		world.setBlock(i + 5, j + 5, k + 2, 0);
		world.setBlock(i + 5, j + 5, k + 3, DivineRPGTwilight.hungerstone1.blockID);
		world.setBlock(i + 5, j + 5, k + 4, 0);
		world.setBlock(i + 5, j + 5, k + 5, 0);
		world.setBlock(i + 5, j + 5, k + 6, DivineRPGTwilight.hungerstone1.blockID);
		world.setBlock(i + 5, j + 5, k + 7, 0);
		world.setBlock(i + 5, j + 5, k + 8, 0);
		world.setBlock(i + 5, j + 5, k + 9, 0);
		world.setBlock(i + 5, j + 5, k + 10, DivineRPGTwilight.metalCaging.blockID);
		world.setBlock(i + 5, j + 6, k + 0, DivineRPGTwilight.hungerstone1.blockID);
		world.setBlock(i + 5, j + 6, k + 1, 0);
		world.setBlock(i + 5, j + 6, k + 2, 0);
		world.setBlock(i + 5, j + 6, k + 3, DivineRPGTwilight.hungerstone2.blockID);
		world.setBlock(i + 5, j + 6, k + 4, 0);
		world.setBlock(i + 5, j + 6, k + 5, 0);
		world.setBlock(i + 5, j + 6, k + 6, DivineRPGTwilight.hungerstone2.blockID);
		world.setBlock(i + 5, j + 6, k + 7, 0);
		world.setBlock(i + 5, j + 6, k + 8, 0);
		world.setBlock(i + 5, j + 6, k + 9, 0);
		world.setBlock(i + 5, j + 6, k + 10, DivineRPGTwilight.hungerstone1.blockID);
		world.setBlock(i + 5, j + 7, k + 0, 0);
		world.setBlock(i + 5, j + 7, k + 1, 0);
		world.setBlock(i + 5, j + 7, k + 2, 0);
		world.setBlock(i + 5, j + 7, k + 3, 0);
		world.setBlock(i + 5, j + 7, k + 4, DivineRPGTwilight.hungerstone1.blockID);
		world.setBlock(i + 5, j + 7, k + 5, DivineRPGTwilight.hungerstone1.blockID);
		world.setBlock(i + 5, j + 7, k + 6, 0);
		world.setBlock(i + 5, j + 7, k + 7, 0);
		world.setBlock(i + 5, j + 7, k + 8, 0);
		world.setBlock(i + 5, j + 7, k + 9, 0);
		world.setBlock(i + 5, j + 7, k + 10, 0);
		world.setBlock(i + 5, j + 8, k + 0, 0);
		world.setBlock(i + 5, j + 8, k + 1, 0);
		world.setBlock(i + 5, j + 8, k + 2, 0);
		world.setBlock(i + 5, j + 8, k + 3, 0);
		world.setBlock(i + 5, j + 8, k + 4, 0);
		world.setBlock(i + 5, j + 8, k + 5, 0);
		world.setBlock(i + 5, j + 8, k + 6, 0);
		world.setBlock(i + 5, j + 8, k + 7, 0);
		world.setBlock(i + 5, j + 8, k + 8, 0);
		world.setBlock(i + 5, j + 8, k + 9, 0);
		world.setBlock(i + 5, j + 8, k + 10, 0);
		world.setBlock(i + 5, j + 9, k + 0, 0);
		world.setBlock(i + 5, j + 9, k + 1, 0);
		world.setBlock(i + 5, j + 9, k + 2, 0);
		world.setBlock(i + 5, j + 9, k + 3, 0);
		world.setBlock(i + 5, j + 9, k + 4, 0);
		world.setBlock(i + 5, j + 9, k + 5, 0);
		world.setBlock(i + 5, j + 9, k + 6, 0);
		world.setBlock(i + 5, j + 9, k + 7, 0);
		world.setBlock(i + 5, j + 9, k + 8, 0);
		world.setBlock(i + 5, j + 9, k + 9, 0);
		world.setBlock(i + 5, j + 9, k + 10, 0);
		world.setBlock(i + 5, j + 10, k + 0, 0);
		world.setBlock(i + 5, j + 10, k + 1, 0);
		world.setBlock(i + 5, j + 10, k + 2, 0);
		world.setBlock(i + 5, j + 10, k + 3, 0);
		world.setBlock(i + 5, j + 10, k + 4, 0);
		world.setBlock(i + 5, j + 10, k + 5, 0);
		world.setBlock(i + 5, j + 10, k + 6, 0);
		world.setBlock(i + 5, j + 10, k + 7, 0);
		world.setBlock(i + 5, j + 10, k + 8, 0);
		world.setBlock(i + 5, j + 10, k + 9, 0);
		world.setBlock(i + 5, j + 10, k + 10, 0);
		world.setBlock(i + 6, j + 0, k + 0, DivineRPGTwilight.dreamdirt.blockID);
		world.setBlock(i + 6, j + 0, k + 1, DivineRPGTwilight.dreamdirt.blockID);
		world.setBlock(i + 6, j + 0, k + 2, DivineRPGTwilight.dreamdirt.blockID);
		world.setBlock(i + 6, j + 0, k + 3, DivineRPGTwilight.dreamdirt.blockID);
		world.setBlock(i + 6, j + 0, k + 4, DivineRPGTwilight.dreamdirt.blockID);
		world.setBlock(i + 6, j + 0, k + 5, DivineRPGTwilight.dreamdirt.blockID);
		world.setBlock(i + 6, j + 0, k + 6, DivineRPGTwilight.dreamdirt.blockID);
		world.setBlock(i + 6, j + 0, k + 7, DivineRPGTwilight.cryptFloor.blockID);
		world.setBlock(i + 6, j + 0, k + 8, DivineRPGTwilight.cryptFloor.blockID);
		world.setBlock(i + 6, j + 0, k + 9, DivineRPGTwilight.dreamdirt.blockID);
		world.setBlock(i + 6, j + 0, k + 10, DivineRPGTwilight.dreamdirt.blockID);
		world.setBlock(i + 6, j + 1, k + 0, DivineRPGTwilight.dreamdirt.blockID);
		world.setBlock(i + 6, j + 1, k + 1, DivineRPGTwilight.dreamdirt.blockID);
		world.setBlock(i + 6, j + 1, k + 2, DivineRPGTwilight.dreamdirt.blockID);
		world.setBlock(i + 6, j + 1, k + 3, DivineRPGTwilight.dreamdirt.blockID);
		world.setBlock(i + 6, j + 1, k + 4, DivineRPGTwilight.dreamdirt.blockID);
		world.setBlock(i + 6, j + 1, k + 5, DivineRPGTwilight.dreamdirt.blockID);
		world.setBlock(i + 6, j + 1, k + 6, DivineRPGTwilight.cryptWall.blockID);
		world.setBlock(i + 6, j + 1, k + 7, 0);
		world.setBlock(i + 6, j + 1, k + 8, 0);
		world.setBlock(i + 6, j + 1, k + 9, DivineRPGTwilight.cryptWall.blockID);
		world.setBlock(i + 6, j + 1, k + 10, DivineRPGTwilight.dreamdirt.blockID);
		world.setBlock(i + 6, j + 2, k + 0, DivineRPGTwilight.dreamdirt.blockID);
		world.setBlock(i + 6, j + 2, k + 1, DivineRPGTwilight.dreamdirt.blockID);
		world.setBlock(i + 6, j + 2, k + 2, DivineRPGTwilight.dreamdirt.blockID);
		world.setBlock(i + 6, j + 2, k + 3, DivineRPGTwilight.dreamdirt.blockID);
		world.setBlock(i + 6, j + 2, k + 4, DivineRPGTwilight.dreamdirt.blockID);
		world.setBlock(i + 6, j + 2, k + 5, DivineRPGTwilight.dreamdirt.blockID);
		world.setBlock(i + 6, j + 2, k + 6, DivineRPGTwilight.cryptWall.blockID);
		world.setBlock(i + 6, j + 2, k + 7, 0);
		world.setBlock(i + 6, j + 2, k + 8, 0);
		world.setBlock(i + 6, j + 2, k + 9, DivineRPGTwilight.cryptWall.blockID);
		world.setBlock(i + 6, j + 2, k + 10, DivineRPGTwilight.dreamdirt.blockID);
		world.setBlock(i + 6, j + 3, k + 0, DivineRPGTwilight.dreamdirt.blockID);
		world.setBlock(i + 6, j + 3, k + 1, DivineRPGTwilight.dreamdirt.blockID);
		world.setBlock(i + 6, j + 3, k + 2, DivineRPGTwilight.dreamdirt.blockID);
		world.setBlock(i + 6, j + 3, k + 3, DivineRPGTwilight.dreamdirt.blockID);
		world.setBlock(i + 6, j + 3, k + 4, DivineRPGTwilight.cryptWall.blockID);
		world.setBlock(i + 6, j + 3, k + 5, DivineRPGTwilight.cryptWall.blockID);
		world.setBlock(i + 6, j + 3, k + 6, DivineRPGTwilight.dreamdirt.blockID);
		world.setBlock(i + 6, j + 3, k + 7, DivineRPGTwilight.hungerstone2.blockID);
		world.setBlock(i + 6, j + 3, k + 8, DivineRPGTwilight.hungerstone2.blockID);
		world.setBlock(i + 6, j + 3, k + 9, DivineRPGTwilight.dreamdirt.blockID);
		world.setBlock(i + 6, j + 3, k + 10, DivineRPGTwilight.dreamdirt.blockID);
		world.setBlock(i + 6, j + 4, k + 0, DivineRPGTwilight.dreamdirt.blockID);
		world.setBlock(i + 6, j + 4, k + 1, DivineRPGTwilight.dreamdirt.blockID);
		world.setBlock(i + 6, j + 4, k + 2, DivineRPGTwilight.dreamdirt.blockID);
		world.setBlock(i + 6, j + 4, k + 3, DivineRPGTwilight.hungerstone2.blockID);
		world.setBlock(i + 6, j + 4, k + 4, 0);
		world.setBlock(i + 6, j + 4, k + 5, 0);
		world.setBlock(i + 6, j + 4, k + 6, DivineRPGTwilight.hungerstone2.blockID);
		world.setBlock(i + 6, j + 4, k + 7, DivineRPGTwilight.dreamdirt.blockID);
		world.setBlock(i + 6, j + 4, k + 8, DivineRPGTwilight.dreamdirt.blockID);
		world.setBlock(i + 6, j + 4, k + 9, DivineRPGTwilight.dreamdirt.blockID);
		world.setBlock(i + 6, j + 4, k + 10, DivineRPGTwilight.dreamdirt.blockID);
		world.setBlock(i + 6, j + 5, k + 0, DivineRPGTwilight.metalCaging.blockID);
		world.setBlock(i + 6, j + 5, k + 1, 0);
		world.setBlock(i + 6, j + 5, k + 2, 0);
		world.setBlock(i + 6, j + 5, k + 3, DivineRPGTwilight.hungerstone1.blockID);
		world.setBlock(i + 6, j + 5, k + 4, 0);
		world.setBlock(i + 6, j + 5, k + 5, 0);
		world.setBlock(i + 6, j + 5, k + 6, DivineRPGTwilight.hungerstone1.blockID);
		world.setBlock(i + 6, j + 5, k + 7, 0);
		world.setBlock(i + 6, j + 5, k + 8, 0);
		world.setBlock(i + 6, j + 5, k + 9, 0);
		world.setBlock(i + 6, j + 5, k + 10, DivineRPGTwilight.metalCaging.blockID);
		world.setBlock(i + 6, j + 6, k + 0, DivineRPGTwilight.hungerstone1.blockID);
		world.setBlock(i + 6, j + 6, k + 1, 0);
		world.setBlock(i + 6, j + 6, k + 2, 0);
		world.setBlock(i + 6, j + 6, k + 3, DivineRPGTwilight.hungerstone2.blockID);
		world.setBlock(i + 6, j + 6, k + 4, 0);
		world.setBlock(i + 6, j + 6, k + 5, 0);
		world.setBlock(i + 6, j + 6, k + 6, DivineRPGTwilight.hungerstone2.blockID);
		world.setBlock(i + 6, j + 6, k + 7, 0);
		world.setBlock(i + 6, j + 6, k + 8, 0);
		world.setBlock(i + 6, j + 6, k + 9, 0);
		world.setBlock(i + 6, j + 6, k + 10, DivineRPGTwilight.hungerstone1.blockID);
		world.setBlock(i + 6, j + 7, k + 0, 0);
		world.setBlock(i + 6, j + 7, k + 1, 0);
		world.setBlock(i + 6, j + 7, k + 2, 0);
		world.setBlock(i + 6, j + 7, k + 3, 0);
		world.setBlock(i + 6, j + 7, k + 4, DivineRPGTwilight.hungerstone1.blockID);
		world.setBlock(i + 6, j + 7, k + 5, DivineRPGTwilight.hungerstone1.blockID);
		world.setBlock(i + 6, j + 7, k + 6, 0);
		world.setBlock(i + 6, j + 7, k + 7, 0);
		world.setBlock(i + 6, j + 7, k + 8, 0);
		world.setBlock(i + 6, j + 7, k + 9, 0);
		world.setBlock(i + 6, j + 7, k + 10, 0);
		world.setBlock(i + 6, j + 8, k + 0, 0);
		world.setBlock(i + 6, j + 8, k + 1, 0);
		world.setBlock(i + 6, j + 8, k + 2, 0);
		world.setBlock(i + 6, j + 8, k + 3, 0);
		world.setBlock(i + 6, j + 8, k + 4, 0);
		world.setBlock(i + 6, j + 8, k + 5, 0);
		world.setBlock(i + 6, j + 8, k + 6, 0);
		world.setBlock(i + 6, j + 8, k + 7, 0);
		world.setBlock(i + 6, j + 8, k + 8, 0);
		world.setBlock(i + 6, j + 8, k + 9, 0);
		world.setBlock(i + 6, j + 8, k + 10, 0);
		world.setBlock(i + 6, j + 9, k + 0, 0);
		world.setBlock(i + 6, j + 9, k + 1, 0);
		world.setBlock(i + 6, j + 9, k + 2, 0);
		world.setBlock(i + 6, j + 9, k + 3, 0);
		world.setBlock(i + 6, j + 9, k + 4, 0);
		world.setBlock(i + 6, j + 9, k + 5, 0);
		world.setBlock(i + 6, j + 9, k + 6, 0);
		world.setBlock(i + 6, j + 9, k + 7, 0);
		world.setBlock(i + 6, j + 9, k + 8, 0);
		world.setBlock(i + 6, j + 9, k + 9, 0);
		world.setBlock(i + 6, j + 9, k + 10, 0);
		world.setBlock(i + 6, j + 10, k + 0, 0);
		world.setBlock(i + 6, j + 10, k + 1, 0);
		world.setBlock(i + 6, j + 10, k + 2, 0);
		world.setBlock(i + 6, j + 10, k + 3, 0);
		world.setBlock(i + 6, j + 10, k + 4, 0);
		world.setBlock(i + 6, j + 10, k + 5, 0);
		world.setBlock(i + 6, j + 10, k + 6, 0);
		world.setBlock(i + 6, j + 10, k + 7, 0);
		world.setBlock(i + 6, j + 10, k + 8, 0);
		world.setBlock(i + 6, j + 10, k + 9, 0);
		world.setBlock(i + 6, j + 10, k + 10, 0);
		world.setBlock(i + 7, j + 0, k + 0, DivineRPGTwilight.dreamdirt.blockID);
		world.setBlock(i + 7, j + 0, k + 1, DivineRPGTwilight.dreamdirt.blockID);
		world.setBlock(i + 7, j + 0, k + 2, DivineRPGTwilight.dreamdirt.blockID);
		world.setBlock(i + 7, j + 0, k + 3, DivineRPGTwilight.dreamdirt.blockID);
		world.setBlock(i + 7, j + 0, k + 4, DivineRPGTwilight.dreamdirt.blockID);
		world.setBlock(i + 7, j + 0, k + 5, DivineRPGTwilight.dreamdirt.blockID);
		world.setBlock(i + 7, j + 0, k + 6, DivineRPGTwilight.dreamdirt.blockID);
		world.setBlock(i + 7, j + 0, k + 7, DivineRPGTwilight.cryptFloor.blockID);
		world.setBlock(i + 7, j + 0, k + 8, DivineRPGTwilight.cryptFloor.blockID);
		world.setBlock(i + 7, j + 0, k + 9, DivineRPGTwilight.dreamdirt.blockID);
		world.setBlock(i + 7, j + 0, k + 10, DivineRPGTwilight.dreamdirt.blockID);
		world.setBlock(i + 7, j + 1, k + 0, DivineRPGTwilight.dreamdirt.blockID);
		world.setBlock(i + 7, j + 1, k + 1, DivineRPGTwilight.dreamdirt.blockID);
		world.setBlock(i + 7, j + 1, k + 2, DivineRPGTwilight.dreamdirt.blockID);
		world.setBlock(i + 7, j + 1, k + 3, DivineRPGTwilight.dreamdirt.blockID);
		world.setBlock(i + 7, j + 1, k + 4, DivineRPGTwilight.dreamdirt.blockID);
		world.setBlock(i + 7, j + 1, k + 5, DivineRPGTwilight.cryptWall.blockID);
		world.setBlock(i + 7, j + 1, k + 6, DivineRPGTwilight.cryptWall.blockID);
		world.setBlock(i + 7, j + 1, k + 7, 0);
		world.setBlock(i + 7, j + 1, k + 8, 0);
		world.setBlock(i + 7, j + 1, k + 9, DivineRPGTwilight.cryptWall.blockID);
		world.setBlock(i + 7, j + 1, k + 10, DivineRPGTwilight.dreamdirt.blockID);
		world.setBlock(i + 7, j + 2, k + 0, DivineRPGTwilight.dreamdirt.blockID);
		world.setBlock(i + 7, j + 2, k + 1, DivineRPGTwilight.dreamdirt.blockID);
		world.setBlock(i + 7, j + 2, k + 2, DivineRPGTwilight.dreamdirt.blockID);
		world.setBlock(i + 7, j + 2, k + 3, DivineRPGTwilight.dreamdirt.blockID);
		world.setBlock(i + 7, j + 2, k + 4, DivineRPGTwilight.dreamdirt.blockID);
		world.setBlock(i + 7, j + 2, k + 5, DivineRPGTwilight.cryptWall.blockID);
		world.setBlock(i + 7, j + 2, k + 6, DivineRPGTwilight.firecrystal.blockID);
		world.setBlock(i + 7, j + 2, k + 7, 0);
		world.setBlock(i + 7, j + 2, k + 8, 0);
		world.setBlock(i + 7, j + 2, k + 9, DivineRPGTwilight.cryptWall.blockID);
		world.setBlock(i + 7, j + 2, k + 10, DivineRPGTwilight.dreamdirt.blockID);
		world.setBlock(i + 7, j + 3, k + 0, DivineRPGTwilight.dreamdirt.blockID);
		world.setBlock(i + 7, j + 3, k + 1, DivineRPGTwilight.dreamdirt.blockID);
		world.setBlock(i + 7, j + 3, k + 2, DivineRPGTwilight.dreamdirt.blockID);
		world.setBlock(i + 7, j + 3, k + 3, DivineRPGTwilight.dreamdirt.blockID);
		world.setBlock(i + 7, j + 3, k + 4, DivineRPGTwilight.dreamdirt.blockID);
		world.setBlock(i + 7, j + 3, k + 5, DivineRPGTwilight.dreamdirt.blockID);
		world.setBlock(i + 7, j + 3, k + 6, DivineRPGTwilight.dreamdirt.blockID);
		world.setBlock(i + 7, j + 3, k + 7, DivineRPGTwilight.hungerstone2.blockID);
		world.setBlock(i + 7, j + 3, k + 8, DivineRPGTwilight.hungerstone2.blockID);
		world.setBlock(i + 7, j + 3, k + 9, DivineRPGTwilight.dreamdirt.blockID);
		world.setBlock(i + 7, j + 3, k + 10, DivineRPGTwilight.dreamdirt.blockID);
		world.setBlock(i + 7, j + 4, k + 0, DivineRPGTwilight.dreamdirt.blockID);
		world.setBlock(i + 7, j + 4, k + 1, DivineRPGTwilight.dreamdirt.blockID);
		world.setBlock(i + 7, j + 4, k + 2, DivineRPGTwilight.dreamdirt.blockID);
		world.setBlock(i + 7, j + 4, k + 3, DivineRPGTwilight.hungerstone2.blockID);
		world.setBlock(i + 7, j + 4, k + 4, DivineRPGTwilight.cryptWall.blockID);
		world.setBlock(i + 7, j + 4, k + 5, DivineRPGTwilight.cryptWall.blockID);
		world.setBlock(i + 7, j + 4, k + 6, DivineRPGTwilight.hungerstone2.blockID);
		world.setBlock(i + 7, j + 4, k + 7, DivineRPGTwilight.dreamdirt.blockID);
		world.setBlock(i + 7, j + 4, k + 8, DivineRPGTwilight.dreamdirt.blockID);
		world.setBlock(i + 7, j + 4, k + 9, DivineRPGTwilight.dreamdirt.blockID);
		world.setBlock(i + 7, j + 4, k + 10, DivineRPGTwilight.dreamdirt.blockID);
		world.setBlock(i + 7, j + 5, k + 0, DivineRPGTwilight.metalCaging.blockID);
		world.setBlock(i + 7, j + 5, k + 1, 0);
		world.setBlock(i + 7, j + 5, k + 2, 0);
		world.setBlock(i + 7, j + 5, k + 3, DivineRPGTwilight.hungerstone1.blockID);
		world.setBlock(i + 7, j + 5, k + 4, 0);
		world.setBlock(i + 7, j + 5, k + 5, 0);
		world.setBlock(i + 7, j + 5, k + 6, DivineRPGTwilight.hungerstone1.blockID);
		world.setBlock(i + 7, j + 5, k + 7, 0);
		world.setBlock(i + 7, j + 5, k + 8, 0);
		world.setBlock(i + 7, j + 5, k + 9, 0);
		world.setBlock(i + 7, j + 5, k + 10, DivineRPGTwilight.metalCaging.blockID);
		world.setBlock(i + 7, j + 6, k + 0, DivineRPGTwilight.hungerstone1.blockID);
		world.setBlock(i + 7, j + 6, k + 1, 0);
		world.setBlock(i + 7, j + 6, k + 2, DivineRPGTwilight.firecrystal.blockID);
		world.setBlock(i + 7, j + 6, k + 3, DivineRPGTwilight.hungerstone2.blockID);
		world.setBlock(i + 7, j + 6, k + 4, 0);
		world.setBlock(i + 7, j + 6, k + 5, 0);
		world.setBlock(i + 7, j + 6, k + 6, DivineRPGTwilight.hungerstone2.blockID);
		world.setBlock(i + 7, j + 6, k + 7, DivineRPGTwilight.firecrystal.blockID);
		world.setBlock(i + 7, j + 6, k + 8, 0);
		world.setBlock(i + 7, j + 6, k + 9, 0);
		world.setBlock(i + 7, j + 6, k + 10, DivineRPGTwilight.hungerstone1.blockID);
		world.setBlock(i + 7, j + 7, k + 0, 0);
		world.setBlock(i + 7, j + 7, k + 1, 0);
		world.setBlock(i + 7, j + 7, k + 2, DivineRPGTwilight.hungerstone2.blockID);
		world.setBlock(i + 7, j + 7, k + 3, DivineRPGTwilight.hungerstone2.blockID);
		world.setBlock(i + 7, j + 7, k + 4, DivineRPGTwilight.hungerstone1.blockID);
		world.setBlock(i + 7, j + 7, k + 5, DivineRPGTwilight.hungerstone1.blockID);
		world.setBlock(i + 7, j + 7, k + 6, DivineRPGTwilight.hungerstone2.blockID);
		world.setBlock(i + 7, j + 7, k + 7, DivineRPGTwilight.hungerstone2.blockID);
		world.setBlock(i + 7, j + 7, k + 8, 0);
		world.setBlock(i + 7, j + 7, k + 9, 0);
		world.setBlock(i + 7, j + 7, k + 10, 0);
		world.setBlock(i + 7, j + 8, k + 0, 0);
		world.setBlock(i + 7, j + 8, k + 1, 0);
		world.setBlock(i + 7, j + 8, k + 2, 0);
		world.setBlock(i + 7, j + 8, k + 3, 0);
		world.setBlock(i + 7, j + 8, k + 4, 0);
		world.setBlock(i + 7, j + 8, k + 5, 0);
		world.setBlock(i + 7, j + 8, k + 6, 0);
		world.setBlock(i + 7, j + 8, k + 7, 0);
		world.setBlock(i + 7, j + 8, k + 8, 0);
		world.setBlock(i + 7, j + 8, k + 9, 0);
		world.setBlock(i + 7, j + 8, k + 10, 0);
		world.setBlock(i + 7, j + 9, k + 0, 0);
		world.setBlock(i + 7, j + 9, k + 1, 0);
		world.setBlock(i + 7, j + 9, k + 2, 0);
		world.setBlock(i + 7, j + 9, k + 3, 0);
		world.setBlock(i + 7, j + 9, k + 4, 0);
		world.setBlock(i + 7, j + 9, k + 5, 0);
		world.setBlock(i + 7, j + 9, k + 6, 0);
		world.setBlock(i + 7, j + 9, k + 7, 0);
		world.setBlock(i + 7, j + 9, k + 8, 0);
		world.setBlock(i + 7, j + 9, k + 9, 0);
		world.setBlock(i + 7, j + 9, k + 10, 0);
		world.setBlock(i + 7, j + 10, k + 0, 0);
		world.setBlock(i + 7, j + 10, k + 1, 0);
		world.setBlock(i + 7, j + 10, k + 2, 0);
		world.setBlock(i + 7, j + 10, k + 3, 0);
		world.setBlock(i + 7, j + 10, k + 4, 0);
		world.setBlock(i + 7, j + 10, k + 5, 0);
		world.setBlock(i + 7, j + 10, k + 6, 0);
		world.setBlock(i + 7, j + 10, k + 7, 0);
		world.setBlock(i + 7, j + 10, k + 8, 0);
		world.setBlock(i + 7, j + 10, k + 9, 0);
		world.setBlock(i + 7, j + 10, k + 10, 0);
		world.setBlock(i + 8, j + 0, k + 0, DivineRPGTwilight.dreamdirt.blockID);
		world.setBlock(i + 8, j + 0, k + 1, DivineRPGTwilight.dreamdirt.blockID);
		world.setBlock(i + 8, j + 0, k + 2, DivineRPGTwilight.dreamdirt.blockID);
		world.setBlock(i + 8, j + 0, k + 3, DivineRPGTwilight.dreamdirt.blockID);
		world.setBlock(i + 8, j + 0, k + 4, DivineRPGTwilight.dreamdirt.blockID);
		world.setBlock(i + 8, j + 0, k + 5, DivineRPGTwilight.cryptFloor.blockID);
		world.setBlock(i + 8, j + 0, k + 6, DivineRPGTwilight.cryptFloor.blockID);
		world.setBlock(i + 8, j + 0, k + 7, DivineRPGTwilight.cryptFloor.blockID);
		world.setBlock(i + 8, j + 0, k + 8, DivineRPGTwilight.cryptFloor.blockID);
		world.setBlock(i + 8, j + 0, k + 9, DivineRPGTwilight.dreamdirt.blockID);
		world.setBlock(i + 8, j + 0, k + 10, DivineRPGTwilight.dreamdirt.blockID);
		world.setBlock(i + 8, j + 1, k + 0, DivineRPGTwilight.dreamdirt.blockID);
		world.setBlock(i + 8, j + 1, k + 1, DivineRPGTwilight.dreamdirt.blockID);
		world.setBlock(i + 8, j + 1, k + 2, DivineRPGTwilight.dreamdirt.blockID);
		world.setBlock(i + 8, j + 1, k + 3, DivineRPGTwilight.dreamdirt.blockID);
		world.setBlock(i + 8, j + 1, k + 4, DivineRPGTwilight.cryptWall.blockID);
		world.setBlock(i + 8, j + 1, k + 5, DivineRPGTwilight.vermenousSpawner.blockID);
		world.setBlock(i + 8, j + 1, k + 6, 0);
		world.setBlock(i + 8, j + 1, k + 7, 0);
		world.setBlock(i + 8, j + 1, k + 8, 0);
		world.setBlock(i + 8, j + 1, k + 9, DivineRPGTwilight.cryptWall.blockID);
		world.setBlock(i + 8, j + 1, k + 10, DivineRPGTwilight.dreamdirt.blockID);
		world.setBlock(i + 8, j + 2, k + 0, DivineRPGTwilight.dreamdirt.blockID);
		world.setBlock(i + 8, j + 2, k + 1, DivineRPGTwilight.dreamdirt.blockID);
		world.setBlock(i + 8, j + 2, k + 2, DivineRPGTwilight.dreamdirt.blockID);
		world.setBlock(i + 8, j + 2, k + 3, DivineRPGTwilight.dreamdirt.blockID);
		world.setBlock(i + 8, j + 2, k + 4, DivineRPGTwilight.cryptWall.blockID);
		world.setBlock(i + 8, j + 2, k + 5, 0);
		world.setBlock(i + 8, j + 2, k + 6, 0);
		world.setBlock(i + 8, j + 2, k + 7, 0);
		world.setBlock(i + 8, j + 2, k + 8, 0);
		world.setBlock(i + 8, j + 2, k + 9, DivineRPGTwilight.cryptWall.blockID);
		world.setBlock(i + 8, j + 2, k + 10, DivineRPGTwilight.dreamdirt.blockID);
		world.setBlock(i + 8, j + 3, k + 0, DivineRPGTwilight.dreamdirt.blockID);
		world.setBlock(i + 8, j + 3, k + 1, DivineRPGTwilight.dreamdirt.blockID);
		world.setBlock(i + 8, j + 3, k + 2, DivineRPGTwilight.dreamdirt.blockID);
		world.setBlock(i + 8, j + 3, k + 3, DivineRPGTwilight.dreamdirt.blockID);
		world.setBlock(i + 8, j + 3, k + 4, DivineRPGTwilight.dreamdirt.blockID);
		world.setBlock(i + 8, j + 3, k + 5, DivineRPGTwilight.hungerstone2.blockID);
		world.setBlock(i + 8, j + 3, k + 6, DivineRPGTwilight.hungerstone2.blockID);
		world.setBlock(i + 8, j + 3, k + 7, DivineRPGTwilight.hungerstone2.blockID);
		world.setBlock(i + 8, j + 3, k + 8, DivineRPGTwilight.hungerstone2.blockID);
		world.setBlock(i + 8, j + 3, k + 9, DivineRPGTwilight.dreamdirt.blockID);
		world.setBlock(i + 8, j + 3, k + 10, DivineRPGTwilight.dreamdirt.blockID);
		world.setBlock(i + 8, j + 4, k + 0, DivineRPGTwilight.dreamdirt.blockID);
		world.setBlock(i + 8, j + 4, k + 1, DivineRPGTwilight.dreamdirt.blockID);
		world.setBlock(i + 8, j + 4, k + 2, DivineRPGTwilight.dreamdirt.blockID);
		world.setBlock(i + 8, j + 4, k + 3, DivineRPGTwilight.dreamdirt.blockID);
		world.setBlock(i + 8, j + 4, k + 4, DivineRPGTwilight.cryptWall.blockID);
		world.setBlock(i + 8, j + 4, k + 5, DivineRPGTwilight.cryptWall.blockID);
		world.setBlock(i + 8, j + 4, k + 6, DivineRPGTwilight.dreamdirt.blockID);
		world.setBlock(i + 8, j + 4, k + 7, DivineRPGTwilight.dreamdirt.blockID);
		world.setBlock(i + 8, j + 4, k + 8, DivineRPGTwilight.dreamdirt.blockID);
		world.setBlock(i + 8, j + 4, k + 9, DivineRPGTwilight.dreamdirt.blockID);
		world.setBlock(i + 8, j + 4, k + 10, DivineRPGTwilight.dreamdirt.blockID);
		world.setBlock(i + 8, j + 5, k + 0, DivineRPGTwilight.metalCaging.blockID);
		world.setBlock(i + 8, j + 5, k + 1, 0);
		world.setBlock(i + 8, j + 5, k + 2, 0);
		world.setBlock(i + 8, j + 5, k + 3, DivineRPGTwilight.hungerstone1.blockID);
		world.setBlock(i + 8, j + 5, k + 4, 0);
		world.setBlock(i + 8, j + 5, k + 5, 0);
		world.setBlock(i + 8, j + 5, k + 6, DivineRPGTwilight.hungerstone1.blockID);
		world.setBlock(i + 8, j + 5, k + 7, 0);
		world.setBlock(i + 8, j + 5, k + 8, 0);
		world.setBlock(i + 8, j + 5, k + 9, 0);
		world.setBlock(i + 8, j + 5, k + 10, DivineRPGTwilight.metalCaging.blockID);
		world.setBlock(i + 8, j + 6, k + 0, DivineRPGTwilight.hungerstone1.blockID);
		world.setBlock(i + 8, j + 6, k + 1, 0);
		world.setBlock(i + 8, j + 6, k + 2, 0);
		world.setBlock(i + 8, j + 6, k + 3, 0);
		world.setBlock(i + 8, j + 6, k + 4, 0);
		world.setBlock(i + 8, j + 6, k + 5, 0);
		world.setBlock(i + 8, j + 6, k + 6, 0);
		world.setBlock(i + 8, j + 6, k + 7, 0);
		world.setBlock(i + 8, j + 6, k + 8, 0);
		world.setBlock(i + 8, j + 6, k + 9, 0);
		world.setBlock(i + 8, j + 6, k + 10, DivineRPGTwilight.hungerstone1.blockID);
		world.setBlock(i + 8, j + 7, k + 0, 0);
		world.setBlock(i + 8, j + 7, k + 1, 0);
		world.setBlock(i + 8, j + 7, k + 2, 0);
		world.setBlock(i + 8, j + 7, k + 3, 0);
		world.setBlock(i + 8, j + 7, k + 4, DivineRPGTwilight.hungerstone1.blockID);
		world.setBlock(i + 8, j + 7, k + 5, DivineRPGTwilight.hungerstone1.blockID);
		world.setBlock(i + 8, j + 7, k + 6, 0);
		world.setBlock(i + 8, j + 7, k + 7, 0);
		world.setBlock(i + 8, j + 7, k + 8, 0);
		world.setBlock(i + 8, j + 7, k + 9, 0);
		world.setBlock(i + 8, j + 7, k + 10, 0);
		world.setBlock(i + 8, j + 8, k + 0, 0);
		world.setBlock(i + 8, j + 8, k + 1, 0);
		world.setBlock(i + 8, j + 8, k + 2, 0);
		world.setBlock(i + 8, j + 8, k + 3, 0);
		world.setBlock(i + 8, j + 8, k + 4, 0);
		world.setBlock(i + 8, j + 8, k + 5, 0);
		world.setBlock(i + 8, j + 8, k + 6, 0);
		world.setBlock(i + 8, j + 8, k + 7, 0);
		world.setBlock(i + 8, j + 8, k + 8, 0);
		world.setBlock(i + 8, j + 8, k + 9, 0);
		world.setBlock(i + 8, j + 8, k + 10, 0);
		world.setBlock(i + 8, j + 9, k + 0, 0);
		world.setBlock(i + 8, j + 9, k + 1, 0);
		world.setBlock(i + 8, j + 9, k + 2, 0);
		world.setBlock(i + 8, j + 9, k + 3, 0);
		world.setBlock(i + 8, j + 9, k + 4, 0);
		world.setBlock(i + 8, j + 9, k + 5, 0);
		world.setBlock(i + 8, j + 9, k + 6, 0);
		world.setBlock(i + 8, j + 9, k + 7, 0);
		world.setBlock(i + 8, j + 9, k + 8, 0);
		world.setBlock(i + 8, j + 9, k + 9, 0);
		world.setBlock(i + 8, j + 9, k + 10, 0);
		world.setBlock(i + 8, j + 10, k + 0, 0);
		world.setBlock(i + 8, j + 10, k + 1, 0);
		world.setBlock(i + 8, j + 10, k + 2, 0);
		world.setBlock(i + 8, j + 10, k + 3, 0);
		world.setBlock(i + 8, j + 10, k + 4, 0);
		world.setBlock(i + 8, j + 10, k + 5, 0);
		world.setBlock(i + 8, j + 10, k + 6, 0);
		world.setBlock(i + 8, j + 10, k + 7, 0);
		world.setBlock(i + 8, j + 10, k + 8, 0);
		world.setBlock(i + 8, j + 10, k + 9, 0);
		world.setBlock(i + 8, j + 10, k + 10, 0);
		world.setBlock(i + 9, j + 0, k + 0, DivineRPGTwilight.dreamdirt.blockID);
		world.setBlock(i + 9, j + 0, k + 1, DivineRPGTwilight.dreamdirt.blockID);
		world.setBlock(i + 9, j + 0, k + 2, DivineRPGTwilight.dreamdirt.blockID);
		world.setBlock(i + 9, j + 0, k + 3, DivineRPGTwilight.dreamdirt.blockID);
		world.setBlock(i + 9, j + 0, k + 4, DivineRPGTwilight.dreamdirt.blockID);
		world.setBlock(i + 9, j + 0, k + 5, DivineRPGTwilight.cryptFloor.blockID);
		world.setBlock(i + 9, j + 0, k + 6, DivineRPGTwilight.cryptFloor.blockID);
		world.setBlock(i + 9, j + 0, k + 7, DivineRPGTwilight.cryptFloor.blockID);
		world.setBlock(i + 9, j + 0, k + 8, DivineRPGTwilight.cryptFloor.blockID);
		world.setBlock(i + 9, j + 0, k + 9, DivineRPGTwilight.dreamdirt.blockID);
		world.setBlock(i + 9, j + 0, k + 10, DivineRPGTwilight.dreamdirt.blockID);
		world.setBlock(i + 9, j + 1, k + 0, DivineRPGTwilight.dreamdirt.blockID);
		world.setBlock(i + 9, j + 1, k + 1, DivineRPGTwilight.dreamdirt.blockID);
		world.setBlock(i + 9, j + 1, k + 2, DivineRPGTwilight.dreamdirt.blockID);
		world.setBlock(i + 9, j + 1, k + 3, DivineRPGTwilight.dreamdirt.blockID);
		world.setBlock(i + 9, j + 1, k + 4, DivineRPGTwilight.cryptWall.blockID);
		world.setBlock(i + 9, j + 1, k + 5, 0);
		world.setBlock(i + 9, j + 1, k + 6, 0);
		world.setBlock(i + 9, j + 1, k + 7, 0);
		world.setBlock(i + 9, j + 1, k + 8, 0);
		world.setBlock(i + 9, j + 1, k + 9, DivineRPGTwilight.cryptWall.blockID);
		world.setBlock(i + 9, j + 1, k + 10, DivineRPGTwilight.dreamdirt.blockID);
		world.setBlock(i + 9, j + 2, k + 0, DivineRPGTwilight.dreamdirt.blockID);
		world.setBlock(i + 9, j + 2, k + 1, DivineRPGTwilight.dreamdirt.blockID);
		world.setBlock(i + 9, j + 2, k + 2, DivineRPGTwilight.dreamdirt.blockID);
		world.setBlock(i + 9, j + 2, k + 3, DivineRPGTwilight.dreamdirt.blockID);
		world.setBlock(i + 9, j + 2, k + 4, DivineRPGTwilight.cryptWall.blockID);
		world.setBlock(i + 9, j + 2, k + 5, 0);
		world.setBlock(i + 9, j + 2, k + 6, 0);
		world.setBlock(i + 9, j + 2, k + 7, 0);
		world.setBlock(i + 9, j + 2, k + 8, 0);
		world.setBlock(i + 9, j + 2, k + 9, DivineRPGTwilight.cryptWall.blockID);
		world.setBlock(i + 9, j + 2, k + 10, DivineRPGTwilight.dreamdirt.blockID);
		world.setBlock(i + 9, j + 3, k + 0, DivineRPGTwilight.dreamdirt.blockID);
		world.setBlock(i + 9, j + 3, k + 1, DivineRPGTwilight.dreamdirt.blockID);
		world.setBlock(i + 9, j + 3, k + 2, DivineRPGTwilight.dreamdirt.blockID);
		world.setBlock(i + 9, j + 3, k + 3, DivineRPGTwilight.dreamdirt.blockID);
		world.setBlock(i + 9, j + 3, k + 4, DivineRPGTwilight.dreamdirt.blockID);
		world.setBlock(i + 9, j + 3, k + 5, DivineRPGTwilight.hungerstone2.blockID);
		world.setBlock(i + 9, j + 3, k + 6, DivineRPGTwilight.hungerstone2.blockID);
		world.setBlock(i + 9, j + 3, k + 7, DivineRPGTwilight.hungerstone2.blockID);
		world.setBlock(i + 9, j + 3, k + 8, DivineRPGTwilight.hungerstone2.blockID);
		world.setBlock(i + 9, j + 3, k + 9, DivineRPGTwilight.dreamdirt.blockID);
		world.setBlock(i + 9, j + 3, k + 10, DivineRPGTwilight.dreamdirt.blockID);
		world.setBlock(i + 9, j + 4, k + 0, DivineRPGTwilight.dreamdirt.blockID);
		world.setBlock(i + 9, j + 4, k + 1, DivineRPGTwilight.dreamdirt.blockID);
		world.setBlock(i + 9, j + 4, k + 2, DivineRPGTwilight.dreamdirt.blockID);
		world.setBlock(i + 9, j + 4, k + 3, DivineRPGTwilight.dreamdirt.blockID);
		world.setBlock(i + 9, j + 4, k + 4, DivineRPGTwilight.cryptWall.blockID);
		world.setBlock(i + 9, j + 4, k + 5, DivineRPGTwilight.cryptWall.blockID);
		world.setBlock(i + 9, j + 4, k + 6, DivineRPGTwilight.dreamdirt.blockID);
		world.setBlock(i + 9, j + 4, k + 7, DivineRPGTwilight.dreamdirt.blockID);
		world.setBlock(i + 9, j + 4, k + 8, DivineRPGTwilight.dreamdirt.blockID);
		world.setBlock(i + 9, j + 4, k + 9, DivineRPGTwilight.dreamdirt.blockID);
		world.setBlock(i + 9, j + 4, k + 10, DivineRPGTwilight.dreamdirt.blockID);
		world.setBlock(i + 9, j + 5, k + 0, DivineRPGTwilight.metalCaging.blockID);
		world.setBlock(i + 9, j + 5, k + 1, 0);
		world.setBlock(i + 9, j + 5, k + 2, 0);
		world.setBlock(i + 9, j + 5, k + 3, 0);
		world.setBlock(i + 9, j + 5, k + 4, 0);
		world.setBlock(i + 9, j + 5, k + 5, 0);
		world.setBlock(i + 9, j + 5, k + 6, 0);
		world.setBlock(i + 9, j + 5, k + 7, 0);
		world.setBlock(i + 9, j + 5, k + 8, 0);
		world.setBlock(i + 9, j + 5, k + 9, 0);
		world.setBlock(i + 9, j + 5, k + 10, DivineRPGTwilight.metalCaging.blockID);
		world.setBlock(i + 9, j + 6, k + 0, DivineRPGTwilight.hungerstone1.blockID);
		world.setBlock(i + 9, j + 6, k + 1, 0);
		world.setBlock(i + 9, j + 6, k + 2, 0);
		world.setBlock(i + 9, j + 6, k + 3, 0);
		world.setBlock(i + 9, j + 6, k + 4, 0);
		world.setBlock(i + 9, j + 6, k + 5, 0);
		world.setBlock(i + 9, j + 6, k + 6, 0);
		world.setBlock(i + 9, j + 6, k + 7, 0);
		world.setBlock(i + 9, j + 6, k + 8, 0);
		world.setBlock(i + 9, j + 6, k + 9, 0);
		world.setBlock(i + 9, j + 6, k + 10, DivineRPGTwilight.hungerstone1.blockID);
		world.setBlock(i + 9, j + 7, k + 0, 0);
		world.setBlock(i + 9, j + 7, k + 1, 0);
		world.setBlock(i + 9, j + 7, k + 2, 0);
		world.setBlock(i + 9, j + 7, k + 3, 0);
		world.setBlock(i + 9, j + 7, k + 4, 0);
		world.setBlock(i + 9, j + 7, k + 5, 0);
		world.setBlock(i + 9, j + 7, k + 6, 0);
		world.setBlock(i + 9, j + 7, k + 7, 0);
		world.setBlock(i + 9, j + 7, k + 8, 0);
		world.setBlock(i + 9, j + 7, k + 9, 0);
		world.setBlock(i + 9, j + 7, k + 10, 0);
		world.setBlock(i + 9, j + 8, k + 0, 0);
		world.setBlock(i + 9, j + 8, k + 1, 0);
		world.setBlock(i + 9, j + 8, k + 2, 0);
		world.setBlock(i + 9, j + 8, k + 3, 0);
		world.setBlock(i + 9, j + 8, k + 4, 0);
		world.setBlock(i + 9, j + 8, k + 5, 0);
		world.setBlock(i + 9, j + 8, k + 6, 0);
		world.setBlock(i + 9, j + 8, k + 7, 0);
		world.setBlock(i + 9, j + 8, k + 8, 0);
		world.setBlock(i + 9, j + 8, k + 9, 0);
		world.setBlock(i + 9, j + 8, k + 10, 0);
		world.setBlock(i + 9, j + 9, k + 0, 0);
		world.setBlock(i + 9, j + 9, k + 1, 0);
		world.setBlock(i + 9, j + 9, k + 2, 0);
		world.setBlock(i + 9, j + 9, k + 3, 0);
		world.setBlock(i + 9, j + 9, k + 4, 0);
		world.setBlock(i + 9, j + 9, k + 5, 0);
		world.setBlock(i + 9, j + 9, k + 6, 0);
		world.setBlock(i + 9, j + 9, k + 7, 0);
		world.setBlock(i + 9, j + 9, k + 8, 0);
		world.setBlock(i + 9, j + 9, k + 9, 0);
		world.setBlock(i + 9, j + 9, k + 10, 0);
		world.setBlock(i + 9, j + 10, k + 0, 0);
		world.setBlock(i + 9, j + 10, k + 1, 0);
		world.setBlock(i + 9, j + 10, k + 2, 0);
		world.setBlock(i + 9, j + 10, k + 3, 0);
		world.setBlock(i + 9, j + 10, k + 4, 0);
		world.setBlock(i + 9, j + 10, k + 5, 0);
		world.setBlock(i + 9, j + 10, k + 6, 0);
		world.setBlock(i + 9, j + 10, k + 7, 0);
		world.setBlock(i + 9, j + 10, k + 8, 0);
		world.setBlock(i + 9, j + 10, k + 9, 0);
		world.setBlock(i + 9, j + 10, k + 10, 0);
		world.setBlock(i + 10, j + 0, k + 0, DivineRPGTwilight.dreamdirt.blockID);
		world.setBlock(i + 10, j + 0, k + 1, DivineRPGTwilight.dreamdirt.blockID);
		world.setBlock(i + 10, j + 0, k + 2, DivineRPGTwilight.dreamdirt.blockID);
		world.setBlock(i + 10, j + 0, k + 3, DivineRPGTwilight.dreamdirt.blockID);
		world.setBlock(i + 10, j + 0, k + 4, DivineRPGTwilight.dreamdirt.blockID);
		world.setBlock(i + 10, j + 0, k + 5, DivineRPGTwilight.cryptFloor.blockID);
		world.setBlock(i + 10, j + 0, k + 6, DivineRPGTwilight.cryptFloor.blockID);
		world.setBlock(i + 10, j + 0, k + 7, DivineRPGTwilight.cryptFloor.blockID);
		world.setBlock(i + 10, j + 0, k + 8, DivineRPGTwilight.cryptFloor.blockID);
		world.setBlock(i + 10, j + 0, k + 9, DivineRPGTwilight.dreamdirt.blockID);
		world.setBlock(i + 10, j + 0, k + 10, DivineRPGTwilight.dreamdirt.blockID);
		world.setBlock(i + 10, j + 1, k + 0, DivineRPGTwilight.dreamdirt.blockID);
		world.setBlock(i + 10, j + 1, k + 1, DivineRPGTwilight.dreamdirt.blockID);
		world.setBlock(i + 10, j + 1, k + 2, DivineRPGTwilight.dreamdirt.blockID);
		world.setBlock(i + 10, j + 1, k + 3, DivineRPGTwilight.dreamdirt.blockID);
		world.setBlock(i + 10, j + 1, k + 4, DivineRPGTwilight.cryptWall.blockID);
		world.setBlock(i + 10, j + 1, k + 5, 0);
		world.setBlock(i + 10, j + 1, k + 6, 0);
		world.setBlock(i + 10, j + 1, k + 7, 0);
		world.setBlock(i + 10, j + 1, k + 8, 0);
		world.setBlock(i + 10, j + 1, k + 9, DivineRPGTwilight.cryptWall.blockID);
		world.setBlock(i + 10, j + 1, k + 10, DivineRPGTwilight.dreamdirt.blockID);
		world.setBlock(i + 10, j + 2, k + 0, DivineRPGTwilight.dreamdirt.blockID);
		world.setBlock(i + 10, j + 2, k + 1, DivineRPGTwilight.dreamdirt.blockID);
		world.setBlock(i + 10, j + 2, k + 2, DivineRPGTwilight.dreamdirt.blockID);
		world.setBlock(i + 10, j + 2, k + 3, DivineRPGTwilight.dreamdirt.blockID);
		world.setBlock(i + 10, j + 2, k + 4, DivineRPGTwilight.cryptWall.blockID);
		world.setBlock(i + 10, j + 2, k + 5, 0);
		world.setBlock(i + 10, j + 2, k + 6, 0);
		world.setBlock(i + 10, j + 2, k + 7, 0);
		world.setBlock(i + 10, j + 2, k + 8, 0);
		world.setBlock(i + 10, j + 2, k + 9, DivineRPGTwilight.cryptWall.blockID);
		world.setBlock(i + 10, j + 2, k + 10, DivineRPGTwilight.dreamdirt.blockID);
		world.setBlock(i + 10, j + 3, k + 0, DivineRPGTwilight.dreamdirt.blockID);
		world.setBlock(i + 10, j + 3, k + 1, DivineRPGTwilight.dreamdirt.blockID);
		world.setBlock(i + 10, j + 3, k + 2, DivineRPGTwilight.dreamdirt.blockID);
		world.setBlock(i + 10, j + 3, k + 3, DivineRPGTwilight.dreamdirt.blockID);
		world.setBlock(i + 10, j + 3, k + 4, DivineRPGTwilight.dreamdirt.blockID);
		world.setBlock(i + 10, j + 3, k + 5, DivineRPGTwilight.hungerstone2.blockID);
		world.setBlock(i + 10, j + 3, k + 6, DivineRPGTwilight.hungerstone2.blockID);
		world.setBlock(i + 10, j + 3, k + 7, DivineRPGTwilight.hungerstone2.blockID);
		world.setBlock(i + 10, j + 3, k + 8, DivineRPGTwilight.hungerstone2.blockID);
		world.setBlock(i + 10, j + 3, k + 9, DivineRPGTwilight.dreamdirt.blockID);
		world.setBlock(i + 10, j + 3, k + 10, DivineRPGTwilight.dreamdirt.blockID);
		world.setBlock(i + 10, j + 4, k + 0, DivineRPGTwilight.dreamdirt.blockID);
		world.setBlock(i + 10, j + 4, k + 1, DivineRPGTwilight.dreamdirt.blockID);
		world.setBlock(i + 10, j + 4, k + 2, DivineRPGTwilight.dreamdirt.blockID);
		world.setBlock(i + 10, j + 4, k + 3, DivineRPGTwilight.dreamdirt.blockID);
		world.setBlock(i + 10, j + 4, k + 4, DivineRPGTwilight.cryptWall.blockID);
		world.setBlock(i + 10, j + 4, k + 5, DivineRPGTwilight.cryptWall.blockID);
		world.setBlock(i + 10, j + 4, k + 6, DivineRPGTwilight.cryptWall.blockID);
		world.setBlock(i + 10, j + 4, k + 7, DivineRPGTwilight.cryptWall.blockID);
		world.setBlock(i + 10, j + 4, k + 8, DivineRPGTwilight.cryptWall.blockID);
		world.setBlock(i + 10, j + 4, k + 9, DivineRPGTwilight.dreamdirt.blockID);
		world.setBlock(i + 10, j + 4, k + 10, DivineRPGTwilight.dreamdirt.blockID);
		world.setBlock(i + 10, j + 5, k + 0, DivineRPGTwilight.metalCaging.blockID);
		world.setBlock(i + 10, j + 5, k + 1, 0);
		world.setBlock(i + 10, j + 5, k + 2, 0);
		world.setBlock(i + 10, j + 5, k + 3, 0);
		world.setBlock(i + 10, j + 5, k + 4, 0);
		world.setBlock(i + 10, j + 5, k + 5, 0);
		world.setBlock(i + 10, j + 5, k + 6, 0);
		world.setBlock(i + 10, j + 5, k + 7, 0);
		world.setBlock(i + 10, j + 5, k + 8, 0);
		world.setBlock(i + 10, j + 5, k + 9, 0);
		world.setBlock(i + 10, j + 5, k + 10, DivineRPGTwilight.metalCaging.blockID);
		world.setBlock(i + 10, j + 6, k + 0, DivineRPGTwilight.hungerstone1.blockID);
		world.setBlock(i + 10, j + 6, k + 1, 0);
		world.setBlock(i + 10, j + 6, k + 2, 0);
		world.setBlock(i + 10, j + 6, k + 3, 0);
		world.setBlock(i + 10, j + 6, k + 4, 0);
		world.setBlock(i + 10, j + 6, k + 5, 0);
		world.setBlock(i + 10, j + 6, k + 6, 0);
		world.setBlock(i + 10, j + 6, k + 7, 0);
		world.setBlock(i + 10, j + 6, k + 8, 0);
		world.setBlock(i + 10, j + 6, k + 9, 0);
		world.setBlock(i + 10, j + 6, k + 10, DivineRPGTwilight.hungerstone1.blockID);
		world.setBlock(i + 10, j + 7, k + 0, 0);
		world.setBlock(i + 10, j + 7, k + 1, 0);
		world.setBlock(i + 10, j + 7, k + 2, 0);
		world.setBlock(i + 10, j + 7, k + 3, 0);
		world.setBlock(i + 10, j + 7, k + 4, 0);
		world.setBlock(i + 10, j + 7, k + 5, 0);
		world.setBlock(i + 10, j + 7, k + 6, 0);
		world.setBlock(i + 10, j + 7, k + 7, 0);
		world.setBlock(i + 10, j + 7, k + 8, 0);
		world.setBlock(i + 10, j + 7, k + 9, 0);
		world.setBlock(i + 10, j + 7, k + 10, 0);
		world.setBlock(i + 10, j + 8, k + 0, 0);
		world.setBlock(i + 10, j + 8, k + 1, 0);
		world.setBlock(i + 10, j + 8, k + 2, 0);
		world.setBlock(i + 10, j + 8, k + 3, 0);
		world.setBlock(i + 10, j + 8, k + 4, 0);
		world.setBlock(i + 10, j + 8, k + 5, 0);
		world.setBlock(i + 10, j + 8, k + 6, 0);
		world.setBlock(i + 10, j + 8, k + 7, 0);
		world.setBlock(i + 10, j + 8, k + 8, 0);
		world.setBlock(i + 10, j + 8, k + 9, 0);
		world.setBlock(i + 10, j + 8, k + 10, 0);
		world.setBlock(i + 10, j + 9, k + 0, 0);
		world.setBlock(i + 10, j + 9, k + 1, 0);
		world.setBlock(i + 10, j + 9, k + 2, 0);
		world.setBlock(i + 10, j + 9, k + 3, 0);
		world.setBlock(i + 10, j + 9, k + 4, 0);
		world.setBlock(i + 10, j + 9, k + 5, 0);
		world.setBlock(i + 10, j + 9, k + 6, 0);
		world.setBlock(i + 10, j + 9, k + 7, 0);
		world.setBlock(i + 10, j + 9, k + 8, 0);
		world.setBlock(i + 10, j + 9, k + 9, 0);
		world.setBlock(i + 10, j + 9, k + 10, 0);
		world.setBlock(i + 10, j + 10, k + 0, 0);
		world.setBlock(i + 10, j + 10, k + 1, 0);
		world.setBlock(i + 10, j + 10, k + 2, 0);
		world.setBlock(i + 10, j + 10, k + 3, 0);
		world.setBlock(i + 10, j + 10, k + 4, 0);
		world.setBlock(i + 10, j + 10, k + 5, 0);
		world.setBlock(i + 10, j + 10, k + 6, 0);
		world.setBlock(i + 10, j + 10, k + 7, 0);
		world.setBlock(i + 10, j + 10, k + 8, 0);
		world.setBlock(i + 10, j + 10, k + 9, 0);
		world.setBlock(i + 10, j + 10, k + 10, 0);
		world.setBlock(i + 11, j + 0, k + 0, DivineRPGTwilight.dreamdirt.blockID);
		world.setBlock(i + 11, j + 0, k + 1, DivineRPGTwilight.dreamdirt.blockID);
		world.setBlock(i + 11, j + 0, k + 2, DivineRPGTwilight.dreamdirt.blockID);
		world.setBlock(i + 11, j + 0, k + 3, DivineRPGTwilight.dreamdirt.blockID);
		world.setBlock(i + 11, j + 0, k + 4, DivineRPGTwilight.dreamdirt.blockID);
		world.setBlock(i + 11, j + 0, k + 5, DivineRPGTwilight.cryptFloor.blockID);
		world.setBlock(i + 11, j + 0, k + 6, DivineRPGTwilight.cryptFloor.blockID);
		world.setBlock(i + 11, j + 0, k + 7, DivineRPGTwilight.cryptFloor.blockID);
		world.setBlock(i + 11, j + 0, k + 8, DivineRPGTwilight.cryptFloor.blockID);
		world.setBlock(i + 11, j + 0, k + 9, DivineRPGTwilight.dreamdirt.blockID);
		world.setBlock(i + 11, j + 0, k + 10, DivineRPGTwilight.dreamdirt.blockID);
		world.setBlock(i + 11, j + 1, k + 0, DivineRPGTwilight.dreamdirt.blockID);
		world.setBlock(i + 11, j + 1, k + 1, DivineRPGTwilight.dreamdirt.blockID);
		world.setBlock(i + 11, j + 1, k + 2, 0);
		world.setBlock(i + 11, j + 1, k + 3, DivineRPGTwilight.dreamdirt.blockID);
		world.setBlock(i + 11, j + 1, k + 4, DivineRPGTwilight.cryptWall.blockID);
		world.setBlock(i + 11, j + 1, k + 5, 0);
		world.setBlock(i + 11, j + 1, k + 6, 0);
		world.setBlock(i + 11, j + 1, k + 7, 0);
		world.setBlock(i + 11, j + 1, k + 8, 0);
		world.setBlock(i + 11, j + 1, k + 9, DivineRPGTwilight.cryptWall.blockID);
		world.setBlock(i + 11, j + 1, k + 10, DivineRPGTwilight.dreamdirt.blockID);
		world.setBlock(i + 11, j + 2, k + 0, DivineRPGTwilight.dreamdirt.blockID);
		world.setBlock(i + 11, j + 2, k + 1, DivineRPGTwilight.dreamdirt.blockID);
		world.setBlock(i + 11, j + 2, k + 2, DivineRPGTwilight.dreamdirt.blockID);
		world.setBlock(i + 11, j + 2, k + 3, DivineRPGTwilight.dreamdirt.blockID);
		world.setBlock(i + 11, j + 2, k + 4, DivineRPGTwilight.cryptWall.blockID);
		world.setBlock(i + 11, j + 2, k + 5, 0);
		world.setBlock(i + 11, j + 2, k + 6, 0);
		world.setBlock(i + 11, j + 2, k + 7, 0);
		world.setBlock(i + 11, j + 2, k + 8, 0);
		world.setBlock(i + 11, j + 2, k + 9, DivineRPGTwilight.cryptWall.blockID);
		world.setBlock(i + 11, j + 2, k + 10, DivineRPGTwilight.dreamdirt.blockID);
		world.setBlock(i + 11, j + 3, k + 0, DivineRPGTwilight.dreamdirt.blockID);
		world.setBlock(i + 11, j + 3, k + 1, DivineRPGTwilight.dreamdirt.blockID);
		world.setBlock(i + 11, j + 3, k + 2, DivineRPGTwilight.dreamdirt.blockID);
		world.setBlock(i + 11, j + 3, k + 3, DivineRPGTwilight.dreamdirt.blockID);
		world.setBlock(i + 11, j + 3, k + 4, DivineRPGTwilight.dreamdirt.blockID);
		world.setBlock(i + 11, j + 3, k + 5, DivineRPGTwilight.hungerstone2.blockID);
		world.setBlock(i + 11, j + 3, k + 6, DivineRPGTwilight.hungerstone2.blockID);
		world.setBlock(i + 11, j + 3, k + 7, DivineRPGTwilight.hungerstone2.blockID);
		world.setBlock(i + 11, j + 3, k + 8, DivineRPGTwilight.hungerstone2.blockID);
		world.setBlock(i + 11, j + 3, k + 9, DivineRPGTwilight.dreamdirt.blockID);
		world.setBlock(i + 11, j + 3, k + 10, DivineRPGTwilight.dreamdirt.blockID);
		world.setBlock(i + 11, j + 4, k + 0, DivineRPGTwilight.dreamdirt.blockID);
		world.setBlock(i + 11, j + 4, k + 1, DivineRPGTwilight.dreamdirt.blockID);
		world.setBlock(i + 11, j + 4, k + 2, DivineRPGTwilight.dreamdirt.blockID);
		world.setBlock(i + 11, j + 4, k + 3, DivineRPGTwilight.dreamdirt.blockID);
		world.setBlock(i + 11, j + 4, k + 4, DivineRPGTwilight.cryptWall.blockID);
		world.setBlock(i + 11, j + 4, k + 5, DivineRPGTwilight.cryptWall.blockID);
		world.setBlock(i + 11, j + 4, k + 6, DivineRPGTwilight.cryptWall.blockID);
		world.setBlock(i + 11, j + 4, k + 7, DivineRPGTwilight.cryptWall.blockID);
		world.setBlock(i + 11, j + 4, k + 8, DivineRPGTwilight.cryptWall.blockID);
		world.setBlock(i + 11, j + 4, k + 9, DivineRPGTwilight.dreamdirt.blockID);
		world.setBlock(i + 11, j + 4, k + 10, DivineRPGTwilight.dreamdirt.blockID);
		world.setBlock(i + 11, j + 5, k + 0, DivineRPGTwilight.metalCaging.blockID);
		world.setBlock(i + 11, j + 5, k + 1, 0);
		world.setBlock(i + 11, j + 5, k + 2, 0);
		world.setBlock(i + 11, j + 5, k + 3, 0);
		world.setBlock(i + 11, j + 5, k + 4, 0);
		world.setBlock(i + 11, j + 5, k + 5, 0);
		world.setBlock(i + 11, j + 5, k + 6, 0);
		world.setBlock(i + 11, j + 5, k + 7, 0);
		world.setBlock(i + 11, j + 5, k + 8, 0);
		world.setBlock(i + 11, j + 5, k + 9, 0);
		world.setBlock(i + 11, j + 5, k + 10, DivineRPGTwilight.metalCaging.blockID);
		world.setBlock(i + 11, j + 6, k + 0, DivineRPGTwilight.hungerstone1.blockID);
		world.setBlock(i + 11, j + 6, k + 1, 0);
		world.setBlock(i + 11, j + 6, k + 2, 0);
		world.setBlock(i + 11, j + 6, k + 3, 0);
		world.setBlock(i + 11, j + 6, k + 4, 0);
		world.setBlock(i + 11, j + 6, k + 5, 0);
		world.setBlock(i + 11, j + 6, k + 6, 0);
		world.setBlock(i + 11, j + 6, k + 7, 0);
		world.setBlock(i + 11, j + 6, k + 8, 0);
		world.setBlock(i + 11, j + 6, k + 9, 0);
		world.setBlock(i + 11, j + 6, k + 10, DivineRPGTwilight.hungerstone1.blockID);
		world.setBlock(i + 11, j + 7, k + 0, 0);
		world.setBlock(i + 11, j + 7, k + 1, 0);
		world.setBlock(i + 11, j + 7, k + 2, 0);
		world.setBlock(i + 11, j + 7, k + 3, 0);
		world.setBlock(i + 11, j + 7, k + 4, 0);
		world.setBlock(i + 11, j + 7, k + 5, 0);
		world.setBlock(i + 11, j + 7, k + 6, 0);
		world.setBlock(i + 11, j + 7, k + 7, 0);
		world.setBlock(i + 11, j + 7, k + 8, 0);
		world.setBlock(i + 11, j + 7, k + 9, 0);
		world.setBlock(i + 11, j + 7, k + 10, 0);
		world.setBlock(i + 11, j + 8, k + 0, 0);
		world.setBlock(i + 11, j + 8, k + 1, 0);
		world.setBlock(i + 11, j + 8, k + 2, 0);
		world.setBlock(i + 11, j + 8, k + 3, 0);
		world.setBlock(i + 11, j + 8, k + 4, 0);
		world.setBlock(i + 11, j + 8, k + 5, 0);
		world.setBlock(i + 11, j + 8, k + 6, 0);
		world.setBlock(i + 11, j + 8, k + 7, 0);
		world.setBlock(i + 11, j + 8, k + 8, 0);
		world.setBlock(i + 11, j + 8, k + 9, 0);
		world.setBlock(i + 11, j + 8, k + 10, 0);
		world.setBlock(i + 11, j + 9, k + 0, 0);
		world.setBlock(i + 11, j + 9, k + 1, 0);
		world.setBlock(i + 11, j + 9, k + 2, 0);
		world.setBlock(i + 11, j + 9, k + 3, 0);
		world.setBlock(i + 11, j + 9, k + 4, 0);
		world.setBlock(i + 11, j + 9, k + 5, 0);
		world.setBlock(i + 11, j + 9, k + 6, 0);
		world.setBlock(i + 11, j + 9, k + 7, 0);
		world.setBlock(i + 11, j + 9, k + 8, 0);
		world.setBlock(i + 11, j + 9, k + 9, 0);
		world.setBlock(i + 11, j + 9, k + 10, 0);
		world.setBlock(i + 11, j + 10, k + 0, 0);
		world.setBlock(i + 11, j + 10, k + 1, 0);
		world.setBlock(i + 11, j + 10, k + 2, 0);
		world.setBlock(i + 11, j + 10, k + 3, 0);
		world.setBlock(i + 11, j + 10, k + 4, 0);
		world.setBlock(i + 11, j + 10, k + 5, 0);
		world.setBlock(i + 11, j + 10, k + 6, 0);
		world.setBlock(i + 11, j + 10, k + 7, 0);
		world.setBlock(i + 11, j + 10, k + 8, 0);
		world.setBlock(i + 11, j + 10, k + 9, 0);
		world.setBlock(i + 11, j + 10, k + 10, 0);
		world.setBlock(i + 12, j + 0, k + 0, DivineRPGTwilight.dreamdirt.blockID);
		world.setBlock(i + 12, j + 0, k + 1, DivineRPGTwilight.dreamdirt.blockID);
		world.setBlock(i + 12, j + 0, k + 2, DivineRPGTwilight.dreamdirt.blockID);
		world.setBlock(i + 12, j + 0, k + 3, DivineRPGTwilight.dreamdirt.blockID);
		world.setBlock(i + 12, j + 0, k + 4, DivineRPGTwilight.dreamdirt.blockID);
		world.setBlock(i + 12, j + 0, k + 5, DivineRPGTwilight.cryptFloor.blockID);
		world.setBlock(i + 12, j + 0, k + 6, DivineRPGTwilight.cryptFloor.blockID);
		world.setBlock(i + 12, j + 0, k + 7, DivineRPGTwilight.cryptFloor.blockID);
		world.setBlock(i + 12, j + 0, k + 8, DivineRPGTwilight.cryptFloor.blockID);
		world.setBlock(i + 12, j + 0, k + 9, DivineRPGTwilight.dreamdirt.blockID);
		world.setBlock(i + 12, j + 0, k + 10, DivineRPGTwilight.dreamdirt.blockID);
		world.setBlock(i + 12, j + 1, k + 0, DivineRPGTwilight.dreamdirt.blockID);
		world.setBlock(i + 12, j + 1, k + 1, DivineRPGTwilight.cryptWall.blockID);
		world.setBlock(i + 12, j + 1, k + 2, DivineRPGTwilight.cryptWall.blockID);
		world.setBlock(i + 12, j + 1, k + 3, DivineRPGTwilight.cryptWall.blockID);
		world.setBlock(i + 12, j + 1, k + 4, DivineRPGTwilight.cryptWall.blockID);
		world.setBlock(i + 12, j + 1, k + 5, 0);
		world.setBlock(i + 12, j + 1, k + 6, 0);
		world.setBlock(i + 12, j + 1, k + 7, 0);
		world.setBlock(i + 12, j + 1, k + 8, 0);
		world.setBlock(i + 12, j + 1, k + 9, DivineRPGTwilight.cryptWall.blockID);
		world.setBlock(i + 12, j + 1, k + 10, DivineRPGTwilight.dreamdirt.blockID);
		world.setBlock(i + 12, j + 2, k + 0, DivineRPGTwilight.dreamdirt.blockID);
		world.setBlock(i + 12, j + 2, k + 1, DivineRPGTwilight.cryptWall.blockID);
		world.setBlock(i + 12, j + 2, k + 2, DivineRPGTwilight.cryptWall.blockID);
		world.setBlock(i + 12, j + 2, k + 3, DivineRPGTwilight.cryptWall.blockID);
		world.setBlock(i + 12, j + 2, k + 4, DivineRPGTwilight.cryptWall.blockID);
		world.setBlock(i + 12, j + 2, k + 5, 0);
		world.setBlock(i + 12, j + 2, k + 6, 0);
		world.setBlock(i + 12, j + 2, k + 7, 0);
		world.setBlock(i + 12, j + 2, k + 8, 0);
		world.setBlock(i + 12, j + 2, k + 9, DivineRPGTwilight.cryptWall.blockID);
		world.setBlock(i + 12, j + 2, k + 10, DivineRPGTwilight.dreamdirt.blockID);
		world.setBlock(i + 12, j + 3, k + 0, DivineRPGTwilight.dreamdirt.blockID);
		world.setBlock(i + 12, j + 3, k + 1, DivineRPGTwilight.dreamdirt.blockID);
		world.setBlock(i + 12, j + 3, k + 2, DivineRPGTwilight.dreamdirt.blockID);
		world.setBlock(i + 12, j + 3, k + 3, DivineRPGTwilight.dreamdirt.blockID);
		world.setBlock(i + 12, j + 3, k + 4, DivineRPGTwilight.dreamdirt.blockID);
		world.setBlock(i + 12, j + 3, k + 5, DivineRPGTwilight.hungerstone2.blockID);
		world.setBlock(i + 12, j + 3, k + 6, DivineRPGTwilight.hungerstone2.blockID);
		world.setBlock(i + 12, j + 3, k + 7, DivineRPGTwilight.hungerstone2.blockID);
		world.setBlock(i + 12, j + 3, k + 8, DivineRPGTwilight.hungerstone2.blockID);
		world.setBlock(i + 12, j + 3, k + 9, DivineRPGTwilight.dreamdirt.blockID);
		world.setBlock(i + 12, j + 3, k + 10, DivineRPGTwilight.dreamdirt.blockID);
		world.setBlock(i + 12, j + 4, k + 0, DivineRPGTwilight.dreamdirt.blockID);
		world.setBlock(i + 12, j + 4, k + 1, DivineRPGTwilight.dreamdirt.blockID);
		world.setBlock(i + 12, j + 4, k + 2, DivineRPGTwilight.dreamdirt.blockID);
		world.setBlock(i + 12, j + 4, k + 3, DivineRPGTwilight.dreamdirt.blockID);

		generate2(world, rand, i, j, k);
		return true;
	}

	public boolean generate2(World world, Random rand, int i, int j, int k) {
		world.setBlock(i + 12, j + 4, k + 4, DivineRPGTwilight.dreamdirt.blockID);
		world.setBlock(i + 12, j + 4, k + 5, DivineRPGTwilight.dreamdirt.blockID);
		world.setBlock(i + 12, j + 4, k + 6, DivineRPGTwilight.dreamdirt.blockID);
		world.setBlock(i + 12, j + 4, k + 7, DivineRPGTwilight.cryptWall.blockID);
		world.setBlock(i + 12, j + 4, k + 8, DivineRPGTwilight.cryptWall.blockID);
		world.setBlock(i + 12, j + 4, k + 9, DivineRPGTwilight.dreamdirt.blockID);
		world.setBlock(i + 12, j + 4, k + 10, DivineRPGTwilight.dreamdirt.blockID);
		world.setBlock(i + 12, j + 5, k + 0, DivineRPGTwilight.metalCaging.blockID);
		world.setBlock(i + 12, j + 5, k + 1, 0);
		world.setBlock(i + 12, j + 5, k + 2, 0);
		world.setBlock(i + 12, j + 5, k + 3, 0);
		world.setBlock(i + 12, j + 5, k + 4, 0);
		world.setBlock(i + 12, j + 5, k + 5, 0);
		world.setBlock(i + 12, j + 5, k + 6, 0);
		world.setBlock(i + 12, j + 5, k + 7, 0);
		world.setBlock(i + 12, j + 5, k + 8, 0);
		world.setBlock(i + 12, j + 5, k + 9, 0);
		world.setBlock(i + 12, j + 5, k + 10, DivineRPGTwilight.metalCaging.blockID);
		world.setBlock(i + 12, j + 6, k + 0, DivineRPGTwilight.hungerstone1.blockID);
		world.setBlock(i + 12, j + 6, k + 1, 0);
		world.setBlock(i + 12, j + 6, k + 2, 0);
		world.setBlock(i + 12, j + 6, k + 3, 0);
		world.setBlock(i + 12, j + 6, k + 4, 0);
		world.setBlock(i + 12, j + 6, k + 5, 0);
		world.setBlock(i + 12, j + 6, k + 6, 0);
		world.setBlock(i + 12, j + 6, k + 7, 0);
		world.setBlock(i + 12, j + 6, k + 8, 0);
		world.setBlock(i + 12, j + 6, k + 9, 0);
		world.setBlock(i + 12, j + 6, k + 10, DivineRPGTwilight.hungerstone1.blockID);
		world.setBlock(i + 12, j + 7, k + 0, 0);
		world.setBlock(i + 12, j + 7, k + 1, 0);
		world.setBlock(i + 12, j + 7, k + 2, 0);
		world.setBlock(i + 12, j + 7, k + 3, 0);
		world.setBlock(i + 12, j + 7, k + 4, 0);
		world.setBlock(i + 12, j + 7, k + 5, 0);
		world.setBlock(i + 12, j + 7, k + 6, 0);
		world.setBlock(i + 12, j + 7, k + 7, 0);
		world.setBlock(i + 12, j + 7, k + 8, 0);
		world.setBlock(i + 12, j + 7, k + 9, 0);
		world.setBlock(i + 12, j + 7, k + 10, 0);
		world.setBlock(i + 12, j + 8, k + 0, 0);
		world.setBlock(i + 12, j + 8, k + 1, 0);
		world.setBlock(i + 12, j + 8, k + 2, 0);
		world.setBlock(i + 12, j + 8, k + 3, 0);
		world.setBlock(i + 12, j + 8, k + 4, 0);
		world.setBlock(i + 12, j + 8, k + 5, 0);
		world.setBlock(i + 12, j + 8, k + 6, 0);
		world.setBlock(i + 12, j + 8, k + 7, 0);
		world.setBlock(i + 12, j + 8, k + 8, 0);
		world.setBlock(i + 12, j + 8, k + 9, 0);
		world.setBlock(i + 12, j + 8, k + 10, 0);
		world.setBlock(i + 12, j + 9, k + 0, 0);
		world.setBlock(i + 12, j + 9, k + 1, 0);
		world.setBlock(i + 12, j + 9, k + 2, 0);
		world.setBlock(i + 12, j + 9, k + 3, 0);
		world.setBlock(i + 12, j + 9, k + 4, 0);
		world.setBlock(i + 12, j + 9, k + 5, 0);
		world.setBlock(i + 12, j + 9, k + 6, 0);
		world.setBlock(i + 12, j + 9, k + 7, 0);
		world.setBlock(i + 12, j + 9, k + 8, 0);
		world.setBlock(i + 12, j + 9, k + 9, 0);
		world.setBlock(i + 12, j + 9, k + 10, 0);
		world.setBlock(i + 12, j + 10, k + 0, 0);
		world.setBlock(i + 12, j + 10, k + 1, 0);
		world.setBlock(i + 12, j + 10, k + 2, 0);
		world.setBlock(i + 12, j + 10, k + 3, 0);
		world.setBlock(i + 12, j + 10, k + 4, 0);
		world.setBlock(i + 12, j + 10, k + 5, 0);
		world.setBlock(i + 12, j + 10, k + 6, 0);
		world.setBlock(i + 12, j + 10, k + 7, 0);
		world.setBlock(i + 12, j + 10, k + 8, 0);
		world.setBlock(i + 12, j + 10, k + 9, 0);
		world.setBlock(i + 12, j + 10, k + 10, 0);
		world.setBlock(i + 13, j + 0, k + 0, DivineRPGTwilight.dreamdirt.blockID);
		world.setBlock(i + 13, j + 0, k + 1, DivineRPGTwilight.cryptFloor.blockID);
		world.setBlock(i + 13, j + 0, k + 2, DivineRPGTwilight.cryptFloor.blockID);
		world.setBlock(i + 13, j + 0, k + 3, DivineRPGTwilight.cryptFloor.blockID);
		world.setBlock(i + 13, j + 0, k + 4, DivineRPGTwilight.cryptFloor.blockID);
		world.setBlock(i + 13, j + 0, k + 5, DivineRPGTwilight.cryptFloor.blockID);
		world.setBlock(i + 13, j + 0, k + 6, DivineRPGTwilight.cryptFloor.blockID);
		world.setBlock(i + 13, j + 0, k + 7, DivineRPGTwilight.cryptFloor.blockID);
		world.setBlock(i + 13, j + 0, k + 8, DivineRPGTwilight.cryptFloor.blockID);
		world.setBlock(i + 13, j + 0, k + 9, DivineRPGTwilight.dreamdirt.blockID);
		world.setBlock(i + 13, j + 0, k + 10, DivineRPGTwilight.dreamdirt.blockID);
		world.setBlock(i + 13, j + 1, k + 0, DivineRPGTwilight.cryptWall.blockID);
		world.setBlock(i + 13, j + 1, k + 1, 0);
		world.setBlock(i + 13, j + 1, k + 2, 0);
		world.setBlock(i + 13, j + 1, k + 3, 0);
		world.setBlock(i + 13, j + 1, k + 4, 0);
		world.setBlock(i + 13, j + 1, k + 5, 0);
		world.setBlock(i + 13, j + 1, k + 6, 0);
		world.setBlock(i + 13, j + 1, k + 7, 0);
		world.setBlock(i + 13, j + 1, k + 8, 0);
		world.setBlock(i + 13, j + 1, k + 9, DivineRPGTwilight.cryptWall.blockID);
		world.setBlock(i + 13, j + 1, k + 10, DivineRPGTwilight.dreamdirt.blockID);
		world.setBlock(i + 13, j + 2, k + 0, DivineRPGTwilight.cryptWall.blockID);
		world.setBlock(i + 13, j + 2, k + 1, 0);
		world.setBlock(i + 13, j + 2, k + 2, 0);
		world.setBlock(i + 13, j + 2, k + 3, 0);
		world.setBlock(i + 13, j + 2, k + 4, 0);
		world.setBlock(i + 13, j + 2, k + 5, 0);
		world.setBlock(i + 13, j + 2, k + 6, 0);
		world.setBlock(i + 13, j + 2, k + 7, 0);
		world.setBlock(i + 13, j + 2, k + 8, 0);
		world.setBlock(i + 13, j + 2, k + 9, DivineRPGTwilight.cryptWall.blockID);
		world.setBlock(i + 13, j + 2, k + 10, DivineRPGTwilight.dreamdirt.blockID);
		world.setBlock(i + 13, j + 3, k + 0, DivineRPGTwilight.dreamdirt.blockID);
		world.setBlock(i + 13, j + 3, k + 1, DivineRPGTwilight.hungerstone2.blockID);
		world.setBlock(i + 13, j + 3, k + 2, DivineRPGTwilight.hungerstone2.blockID);
		world.setBlock(i + 13, j + 3, k + 3, DivineRPGTwilight.hungerstone2.blockID);
		world.setBlock(i + 13, j + 3, k + 4, DivineRPGTwilight.hungerstone2.blockID);
		world.setBlock(i + 13, j + 3, k + 5, DivineRPGTwilight.hungerstone2.blockID);
		world.setBlock(i + 13, j + 3, k + 6, DivineRPGTwilight.hungerstone2.blockID);
		world.setBlock(i + 13, j + 3, k + 7, DivineRPGTwilight.hungerstone2.blockID);
		world.setBlock(i + 13, j + 3, k + 8, DivineRPGTwilight.hungerstone2.blockID);
		world.setBlock(i + 13, j + 3, k + 9, DivineRPGTwilight.dreamdirt.blockID);
		world.setBlock(i + 13, j + 3, k + 10, DivineRPGTwilight.dreamdirt.blockID);
		world.setBlock(i + 13, j + 4, k + 0, DivineRPGTwilight.dreamdirt.blockID);
		world.setBlock(i + 13, j + 4, k + 1, DivineRPGTwilight.dreamdirt.blockID);
		world.setBlock(i + 13, j + 4, k + 2, DivineRPGTwilight.dreamdirt.blockID);
		world.setBlock(i + 13, j + 4, k + 3, DivineRPGTwilight.dreamdirt.blockID);
		world.setBlock(i + 13, j + 4, k + 4, DivineRPGTwilight.dreamdirt.blockID);
		world.setBlock(i + 13, j + 4, k + 5, DivineRPGTwilight.dreamdirt.blockID);
		world.setBlock(i + 13, j + 4, k + 6, DivineRPGTwilight.dreamdirt.blockID);
		world.setBlock(i + 13, j + 4, k + 7, DivineRPGTwilight.cryptWall.blockID);
		world.setBlock(i + 13, j + 4, k + 8, DivineRPGTwilight.cryptWall.blockID);
		world.setBlock(i + 13, j + 4, k + 9, DivineRPGTwilight.dreamdirt.blockID);
		world.setBlock(i + 13, j + 4, k + 10, DivineRPGTwilight.dreamdirt.blockID);
		world.setBlock(i + 13, j + 5, k + 0, DivineRPGTwilight.metalCaging.blockID);
		world.setBlock(i + 13, j + 5, k + 1, 0);
		world.setBlock(i + 13, j + 5, k + 2, 0);
		world.setBlock(i + 13, j + 5, k + 3, DivineRPGTwilight.hungerstone1.blockID);
		world.setBlock(i + 13, j + 5, k + 4, DivineRPGTwilight.hungerstone1.blockID);
		world.setBlock(i + 13, j + 5, k + 5, DivineRPGTwilight.hungerstone1.blockID);
		world.setBlock(i + 13, j + 5, k + 6, 0);
		world.setBlock(i + 13, j + 5, k + 7, 0);
		world.setBlock(i + 13, j + 5, k + 8, 0);
		world.setBlock(i + 13, j + 5, k + 9, 0);
		world.setBlock(i + 13, j + 5, k + 10, DivineRPGTwilight.metalCaging.blockID);
		world.setBlock(i + 13, j + 6, k + 0, DivineRPGTwilight.hungerstone1.blockID);
		world.setBlock(i + 13, j + 6, k + 1, 0);
		world.setBlock(i + 13, j + 6, k + 2, 0);
		world.setBlock(i + 13, j + 6, k + 3, 0);
		world.setBlock(i + 13, j + 6, k + 4, 0);
		world.setBlock(i + 13, j + 6, k + 5, 0);
		world.setBlock(i + 13, j + 6, k + 6, 0);
		world.setBlock(i + 13, j + 6, k + 7, 0);
		world.setBlock(i + 13, j + 6, k + 8, 0);
		world.setBlock(i + 13, j + 6, k + 9, 0);
		world.setBlock(i + 13, j + 6, k + 10, DivineRPGTwilight.hungerstone1.blockID);
		world.setBlock(i + 13, j + 7, k + 0, 0);
		world.setBlock(i + 13, j + 7, k + 1, 0);
		world.setBlock(i + 13, j + 7, k + 2, 0);
		world.setBlock(i + 13, j + 7, k + 3, 0);
		world.setBlock(i + 13, j + 7, k + 4, 0);
		world.setBlock(i + 13, j + 7, k + 5, 0);
		world.setBlock(i + 13, j + 7, k + 6, 0);
		world.setBlock(i + 13, j + 7, k + 7, 0);
		world.setBlock(i + 13, j + 7, k + 8, 0);
		world.setBlock(i + 13, j + 7, k + 9, 0);
		world.setBlock(i + 13, j + 7, k + 10, 0);
		world.setBlock(i + 13, j + 8, k + 0, 0);
		world.setBlock(i + 13, j + 8, k + 1, 0);
		world.setBlock(i + 13, j + 8, k + 2, 0);
		world.setBlock(i + 13, j + 8, k + 3, 0);
		world.setBlock(i + 13, j + 8, k + 4, 0);
		world.setBlock(i + 13, j + 8, k + 5, 0);
		world.setBlock(i + 13, j + 8, k + 6, 0);
		world.setBlock(i + 13, j + 8, k + 7, 0);
		world.setBlock(i + 13, j + 8, k + 8, 0);
		world.setBlock(i + 13, j + 8, k + 9, 0);
		world.setBlock(i + 13, j + 8, k + 10, 0);
		world.setBlock(i + 13, j + 9, k + 0, 0);
		world.setBlock(i + 13, j + 9, k + 1, 0);
		world.setBlock(i + 13, j + 9, k + 2, 0);
		world.setBlock(i + 13, j + 9, k + 3, 0);
		world.setBlock(i + 13, j + 9, k + 4, 0);
		world.setBlock(i + 13, j + 9, k + 5, 0);
		world.setBlock(i + 13, j + 9, k + 6, 0);
		world.setBlock(i + 13, j + 9, k + 7, 0);
		world.setBlock(i + 13, j + 9, k + 8, 0);
		world.setBlock(i + 13, j + 9, k + 9, 0);
		world.setBlock(i + 13, j + 9, k + 10, 0);
		world.setBlock(i + 13, j + 10, k + 0, 0);
		world.setBlock(i + 13, j + 10, k + 1, 0);
		world.setBlock(i + 13, j + 10, k + 2, 0);
		world.setBlock(i + 13, j + 10, k + 3, 0);
		world.setBlock(i + 13, j + 10, k + 4, 0);
		world.setBlock(i + 13, j + 10, k + 5, 0);
		world.setBlock(i + 13, j + 10, k + 6, 0);
		world.setBlock(i + 13, j + 10, k + 7, 0);
		world.setBlock(i + 13, j + 10, k + 8, 0);
		world.setBlock(i + 13, j + 10, k + 9, 0);
		world.setBlock(i + 13, j + 10, k + 10, 0);
		world.setBlock(i + 14, j + 0, k + 0, DivineRPGTwilight.dreamdirt.blockID);
		world.setBlock(i + 14, j + 0, k + 1, DivineRPGTwilight.cryptFloor.blockID);
		world.setBlock(i + 14, j + 0, k + 2, DivineRPGTwilight.dreamdirt.blockID);
