/*
*** MADE BY MITHION'S .SCHEMATIC TO JAVA CONVERTING TOOL v1.6 ***
*/

package xolova.divinerpg.worldgen.vethea.layer1;
import java.util.Random;

import net.minecraft.entity.EntityLiving;
import net.minecraft.world.World;
import net.minecraft.world.gen.feature.WorldGenerator;
import xolova.divinerpg.entities.vethea.mobs.EntityCryptKeeper;
import xolova.divinerpg.utils.helpers.block.VetheaBlockHelper;

public class Crypt1 extends WorldGenerator
{
	public Crypt1() { }

	public boolean generate(World world, Random rand, int i, int j, int k) {		
		world.setBlock(i + 0, j + 0, k + 0, VetheaBlockHelper.dreamdirt.blockID);
		world.setBlock(i + 0, j + 0, k + 1, VetheaBlockHelper.dreamdirt.blockID);
		world.setBlock(i + 0, j + 0, k + 2, VetheaBlockHelper.dreamdirt.blockID);
		world.setBlock(i + 0, j + 0, k + 3, VetheaBlockHelper.dreamdirt.blockID);
		world.setBlock(i + 0, j + 0, k + 4, VetheaBlockHelper.dreamdirt.blockID);
		world.setBlock(i + 0, j + 0, k + 5, VetheaBlockHelper.dreamdirt.blockID);
		world.setBlock(i + 0, j + 0, k + 6, VetheaBlockHelper.dreamdirt.blockID);
		world.setBlock(i + 0, j + 0, k + 7, VetheaBlockHelper.dreamdirt.blockID);
		world.setBlock(i + 0, j + 0, k + 8, VetheaBlockHelper.dreamdirt.blockID);
		world.setBlock(i + 0, j + 0, k + 9, VetheaBlockHelper.dreamdirt.blockID);
		world.setBlock(i + 0, j + 0, k + 10, VetheaBlockHelper.dreamdirt.blockID);
		world.setBlock(i + 0, j + 0, k + 11, VetheaBlockHelper.dreamdirt.blockID);
		world.setBlock(i + 0, j + 0, k + 12, VetheaBlockHelper.dreamdirt.blockID);
		world.setBlock(i + 0, j + 0, k + 13, VetheaBlockHelper.dreamdirt.blockID);
		world.setBlock(i + 0, j + 0, k + 14, VetheaBlockHelper.dreamdirt.blockID);
		world.setBlock(i + 0, j + 0, k + 15, VetheaBlockHelper.dreamdirt.blockID);
		world.setBlock(i + 0, j + 0, k + 16, VetheaBlockHelper.dreamdirt.blockID);
		world.setBlock(i + 0, j + 0, k + 17, VetheaBlockHelper.dreamdirt.blockID);
		world.setBlock(i + 0, j + 0, k + 18, VetheaBlockHelper.dreamdirt.blockID);
		world.setBlock(i + 0, j + 0, k + 19, VetheaBlockHelper.dreamdirt.blockID);
		world.setBlock(i + 0, j + 1, k + 0, VetheaBlockHelper.dreamdirt.blockID);
		world.setBlock(i + 0, j + 1, k + 1, VetheaBlockHelper.dreamdirt.blockID);
		world.setBlock(i + 0, j + 1, k + 2, VetheaBlockHelper.dreamdirt.blockID);
		world.setBlock(i + 0, j + 1, k + 3, VetheaBlockHelper.dreamdirt.blockID);
		world.setBlock(i + 0, j + 1, k + 4, VetheaBlockHelper.dreamdirt.blockID);
		world.setBlock(i + 0, j + 1, k + 5, VetheaBlockHelper.dreamdirt.blockID);
		world.setBlock(i + 0, j + 1, k + 6, VetheaBlockHelper.dreamdirt.blockID);
		world.setBlock(i + 0, j + 1, k + 7, VetheaBlockHelper.dreamdirt.blockID);
		world.setBlock(i + 0, j + 1, k + 8, VetheaBlockHelper.dreamdirt.blockID);
		world.setBlock(i + 0, j + 1, k + 9, VetheaBlockHelper.dreamdirt.blockID);
		world.setBlock(i + 0, j + 1, k + 10, VetheaBlockHelper.dreamdirt.blockID);
		world.setBlock(i + 0, j + 1, k + 11, VetheaBlockHelper.dreamdirt.blockID);
		world.setBlock(i + 0, j + 1, k + 12, VetheaBlockHelper.dreamdirt.blockID);
		world.setBlock(i + 0, j + 1, k + 13, VetheaBlockHelper.dreamdirt.blockID);
		world.setBlock(i + 0, j + 1, k + 14, VetheaBlockHelper.dreamdirt.blockID);
		world.setBlock(i + 0, j + 1, k + 15, VetheaBlockHelper.dreamdirt.blockID);
		world.setBlock(i + 0, j + 1, k + 16, VetheaBlockHelper.dreamdirt.blockID);
		world.setBlock(i + 0, j + 1, k + 17, VetheaBlockHelper.dreamdirt.blockID);
		world.setBlock(i + 0, j + 1, k + 18, VetheaBlockHelper.dreamdirt.blockID);
		world.setBlock(i + 0, j + 1, k + 19, VetheaBlockHelper.dreamdirt.blockID);
		world.setBlock(i + 0, j + 2, k + 0, VetheaBlockHelper.dreamdirt.blockID);
		world.setBlock(i + 0, j + 2, k + 1, VetheaBlockHelper.dreamdirt.blockID);
		world.setBlock(i + 0, j + 2, k + 2, VetheaBlockHelper.dreamdirt.blockID);
		world.setBlock(i + 0, j + 2, k + 3, VetheaBlockHelper.dreamdirt.blockID);
		world.setBlock(i + 0, j + 2, k + 4, VetheaBlockHelper.dreamdirt.blockID);
		world.setBlock(i + 0, j + 2, k + 5, VetheaBlockHelper.dreamdirt.blockID);
		world.setBlock(i + 0, j + 2, k + 6, VetheaBlockHelper.dreamdirt.blockID);
		world.setBlock(i + 0, j + 2, k + 7, VetheaBlockHelper.dreamdirt.blockID);
		world.setBlock(i + 0, j + 2, k + 8, VetheaBlockHelper.dreamdirt.blockID);
		world.setBlock(i + 0, j + 2, k + 9, VetheaBlockHelper.dreamdirt.blockID);
		world.setBlock(i + 0, j + 2, k + 10, VetheaBlockHelper.dreamdirt.blockID);
		world.setBlock(i + 0, j + 2, k + 11, VetheaBlockHelper.dreamdirt.blockID);
		world.setBlock(i + 0, j + 2, k + 12, VetheaBlockHelper.dreamdirt.blockID);
		world.setBlock(i + 0, j + 2, k + 13, VetheaBlockHelper.dreamdirt.blockID);
		world.setBlock(i + 0, j + 2, k + 14, VetheaBlockHelper.dreamdirt.blockID);
		world.setBlock(i + 0, j + 2, k + 15, VetheaBlockHelper.dreamdirt.blockID);
		world.setBlock(i + 0, j + 2, k + 16, VetheaBlockHelper.dreamdirt.blockID);
		world.setBlock(i + 0, j + 2, k + 17, VetheaBlockHelper.dreamdirt.blockID);
		world.setBlock(i + 0, j + 2, k + 18, VetheaBlockHelper.dreamdirt.blockID);
		world.setBlock(i + 0, j + 2, k + 19, VetheaBlockHelper.dreamdirt.blockID);
		world.setBlock(i + 0, j + 3, k + 0, VetheaBlockHelper.dreamdirt.blockID);
		world.setBlock(i + 0, j + 3, k + 1, VetheaBlockHelper.dreamdirt.blockID);
		world.setBlock(i + 0, j + 3, k + 2, VetheaBlockHelper.dreamdirt.blockID);
		world.setBlock(i + 0, j + 3, k + 3, VetheaBlockHelper.dreamdirt.blockID);
		world.setBlock(i + 0, j + 3, k + 4, VetheaBlockHelper.dreamdirt.blockID);
		world.setBlock(i + 0, j + 3, k + 5, VetheaBlockHelper.dreamdirt.blockID);
		world.setBlock(i + 0, j + 3, k + 6, VetheaBlockHelper.dreamdirt.blockID);
		world.setBlock(i + 0, j + 3, k + 7, VetheaBlockHelper.dreamdirt.blockID);
		world.setBlock(i + 0, j + 3, k + 8, VetheaBlockHelper.dreamdirt.blockID);
		world.setBlock(i + 0, j + 3, k + 9, VetheaBlockHelper.dreamdirt.blockID);
		world.setBlock(i + 0, j + 3, k + 10, VetheaBlockHelper.dreamdirt.blockID);
		world.setBlock(i + 0, j + 3, k + 11, VetheaBlockHelper.dreamdirt.blockID);
		world.setBlock(i + 0, j + 3, k + 12, VetheaBlockHelper.dreamdirt.blockID);
		world.setBlock(i + 0, j + 3, k + 13, VetheaBlockHelper.dreamdirt.blockID);
		world.setBlock(i + 0, j + 3, k + 14, VetheaBlockHelper.dreamdirt.blockID);
		world.setBlock(i + 0, j + 3, k + 15, VetheaBlockHelper.dreamdirt.blockID);
		world.setBlock(i + 0, j + 3, k + 16, VetheaBlockHelper.dreamdirt.blockID);
		world.setBlock(i + 0, j + 3, k + 17, VetheaBlockHelper.dreamdirt.blockID);
		world.setBlock(i + 0, j + 3, k + 18, VetheaBlockHelper.dreamdirt.blockID);
		world.setBlock(i + 0, j + 3, k + 19, VetheaBlockHelper.dreamdirt.blockID);
		world.setBlock(i + 0, j + 4, k + 0, VetheaBlockHelper.dreamdirt.blockID);
		world.setBlock(i + 0, j + 4, k + 1, VetheaBlockHelper.dreamdirt.blockID);
		world.setBlock(i + 0, j + 4, k + 2, VetheaBlockHelper.dreamdirt.blockID);
		world.setBlock(i + 0, j + 4, k + 3, VetheaBlockHelper.dreamdirt.blockID);
		world.setBlock(i + 0, j + 4, k + 4, VetheaBlockHelper.dreamdirt.blockID);
		world.setBlock(i + 0, j + 4, k + 5, VetheaBlockHelper.dreamdirt.blockID);
		world.setBlock(i + 0, j + 4, k + 6, VetheaBlockHelper.dreamdirt.blockID);
		world.setBlock(i + 0, j + 4, k + 7, VetheaBlockHelper.dreamdirt.blockID);
		world.setBlock(i + 0, j + 4, k + 8, VetheaBlockHelper.dreamdirt.blockID);
		world.setBlock(i + 0, j + 4, k + 9, VetheaBlockHelper.dreamdirt.blockID);
		world.setBlock(i + 0, j + 4, k + 10, VetheaBlockHelper.dreamdirt.blockID);
		world.setBlock(i + 0, j + 4, k + 11, VetheaBlockHelper.dreamdirt.blockID);
		world.setBlock(i + 0, j + 4, k + 12, VetheaBlockHelper.dreamdirt.blockID);
		world.setBlock(i + 0, j + 4, k + 13, VetheaBlockHelper.dreamdirt.blockID);
		world.setBlock(i + 0, j + 4, k + 14, VetheaBlockHelper.dreamdirt.blockID);
		world.setBlock(i + 0, j + 4, k + 15, VetheaBlockHelper.dreamdirt.blockID);
		world.setBlock(i + 0, j + 4, k + 16, VetheaBlockHelper.dreamdirt.blockID);
		world.setBlock(i + 0, j + 4, k + 17, VetheaBlockHelper.dreamdirt.blockID);
		world.setBlock(i + 0, j + 4, k + 18, VetheaBlockHelper.dreamdirt.blockID);
		world.setBlock(i + 0, j + 4, k + 19, VetheaBlockHelper.dreamdirt.blockID);
		world.setBlock(i + 0, j + 5, k + 0, VetheaBlockHelper.dreamdirt.blockID);
		world.setBlock(i + 0, j + 5, k + 1, VetheaBlockHelper.dreamdirt.blockID);
		world.setBlock(i + 0, j + 5, k + 2, VetheaBlockHelper.dreamdirt.blockID);
		world.setBlock(i + 0, j + 5, k + 3, VetheaBlockHelper.cryptWall.blockID);
		world.setBlock(i + 0, j + 5, k + 4, VetheaBlockHelper.cryptWall.blockID);
		world.setBlock(i + 0, j + 5, k + 5, VetheaBlockHelper.dreamdirt.blockID);
		world.setBlock(i + 0, j + 5, k + 6, VetheaBlockHelper.dreamdirt.blockID);
		world.setBlock(i + 0, j + 5, k + 7, VetheaBlockHelper.dreamdirt.blockID);
		world.setBlock(i + 0, j + 5, k + 8, VetheaBlockHelper.dreamdirt.blockID);
		world.setBlock(i + 0, j + 5, k + 9, VetheaBlockHelper.dreamdirt.blockID);
		world.setBlock(i + 0, j + 5, k + 10, VetheaBlockHelper.dreamdirt.blockID);
		world.setBlock(i + 0, j + 5, k + 11, VetheaBlockHelper.dreamdirt.blockID);
		world.setBlock(i + 0, j + 5, k + 12, VetheaBlockHelper.dreamdirt.blockID);
		world.setBlock(i + 0, j + 5, k + 13, VetheaBlockHelper.dreamdirt.blockID);
		world.setBlock(i + 0, j + 5, k + 14, VetheaBlockHelper.cryptWall.blockID);
		world.setBlock(i + 0, j + 5, k + 15, VetheaBlockHelper.cryptWall.blockID);
		world.setBlock(i + 0, j + 5, k + 16, VetheaBlockHelper.dreamdirt.blockID);
		world.setBlock(i + 0, j + 5, k + 17, VetheaBlockHelper.dreamdirt.blockID);
		world.setBlock(i + 0, j + 5, k + 18, VetheaBlockHelper.dreamdirt.blockID);
		world.setBlock(i + 0, j + 5, k + 19, VetheaBlockHelper.dreamdirt.blockID);
		world.setBlock(i + 0, j + 6, k + 0, VetheaBlockHelper.metalCaging.blockID);
		world.setBlock(i + 0, j + 6, k + 1, VetheaBlockHelper.metalCaging.blockID);
		world.setBlock(i + 0, j + 6, k + 2, VetheaBlockHelper.hungerstone1.blockID);
		world.setBlock(i + 0, j + 6, k + 3, 0);
		world.setBlock(i + 0, j + 6, k + 4, 0);
		world.setBlock(i + 0, j + 6, k + 5, VetheaBlockHelper.hungerstone1.blockID);
		world.setBlock(i + 0, j + 6, k + 6, VetheaBlockHelper.metalCaging.blockID);
		world.setBlock(i + 0, j + 6, k + 7, VetheaBlockHelper.metalCaging.blockID);
		world.setBlock(i + 0, j + 6, k + 8, VetheaBlockHelper.metalCaging.blockID);
		world.setBlock(i + 0, j + 6, k + 9, VetheaBlockHelper.metalCaging.blockID);
		world.setBlock(i + 0, j + 6, k + 10, VetheaBlockHelper.metalCaging.blockID);
		world.setBlock(i + 0, j + 6, k + 11, VetheaBlockHelper.metalCaging.blockID);
		world.setBlock(i + 0, j + 6, k + 12, VetheaBlockHelper.metalCaging.blockID);
		world.setBlock(i + 0, j + 6, k + 13, VetheaBlockHelper.hungerstone1.blockID);
		world.setBlock(i + 0, j + 6, k + 14, 0);
		world.setBlock(i + 0, j + 6, k + 15, 0);
		world.setBlock(i + 0, j + 6, k + 16, VetheaBlockHelper.hungerstone1.blockID);
		world.setBlock(i + 0, j + 6, k + 17, VetheaBlockHelper.metalCaging.blockID);
		world.setBlock(i + 0, j + 6, k + 18, VetheaBlockHelper.metalCaging.blockID);
		world.setBlock(i + 0, j + 6, k + 19, VetheaBlockHelper.metalCaging.blockID);
		world.setBlock(i + 0, j + 7, k + 0, VetheaBlockHelper.hungerstone1.blockID);
		world.setBlock(i + 0, j + 7, k + 1, VetheaBlockHelper.hungerstone1.blockID);
		world.setBlock(i + 0, j + 7, k + 2, VetheaBlockHelper.hungerstone1.blockID);
		world.setBlock(i + 0, j + 7, k + 3, 0);
		world.setBlock(i + 0, j + 7, k + 4, 0);
		world.setBlock(i + 0, j + 7, k + 5, VetheaBlockHelper.hungerstone1.blockID);
		world.setBlock(i + 0, j + 7, k + 6, VetheaBlockHelper.hungerstone1.blockID);
		world.setBlock(i + 0, j + 7, k + 7, VetheaBlockHelper.hungerstone1.blockID);
		world.setBlock(i + 0, j + 7, k + 8, VetheaBlockHelper.hungerstone1.blockID);
		world.setBlock(i + 0, j + 7, k + 9, VetheaBlockHelper.hungerstone1.blockID);
		world.setBlock(i + 0, j + 7, k + 10, VetheaBlockHelper.hungerstone1.blockID);
		world.setBlock(i + 0, j + 7, k + 11, VetheaBlockHelper.hungerstone1.blockID);
		world.setBlock(i + 0, j + 7, k + 12, VetheaBlockHelper.hungerstone1.blockID);
		world.setBlock(i + 0, j + 7, k + 13, VetheaBlockHelper.hungerstone1.blockID);
		world.setBlock(i + 0, j + 7, k + 14, 0);
		world.setBlock(i + 0, j + 7, k + 15, 0);
		world.setBlock(i + 0, j + 7, k + 16, VetheaBlockHelper.hungerstone1.blockID);
		world.setBlock(i + 0, j + 7, k + 17, VetheaBlockHelper.hungerstone1.blockID);
		world.setBlock(i + 0, j + 7, k + 18, VetheaBlockHelper.hungerstone1.blockID);
		world.setBlock(i + 0, j + 7, k + 19, VetheaBlockHelper.hungerstone1.blockID);
		world.setBlock(i + 0, j + 8, k + 0, 0);
		world.setBlock(i + 0, j + 8, k + 1, 0);
		world.setBlock(i + 0, j + 8, k + 2, VetheaBlockHelper.hungerstone1.blockID);
		world.setBlock(i + 0, j + 8, k + 3, VetheaBlockHelper.hungerstone1.blockID);
		world.setBlock(i + 0, j + 8, k + 4, VetheaBlockHelper.hungerstone1.blockID);
		world.setBlock(i + 0, j + 8, k + 5, VetheaBlockHelper.hungerstone1.blockID);
		world.setBlock(i + 0, j + 8, k + 6, 0);
		world.setBlock(i + 0, j + 8, k + 7, 0);
		world.setBlock(i + 0, j + 8, k + 8, 0);
		world.setBlock(i + 0, j + 8, k + 9, 0);
		world.setBlock(i + 0, j + 8, k + 10, 0);
		world.setBlock(i + 0, j + 8, k + 11, 0);
		world.setBlock(i + 0, j + 8, k + 12, 0);
		world.setBlock(i + 0, j + 8, k + 13, VetheaBlockHelper.hungerstone1.blockID);
		world.setBlock(i + 0, j + 8, k + 14, VetheaBlockHelper.hungerstone1.blockID);
		world.setBlock(i + 0, j + 8, k + 15, VetheaBlockHelper.hungerstone1.blockID);
		world.setBlock(i + 0, j + 8, k + 16, VetheaBlockHelper.hungerstone1.blockID);
		world.setBlock(i + 0, j + 8, k + 17, 0);
		world.setBlock(i + 0, j + 8, k + 18, 0);
		world.setBlock(i + 0, j + 8, k + 19, 0);
		world.setBlock(i + 0, j + 9, k + 0, 0);
		world.setBlock(i + 0, j + 9, k + 1, 0);
		world.setBlock(i + 0, j + 9, k + 2, 0);
		world.setBlock(i + 0, j + 9, k + 3, 0);
		world.setBlock(i + 0, j + 9, k + 4, 0);
		world.setBlock(i + 0, j + 9, k + 5, 0);
		world.setBlock(i + 0, j + 9, k + 6, 0);
		world.setBlock(i + 0, j + 9, k + 7, 0);
		world.setBlock(i + 0, j + 9, k + 8, 0);
		world.setBlock(i + 0, j + 9, k + 9, 0);
		world.setBlock(i + 0, j + 9, k + 10, 0);
		world.setBlock(i + 0, j + 9, k + 11, 0);
		world.setBlock(i + 0, j + 9, k + 12, 0);
		world.setBlock(i + 0, j + 9, k + 13, 0);
		world.setBlock(i + 0, j + 9, k + 14, 0);
		world.setBlock(i + 0, j + 9, k + 15, 0);
		world.setBlock(i + 0, j + 9, k + 16, 0);
		world.setBlock(i + 0, j + 9, k + 17, 0);
		world.setBlock(i + 0, j + 9, k + 18, 0);
		world.setBlock(i + 0, j + 9, k + 19, 0);
		world.setBlock(i + 0, j + 10, k + 0, 0);
		world.setBlock(i + 0, j + 10, k + 1, 0);
		world.setBlock(i + 0, j + 10, k + 2, 0);
		world.setBlock(i + 0, j + 10, k + 3, 0);
		world.setBlock(i + 0, j + 10, k + 4, 0);
		world.setBlock(i + 0, j + 10, k + 5, 0);
		world.setBlock(i + 0, j + 10, k + 6, 0);
		world.setBlock(i + 0, j + 10, k + 7, 0);
		world.setBlock(i + 0, j + 10, k + 8, 0);
		world.setBlock(i + 0, j + 10, k + 9, 0);
		world.setBlock(i + 0, j + 10, k + 10, 0);
		world.setBlock(i + 0, j + 10, k + 11, 0);
		world.setBlock(i + 0, j + 10, k + 12, 0);
		world.setBlock(i + 0, j + 10, k + 13, 0);
		world.setBlock(i + 0, j + 10, k + 14, 0);
		world.setBlock(i + 0, j + 10, k + 15, 0);
		world.setBlock(i + 0, j + 10, k + 16, 0);
		world.setBlock(i + 0, j + 10, k + 17, 0);
		world.setBlock(i + 0, j + 10, k + 18, 0);
		world.setBlock(i + 0, j + 10, k + 19, 0);
		world.setBlock(i + 1, j + 0, k + 0, VetheaBlockHelper.dreamdirt.blockID);
		world.setBlock(i + 1, j + 0, k + 1, VetheaBlockHelper.dreamdirt.blockID);
		world.setBlock(i + 1, j + 0, k + 2, VetheaBlockHelper.dreamdirt.blockID);
		world.setBlock(i + 1, j + 0, k + 3, VetheaBlockHelper.dreamdirt.blockID);
		world.setBlock(i + 1, j + 0, k + 4, VetheaBlockHelper.dreamdirt.blockID);
		world.setBlock(i + 1, j + 0, k + 5, VetheaBlockHelper.dreamdirt.blockID);
		world.setBlock(i + 1, j + 0, k + 6, VetheaBlockHelper.dreamdirt.blockID);
		world.setBlock(i + 1, j + 0, k + 7, VetheaBlockHelper.dreamdirt.blockID);
		world.setBlock(i + 1, j + 0, k + 8, VetheaBlockHelper.dreamdirt.blockID);
		world.setBlock(i + 1, j + 0, k + 9, VetheaBlockHelper.dreamdirt.blockID);
		world.setBlock(i + 1, j + 0, k + 10, VetheaBlockHelper.cryptWall.blockID);
		world.setBlock(i + 1, j + 0, k + 11, VetheaBlockHelper.cryptWall.blockID);
		world.setBlock(i + 1, j + 0, k + 12, VetheaBlockHelper.cryptWall.blockID);
		world.setBlock(i + 1, j + 0, k + 13, VetheaBlockHelper.dreamdirt.blockID);
		world.setBlock(i + 1, j + 0, k + 14, VetheaBlockHelper.dreamdirt.blockID);
		world.setBlock(i + 1, j + 0, k + 15, VetheaBlockHelper.dreamdirt.blockID);
		world.setBlock(i + 1, j + 0, k + 16, VetheaBlockHelper.dreamdirt.blockID);
		world.setBlock(i + 1, j + 0, k + 17, VetheaBlockHelper.dreamdirt.blockID);
		world.setBlock(i + 1, j + 0, k + 18, VetheaBlockHelper.dreamdirt.blockID);
		world.setBlock(i + 1, j + 0, k + 19, VetheaBlockHelper.dreamdirt.blockID);
		world.setBlock(i + 1, j + 1, k + 0, VetheaBlockHelper.dreamdirt.blockID);
		world.setBlock(i + 1, j + 1, k + 1, VetheaBlockHelper.dreamdirt.blockID);
		world.setBlock(i + 1, j + 1, k + 2, VetheaBlockHelper.dreamdirt.blockID);
		world.setBlock(i + 1, j + 1, k + 3, VetheaBlockHelper.dreamdirt.blockID);
		world.setBlock(i + 1, j + 1, k + 4, VetheaBlockHelper.dreamdirt.blockID);
		world.setBlock(i + 1, j + 1, k + 5, VetheaBlockHelper.dreamdirt.blockID);
		world.setBlock(i + 1, j + 1, k + 6, VetheaBlockHelper.dreamdirt.blockID);
		world.setBlock(i + 1, j + 1, k + 7, VetheaBlockHelper.dreamdirt.blockID);
		world.setBlock(i + 1, j + 1, k + 8, VetheaBlockHelper.dreamdirt.blockID);
		world.setBlock(i + 1, j + 1, k + 9, VetheaBlockHelper.dreamdirt.blockID);
		world.setBlock(i + 1, j + 1, k + 10, VetheaBlockHelper.cryptWall.blockID);
		world.setBlock(i + 1, j + 1, k + 11, VetheaBlockHelper.cryptWall.blockID);
		world.setBlock(i + 1, j + 1, k + 12, VetheaBlockHelper.cryptWall.blockID);
		world.setBlock(i + 1, j + 1, k + 13, VetheaBlockHelper.cryptWall.blockID);
		world.setBlock(i + 1, j + 1, k + 14, VetheaBlockHelper.cryptWall.blockID);
		world.setBlock(i + 1, j + 1, k + 15, VetheaBlockHelper.cryptWall.blockID);
		world.setBlock(i + 1, j + 1, k + 16, VetheaBlockHelper.dreamdirt.blockID);
		world.setBlock(i + 1, j + 1, k + 17, VetheaBlockHelper.dreamdirt.blockID);
		world.setBlock(i + 1, j + 1, k + 18, VetheaBlockHelper.dreamdirt.blockID);
		world.setBlock(i + 1, j + 1, k + 19, VetheaBlockHelper.dreamdirt.blockID);
		world.setBlock(i + 1, j + 2, k + 0, VetheaBlockHelper.dreamdirt.blockID);
		world.setBlock(i + 1, j + 2, k + 1, VetheaBlockHelper.dreamdirt.blockID);
		world.setBlock(i + 1, j + 2, k + 2, VetheaBlockHelper.dreamdirt.blockID);
		world.setBlock(i + 1, j + 2, k + 3, VetheaBlockHelper.dreamdirt.blockID);
		world.setBlock(i + 1, j + 2, k + 4, VetheaBlockHelper.dreamdirt.blockID);
		world.setBlock(i + 1, j + 2, k + 5, VetheaBlockHelper.dreamdirt.blockID);
		world.setBlock(i + 1, j + 2, k + 6, VetheaBlockHelper.dreamdirt.blockID);
		world.setBlock(i + 1, j + 2, k + 7, VetheaBlockHelper.dreamdirt.blockID);
		world.setBlock(i + 1, j + 2, k + 8, VetheaBlockHelper.dreamdirt.blockID);
		world.setBlock(i + 1, j + 2, k + 9, VetheaBlockHelper.dreamdirt.blockID);
		world.setBlock(i + 1, j + 2, k + 10, VetheaBlockHelper.cryptWall.blockID);
		world.setBlock(i + 1, j + 2, k + 11, VetheaBlockHelper.cryptWall.blockID);
		world.setBlock(i + 1, j + 2, k + 12, VetheaBlockHelper.cryptWall.blockID);
		world.setBlock(i + 1, j + 2, k + 13, VetheaBlockHelper.cryptWall.blockID);
		world.setBlock(i + 1, j + 2, k + 14, VetheaBlockHelper.cryptWall.blockID);
		world.setBlock(i + 1, j + 2, k + 15, VetheaBlockHelper.cryptWall.blockID);
		world.setBlock(i + 1, j + 2, k + 16, VetheaBlockHelper.dreamdirt.blockID);
		world.setBlock(i + 1, j + 2, k + 17, VetheaBlockHelper.dreamdirt.blockID);
		world.setBlock(i + 1, j + 2, k + 18, VetheaBlockHelper.dreamdirt.blockID);
		world.setBlock(i + 1, j + 2, k + 19, VetheaBlockHelper.dreamdirt.blockID);
		world.setBlock(i + 1, j + 3, k + 0, VetheaBlockHelper.dreamdirt.blockID);
		world.setBlock(i + 1, j + 3, k + 1, VetheaBlockHelper.dreamdirt.blockID);
		world.setBlock(i + 1, j + 3, k + 2, VetheaBlockHelper.dreamdirt.blockID);
		world.setBlock(i + 1, j + 3, k + 3, VetheaBlockHelper.dreamdirt.blockID);
		world.setBlock(i + 1, j + 3, k + 4, VetheaBlockHelper.dreamdirt.blockID);
		world.setBlock(i + 1, j + 3, k + 5, VetheaBlockHelper.dreamdirt.blockID);
		world.setBlock(i + 1, j + 3, k + 6, VetheaBlockHelper.dreamdirt.blockID);
		world.setBlock(i + 1, j + 3, k + 7, VetheaBlockHelper.dreamdirt.blockID);
		world.setBlock(i + 1, j + 3, k + 8, VetheaBlockHelper.dreamdirt.blockID);
		world.setBlock(i + 1, j + 3, k + 9, VetheaBlockHelper.dreamdirt.blockID);
		world.setBlock(i + 1, j + 3, k + 10, VetheaBlockHelper.cryptWall.blockID);
		world.setBlock(i + 1, j + 3, k + 11, VetheaBlockHelper.cryptWall.blockID);
		world.setBlock(i + 1, j + 3, k + 12, VetheaBlockHelper.cryptWall.blockID);
		world.setBlock(i + 1, j + 3, k + 13, VetheaBlockHelper.cryptWall.blockID);
		world.setBlock(i + 1, j + 3, k + 14, VetheaBlockHelper.cryptWall.blockID);
		world.setBlock(i + 1, j + 3, k + 15, VetheaBlockHelper.cryptWall.blockID);
		world.setBlock(i + 1, j + 3, k + 16, VetheaBlockHelper.dreamdirt.blockID);
		world.setBlock(i + 1, j + 3, k + 17, VetheaBlockHelper.dreamdirt.blockID);
		world.setBlock(i + 1, j + 3, k + 18, VetheaBlockHelper.dreamdirt.blockID);
		world.setBlock(i + 1, j + 3, k + 19, VetheaBlockHelper.dreamdirt.blockID);
		world.setBlock(i + 1, j + 4, k + 0, VetheaBlockHelper.dreamdirt.blockID);
		world.setBlock(i + 1, j + 4, k + 1, VetheaBlockHelper.dreamdirt.blockID);
		world.setBlock(i + 1, j + 4, k + 2, VetheaBlockHelper.dreamdirt.blockID);
		world.setBlock(i + 1, j + 4, k + 3, VetheaBlockHelper.dreamdirt.blockID);
		world.setBlock(i + 1, j + 4, k + 4, VetheaBlockHelper.dreamdirt.blockID);
		world.setBlock(i + 1, j + 4, k + 5, VetheaBlockHelper.dreamdirt.blockID);
		world.setBlock(i + 1, j + 4, k + 6, VetheaBlockHelper.dreamdirt.blockID);
		world.setBlock(i + 1, j + 4, k + 7, VetheaBlockHelper.dreamdirt.blockID);
		world.setBlock(i + 1, j + 4, k + 8, VetheaBlockHelper.dreamdirt.blockID);
		world.setBlock(i + 1, j + 4, k + 9, VetheaBlockHelper.dreamdirt.blockID);
		world.setBlock(i + 1, j + 4, k + 10, VetheaBlockHelper.dreamdirt.blockID);
		world.setBlock(i + 1, j + 4, k + 11, VetheaBlockHelper.dreamdirt.blockID);
		world.setBlock(i + 1, j + 4, k + 12, VetheaBlockHelper.dreamdirt.blockID);
		world.setBlock(i + 1, j + 4, k + 13, VetheaBlockHelper.dreamdirt.blockID);
		world.setBlock(i + 1, j + 4, k + 14, VetheaBlockHelper.dreamdirt.blockID);
		world.setBlock(i + 1, j + 4, k + 15, VetheaBlockHelper.dreamdirt.blockID);
		world.setBlock(i + 1, j + 4, k + 16, VetheaBlockHelper.dreamdirt.blockID);
		world.setBlock(i + 1, j + 4, k + 17, VetheaBlockHelper.dreamdirt.blockID);
		world.setBlock(i + 1, j + 4, k + 18, VetheaBlockHelper.dreamdirt.blockID);
		world.setBlock(i + 1, j + 4, k + 19, VetheaBlockHelper.dreamdirt.blockID);
		world.setBlock(i + 1, j + 5, k + 0, VetheaBlockHelper.dreamdirt.blockID);
		world.setBlock(i + 1, j + 5, k + 1, VetheaBlockHelper.dreamdirt.blockID);
		world.setBlock(i + 1, j + 5, k + 2, VetheaBlockHelper.dreamdirt.blockID);
		world.setBlock(i + 1, j + 5, k + 3, VetheaBlockHelper.cryptWall.blockID);
		world.setBlock(i + 1, j + 5, k + 4, VetheaBlockHelper.cryptWall.blockID);
		world.setBlock(i + 1, j + 5, k + 5, VetheaBlockHelper.dreamdirt.blockID);
		world.setBlock(i + 1, j + 5, k + 6, VetheaBlockHelper.dreamdirt.blockID);
		world.setBlock(i + 1, j + 5, k + 7, VetheaBlockHelper.dreamdirt.blockID);
		world.setBlock(i + 1, j + 5, k + 8, VetheaBlockHelper.dreamdirt.blockID);
		world.setBlock(i + 1, j + 5, k + 9, VetheaBlockHelper.dreamdirt.blockID);
		world.setBlock(i + 1, j + 5, k + 10, VetheaBlockHelper.dreamdirt.blockID);
		world.setBlock(i + 1, j + 5, k + 11, VetheaBlockHelper.dreamdirt.blockID);
		world.setBlock(i + 1, j + 5, k + 12, VetheaBlockHelper.dreamdirt.blockID);
		world.setBlock(i + 1, j + 5, k + 13, VetheaBlockHelper.dreamdirt.blockID);
		world.setBlock(i + 1, j + 5, k + 14, VetheaBlockHelper.cryptWall.blockID);
		world.setBlock(i + 1, j + 5, k + 15, VetheaBlockHelper.cryptWall.blockID);
		world.setBlock(i + 1, j + 5, k + 16, VetheaBlockHelper.dreamdirt.blockID);
		world.setBlock(i + 1, j + 5, k + 17, VetheaBlockHelper.dreamdirt.blockID);
		world.setBlock(i + 1, j + 5, k + 18, VetheaBlockHelper.dreamdirt.blockID);
		world.setBlock(i + 1, j + 5, k + 19, VetheaBlockHelper.dreamdirt.blockID);
		world.setBlock(i + 1, j + 6, k + 0, VetheaBlockHelper.metalCaging.blockID);
		world.setBlock(i + 1, j + 6, k + 1, 0);
		world.setBlock(i + 1, j + 6, k + 2, 0);
		world.setBlock(i + 1, j + 6, k + 3, 0);
		world.setBlock(i + 1, j + 6, k + 4, 0);
		world.setBlock(i + 1, j + 6, k + 5, 0);
		world.setBlock(i + 1, j + 6, k + 6, 0);
		world.setBlock(i + 1, j + 6, k + 7, 0);
		world.setBlock(i + 1, j + 6, k + 8, 0);
		world.setBlock(i + 1, j + 6, k + 9, 0);
		world.setBlock(i + 1, j + 6, k + 10, 0);
		world.setBlock(i + 1, j + 6, k + 11, 0);
		world.setBlock(i + 1, j + 6, k + 12, 0);
		world.setBlock(i + 1, j + 6, k + 13, 0);
		world.setBlock(i + 1, j + 6, k + 14, 0);
		world.setBlock(i + 1, j + 6, k + 15, 0);
		world.setBlock(i + 1, j + 6, k + 16, 0);
		world.setBlock(i + 1, j + 6, k + 17, 0);
		world.setBlock(i + 1, j + 6, k + 18, 0);
		world.setBlock(i + 1, j + 6, k + 19, VetheaBlockHelper.metalCaging.blockID);
		world.setBlock(i + 1, j + 7, k + 0, VetheaBlockHelper.hungerstone1.blockID);
		world.setBlock(i + 1, j + 7, k + 1, 0);
		world.setBlock(i + 1, j + 7, k + 2, 0);
		world.setBlock(i + 1, j + 7, k + 3, 0);
		world.setBlock(i + 1, j + 7, k + 4, 0);
		world.setBlock(i + 1, j + 7, k + 5, 0);
		world.setBlock(i + 1, j + 7, k + 6, 0);
		world.setBlock(i + 1, j + 7, k + 7, 0);
		world.setBlock(i + 1, j + 7, k + 8, 0);
		world.setBlock(i + 1, j + 7, k + 9, 0);
		world.setBlock(i + 1, j + 7, k + 10, 0);
		world.setBlock(i + 1, j + 7, k + 11, 0);
		world.setBlock(i + 1, j + 7, k + 12, 0);
		world.setBlock(i + 1, j + 7, k + 13, 0);
		world.setBlock(i + 1, j + 7, k + 14, 0);
		world.setBlock(i + 1, j + 7, k + 15, 0);
		world.setBlock(i + 1, j + 7, k + 16, 0);
		world.setBlock(i + 1, j + 7, k + 17, 0);
		world.setBlock(i + 1, j + 7, k + 18, 0);
		world.setBlock(i + 1, j + 7, k + 19, VetheaBlockHelper.hungerstone1.blockID);
		world.setBlock(i + 1, j + 8, k + 0, 0);
		world.setBlock(i + 1, j + 8, k + 1, 0);
		world.setBlock(i + 1, j + 8, k + 2, 0);
		world.setBlock(i + 1, j + 8, k + 3, 0);
		world.setBlock(i + 1, j + 8, k + 4, 0);
		world.setBlock(i + 1, j + 8, k + 5, 0);
		world.setBlock(i + 1, j + 8, k + 6, 0);
		world.setBlock(i + 1, j + 8, k + 7, 0);
		world.setBlock(i + 1, j + 8, k + 8, 0);
		world.setBlock(i + 1, j + 8, k + 9, 0);
		world.setBlock(i + 1, j + 8, k + 10, 0);
		world.setBlock(i + 1, j + 8, k + 11, 0);
		world.setBlock(i + 1, j + 8, k + 12, 0);
		world.setBlock(i + 1, j + 8, k + 13, 0);
		world.setBlock(i + 1, j + 8, k + 14, 0);
		world.setBlock(i + 1, j + 8, k + 15, 0);
		world.setBlock(i + 1, j + 8, k + 16, 0);
		world.setBlock(i + 1, j + 8, k + 17, 0);
		world.setBlock(i + 1, j + 8, k + 18, 0);
		world.setBlock(i + 1, j + 8, k + 19, 0);
		world.setBlock(i + 1, j + 9, k + 0, 0);
		world.setBlock(i + 1, j + 9, k + 1, 0);
		world.setBlock(i + 1, j + 9, k + 2, 0);
		world.setBlock(i + 1, j + 9, k + 3, 0);
		world.setBlock(i + 1, j + 9, k + 4, 0);
		world.setBlock(i + 1, j + 9, k + 5, 0);
		world.setBlock(i + 1, j + 9, k + 6, 0);
		world.setBlock(i + 1, j + 9, k + 7, 0);
		world.setBlock(i + 1, j + 9, k + 8, 0);
		world.setBlock(i + 1, j + 9, k + 9, 0);
		world.setBlock(i + 1, j + 9, k + 10, 0);
		world.setBlock(i + 1, j + 9, k + 11, 0);
		world.setBlock(i + 1, j + 9, k + 12, 0);
		world.setBlock(i + 1, j + 9, k + 13, 0);
		world.setBlock(i + 1, j + 9, k + 14, 0);
		world.setBlock(i + 1, j + 9, k + 15, 0);
		world.setBlock(i + 1, j + 9, k + 16, 0);
		world.setBlock(i + 1, j + 9, k + 17, 0);
		world.setBlock(i + 1, j + 9, k + 18, 0);
		world.setBlock(i + 1, j + 9, k + 19, 0);
		world.setBlock(i + 1, j + 10, k + 0, 0);
		world.setBlock(i + 1, j + 10, k + 1, 0);
		world.setBlock(i + 1, j + 10, k + 2, 0);
		world.setBlock(i + 1, j + 10, k + 3, 0);
		world.setBlock(i + 1, j + 10, k + 4, 0);
		world.setBlock(i + 1, j + 10, k + 5, 0);
		world.setBlock(i + 1, j + 10, k + 6, 0);
		world.setBlock(i + 1, j + 10, k + 7, 0);
		world.setBlock(i + 1, j + 10, k + 8, 0);
		world.setBlock(i + 1, j + 10, k + 9, 0);
		world.setBlock(i + 1, j + 10, k + 10, 0);
		world.setBlock(i + 1, j + 10, k + 11, 0);
		world.setBlock(i + 1, j + 10, k + 12, 0);
		world.setBlock(i + 1, j + 10, k + 13, 0);
		world.setBlock(i + 1, j + 10, k + 14, 0);
		world.setBlock(i + 1, j + 10, k + 15, 0);
		world.setBlock(i + 1, j + 10, k + 16, 0);
		world.setBlock(i + 1, j + 10, k + 17, 0);
		world.setBlock(i + 1, j + 10, k + 18, 0);
		world.setBlock(i + 1, j + 10, k + 19, 0);
		world.setBlock(i + 2, j + 0, k + 0, VetheaBlockHelper.dreamdirt.blockID);
		world.setBlock(i + 2, j + 0, k + 1, VetheaBlockHelper.cryptWall.blockID);
		world.setBlock(i + 2, j + 0, k + 2, VetheaBlockHelper.cryptWall.blockID);
		world.setBlock(i + 2, j + 0, k + 3, VetheaBlockHelper.cryptWall.blockID);
		world.setBlock(i + 2, j + 0, k + 4, VetheaBlockHelper.cryptWall.blockID);
		world.setBlock(i + 2, j + 0, k + 5, VetheaBlockHelper.cryptWall.blockID);
		world.setBlock(i + 2, j + 0, k + 6, VetheaBlockHelper.cryptWall.blockID);
		world.setBlock(i + 2, j + 0, k + 7, VetheaBlockHelper.cryptWall.blockID);
		world.setBlock(i + 2, j + 0, k + 8, VetheaBlockHelper.cryptWall.blockID);
		world.setBlock(i + 2, j + 0, k + 9, VetheaBlockHelper.cryptWall.blockID);
		world.setBlock(i + 2, j + 0, k + 10, 0);
		world.setBlock(i + 2, j + 0, k + 11, 0);
		world.setBlock(i + 2, j + 0, k + 12, 0);
		world.setBlock(i + 2, j + 0, k + 13, VetheaBlockHelper.cryptFloor.blockID);
		world.setBlock(i + 2, j + 0, k + 14, VetheaBlockHelper.cryptFloor.blockID);
		world.setBlock(i + 2, j + 0, k + 15, VetheaBlockHelper.cryptFloor.blockID);
		world.setBlock(i + 2, j + 0, k + 16, VetheaBlockHelper.dreamdirt.blockID);
		world.setBlock(i + 2, j + 0, k + 17, VetheaBlockHelper.dreamdirt.blockID);
		world.setBlock(i + 2, j + 0, k + 18, VetheaBlockHelper.dreamdirt.blockID);
		world.setBlock(i + 2, j + 0, k + 19, VetheaBlockHelper.dreamdirt.blockID);
		world.setBlock(i + 2, j + 1, k + 0, VetheaBlockHelper.dreamdirt.blockID);
		world.setBlock(i + 2, j + 1, k + 1, VetheaBlockHelper.cryptWall.blockID);
		world.setBlock(i + 2, j + 1, k + 2, VetheaBlockHelper.cryptWall.blockID);
		world.setBlock(i + 2, j + 1, k + 3, VetheaBlockHelper.cryptWall.blockID);
		world.setBlock(i + 2, j + 1, k + 4, VetheaBlockHelper.cryptWall.blockID);
		world.setBlock(i + 2, j + 1, k + 5, VetheaBlockHelper.cryptWall.blockID);
		world.setBlock(i + 2, j + 1, k + 6, VetheaBlockHelper.cryptWall.blockID);
		world.setBlock(i + 2, j + 1, k + 7, VetheaBlockHelper.cryptWall.blockID);
		world.setBlock(i + 2, j + 1, k + 8, VetheaBlockHelper.cryptWall.blockID);
		world.setBlock(i + 2, j + 1, k + 9, VetheaBlockHelper.cryptWall.blockID);
		world.setBlock(i + 2, j + 1, k + 10, 0);
		world.setBlock(i + 2, j + 1, k + 11, 0);
		world.setBlock(i + 2, j + 1, k + 12, 0);
		world.setBlock(i + 2, j + 1, k + 13, 0);
		world.setBlock(i + 2, j + 1, k + 14, 0);
		world.setBlock(i + 2, j + 1, k + 15, VetheaBlockHelper.biphronSpawner.blockID);
		world.setBlock(i + 2, j + 1, k + 16, VetheaBlockHelper.cryptWall.blockID);
		world.setBlock(i + 2, j + 1, k + 17, VetheaBlockHelper.dreamdirt.blockID);
		world.setBlock(i + 2, j + 1, k + 18, VetheaBlockHelper.dreamdirt.blockID);
		world.setBlock(i + 2, j + 1, k + 19, VetheaBlockHelper.dreamdirt.blockID);
		world.setBlock(i + 2, j + 2, k + 0, VetheaBlockHelper.dreamdirt.blockID);
		world.setBlock(i + 2, j + 2, k + 1, VetheaBlockHelper.cryptWall.blockID);
		world.setBlock(i + 2, j + 2, k + 2, VetheaBlockHelper.cryptWall.blockID);
		world.setBlock(i + 2, j + 2, k + 3, VetheaBlockHelper.cryptWall.blockID);
		world.setBlock(i + 2, j + 2, k + 4, VetheaBlockHelper.cryptWall.blockID);
		world.setBlock(i + 2, j + 2, k + 5, VetheaBlockHelper.cryptWall.blockID);
		world.setBlock(i + 2, j + 2, k + 6, VetheaBlockHelper.cryptWall.blockID);
		world.setBlock(i + 2, j + 2, k + 7, VetheaBlockHelper.cryptWall.blockID);
		world.setBlock(i + 2, j + 2, k + 8, VetheaBlockHelper.cryptWall.blockID);
		world.setBlock(i + 2, j + 2, k + 9, VetheaBlockHelper.cryptWall.blockID);
		world.setBlock(i + 2, j + 2, k + 10, 0);
		world.setBlock(i + 2, j + 2, k + 11, 0);
		world.setBlock(i + 2, j + 2, k + 12, 0);
		world.setBlock(i + 2, j + 2, k + 13, 0);
		world.setBlock(i + 2, j + 2, k + 14, 0);
		world.setBlock(i + 2, j + 2, k + 15, 0);
		world.setBlock(i + 2, j + 2, k + 16, VetheaBlockHelper.cryptWall.blockID);
		world.setBlock(i + 2, j + 2, k + 17, VetheaBlockHelper.dreamdirt.blockID);
		world.setBlock(i + 2, j + 2, k + 18, VetheaBlockHelper.dreamdirt.blockID);
		world.setBlock(i + 2, j + 2, k + 19, VetheaBlockHelper.dreamdirt.blockID);
		world.setBlock(i + 2, j + 3, k + 0, VetheaBlockHelper.dreamdirt.blockID);
		world.setBlock(i + 2, j + 3, k + 1, VetheaBlockHelper.dreamdirt.blockID);
		world.setBlock(i + 2, j + 3, k + 2, VetheaBlockHelper.dreamdirt.blockID);
		world.setBlock(i + 2, j + 3, k + 3, VetheaBlockHelper.dreamdirt.blockID);
		world.setBlock(i + 2, j + 3, k + 4, VetheaBlockHelper.dreamdirt.blockID);
		world.setBlock(i + 2, j + 3, k + 5, VetheaBlockHelper.dreamdirt.blockID);
		world.setBlock(i + 2, j + 3, k + 6, VetheaBlockHelper.dreamdirt.blockID);
		world.setBlock(i + 2, j + 3, k + 7, VetheaBlockHelper.dreamdirt.blockID);
		world.setBlock(i + 2, j + 3, k + 8, VetheaBlockHelper.dreamdirt.blockID);
		world.setBlock(i + 2, j + 3, k + 9, VetheaBlockHelper.cryptWall.blockID);
		world.setBlock(i + 2, j + 3, k + 10, 0);
		world.setBlock(i + 2, j + 3, k + 11, 0);
		world.setBlock(i + 2, j + 3, k + 12, 0);
		world.setBlock(i + 2, j + 3, k + 13, 0);
		world.setBlock(i + 2, j + 3, k + 14, 0);
		world.setBlock(i + 2, j + 3, k + 15, 0);
		world.setBlock(i + 2, j + 3, k + 16, VetheaBlockHelper.cryptWall.blockID);
		world.setBlock(i + 2, j + 3, k + 17, VetheaBlockHelper.dreamdirt.blockID);
		world.setBlock(i + 2, j + 3, k + 18, VetheaBlockHelper.dreamdirt.blockID);
		world.setBlock(i + 2, j + 3, k + 19, VetheaBlockHelper.dreamdirt.blockID);
		world.setBlock(i + 2, j + 4, k + 0, VetheaBlockHelper.dreamdirt.blockID);
		world.setBlock(i + 2, j + 4, k + 1, VetheaBlockHelper.dreamdirt.blockID);
		world.setBlock(i + 2, j + 4, k + 2, VetheaBlockHelper.dreamdirt.blockID);
		world.setBlock(i + 2, j + 4, k + 3, VetheaBlockHelper.dreamdirt.blockID);
		world.setBlock(i + 2, j + 4, k + 4, VetheaBlockHelper.dreamdirt.blockID);
		world.setBlock(i + 2, j + 4, k + 5, VetheaBlockHelper.dreamdirt.blockID);
		world.setBlock(i + 2, j + 4, k + 6, VetheaBlockHelper.dreamdirt.blockID);
		world.setBlock(i + 2, j + 4, k + 7, VetheaBlockHelper.dreamdirt.blockID);
		world.setBlock(i + 2, j + 4, k + 8, VetheaBlockHelper.dreamdirt.blockID);
		world.setBlock(i + 2, j + 4, k + 9, VetheaBlockHelper.dreamdirt.blockID);
		world.setBlock(i + 2, j + 4, k + 10, VetheaBlockHelper.hungerstone2.blockID);
		world.setBlock(i + 2, j + 4, k + 11, VetheaBlockHelper.hungerstone2.blockID);
		world.setBlock(i + 2, j + 4, k + 12, VetheaBlockHelper.hungerstone2.blockID);
		world.setBlock(i + 2, j + 4, k + 13, VetheaBlockHelper.hungerstone2.blockID);
		world.setBlock(i + 2, j + 4, k + 14, VetheaBlockHelper.hungerstone2.blockID);
		world.setBlock(i + 2, j + 4, k + 15, VetheaBlockHelper.hungerstone2.blockID);
		world.setBlock(i + 2, j + 4, k + 16, VetheaBlockHelper.dreamdirt.blockID);
		world.setBlock(i + 2, j + 4, k + 17, VetheaBlockHelper.dreamdirt.blockID);
		world.setBlock(i + 2, j + 4, k + 18, VetheaBlockHelper.dreamdirt.blockID);
		world.setBlock(i + 2, j + 4, k + 19, VetheaBlockHelper.dreamdirt.blockID);
		world.setBlock(i + 2, j + 5, k + 0, VetheaBlockHelper.dreamdirt.blockID);
		world.setBlock(i + 2, j + 5, k + 1, VetheaBlockHelper.dreamdirt.blockID);
		world.setBlock(i + 2, j + 5, k + 2, VetheaBlockHelper.dreamdirt.blockID);
		world.setBlock(i + 2, j + 5, k + 3, VetheaBlockHelper.cryptWall.blockID);
		world.setBlock(i + 2, j + 5, k + 4, VetheaBlockHelper.cryptWall.blockID);
		world.setBlock(i + 2, j + 5, k + 5, VetheaBlockHelper.dreamdirt.blockID);
		world.setBlock(i + 2, j + 5, k + 6, VetheaBlockHelper.dreamdirt.blockID);
		world.setBlock(i + 2, j + 5, k + 7, VetheaBlockHelper.dreamdirt.blockID);
		world.setBlock(i + 2, j + 5, k + 8, VetheaBlockHelper.dreamdirt.blockID);
		world.setBlock(i + 2, j + 5, k + 9, VetheaBlockHelper.dreamdirt.blockID);
		world.setBlock(i + 2, j + 5, k + 10, VetheaBlockHelper.dreamdirt.blockID);
		world.setBlock(i + 2, j + 5, k + 11, VetheaBlockHelper.dreamdirt.blockID);
		world.setBlock(i + 2, j + 5, k + 12, VetheaBlockHelper.dreamdirt.blockID);
		world.setBlock(i + 2, j + 5, k + 13, VetheaBlockHelper.dreamdirt.blockID);
		world.setBlock(i + 2, j + 5, k + 14, VetheaBlockHelper.cryptWall.blockID);
		world.setBlock(i + 2, j + 5, k + 15, VetheaBlockHelper.cryptWall.blockID);
		world.setBlock(i + 2, j + 5, k + 16, VetheaBlockHelper.dreamdirt.blockID);
		world.setBlock(i + 2, j + 5, k + 17, VetheaBlockHelper.dreamdirt.blockID);
		world.setBlock(i + 2, j + 5, k + 18, VetheaBlockHelper.dreamdirt.blockID);
		world.setBlock(i + 2, j + 5, k + 19, VetheaBlockHelper.dreamdirt.blockID);
		world.setBlock(i + 2, j + 6, k + 0, VetheaBlockHelper.metalCaging.blockID);
		world.setBlock(i + 2, j + 6, k + 1, 0);
		world.setBlock(i + 2, j + 6, k + 2, 0);
		world.setBlock(i + 2, j + 6, k + 3, 0);
		world.setBlock(i + 2, j + 6, k + 4, 0);
		world.setBlock(i + 2, j + 6, k + 5, 0);
		world.setBlock(i + 2, j + 6, k + 6, 0);
		world.setBlock(i + 2, j + 6, k + 7, 0);
		world.setBlock(i + 2, j + 6, k + 8, 0);
		world.setBlock(i + 2, j + 6, k + 9, 0);
		world.setBlock(i + 2, j + 6, k + 10, 0);
		world.setBlock(i + 2, j + 6, k + 11, 0);
		world.setBlock(i + 2, j + 6, k + 12, 0);
		world.setBlock(i + 2, j + 6, k + 13, 0);
		world.setBlock(i + 2, j + 6, k + 14, 0);
		world.setBlock(i + 2, j + 6, k + 15, 0);
		world.setBlock(i + 2, j + 6, k + 16, 0);
		world.setBlock(i + 2, j + 6, k + 17, 0);
		world.setBlock(i + 2, j + 6, k + 18, 0);
		world.setBlock(i + 2, j + 6, k + 19, VetheaBlockHelper.metalCaging.blockID);
		world.setBlock(i + 2, j + 7, k + 0, VetheaBlockHelper.hungerstone1.blockID);
		world.setBlock(i + 2, j + 7, k + 1, 0);
		world.setBlock(i + 2, j + 7, k + 2, 0);
		world.setBlock(i + 2, j + 7, k + 3, 0);
		world.setBlock(i + 2, j + 7, k + 4, 0);
		world.setBlock(i + 2, j + 7, k + 5, 0);
		world.setBlock(i + 2, j + 7, k + 6, 0);
		world.setBlock(i + 2, j + 7, k + 7, 0);
		world.setBlock(i + 2, j + 7, k + 8, 0);
		world.setBlock(i + 2, j + 7, k + 9, 0);
		world.setBlock(i + 2, j + 7, k + 10, 0);
		world.setBlock(i + 2, j + 7, k + 11, 0);
		world.setBlock(i + 2, j + 7, k + 12, 0);
		world.setBlock(i + 2, j + 7, k + 13, 0);
		world.setBlock(i + 2, j + 7, k + 14, 0);
		world.setBlock(i + 2, j + 7, k + 15, 0);
		world.setBlock(i + 2, j + 7, k + 16, 0);
		world.setBlock(i + 2, j + 7, k + 17, 0);
		world.setBlock(i + 2, j + 7, k + 18, 0);
		world.setBlock(i + 2, j + 7, k + 19, VetheaBlockHelper.hungerstone1.blockID);
		world.setBlock(i + 2, j + 8, k + 0, 0);
		world.setBlock(i + 2, j + 8, k + 1, 0);
		world.setBlock(i + 2, j + 8, k + 2, 0);
		world.setBlock(i + 2, j + 8, k + 3, 0);
		world.setBlock(i + 2, j + 8, k + 4, 0);
		world.setBlock(i + 2, j + 8, k + 5, 0);
		world.setBlock(i + 2, j + 8, k + 6, 0);
		world.setBlock(i + 2, j + 8, k + 7, 0);
		world.setBlock(i + 2, j + 8, k + 8, 0);
		world.setBlock(i + 2, j + 8, k + 9, 0);
		world.setBlock(i + 2, j + 8, k + 10, 0);
		world.setBlock(i + 2, j + 8, k + 11, 0);
		world.setBlock(i + 2, j + 8, k + 12, 0);
		world.setBlock(i + 2, j + 8, k + 13, 0);
		world.setBlock(i + 2, j + 8, k + 14, 0);
		world.setBlock(i + 2, j + 8, k + 15, 0);
		world.setBlock(i + 2, j + 8, k + 16, 0);
		world.setBlock(i + 2, j + 8, k + 17, 0);
		world.setBlock(i + 2, j + 8, k + 18, 0);
		world.setBlock(i + 2, j + 8, k + 19, 0);
		world.setBlock(i + 2, j + 9, k + 0, 0);
		world.setBlock(i + 2, j + 9, k + 1, 0);
		world.setBlock(i + 2, j + 9, k + 2, 0);
		world.setBlock(i + 2, j + 9, k + 3, 0);
		world.setBlock(i + 2, j + 9, k + 4, 0);
		world.setBlock(i + 2, j + 9, k + 5, 0);
		world.setBlock(i + 2, j + 9, k + 6, 0);
		world.setBlock(i + 2, j + 9, k + 7, 0);
		world.setBlock(i + 2, j + 9, k + 8, 0);
		world.setBlock(i + 2, j + 9, k + 9, 0);
		world.setBlock(i + 2, j + 9, k + 10, 0);
		world.setBlock(i + 2, j + 9, k + 11, 0);
		world.setBlock(i + 2, j + 9, k + 12, 0);
		world.setBlock(i + 2, j + 9, k + 13, 0);
		world.setBlock(i + 2, j + 9, k + 14, 0);
		world.setBlock(i + 2, j + 9, k + 15, 0);
		world.setBlock(i + 2, j + 9, k + 16, 0);
		world.setBlock(i + 2, j + 9, k + 17, 0);
		world.setBlock(i + 2, j + 9, k + 18, 0);
		world.setBlock(i + 2, j + 9, k + 19, 0);
		world.setBlock(i + 2, j + 10, k + 0, 0);
		world.setBlock(i + 2, j + 10, k + 1, 0);
		world.setBlock(i + 2, j + 10, k + 2, 0);
		world.setBlock(i + 2, j + 10, k + 3, 0);
		world.setBlock(i + 2, j + 10, k + 4, 0);
		world.setBlock(i + 2, j + 10, k + 5, 0);
		world.setBlock(i + 2, j + 10, k + 6, 0);
		world.setBlock(i + 2, j + 10, k + 7, 0);
		world.setBlock(i + 2, j + 10, k + 8, 0);
		world.setBlock(i + 2, j + 10, k + 9, 0);
		world.setBlock(i + 2, j + 10, k + 10, 0);
		world.setBlock(i + 2, j + 10, k + 11, 0);
		world.setBlock(i + 2, j + 10, k + 12, 0);
		world.setBlock(i + 2, j + 10, k + 13, 0);
		world.setBlock(i + 2, j + 10, k + 14, 0);
		world.setBlock(i + 2, j + 10, k + 15, 0);
		world.setBlock(i + 2, j + 10, k + 16, 0);
		world.setBlock(i + 2, j + 10, k + 17, 0);
		world.setBlock(i + 2, j + 10, k + 18, 0);
		world.setBlock(i + 2, j + 10, k + 19, 0);
		world.setBlock(i + 3, j + 0, k + 0, VetheaBlockHelper.cryptWall.blockID);
		world.setBlock(i + 3, j + 0, k + 1, 0);
		world.setBlock(i + 3, j + 0, k + 2, 0);
		world.setBlock(i + 3, j + 0, k + 3, 0);
		world.setBlock(i + 3, j + 0, k + 4, 0);
		world.setBlock(i + 3, j + 0, k + 5, 0);
		world.setBlock(i + 3, j + 0, k + 6, 0);
		world.setBlock(i + 3, j + 0, k + 7, 0);
		world.setBlock(i + 3, j + 0, k + 8, 0);
		world.setBlock(i + 3, j + 0, k + 9, 0);
		world.setBlock(i + 3, j + 0, k + 10, 0);
		world.setBlock(i + 3, j + 0, k + 11, 0);
		world.setBlock(i + 3, j + 0, k + 12, 0);
		world.setBlock(i + 3, j + 0, k + 13, VetheaBlockHelper.cryptFloor.blockID);
		world.setBlock(i + 3, j + 0, k + 14, VetheaBlockHelper.cryptFloor.blockID);
		world.setBlock(i + 3, j + 0, k + 15, VetheaBlockHelper.cryptFloor.blockID);
		world.setBlock(i + 3, j + 0, k + 16, VetheaBlockHelper.dreamdirt.blockID);
		world.setBlock(i + 3, j + 0, k + 17, VetheaBlockHelper.dreamdirt.blockID);
		world.setBlock(i + 3, j + 0, k + 18, VetheaBlockHelper.dreamdirt.blockID);
		world.setBlock(i + 3, j + 0, k + 19, VetheaBlockHelper.dreamdirt.blockID);
		world.setBlock(i + 3, j + 1, k + 0, VetheaBlockHelper.cryptWall.blockID);
		world.setBlock(i + 3, j + 1, k + 1, 0);
		world.setBlock(i + 3, j + 1, k + 2, 0);
		world.setBlock(i + 3, j + 1, k + 3, 0);
		world.setBlock(i + 3, j + 1, k + 4, 0);
		world.setBlock(i + 3, j + 1, k + 5, 0);
		world.setBlock(i + 3, j + 1, k + 6, 0);
		world.setBlock(i + 3, j + 1, k + 7, 0);
		world.setBlock(i + 3, j + 1, k + 8, 0);
		world.setBlock(i + 3, j + 1, k + 9, 0);
		world.setBlock(i + 3, j + 1, k + 10, 0);
		world.setBlock(i + 3, j + 1, k + 11, 0);
		world.setBlock(i + 3, j + 1, k + 12, 0);
		world.setBlock(i + 3, j + 1, k + 13, 0);
		world.setBlock(i + 3, j + 1, k + 14, 0);
		world.setBlock(i + 3, j + 1, k + 15, 0);
		world.setBlock(i + 3, j + 1, k + 16, VetheaBlockHelper.cryptWall.blockID);
		world.setBlock(i + 3, j + 1, k + 17, VetheaBlockHelper.dreamdirt.blockID);
		world.setBlock(i + 3, j + 1, k + 18, VetheaBlockHelper.dreamdirt.blockID);
		world.setBlock(i + 3, j + 1, k + 19, VetheaBlockHelper.dreamdirt.blockID);
		world.setBlock(i + 3, j + 2, k + 0, VetheaBlockHelper.cryptWall.blockID);
		world.setBlock(i + 3, j + 2, k + 1, 0);
		world.setBlock(i + 3, j + 2, k + 2, 0);
		world.setBlock(i + 3, j + 2, k + 3, 0);
		world.setBlock(i + 3, j + 2, k + 4, 0);
		world.setBlock(i + 3, j + 2, k + 5, 0);
		world.setBlock(i + 3, j + 2, k + 6, 0);
		world.setBlock(i + 3, j + 2, k + 7, 0);
		world.setBlock(i + 3, j + 2, k + 8, 0);
		world.setBlock(i + 3, j + 2, k + 9, 0);
		world.setBlock(i + 3, j + 2, k + 10, 0);
		world.setBlock(i + 3, j + 2, k + 11, 0);
		world.setBlock(i + 3, j + 2, k + 12, 0);
		world.setBlock(i + 3, j + 2, k + 13, 0);
		world.setBlock(i + 3, j + 2, k + 14, 0);
		world.setBlock(i + 3, j + 2, k + 15, 0);
		world.setBlock(i + 3, j + 2, k + 16, VetheaBlockHelper.cryptWall.blockID);
		world.setBlock(i + 3, j + 2, k + 17, VetheaBlockHelper.dreamdirt.blockID);
		world.setBlock(i + 3, j + 2, k + 18, VetheaBlockHelper.dreamdirt.blockID);
		world.setBlock(i + 3, j + 2, k + 19, VetheaBlockHelper.dreamdirt.blockID);
		world.setBlock(i + 3, j + 3, k + 0, VetheaBlockHelper.dreamdirt.blockID);
		world.setBlock(i + 3, j + 3, k + 1, VetheaBlockHelper.hungerstone2.blockID);
		world.setBlock(i + 3, j + 3, k + 2, VetheaBlockHelper.hungerstone2.blockID);
		world.setBlock(i + 3, j + 3, k + 3, VetheaBlockHelper.hungerstone2.blockID);
		world.setBlock(i + 3, j + 3, k + 4, VetheaBlockHelper.hungerstone2.blockID);
		world.setBlock(i + 3, j + 3, k + 5, VetheaBlockHelper.hungerstone2.blockID);
		world.setBlock(i + 3, j + 3, k + 6, VetheaBlockHelper.hungerstone2.blockID);
		world.setBlock(i + 3, j + 3, k + 7, VetheaBlockHelper.hungerstone2.blockID);
		world.setBlock(i + 3, j + 3, k + 8, VetheaBlockHelper.hungerstone2.blockID);
		world.setBlock(i + 3, j + 3, k + 9, VetheaBlockHelper.cryptWall.blockID);
		world.setBlock(i + 3, j + 3, k + 10, 0);
		world.setBlock(i + 3, j + 3, k + 11, 0);
		world.setBlock(i + 3, j + 3, k + 12, 0);
		world.setBlock(i + 3, j + 3, k + 13, 0);
		world.setBlock(i + 3, j + 3, k + 14, 0);
		world.setBlock(i + 3, j + 3, k + 15, 0);
		world.setBlock(i + 3, j + 3, k + 16, VetheaBlockHelper.cryptWall.blockID);
		world.setBlock(i + 3, j + 3, k + 17, VetheaBlockHelper.dreamdirt.blockID);
		world.setBlock(i + 3, j + 3, k + 18, VetheaBlockHelper.dreamdirt.blockID);
		world.setBlock(i + 3, j + 3, k + 19, VetheaBlockHelper.dreamdirt.blockID);
		world.setBlock(i + 3, j + 4, k + 0, VetheaBlockHelper.dreamdirt.blockID);
		world.setBlock(i + 3, j + 4, k + 1, VetheaBlockHelper.dreamdirt.blockID);
		world.setBlock(i + 3, j + 4, k + 2, VetheaBlockHelper.dreamdirt.blockID);
		world.setBlock(i + 3, j + 4, k + 3, VetheaBlockHelper.dreamdirt.blockID);
		world.setBlock(i + 3, j + 4, k + 4, VetheaBlockHelper.dreamdirt.blockID);
		world.setBlock(i + 3, j + 4, k + 5, VetheaBlockHelper.dreamdirt.blockID);
		world.setBlock(i + 3, j + 4, k + 6, VetheaBlockHelper.dreamdirt.blockID);
		world.setBlock(i + 3, j + 4, k + 7, 0);
		world.setBlock(i + 3, j + 4, k + 8, VetheaBlockHelper.dreamdirt.blockID);
		world.setBlock(i + 3, j + 4, k + 9, VetheaBlockHelper.dreamdirt.blockID);
		world.setBlock(i + 3, j + 4, k + 10, VetheaBlockHelper.hungerstone2.blockID);
		world.setBlock(i + 3, j + 4, k + 11, VetheaBlockHelper.hungerstone2.blockID);
		world.setBlock(i + 3, j + 4, k + 12, VetheaBlockHelper.hungerstone2.blockID);
		world.setBlock(i + 3, j + 4, k + 13, VetheaBlockHelper.hungerstone2.blockID);
		world.setBlock(i + 3, j + 4, k + 14, VetheaBlockHelper.hungerstone2.blockID);
		world.setBlock(i + 3, j + 4, k + 15, VetheaBlockHelper.hungerstone2.blockID);
		world.setBlock(i + 3, j + 4, k + 16, VetheaBlockHelper.dreamdirt.blockID);
		world.setBlock(i + 3, j + 4, k + 17, VetheaBlockHelper.dreamdirt.blockID);
		world.setBlock(i + 3, j + 4, k + 18, VetheaBlockHelper.dreamdirt.blockID);
		world.setBlock(i + 3, j + 4, k + 19, VetheaBlockHelper.dreamdirt.blockID);
		world.setBlock(i + 3, j + 5, k + 0, VetheaBlockHelper.dreamdirt.blockID);
		world.setBlock(i + 3, j + 5, k + 1, VetheaBlockHelper.dreamdirt.blockID);
		world.setBlock(i + 3, j + 5, k + 2, VetheaBlockHelper.dreamdirt.blockID);
		world.setBlock(i + 3, j + 5, k + 3, VetheaBlockHelper.cryptWall.blockID);
		world.setBlock(i + 3, j + 5, k + 4, VetheaBlockHelper.cryptWall.blockID);
		world.setBlock(i + 3, j + 5, k + 5, VetheaBlockHelper.dreamdirt.blockID);
		world.setBlock(i + 3, j + 5, k + 6, VetheaBlockHelper.dreamdirt.blockID);
		world.setBlock(i + 3, j + 5, k + 7, VetheaBlockHelper.dreamdirt.blockID);
		world.setBlock(i + 3, j + 5, k + 8, VetheaBlockHelper.dreamdirt.blockID);
		world.setBlock(i + 3, j + 5, k + 9, VetheaBlockHelper.dreamdirt.blockID);
		world.setBlock(i + 3, j + 5, k + 10, VetheaBlockHelper.dreamdirt.blockID);
		world.setBlock(i + 3, j + 5, k + 11, VetheaBlockHelper.dreamdirt.blockID);
		world.setBlock(i + 3, j + 5, k + 12, VetheaBlockHelper.dreamdirt.blockID);
		world.setBlock(i + 3, j + 5, k + 13, VetheaBlockHelper.dreamdirt.blockID);
		world.setBlock(i + 3, j + 5, k + 14, VetheaBlockHelper.cryptWall.blockID);
		world.setBlock(i + 3, j + 5, k + 15, VetheaBlockHelper.cryptWall.blockID);
		world.setBlock(i + 3, j + 5, k + 16, VetheaBlockHelper.dreamdirt.blockID);
		world.setBlock(i + 3, j + 5, k + 17, VetheaBlockHelper.dreamdirt.blockID);
		world.setBlock(i + 3, j + 5, k + 18, VetheaBlockHelper.dreamdirt.blockID);
		world.setBlock(i + 3, j + 5, k + 19, VetheaBlockHelper.dreamdirt.blockID);
		world.setBlock(i + 3, j + 6, k + 0, VetheaBlockHelper.metalCaging.blockID);
		world.setBlock(i + 3, j + 6, k + 1, 0);
		world.setBlock(i + 3, j + 6, k + 2, 0);
		world.setBlock(i + 3, j + 6, k + 3, 0);
		world.setBlock(i + 3, j + 6, k + 4, 0);
		world.setBlock(i + 3, j + 6, k + 5, 0);
		world.setBlock(i + 3, j + 6, k + 6, 0);
		world.setBlock(i + 3, j + 6, k + 7, 0);
		world.setBlock(i + 3, j + 6, k + 8, 0);
		world.setBlock(i + 3, j + 6, k + 9, 0);
		world.setBlock(i + 3, j + 6, k + 10, 0);
		world.setBlock(i + 3, j + 6, k + 11, VetheaBlockHelper.hungerstone1.blockID);
		world.setBlock(i + 3, j + 6, k + 12, VetheaBlockHelper.hungerstone1.blockID);
		world.setBlock(i + 3, j + 6, k + 13, VetheaBlockHelper.hungerstone1.blockID);
		world.setBlock(i + 3, j + 6, k + 14, 0);
		world.setBlock(i + 3, j + 6, k + 15, 0);
		world.setBlock(i + 3, j + 6, k + 16, 0);
		world.setBlock(i + 3, j + 6, k + 17, 0);
		world.setBlock(i + 3, j + 6, k + 18, 0);
		world.setBlock(i + 3, j + 6, k + 19, VetheaBlockHelper.metalCaging.blockID);
		world.setBlock(i + 3, j + 7, k + 0, VetheaBlockHelper.hungerstone1.blockID);
		world.setBlock(i + 3, j + 7, k + 1, 0);
		world.setBlock(i + 3, j + 7, k + 2, 0);
		world.setBlock(i + 3, j + 7, k + 3, 0);
		world.setBlock(i + 3, j + 7, k + 4, 0);
		world.setBlock(i + 3, j + 7, k + 5, 0);
		world.setBlock(i + 3, j + 7, k + 6, 0);
		world.setBlock(i + 3, j + 7, k + 7, 0);
		world.setBlock(i + 3, j + 7, k + 8, 0);
		world.setBlock(i + 3, j + 7, k + 9, 0);
		world.setBlock(i + 3, j + 7, k + 10, 0);
		world.setBlock(i + 3, j + 7, k + 11, 0);
		world.setBlock(i + 3, j + 7, k + 12, 0);
		world.setBlock(i + 3, j + 7, k + 13, 0);
		world.setBlock(i + 3, j + 7, k + 14, 0);
		world.setBlock(i + 3, j + 7, k + 15, 0);
		world.setBlock(i + 3, j + 7, k + 16, 0);
		world.setBlock(i + 3, j + 7, k + 17, 0);
		world.setBlock(i + 3, j + 7, k + 18, 0);
		world.setBlock(i + 3, j + 7, k + 19, VetheaBlockHelper.hungerstone1.blockID);
		world.setBlock(i + 3, j + 8, k + 0, 0);
		world.setBlock(i + 3, j + 8, k + 1, 0);
		world.setBlock(i + 3, j + 8, k + 2, 0);
		world.setBlock(i + 3, j + 8, k + 3, 0);
		world.setBlock(i + 3, j + 8, k + 4, 0);
		world.setBlock(i + 3, j + 8, k + 5, 0);
		world.setBlock(i + 3, j + 8, k + 6, 0);
		world.setBlock(i + 3, j + 8, k + 7, 0);
		world.setBlock(i + 3, j + 8, k + 8, 0);
		world.setBlock(i + 3, j + 8, k + 9, 0);
		world.setBlock(i + 3, j + 8, k + 10, 0);
		world.setBlock(i + 3, j + 8, k + 11, 0);
		world.setBlock(i + 3, j + 8, k + 12, 0);
		world.setBlock(i + 3, j + 8, k + 13, 0);
		world.setBlock(i + 3, j + 8, k + 14, 0);
		world.setBlock(i + 3, j + 8, k + 15, 0);
		world.setBlock(i + 3, j + 8, k + 16, 0);
		world.setBlock(i + 3, j + 8, k + 17, 0);
		world.setBlock(i + 3, j + 8, k + 18, 0);
		world.setBlock(i + 3, j + 8, k + 19, 0);
		world.setBlock(i + 3, j + 9, k + 0, 0);
		world.setBlock(i + 3, j + 9, k + 1, 0);
		world.setBlock(i + 3, j + 9, k + 2, 0);
		world.setBlock(i + 3, j + 9, k + 3, 0);
		world.setBlock(i + 3, j + 9, k + 4, 0);
		world.setBlock(i + 3, j + 9, k + 5, 0);
		world.setBlock(i + 3, j + 9, k + 6, 0);
		world.setBlock(i + 3, j + 9, k + 7, 0);
		world.setBlock(i + 3, j + 9, k + 8, 0);
		world.setBlock(i + 3, j + 9, k + 9, 0);
		world.setBlock(i + 3, j + 9, k + 10, 0);
		world.setBlock(i + 3, j + 9, k + 11, 0);
		world.setBlock(i + 3, j + 9, k + 12, 0);
		world.setBlock(i + 3, j + 9, k + 13, 0);
		world.setBlock(i + 3, j + 9, k + 14, 0);
		world.setBlock(i + 3, j + 9, k + 15, 0);
		world.setBlock(i + 3, j + 9, k + 16, 0);
		world.setBlock(i + 3, j + 9, k + 17, 0);
		world.setBlock(i + 3, j + 9, k + 18, 0);
		world.setBlock(i + 3, j + 9, k + 19, 0);
		world.setBlock(i + 3, j + 10, k + 0, 0);
		world.setBlock(i + 3, j + 10, k + 1, 0);
		world.setBlock(i + 3, j + 10, k + 2, 0);
		world.setBlock(i + 3, j + 10, k + 3, 0);
		world.setBlock(i + 3, j + 10, k + 4, 0);
		world.setBlock(i + 3, j + 10, k + 5, 0);
		world.setBlock(i + 3, j + 10, k + 6, 0);
		world.setBlock(i + 3, j + 10, k + 7, 0);
		world.setBlock(i + 3, j + 10, k + 8, 0);
		world.setBlock(i + 3, j + 10, k + 9, 0);
		world.setBlock(i + 3, j + 10, k + 10, 0);
		world.setBlock(i + 3, j + 10, k + 11, 0);
		world.setBlock(i + 3, j + 10, k + 12, 0);
		world.setBlock(i + 3, j + 10, k + 13, 0);
		world.setBlock(i + 3, j + 10, k + 14, 0);
		world.setBlock(i + 3, j + 10, k + 15, 0);
		world.setBlock(i + 3, j + 10, k + 16, 0);
		world.setBlock(i + 3, j + 10, k + 17, 0);
		world.setBlock(i + 3, j + 10, k + 18, 0);
		world.setBlock(i + 3, j + 10, k + 19, 0);
		world.setBlock(i + 4, j + 0, k + 0, VetheaBlockHelper.cryptWall.blockID);
		world.setBlock(i + 4, j + 0, k + 1, 0);
		world.setBlock(i + 4, j + 0, k + 2, VetheaBlockHelper.cryptWall.blockID);
		world.setBlock(i + 4, j + 0, k + 3, VetheaBlockHelper.cryptWall.blockID);
		world.setBlock(i + 4, j + 0, k + 4, VetheaBlockHelper.cryptWall.blockID);
		world.setBlock(i + 4, j + 0, k + 5, VetheaBlockHelper.cryptWall.blockID);
		world.setBlock(i + 4, j + 0, k + 6, VetheaBlockHelper.cryptWall.blockID);
		world.setBlock(i + 4, j + 0, k + 7, VetheaBlockHelper.cryptWall.blockID);
		world.setBlock(i + 4, j + 0, k + 8, VetheaBlockHelper.cryptWall.blockID);
		world.setBlock(i + 4, j + 0, k + 9, VetheaBlockHelper.cryptWall.blockID);
		world.setBlock(i + 4, j + 0, k + 10, 0);
		world.setBlock(i + 4, j + 0, k + 11, 0);
		world.setBlock(i + 4, j + 0, k + 12, 0);
		world.setBlock(i + 4, j + 0, k + 13, VetheaBlockHelper.cryptFloor.blockID);
		world.setBlock(i + 4, j + 0, k + 14, VetheaBlockHelper.cryptFloor.blockID);
		world.setBlock(i + 4, j + 0, k + 15, VetheaBlockHelper.cryptFloor.blockID);
		world.setBlock(i + 4, j + 0, k + 16, VetheaBlockHelper.dreamdirt.blockID);
		world.setBlock(i + 4, j + 0, k + 17, VetheaBlockHelper.dreamdirt.blockID);
		world.setBlock(i + 4, j + 0, k + 18, VetheaBlockHelper.dreamdirt.blockID);
		world.setBlock(i + 4, j + 0, k + 19, VetheaBlockHelper.dreamdirt.blockID);
		world.setBlock(i + 4, j + 1, k + 0, VetheaBlockHelper.cryptWall.blockID);
		world.setBlock(i + 4, j + 1, k + 1, 0);
		world.setBlock(i + 4, j + 1, k + 2, VetheaBlockHelper.cryptWall.blockID);
		world.setBlock(i + 4, j + 1, k + 3, VetheaBlockHelper.cryptWall.blockID);
		world.setBlock(i + 4, j + 1, k + 4, VetheaBlockHelper.cryptWall.blockID);
		world.setBlock(i + 4, j + 1, k + 5, VetheaBlockHelper.cryptWall.blockID);
		world.setBlock(i + 4, j + 1, k + 6, VetheaBlockHelper.cryptWall.blockID);
		world.setBlock(i + 4, j + 1, k + 7, VetheaBlockHelper.cryptWall.blockID);
		world.setBlock(i + 4, j + 1, k + 8, VetheaBlockHelper.cryptWall.blockID);
		world.setBlock(i + 4, j + 1, k + 9, VetheaBlockHelper.cryptWall.blockID);
		world.setBlock(i + 4, j + 1, k + 10, 0);
		world.setBlock(i + 4, j + 1, k + 11, 0);
		world.setBlock(i + 4, j + 1, k + 12, 0);
		world.setBlock(i + 4, j + 1, k + 13, 0);
		world.setBlock(i + 4, j + 1, k + 14, 0);
		world.setBlock(i + 4, j + 1, k + 15, 0);
		world.setBlock(i + 4, j + 1, k + 16, VetheaBlockHelper.cryptWall.blockID);
		world.setBlock(i + 4, j + 1, k + 17, VetheaBlockHelper.dreamdirt.blockID);
		world.setBlock(i + 4, j + 1, k + 18, VetheaBlockHelper.dreamdirt.blockID);
		world.setBlock(i + 4, j + 1, k + 19, VetheaBlockHelper.dreamdirt.blockID);
		world.setBlock(i + 4, j + 2, k + 0, VetheaBlockHelper.cryptWall.blockID);
		world.setBlock(i + 4, j + 2, k + 1, 0);
		world.setBlock(i + 4, j + 2, k + 2, VetheaBlockHelper.cryptWall.blockID);
		world.setBlock(i + 4, j + 2, k + 3, VetheaBlockHelper.cryptWall.blockID);
		world.setBlock(i + 4, j + 2, k + 4, VetheaBlockHelper.cryptWall.blockID);
		world.setBlock(i + 4, j + 2, k + 5, VetheaBlockHelper.cryptWall.blockID);
		world.setBlock(i + 4, j + 2, k + 6, VetheaBlockHelper.cryptWall.blockID);
		world.setBlock(i + 4, j + 2, k + 7, VetheaBlockHelper.cryptWall.blockID);
		world.setBlock(i + 4, j + 2, k + 8, VetheaBlockHelper.cryptWall.blockID);
		world.setBlock(i + 4, j + 2, k + 9, VetheaBlockHelper.cryptWall.blockID);
		world.setBlock(i + 4, j + 2, k + 10, 0);
		world.setBlock(i + 4, j + 2, k + 11, 0);
		world.setBlock(i + 4, j + 2, k + 12, 0);
		world.setBlock(i + 4, j + 2, k + 13, 0);
		world.setBlock(i + 4, j + 2, k + 14, 0);
		world.setBlock(i + 4, j + 2, k + 15, 0);
		world.setBlock(i + 4, j + 2, k + 16, VetheaBlockHelper.cryptWall.blockID);
		world.setBlock(i + 4, j + 2, k + 17, VetheaBlockHelper.dreamdirt.blockID);
		world.setBlock(i + 4, j + 2, k + 18, VetheaBlockHelper.dreamdirt.blockID);
		world.setBlock(i + 4, j + 2, k + 19, VetheaBlockHelper.dreamdirt.blockID);
		world.setBlock(i + 4, j + 3, k + 0, VetheaBlockHelper.dreamdirt.blockID);
		world.setBlock(i + 4, j + 3, k + 1, VetheaBlockHelper.hungerstone2.blockID);
		world.setBlock(i + 4, j + 3, k + 2, VetheaBlockHelper.dreamdirt.blockID);
		world.setBlock(i + 4, j + 3, k + 3, VetheaBlockHelper.dreamdirt.blockID);
		world.setBlock(i + 4, j + 3, k + 4, VetheaBlockHelper.dreamdirt.blockID);
		world.setBlock(i + 4, j + 3, k + 5, VetheaBlockHelper.dreamdirt.blockID);
		world.setBlock(i + 4, j + 3, k + 6, VetheaBlockHelper.dreamdirt.blockID);
		world.setBlock(i + 4, j + 3, k + 7, VetheaBlockHelper.dreamdirt.blockID);
		world.setBlock(i + 4, j + 3, k + 8, VetheaBlockHelper.dreamdirt.blockID);
		world.setBlock(i + 4, j + 3, k + 9, VetheaBlockHelper.cryptWall.blockID);
		world.setBlock(i + 4, j + 3, k + 10, 0);
		world.setBlock(i + 4, j + 3, k + 11, 0);
		world.setBlock(i + 4, j + 3, k + 12, 0);
		world.setBlock(i + 4, j + 3, k + 13, 0);
		world.setBlock(i + 4, j + 3, k + 14, 0);
		world.setBlock(i + 4, j + 3, k + 15, 0);
		world.setBlock(i + 4, j + 3, k + 16, VetheaBlockHelper.cryptWall.blockID);
		world.setBlock(i + 4, j + 3, k + 17, VetheaBlockHelper.dreamdirt.blockID);
		world.setBlock(i + 4, j + 3, k + 18, VetheaBlockHelper.dreamdirt.blockID);
		world.setBlock(i + 4, j + 3, k + 19, VetheaBlockHelper.dreamdirt.blockID);
		world.setBlock(i + 4, j + 4, k + 0, VetheaBlockHelper.dreamdirt.blockID);
		world.setBlock(i + 4, j + 4, k + 1, VetheaBlockHelper.dreamdirt.blockID);
		world.setBlock(i + 4, j + 4, k + 2, VetheaBlockHelper.dreamdirt.blockID);
		world.setBlock(i + 4, j + 4, k + 3, VetheaBlockHelper.dreamdirt.blockID);
		world.setBlock(i + 4, j + 4, k + 4, VetheaBlockHelper.dreamdirt.blockID);
		world.setBlock(i + 4, j + 4, k + 5, VetheaBlockHelper.dreamdirt.blockID);
		world.setBlock(i + 4, j + 4, k + 6, VetheaBlockHelper.dreamdirt.blockID);
		world.setBlock(i + 4, j + 4, k + 7, VetheaBlockHelper.dreamdirt.blockID);
		world.setBlock(i + 4, j + 4, k + 8, VetheaBlockHelper.dreamdirt.blockID);
		world.setBlock(i + 4, j + 4, k + 9, VetheaBlockHelper.dreamdirt.blockID);
		world.setBlock(i + 4, j + 4, k + 10, VetheaBlockHelper.hungerstone2.blockID);
		world.setBlock(i + 4, j + 4, k + 11, VetheaBlockHelper.hungerstone2.blockID);
		world.setBlock(i + 4, j + 4, k + 12, VetheaBlockHelper.hungerstone2.blockID);
		world.setBlock(i + 4, j + 4, k + 13, VetheaBlockHelper.hungerstone2.blockID);
		world.setBlock(i + 4, j + 4, k + 14, VetheaBlockHelper.hungerstone2.blockID);
		world.setBlock(i + 4, j + 4, k + 15, VetheaBlockHelper.hungerstone2.blockID);
		world.setBlock(i + 4, j + 4, k + 16, VetheaBlockHelper.dreamdirt.blockID);
		world.setBlock(i + 4, j + 4, k + 17, VetheaBlockHelper.dreamdirt.blockID);
		world.setBlock(i + 4, j + 4, k + 18, VetheaBlockHelper.dreamdirt.blockID);
		world.setBlock(i + 4, j + 4, k + 19, VetheaBlockHelper.dreamdirt.blockID);
		world.setBlock(i + 4, j + 5, k + 0, VetheaBlockHelper.dreamdirt.blockID);
		world.setBlock(i + 4, j + 5, k + 1, VetheaBlockHelper.dreamdirt.blockID);
		world.setBlock(i + 4, j + 5, k + 2, VetheaBlockHelper.dreamdirt.blockID);
		world.setBlock(i + 4, j + 5, k + 3, VetheaBlockHelper.cryptWall.blockID);
		world.setBlock(i + 4, j + 5, k + 4, VetheaBlockHelper.cryptWall.blockID);
		world.setBlock(i + 4, j + 5, k + 5, VetheaBlockHelper.dreamdirt.blockID);
		world.setBlock(i + 4, j + 5, k + 6, VetheaBlockHelper.dreamdirt.blockID);
		world.setBlock(i + 4, j + 5, k + 7, VetheaBlockHelper.dreamdirt.blockID);
		world.setBlock(i + 4, j + 5, k + 8, VetheaBlockHelper.dreamdirt.blockID);
		world.setBlock(i + 4, j + 5, k + 9, VetheaBlockHelper.dreamdirt.blockID);
		world.setBlock(i + 4, j + 5, k + 10, VetheaBlockHelper.dreamdirt.blockID);
		world.setBlock(i + 4, j + 5, k + 11, VetheaBlockHelper.dreamdirt.blockID);
		world.setBlock(i + 4, j + 5, k + 12, VetheaBlockHelper.dreamdirt.blockID);
		world.setBlock(i + 4, j + 5, k + 13, VetheaBlockHelper.dreamdirt.blockID);
		world.setBlock(i + 4, j + 5, k + 14, VetheaBlockHelper.cryptWall.blockID);
		world.setBlock(i + 4, j + 5, k + 15, VetheaBlockHelper.cryptWall.blockID);
		world.setBlock(i + 4, j + 5, k + 16, VetheaBlockHelper.dreamdirt.blockID);
		world.setBlock(i + 4, j + 5, k + 17, VetheaBlockHelper.dreamdirt.blockID);
		world.setBlock(i + 4, j + 5, k + 18, VetheaBlockHelper.dreamdirt.blockID);
		world.setBlock(i + 4, j + 5, k + 19, VetheaBlockHelper.dreamdirt.blockID);
		world.setBlock(i + 4, j + 6, k + 0, VetheaBlockHelper.metalCaging.blockID);
		world.setBlock(i + 4, j + 6, k + 1, 0);
		world.setBlock(i + 4, j + 6, k + 2, 0);
		world.setBlock(i + 4, j + 6, k + 3, 0);
		world.setBlock(i + 4, j + 6, k + 4, 0);
		world.setBlock(i + 4, j + 6, k + 5, 0);
		world.setBlock(i + 4, j + 6, k + 6, 0);
		world.setBlock(i + 4, j + 6, k + 7, 0);
		world.setBlock(i + 4, j + 6, k + 8, 0);
		world.setBlock(i + 4, j + 6, k + 9, 0);
		world.setBlock(i + 4, j + 6, k + 10, 0);
		world.setBlock(i + 4, j + 6, k + 11, VetheaBlockHelper.hungerstone1.blockID);
		world.setBlock(i + 4, j + 6, k + 12, VetheaBlockHelper.hungerstone1.blockID);
		world.setBlock(i + 4, j + 6, k + 13, VetheaBlockHelper.hungerstone1.blockID);
		world.setBlock(i + 4, j + 6, k + 14, 0);
		world.setBlock(i + 4, j + 6, k + 15, 0);
		world.setBlock(i + 4, j + 6, k + 16, 0);
		world.setBlock(i + 4, j + 6, k + 17, 0);
		world.setBlock(i + 4, j + 6, k + 18, 0);
		world.setBlock(i + 4, j + 6, k + 19, VetheaBlockHelper.metalCaging.blockID);
		world.setBlock(i + 4, j + 7, k + 0, VetheaBlockHelper.hungerstone1.blockID);
		world.setBlock(i + 4, j + 7, k + 1, 0);
		world.setBlock(i + 4, j + 7, k + 2, 0);
		world.setBlock(i + 4, j + 7, k + 3, 0);
		world.setBlock(i + 4, j + 7, k + 4, 0);
		world.setBlock(i + 4, j + 7, k + 5, 0);
		world.setBlock(i + 4, j + 7, k + 6, 0);
		world.setBlock(i + 4, j + 7, k + 7, 0);
		world.setBlock(i + 4, j + 7, k + 8, 0);
		world.setBlock(i + 4, j + 7, k + 9, 0);
		world.setBlock(i + 4, j + 7, k + 10, 0);
		world.setBlock(i + 4, j + 7, k + 11, 0);
		world.setBlock(i + 4, j + 7, k + 12, VetheaBlockHelper.hungerstone1.blockID);
		world.setBlock(i + 4, j + 7, k + 13, 0);
		world.setBlock(i + 4, j + 7, k + 14, 0);
		world.setBlock(i + 4, j + 7, k + 15, 0);
		world.setBlock(i + 4, j + 7, k + 16, 0);
		world.setBlock(i + 4, j + 7, k + 17, 0);
		world.setBlock(i + 4, j + 7, k + 18, 0);
		world.setBlock(i + 4, j + 7, k + 19, VetheaBlockHelper.hungerstone1.blockID);
		world.setBlock(i + 4, j + 8, k + 0, 0);
		world.setBlock(i + 4, j + 8, k + 1, 0);
		world.setBlock(i + 4, j + 8, k + 2, 0);
		world.setBlock(i + 4, j + 8, k + 3, 0);
		world.setBlock(i + 4, j + 8, k + 4, 0);
		world.setBlock(i + 4, j + 8, k + 5, 0);
		world.setBlock(i + 4, j + 8, k + 6, 0);
		world.setBlock(i + 4, j + 8, k + 7, 0);
		world.setBlock(i + 4, j + 8, k + 8, 0);
		world.setBlock(i + 4, j + 8, k + 9, 0);
		world.setBlock(i + 4, j + 8, k + 10, 0);
		world.setBlock(i + 4, j + 8, k + 11, 0);
		world.setBlock(i + 4, j + 8, k + 12, VetheaBlockHelper.firecrystal.blockID);
		world.setBlock(i + 4, j + 8, k + 13, 0);
		world.setBlock(i + 4, j + 8, k + 14, 0);
		world.setBlock(i + 4, j + 8, k + 15, 0);
		world.setBlock(i + 4, j + 8, k + 16, 0);
		world.setBlock(i + 4, j + 8, k + 17, 0);
		world.setBlock(i + 4, j + 8, k + 18, 0);
		world.setBlock(i + 4, j + 8, k + 19, 0);
		world.setBlock(i + 4, j + 9, k + 0, 0);
		world.setBlock(i + 4, j + 9, k + 1, 0);
		world.setBlock(i + 4, j + 9, k + 2, 0);
		world.setBlock(i + 4, j + 9, k + 3, 0);
		world.setBlock(i + 4, j + 9, k + 4, 0);
		world.setBlock(i + 4, j + 9, k + 5, 0);
		world.setBlock(i + 4, j + 9, k + 6, 0);
		world.setBlock(i + 4, j + 9, k + 7, 0);
		world.setBlock(i + 4, j + 9, k + 8, 0);
		world.setBlock(i + 4, j + 9, k + 9, 0);
		world.setBlock(i + 4, j + 9, k + 10, 0);
		world.setBlock(i + 4, j + 9, k + 11, 0);
		world.setBlock(i + 4, j + 9, k + 12, 0);
		world.setBlock(i + 4, j + 9, k + 13, 0);
		world.setBlock(i + 4, j + 9, k + 14, 0);
		world.setBlock(i + 4, j + 9, k + 15, 0);
		world.setBlock(i + 4, j + 9, k + 16, 0);
		world.setBlock(i + 4, j + 9, k + 17, 0);
		world.setBlock(i + 4, j + 9, k + 18, 0);
		world.setBlock(i + 4, j + 9, k + 19, 0);
		world.setBlock(i + 4, j + 10, k + 0, 0);
		world.setBlock(i + 4, j + 10, k + 1, 0);
		world.setBlock(i + 4, j + 10, k + 2, 0);
		world.setBlock(i + 4, j + 10, k + 3, 0);
		world.setBlock(i + 4, j + 10, k + 4, 0);
		world.setBlock(i + 4, j + 10, k + 5, 0);
		world.setBlock(i + 4, j + 10, k + 6, 0);
		world.setBlock(i + 4, j + 10, k + 7, 0);
		world.setBlock(i + 4, j + 10, k + 8, 0);
		world.setBlock(i + 4, j + 10, k + 9, 0);
		world.setBlock(i + 4, j + 10, k + 10, 0);
		world.setBlock(i + 4, j + 10, k + 11, 0);
		world.setBlock(i + 4, j + 10, k + 12, 0);
		world.setBlock(i + 4, j + 10, k + 13, 0);
		world.setBlock(i + 4, j + 10, k + 14, 0);
		world.setBlock(i + 4, j + 10, k + 15, 0);
		world.setBlock(i + 4, j + 10, k + 16, 0);
		world.setBlock(i + 4, j + 10, k + 17, 0);
		world.setBlock(i + 4, j + 10, k + 18, 0);
		world.setBlock(i + 4, j + 10, k + 19, 0);
		world.setBlock(i + 5, j + 0, k + 0, VetheaBlockHelper.cryptWall.blockID);
		world.setBlock(i + 5, j + 0, k + 1, 0);
		world.setBlock(i + 5, j + 0, k + 2, VetheaBlockHelper.cryptWall.blockID);
		world.setBlock(i + 5, j + 0, k + 3, VetheaBlockHelper.dreamdirt.blockID);
		world.setBlock(i + 5, j + 0, k + 4, VetheaBlockHelper.dreamdirt.blockID);
		world.setBlock(i + 5, j + 0, k + 5, VetheaBlockHelper.dreamdirt.blockID);
		world.setBlock(i + 5, j + 0, k + 6, VetheaBlockHelper.dreamdirt.blockID);
		world.setBlock(i + 5, j + 0, k + 7, VetheaBlockHelper.dreamdirt.blockID);
		world.setBlock(i + 5, j + 0, k + 8, VetheaBlockHelper.dreamdirt.blockID);
		world.setBlock(i + 5, j + 0, k + 9, VetheaBlockHelper.dreamdirt.blockID);
		world.setBlock(i + 5, j + 0, k + 10, VetheaBlockHelper.cryptFloor.blockID);
		world.setBlock(i + 5, j + 0, k + 11, VetheaBlockHelper.cryptFloor.blockID);
		world.setBlock(i + 5, j + 0, k + 12, VetheaBlockHelper.cryptFloor.blockID);
		world.setBlock(i + 5, j + 0, k + 13, VetheaBlockHelper.cryptFloor.blockID);
		world.setBlock(i + 5, j + 0, k + 14, VetheaBlockHelper.cryptFloor.blockID);
		world.setBlock(i + 5, j + 0, k + 15, VetheaBlockHelper.cryptFloor.blockID);
		world.setBlock(i + 5, j + 0, k + 16, VetheaBlockHelper.dreamdirt.blockID);
		world.setBlock(i + 5, j + 0, k + 17, VetheaBlockHelper.dreamdirt.blockID);
		world.setBlock(i + 5, j + 0, k + 18, VetheaBlockHelper.dreamdirt.blockID);
		world.setBlock(i + 5, j + 0, k + 19, VetheaBlockHelper.dreamdirt.blockID);
		world.setBlock(i + 5, j + 1, k + 0, VetheaBlockHelper.cryptWall.blockID);
		world.setBlock(i + 5, j + 1, k + 1, 0);
		world.setBlock(i + 5, j + 1, k + 2, VetheaBlockHelper.cryptWall.blockID);
		world.setBlock(i + 5, j + 1, k + 3, VetheaBlockHelper.dreamdirt.blockID);
		world.setBlock(i + 5, j + 1, k + 4, VetheaBlockHelper.dreamdirt.blockID);
		world.setBlock(i + 5, j + 1, k + 5, VetheaBlockHelper.dreamdirt.blockID);
		world.setBlock(i + 5, j + 1, k + 6, VetheaBlockHelper.dreamdirt.blockID);
		world.setBlock(i + 5, j + 1, k + 7, VetheaBlockHelper.dreamdirt.blockID);
		world.setBlock(i + 5, j + 1, k + 8, VetheaBlockHelper.dreamdirt.blockID);
		world.setBlock(i + 5, j + 1, k + 9, VetheaBlockHelper.cryptWall.blockID);
		world.setBlock(i + 5, j + 1, k + 10, 0);
		world.setBlock(i + 5, j + 1, k + 11, 0);
		world.setBlock(i + 5, j + 1, k + 12, 0);
		world.setBlock(i + 5, j + 1, k + 13, 0);
		world.setBlock(i + 5, j + 1, k + 14, 0);
		world.setBlock(i + 5, j + 1, k + 15, 0);
		world.setBlock(i + 5, j + 1, k + 16, VetheaBlockHelper.cryptWall.blockID);
		world.setBlock(i + 5, j + 1, k + 17, VetheaBlockHelper.dreamdirt.blockID);
		world.setBlock(i + 5, j + 1, k + 18, VetheaBlockHelper.dreamdirt.blockID);
		world.setBlock(i + 5, j + 1, k + 19, VetheaBlockHelper.dreamdirt.blockID);
		world.setBlock(i + 5, j + 2, k + 0, VetheaBlockHelper.cryptWall.blockID);
		world.setBlock(i + 5, j + 2, k + 1, 0);
		world.setBlock(i + 5, j + 2, k + 2, VetheaBlockHelper.cryptWall.blockID);
		world.setBlock(i + 5, j + 2, k + 3, VetheaBlockHelper.dreamdirt.blockID);
		world.setBlock(i + 5, j + 2, k + 4, VetheaBlockHelper.dreamdirt.blockID);
		world.setBlock(i + 5, j + 2, k + 5, VetheaBlockHelper.dreamdirt.blockID);
		world.setBlock(i + 5, j + 2, k + 6, VetheaBlockHelper.dreamdirt.blockID);
		world.setBlock(i + 5, j + 2, k + 7, VetheaBlockHelper.dreamdirt.blockID);
		world.setBlock(i + 5, j + 2, k + 8, VetheaBlockHelper.dreamdirt.blockID);
		world.setBlock(i + 5, j + 2, k + 9, VetheaBlockHelper.cryptWall.blockID);
		world.setBlock(i + 5, j + 2, k + 10, 0);
		world.setBlock(i + 5, j + 2, k + 11, 0);
		world.setBlock(i + 5, j + 2, k + 12, 0);
		world.setBlock(i + 5, j + 2, k + 13, 0);
		world.setBlock(i + 5, j + 2, k + 14, 0);
		world.setBlock(i + 5, j + 2, k + 15, 0);
		world.setBlock(i + 5, j + 2, k + 16, VetheaBlockHelper.cryptWall.blockID);
		world.setBlock(i + 5, j + 2, k + 17, VetheaBlockHelper.dreamdirt.blockID);
		world.setBlock(i + 5, j + 2, k + 18, VetheaBlockHelper.dreamdirt.blockID);
		world.setBlock(i + 5, j + 2, k + 19, VetheaBlockHelper.dreamdirt.blockID);
		world.setBlock(i + 5, j + 3, k + 0, VetheaBlockHelper.dreamdirt.blockID);
		world.setBlock(i + 5, j + 3, k + 1, VetheaBlockHelper.hungerstone2.blockID);
		world.setBlock(i + 5, j + 3, k + 2, VetheaBlockHelper.dreamdirt.blockID);
		world.setBlock(i + 5, j + 3, k + 3, VetheaBlockHelper.dreamdirt.blockID);
		world.setBlock(i + 5, j + 3, k + 4, VetheaBlockHelper.dreamdirt.blockID);
		world.setBlock(i + 5, j + 3, k + 5, VetheaBlockHelper.dreamdirt.blockID);
		world.setBlock(i + 5, j + 3, k + 6, VetheaBlockHelper.dreamdirt.blockID);
		world.setBlock(i + 5, j + 3, k + 7, VetheaBlockHelper.dreamdirt.blockID);
		world.setBlock(i + 5, j + 3, k + 8, VetheaBlockHelper.dreamdirt.blockID);
		world.setBlock(i + 5, j + 3, k + 9, VetheaBlockHelper.cryptWall.blockID);
		world.setBlock(i + 5, j + 3, k + 10, 0);
		world.setBlock(i + 5, j + 3, k + 11, 0);
		world.setBlock(i + 5, j + 3, k + 12, 0);
		world.setBlock(i + 5, j + 3, k + 13, 0);
		world.setBlock(i + 5, j + 3, k + 14, 0);
		world.setBlock(i + 5, j + 3, k + 15, 0);
		world.setBlock(i + 5, j + 3, k + 16, VetheaBlockHelper.cryptWall.blockID);
		world.setBlock(i + 5, j + 3, k + 17, VetheaBlockHelper.dreamdirt.blockID);
		world.setBlock(i + 5, j + 3, k + 18, VetheaBlockHelper.dreamdirt.blockID);
		world.setBlock(i + 5, j + 3, k + 19, VetheaBlockHelper.dreamdirt.blockID);
		world.setBlock(i + 5, j + 4, k + 0, VetheaBlockHelper.dreamdirt.blockID);
		world.setBlock(i + 5, j + 4, k + 1, VetheaBlockHelper.dreamdirt.blockID);
		world.setBlock(i + 5, j + 4, k + 2, VetheaBlockHelper.dreamdirt.blockID);
		world.setBlock(i + 5, j + 4, k + 3, VetheaBlockHelper.dreamdirt.blockID);
		world.setBlock(i + 5, j + 4, k + 4, VetheaBlockHelper.dreamdirt.blockID);
		world.setBlock(i + 5, j + 4, k + 5, VetheaBlockHelper.dreamdirt.blockID);
		world.setBlock(i + 5, j + 4, k + 6, VetheaBlockHelper.dreamdirt.blockID);
		world.setBlock(i + 5, j + 4, k + 7, VetheaBlockHelper.dreamdirt.blockID);
		world.setBlock(i + 5, j + 4, k + 8, VetheaBlockHelper.dreamdirt.blockID);
		world.setBlock(i + 5, j + 4, k + 9, VetheaBlockHelper.dreamdirt.blockID);
		world.setBlock(i + 5, j + 4, k + 10, VetheaBlockHelper.hungerstone2.blockID);
		world.setBlock(i + 5, j + 4, k + 11, VetheaBlockHelper.hungerstone2.blockID);
		world.setBlock(i + 5, j + 4, k + 12, VetheaBlockHelper.hungerstone2.blockID);
		world.setBlock(i + 5, j + 4, k + 13, VetheaBlockHelper.hungerstone2.blockID);
		world.setBlock(i + 5, j + 4, k + 14, VetheaBlockHelper.hungerstone2.blockID);
		world.setBlock(i + 5, j + 4, k + 15, VetheaBlockHelper.hungerstone2.blockID);
		world.setBlock(i + 5, j + 4, k + 16, VetheaBlockHelper.dreamdirt.blockID);
		world.setBlock(i + 5, j + 4, k + 17, VetheaBlockHelper.dreamdirt.blockID);
		world.setBlock(i + 5, j + 4, k + 18, VetheaBlockHelper.dreamdirt.blockID);
		world.setBlock(i + 5, j + 4, k + 19, VetheaBlockHelper.dreamdirt.blockID);
		world.setBlock(i + 5, j + 5, k + 0, VetheaBlockHelper.dreamdirt.blockID);
		world.setBlock(i + 5, j + 5, k + 1, VetheaBlockHelper.dreamdirt.blockID);
		world.setBlock(i + 5, j + 5, k + 2, VetheaBlockHelper.dreamdirt.blockID);
		world.setBlock(i + 5, j + 5, k + 3, VetheaBlockHelper.cryptWall.blockID);
		world.setBlock(i + 5, j + 5, k + 4, VetheaBlockHelper.cryptWall.blockID);
		world.setBlock(i + 5, j + 5, k + 5, VetheaBlockHelper.dreamdirt.blockID);
		world.setBlock(i + 5, j + 5, k + 6, VetheaBlockHelper.dreamdirt.blockID);
		world.setBlock(i + 5, j + 5, k + 7, VetheaBlockHelper.dreamdirt.blockID);
		world.setBlock(i + 5, j + 5, k + 8, VetheaBlockHelper.dreamdirt.blockID);
		world.setBlock(i + 5, j + 5, k + 9, VetheaBlockHelper.dreamdirt.blockID);
		world.setBlock(i + 5, j + 5, k + 10, VetheaBlockHelper.dreamdirt.blockID);
		world.setBlock(i + 5, j + 5, k + 11, VetheaBlockHelper.dreamdirt.blockID);
		world.setBlock(i + 5, j + 5, k + 12, VetheaBlockHelper.dreamdirt.blockID);
		world.setBlock(i + 5, j + 5, k + 13, VetheaBlockHelper.dreamdirt.blockID);
		world.setBlock(i + 5, j + 5, k + 14, VetheaBlockHelper.cryptWall.blockID);
		world.setBlock(i + 5, j + 5, k + 15, VetheaBlockHelper.cryptWall.blockID);
		world.setBlock(i + 5, j + 5, k + 16, VetheaBlockHelper.dreamdirt.blockID);
		world.setBlock(i + 5, j + 5, k + 17, VetheaBlockHelper.dreamdirt.blockID);
		world.setBlock(i + 5, j + 5, k + 18, VetheaBlockHelper.dreamdirt.blockID);
		world.setBlock(i + 5, j + 5, k + 19, VetheaBlockHelper.dreamdirt.blockID);
		world.setBlock(i + 5, j + 6, k + 0, VetheaBlockHelper.hungerstone1.blockID);
		world.setBlock(i + 5, j + 6, k + 1, 0);
		world.setBlock(i + 5, j + 6, k + 2, 0);
		world.setBlock(i + 5, j + 6, k + 3, 0);
		world.setBlock(i + 5, j + 6, k + 4, 0);
		world.setBlock(i + 5, j + 6, k + 5, 0);
		world.setBlock(i + 5, j + 6, k + 6, 0);
		world.setBlock(i + 5, j + 6, k + 7, 0);
		world.setBlock(i + 5, j + 6, k + 8, 0);
		world.setBlock(i + 5, j + 6, k + 9, 0);
		world.setBlock(i + 5, j + 6, k + 10, 0);
		world.setBlock(i + 5, j + 6, k + 11, VetheaBlockHelper.hungerstone1.blockID);
		world.setBlock(i + 5, j + 6, k + 12, VetheaBlockHelper.hungerstone1.blockID);
		world.setBlock(i + 5, j + 6, k + 13, VetheaBlockHelper.hungerstone1.blockID);
		world.setBlock(i + 5, j + 6, k + 14, 0);
		world.setBlock(i + 5, j + 6, k + 15, 0);
		world.setBlock(i + 5, j + 6, k + 16, 0);
		world.setBlock(i + 5, j + 6, k + 17, 0);
		world.setBlock(i + 5, j + 6, k + 18, 0);
		world.setBlock(i + 5, j + 6, k + 19, VetheaBlockHelper.hungerstone1.blockID);
		world.setBlock(i + 5, j + 7, k + 0, VetheaBlockHelper.hungerstone1.blockID);
		world.setBlock(i + 5, j + 7, k + 1, 0);
		world.setBlock(i + 5, j + 7, k + 2, 0);
		world.setBlock(i + 5, j + 7, k + 3, 0);
		world.setBlock(i + 5, j + 7, k + 4, 0);
		world.setBlock(i + 5, j + 7, k + 5, 0);
		world.setBlock(i + 5, j + 7, k + 6, 0);
		world.setBlock(i + 5, j + 7, k + 7, 0);
		world.setBlock(i + 5, j + 7, k + 8, 0);
		world.setBlock(i + 5, j + 7, k + 9, 0);
		world.setBlock(i + 5, j + 7, k + 10, 0);
		world.setBlock(i + 5, j + 7, k + 11, 0);
		world.setBlock(i + 5, j + 7, k + 12, 0);
		world.setBlock(i + 5, j + 7, k + 13, 0);
		world.setBlock(i + 5, j + 7, k + 14, 0);
		world.setBlock(i + 5, j + 7, k + 15, 0);
		world.setBlock(i + 5, j + 7, k + 16, 0);
		world.setBlock(i + 5, j + 7, k + 17, 0);
		world.setBlock(i + 5, j + 7, k + 18, 0);
		world.setBlock(i + 5, j + 7, k + 19, VetheaBlockHelper.hungerstone1.blockID);
		world.setBlock(i + 5, j + 8, k + 0, VetheaBlockHelper.hungerstone1.blockID);
		world.setBlock(i + 5, j + 8, k + 1, 0);
		world.setBlock(i + 5, j + 8, k + 2, 0);
		world.setBlock(i + 5, j + 8, k + 3, 0);
		world.setBlock(i + 5, j + 8, k + 4, 0);
		world.setBlock(i + 5, j + 8, k + 5, 0);
		world.setBlock(i + 5, j + 8, k + 6, 0);
		world.setBlock(i + 5, j + 8, k + 7, 0);
		world.setBlock(i + 5, j + 8, k + 8, 0);
		world.setBlock(i + 5, j + 8, k + 9, 0);
		world.setBlock(i + 5, j + 8, k + 10, 0);
		world.setBlock(i + 5, j + 8, k + 11, 0);
		world.setBlock(i + 5, j + 8, k + 12, 0);
		world.setBlock(i + 5, j + 8, k + 13, 0);
		world.setBlock(i + 5, j + 8, k + 14, 0);
		world.setBlock(i + 5, j + 8, k + 15, 0);
		world.setBlock(i + 5, j + 8, k + 16, 0);
		world.setBlock(i + 5, j + 8, k + 17, 0);
		world.setBlock(i + 5, j + 8, k + 18, 0);
		world.setBlock(i + 5, j + 8, k + 19, VetheaBlockHelper.hungerstone1.blockID);
		world.setBlock(i + 5, j + 9, k + 0, 0);
		world.setBlock(i + 5, j + 9, k + 1, 0);
		world.setBlock(i + 5, j + 9, k + 2, 0);
		world.setBlock(i + 5, j + 9, k + 3, 0);
		world.setBlock(i + 5, j + 9, k + 4, 0);
		world.setBlock(i + 5, j + 9, k + 5, 0);
		world.setBlock(i + 5, j + 9, k + 6, 0);
		world.setBlock(i + 5, j + 9, k + 7, 0);
		world.setBlock(i + 5, j + 9, k + 8, 0);
		world.setBlock(i + 5, j + 9, k + 9, 0);
		world.setBlock(i + 5, j + 9, k + 10, 0);
		world.setBlock(i + 5, j + 9, k + 11, 0);
		world.setBlock(i + 5, j + 9, k + 12, 0);
		world.setBlock(i + 5, j + 9, k + 13, 0);
		world.setBlock(i + 5, j + 9, k + 14, 0);
		world.setBlock(i + 5, j + 9, k + 15, 0);
		world.setBlock(i + 5, j + 9, k + 16, 0);
		world.setBlock(i + 5, j + 9, k + 17, 0);
		world.setBlock(i + 5, j + 9, k + 18, 0);
		world.setBlock(i + 5, j + 9, k + 19, 0);
		world.setBlock(i + 5, j + 10, k + 0, 0);
		world.setBlock(i + 5, j + 10, k + 1, 0);
		world.setBlock(i + 5, j + 10, k + 2, 0);
		world.setBlock(i + 5, j + 10, k + 3, 0);
		world.setBlock(i + 5, j + 10, k + 4, 0);
		world.setBlock(i + 5, j + 10, k + 5, 0);
		world.setBlock(i + 5, j + 10, k + 6, 0);
		world.setBlock(i + 5, j + 10, k + 7, 0);
		world.setBlock(i + 5, j + 10, k + 8, 0);
		world.setBlock(i + 5, j + 10, k + 9, 0);
		world.setBlock(i + 5, j + 10, k + 10, 0);
		world.setBlock(i + 5, j + 10, k + 11, 0);
		world.setBlock(i + 5, j + 10, k + 12, 0);
		world.setBlock(i + 5, j + 10, k + 13, 0);
		world.setBlock(i + 5, j + 10, k + 14, 0);
		world.setBlock(i + 5, j + 10, k + 15, 0);
		world.setBlock(i + 5, j + 10, k + 16, 0);
		world.setBlock(i + 5, j + 10, k + 17, 0);
		world.setBlock(i + 5, j + 10, k + 18, 0);
		world.setBlock(i + 5, j + 10, k + 19, 0);
		world.setBlock(i + 6, j + 0, k + 0, VetheaBlockHelper.cryptWall.blockID);
		world.setBlock(i + 6, j + 0, k + 1, 0);
		world.setBlock(i + 6, j + 0, k + 2, VetheaBlockHelper.cryptWall.blockID);
		world.setBlock(i + 6, j + 0, k + 3, VetheaBlockHelper.cryptWall.blockID);
		world.setBlock(i + 6, j + 0, k + 4, VetheaBlockHelper.cryptWall.blockID);
		world.setBlock(i + 6, j + 0, k + 5, VetheaBlockHelper.dreamdirt.blockID);
		world.setBlock(i + 6, j + 0, k + 6, VetheaBlockHelper.dreamdirt.blockID);
		world.setBlock(i + 6, j + 0, k + 7, VetheaBlockHelper.dreamdirt.blockID);
		world.setBlock(i + 6, j + 0, k + 8, VetheaBlockHelper.dreamdirt.blockID);
		world.setBlock(i + 6, j + 0, k + 9, VetheaBlockHelper.dreamdirt.blockID);
		world.setBlock(i + 6, j + 0, k + 10, VetheaBlockHelper.cryptFloor.blockID);
		world.setBlock(i + 6, j + 0, k + 11, VetheaBlockHelper.cryptFloor.blockID);
		world.setBlock(i + 6, j + 0, k + 12, VetheaBlockHelper.cryptFloor.blockID);
		world.setBlock(i + 6, j + 0, k + 13, VetheaBlockHelper.cryptFloor.blockID);
		world.setBlock(i + 6, j + 0, k + 14, VetheaBlockHelper.cryptFloor.blockID);
		world.setBlock(i + 6, j + 0, k + 15, VetheaBlockHelper.cryptFloor.blockID);
		world.setBlock(i + 6, j + 0, k + 16, VetheaBlockHelper.dreamdirt.blockID);
		world.setBlock(i + 6, j + 0, k + 17, VetheaBlockHelper.dreamdirt.blockID);
		world.setBlock(i + 6, j + 0, k + 18, VetheaBlockHelper.dreamdirt.blockID);
		world.setBlock(i + 6, j + 0, k + 19, VetheaBlockHelper.dreamdirt.blockID);
		world.setBlock(i + 6, j + 1, k + 0, VetheaBlockHelper.cryptWall.blockID);
		world.setBlock(i + 6, j + 1, k + 1, 0);
		world.setBlock(i + 6, j + 1, k + 2, VetheaBlockHelper.firecrystal.blockID);
		world.setBlock(i + 6, j + 1, k + 3, VetheaBlockHelper.cryptWall.blockID);
		world.setBlock(i + 6, j + 1, k + 4, VetheaBlockHelper.cryptWall.blockID);
		world.setBlock(i + 6, j + 1, k + 5, VetheaBlockHelper.dreamdirt.blockID);
		world.setBlock(i + 6, j + 1, k + 6, VetheaBlockHelper.dreamdirt.blockID);
		world.setBlock(i + 6, j + 1, k + 7, VetheaBlockHelper.dreamdirt.blockID);
		world.setBlock(i + 6, j + 1, k + 8, VetheaBlockHelper.dreamdirt.blockID);
		world.setBlock(i + 6, j + 1, k + 9, VetheaBlockHelper.cryptWall.blockID);
		world.setBlock(i + 6, j + 1, k + 10, 0);
		world.setBlock(i + 6, j + 1, k + 11, 0);
		world.setBlock(i + 6, j + 1, k + 12, 0);
		world.setBlock(i + 6, j + 1, k + 13, 0);
		world.setBlock(i + 6, j + 1, k + 14, 0);
		world.setBlock(i + 6, j + 1, k + 15, 0);
		world.setBlock(i + 6, j + 1, k + 16, VetheaBlockHelper.cryptWall.blockID);
		world.setBlock(i + 6, j + 1, k + 17, VetheaBlockHelper.dreamdirt.blockID);
		world.setBlock(i + 6, j + 1, k + 18, VetheaBlockHelper.dreamdirt.blockID);
		world.setBlock(i + 6, j + 1, k + 19, VetheaBlockHelper.dreamdirt.blockID);
		world.setBlock(i + 6, j + 2, k + 0, VetheaBlockHelper.cryptWall.blockID);
		world.setBlock(i + 6, j + 2, k + 1, 0);
		world.setBlock(i + 6, j + 2, k + 2, VetheaBlockHelper.cryptWall.blockID);
		world.setBlock(i + 6, j + 2, k + 3, VetheaBlockHelper.cryptWall.blockID);
		world.setBlock(i + 6, j + 2, k + 4, VetheaBlockHelper.cryptWall.blockID);
		world.setBlock(i + 6, j + 2, k + 5, VetheaBlockHelper.dreamdirt.blockID);
		world.setBlock(i + 6, j + 2, k + 6, VetheaBlockHelper.dreamdirt.blockID);
		world.setBlock(i + 6, j + 2, k + 7, VetheaBlockHelper.dreamdirt.blockID);
		world.setBlock(i + 6, j + 2, k + 8, VetheaBlockHelper.dreamdirt.blockID);
		world.setBlock(i + 6, j + 2, k + 9, VetheaBlockHelper.cryptWall.blockID);
		world.setBlock(i + 6, j + 2, k + 10, 0);
		world.setBlock(i + 6, j + 2, k + 11, 0);
		world.setBlock(i + 6, j + 2, k + 12, 0);
		world.setBlock(i + 6, j + 2, k + 13, 0);
		world.setBlock(i + 6, j + 2, k + 14, 0);
		world.setBlock(i + 6, j + 2, k + 15, 0);
		world.setBlock(i + 6, j + 2, k + 16, VetheaBlockHelper.cryptWall.blockID);
		world.setBlock(i + 6, j + 2, k + 17, VetheaBlockHelper.dreamdirt.blockID);
		world.setBlock(i + 6, j + 2, k + 18, VetheaBlockHelper.dreamdirt.blockID);
		world.setBlock(i + 6, j + 2, k + 19, VetheaBlockHelper.dreamdirt.blockID);
		world.setBlock(i + 6, j + 3, k + 0, VetheaBlockHelper.dreamdirt.blockID);
		world.setBlock(i + 6, j + 3, k + 1, VetheaBlockHelper.cryptWall.blockID);
		world.setBlock(i + 6, j + 3, k + 2, VetheaBlockHelper.cryptWall.blockID);
		world.setBlock(i + 6, j + 3, k + 3, VetheaBlockHelper.cryptWall.blockID);
		world.setBlock(i + 6, j + 3, k + 4, VetheaBlockHelper.cryptWall.blockID);
		world.setBlock(i + 6, j + 3, k + 5, VetheaBlockHelper.dreamdirt.blockID);
		world.setBlock(i + 6, j + 3, k + 6, VetheaBlockHelper.dreamdirt.blockID);
		world.setBlock(i + 6, j + 3, k + 7, VetheaBlockHelper.dreamdirt.blockID);
		world.setBlock(i + 6, j + 3, k + 8, VetheaBlockHelper.dreamdirt.blockID);
		world.setBlock(i + 6, j + 3, k + 9, VetheaBlockHelper.cryptWall.blockID);
		world.setBlock(i + 6, j + 3, k + 10, 0);
		world.setBlock(i + 6, j + 3, k + 11, 0);
		world.setBlock(i + 6, j + 3, k + 12, 0);
		world.setBlock(i + 6, j + 3, k + 13, 0);
		world.setBlock(i + 6, j + 3, k + 14, 0);
		world.setBlock(i + 6, j + 3, k + 15, 0);
		world.setBlock(i + 6, j + 3, k + 16, VetheaBlockHelper.cryptWall.blockID);
		world.setBlock(i + 6, j + 3, k + 17, VetheaBlockHelper.dreamdirt.blockID);
		world.setBlock(i + 6, j + 3, k + 18, VetheaBlockHelper.dreamdirt.blockID);
		world.setBlock(i + 6, j + 3, k + 19, VetheaBlockHelper.dreamdirt.blockID);
		world.setBlock(i + 6, j + 4, k + 0, VetheaBlockHelper.dreamdirt.blockID);
		world.setBlock(i + 6, j + 4, k + 1, VetheaBlockHelper.dreamdirt.blockID);
		world.setBlock(i + 6, j + 4, k + 2, VetheaBlockHelper.dreamdirt.blockID);
		world.setBlock(i + 6, j + 4, k + 3, VetheaBlockHelper.dreamdirt.blockID);
		world.setBlock(i + 6, j + 4, k + 4, VetheaBlockHelper.dreamdirt.blockID);
		world.setBlock(i + 6, j + 4, k + 5, VetheaBlockHelper.dreamdirt.blockID);
		world.setBlock(i + 6, j + 4, k + 6, VetheaBlockHelper.dreamdirt.blockID);
		world.setBlock(i + 6, j + 4, k + 7, VetheaBlockHelper.dreamdirt.blockID);
		world.setBlock(i + 6, j + 4, k + 8, VetheaBlockHelper.dreamdirt.blockID);
		world.setBlock(i + 6, j + 4, k + 9, VetheaBlockHelper.dreamdirt.blockID);
		world.setBlock(i + 6, j + 4, k + 10, VetheaBlockHelper.hungerstone2.blockID);
		world.setBlock(i + 6, j + 4, k + 11, VetheaBlockHelper.hungerstone2.blockID);
		world.setBlock(i + 6, j + 4, k + 12, VetheaBlockHelper.hungerstone2.blockID);
		world.setBlock(i + 6, j + 4, k + 13, VetheaBlockHelper.hungerstone2.blockID);
		world.setBlock(i + 6, j + 4, k + 14, VetheaBlockHelper.hungerstone2.blockID);
		world.setBlock(i + 6, j + 4, k + 15, VetheaBlockHelper.hungerstone2.blockID);
		world.setBlock(i + 6, j + 4, k + 16, VetheaBlockHelper.dreamdirt.blockID);
		world.setBlock(i + 6, j + 4, k + 17, VetheaBlockHelper.dreamdirt.blockID);
		world.setBlock(i + 6, j + 4, k + 18, VetheaBlockHelper.dreamdirt.blockID);
		world.setBlock(i + 6, j + 4, k + 19, VetheaBlockHelper.dreamdirt.blockID);
		world.setBlock(i + 6, j + 5, k + 0, VetheaBlockHelper.cryptWall.blockID);
		world.setBlock(i + 6, j + 5, k + 1, VetheaBlockHelper.cryptWall.blockID);
		world.setBlock(i + 6, j + 5, k + 2, VetheaBlockHelper.cryptWall.blockID);
		world.setBlock(i + 6, j + 5, k + 3, VetheaBlockHelper.cryptWall.blockID);
		world.setBlock(i + 6, j + 5, k + 4, VetheaBlockHelper.cryptWall.blockID);
		world.setBlock(i + 6, j + 5, k + 5, VetheaBlockHelper.cryptWall.blockID);
		world.setBlock(i + 6, j + 5, k + 6, VetheaBlockHelper.cryptWall.blockID);
		world.setBlock(i + 6, j + 5, k + 7, VetheaBlockHelper.cryptWall.blockID);
		world.setBlock(i + 6, j + 5, k + 8, VetheaBlockHelper.cryptWall.blockID);
		world.setBlock(i + 6, j + 5, k + 9, VetheaBlockHelper.cryptWall.blockID);
		world.setBlock(i + 6, j + 5, k + 10, VetheaBlockHelper.cryptWall.blockID);
		world.setBlock(i + 6, j + 5, k + 11, VetheaBlockHelper.cryptWall.blockID);
		world.setBlock(i + 6, j + 5, k + 12, VetheaBlockHelper.cryptWall.blockID);
		world.setBlock(i + 6, j + 5, k + 13, VetheaBlockHelper.cryptWall.blockID);
		world.setBlock(i + 6, j + 5, k + 14, VetheaBlockHelper.cryptWall.blockID);
		world.setBlock(i + 6, j + 5, k + 15, VetheaBlockHelper.cryptWall.blockID);
		world.setBlock(i + 6, j + 5, k + 16, VetheaBlockHelper.cryptWall.blockID);
		world.setBlock(i + 6, j + 5, k + 17, VetheaBlockHelper.cryptWall.blockID);
		world.setBlock(i + 6, j + 5, k + 18, VetheaBlockHelper.cryptWall.blockID);
		world.setBlock(i + 6, j + 5, k + 19, VetheaBlockHelper.cryptWall.blockID);
		world.setBlock(i + 6, j + 6, k + 0, 0);
		world.setBlock(i + 6, j + 6, k + 1, 0);
		world.setBlock(i + 6, j + 6, k + 2, 0);
		world.setBlock(i + 6, j + 6, k + 3, 0);
		world.setBlock(i + 6, j + 6, k + 4, 0);
		world.setBlock(i + 6, j + 6, k + 5, 0);
		world.setBlock(i + 6, j + 6, k + 6, 0);
		world.setBlock(i + 6, j + 6, k + 7, 0);
		world.setBlock(i + 6, j + 6, k + 8, 0);
		world.setBlock(i + 6, j + 6, k + 9, 0);
		world.setBlock(i + 6, j + 6, k + 10, 0);
		world.setBlock(i + 6, j + 6, k + 11, 0);
		world.setBlock(i + 6, j + 6, k + 12, 0);
		world.setBlock(i + 6, j + 6, k + 13, 0);
		world.setBlock(i + 6, j + 6, k + 14, 0);
		world.setBlock(i + 6, j + 6, k + 15, 0);
		world.setBlock(i + 6, j + 6, k + 16, 0);
		world.setBlock(i + 6, j + 6, k + 17, 0);
		world.setBlock(i + 6, j + 6, k + 18, 0);
		world.setBlock(i + 6, j + 6, k + 19, 0);
		world.setBlock(i + 6, j + 7, k + 0, 0);
		world.setBlock(i + 6, j + 7, k + 1, 0);
		world.setBlock(i + 6, j + 7, k + 2, 0);
		world.setBlock(i + 6, j + 7, k + 3, 0);
		world.setBlock(i + 6, j + 7, k + 4, 0);
		world.setBlock(i + 6, j + 7, k + 5, 0);
		world.setBlock(i + 6, j + 7, k + 6, 0);
		world.setBlock(i + 6, j + 7, k + 7, 0);
		world.setBlock(i + 6, j + 7, k + 8, 0);
		world.setBlock(i + 6, j + 7, k + 9, 0);
		world.setBlock(i + 6, j + 7, k + 10, 0);
		world.setBlock(i + 6, j + 7, k + 11, 0);
		world.setBlock(i + 6, j + 7, k + 12, 0);
		world.setBlock(i + 6, j + 7, k + 13, 0);
		world.setBlock(i + 6, j + 7, k + 14, 0);
		world.setBlock(i + 6, j + 7, k + 15, 0);
		world.setBlock(i + 6, j + 7, k + 16, 0);
		world.setBlock(i + 6, j + 7, k + 17, 0);
		world.setBlock(i + 6, j + 7, k + 18, 0);
		world.setBlock(i + 6, j + 7, k + 19, 0);
		world.setBlock(i + 6, j + 8, k + 0, VetheaBlockHelper.hungerstone1.blockID);
		world.setBlock(i + 6, j + 8, k + 1, 0);
		world.setBlock(i + 6, j + 8, k + 2, 0);
		world.setBlock(i + 6, j + 8, k + 3, 0);
		world.setBlock(i + 6, j + 8, k + 4, 0);
		world.setBlock(i + 6, j + 8, k + 5, 0);
		world.setBlock(i + 6, j + 8, k + 6, 0);
		world.setBlock(i + 6, j + 8, k + 7, 0);
		world.setBlock(i + 6, j + 8, k + 8, 0);
		world.setBlock(i + 6, j + 8, k + 9, 0);
		world.setBlock(i + 6, j + 8, k + 10, 0);
		world.setBlock(i + 6, j + 8, k + 11, 0);
		world.setBlock(i + 6, j + 8, k + 12, 0);
		world.setBlock(i + 6, j + 8, k + 13, 0);
		world.setBlock(i + 6, j + 8, k + 14, 0);
		world.setBlock(i + 6, j + 8, k + 15, 0);
		world.setBlock(i + 6, j + 8, k + 16, 0);
		world.setBlock(i + 6, j + 8, k + 17, 0);
		world.setBlock(i + 6, j + 8, k + 18, 0);
		world.setBlock(i + 6, j + 8, k + 19, VetheaBlockHelper.hungerstone1.blockID);

		generate2(world, rand, i, j, k);
		return true;
	}

	public boolean generate2(World world, Random rand, int i, int j, int k) {
		world.setBlock(i + 6, j + 9, k + 0, 0);
		world.setBlock(i + 6, j + 9, k + 1, 0);
		world.setBlock(i + 6, j + 9, k + 2, 0);
		world.setBlock(i + 6, j + 9, k + 3, 0);
		world.setBlock(i + 6, j + 9, k + 4, 0);
		world.setBlock(i + 6, j + 9, k + 5, 0);
		world.setBlock(i + 6, j + 9, k + 6, 0);
		world.setBlock(i + 6, j + 9, k + 7, 0);
		world.setBlock(i + 6, j + 9, k + 8, 0);
		world.setBlock(i + 6, j + 9, k + 9, 0);
		world.setBlock(i + 6, j + 9, k + 10, 0);
		world.setBlock(i + 6, j + 9, k + 11, 0);
		world.setBlock(i + 6, j + 9, k + 12, 0);
		world.setBlock(i + 6, j + 9, k + 13, 0);
		world.setBlock(i + 6, j + 9, k + 14, 0);
		world.setBlock(i + 6, j + 9, k + 15, 0);
		world.setBlock(i + 6, j + 9, k + 16, 0);
		world.setBlock(i + 6, j + 9, k + 17, 0);
		world.setBlock(i + 6, j + 9, k + 18, 0);
		world.setBlock(i + 6, j + 9, k + 19, 0);
		world.setBlock(i + 6, j + 10, k + 0, 0);
		world.setBlock(i + 6, j + 10, k + 1, 0);
		world.setBlock(i + 6, j + 10, k + 2, 0);
		world.setBlock(i + 6, j + 10, k + 3, 0);
		world.setBlock(i + 6, j + 10, k + 4, 0);
		world.setBlock(i + 6, j + 10, k + 5, 0);
		world.setBlock(i + 6, j + 10, k + 6, 0);
		world.setBlock(i + 6, j + 10, k + 7, 0);
		world.setBlock(i + 6, j + 10, k + 8, 0);
		world.setBlock(i + 6, j + 10, k + 9, 0);
		world.setBlock(i + 6, j + 10, k + 10, 0);
		world.setBlock(i + 6, j + 10, k + 11, 0);
		world.setBlock(i + 6, j + 10, k + 12, 0);
		world.setBlock(i + 6, j + 10, k + 13, 0);
		world.setBlock(i + 6, j + 10, k + 14, 0);
		world.setBlock(i + 6, j + 10, k + 15, 0);
		world.setBlock(i + 6, j + 10, k + 16, 0);
		world.setBlock(i + 6, j + 10, k + 17, 0);
		world.setBlock(i + 6, j + 10, k + 18, 0);
		world.setBlock(i + 6, j + 10, k + 19, 0);
		world.setBlock(i + 7, j + 0, k + 0, VetheaBlockHelper.cryptWall.blockID);
		world.setBlock(i + 7, j + 0, k + 1, 0);
		world.setBlock(i + 7, j + 0, k + 2, 0);
		world.setBlock(i + 7, j + 0, k + 3, 0);
		world.setBlock(i + 7, j + 0, k + 4, 0);
		world.setBlock(i + 7, j + 0, k + 5, VetheaBlockHelper.cryptWall.blockID);
		world.setBlock(i + 7, j + 0, k + 6, VetheaBlockHelper.dreamdirt.blockID);
		world.setBlock(i + 7, j + 0, k + 7, VetheaBlockHelper.dreamdirt.blockID);
		world.setBlock(i + 7, j + 0, k + 8, VetheaBlockHelper.dreamdirt.blockID);
		world.setBlock(i + 7, j + 0, k + 9, VetheaBlockHelper.dreamdirt.blockID);
		world.setBlock(i + 7, j + 0, k + 10, VetheaBlockHelper.cryptFloor.blockID);
		world.setBlock(i + 7, j + 0, k + 11, VetheaBlockHelper.cryptFloor.blockID);
		world.setBlock(i + 7, j + 0, k + 12, VetheaBlockHelper.cryptFloor.blockID);
		world.setBlock(i + 7, j + 0, k + 13, VetheaBlockHelper.cryptFloor.blockID);
		world.setBlock(i + 7, j + 0, k + 14, VetheaBlockHelper.cryptFloor.blockID);
		world.setBlock(i + 7, j + 0, k + 15, VetheaBlockHelper.cryptFloor.blockID);
		world.setBlock(i + 7, j + 0, k + 16, VetheaBlockHelper.dreamdirt.blockID);
		world.setBlock(i + 7, j + 0, k + 17, VetheaBlockHelper.dreamdirt.blockID);
		world.setBlock(i + 7, j + 0, k + 18, VetheaBlockHelper.dreamdirt.blockID);
		world.setBlock(i + 7, j + 0, k + 19, VetheaBlockHelper.dreamdirt.blockID);
		world.setBlock(i + 7, j + 1, k + 0, VetheaBlockHelper.cryptWall.blockID);
		world.setBlock(i + 7, j + 1, k + 1, 0);
		world.setBlock(i + 7, j + 1, k + 2, 0);
		world.setBlock(i + 7, j + 1, k + 3, 0);
		world.setBlock(i + 7, j + 1, k + 4, 0);
		world.setBlock(i + 7, j + 1, k + 5, VetheaBlockHelper.cryptWall.blockID);
		world.setBlock(i + 7, j + 1, k + 6, VetheaBlockHelper.dreamdirt.blockID);
		world.setBlock(i + 7, j + 1, k + 7, VetheaBlockHelper.dreamdirt.blockID);
		world.setBlock(i + 7, j + 1, k + 8, VetheaBlockHelper.dreamdirt.blockID);
		world.setBlock(i + 7, j + 1, k + 9, VetheaBlockHelper.cryptWall.blockID);
		world.setBlock(i + 7, j + 1, k + 10, 0);
		world.setBlock(i + 7, j + 1, k + 11, 0);
		world.setBlock(i + 7, j + 1, k + 12, 0);
		world.setBlock(i + 7, j + 1, k + 13, 0);
		world.setBlock(i + 7, j + 1, k + 14, 0);
		world.setBlock(i + 7, j + 1, k + 15, 0);
		world.setBlock(i + 7, j + 1, k + 16, VetheaBlockHelper.cryptWall.blockID);
		world.setBlock(i + 7, j + 1, k + 17, VetheaBlockHelper.dreamdirt.blockID);
		world.setBlock(i + 7, j + 1, k + 18, VetheaBlockHelper.dreamdirt.blockID);
		world.setBlock(i + 7, j + 1, k + 19, VetheaBlockHelper.dreamdirt.blockID);
		world.setBlock(i + 7, j + 2, k + 0, VetheaBlockHelper.cryptWall.blockID);
		world.setBlock(i + 7, j + 2, k + 1, 0);
		world.setBlock(i + 7, j + 2, k + 2, 0);
		world.setBlock(i + 7, j + 2, k + 3, 0);
		world.setBlock(i + 7, j + 2, k + 4, 0);
		world.setBlock(i + 7, j + 2, k + 5, VetheaBlockHelper.cryptWall.blockID);
		world.setBlock(i + 7, j + 2, k + 6, VetheaBlockHelper.dreamdirt.blockID);
		world.setBlock(i + 7, j + 2, k + 7, VetheaBlockHelper.dreamdirt.blockID);
		world.setBlock(i + 7, j + 2, k + 8, VetheaBlockHelper.dreamdirt.blockID);
		world.setBlock(i + 7, j + 2, k + 9, VetheaBlockHelper.cryptWall.blockID);
		world.setBlock(i + 7, j + 2, k + 10, 0);
		world.setBlock(i + 7, j + 2, k + 11, 0);
		world.setBlock(i + 7, j + 2, k + 12, 0);
		world.setBlock(i + 7, j + 2, k + 13, 0);
		world.setBlock(i + 7, j + 2, k + 14, 0);
		world.setBlock(i + 7, j + 2, k + 15, 0);
		world.setBlock(i + 7, j + 2, k + 16, VetheaBlockHelper.cryptWall.blockID);
		world.setBlock(i + 7, j + 2, k + 17, VetheaBlockHelper.dreamdirt.blockID);
		world.setBlock(i + 7, j + 2, k + 18, VetheaBlockHelper.dreamdirt.blockID);
		world.setBlock(i + 7, j + 2, k + 19, VetheaBlockHelper.dreamdirt.blockID);
		world.setBlock(i + 7, j + 3, k + 0, VetheaBlockHelper.cryptWall.blockID);
		world.setBlock(i + 7, j + 3, k + 1, 0);
		world.setBlock(i + 7, j + 3, k + 2, 0);
		world.setBlock(i + 7, j + 3, k + 3, 0);
		world.setBlock(i + 7, j + 3, k + 4, 0);
		world.setBlock(i + 7, j + 3, k + 5, VetheaBlockHelper.cryptWall.blockID);
		world.setBlock(i + 7, j + 3, k + 6, VetheaBlockHelper.dreamdirt.blockID);
		world.setBlock(i + 7, j + 3, k + 7, VetheaBlockHelper.dreamdirt.blockID);
		world.setBlock(i + 7, j + 3, k + 8, VetheaBlockHelper.dreamdirt.blockID);
		world.setBlock(i + 7, j + 3, k + 9, VetheaBlockHelper.cryptWall.blockID);
		world.setBlock(i + 7, j + 3, k + 10, 0);
		world.setBlock(i + 7, j + 3, k + 11, 0);
		world.setBlock(i + 7, j + 3, k + 12, 0);
		world.setBlock(i + 7, j + 3, k + 13, 0);
		world.setBlock(i + 7, j + 3, k + 14, 0);
		world.setBlock(i + 7, j + 3, k + 15, 0);
		world.setBlock(i + 7, j + 3, k + 16, VetheaBlockHelper.cryptWall.blockID);
		world.setBlock(i + 7, j + 3, k + 17, VetheaBlockHelper.dreamdirt.blockID);
		world.setBlock(i + 7, j + 3, k + 18, VetheaBlockHelper.dreamdirt.blockID);
		world.setBlock(i + 7, j + 3, k + 19, VetheaBlockHelper.dreamdirt.blockID);
		world.setBlock(i + 7, j + 4, k + 0, VetheaBlockHelper.dreamdirt.blockID);
		world.setBlock(i + 7, j + 4, k + 1, VetheaBlockHelper.hungerstone2.blockID);
		world.setBlock(i + 7, j + 4, k + 2, VetheaBlockHelper.hungerstone2.blockID);
		world.setBlock(i + 7, j + 4, k + 3, VetheaBlockHelper.hungerstone2.blockID);
		world.setBlock(i + 7, j + 4, k + 4, VetheaBlockHelper.hungerstone2.blockID);
		world.setBlock(i + 7, j + 4, k + 5, VetheaBlockHelper.dreamdirt.blockID);
		world.setBlock(i + 7, j + 4, k + 6, VetheaBlockHelper.dreamdirt.blockID);
		world.setBlock(i + 7, j + 4, k + 7, VetheaBlockHelper.dreamdirt.blockID);
		world.setBlock(i + 7, j + 4, k + 8, VetheaBlockHelper.dreamdirt.blockID);
		world.setBlock(i + 7, j + 4, k + 9, VetheaBlockHelper.dreamdirt.blockID);
		world.setBlock(i + 7, j + 4, k + 10, VetheaBlockHelper.hungerstone2.blockID);
		world.setBlock(i + 7, j + 4, k + 11, VetheaBlockHelper.hungerstone2.blockID);
		world.setBlock(i + 7, j + 4, k + 12, VetheaBlockHelper.hungerstone2.blockID);
		world.setBlock(i + 7, j + 4, k + 13, VetheaBlockHelper.hungerstone2.blockID);
		world.setBlock(i + 7, j + 4, k + 14, VetheaBlockHelper.hungerstone2.blockID);
		world.setBlock(i + 7, j + 4, k + 15, VetheaBlockHelper.hungerstone2.blockID);
		world.setBlock(i + 7, j + 4, k + 16, VetheaBlockHelper.dreamdirt.blockID);
		world.setBlock(i + 7, j + 4, k + 17, VetheaBlockHelper.dreamdirt.blockID);
		world.setBlock(i + 7, j + 4, k + 18, VetheaBlockHelper.dreamdirt.blockID);
		world.setBlock(i + 7, j + 4, k + 19, VetheaBlockHelper.dreamdirt.blockID);
		world.setBlock(i + 7, j + 5, k + 0, VetheaBlockHelper.cryptWall.blockID);
		world.setBlock(i + 7, j + 5, k + 1, VetheaBlockHelper.cryptWall.blockID);
		world.setBlock(i + 7, j + 5, k + 2, VetheaBlockHelper.cryptWall.blockID);
		world.setBlock(i + 7, j + 5, k + 3, VetheaBlockHelper.cryptWall.blockID);
