/*
*** MADE BY MITHION'S .SCHEMATIC TO JAVA CONVERTING TOOL v1.6 ***
*/

package xolova.divinerpg.worldgen.vethea.layer1;
import java.util.Random;

import net.minecraft.world.World;
import net.minecraft.world.gen.feature.WorldGenerator;
import xolova.divinerpg.utils.helpers.block.VetheaBlockHelper;

public class Tree6 extends WorldGenerator
{
	protected int[] GetValidSpawnBlocks() {
		return new int[] {
		};
	}

	public Tree6() { }

	public boolean generate(World world, Random rand, int i, int j, int k) {

		world.setBlock(i + 0, j + 6, k + 3, VetheaBlockHelper.hyrewoodLeaves.blockID);
		world.setBlock(i + 0, j + 7, k + 0, VetheaBlockHelper.hyrewoodLeaves.blockID);
		world.setBlock(i + 0, j + 7, k + 3, VetheaBlockHelper.hyrewoodLeaves.blockID);
		world.setBlock(i + 0, j + 8, k + 0, VetheaBlockHelper.hyrewoodLeaves.blockID);
		world.setBlock(i + 0, j + 8, k + 2, VetheaBlockHelper.hyrewoodLeaves.blockID);
		world.setBlock(i + 0, j + 8, k + 3, VetheaBlockHelper.hyrewoodLeaves.blockID);
		world.setBlock(i + 0, j + 9, k + 0, VetheaBlockHelper.hyrewoodLeaves.blockID);
		world.setBlock(i + 0, j + 9, k + 1, VetheaBlockHelper.hyrewoodLeaves.blockID);
		world.setBlock(i + 0, j + 9, k + 2, VetheaBlockHelper.hyrewoodLeaves.blockID);
		world.setBlock(i + 0, j + 10, k + 0, VetheaBlockHelper.hyrewoodLeaves.blockID);
		world.setBlock(i + 0, j + 10, k + 1, VetheaBlockHelper.hyrewoodLeaves.blockID);
		world.setBlock(i + 0, j + 10, k + 2, VetheaBlockHelper.hyrewoodLeaves.blockID);
		world.setBlock(i + 0, j + 10, k + 3, VetheaBlockHelper.hyrewoodLeaves.blockID);
		world.setBlock(i + 0, j + 11, k + 0, VetheaBlockHelper.hyrewoodLeaves.blockID);
		world.setBlock(i + 0, j + 11, k + 3, VetheaBlockHelper.hyrewoodLeaves.blockID);
		world.setBlock(i + 0, j + 12, k + 0, VetheaBlockHelper.hyrewoodLeaves.blockID);
		world.setBlock(i + 0, j + 12, k + 3, VetheaBlockHelper.hyrewoodLeaves.blockID);
		world.setBlock(i + 0, j + 13, k + 0, VetheaBlockHelper.hyrewoodLeaves.blockID);
		world.setBlock(i + 0, j + 13, k + 1, VetheaBlockHelper.hyrewoodLeaves.blockID);
		world.setBlock(i + 0, j + 13, k + 2, VetheaBlockHelper.hyrewoodLeaves.blockID);
		world.setBlock(i + 0, j + 13, k + 3, VetheaBlockHelper.hyrewoodLeaves.blockID);
		world.setBlock(i + 0, j + 13, k + 4, VetheaBlockHelper.hyrewoodLeaves.blockID);
		world.setBlock(i + 0, j + 13, k + 5, VetheaBlockHelper.hyrewoodLeaves.blockID);
		world.setBlock(i + 1, j + 13, k + 0, VetheaBlockHelper.hyrewoodLeaves.blockID);
		world.setBlock(i + 1, j + 13, k + 5, VetheaBlockHelper.hyrewoodLeaves.blockID);
		world.setBlock(i + 1, j + 14, k + 1, VetheaBlockHelper.hyrewoodLeaves.blockID);
		world.setBlock(i + 1, j + 14, k + 2, VetheaBlockHelper.hyrewoodLeaves.blockID);
		world.setBlock(i + 1, j + 14, k + 3, VetheaBlockHelper.hyrewoodLeaves.blockID);
		world.setBlock(i + 1, j + 14, k + 4, VetheaBlockHelper.hyrewoodLeaves.blockID);
		world.setBlock(i + 2, j + 0, k + 2, VetheaBlockHelper.hyrewood.blockID);
		world.setBlock(i + 2, j + 0, k + 3, VetheaBlockHelper.hyrewood.blockID);
		world.setBlock(i + 2, j + 1, k + 2, VetheaBlockHelper.hyrewood.blockID);
		world.setBlock(i + 2, j + 1, k + 3, VetheaBlockHelper.hyrewood.blockID);
		world.setBlock(i + 2, j + 2, k + 2, VetheaBlockHelper.hyrewood.blockID);
		world.setBlock(i + 2, j + 2, k + 3, VetheaBlockHelper.hyrewood.blockID);
		world.setBlock(i + 2, j + 3, k + 2, VetheaBlockHelper.hyrewood.blockID);
		world.setBlock(i + 2, j + 3, k + 3, VetheaBlockHelper.hyrewood.blockID);
		world.setBlock(i + 2, j + 4, k + 2, VetheaBlockHelper.hyrewood.blockID);
		world.setBlock(i + 2, j + 4, k + 3, VetheaBlockHelper.hyrewood.blockID);
		world.setBlock(i + 2, j + 5, k + 2, VetheaBlockHelper.hyrewood.blockID);
		world.setBlock(i + 2, j + 5, k + 3, VetheaBlockHelper.hyrewood.blockID);
		world.setBlock(i + 2, j + 6, k + 2, VetheaBlockHelper.hyrewood.blockID);
		world.setBlock(i + 2, j + 6, k + 3, VetheaBlockHelper.hyrewood.blockID);
		world.setBlock(i + 2, j + 7, k + 2, VetheaBlockHelper.hyrewood.blockID);
		world.setBlock(i + 2, j + 7, k + 3, VetheaBlockHelper.hyrewood.blockID);
		world.setBlock(i + 2, j + 7, k + 5, VetheaBlockHelper.hyrewoodLeaves.blockID);
		world.setBlock(i + 2, j + 8, k + 2, VetheaBlockHelper.hyrewood.blockID);
		world.setBlock(i + 2, j + 8, k + 3, VetheaBlockHelper.hyrewood.blockID);
		world.setBlock(i + 2, j + 8, k + 5, VetheaBlockHelper.hyrewoodLeaves.blockID);
		world.setBlock(i + 2, j + 9, k + 2, VetheaBlockHelper.hyrewood.blockID);
		world.setBlock(i + 2, j + 9, k + 3, VetheaBlockHelper.hyrewood.blockID);
		world.setBlock(i + 2, j + 10, k + 0, VetheaBlockHelper.hyrewoodLeaves.blockID);
		world.setBlock(i + 2, j + 10, k + 2, VetheaBlockHelper.hyrewood.blockID);
		world.setBlock(i + 2, j + 10, k + 3, VetheaBlockHelper.hyrewood.blockID);
		world.setBlock(i + 2, j + 11, k + 0, VetheaBlockHelper.hyrewoodLeaves.blockID);
		world.setBlock(i + 2, j + 11, k + 2, VetheaBlockHelper.hyrewood.blockID);
		world.setBlock(i + 2, j + 11, k + 3, VetheaBlockHelper.hyrewood.blockID);
		world.setBlock(i + 2, j + 11, k + 5, VetheaBlockHelper.hyrewoodLeaves.blockID);
		world.setBlock(i + 2, j + 12, k + 2, VetheaBlockHelper.hyrewood.blockID);
		world.setBlock(i + 2, j + 12, k + 3, VetheaBlockHelper.hyrewood.blockID);
		world.setBlock(i + 2, j + 12, k + 5, VetheaBlockHelper.hyrewoodLeaves.blockID);
		world.setBlock(i + 2, j + 13, k + 0, VetheaBlockHelper.hyrewoodLeaves.blockID);
		world.setBlock(i + 2, j + 13, k + 2, VetheaBlockHelper.hyrewood.blockID);
		world.setBlock(i + 2, j + 13, k + 3, VetheaBlockHelper.hyrewood.blockID);
		world.setBlock(i + 2, j + 13, k + 5, VetheaBlockHelper.hyrewoodLeaves.blockID);
		world.setBlock(i + 2, j + 14, k + 1, VetheaBlockHelper.hyrewoodLeaves.blockID);
		world.setBlock(i + 2, j + 14, k + 2, VetheaBlockHelper.hyrewoodLeaves.blockID);
		world.setBlock(i + 2, j + 14, k + 3, VetheaBlockHelper.hyrewoodLeaves.blockID);
		world.setBlock(i + 2, j + 14, k + 4, VetheaBlockHelper.hyrewoodLeaves.blockID);
		world.setBlock(i + 2, j + 15, k + 2, VetheaBlockHelper.hyrewoodLeaves.blockID);
		world.setBlock(i + 2, j + 15, k + 3, VetheaBlockHelper.hyrewoodLeaves.blockID);
		world.setBlock(i + 3, j + 0, k + 2, VetheaBlockHelper.hyrewood.blockID);
		world.setBlock(i + 3, j + 0, k + 3, VetheaBlockHelper.hyrewood.blockID);
		world.setBlock(i + 3, j + 1, k + 2, VetheaBlockHelper.hyrewood.blockID);
		world.setBlock(i + 3, j + 1, k + 3, VetheaBlockHelper.hyrewood.blockID);
		world.setBlock(i + 3, j + 2, k + 2, VetheaBlockHelper.hyrewood.blockID);
		world.setBlock(i + 3, j + 2, k + 3, VetheaBlockHelper.hyrewood.blockID);
		world.setBlock(i + 3, j + 3, k + 2, VetheaBlockHelper.hyrewood.blockID);
		world.setBlock(i + 3, j + 3, k + 3, VetheaBlockHelper.hyrewood.blockID);
		world.setBlock(i + 3, j + 4, k + 2, VetheaBlockHelper.hyrewood.blockID);
		world.setBlock(i + 3, j + 4, k + 3, VetheaBlockHelper.hyrewood.blockID);
		world.setBlock(i + 3, j + 5, k + 2, VetheaBlockHelper.hyrewood.blockID);
		world.setBlock(i + 3, j + 5, k + 3, VetheaBlockHelper.hyrewood.blockID);
		world.setBlock(i + 3, j + 6, k + 0, VetheaBlockHelper.hyrewoodLeaves.blockID);
		world.setBlock(i + 3, j + 6, k + 2, VetheaBlockHelper.hyrewood.blockID);
		world.setBlock(i + 3, j + 6, k + 3, VetheaBlockHelper.hyrewood.blockID);
		world.setBlock(i + 3, j + 7, k + 2, VetheaBlockHelper.hyrewood.blockID);
		world.setBlock(i + 3, j + 7, k + 3, VetheaBlockHelper.hyrewood.blockID);
		world.setBlock(i + 3, j + 8, k + 2, VetheaBlockHelper.hyrewood.blockID);
		world.setBlock(i + 3, j + 8, k + 3, VetheaBlockHelper.hyrewood.blockID);
		world.setBlock(i + 3, j + 8, k + 5, VetheaBlockHelper.hyrewoodLeaves.blockID);
		world.setBlock(i + 3, j + 9, k + 2, VetheaBlockHelper.hyrewood.blockID);
		world.setBlock(i + 3, j + 9, k + 3, VetheaBlockHelper.hyrewood.blockID);
		world.setBlock(i + 3, j + 9, k + 5, VetheaBlockHelper.hyrewoodLeaves.blockID);
		world.setBlock(i + 3, j + 10, k + 2, VetheaBlockHelper.hyrewood.blockID);
		world.setBlock(i + 3, j + 10, k + 3, VetheaBlockHelper.hyrewood.blockID);
		world.setBlock(i + 3, j + 10, k + 5, VetheaBlockHelper.hyrewoodLeaves.blockID);
		world.setBlock(i + 3, j + 11, k + 0, VetheaBlockHelper.hyrewoodLeaves.blockID);
		world.setBlock(i + 3, j + 11, k + 2, VetheaBlockHelper.hyrewood.blockID);
		world.setBlock(i + 3, j + 11, k + 3, VetheaBlockHelper.hyrewood.blockID);
		world.setBlock(i + 3, j + 11, k + 5, VetheaBlockHelper.hyrewoodLeaves.blockID);
		world.setBlock(i + 3, j + 12, k + 2, VetheaBlockHelper.hyrewood.blockID);
		world.setBlock(i + 3, j + 12, k + 3, VetheaBlockHelper.hyrewood.blockID);
		world.setBlock(i + 3, j + 13, k + 0, VetheaBlockHelper.hyrewoodLeaves.blockID);
		world.setBlock(i + 3, j + 13, k + 2, VetheaBlockHelper.hyrewood.blockID);
		world.setBlock(i + 3, j + 13, k + 3, VetheaBlockHelper.hyrewood.blockID);
		world.setBlock(i + 3, j + 13, k + 5, VetheaBlockHelper.hyrewoodLeaves.blockID);
		world.setBlock(i + 3, j + 14, k + 1, VetheaBlockHelper.hyrewoodLeaves.blockID);
		world.setBlock(i + 3, j + 14, k + 2, VetheaBlockHelper.hyrewoodLeaves.blockID);
		world.setBlock(i + 3, j + 14, k + 3, VetheaBlockHelper.hyrewoodLeaves.blockID);
		world.setBlock(i + 3, j + 14, k + 4, VetheaBlockHelper.hyrewoodLeaves.blockID);
		world.setBlock(i + 3, j + 15, k + 2, VetheaBlockHelper.hyrewoodLeaves.blockID);
		world.setBlock(i + 3, j + 15, k + 3, VetheaBlockHelper.hyrewoodLeaves.blockID);
		world.setBlock(i + 4, j + 6, k + 0, VetheaBlockHelper.hyrewoodLeaves.blockID);
		world.setBlock(i + 4, j + 7, k + 0, VetheaBlockHelper.hyrewoodLeaves.blockID);
		world.setBlock(i + 4, j + 8, k + 0, VetheaBlockHelper.hyrewoodLeaves.blockID);
		world.setBlock(i + 4, j + 10, k + 0, VetheaBlockHelper.hyrewoodLeaves.blockID);
		world.setBlock(i + 4, j + 11, k + 0, VetheaBlockHelper.hyrewoodLeaves.blockID);
		world.setBlock(i + 4, j + 12, k + 0, VetheaBlockHelper.hyrewoodLeaves.blockID);
		world.setBlock(i + 4, j + 13, k + 0, VetheaBlockHelper.hyrewoodLeaves.blockID);
		world.setBlock(i + 4, j + 13, k + 5, VetheaBlockHelper.hyrewoodLeaves.blockID);
		world.setBlock(i + 4, j + 14, k + 1, VetheaBlockHelper.hyrewoodLeaves.blockID);
		world.setBlock(i + 4, j + 14, k + 2, VetheaBlockHelper.hyrewoodLeaves.blockID);
		world.setBlock(i + 4, j + 14, k + 3, VetheaBlockHelper.hyrewoodLeaves.blockID);
		world.setBlock(i + 4, j + 14, k + 4, VetheaBlockHelper.hyrewoodLeaves.blockID);
		world.setBlock(i + 5, j + 7, k + 4, VetheaBlockHelper.hyrewoodLeaves.blockID);
		world.setBlock(i + 5, j + 7, k + 5, VetheaBlockHelper.hyrewoodLeaves.blockID);
		world.setBlock(i + 5, j + 8, k + 0, VetheaBlockHelper.hyrewoodLeaves.blockID);
		world.setBlock(i + 5, j + 8, k + 4, VetheaBlockHelper.hyrewoodLeaves.blockID);
		world.setBlock(i + 5, j + 9, k + 0, VetheaBlockHelper.hyrewoodLeaves.blockID);
		world.setBlock(i + 5, j + 9, k + 4, VetheaBlockHelper.hyrewoodLeaves.blockID);
		world.setBlock(i + 5, j + 9, k + 5, VetheaBlockHelper.hyrewoodLeaves.blockID);
		world.setBlock(i + 5, j + 10, k + 0, VetheaBlockHelper.hyrewoodLeaves.blockID);
		world.setBlock(i + 5, j + 10, k + 5, VetheaBlockHelper.hyrewoodLeaves.blockID);
		world.setBlock(i + 5, j + 11, k + 4, VetheaBlockHelper.hyrewoodLeaves.blockID);
		world.setBlock(i + 5, j + 11, k + 5, VetheaBlockHelper.hyrewoodLeaves.blockID);
		world.setBlock(i + 5, j + 12, k + 4, VetheaBlockHelper.hyrewoodLeaves.blockID);
		world.setBlock(i + 5, j + 13, k + 0, VetheaBlockHelper.hyrewoodLeaves.blockID);
		world.setBlock(i + 5, j + 13, k + 1, VetheaBlockHelper.hyrewoodLeaves.blockID);
		world.setBlock(i + 5, j + 13, k + 2, VetheaBlockHelper.hyrewoodLeaves.blockID);
		world.setBlock(i + 5, j + 13, k + 3, VetheaBlockHelper.hyrewoodLeaves.blockID);
		world.setBlock(i + 5, j + 13, k + 4, VetheaBlockHelper.hyrewoodLeaves.blockID);
		world.setBlock(i + 5, j + 13, k + 5, VetheaBlockHelper.hyrewoodLeaves.blockID);
		world.setBlock(i + 6, j + 7, k + 2, VetheaBlockHelper.hyrewoodLeaves.blockID);
		world.setBlock(i + 6, j + 8, k + 1, VetheaBlockHelper.hyrewoodLeaves.blockID);
		world.setBlock(i + 6, j + 8, k + 2, VetheaBlockHelper.hyrewoodLeaves.blockID);
		world.setBlock(i + 6, j + 9, k + 1, VetheaBlockHelper.hyrewoodLeaves.blockID);
		world.setBlock(i + 6, j + 10, k + 1, VetheaBlockHelper.hyrewoodLeaves.blockID);
		world.setBlock(i + 6, j + 10, k + 2, VetheaBlockHelper.hyrewoodLeaves.blockID);
		world.setBlock(i + 6, j + 11, k + 2, VetheaBlockHelper.hyrewoodLeaves.blockID);
		world.setBlock(i + 6, j + 12, k + 2, VetheaBlockHelper.hyrewoodLeaves.blockID);
		world.setBlock(i + 6, j + 13, k + 2, VetheaBlockHelper.hyrewoodLeaves.blockID);

		return true;
	}
}