/*
*** MADE BY MITHION'S .SCHEMATIC TO JAVA CONVERTING TOOL v1.6 ***
*/

package xolova.blued00r.divinerpg.generation.iceika;
import java.util.Random;

import xolova.blued00r.divinerpg.DivineRPG;
import xolova.blued00r.divinerpg.entities.tileentities.TileEntityIceikaChest;

import net.minecraft.block.Block;
import net.minecraft.item.ItemStack;
import net.minecraft.world.World;
import net.minecraft.world.gen.feature.WorldGenerator;
import net.minecraftforge.common.DungeonHooks;

public class WorldGenDungeon2 extends WorldGenerator
{
	protected int[] GetValidSpawnBlocks() {
		return new int[] {
			DivineRPG.iceikaStone.blockID
		};
	}

	public boolean LocationIsValidSpawn(World world, int i, int j, int k){
		int distanceToAir = 0;
		int checkID = world.getBlockId(i, j, k);

		while (checkID != 0){
			distanceToAir++;
			checkID = world.getBlockId(i, j + distanceToAir, k);
		}

		if (distanceToAir > 3){
			return false;
		}
		j += distanceToAir - 1;

		int blockID = world.getBlockId(i, j, k);
		int blockIDAbove = world.getBlockId(i, j+1, k);
		int blockIDBelow = world.getBlockId(i, j-1, k);
		for (int x : GetValidSpawnBlocks()){
			if (blockIDAbove != 0){
				return false;
			}
			if (blockID == x){
				return true;
			}else if (blockID == Block.snow.blockID && blockIDBelow == x){
				return true;
			}
		}
		return false;
	}

	public boolean generate(World world, Random rand, int i, int j, int k) {
		//check that each corner is one of the valid spawn blocks

		world.setBlock(i + 0, j + 0, k + 0, DivineRPG.iceikaStoneBricks.blockID);
		world.setBlock(i + 0, j + 0, k + 1, DivineRPG.iceikaStoneBricks.blockID);
		world.setBlock(i + 0, j + 0, k + 2, DivineRPG.iceikaStoneBricks.blockID);
		world.setBlock(i + 0, j + 0, k + 3, DivineRPG.iceikaStoneBricks.blockID);
		world.setBlock(i + 0, j + 0, k + 4, DivineRPG.iceikaStoneBricks.blockID);
		world.setBlock(i + 0, j + 0, k + 5, DivineRPG.iceikaStoneBricks.blockID);
		world.setBlock(i + 0, j + 0, k + 6, DivineRPG.iceikaStoneBricks.blockID);
		world.setBlock(i + 0, j + 0, k + 7, DivineRPG.iceikaStoneBricks.blockID);
		world.setBlock(i + 0, j + 1, k + 0, DivineRPG.iceikaStoneBricks.blockID);
		world.setBlock(i + 0, j + 1, k + 1, DivineRPG.iceikaStoneBricks.blockID);
		world.setBlock(i + 0, j + 1, k + 2, DivineRPG.iceikaStoneBricks.blockID);
		world.setBlock(i + 0, j + 1, k + 3, DivineRPG.iceikaStoneBricks.blockID);
		world.setBlock(i + 0, j + 1, k + 4, DivineRPG.iceikaStoneBricks.blockID);
		world.setBlock(i + 0, j + 1, k + 5, DivineRPG.iceikaStoneBricks.blockID);
		world.setBlock(i + 0, j + 1, k + 6, DivineRPG.iceikaStoneBricks.blockID);
		world.setBlock(i + 0, j + 1, k + 7, DivineRPG.iceikaStoneBricks.blockID);
		world.setBlock(i + 0, j + 2, k + 0, DivineRPG.iceikaStoneBricks.blockID);
		world.setBlock(i + 0, j + 2, k + 1, DivineRPG.iceikaStoneBricks.blockID);
		world.setBlock(i + 0, j + 2, k + 2, DivineRPG.iceikaStoneBricks.blockID);
		world.setBlock(i + 0, j + 2, k + 3, DivineRPG.iceikaStoneBricks.blockID);
		world.setBlock(i + 0, j + 2, k + 4, DivineRPG.iceikaStoneBricks.blockID);
		world.setBlock(i + 0, j + 2, k + 5, DivineRPG.iceikaStoneBricks.blockID);
		world.setBlock(i + 0, j + 2, k + 6, DivineRPG.iceikaStoneBricks.blockID);
		world.setBlock(i + 0, j + 2, k + 7, DivineRPG.iceikaStoneBricks.blockID);
		world.setBlock(i + 0, j + 3, k + 0, DivineRPG.iceikaStoneBricks.blockID);
		world.setBlock(i + 0, j + 3, k + 1, DivineRPG.iceikaStoneBricks.blockID);
		world.setBlock(i + 0, j + 3, k + 2, DivineRPG.iceikaStoneBricks.blockID);
		world.setBlock(i + 0, j + 3, k + 3, DivineRPG.iceikaStoneBricks.blockID);
		world.setBlock(i + 0, j + 3, k + 4, DivineRPG.iceikaStoneBricks.blockID);
		world.setBlock(i + 0, j + 3, k + 5, DivineRPG.iceikaStoneBricks.blockID);
		world.setBlock(i + 0, j + 3, k + 6, DivineRPG.iceikaStoneBricks.blockID);
		world.setBlock(i + 0, j + 3, k + 7, DivineRPG.iceikaStoneBricks.blockID);
		world.setBlock(i + 1, j + 0, k + 0, DivineRPG.iceikaStoneBricks.blockID);
		world.setBlock(i + 1, j + 0, k + 1, DivineRPG.iceikaMossyCobble.blockID);
		world.setBlock(i + 1, j + 0, k + 2, DivineRPG.iceikaMossyCobble.blockID);
		world.setBlock(i + 1, j + 0, k + 3, DivineRPG.iceikaMossyCobble.blockID);
		world.setBlock(i + 1, j + 0, k + 4, DivineRPG.iceikaMossyCobble.blockID);
		world.setBlock(i + 1, j + 0, k + 5, DivineRPG.iceikaMossyCobble.blockID);
		world.setBlock(i + 1, j + 0, k + 6, DivineRPG.iceikaMossyCobble.blockID);
		world.setBlock(i + 1, j + 0, k + 7, DivineRPG.iceikaStoneBricks.blockID);
		world.setBlock(i + 1, j + 0, k + 13, DivineRPG.iceikaStoneBricks.blockID);
		world.setBlock(i + 1, j + 0, k + 14, DivineRPG.iceikaStoneBricks.blockID);
		world.setBlock(i + 1, j + 0, k + 15, DivineRPG.iceikaStoneBricks.blockID);
		world.setBlock(i + 1, j + 0, k + 16, DivineRPG.iceikaStoneBricks.blockID);
		world.setBlock(i + 1, j + 0, k + 17, DivineRPG.iceikaStoneBricks.blockID);
		world.setBlock(i + 1, j + 0, k + 18, DivineRPG.iceikaStoneBricks.blockID);
		world.setBlock(i + 1, j + 0, k + 19, DivineRPG.iceikaStoneBricks.blockID);
		world.setBlock(i + 1, j + 0, k + 20, DivineRPG.iceikaStoneBricks.blockID);
		world.setBlock(i + 1, j + 1, k + 0, DivineRPG.iceikaStoneBricks.blockID);
		world.setBlockWithNotify(i + 1, j + 1, k + 1, DivineRPG.iceikaChest.blockID);
		world.setBlock(i + 1, j + 1, k + 2, 0);
		world.setBlock(i + 1, j + 1, k + 3, 0);
		world.setBlock(i + 1, j + 1, k + 4, 0);
		world.setBlock(i + 1, j + 1, k + 5, 0);
		world.setBlockWithNotify(i + 1, j + 1, k + 6, DivineRPG.iceikaChest.blockID);
		world.setBlock(i + 1, j + 1, k + 7, DivineRPG.iceikaStoneBricks.blockID);
		world.setBlock(i + 1, j + 1, k + 13, DivineRPG.iceikaStoneBricks.blockID);
		world.setBlock(i + 1, j + 1, k + 14, DivineRPG.iceikaStoneBricks.blockID);
		world.setBlock(i + 1, j + 1, k + 15, DivineRPG.iceikaStoneBricks.blockID);
		world.setBlock(i + 1, j + 1, k + 16, DivineRPG.iceikaStoneBricks.blockID);
		world.setBlock(i + 1, j + 1, k + 17, DivineRPG.iceikaStoneBricks.blockID);
		world.setBlock(i + 1, j + 1, k + 18, DivineRPG.iceikaStoneBricks.blockID);
		world.setBlock(i + 1, j + 1, k + 19, DivineRPG.iceikaStoneBricks.blockID);
		world.setBlock(i + 1, j + 1, k + 20, DivineRPG.iceikaStoneBricks.blockID);
		world.setBlock(i + 1, j + 2, k + 0, DivineRPG.iceikaStoneBricks.blockID);
		world.setBlock(i + 1, j + 2, k + 1, 0);
		world.setBlock(i + 1, j + 2, k + 2, 0);
		world.setBlock(i + 1, j + 2, k + 3, 0);
		world.setBlock(i + 1, j + 2, k + 4, 0);
		world.setBlock(i + 1, j + 2, k + 5, 0);
		world.setBlock(i + 1, j + 2, k + 6, 0);
		world.setBlock(i + 1, j + 2, k + 7, DivineRPG.iceikaStoneBricks.blockID);
		world.setBlock(i + 1, j + 2, k + 13, DivineRPG.iceikaStoneBricks.blockID);
		world.setBlock(i + 1, j + 2, k + 14, DivineRPG.iceikaStoneBricks.blockID);
		world.setBlock(i + 1, j + 2, k + 15, DivineRPG.iceikaStoneBricks.blockID);
		world.setBlock(i + 1, j + 2, k + 16, DivineRPG.iceikaStoneBricks.blockID);
		world.setBlock(i + 1, j + 2, k + 17, DivineRPG.iceikaStoneBricks.blockID);
		world.setBlock(i + 1, j + 2, k + 18, DivineRPG.iceikaStoneBricks.blockID);
		world.setBlock(i + 1, j + 2, k + 19, DivineRPG.iceikaStoneBricks.blockID);
		world.setBlock(i + 1, j + 2, k + 20, DivineRPG.iceikaStoneBricks.blockID);
		world.setBlock(i + 1, j + 3, k + 0, DivineRPG.iceikaStoneBricks.blockID);
		world.setBlock(i + 1, j + 3, k + 1, 0);
		world.setBlock(i + 1, j + 3, k + 2, 0);
		world.setBlock(i + 1, j + 3, k + 3, 0);
		world.setBlock(i + 1, j + 3, k + 4, 0);
		world.setBlock(i + 1, j + 3, k + 5, 0);
		world.setBlock(i + 1, j + 3, k + 6, 0);
		world.setBlock(i + 1, j + 3, k + 7, DivineRPG.iceikaStoneBricks.blockID);
		world.setBlock(i + 1, j + 3, k + 13, DivineRPG.iceikaStoneBricks.blockID);
		world.setBlock(i + 1, j + 3, k + 14, DivineRPG.iceikaStoneBricks.blockID);
		world.setBlock(i + 1, j + 3, k + 15, DivineRPG.iceikaStoneBricks.blockID);
		world.setBlock(i + 1, j + 3, k + 16, DivineRPG.iceikaStoneBricks.blockID);
		world.setBlock(i + 1, j + 3, k + 17, DivineRPG.iceikaStoneBricks.blockID);
		world.setBlock(i + 1, j + 3, k + 18, DivineRPG.iceikaStoneBricks.blockID);
		world.setBlock(i + 1, j + 3, k + 19, DivineRPG.iceikaStoneBricks.blockID);
		world.setBlock(i + 1, j + 3, k + 20, DivineRPG.iceikaStoneBricks.blockID);
		world.setBlock(i + 1, j + 4, k + 1, DivineRPG.iceikaStoneBricks.blockID);
		world.setBlock(i + 1, j + 4, k + 2, DivineRPG.iceikaStoneBricks.blockID);
		world.setBlock(i + 1, j + 4, k + 3, DivineRPG.iceikaStoneBricks.blockID);
		world.setBlock(i + 1, j + 4, k + 4, DivineRPG.iceikaStoneBricks.blockID);
		world.setBlock(i + 1, j + 4, k + 5, DivineRPG.iceikaStoneBricks.blockID);
		world.setBlock(i + 1, j + 4, k + 6, DivineRPG.iceikaStoneBricks.blockID);
		world.setBlock(i + 2, j + 0, k + 0, DivineRPG.iceikaStoneBricks.blockID);
		world.setBlock(i + 2, j + 0, k + 1, DivineRPG.iceikaMossyCobble.blockID);
		world.setBlock(i + 2, j + 0, k + 2, DivineRPG.iceikaMossyCobble.blockID);
		world.setBlock(i + 2, j + 0, k + 3, DivineRPG.iceikaMossyCobble.blockID);
		world.setBlock(i + 2, j + 0, k + 4, DivineRPG.iceikaMossyCobble.blockID);
		world.setBlock(i + 2, j + 0, k + 5, DivineRPG.iceikaMossyCobble.blockID);
		world.setBlock(i + 2, j + 0, k + 6, DivineRPG.iceikaMossyCobble.blockID);
		world.setBlock(i + 2, j + 0, k + 7, DivineRPG.iceikaStoneBricks.blockID);
		world.setBlock(i + 2, j + 0, k + 13, DivineRPG.iceikaStoneBricks.blockID);
		world.setBlock(i + 2, j + 0, k + 14, DivineRPG.iceikaMossyCobble.blockID);
		world.setBlock(i + 2, j + 0, k + 15, DivineRPG.iceikaMossyCobble.blockID);
		world.setBlock(i + 2, j + 0, k + 16, DivineRPG.iceikaMossyCobble.blockID);
		world.setBlock(i + 2, j + 0, k + 17, DivineRPG.iceikaMossyCobble.blockID);
		world.setBlock(i + 2, j + 0, k + 18, DivineRPG.iceikaMossyCobble.blockID);
		world.setBlock(i + 2, j + 0, k + 19, DivineRPG.iceikaMossyCobble.blockID);
		world.setBlock(i + 2, j + 0, k + 20, DivineRPG.iceikaStoneBricks.blockID);
		world.setBlock(i + 2, j + 1, k + 0, DivineRPG.iceikaStoneBricks.blockID);
		world.setBlock(i + 2, j + 1, k + 1, 0);
		world.setBlock(i + 2, j + 1, k + 2, 0);
		world.setBlock(i + 2, j + 1, k + 3, 0);
		world.setBlock(i + 2, j + 1, k + 4, 0);
		world.setBlock(i + 2, j + 1, k + 5, 0);
		world.setBlock(i + 2, j + 1, k + 6, 0);
		world.setBlock(i + 2, j + 1, k + 7, DivineRPG.iceikaStoneBricks.blockID);
		world.setBlock(i + 2, j + 1, k + 13, DivineRPG.iceikaStoneBricks.blockID);
		world.setBlock(i + 2, j + 1, k + 14, 0);
		world.setBlock(i + 2, j + 1, k + 15, 0);
		world.setBlock(i + 2, j + 1, k + 16, 0);
		world.setBlock(i + 2, j + 1, k + 17, 0);
		world.setBlock(i + 2, j + 1, k + 18, 0);
		world.setBlock(i + 2, j + 1, k + 19, 0);
		world.setBlock(i + 2, j + 1, k + 20, DivineRPG.iceikaStoneBricks.blockID);
		world.setBlock(i + 2, j + 2, k + 0, DivineRPG.iceikaStoneBricks.blockID);
		world.setBlock(i + 2, j + 2, k + 1, 0);
		world.setBlock(i + 2, j + 2, k + 2, 0);
		world.setBlock(i + 2, j + 2, k + 3, 0);
		world.setBlock(i + 2, j + 2, k + 4, 0);
		world.setBlock(i + 2, j + 2, k + 5, 0);
		world.setBlock(i + 2, j + 2, k + 6, 0);
		world.setBlock(i + 2, j + 2, k + 7, DivineRPG.iceikaStoneBricks.blockID);
		world.setBlock(i + 2, j + 2, k + 13, DivineRPG.iceikaStoneBricks.blockID);
		world.setBlock(i + 2, j + 2, k + 14, 0);
		world.setBlock(i + 2, j + 2, k + 15, 0);
		world.setBlock(i + 2, j + 2, k + 16, 0);
		world.setBlock(i + 2, j + 2, k + 17, 0);
		world.setBlock(i + 2, j + 2, k + 18, 0);
		world.setBlock(i + 2, j + 2, k + 19, 0);
		world.setBlock(i + 2, j + 2, k + 20, DivineRPG.iceikaStoneBricks.blockID);
		world.setBlock(i + 2, j + 3, k + 0, DivineRPG.iceikaStoneBricks.blockID);
		world.setBlock(i + 2, j + 3, k + 1, 0);
		world.setBlock(i + 2, j + 3, k + 2, 0);
		world.setBlock(i + 2, j + 3, k + 3, 0);
		world.setBlock(i + 2, j + 3, k + 4, 0);
		world.setBlock(i + 2, j + 3, k + 5, 0);
		world.setBlock(i + 2, j + 3, k + 6, 0);
		world.setBlock(i + 2, j + 3, k + 7, DivineRPG.iceikaStoneBricks.blockID);
		world.setBlock(i + 2, j + 3, k + 13, DivineRPG.iceikaStoneBricks.blockID);
		world.setBlock(i + 2, j + 3, k + 14, 0);
		world.setBlock(i + 2, j + 3, k + 15, 0);
		world.setBlock(i + 2, j + 3, k + 16, 0);
		world.setBlock(i + 2, j + 3, k + 17, 0);
		world.setBlock(i + 2, j + 3, k + 18, 0);
		world.setBlock(i + 2, j + 3, k + 19, 0);
		world.setBlock(i + 2, j + 3, k + 20, DivineRPG.iceikaStoneBricks.blockID);
		world.setBlock(i + 2, j + 4, k + 1, DivineRPG.iceikaStoneBricks.blockID);
		world.setBlock(i + 2, j + 4, k + 2, DivineRPG.iceikaStoneBricks.blockID);
		world.setBlock(i + 2, j + 4, k + 3, DivineRPG.iceikaStoneBricks.blockID);
		world.setBlock(i + 2, j + 4, k + 4, DivineRPG.iceikaStoneBricks.blockID);
		world.setBlock(i + 2, j + 4, k + 5, DivineRPG.iceikaStoneBricks.blockID);
		world.setBlock(i + 2, j + 4, k + 6, DivineRPG.iceikaStoneBricks.blockID);
		world.setBlock(i + 2, j + 4, k + 14, DivineRPG.iceikaStoneBricks.blockID);
		world.setBlock(i + 2, j + 4, k + 15, DivineRPG.iceikaStoneBricks.blockID);
		world.setBlock(i + 2, j + 4, k + 16, DivineRPG.iceikaStoneBricks.blockID);
		world.setBlock(i + 2, j + 4, k + 17, DivineRPG.iceikaStoneBricks.blockID);
		world.setBlock(i + 2, j + 4, k + 18, DivineRPG.iceikaStoneBricks.blockID);
		world.setBlock(i + 2, j + 4, k + 19, DivineRPG.iceikaStoneBricks.blockID);
		world.setBlock(i + 3, j + 0, k + 0, DivineRPG.iceikaStoneBricks.blockID);
		world.setBlock(i + 3, j + 0, k + 1, DivineRPG.iceikaMossyCobble.blockID);
		world.setBlock(i + 3, j + 0, k + 2, DivineRPG.iceikaMossyCobble.blockID);
		world.setBlock(i + 3, j + 0, k + 3, DivineRPG.iceikaMossyCobble.blockID);
		world.setBlock(i + 3, j + 0, k + 4, DivineRPG.iceikaMossyCobble.blockID);
		world.setBlock(i + 3, j + 0, k + 5, DivineRPG.iceikaMossyCobble.blockID);
		world.setBlock(i + 3, j + 0, k + 6, DivineRPG.iceikaMossyCobble.blockID);
		world.setBlock(i + 3, j + 0, k + 7, DivineRPG.iceikaStoneBricks.blockID);
		world.setBlock(i + 3, j + 0, k + 13, DivineRPG.iceikaStoneBricks.blockID);
		world.setBlock(i + 3, j + 0, k + 14, DivineRPG.iceikaMossyCobble.blockID);
		world.setBlock(i + 3, j + 0, k + 15, DivineRPG.iceikaMossyCobble.blockID);
		world.setBlock(i + 3, j + 0, k + 16, DivineRPG.iceikaMossyCobble.blockID);
		world.setBlock(i + 3, j + 0, k + 17, DivineRPG.iceikaMossyCobble.blockID);
		world.setBlock(i + 3, j + 0, k + 18, DivineRPG.iceikaMossyCobble.blockID);
		world.setBlock(i + 3, j + 0, k + 19, DivineRPG.iceikaMossyCobble.blockID);
		world.setBlock(i + 3, j + 0, k + 20, DivineRPG.iceikaStoneBricks.blockID);
		world.setBlock(i + 3, j + 0, k + 21, DivineRPG.iceikaStoneBricks.blockID);
		world.setBlock(i + 3, j + 0, k + 22, DivineRPG.iceikaStoneBricks.blockID);
		world.setBlock(i + 3, j + 0, k + 23, DivineRPG.iceikaStoneBricks.blockID);
		world.setBlock(i + 3, j + 0, k + 24, DivineRPG.iceikaStoneBricks.blockID);
		world.setBlock(i + 3, j + 0, k + 25, DivineRPG.iceikaStoneBricks.blockID);
		world.setBlock(i + 3, j + 1, k + 0, DivineRPG.iceikaStoneBricks.blockID);
		world.setBlock(i + 3, j + 1, k + 1, 0);
		world.setBlock(i + 3, j + 1, k + 2, 0);
		world.setBlock(i + 3, j + 1, k + 3, 0);
		world.setBlock(i + 3, j + 1, k + 4, 0);
		world.setBlock(i + 3, j + 1, k + 5, 0);
		world.setBlock(i + 3, j + 1, k + 6, 0);
		world.setBlock(i + 3, j + 1, k + 7, DivineRPG.iceikaStoneBricks.blockID);
		world.setBlock(i + 3, j + 1, k + 13, DivineRPG.iceikaStoneBricks.blockID);
		world.setBlock(i + 3, j + 1, k + 14, 0);
		world.setBlock(i + 3, j + 1, k + 15, 0);
		world.setBlock(i + 3, j + 1, k + 16, 0);
		world.setBlock(i + 3, j + 1, k + 17, 0);
		world.setBlock(i + 3, j + 1, k + 18, 0);
		world.setBlock(i + 3, j + 1, k + 19, 0);
		world.setBlock(i + 3, j + 1, k + 20, DivineRPG.iceikaStoneBricks.blockID);
		world.setBlock(i + 3, j + 1, k + 21, DivineRPG.iceikaStoneBricks.blockID);
		world.setBlock(i + 3, j + 1, k + 22, DivineRPG.iceikaStoneBricks.blockID);
		world.setBlock(i + 3, j + 1, k + 23, DivineRPG.iceikaStoneBricks.blockID);
		world.setBlock(i + 3, j + 1, k + 24, DivineRPG.iceikaStoneBricks.blockID);
		world.setBlock(i + 3, j + 1, k + 25, DivineRPG.iceikaStoneBricks.blockID);
		world.setBlock(i + 3, j + 2, k + 0, DivineRPG.iceikaStoneBricks.blockID);
		world.setBlock(i + 3, j + 2, k + 1, 0);
		world.setBlock(i + 3, j + 2, k + 2, 0);
		world.setBlock(i + 3, j + 2, k + 3, 0);
		world.setBlock(i + 3, j + 2, k + 4, 0);
		world.setBlock(i + 3, j + 2, k + 5, 0);
		world.setBlock(i + 3, j + 2, k + 6, 0);
		world.setBlock(i + 3, j + 2, k + 7, DivineRPG.iceikaStoneBricks.blockID);
		world.setBlock(i + 3, j + 2, k + 13, DivineRPG.iceikaStoneBricks.blockID);
		world.setBlock(i + 3, j + 2, k + 14, 0);
		world.setBlock(i + 3, j + 2, k + 15, 0);
		world.setBlock(i + 3, j + 2, k + 16, 0);
		world.setBlock(i + 3, j + 2, k + 17, 0);
		world.setBlock(i + 3, j + 2, k + 18, 0);
		world.setBlock(i + 3, j + 2, k + 19, 0);
		world.setBlock(i + 3, j + 2, k + 20, DivineRPG.iceikaStoneBricks.blockID);
		world.setBlock(i + 3, j + 2, k + 21, DivineRPG.iceikaStoneBricks.blockID);
		world.setBlock(i + 3, j + 2, k + 22, DivineRPG.iceikaStoneBricks.blockID);
		world.setBlock(i + 3, j + 2, k + 23, DivineRPG.iceikaStoneBricks.blockID);
		world.setBlock(i + 3, j + 2, k + 24, DivineRPG.iceikaStoneBricks.blockID);
		world.setBlock(i + 3, j + 2, k + 25, DivineRPG.iceikaStoneBricks.blockID);
		world.setBlock(i + 3, j + 3, k + 0, DivineRPG.iceikaStoneBricks.blockID);
		world.setBlock(i + 3, j + 3, k + 1, 0);
		world.setBlock(i + 3, j + 3, k + 2, 0);
		world.setBlock(i + 3, j + 3, k + 3, 0);
		world.setBlock(i + 3, j + 3, k + 4, 0);
		world.setBlock(i + 3, j + 3, k + 5, 0);
		world.setBlock(i + 3, j + 3, k + 6, 0);
		world.setBlock(i + 3, j + 3, k + 7, DivineRPG.iceikaStoneBricks.blockID);
		world.setBlock(i + 3, j + 3, k + 13, DivineRPG.iceikaStoneBricks.blockID);
		world.setBlock(i + 3, j + 3, k + 14, 0);
		world.setBlock(i + 3, j + 3, k + 15, 0);
		world.setBlock(i + 3, j + 3, k + 16, 0);
		world.setBlock(i + 3, j + 3, k + 17, 0);
		world.setBlock(i + 3, j + 3, k + 18, 0);
		world.setBlock(i + 3, j + 3, k + 19, 0);
		world.setBlock(i + 3, j + 3, k + 20, DivineRPG.iceikaStoneBricks.blockID);
		world.setBlock(i + 3, j + 3, k + 21, DivineRPG.iceikaStoneBricks.blockID);
		world.setBlock(i + 3, j + 3, k + 22, DivineRPG.iceikaStoneBricks.blockID);
		world.setBlock(i + 3, j + 3, k + 23, DivineRPG.iceikaStoneBricks.blockID);
		world.setBlock(i + 3, j + 3, k + 24, DivineRPG.iceikaStoneBricks.blockID);
		world.setBlock(i + 3, j + 3, k + 25, DivineRPG.iceikaStoneBricks.blockID);
		world.setBlock(i + 3, j + 4, k + 1, DivineRPG.iceikaStoneBricks.blockID);
		world.setBlock(i + 3, j + 4, k + 2, DivineRPG.iceikaStoneBricks.blockID);
		world.setBlock(i + 3, j + 4, k + 3, DivineRPG.iceikaStoneBricks.blockID);
		world.setBlock(i + 3, j + 4, k + 4, DivineRPG.iceikaStoneBricks.blockID);
		world.setBlock(i + 3, j + 4, k + 5, DivineRPG.iceikaStoneBricks.blockID);
		world.setBlock(i + 3, j + 4, k + 6, DivineRPG.iceikaStoneBricks.blockID);
		world.setBlock(i + 3, j + 4, k + 14, DivineRPG.iceikaStoneBricks.blockID);
		world.setBlock(i + 3, j + 4, k + 15, DivineRPG.iceikaStoneBricks.blockID);
		world.setBlock(i + 3, j + 4, k + 16, DivineRPG.iceikaStoneBricks.blockID);
		world.setBlock(i + 3, j + 4, k + 17, DivineRPG.iceikaStoneBricks.blockID);
		world.setBlock(i + 3, j + 4, k + 18, DivineRPG.iceikaStoneBricks.blockID);
		world.setBlock(i + 3, j + 4, k + 19, DivineRPG.iceikaStoneBricks.blockID);
		world.setBlock(i + 4, j + 0, k + 0, DivineRPG.iceikaStoneBricks.blockID);
		world.setBlock(i + 4, j + 0, k + 1, DivineRPG.iceikaMossyCobble.blockID);
		world.setBlock(i + 4, j + 0, k + 2, DivineRPG.iceikaMossyCobble.blockID);
		world.setBlock(i + 4, j + 0, k + 3, DivineRPG.iceikaMossyCobble.blockID);
		world.setBlock(i + 4, j + 0, k + 4, DivineRPG.iceikaMossyCobble.blockID);
		world.setBlock(i + 4, j + 0, k + 5, DivineRPG.iceikaMossyCobble.blockID);
		world.setBlock(i + 4, j + 0, k + 6, DivineRPG.iceikaMossyCobble.blockID);
		world.setBlock(i + 4, j + 0, k + 7, DivineRPG.iceikaStoneBricks.blockID);
		world.setBlock(i + 4, j + 0, k + 13, DivineRPG.iceikaStoneBricks.blockID);
		world.setBlock(i + 4, j + 0, k + 14, DivineRPG.iceikaMossyCobble.blockID);
		world.setBlock(i + 4, j + 0, k + 15, DivineRPG.iceikaMossyCobble.blockID);
		world.setBlock(i + 4, j + 0, k + 16, DivineRPG.iceikaMossyCobble.blockID);
		world.setBlock(i + 4, j + 0, k + 17, DivineRPG.iceikaMossyCobble.blockID);
		world.setBlock(i + 4, j + 0, k + 18, DivineRPG.iceikaMossyCobble.blockID);
		world.setBlock(i + 4, j + 0, k + 19, DivineRPG.iceikaMossyCobble.blockID);
		world.setBlock(i + 4, j + 0, k + 20, DivineRPG.iceikaMossyCobble.blockID);
		world.setBlock(i + 4, j + 0, k + 21, DivineRPG.iceikaMossyCobble.blockID);
		world.setBlock(i + 4, j + 0, k + 22, DivineRPG.iceikaMossyCobble.blockID);
		world.setBlock(i + 4, j + 0, k + 23, DivineRPG.iceikaMossyCobble.blockID);
		world.setBlock(i + 4, j + 0, k + 24, DivineRPG.iceikaMossyCobble.blockID);
		world.setBlock(i + 4, j + 0, k + 25, DivineRPG.iceikaMossyCobble.blockID);
		world.setBlock(i + 4, j + 1, k + 0, DivineRPG.iceikaStoneBricks.blockID);
		world.setBlock(i + 4, j + 1, k + 1, 0);
		world.setBlock(i + 4, j + 1, k + 2, DivineRPG.iceikaSpawnerCage2.blockID);
		world.setBlock(i + 4, j + 1, k + 3, 0);
		world.setBlock(i + 4, j + 1, k + 4, 0);
		world.setBlock(i + 4, j + 1, k + 5, DivineRPG.iceikaSpawnerCage2.blockID);
		world.setBlock(i + 4, j + 1, k + 6, 0);
		world.setBlock(i + 4, j + 1, k + 7, DivineRPG.iceikaStoneBricks.blockID);
		world.setBlock(i + 4, j + 1, k + 13, DivineRPG.iceikaStoneBricks.blockID);
		world.setBlock(i + 4, j + 1, k + 14, 0);
		world.setBlock(i + 4, j + 1, k + 15, 0);
		world.setBlock(i + 4, j + 1, k + 16, DivineRPG.iceikaSpawnerCage2.blockID);
		world.setBlock(i + 4, j + 1, k + 17, 0);
		world.setBlock(i + 4, j + 1, k + 18, 0);
		world.setBlock(i + 4, j + 1, k + 19, 0);
		world.setBlock(i + 4, j + 1, k + 20, 0);
		world.setBlock(i + 4, j + 1, k + 21, 0);
		world.setBlock(i + 4, j + 1, k + 22, 0);
		world.setBlock(i + 4, j + 1, k + 23, 0);
		world.setBlock(i + 4, j + 1, k + 24, 0);
		world.setBlock(i + 4, j + 2, k + 0, DivineRPG.iceikaStoneBricks.blockID);
		world.setBlock(i + 4, j + 2, k + 1, 0);
		world.setBlock(i + 4, j + 2, k + 2, 0);
		world.setBlock(i + 4, j + 2, k + 3, 0);
		world.setBlock(i + 4, j + 2, k + 4, 0);
		world.setBlock(i + 4, j + 2, k + 5, 0);
		world.setBlock(i + 4, j + 2, k + 6, 0);
		world.setBlock(i + 4, j + 2, k + 7, DivineRPG.iceikaStoneBricks.blockID);
		world.setBlock(i + 4, j + 2, k + 13, DivineRPG.iceikaStoneBricks.blockID);
		world.setBlock(i + 4, j + 2, k + 14, 0);
		world.setBlock(i + 4, j + 2, k + 15, 0);
		world.setBlock(i + 4, j + 2, k + 16, 0);
		world.setBlock(i + 4, j + 2, k + 17, 0);
		world.setBlock(i + 4, j + 2, k + 18, 0);
		world.setBlock(i + 4, j + 2, k + 19, 0);
		world.setBlock(i + 4, j + 2, k + 20, 0);
		world.setBlock(i + 4, j + 2, k + 21, 0);
		world.setBlock(i + 4, j + 2, k + 22, 0);
		world.setBlock(i + 4, j + 2, k + 23, 0);
		world.setBlock(i + 4, j + 2, k + 24, 0);
		world.setBlock(i + 4, j + 3, k + 0, DivineRPG.iceikaStoneBricks.blockID);
		world.setBlock(i + 4, j + 3, k + 1, 0);
		world.setBlock(i + 4, j + 3, k + 2, 0);
		world.setBlock(i + 4, j + 3, k + 3, 0);
		world.setBlock(i + 4, j + 3, k + 4, 0);
		world.setBlock(i + 4, j + 3, k + 5, 0);
		world.setBlock(i + 4, j + 3, k + 6, 0);
		world.setBlock(i + 4, j + 3, k + 7, DivineRPG.iceikaStoneBricks.blockID);
		world.setBlock(i + 4, j + 3, k + 13, DivineRPG.iceikaStoneBricks.blockID);
		world.setBlock(i + 4, j + 3, k + 14, 0);
		world.setBlock(i + 4, j + 3, k + 15, 0);
		world.setBlock(i + 4, j + 3, k + 16, 0);
		world.setBlock(i + 4, j + 3, k + 17, 0);
		world.setBlock(i + 4, j + 3, k + 18, 0);
		world.setBlock(i + 4, j + 3, k + 19, 0);
		world.setBlock(i + 4, j + 3, k + 20, 0);
		world.setBlock(i + 4, j + 3, k + 21, 0);
		world.setBlock(i + 4, j + 3, k + 22, 0);
		world.setBlock(i + 4, j + 3, k + 23, 0);
		world.setBlock(i + 4, j + 3, k + 24, 0);
		world.setBlock(i + 4, j + 4, k + 1, DivineRPG.iceikaStoneBricks.blockID);
		world.setBlock(i + 4, j + 4, k + 2, DivineRPG.iceikaStoneBricks.blockID);
		world.setBlock(i + 4, j + 4, k + 3, DivineRPG.iceikaStoneBricks.blockID);
		world.setBlock(i + 4, j + 4, k + 4, DivineRPG.iceikaStoneBricks.blockID);
		world.setBlock(i + 4, j + 4, k + 5, DivineRPG.iceikaStoneBricks.blockID);
		world.setBlock(i + 4, j + 4, k + 6, DivineRPG.iceikaStoneBricks.blockID);
		world.setBlock(i + 4, j + 4, k + 14, DivineRPG.iceikaStoneBricks.blockID);
		world.setBlock(i + 4, j + 4, k + 15, DivineRPG.iceikaStoneBricks.blockID);
		world.setBlock(i + 4, j + 4, k + 16, DivineRPG.iceikaStoneBricks.blockID);
		world.setBlock(i + 4, j + 4, k + 17, DivineRPG.iceikaStoneBricks.blockID);
		world.setBlock(i + 4, j + 4, k + 18, DivineRPG.iceikaStoneBricks.blockID);
		world.setBlock(i + 4, j + 4, k + 19, DivineRPG.iceikaStoneBricks.blockID);
		world.setBlock(i + 4, j + 4, k + 20, DivineRPG.iceikaStoneBricks.blockID);
		world.setBlock(i + 4, j + 4, k + 21, DivineRPG.iceikaStoneBricks.blockID);
		world.setBlock(i + 4, j + 4, k + 22, DivineRPG.iceikaStoneBricks.blockID);
		world.setBlock(i + 4, j + 4, k + 23, DivineRPG.iceikaStoneBricks.blockID);
		world.setBlock(i + 4, j + 4, k + 24, DivineRPG.iceikaStoneBricks.blockID);
		world.setBlock(i + 4, j + 4, k + 25, DivineRPG.iceikaStoneBricks.blockID);
		world.setBlock(i + 5, j + 0, k + 0, DivineRPG.iceikaStoneBricks.blockID);
		world.setBlock(i + 5, j + 0, k + 1, DivineRPG.iceikaMossyCobble.blockID);
		world.setBlock(i + 5, j + 0, k + 2, DivineRPG.iceikaMossyCobble.blockID);
		world.setBlock(i + 5, j + 0, k + 3, DivineRPG.iceikaMossyCobble.blockID);
		world.setBlock(i + 5, j + 0, k + 4, DivineRPG.iceikaMossyCobble.blockID);
		world.setBlock(i + 5, j + 0, k + 5, DivineRPG.iceikaMossyCobble.blockID);
		world.setBlock(i + 5, j + 0, k + 6, DivineRPG.iceikaMossyCobble.blockID);
		world.setBlock(i + 5, j + 0, k + 7, DivineRPG.iceikaStoneBricks.blockID);
		world.setBlock(i + 5, j + 0, k + 9, DivineRPG.iceikaStoneBricks.blockID);
		world.setBlock(i + 5, j + 0, k + 10, DivineRPG.iceikaStoneBricks.blockID);
		world.setBlock(i + 5, j + 0, k + 11, DivineRPG.iceikaStoneBricks.blockID);
		world.setBlock(i + 5, j + 0, k + 12, DivineRPG.iceikaStoneBricks.blockID);
		world.setBlock(i + 5, j + 0, k + 13, DivineRPG.iceikaStoneBricks.blockID);
		world.setBlock(i + 5, j + 0, k + 14, DivineRPG.iceikaMossyCobble.blockID);
		world.setBlock(i + 5, j + 0, k + 15, DivineRPG.iceikaMossyCobble.blockID);
		world.setBlock(i + 5, j + 0, k + 16, DivineRPG.iceikaMossyCobble.blockID);
		world.setBlock(i + 5, j + 0, k + 17, DivineRPG.iceikaMossyCobble.blockID);
		world.setBlock(i + 5, j + 0, k + 18, DivineRPG.iceikaMossyCobble.blockID);
		world.setBlock(i + 5, j + 0, k + 19, DivineRPG.iceikaMossyCobble.blockID);
		world.setBlock(i + 5, j + 0, k + 20, DivineRPG.iceikaMossyCobble.blockID);
		world.setBlock(i + 5, j + 0, k + 21, DivineRPG.iceikaMossyCobble.blockID);
		world.setBlock(i + 5, j + 0, k + 22, DivineRPG.iceikaMossyCobble.blockID);
		world.setBlock(i + 5, j + 0, k + 23, DivineRPG.iceikaMossyCobble.blockID);
		world.setBlock(i + 5, j + 0, k + 24, DivineRPG.iceikaMossyCobble.blockID);
		world.setBlock(i + 5, j + 0, k + 25, DivineRPG.iceikaMossyCobble.blockID);
		world.setBlock(i + 5, j + 1, k + 0, DivineRPG.iceikaStoneBricks.blockID);
		world.setBlock(i + 5, j + 1, k + 1, 0);
		world.setBlock(i + 5, j + 1, k + 2, 0);
		world.setBlock(i + 5, j + 1, k + 3, 0);
		world.setBlock(i + 5, j + 1, k + 4, 0);
		world.setBlock(i + 5, j + 1, k + 5, 0);
		world.setBlock(i + 5, j + 1, k + 6, 0);
		world.setBlock(i + 5, j + 1, k + 7, DivineRPG.iceikaStoneBricks.blockID);
		world.setBlock(i + 5, j + 1, k + 9, DivineRPG.iceikaStoneBricks.blockID);
		world.setBlock(i + 5, j + 1, k + 10, DivineRPG.iceikaStoneBricks.blockID);
		world.setBlock(i + 5, j + 1, k + 11, DivineRPG.iceikaStoneBricks.blockID);
		world.setBlock(i + 5, j + 1, k + 12, DivineRPG.iceikaStoneBricks.blockID);
		world.setBlock(i + 5, j + 1, k + 13, DivineRPG.iceikaStoneBricks.blockID);
		world.setBlock(i + 5, j + 1, k + 14, 0);
		world.setBlock(i + 5, j + 1, k + 15, 0);
		world.setBlock(i + 5, j + 1, k + 16, 0);
		world.setBlock(i + 5, j + 1, k + 17, 0);
		world.setBlock(i + 5, j + 1, k + 18, 0);
		world.setBlock(i + 5, j + 1, k + 19, 0);
		world.setBlock(i + 5, j + 1, k + 20, 0);
		world.setBlock(i + 5, j + 1, k + 21, 0);
		world.setBlock(i + 5, j + 1, k + 22, 0);
		world.setBlock(i + 5, j + 1, k + 23, 0);
		world.setBlock(i + 5, j + 1, k + 24, 0);
		world.setBlock(i + 5, j + 2, k + 0, DivineRPG.iceikaStoneBricks.blockID);
		world.setBlock(i + 5, j + 2, k + 1, 0);
		world.setBlock(i + 5, j + 2, k + 2, 0);
		world.setBlock(i + 5, j + 2, k + 3, 0);
		world.setBlock(i + 5, j + 2, k + 4, 0);
		world.setBlock(i + 5, j + 2, k + 5, 0);
		world.setBlock(i + 5, j + 2, k + 6, 0);
		world.setBlock(i + 5, j + 2, k + 7, DivineRPG.iceikaStoneBricks.blockID);
		world.setBlock(i + 5, j + 2, k + 9, DivineRPG.iceikaStoneBricks.blockID);
		world.setBlock(i + 5, j + 2, k + 10, DivineRPG.iceikaStoneBricks.blockID);
		world.setBlock(i + 5, j + 2, k + 11, DivineRPG.iceikaStoneBricks.blockID);
		world.setBlock(i + 5, j + 2, k + 12, DivineRPG.iceikaStoneBricks.blockID);
		world.setBlock(i + 5, j + 2, k + 13, DivineRPG.iceikaStoneBricks.blockID);
		world.setBlock(i + 5, j + 2, k + 14, 0);
		world.setBlock(i + 5, j + 2, k + 15, 0);
		world.setBlock(i + 5, j + 2, k + 16, 0);
		world.setBlock(i + 5, j + 2, k + 17, 0);
		world.setBlock(i + 5, j + 2, k + 18, 0);
		world.setBlock(i + 5, j + 2, k + 19, 0);
		world.setBlock(i + 5, j + 2, k + 20, 0);
		world.setBlock(i + 5, j + 2, k + 21, 0);
		world.setBlock(i + 5, j + 2, k + 22, 0);
		world.setBlock(i + 5, j + 2, k + 23, 0);
		world.setBlock(i + 5, j + 2, k + 24, 0);
		world.setBlock(i + 5, j + 3, k + 0, DivineRPG.iceikaStoneBricks.blockID);
		world.setBlock(i + 5, j + 3, k + 1, 0);
		world.setBlock(i + 5, j + 3, k + 2, 0);
		world.setBlock(i + 5, j + 3, k + 3, 0);
		world.setBlock(i + 5, j + 3, k + 4, 0);
		world.setBlock(i + 5, j + 3, k + 5, 0);
		world.setBlock(i + 5, j + 3, k + 6, 0);
		world.setBlock(i + 5, j + 3, k + 7, DivineRPG.iceikaStoneBricks.blockID);
		world.setBlock(i + 5, j + 3, k + 9, DivineRPG.iceikaStoneBricks.blockID);
		world.setBlock(i + 5, j + 3, k + 10, DivineRPG.iceikaStoneBricks.blockID);
		world.setBlock(i + 5, j + 3, k + 11, DivineRPG.iceikaStoneBricks.blockID);
		world.setBlock(i + 5, j + 3, k + 12, DivineRPG.iceikaStoneBricks.blockID);
		world.setBlock(i + 5, j + 3, k + 13, DivineRPG.iceikaStoneBricks.blockID);
		world.setBlock(i + 5, j + 3, k + 14, 0);
		world.setBlock(i + 5, j + 3, k + 15, 0);
		world.setBlock(i + 5, j + 3, k + 16, 0);
		world.setBlock(i + 5, j + 3, k + 17, 0);
		world.setBlock(i + 5, j + 3, k + 18, 0);
		world.setBlock(i + 5, j + 3, k + 19, 0);
		world.setBlock(i + 5, j + 3, k + 20, 0);
		world.setBlock(i + 5, j + 3, k + 21, 0);
		world.setBlock(i + 5, j + 3, k + 22, 0);
		world.setBlock(i + 5, j + 3, k + 23, 0);
		world.setBlock(i + 5, j + 3, k + 24, 0);
		world.setBlock(i + 5, j + 4, k + 1, DivineRPG.iceikaStoneBricks.blockID);
		world.setBlock(i + 5, j + 4, k + 2, DivineRPG.iceikaStoneBricks.blockID);
		world.setBlock(i + 5, j + 4, k + 3, DivineRPG.iceikaStoneBricks.blockID);
		world.setBlock(i + 5, j + 4, k + 4, DivineRPG.iceikaStoneBricks.blockID);
		world.setBlock(i + 5, j + 4, k + 5, DivineRPG.iceikaStoneBricks.blockID);
		world.setBlock(i + 5, j + 4, k + 6, DivineRPG.iceikaStoneBricks.blockID);
		world.setBlock(i + 5, j + 4, k + 14, DivineRPG.iceikaStoneBricks.blockID);
		world.setBlock(i + 5, j + 4, k + 15, DivineRPG.iceikaStoneBricks.blockID);
		world.setBlock(i + 5, j + 4, k + 16, DivineRPG.iceikaStoneBricks.blockID);
		world.setBlock(i + 5, j + 4, k + 17, DivineRPG.iceikaStoneBricks.blockID);
		world.setBlock(i + 5, j + 4, k + 18, DivineRPG.iceikaStoneBricks.blockID);
		world.setBlock(i + 5, j + 4, k + 19, DivineRPG.iceikaStoneBricks.blockID);
		world.setBlock(i + 5, j + 4, k + 20, DivineRPG.iceikaStoneBricks.blockID);
		world.setBlock(i + 5, j + 4, k + 21, DivineRPG.iceikaStoneBricks.blockID);
		world.setBlock(i + 5, j + 4, k + 22, DivineRPG.iceikaStoneBricks.blockID);
		world.setBlock(i + 5, j + 4, k + 23, DivineRPG.iceikaStoneBricks.blockID);
		world.setBlock(i + 5, j + 4, k + 24, DivineRPG.iceikaStoneBricks.blockID);
		world.setBlock(i + 5, j + 4, k + 25, DivineRPG.iceikaStoneBricks.blockID);
		world.setBlock(i + 6, j + 0, k + 0, DivineRPG.iceikaStoneBricks.blockID);
		world.setBlock(i + 6, j + 0, k + 1, DivineRPG.iceikaMossyCobble.blockID);
		world.setBlock(i + 6, j + 0, k + 2, DivineRPG.iceikaMossyCobble.blockID);
		world.setBlock(i + 6, j + 0, k + 3, DivineRPG.iceikaMossyCobble.blockID);
		world.setBlock(i + 6, j + 0, k + 4, DivineRPG.iceikaMossyCobble.blockID);
		world.setBlock(i + 6, j + 0, k + 5, DivineRPG.iceikaMossyCobble.blockID);
		world.setBlock(i + 6, j + 0, k + 6, DivineRPG.iceikaMossyCobble.blockID);
		world.setBlock(i + 6, j + 0, k + 7, DivineRPG.iceikaStoneBricks.blockID);
		world.setBlock(i + 6, j + 0, k + 9, DivineRPG.iceikaStoneBricks.blockID);
		world.setBlock(i + 6, j + 0, k + 10, DivineRPG.iceikaMossyCobble.blockID);
		world.setBlock(i + 6, j + 0, k + 11, DivineRPG.iceikaMossyCobble.blockID);
		world.setBlock(i + 6, j + 0, k + 12, DivineRPG.iceikaMossyCobble.blockID);
		world.setBlock(i + 6, j + 0, k + 13, DivineRPG.iceikaMossyCobble.blockID);
		world.setBlock(i + 6, j + 0, k + 14, DivineRPG.iceikaMossyCobble.blockID);
		world.setBlock(i + 6, j + 0, k + 15, DivineRPG.iceikaMossyCobble.blockID);
		world.setBlock(i + 6, j + 0, k + 16, DivineRPG.iceikaMossyCobble.blockID);
		world.setBlock(i + 6, j + 0, k + 17, DivineRPG.iceikaMossyCobble.blockID);
		world.setBlock(i + 6, j + 0, k + 18, DivineRPG.iceikaMossyCobble.blockID);
		world.setBlock(i + 6, j + 0, k + 19, DivineRPG.iceikaMossyCobble.blockID);
		world.setBlock(i + 6, j + 0, k + 20, DivineRPG.iceikaStoneBricks.blockID);
		world.setBlock(i + 6, j + 0, k + 21, DivineRPG.iceikaStoneBricks.blockID);
		world.setBlock(i + 6, j + 0, k + 22, DivineRPG.iceikaStoneBricks.blockID);
		world.setBlock(i + 6, j + 0, k + 23, DivineRPG.iceikaStoneBricks.blockID);
		world.setBlock(i + 6, j + 0, k + 24, DivineRPG.iceikaStoneBricks.blockID);
		world.setBlock(i + 6, j + 0, k + 25, DivineRPG.iceikaStoneBricks.blockID);
		world.setBlock(i + 6, j + 1, k + 0, DivineRPG.iceikaStoneBricks.blockID);
		world.setBlock(i + 6, j + 1, k + 1, 0);
		world.setBlock(i + 6, j + 1, k + 2, 0);
		world.setBlock(i + 6, j + 1, k + 3, 0);
		world.setBlock(i + 6, j + 1, k + 4, 0);
		world.setBlock(i + 6, j + 1, k + 5, 0);
		world.setBlock(i + 6, j + 1, k + 6, 0);
		world.setBlock(i + 6, j + 1, k + 7, DivineRPG.iceikaStoneBricks.blockID);
		world.setBlock(i + 6, j + 1, k + 9, DivineRPG.iceikaStoneBricks.blockID);
		world.setBlock(i + 6, j + 1, k + 10, 0);
		world.setBlock(i + 6, j + 1, k + 11, 0);
		world.setBlock(i + 6, j + 1, k + 12, 0);
		world.setBlock(i + 6, j + 1, k + 13, 0);
		world.setBlock(i + 6, j + 1, k + 14, 0);
		world.setBlock(i + 6, j + 1, k + 15, 0);
		world.setBlock(i + 6, j + 1, k + 16, 0);
		world.setBlock(i + 6, j + 1, k + 17, 0);
		world.setBlock(i + 6, j + 1, k + 18, 0);
		world.setBlock(i + 6, j + 1, k + 19, 0);
		world.setBlock(i + 6, j + 1, k + 20, DivineRPG.iceikaStoneBricks.blockID);
		world.setBlock(i + 6, j + 1, k + 21, DivineRPG.iceikaStoneBricks.blockID);
		world.setBlock(i + 6, j + 1, k + 22, DivineRPG.iceikaStoneBricks.blockID);
		world.setBlock(i + 6, j + 1, k + 23, DivineRPG.iceikaStoneBricks.blockID);
		world.setBlock(i + 6, j + 1, k + 24, DivineRPG.iceikaStoneBricks.blockID);
		world.setBlock(i + 6, j + 1, k + 25, DivineRPG.iceikaStoneBricks.blockID);
		world.setBlock(i + 6, j + 2, k + 0, DivineRPG.iceikaStoneBricks.blockID);
		world.setBlock(i + 6, j + 2, k + 1, 0);
		world.setBlock(i + 6, j + 2, k + 2, 0);
		world.setBlock(i + 6, j + 2, k + 3, 0);
		world.setBlock(i + 6, j + 2, k + 4, 0);
		world.setBlock(i + 6, j + 2, k + 5, 0);
		world.setBlock(i + 6, j + 2, k + 6, 0);
		world.setBlock(i + 6, j + 2, k + 7, DivineRPG.iceikaStoneBricks.blockID);
		world.setBlock(i + 6, j + 2, k + 9, DivineRPG.iceikaStoneBricks.blockID);
		world.setBlock(i + 6, j + 2, k + 10, 0);
		world.setBlock(i + 6, j + 2, k + 11, 0);
		world.setBlock(i + 6, j + 2, k + 12, 0);
		world.setBlock(i + 6, j + 2, k + 13, 0);
		world.setBlock(i + 6, j + 2, k + 14, 0);
		world.setBlock(i + 6, j + 2, k + 15, 0);
		world.setBlock(i + 6, j + 2, k + 16, 0);
		world.setBlock(i + 6, j + 2, k + 17, 0);
		world.setBlock(i + 6, j + 2, k + 18, 0);
		world.setBlock(i + 6, j + 2, k + 19, 0);
		world.setBlock(i + 6, j + 2, k + 20, DivineRPG.iceikaStoneBricks.blockID);
		world.setBlock(i + 6, j + 2, k + 21, DivineRPG.iceikaStoneBricks.blockID);
		world.setBlock(i + 6, j + 2, k + 22, DivineRPG.iceikaStoneBricks.blockID);
		world.setBlock(i + 6, j + 2, k + 23, DivineRPG.iceikaStoneBricks.blockID);
		world.setBlock(i + 6, j + 2, k + 24, DivineRPG.iceikaStoneBricks.blockID);
		world.setBlock(i + 6, j + 2, k + 25, DivineRPG.iceikaStoneBricks.blockID);
		world.setBlock(i + 6, j + 3, k + 0, DivineRPG.iceikaStoneBricks.blockID);
		world.setBlock(i + 6, j + 3, k + 1, 0);
		world.setBlock(i + 6, j + 3, k + 2, 0);
		world.setBlock(i + 6, j + 3, k + 3, 0);
		world.setBlock(i + 6, j + 3, k + 4, 0);
		world.setBlock(i + 6, j + 3, k + 5, 0);
		world.setBlock(i + 6, j + 3, k + 6, 0);
		world.setBlock(i + 6, j + 3, k + 7, DivineRPG.iceikaStoneBricks.blockID);
		world.setBlock(i + 6, j + 3, k + 9, DivineRPG.iceikaStoneBricks.blockID);
		world.setBlock(i + 6, j + 3, k + 10, 0);
		world.setBlock(i + 6, j + 3, k + 11, 0);
		world.setBlock(i + 6, j + 3, k + 12, 0);
		world.setBlock(i + 6, j + 3, k + 13, 0);
		world.setBlock(i + 6, j + 3, k + 14, 0);
		world.setBlock(i + 6, j + 3, k + 15, 0);
		world.setBlock(i + 6, j + 3, k + 16, 0);
		world.setBlock(i + 6, j + 3, k + 17, 0);
		world.setBlock(i + 6, j + 3, k + 18, 0);
		world.setBlock(i + 6, j + 3, k + 19, 0);
		world.setBlock(i + 6, j + 3, k + 20, DivineRPG.iceikaStoneBricks.blockID);
		world.setBlock(i + 6, j + 3, k + 21, DivineRPG.iceikaStoneBricks.blockID);
		world.setBlock(i + 6, j + 3, k + 22, DivineRPG.iceikaStoneBricks.blockID);
		world.setBlock(i + 6, j + 3, k + 23, DivineRPG.iceikaStoneBricks.blockID);
		world.setBlock(i + 6, j + 3, k + 24, DivineRPG.iceikaStoneBricks.blockID);
		world.setBlock(i + 6, j + 3, k + 25, DivineRPG.iceikaStoneBricks.blockID);
		world.setBlock(i + 6, j + 4, k + 1, DivineRPG.iceikaStoneBricks.blockID);
		world.setBlock(i + 6, j + 4, k + 2, DivineRPG.iceikaStoneBricks.blockID);
		world.setBlock(i + 6, j + 4, k + 3, DivineRPG.iceikaStoneBricks.blockID);
		world.setBlock(i + 6, j + 4, k + 4, DivineRPG.iceikaStoneBricks.blockID);
		world.setBlock(i + 6, j + 4, k + 5, DivineRPG.iceikaStoneBricks.blockID);
		world.setBlock(i + 6, j + 4, k + 6, DivineRPG.iceikaStoneBricks.blockID);
		world.setBlock(i + 6, j + 4, k + 10, DivineRPG.iceikaStoneBricks.blockID);
		world.setBlock(i + 6, j + 4, k + 11, DivineRPG.iceikaStoneBricks.blockID);
		world.setBlock(i + 6, j + 4, k + 12, DivineRPG.iceikaStoneBricks.blockID);
		world.setBlock(i + 6, j + 4, k + 13, DivineRPG.iceikaStoneBricks.blockID);
		world.setBlock(i + 6, j + 4, k + 14, DivineRPG.iceikaStoneBricks.blockID);
		world.setBlock(i + 6, j + 4, k + 15, DivineRPG.iceikaStoneBricks.blockID);
		world.setBlock(i + 6, j + 4, k + 16, DivineRPG.iceikaStoneBricks.blockID);
		world.setBlock(i + 6, j + 4, k + 17, DivineRPG.iceikaStoneBricks.blockID);
		world.setBlock(i + 6, j + 4, k + 18, DivineRPG.iceikaStoneBricks.blockID);
		world.setBlock(i + 6, j + 4, k + 19, DivineRPG.iceikaStoneBricks.blockID);
		world.setBlock(i + 7, j + 0, k + 0, DivineRPG.iceikaStoneBricks.blockID);
		world.setBlock(i + 7, j + 0, k + 1, DivineRPG.iceikaStoneBricks.blockID);
		world.setBlock(i + 7, j + 0, k + 2, DivineRPG.iceikaStoneBricks.blockID);
		world.setBlock(i + 7, j + 0, k + 3, DivineRPG.iceikaMossyCobble.blockID);
		world.setBlock(i + 7, j + 0, k + 4, DivineRPG.iceikaMossyCobble.blockID);
		world.setBlock(i + 7, j + 0, k + 5, DivineRPG.iceikaStoneBricks.blockID);
		world.setBlock(i + 7, j + 0, k + 6, DivineRPG.iceikaStoneBricks.blockID);
		world.setBlock(i + 7, j + 0, k + 7, DivineRPG.iceikaStoneBricks.blockID);
		world.setBlock(i + 7, j + 0, k + 9, DivineRPG.iceikaStoneBricks.blockID);
		world.setBlock(i + 7, j + 0, k + 10, DivineRPG.iceikaMossyCobble.blockID);
		world.setBlock(i + 7, j + 0, k + 11, DivineRPG.iceikaMossyCobble.blockID);
		world.setBlock(i + 7, j + 0, k + 12, DivineRPG.iceikaMossyCobble.blockID);
		world.setBlock(i + 7, j + 0, k + 13, DivineRPG.iceikaMossyCobble.blockID);
		world.setBlock(i + 7, j + 0, k + 14, DivineRPG.iceikaMossyCobble.blockID);
		world.setBlock(i + 7, j + 0, k + 15, DivineRPG.iceikaMossyCobble.blockID);
		world.setBlock(i + 7, j + 0, k + 16, DivineRPG.iceikaMossyCobble.blockID);
		world.setBlock(i + 7, j + 0, k + 17, DivineRPG.iceikaMossyCobble.blockID);
		world.setBlock(i + 7, j + 0, k + 18, DivineRPG.iceikaMossyCobble.blockID);
		world.setBlock(i + 7, j + 0, k + 19, DivineRPG.iceikaMossyCobble.blockID);
		world.setBlock(i + 7, j + 0, k + 20, DivineRPG.iceikaStoneBricks.blockID);
		world.setBlock(i + 7, j + 1, k + 0, DivineRPG.iceikaStoneBricks.blockID);
		world.setBlock(i + 7, j + 1, k + 1, DivineRPG.iceikaStoneBricks.blockID);
		world.setBlock(i + 7, j + 1, k + 2, DivineRPG.iceikaStoneBricks.blockID);
		world.setBlock(i + 7, j + 1, k + 3, 0);
		world.setBlock(i + 7, j + 1, k + 4, 0);
		world.setBlock(i + 7, j + 1, k + 5, DivineRPG.iceikaStoneBricks.blockID);
		world.setBlock(i + 7, j + 1, k + 6, DivineRPG.iceikaStoneBricks.blockID);
		world.setBlock(i + 7, j + 1, k + 7, DivineRPG.iceikaStoneBricks.blockID);
		world.setBlock(i + 7, j + 1, k + 9, DivineRPG.iceikaStoneBricks.blockID);
		world.setBlock(i + 7, j + 1, k + 10, 0);
		world.setBlock(i + 7, j + 1, k + 11, 0);
		world.setBlock(i + 7, j + 1, k + 12, 0);
		world.setBlock(i + 7, j + 1, k + 13, 0);
		world.setBlock(i + 7, j + 1, k + 14, 0);
		world.setBlock(i + 7, j + 1, k + 15, 0);
		world.setBlock(i + 7, j + 1, k + 16, 0);
		world.setBlock(i + 7, j + 1, k + 17, 0);
		world.setBlock(i + 7, j + 1, k + 18, 0);
		world.setBlock(i + 7, j + 1, k + 19, 0);
		world.setBlock(i + 7, j + 1, k + 20, DivineRPG.iceikaStoneBricks.blockID);
		world.setBlock(i + 7, j + 2, k + 0, DivineRPG.iceikaStoneBricks.blockID);
		world.setBlock(i + 7, j + 2, k + 1, DivineRPG.iceikaStoneBricks.blockID);
		world.setBlock(i + 7, j + 2, k + 2, DivineRPG.iceikaStoneBricks.blockID);
		world.setBlock(i + 7, j + 2, k + 3, 0);
		world.setBlock(i + 7, j + 2, k + 4, 0);
		world.setBlock(i + 7, j + 2, k + 5, DivineRPG.iceikaStoneBricks.blockID);
		world.setBlock(i + 7, j + 2, k + 6, DivineRPG.iceikaStoneBricks.blockID);
		world.setBlock(i + 7, j + 2, k + 7, DivineRPG.iceikaStoneBricks.blockID);
		world.setBlock(i + 7, j + 2, k + 9, DivineRPG.iceikaStoneBricks.blockID);
		world.setBlock(i + 7, j + 2, k + 10, 0);
		world.setBlock(i + 7, j + 2, k + 11, 0);
		world.setBlock(i + 7, j + 2, k + 12, 0);
		world.setBlock(i + 7, j + 2, k + 13, 0);
		world.setBlock(i + 7, j + 2, k + 14, 0);
		world.setBlock(i + 7, j + 2, k + 15, 0);
		world.setBlock(i + 7, j + 2, k + 16, 0);
		world.setBlock(i + 7, j + 2, k + 17, 0);
		world.setBlock(i + 7, j + 2, k + 18, 0);
		world.setBlock(i + 7, j + 2, k + 19, 0);
		world.setBlock(i + 7, j + 2, k + 20, DivineRPG.iceikaStoneBricks.blockID);
		world.setBlock(i + 7, j + 3, k + 0, DivineRPG.iceikaStoneBricks.blockID);
		world.setBlock(i + 7, j + 3, k + 1, DivineRPG.iceikaStoneBricks.blockID);
		world.setBlock(i + 7, j + 3, k + 2, DivineRPG.iceikaStoneBricks.blockID);
		world.setBlock(i + 7, j + 3, k + 3, 0);
		world.setBlock(i + 7, j + 3, k + 4, 0);
		world.setBlock(i + 7, j + 3, k + 5, DivineRPG.iceikaStoneBricks.blockID);
		world.setBlock(i + 7, j + 3, k + 6, DivineRPG.iceikaStoneBricks.blockID);
		world.setBlock(i + 7, j + 3, k + 7, DivineRPG.iceikaStoneBricks.blockID);
		world.setBlock(i + 7, j + 3, k + 9, DivineRPG.iceikaStoneBricks.blockID);
		world.setBlock(i + 7, j + 3, k + 10, 0);
		world.setBlock(i + 7, j + 3, k + 11, 0);
		world.setBlock(i + 7, j + 3, k + 12, 0);
		world.setBlock(i + 7, j + 3, k + 13, 0);
		world.setBlock(i + 7, j + 3, k + 14, 0);
		world.setBlock(i + 7, j + 3, k + 15, 0);
		world.setBlock(i + 7, j + 3, k + 16, 0);
		world.setBlock(i + 7, j + 3, k + 17, 0);
		world.setBlock(i + 7, j + 3, k + 18, 0);
		world.setBlock(i + 7, j + 3, k + 19, 0);
		world.setBlock(i + 7, j + 3, k + 20, DivineRPG.iceikaStoneBricks.blockID);
		world.setBlock(i + 7, j + 4, k + 3, DivineRPG.iceikaStoneBricks.blockID);
		world.setBlock(i + 7, j + 4, k + 4, DivineRPG.iceikaStoneBricks.blockID);
		world.setBlock(i + 7, j + 4, k + 10, DivineRPG.iceikaStoneBricks.blockID);
		world.setBlock(i + 7, j + 4, k + 11, DivineRPG.iceikaStoneBricks.blockID);
		world.setBlock(i + 7, j + 4, k + 12, DivineRPG.iceikaStoneBricks.blockID);
		world.setBlock(i + 7, j + 4, k + 13, DivineRPG.iceikaStoneBricks.blockID);
		world.setBlock(i + 7, j + 4, k + 14, DivineRPG.iceikaStoneBricks.blockID);
		world.setBlock(i + 7, j + 4, k + 15, DivineRPG.iceikaStoneBricks.blockID);
		world.setBlock(i + 7, j + 4, k + 16, DivineRPG.iceikaStoneBricks.blockID);
		world.setBlock(i + 7, j + 4, k + 17, DivineRPG.iceikaStoneBricks.blockID);
		world.setBlock(i + 7, j + 4, k + 18, DivineRPG.iceikaStoneBricks.blockID);
		world.setBlock(i + 7, j + 4, k + 19, DivineRPG.iceikaStoneBricks.blockID);
		world.setBlock(i + 8, j + 0, k + 2, DivineRPG.iceikaStoneBricks.blockID);
		world.setBlock(i + 8, j + 0, k + 3, DivineRPG.iceikaMossyCobble.blockID);
		world.setBlock(i + 8, j + 0, k + 4, DivineRPG.iceikaMossyCobble.blockID);
		world.setBlock(i + 8, j + 0, k + 5, DivineRPG.iceikaStoneBricks.blockID);
		world.setBlock(i + 8, j + 0, k + 9, DivineRPG.iceikaStoneBricks.blockID);
		world.setBlock(i + 8, j + 0, k + 10, DivineRPG.iceikaMossyCobble.blockID);
		world.setBlock(i + 8, j + 0, k + 11, DivineRPG.iceikaMossyCobble.blockID);
		world.setBlock(i + 8, j + 0, k + 12, DivineRPG.iceikaStoneBricks.blockID);
		world.setBlock(i + 8, j + 0, k + 13, DivineRPG.iceikaStoneBricks.blockID);
		world.setBlock(i + 8, j + 0, k + 14, DivineRPG.iceikaStoneBricks.blockID);
		world.setBlock(i + 8, j + 0, k + 15, DivineRPG.iceikaStoneBricks.blockID);
		world.setBlock(i + 8, j + 0, k + 16, DivineRPG.iceikaStoneBricks.blockID);
		world.setBlock(i + 8, j + 0, k + 17, DivineRPG.iceikaStoneBricks.blockID);
		world.setBlock(i + 8, j + 0, k + 18, DivineRPG.iceikaStoneBricks.blockID);
		world.setBlock(i + 8, j + 0, k + 19, DivineRPG.iceikaStoneBricks.blockID);
		world.setBlock(i + 8, j + 0, k + 20, DivineRPG.iceikaStoneBricks.blockID);
		world.setBlock(i + 8, j + 1, k + 2, DivineRPG.iceikaStoneBricks.blockID);
		world.setBlock(i + 8, j + 1, k + 3, 0);
		world.setBlock(i + 8, j + 1, k + 4, 0);
		world.setBlock(i + 8, j + 1, k + 5, DivineRPG.iceikaStoneBricks.blockID);
		world.setBlock(i + 8, j + 1, k + 9, DivineRPG.iceikaStoneBricks.blockID);
		world.setBlock(i + 8, j + 1, k + 10, 0);
		world.setBlock(i + 8, j + 1, k + 11, 0);
		world.setBlock(i + 8, j + 1, k + 12, DivineRPG.iceikaStoneBricks.blockID);
		world.setBlock(i + 8, j + 1, k + 13, DivineRPG.iceikaStoneBricks.blockID);
		world.setBlock(i + 8, j + 1, k + 14, DivineRPG.iceikaStoneBricks.blockID);
		world.setBlock(i + 8, j + 1, k + 15, DivineRPG.iceikaStoneBricks.blockID);
		world.setBlock(i + 8, j + 1, k + 16, DivineRPG.iceikaStoneBricks.blockID);
		world.setBlock(i + 8, j + 1, k + 17, DivineRPG.iceikaStoneBricks.blockID);
		world.setBlock(i + 8, j + 1, k + 18, DivineRPG.iceikaStoneBricks.blockID);
		world.setBlock(i + 8, j + 1, k + 19, DivineRPG.iceikaStoneBricks.blockID);
		world.setBlock(i + 8, j + 1, k + 20, DivineRPG.iceikaStoneBricks.blockID);
		world.setBlock(i + 8, j + 2, k + 2, DivineRPG.iceikaStoneBricks.blockID);
		world.setBlock(i + 8, j + 2, k + 3, 0);
		world.setBlock(i + 8, j + 2, k + 4, 0);
		world.setBlock(i + 8, j + 2, k + 5, DivineRPG.iceikaStoneBricks.blockID);
		world.setBlock(i + 8, j + 2, k + 9, DivineRPG.iceikaStoneBricks.blockID);
		world.setBlock(i + 8, j + 2, k + 10, 0);
		world.setBlock(i + 8, j + 2, k + 11, 0);
		world.setBlock(i + 8, j + 2, k + 12, DivineRPG.iceikaStoneBricks.blockID);
		world.setBlock(i + 8, j + 2, k + 13, DivineRPG.iceikaStoneBricks.blockID);
		world.setBlock(i + 8, j + 2, k + 14, DivineRPG.iceikaStoneBricks.blockID);
		world.setBlock(i + 8, j + 2, k + 15, DivineRPG.iceikaStoneBricks.blockID);
		world.setBlock(i + 8, j + 2, k + 16, DivineRPG.iceikaStoneBricks.blockID);
		world.setBlock(i + 8, j + 2, k + 17, DivineRPG.iceikaStoneBricks.blockID);
		world.setBlock(i + 8, j + 2, k + 18, DivineRPG.iceikaStoneBricks.blockID);
		world.setBlock(i + 8, j + 2, k + 19, DivineRPG.iceikaStoneBricks.blockID);
		world.setBlock(i + 8, j + 2, k + 20, DivineRPG.iceikaStoneBricks.blockID);
		world.setBlock(i + 8, j + 3, k + 2, DivineRPG.iceikaStoneBricks.blockID);
		world.setBlock(i + 8, j + 3, k + 3, 0);
		world.setBlock(i + 8, j + 3, k + 4, 0);
		world.setBlock(i + 8, j + 3, k + 5, DivineRPG.iceikaStoneBricks.blockID);
		world.setBlock(i + 8, j + 3, k + 9, DivineRPG.iceikaStoneBricks.blockID);
		world.setBlock(i + 8, j + 3, k + 10, 0);
		world.setBlock(i + 8, j + 3, k + 11, 0);
		world.setBlock(i + 8, j + 3, k + 12, DivineRPG.iceikaStoneBricks.blockID);
		world.setBlock(i + 8, j + 3, k + 13, DivineRPG.iceikaStoneBricks.blockID);
		world.setBlock(i + 8, j + 3, k + 14, DivineRPG.iceikaStoneBricks.blockID);
		world.setBlock(i + 8, j + 3, k + 15, DivineRPG.iceikaStoneBricks.blockID);
		world.setBlock(i + 8, j + 3, k + 16, DivineRPG.iceikaStoneBricks.blockID);
		world.setBlock(i + 8, j + 3, k + 17, DivineRPG.iceikaStoneBricks.blockID);
		world.setBlock(i + 8, j + 3, k + 18, DivineRPG.iceikaStoneBricks.blockID);
		world.setBlock(i + 8, j + 3, k + 19, DivineRPG.iceikaStoneBricks.blockID);
		world.setBlock(i + 8, j + 3, k + 20, DivineRPG.iceikaStoneBricks.blockID);
		world.setBlock(i + 8, j + 4, k + 3, DivineRPG.iceikaStoneBricks.blockID);
		world.setBlock(i + 8, j + 4, k + 4, DivineRPG.iceikaStoneBricks.blockID);
		world.setBlock(i + 8, j + 4, k + 10, DivineRPG.iceikaStoneBricks.blockID);
		world.setBlock(i + 8, j + 4, k + 11, DivineRPG.iceikaStoneBricks.blockID);
		world.setBlock(i + 9, j + 0, k + 2, DivineRPG.iceikaStoneBricks.blockID);
		world.setBlock(i + 9, j + 0, k + 3, DivineRPG.iceikaMossyCobble.blockID);
		world.setBlock(i + 9, j + 0, k + 4, DivineRPG.iceikaMossyCobble.blockID);
		world.setBlock(i + 9, j + 0, k + 5, DivineRPG.iceikaStoneBricks.blockID);
		world.setBlock(i + 9, j + 0, k + 6, DivineRPG.iceikaStoneBricks.blockID);
		world.setBlock(i + 9, j + 0, k + 7, DivineRPG.iceikaStoneBricks.blockID);
		world.setBlock(i + 9, j + 0, k + 8, DivineRPG.iceikaStoneBricks.blockID);
		world.setBlock(i + 9, j + 0, k + 9, DivineRPG.iceikaStoneBricks.blockID);
		world.setBlock(i + 9, j + 0, k + 10, DivineRPG.iceikaMossyCobble.blockID);
		world.setBlock(i + 9, j + 0, k + 11, DivineRPG.iceikaMossyCobble.blockID);
		world.setBlock(i + 9, j + 0, k + 12, DivineRPG.iceikaStoneBricks.blockID);
		world.setBlock(i + 9, j + 1, k + 2, DivineRPG.iceikaStoneBricks.blockID);
		world.setBlock(i + 9, j + 1, k + 3, 0);
		world.setBlock(i + 9, j + 1, k + 4, 0);
		world.setBlock(i + 9, j + 1, k + 5, DivineRPG.iceikaStoneBricks.blockID);
		world.setBlock(i + 9, j + 1, k + 6, DivineRPG.iceikaStoneBricks.blockID);
		world.setBlock(i + 9, j + 1, k + 7, DivineRPG.iceikaStoneBricks.blockID);
		world.setBlock(i + 9, j + 1, k + 8, DivineRPG.iceikaStoneBricks.blockID);
		world.setBlock(i + 9, j + 1, k + 9, DivineRPG.iceikaStoneBricks.blockID);
		world.setBlock(i + 9, j + 1, k + 10, 0);
		world.setBlock(i + 9, j + 1, k + 11, 0);
		world.setBlock(i + 9, j + 1, k + 12, DivineRPG.iceikaStoneBricks.blockID);
		world.setBlock(i + 9, j + 2, k + 2, DivineRPG.iceikaStoneBricks.blockID);
		world.setBlock(i + 9, j + 2, k + 3, 0);
		world.setBlock(i + 9, j + 2, k + 4, 0);
		world.setBlock(i + 9, j + 2, k + 5, DivineRPG.iceikaStoneBricks.blockID);
		world.setBlock(i + 9, j + 2, k + 6, DivineRPG.iceikaStoneBricks.blockID);
		world.setBlock(i + 9, j + 2, k + 7, DivineRPG.iceikaStoneBricks.blockID);
		world.setBlock(i + 9, j + 2, k + 8, DivineRPG.iceikaStoneBricks.blockID);
		world.setBlock(i + 9, j + 2, k + 9, DivineRPG.iceikaStoneBricks.blockID);
		world.setBlock(i + 9, j + 2, k + 10, 0);
		world.setBlock(i + 9, j + 2, k + 11, 0);
		world.setBlock(i + 9, j + 2, k + 12, DivineRPG.iceikaStoneBricks.blockID);
		world.setBlock(i + 9, j + 3, k + 2, DivineRPG.iceikaStoneBricks.blockID);
		world.setBlock(i + 9, j + 3, k + 3, 0);
		world.setBlock(i + 9, j + 3, k + 4, 0);
		world.setBlock(i + 9, j + 3, k + 5, DivineRPG.iceikaStoneBricks.blockID);
		world.setBlock(i + 9, j + 3, k + 6, DivineRPG.iceikaStoneBricks.blockID);
		world.setBlock(i + 9, j + 3, k + 7, DivineRPG.iceikaStoneBricks.blockID);
		world.setBlock(i + 9, j + 3, k + 8, DivineRPG.iceikaStoneBricks.blockID);
		world.setBlock(i + 9, j + 3, k + 9, DivineRPG.iceikaStoneBricks.blockID);
		world.setBlock(i + 9, j + 3, k + 10, 0);
		world.setBlock(i + 9, j + 3, k + 11, 0);
		world.setBlock(i + 9, j + 3, k + 12, DivineRPG.iceikaStoneBricks.blockID);
		world.setBlock(i + 9, j + 4, k + 3, DivineRPG.iceikaStoneBricks.blockID);
		world.setBlock(i + 9, j + 4, k + 4, DivineRPG.iceikaStoneBricks.blockID);
		world.setBlock(i + 9, j + 4, k + 10, DivineRPG.iceikaStoneBricks.blockID);
		world.setBlock(i + 9, j + 4, k + 11, DivineRPG.iceikaStoneBricks.blockID);
		world.setBlock(i + 10, j + 0, k + 2, DivineRPG.iceikaStoneBricks.blockID);
		world.setBlock(i + 10, j + 0, k + 3, DivineRPG.iceikaMossyCobble.blockID);
		world.setBlock(i + 10, j + 0, k + 4, DivineRPG.iceikaMossyCobble.blockID);
		world.setBlock(i + 10, j + 0, k + 5, DivineRPG.iceikaMossyCobble.blockID);
		world.setBlock(i + 10, j + 0, k + 6, DivineRPG.iceikaMossyCobble.blockID);
		world.setBlock(i + 10, j + 0, k + 7, DivineRPG.iceikaMossyCobble.blockID);
		world.setBlock(i + 10, j + 0, k + 8, DivineRPG.iceikaMossyCobble.blockID);
		world.setBlock(i + 10, j + 0, k + 9, DivineRPG.iceikaMossyCobble.blockID);
		world.setBlock(i + 10, j + 0, k + 10, DivineRPG.iceikaMossyCobble.blockID);
		world.setBlock(i + 10, j + 0, k + 11, DivineRPG.iceikaMossyCobble.blockID);
		world.setBlock(i + 10, j + 0, k + 12, DivineRPG.iceikaStoneBricks.blockID);
		world.setBlock(i + 10, j + 1, k + 2, DivineRPG.iceikaStoneBricks.blockID);
		world.setBlock(i + 10, j + 1, k + 3, 0);
		world.setBlock(i + 10, j + 1, k + 4, 0);
		world.setBlock(i + 10, j + 1, k + 5, 0);
		world.setBlock(i + 10, j + 1, k + 6, 0);
		world.setBlock(i + 10, j + 1, k + 7, 0);
		world.setBlock(i + 10, j + 1, k + 8, 0);
		world.setBlock(i + 10, j + 1, k + 9, 0);
		world.setBlock(i + 10, j + 1, k + 10, 0);
		world.setBlock(i + 10, j + 1, k + 11, 0);
		world.setBlock(i + 10, j + 1, k + 12, DivineRPG.iceikaStoneBricks.blockID);
		world.setBlock(i + 10, j + 2, k + 2, DivineRPG.iceikaStoneBricks.blockID);
		world.setBlock(i + 10, j + 2, k + 3, 0);
		world.setBlock(i + 10, j + 2, k + 4, 0);
		world.setBlock(i + 10, j + 2, k + 5, 0);
		world.setBlock(i + 10, j + 2, k + 6, 0);
		world.setBlock(i + 10, j + 2, k + 7, 0);
		world.setBlock(i + 10, j + 2, k + 8, 0);
		world.setBlock(i + 10, j + 2, k + 9, 0);
		world.setBlock(i + 10, j + 2, k + 10, 0);
		world.setBlock(i + 10, j + 2, k + 11, 0);
		world.setBlock(i + 10, j + 2, k + 12, DivineRPG.iceikaStoneBricks.blockID);
		world.setBlock(i + 10, j + 3, k + 2, DivineRPG.iceikaStoneBricks.blockID);
		world.setBlock(i + 10, j + 3, k + 3, 0);
		world.setBlock(i + 10, j + 3, k + 4, 0);
		world.setBlock(i + 10, j + 3, k + 5, 0);
		world.setBlock(i + 10, j + 3, k + 6, 0);
		world.setBlock(i + 10, j + 3, k + 7, 0);
		world.setBlock(i + 10, j + 3, k + 8, 0);
		world.setBlock(i + 10, j + 3, k + 9, 0);
		world.setBlock(i + 10, j + 3, k + 10, 0);
		world.setBlock(i + 10, j + 3, k + 11, 0);
		world.setBlock(i + 10, j + 3, k + 12, DivineRPG.iceikaStoneBricks.blockID);
		world.setBlock(i + 10, j + 4, k + 3, DivineRPG.iceikaStoneBricks.blockID);
		world.setBlock(i + 10, j + 4, k + 4, DivineRPG.iceikaStoneBricks.blockID);
		world.setBlock(i + 10, j + 4, k + 5, DivineRPG.iceikaStoneBricks.blockID);
		world.setBlock(i + 10, j + 4, k + 6, DivineRPG.iceikaStoneBricks.blockID);
		world.setBlock(i + 10, j + 4, k + 7, DivineRPG.iceikaStoneBricks.blockID);
		world.setBlock(i + 10, j + 4, k + 8, DivineRPG.iceikaStoneBricks.blockID);
		world.setBlock(i + 10, j + 4, k + 9, DivineRPG.iceikaStoneBricks.blockID);
		world.setBlock(i + 10, j + 4, k + 10, DivineRPG.iceikaStoneBricks.blockID);
		world.setBlock(i + 10, j + 4, k + 11, DivineRPG.iceikaStoneBricks.blockID);
		world.setBlock(i + 11, j + 0, k + 2, DivineRPG.iceikaStoneBricks.blockID);
		world.setBlock(i + 11, j + 0, k + 3, DivineRPG.iceikaMossyCobble.blockID);
		world.setBlock(i + 11, j + 0, k + 4, DivineRPG.iceikaMossyCobble.blockID);
		world.setBlock(i + 11, j + 0, k + 5, DivineRPG.iceikaMossyCobble.blockID);
		world.setBlock(i + 11, j + 0, k + 6, DivineRPG.iceikaMossyCobble.blockID);
		world.setBlock(i + 11, j + 0, k + 7, DivineRPG.iceikaMossyCobble.blockID);
		world.setBlock(i + 11, j + 0, k + 8, DivineRPG.iceikaMossyCobble.blockID);
		world.setBlock(i + 11, j + 0, k + 9, DivineRPG.iceikaMossyCobble.blockID);
		world.setBlock(i + 11, j + 0, k + 10, DivineRPG.iceikaMossyCobble.blockID);
		world.setBlock(i + 11, j + 0, k + 11, DivineRPG.iceikaMossyCobble.blockID);
		world.setBlock(i + 11, j + 0, k + 12, DivineRPG.iceikaStoneBricks.blockID);
		world.setBlock(i + 11, j + 1, k + 2, DivineRPG.iceikaStoneBricks.blockID);
		world.setBlock(i + 11, j + 1, k + 3, 0);
		world.setBlock(i + 11, j + 1, k + 4, 0);
		world.setBlock(i + 11, j + 1, k + 5, 0);
		world.setBlock(i + 11, j + 1, k + 6, 0);
		world.setBlock(i + 11, j + 1, k + 7, 0);
		world.setBlock(i + 11, j + 1, k + 8, 0);
		world.setBlock(i + 11, j + 1, k + 9, 0);
		world.setBlock(i + 11, j + 1, k + 10, 0);
		world.setBlock(i + 11, j + 1, k + 11, 0);
		world.setBlock(i + 11, j + 1, k + 12, DivineRPG.iceikaStoneBricks.blockID);
		world.setBlock(i + 11, j + 2, k + 2, DivineRPG.iceikaStoneBricks.blockID);
		world.setBlock(i + 11, j + 2, k + 3, 0);
		world.setBlock(i + 11, j + 2, k + 4, 0);
		world.setBlock(i + 11, j + 2, k + 5, 0);
		world.setBlock(i + 11, j + 2, k + 6, 0);
		world.setBlock(i + 11, j + 2, k + 7, 0);
		world.setBlock(i + 11, j + 2, k + 8, 0);
		world.setBlock(i + 11, j + 2, k + 9, 0);
		world.setBlock(i + 11, j + 2, k + 10, 0);
		world.setBlock(i + 11, j + 2, k + 11, 0);
		world.setBlock(i + 11, j + 2, k + 12, DivineRPG.iceikaStoneBricks.blockID);
		world.setBlock(i + 11, j + 3, k + 2, DivineRPG.iceikaStoneBricks.blockID);
		world.setBlock(i + 11, j + 3, k + 3, 0);
		world.setBlock(i + 11, j + 3, k + 4, 0);
		world.setBlock(i + 11, j + 3, k + 5, 0);
		world.setBlock(i + 11, j + 3, k + 6, 0);
		world.setBlock(i + 11, j + 3, k + 7, 0);
		world.setBlock(i + 11, j + 3, k + 8, 0);
		world.setBlock(i + 11, j + 3, k + 9, 0);
		world.setBlock(i + 11, j + 3, k + 10, 0);
		world.setBlock(i + 11, j + 3, k + 11, 0);
		world.setBlock(i + 11, j + 3, k + 12, DivineRPG.iceikaStoneBricks.blockID);
		world.setBlock(i + 11, j + 4, k + 3, DivineRPG.iceikaStoneBricks.blockID);
		world.setBlock(i + 11, j + 4, k + 4, DivineRPG.iceikaStoneBricks.blockID);
		world.setBlock(i + 11, j + 4, k + 5, DivineRPG.iceikaStoneBricks.blockID);
		world.setBlock(i + 11, j + 4, k + 6, DivineRPG.iceikaStoneBricks.blockID);
		world.setBlock(i + 11, j + 4, k + 7, DivineRPG.iceikaStoneBricks.blockID);
		world.setBlock(i + 11, j + 4, k + 8, DivineRPG.iceikaStoneBricks.blockID);
		world.setBlock(i + 11, j + 4, k + 9, DivineRPG.iceikaStoneBricks.blockID);
		world.setBlock(i + 11, j + 4, k + 10, DivineRPG.iceikaStoneBricks.blockID);
		world.setBlock(i + 11, j + 4, k + 11, DivineRPG.iceikaStoneBricks.blockID);
		world.setBlock(i + 12, j + 0, k + 2, DivineRPG.iceikaStoneBricks.blockID);
		world.setBlock(i + 12, j + 0, k + 3, DivineRPG.iceikaStoneBricks.blockID);
		world.setBlock(i + 12, j + 0, k + 4, DivineRPG.iceikaStoneBricks.blockID);
		world.setBlock(i + 12, j + 0, k + 5, DivineRPG.iceikaStoneBricks.blockID);
		world.setBlock(i + 12, j + 0, k + 6, DivineRPG.iceikaStoneBricks.blockID);
		world.setBlock(i + 12, j + 0, k + 7, DivineRPG.iceikaStoneBricks.blockID);
		world.setBlock(i + 12, j + 0, k + 8, DivineRPG.iceikaStoneBricks.blockID);
		world.setBlock(i + 12, j + 0, k + 9, DivineRPG.iceikaStoneBricks.blockID);
		world.setBlock(i + 12, j + 0, k + 10, DivineRPG.iceikaStoneBricks.blockID);
		world.setBlock(i + 12, j + 0, k + 11, DivineRPG.iceikaStoneBricks.blockID);
		world.setBlock(i + 12, j + 0, k + 12, DivineRPG.iceikaStoneBricks.blockID);
		world.setBlock(i + 12, j + 1, k + 2, DivineRPG.iceikaStoneBricks.blockID);
		world.setBlock(i + 12, j + 1, k + 3, DivineRPG.iceikaStoneBricks.blockID);
		world.setBlock(i + 12, j + 1, k + 4, DivineRPG.iceikaStoneBricks.blockID);
		world.setBlock(i + 12, j + 1, k + 5, DivineRPG.iceikaStoneBricks.blockID);
		world.setBlock(i + 12, j + 1, k + 6, DivineRPG.iceikaStoneBricks.blockID);
		world.setBlock(i + 12, j + 1, k + 7, DivineRPG.iceikaStoneBricks.blockID);
		world.setBlock(i + 12, j + 1, k + 8, DivineRPG.iceikaStoneBricks.blockID);
		world.setBlock(i + 12, j + 1, k + 9, DivineRPG.iceikaStoneBricks.blockID);
		world.setBlock(i + 12, j + 1, k + 10, DivineRPG.iceikaStoneBricks.blockID);
		world.setBlock(i + 12, j + 1, k + 11, DivineRPG.iceikaStoneBricks.blockID);
		world.setBlock(i + 12, j + 1, k + 12, DivineRPG.iceikaStoneBricks.blockID);
		world.setBlock(i + 12, j + 2, k + 2, DivineRPG.iceikaStoneBricks.blockID);
		world.setBlock(i + 12, j + 2, k + 3, DivineRPG.iceikaStoneBricks.blockID);
		world.setBlock(i + 12, j + 2, k + 4, DivineRPG.iceikaStoneBricks.blockID);
		world.setBlock(i + 12, j + 2, k + 5, DivineRPG.iceikaStoneBricks.blockID);
		world.setBlock(i + 12, j + 2, k + 6, DivineRPG.iceikaStoneBricks.blockID);
		world.setBlock(i + 12, j + 2, k + 7, DivineRPG.iceikaStoneBricks.blockID);
		world.setBlock(i + 12, j + 2, k + 8, DivineRPG.iceikaStoneBricks.blockID);
		world.setBlock(i + 12, j + 2, k + 9, DivineRPG.iceikaStoneBricks.blockID);
		world.setBlock(i + 12, j + 2, k + 10, DivineRPG.iceikaStoneBricks.blockID);
		world.setBlock(i + 12, j + 2, k + 11, DivineRPG.iceikaStoneBricks.blockID);
		world.setBlock(i + 12, j + 2, k + 12, DivineRPG.iceikaStoneBricks.blockID);
		world.setBlock(i + 12, j + 3, k + 2, DivineRPG.iceikaStoneBricks.blockID);
		world.setBlock(i + 12, j + 3, k + 3, DivineRPG.iceikaStoneBricks.blockID);
		world.setBlock(i + 12, j + 3, k + 4, DivineRPG.iceikaStoneBricks.blockID);
		world.setBlock(i + 12, j + 3, k + 5, DivineRPG.iceikaStoneBricks.blockID);
		world.setBlock(i + 12, j + 3, k + 6, DivineRPG.iceikaStoneBricks.blockID);
		world.setBlock(i + 12, j + 3, k + 7, DivineRPG.iceikaStoneBricks.blockID);
		world.setBlock(i + 12, j + 3, k + 8, DivineRPG.iceikaStoneBricks.blockID);
		world.setBlock(i + 12, j + 3, k + 9, DivineRPG.iceikaStoneBricks.blockID);
		world.setBlock(i + 12, j + 3, k + 10, DivineRPG.iceikaStoneBricks.blockID);
		world.setBlock(i + 12, j + 3, k + 11, DivineRPG.iceikaStoneBricks.blockID);
		world.setBlock(i + 12, j + 3, k + 12, DivineRPG.iceikaStoneBricks.blockID);
	
		TileEntityIceikaChest var16 = (TileEntityIceikaChest)world.getBlockTileEntity(i,j,k);

		if (var16 != null)
		{      
			var16.setInventorySlotContents(rand.nextInt(var16.getSizeInventory()), new ItemStack(DivineRPG.snowFlake.itemID, 1, 1));
		}
		return true;
	}
}