/*
*** MADE BY MITHION'S .SCHEMATIC TO JAVA CONVERTING TOOL v1.6 ***
*/

package net.divinerpg.worldgen.vethea.village;
import java.util.Random;

import net.divinerpg.utils.helpers.block.VetheaBlockHelper;
import net.minecraft.world.World;
import net.minecraft.world.gen.feature.WorldGenerator;

public class LightDown2 extends WorldGenerator
{
	protected int[] GetValidSpawnBlocks() {
		return new int[] {
		};
	}

	public LightDown2() { }

	public boolean generate(World world, Random rand, int i, int j, int k) {

		world.setBlock(i + 0, j + 0, k + 0, VetheaBlockHelper.darkEverstone.blockID);
		world.setBlock(i + 0, j + 0, k + 3, VetheaBlockHelper.darkEverstone.blockID);
		world.setBlock(i + 0, j + 1, k + 0, VetheaBlockHelper.darkEverstone.blockID);
		world.setBlock(i + 0, j + 1, k + 1, VetheaBlockHelper.darkEverstone.blockID);
		world.setBlock(i + 0, j + 1, k + 2, VetheaBlockHelper.darkEverstone.blockID);
		world.setBlock(i + 0, j + 1, k + 3, VetheaBlockHelper.darkEverstone.blockID);
		world.setBlock(i + 0, j + 2, k + 0, VetheaBlockHelper.darkEverstone.blockID);
		world.setBlock(i + 0, j + 2, k + 3, VetheaBlockHelper.darkEverstone.blockID);
		world.setBlock(i + 0, j + 3, k + 0, VetheaBlockHelper.darkEverstone.blockID);
		world.setBlock(i + 0, j + 3, k + 1, VetheaBlockHelper.darkEverstone.blockID);
		world.setBlock(i + 0, j + 3, k + 2, VetheaBlockHelper.darkEverstone.blockID);
		world.setBlock(i + 0, j + 3, k + 3, VetheaBlockHelper.darkEverstone.blockID);
		world.setBlock(i + 0, j + 5, k + 0, VetheaBlockHelper.darkEverstone.blockID);
		world.setBlock(i + 0, j + 5, k + 1, VetheaBlockHelper.darkEverstone.blockID);
		world.setBlock(i + 0, j + 5, k + 2, VetheaBlockHelper.darkEverstone.blockID);
		world.setBlock(i + 0, j + 5, k + 3, VetheaBlockHelper.darkEverstone.blockID);
		world.setBlock(i + 1, j + 1, k + 0, VetheaBlockHelper.darkEverstone.blockID);
		world.setBlock(i + 1, j + 1, k + 3, VetheaBlockHelper.darkEverstone.blockID);
		world.setBlock(i + 1, j + 3, k + 0, VetheaBlockHelper.darkEverstone.blockID);
		world.setBlock(i + 1, j + 3, k + 1, VetheaBlockHelper.darkEverstone.blockID);
		world.setBlock(i + 1, j + 3, k + 2, VetheaBlockHelper.darkEverstone.blockID);
		world.setBlock(i + 1, j + 3, k + 3, VetheaBlockHelper.darkEverstone.blockID);
		world.setBlock(i + 1, j + 4, k + 1, VetheaBlockHelper.darkEverstone.blockID);
		world.setBlock(i + 1, j + 4, k + 2, VetheaBlockHelper.darkEverstone.blockID);
		world.setBlock(i + 1, j + 5, k + 0, VetheaBlockHelper.darkEverstone.blockID);
		world.setBlock(i + 1, j + 5, k + 1, VetheaBlockHelper.darkEverstone.blockID);
		world.setBlock(i + 1, j + 5, k + 2, VetheaBlockHelper.darkEverstone.blockID);
		world.setBlock(i + 1, j + 5, k + 3, VetheaBlockHelper.darkEverstone.blockID);
		world.setBlock(i + 2, j + 1, k + 0, VetheaBlockHelper.darkEverstone.blockID);
		world.setBlock(i + 2, j + 1, k + 3, VetheaBlockHelper.darkEverstone.blockID);
		world.setBlock(i + 2, j + 3, k + 0, VetheaBlockHelper.darkEverstone.blockID);
		world.setBlock(i + 2, j + 3, k + 1, VetheaBlockHelper.darkEverstone.blockID);
		world.setBlock(i + 2, j + 3, k + 2, VetheaBlockHelper.darkEverstone.blockID);
		world.setBlock(i + 2, j + 3, k + 3, VetheaBlockHelper.darkEverstone.blockID);
		world.setBlock(i + 2, j + 4, k + 1, VetheaBlockHelper.darkEverstone.blockID);
		world.setBlock(i + 2, j + 4, k + 2, VetheaBlockHelper.darkEverstone.blockID);
		world.setBlock(i + 2, j + 5, k + 0, VetheaBlockHelper.darkEverstone.blockID);
		world.setBlock(i + 2, j + 5, k + 1, VetheaBlockHelper.darkEverstone.blockID);
		world.setBlock(i + 2, j + 5, k + 2, VetheaBlockHelper.darkEverstone.blockID);
		world.setBlock(i + 2, j + 5, k + 3, VetheaBlockHelper.darkEverstone.blockID);
		world.setBlock(i + 3, j + 0, k + 0, VetheaBlockHelper.darkEverstone.blockID);
		world.setBlock(i + 3, j + 0, k + 3, VetheaBlockHelper.darkEverstone.blockID);
		world.setBlock(i + 3, j + 1, k + 0, VetheaBlockHelper.darkEverstone.blockID);
		world.setBlock(i + 3, j + 1, k + 1, VetheaBlockHelper.darkEverstone.blockID);
		world.setBlock(i + 3, j + 1, k + 2, VetheaBlockHelper.darkEverstone.blockID);
		world.setBlock(i + 3, j + 1, k + 3, VetheaBlockHelper.darkEverstone.blockID);
		world.setBlock(i + 3, j + 2, k + 0, VetheaBlockHelper.darkEverstone.blockID);
		world.setBlock(i + 3, j + 2, k + 3, VetheaBlockHelper.darkEverstone.blockID);
		world.setBlock(i + 3, j + 3, k + 0, VetheaBlockHelper.darkEverstone.blockID);
		world.setBlock(i + 3, j + 3, k + 1, VetheaBlockHelper.darkEverstone.blockID);
		world.setBlock(i + 3, j + 3, k + 2, VetheaBlockHelper.darkEverstone.blockID);
		world.setBlock(i + 3, j + 3, k + 3, VetheaBlockHelper.darkEverstone.blockID);
		world.setBlock(i + 3, j + 5, k + 0, VetheaBlockHelper.darkEverstone.blockID);
		world.setBlock(i + 3, j + 5, k + 1, VetheaBlockHelper.darkEverstone.blockID);
		world.setBlock(i + 3, j + 5, k + 2, VetheaBlockHelper.darkEverstone.blockID);
		world.setBlock(i + 3, j + 5, k + 3, VetheaBlockHelper.darkEverstone.blockID);

		return true;
	}
}