/*
*** MADE BY MITHION'S .SCHEMATIC TO JAVA CONVERTING TOOL v1.6 ***
*/

package net.divinerpg.worldgen.vethea.layer4;
import java.util.Random;

import net.divinerpg.utils.helpers.block.VetheaBlockHelper;
import net.minecraft.world.World;
import net.minecraft.world.gen.feature.WorldGenerator;

public class WreckHall extends WorldGenerator
{
	protected int[] GetValidSpawnBlocks() {
		return new int[] {
		};
	}

	public WreckHall() { }

	public boolean generate(World world, Random rand, int i, int j, int k) {

		world.setBlock(i + 0, j + 0, k + 16, VetheaBlockHelper.hallWall.blockID);
		world.setBlock(i + 0, j + 0, k + 17, VetheaBlockHelper.firecrystal.blockID);
		world.setBlock(i + 0, j + 0, k + 18, VetheaBlockHelper.firecrystal.blockID);
		world.setBlock(i + 0, j + 0, k + 19, VetheaBlockHelper.hallWall.blockID);
		world.setBlock(i + 0, j + 0, k + 35, VetheaBlockHelper.darkEverstone.blockID);
		world.setBlock(i + 0, j + 1, k + 16, VetheaBlockHelper.hallWall.blockID);
		world.setBlock(i + 0, j + 1, k + 19, VetheaBlockHelper.hallWall.blockID);
		world.setBlock(i + 0, j + 1, k + 35, VetheaBlockHelper.darkEverstone.blockID);
		world.setBlock(i + 0, j + 2, k + 16, VetheaBlockHelper.hallWall.blockID);
		world.setBlock(i + 0, j + 2, k + 19, VetheaBlockHelper.hallWall.blockID);
		world.setBlock(i + 0, j + 2, k + 35, VetheaBlockHelper.darkEverstone.blockID);
		world.setBlock(i + 0, j + 3, k + 16, VetheaBlockHelper.hallWall.blockID);
		world.setBlock(i + 0, j + 3, k + 17, VetheaBlockHelper.hallWall.blockID);
		world.setBlock(i + 0, j + 3, k + 18, VetheaBlockHelper.hallWall.blockID);
		world.setBlock(i + 0, j + 3, k + 19, VetheaBlockHelper.hallWall.blockID);
		world.setBlock(i + 0, j + 3, k + 35, VetheaBlockHelper.darkEverstone.blockID);
		world.setBlock(i + 0, j + 4, k + 35, VetheaBlockHelper.darkEverstone.blockID);
		world.setBlock(i + 1, j + 0, k + 16, VetheaBlockHelper.hallWall.blockID);
		world.setBlock(i + 1, j + 0, k + 17, VetheaBlockHelper.firecrystal.blockID);
		world.setBlock(i + 1, j + 0, k + 18, VetheaBlockHelper.firecrystal.blockID);
		world.setBlock(i + 1, j + 0, k + 19, VetheaBlockHelper.hallWall.blockID);
		world.setBlock(i + 1, j + 0, k + 20, VetheaBlockHelper.hallWall.blockID);
		world.setBlock(i + 1, j + 0, k + 21, VetheaBlockHelper.hallWall.blockID);
		world.setBlock(i + 1, j + 0, k + 22, VetheaBlockHelper.hallWall.blockID);
		world.setBlock(i + 1, j + 0, k + 23, VetheaBlockHelper.hallWall.blockID);
		world.setBlock(i + 1, j + 0, k + 24, VetheaBlockHelper.hallWall.blockID);
		world.setBlock(i + 1, j + 0, k + 25, VetheaBlockHelper.hallWall.blockID);
		world.setBlock(i + 1, j + 0, k + 26, VetheaBlockHelper.hallWall.blockID);
		world.setBlock(i + 1, j + 0, k + 27, VetheaBlockHelper.hallWall.blockID);
		world.setBlock(i + 1, j + 0, k + 28, VetheaBlockHelper.hallWall.blockID);
		world.setBlock(i + 1, j + 0, k + 29, VetheaBlockHelper.hallWall.blockID);
		world.setBlock(i + 1, j + 0, k + 30, VetheaBlockHelper.hallWall.blockID);
		world.setBlock(i + 1, j + 0, k + 31, VetheaBlockHelper.hallWall.blockID);
		world.setBlock(i + 1, j + 0, k + 32, VetheaBlockHelper.hallWall.blockID);
		world.setBlock(i + 1, j + 0, k + 33, VetheaBlockHelper.hallWall.blockID);
		world.setBlock(i + 1, j + 0, k + 34, VetheaBlockHelper.hallWall.blockID);
		world.setBlock(i + 1, j + 0, k + 35, VetheaBlockHelper.hallWall.blockID);
		world.setBlock(i + 1, j + 0, k + 36, VetheaBlockHelper.hallWall.blockID);
		world.setBlock(i + 1, j + 1, k + 16, VetheaBlockHelper.hallWall.blockID);
		world.setBlock(i + 1, j + 1, k + 19, VetheaBlockHelper.hallWall.blockID);
		world.setBlock(i + 1, j + 1, k + 20, VetheaBlockHelper.hallWall.blockID);
		world.setBlock(i + 1, j + 1, k + 21, VetheaBlockHelper.hallWall.blockID);
		world.setBlock(i + 1, j + 1, k + 22, VetheaBlockHelper.hallWall.blockID);
		world.setBlock(i + 1, j + 1, k + 23, VetheaBlockHelper.hallWall.blockID);
		world.setBlock(i + 1, j + 1, k + 24, VetheaBlockHelper.hallWall.blockID);
		world.setBlock(i + 1, j + 1, k + 25, VetheaBlockHelper.hallWall.blockID);
		world.setBlock(i + 1, j + 1, k + 26, VetheaBlockHelper.hallWall.blockID);
		world.setBlock(i + 1, j + 1, k + 27, VetheaBlockHelper.hallWall.blockID);
		world.setBlock(i + 1, j + 1, k + 28, VetheaBlockHelper.hallWall.blockID);
		world.setBlock(i + 1, j + 1, k + 29, VetheaBlockHelper.hallWall.blockID);
		world.setBlock(i + 1, j + 1, k + 30, VetheaBlockHelper.hallWall.blockID);
		world.setBlock(i + 1, j + 1, k + 31, VetheaBlockHelper.hallWall.blockID);
		world.setBlock(i + 1, j + 1, k + 32, VetheaBlockHelper.hallWall.blockID);
		world.setBlock(i + 1, j + 1, k + 33, VetheaBlockHelper.hallWall.blockID);
		world.setBlock(i + 1, j + 1, k + 34, VetheaBlockHelper.hallWall.blockID);
		world.setBlock(i + 1, j + 1, k + 35, VetheaBlockHelper.hallWall.blockID);
		world.setBlock(i + 1, j + 1, k + 36, VetheaBlockHelper.hallWall.blockID);
		world.setBlock(i + 1, j + 2, k + 16, VetheaBlockHelper.hallWall.blockID);
		world.setBlock(i + 1, j + 2, k + 19, VetheaBlockHelper.hallWall.blockID);
		world.setBlock(i + 1, j + 2, k + 20, VetheaBlockHelper.hallWall.blockID);
		world.setBlock(i + 1, j + 2, k + 21, VetheaBlockHelper.hallWall.blockID);
		world.setBlock(i + 1, j + 2, k + 22, VetheaBlockHelper.hallWall.blockID);
		world.setBlock(i + 1, j + 2, k + 23, VetheaBlockHelper.hallWall.blockID);
		world.setBlock(i + 1, j + 2, k + 24, VetheaBlockHelper.hallWall.blockID);
		world.setBlock(i + 1, j + 2, k + 25, VetheaBlockHelper.hallWall.blockID);
		world.setBlock(i + 1, j + 2, k + 26, VetheaBlockHelper.hallWall.blockID);
		world.setBlock(i + 1, j + 2, k + 27, VetheaBlockHelper.hallWall.blockID);
		world.setBlock(i + 1, j + 2, k + 28, VetheaBlockHelper.hallWall.blockID);
		world.setBlock(i + 1, j + 2, k + 29, VetheaBlockHelper.hallWall.blockID);
		world.setBlock(i + 1, j + 2, k + 30, VetheaBlockHelper.hallWall.blockID);
		world.setBlock(i + 1, j + 2, k + 31, VetheaBlockHelper.hallWall.blockID);
		world.setBlock(i + 1, j + 2, k + 32, VetheaBlockHelper.hallWall.blockID);
		world.setBlock(i + 1, j + 2, k + 33, VetheaBlockHelper.hallWall.blockID);
		world.setBlock(i + 1, j + 2, k + 34, VetheaBlockHelper.hallWall.blockID);
		world.setBlock(i + 1, j + 2, k + 35, VetheaBlockHelper.hallWall.blockID);
		world.setBlock(i + 1, j + 2, k + 36, VetheaBlockHelper.hallWall.blockID);
		world.setBlock(i + 1, j + 3, k + 16, VetheaBlockHelper.hallWall.blockID);
		world.setBlock(i + 1, j + 3, k + 17, VetheaBlockHelper.hallWall.blockID);
		world.setBlock(i + 1, j + 3, k + 18, VetheaBlockHelper.hallWall.blockID);
		world.setBlock(i + 1, j + 3, k + 19, VetheaBlockHelper.hallWall.blockID);
		world.setBlock(i + 1, j + 3, k + 20, VetheaBlockHelper.hallWall.blockID);
		world.setBlock(i + 1, j + 3, k + 21, VetheaBlockHelper.hallWall.blockID);
		world.setBlock(i + 1, j + 3, k + 22, VetheaBlockHelper.hallWall.blockID);
		world.setBlock(i + 1, j + 3, k + 23, VetheaBlockHelper.hallWall.blockID);
		world.setBlock(i + 1, j + 3, k + 24, VetheaBlockHelper.hallWall.blockID);
		world.setBlock(i + 1, j + 3, k + 25, VetheaBlockHelper.hallWall.blockID);
		world.setBlock(i + 1, j + 3, k + 26, VetheaBlockHelper.hallWall.blockID);
		world.setBlock(i + 1, j + 3, k + 27, VetheaBlockHelper.hallWall.blockID);
		world.setBlock(i + 1, j + 3, k + 28, VetheaBlockHelper.hallWall.blockID);
		world.setBlock(i + 1, j + 3, k + 29, VetheaBlockHelper.hallWall.blockID);
		world.setBlock(i + 1, j + 3, k + 30, VetheaBlockHelper.hallWall.blockID);
		world.setBlock(i + 1, j + 3, k + 31, VetheaBlockHelper.hallWall.blockID);
		world.setBlock(i + 1, j + 3, k + 32, VetheaBlockHelper.hallWall.blockID);
		world.setBlock(i + 1, j + 3, k + 33, VetheaBlockHelper.hallWall.blockID);
		world.setBlock(i + 1, j + 3, k + 34, VetheaBlockHelper.hallWall.blockID);
		world.setBlock(i + 1, j + 3, k + 35, VetheaBlockHelper.hallWall.blockID);
		world.setBlock(i + 1, j + 3, k + 36, VetheaBlockHelper.hallWall.blockID);
		world.setBlock(i + 1, j + 4, k + 3, VetheaBlockHelper.darkEverstone.blockID);
		world.setBlock(i + 1, j + 4, k + 7, VetheaBlockHelper.darkEverstone.blockID);
		world.setBlock(i + 1, j + 4, k + 9, VetheaBlockHelper.darkEverstone.blockID);
		world.setBlock(i + 1, j + 4, k + 13, VetheaBlockHelper.darkEverstone.blockID);
		world.setBlock(i + 1, j + 4, k + 35, VetheaBlockHelper.darkEverstone.blockID);
		world.setBlock(i + 1, j + 5, k + 3, VetheaBlockHelper.darkEverstone.blockID);
		world.setBlock(i + 1, j + 5, k + 7, VetheaBlockHelper.darkEverstone.blockID);
		world.setBlock(i + 1, j + 5, k + 9, VetheaBlockHelper.darkEverstone.blockID);
		world.setBlock(i + 1, j + 5, k + 13, VetheaBlockHelper.darkEverstone.blockID);
		world.setBlock(i + 1, j + 6, k + 3, VetheaBlockHelper.darkEverstone.blockID);
		world.setBlock(i + 1, j + 6, k + 7, VetheaBlockHelper.darkEverstone.blockID);
		world.setBlock(i + 1, j + 6, k + 9, VetheaBlockHelper.darkEverstone.blockID);
		world.setBlock(i + 1, j + 6, k + 13, VetheaBlockHelper.darkEverstone.blockID);
		world.setBlock(i + 1, j + 7, k + 2, VetheaBlockHelper.hallWall.blockID);
		world.setBlock(i + 1, j + 7, k + 3, VetheaBlockHelper.hallWall.blockID);
		world.setBlock(i + 1, j + 7, k + 4, VetheaBlockHelper.hallWall.blockID);
		world.setBlock(i + 1, j + 7, k + 5, VetheaBlockHelper.hallWall.blockID);
		world.setBlock(i + 1, j + 7, k + 6, VetheaBlockHelper.hallWall.blockID);
		world.setBlock(i + 1, j + 7, k + 7, VetheaBlockHelper.hallWall.blockID);
		world.setBlock(i + 1, j + 7, k + 8, VetheaBlockHelper.hallWall.blockID);
		world.setBlock(i + 1, j + 7, k + 9, VetheaBlockHelper.hallWall.blockID);
		world.setBlock(i + 1, j + 7, k + 10, VetheaBlockHelper.hallWall.blockID);
		world.setBlock(i + 1, j + 7, k + 11, VetheaBlockHelper.hallWall.blockID);
		world.setBlock(i + 1, j + 7, k + 12, VetheaBlockHelper.hallWall.blockID);
		world.setBlock(i + 1, j + 7, k + 13, VetheaBlockHelper.hallWall.blockID);
		world.setBlock(i + 1, j + 7, k + 14, VetheaBlockHelper.hallWall.blockID);
		world.setBlock(i + 2, j + 0, k + 3, VetheaBlockHelper.darkEverstone.blockID);
		world.setBlock(i + 2, j + 0, k + 7, VetheaBlockHelper.darkEverstone.blockID);
		world.setBlock(i + 2, j + 0, k + 9, VetheaBlockHelper.darkEverstone.blockID);
		world.setBlock(i + 2, j + 0, k + 13, VetheaBlockHelper.darkEverstone.blockID);
		world.setBlock(i + 2, j + 0, k + 16, VetheaBlockHelper.hallWall.blockID);
		world.setBlock(i + 2, j + 0, k + 17, VetheaBlockHelper.firecrystal.blockID);
		world.setBlock(i + 2, j + 0, k + 18, VetheaBlockHelper.firecrystal.blockID);
		world.setBlock(i + 2, j + 0, k + 19, VetheaBlockHelper.firecrystal.blockID);
		world.setBlock(i + 2, j + 0, k + 20, VetheaBlockHelper.firecrystal.blockID);
		world.setBlock(i + 2, j + 0, k + 21, VetheaBlockHelper.firecrystal.blockID);
		world.setBlock(i + 2, j + 0, k + 22, VetheaBlockHelper.firecrystal.blockID);
		world.setBlock(i + 2, j + 0, k + 23, VetheaBlockHelper.firecrystal.blockID);
		world.setBlock(i + 2, j + 0, k + 24, VetheaBlockHelper.firecrystal.blockID);
		world.setBlock(i + 2, j + 0, k + 25, VetheaBlockHelper.firecrystal.blockID);
		world.setBlock(i + 2, j + 0, k + 26, VetheaBlockHelper.firecrystal.blockID);
		world.setBlock(i + 2, j + 0, k + 27, VetheaBlockHelper.firecrystal.blockID);
		world.setBlock(i + 2, j + 0, k + 28, VetheaBlockHelper.firecrystal.blockID);
		world.setBlock(i + 2, j + 0, k + 29, VetheaBlockHelper.firecrystal.blockID);
		world.setBlock(i + 2, j + 0, k + 30, VetheaBlockHelper.firecrystal.blockID);
		world.setBlock(i + 2, j + 0, k + 31, VetheaBlockHelper.firecrystal.blockID);
		world.setBlock(i + 2, j + 0, k + 32, VetheaBlockHelper.firecrystal.blockID);
		world.setBlock(i + 2, j + 0, k + 33, VetheaBlockHelper.firecrystal.blockID);
		world.setBlock(i + 2, j + 0, k + 34, VetheaBlockHelper.firecrystal.blockID);
		world.setBlock(i + 2, j + 0, k + 35, VetheaBlockHelper.firecrystal.blockID);
		world.setBlock(i + 2, j + 0, k + 36, VetheaBlockHelper.hallWall.blockID);
		world.setBlock(i + 2, j + 0, k + 37, VetheaBlockHelper.darkEverstone.blockID);
		world.setBlock(i + 2, j + 1, k + 3, VetheaBlockHelper.darkEverstone.blockID);
		world.setBlock(i + 2, j + 1, k + 7, VetheaBlockHelper.darkEverstone.blockID);
		world.setBlock(i + 2, j + 1, k + 9, VetheaBlockHelper.darkEverstone.blockID);
		world.setBlock(i + 2, j + 1, k + 13, VetheaBlockHelper.darkEverstone.blockID);
		world.setBlock(i + 2, j + 1, k + 16, VetheaBlockHelper.hallWall.blockID);
		world.setBlock(i + 2, j + 1, k + 36, VetheaBlockHelper.hallWall.blockID);
		world.setBlock(i + 2, j + 1, k + 37, VetheaBlockHelper.darkEverstone.blockID);
		world.setBlock(i + 2, j + 2, k + 3, VetheaBlockHelper.darkEverstone.blockID);
		world.setBlock(i + 2, j + 2, k + 7, VetheaBlockHelper.darkEverstone.blockID);
		world.setBlock(i + 2, j + 2, k + 9, VetheaBlockHelper.darkEverstone.blockID);
		world.setBlock(i + 2, j + 2, k + 13, VetheaBlockHelper.darkEverstone.blockID);
		world.setBlock(i + 2, j + 2, k + 16, VetheaBlockHelper.hallWall.blockID);
		world.setBlock(i + 2, j + 2, k + 36, VetheaBlockHelper.hallWall.blockID);
		world.setBlock(i + 2, j + 2, k + 37, VetheaBlockHelper.darkEverstone.blockID);
		world.setBlock(i + 2, j + 3, k + 3, VetheaBlockHelper.darkEverstone.blockID);
		world.setBlock(i + 2, j + 3, k + 7, VetheaBlockHelper.darkEverstone.blockID);
		world.setBlock(i + 2, j + 3, k + 9, VetheaBlockHelper.darkEverstone.blockID);
		world.setBlock(i + 2, j + 3, k + 13, VetheaBlockHelper.darkEverstone.blockID);
		world.setBlock(i + 2, j + 3, k + 16, VetheaBlockHelper.hallWall.blockID);
		world.setBlock(i + 2, j + 3, k + 17, VetheaBlockHelper.hallWall.blockID);
		world.setBlock(i + 2, j + 3, k + 18, VetheaBlockHelper.hallWall.blockID);
		world.setBlock(i + 2, j + 3, k + 19, VetheaBlockHelper.hallWall.blockID);
		world.setBlock(i + 2, j + 3, k + 20, VetheaBlockHelper.hallWall.blockID);
		world.setBlock(i + 2, j + 3, k + 21, VetheaBlockHelper.hallWall.blockID);
		world.setBlock(i + 2, j + 3, k + 22, VetheaBlockHelper.hallWall.blockID);
		world.setBlock(i + 2, j + 3, k + 23, VetheaBlockHelper.hallWall.blockID);
		world.setBlock(i + 2, j + 3, k + 24, VetheaBlockHelper.hallWall.blockID);
		world.setBlock(i + 2, j + 3, k + 25, VetheaBlockHelper.hallWall.blockID);
		world.setBlock(i + 2, j + 3, k + 26, VetheaBlockHelper.hallWall.blockID);
		world.setBlock(i + 2, j + 3, k + 27, VetheaBlockHelper.hallWall.blockID);
		world.setBlock(i + 2, j + 3, k + 28, VetheaBlockHelper.hallWall.blockID);
		world.setBlock(i + 2, j + 3, k + 29, VetheaBlockHelper.hallWall.blockID);
		world.setBlock(i + 2, j + 3, k + 30, VetheaBlockHelper.hallWall.blockID);
		world.setBlock(i + 2, j + 3, k + 31, VetheaBlockHelper.hallWall.blockID);
		world.setBlock(i + 2, j + 3, k + 32, VetheaBlockHelper.hallWall.blockID);
		world.setBlock(i + 2, j + 3, k + 33, VetheaBlockHelper.hallWall.blockID);
		world.setBlock(i + 2, j + 3, k + 34, VetheaBlockHelper.hallWall.blockID);
		world.setBlock(i + 2, j + 3, k + 35, VetheaBlockHelper.hallWall.blockID);
		world.setBlock(i + 2, j + 3, k + 36, VetheaBlockHelper.hallWall.blockID);
		world.setBlock(i + 2, j + 3, k + 37, VetheaBlockHelper.darkEverstone.blockID);
		world.setBlock(i + 2, j + 4, k + 3, VetheaBlockHelper.darkEverstone.blockID);
		world.setBlock(i + 2, j + 4, k + 7, VetheaBlockHelper.darkEverstone.blockID);
		world.setBlock(i + 2, j + 4, k + 9, VetheaBlockHelper.darkEverstone.blockID);
		world.setBlock(i + 2, j + 4, k + 13, VetheaBlockHelper.darkEverstone.blockID);
		world.setBlock(i + 2, j + 4, k + 17, VetheaBlockHelper.darkEverstone.blockID);
		world.setBlock(i + 2, j + 4, k + 20, VetheaBlockHelper.darkEverstone.blockID);
		world.setBlock(i + 2, j + 4, k + 23, VetheaBlockHelper.darkEverstone.blockID);
		world.setBlock(i + 2, j + 4, k + 27, VetheaBlockHelper.darkEverstone.blockID);
		world.setBlock(i + 2, j + 4, k + 30, VetheaBlockHelper.darkEverstone.blockID);
		world.setBlock(i + 2, j + 4, k + 33, VetheaBlockHelper.darkEverstone.blockID);
		world.setBlock(i + 2, j + 4, k + 35, VetheaBlockHelper.darkEverstone.blockID);
		world.setBlock(i + 2, j + 4, k + 36, VetheaBlockHelper.darkEverstone.blockID);
		world.setBlock(i + 2, j + 4, k + 37, VetheaBlockHelper.darkEverstone.blockID);
		world.setBlock(i + 2, j + 5, k + 1, VetheaBlockHelper.hallWall.blockID);
		world.setBlock(i + 2, j + 5, k + 2, VetheaBlockHelper.hallWall.blockID);
		world.setBlock(i + 2, j + 5, k + 3, VetheaBlockHelper.hallWall.blockID);
		world.setBlock(i + 2, j + 5, k + 4, VetheaBlockHelper.hallWall.blockID);
		world.setBlock(i + 2, j + 5, k + 5, VetheaBlockHelper.hallWall.blockID);
		world.setBlock(i + 2, j + 5, k + 6, VetheaBlockHelper.hallWall.blockID);
		world.setBlock(i + 2, j + 5, k + 7, VetheaBlockHelper.hallWall.blockID);
		world.setBlock(i + 2, j + 5, k + 8, VetheaBlockHelper.hallWall.blockID);
		world.setBlock(i + 2, j + 5, k + 9, VetheaBlockHelper.hallWall.blockID);
		world.setBlock(i + 2, j + 5, k + 10, VetheaBlockHelper.hallWall.blockID);
		world.setBlock(i + 2, j + 5, k + 11, VetheaBlockHelper.hallWall.blockID);
		world.setBlock(i + 2, j + 5, k + 12, VetheaBlockHelper.hallWall.blockID);
		world.setBlock(i + 2, j + 5, k + 13, VetheaBlockHelper.hallWall.blockID);
		world.setBlock(i + 2, j + 5, k + 14, VetheaBlockHelper.hallWall.blockID);
		world.setBlock(i + 2, j + 5, k + 15, VetheaBlockHelper.hallWall.blockID);
		world.setBlock(i + 2, j + 5, k + 17, VetheaBlockHelper.darkEverstone.blockID);
		world.setBlock(i + 2, j + 5, k + 20, VetheaBlockHelper.darkEverstone.blockID);
		world.setBlock(i + 2, j + 5, k + 23, VetheaBlockHelper.darkEverstone.blockID);
		world.setBlock(i + 2, j + 5, k + 27, VetheaBlockHelper.darkEverstone.blockID);
		world.setBlock(i + 2, j + 5, k + 30, VetheaBlockHelper.darkEverstone.blockID);
		world.setBlock(i + 2, j + 5, k + 33, VetheaBlockHelper.darkEverstone.blockID);
		world.setBlock(i + 2, j + 6, k + 1, VetheaBlockHelper.hallWall.blockID);
		world.setBlock(i + 2, j + 6, k + 2, VetheaBlockHelper.hallWall.blockID);
		world.setBlock(i + 2, j + 6, k + 3, VetheaBlockHelper.hallWall.blockID);
		world.setBlock(i + 2, j + 6, k + 4, VetheaBlockHelper.hallWall.blockID);
		world.setBlock(i + 2, j + 6, k + 5, VetheaBlockHelper.hallWall.blockID);
		world.setBlock(i + 2, j + 6, k + 6, VetheaBlockHelper.hallWall.blockID);
		world.setBlock(i + 2, j + 6, k + 7, VetheaBlockHelper.hallWall.blockID);
		world.setBlock(i + 2, j + 6, k + 8, VetheaBlockHelper.hallWall.blockID);
		world.setBlock(i + 2, j + 6, k + 9, VetheaBlockHelper.hallWall.blockID);
		world.setBlock(i + 2, j + 6, k + 10, VetheaBlockHelper.hallWall.blockID);
		world.setBlock(i + 2, j + 6, k + 11, VetheaBlockHelper.hallWall.blockID);
		world.setBlock(i + 2, j + 6, k + 12, VetheaBlockHelper.hallWall.blockID);
		world.setBlock(i + 2, j + 6, k + 13, VetheaBlockHelper.hallWall.blockID);
		world.setBlock(i + 2, j + 6, k + 14, VetheaBlockHelper.hallWall.blockID);
		world.setBlock(i + 2, j + 6, k + 15, VetheaBlockHelper.hallWall.blockID);
		world.setBlock(i + 2, j + 6, k + 17, VetheaBlockHelper.darkEverstone.blockID);
		world.setBlock(i + 2, j + 6, k + 20, VetheaBlockHelper.darkEverstone.blockID);
		world.setBlock(i + 2, j + 6, k + 23, VetheaBlockHelper.darkEverstone.blockID);
		world.setBlock(i + 2, j + 6, k + 27, VetheaBlockHelper.darkEverstone.blockID);
		world.setBlock(i + 2, j + 6, k + 30, VetheaBlockHelper.darkEverstone.blockID);
		world.setBlock(i + 2, j + 6, k + 33, VetheaBlockHelper.darkEverstone.blockID);
		world.setBlock(i + 2, j + 7, k + 1, VetheaBlockHelper.hallWall.blockID);
		world.setBlock(i + 2, j + 7, k + 2, VetheaBlockHelper.darkEverstone.blockID);
		world.setBlock(i + 2, j + 7, k + 3, VetheaBlockHelper.darkEverstone.blockID);
		world.setBlock(i + 2, j + 7, k + 4, VetheaBlockHelper.darkEverstone.blockID);
		world.setBlock(i + 2, j + 7, k + 5, VetheaBlockHelper.darkEverstone.blockID);
		world.setBlock(i + 2, j + 7, k + 6, VetheaBlockHelper.darkEverstone.blockID);
		world.setBlock(i + 2, j + 7, k + 7, VetheaBlockHelper.darkEverstone.blockID);
		world.setBlock(i + 2, j + 7, k + 8, VetheaBlockHelper.darkEverstone.blockID);
		world.setBlock(i + 2, j + 7, k + 9, VetheaBlockHelper.darkEverstone.blockID);
		world.setBlock(i + 2, j + 7, k + 10, VetheaBlockHelper.darkEverstone.blockID);
		world.setBlock(i + 2, j + 7, k + 11, VetheaBlockHelper.darkEverstone.blockID);
		world.setBlock(i + 2, j + 7, k + 12, VetheaBlockHelper.darkEverstone.blockID);
		world.setBlock(i + 2, j + 7, k + 13, VetheaBlockHelper.darkEverstone.blockID);
		world.setBlock(i + 2, j + 7, k + 14, VetheaBlockHelper.darkEverstone.blockID);
		world.setBlock(i + 2, j + 7, k + 15, VetheaBlockHelper.hallWall.blockID);
		world.setBlock(i + 2, j + 7, k + 17, VetheaBlockHelper.darkEverstone.blockID);
		world.setBlock(i + 2, j + 7, k + 20, VetheaBlockHelper.darkEverstone.blockID);
		world.setBlock(i + 2, j + 7, k + 23, VetheaBlockHelper.darkEverstone.blockID);
		world.setBlock(i + 2, j + 7, k + 27, VetheaBlockHelper.darkEverstone.blockID);
		world.setBlock(i + 2, j + 7, k + 30, VetheaBlockHelper.darkEverstone.blockID);
		world.setBlock(i + 2, j + 7, k + 33, VetheaBlockHelper.darkEverstone.blockID);
		world.setBlock(i + 2, j + 8, k + 1, VetheaBlockHelper.hallWall.blockID);
		world.setBlock(i + 2, j + 8, k + 2, VetheaBlockHelper.hallWall.blockID);
		world.setBlock(i + 2, j + 8, k + 3, VetheaBlockHelper.hallWall.blockID);
		world.setBlock(i + 2, j + 8, k + 4, VetheaBlockHelper.hallWall.blockID);
		world.setBlock(i + 2, j + 8, k + 5, VetheaBlockHelper.hallWall.blockID);
		world.setBlock(i + 2, j + 8, k + 6, VetheaBlockHelper.hallWall.blockID);
		world.setBlock(i + 2, j + 8, k + 7, VetheaBlockHelper.hallWall.blockID);
		world.setBlock(i + 2, j + 8, k + 8, VetheaBlockHelper.hallWall.blockID);
		world.setBlock(i + 2, j + 8, k + 9, VetheaBlockHelper.hallWall.blockID);
		world.setBlock(i + 2, j + 8, k + 10, VetheaBlockHelper.hallWall.blockID);
		world.setBlock(i + 2, j + 8, k + 11, VetheaBlockHelper.hallWall.blockID);
		world.setBlock(i + 2, j + 8, k + 12, VetheaBlockHelper.hallWall.blockID);
		world.setBlock(i + 2, j + 8, k + 13, VetheaBlockHelper.hallWall.blockID);
		world.setBlock(i + 2, j + 8, k + 14, VetheaBlockHelper.hallWall.blockID);
		world.setBlock(i + 2, j + 8, k + 15, VetheaBlockHelper.hallWall.blockID);
		world.setBlock(i + 2, j + 8, k + 17, VetheaBlockHelper.darkEverstone.blockID);
		world.setBlock(i + 2, j + 8, k + 20, VetheaBlockHelper.darkEverstone.blockID);
		world.setBlock(i + 2, j + 8, k + 23, VetheaBlockHelper.darkEverstone.blockID);
		world.setBlock(i + 2, j + 8, k + 27, VetheaBlockHelper.darkEverstone.blockID);
		world.setBlock(i + 2, j + 8, k + 30, VetheaBlockHelper.darkEverstone.blockID);
		world.setBlock(i + 2, j + 8, k + 33, VetheaBlockHelper.darkEverstone.blockID);
		world.setBlock(i + 2, j + 9, k + 17, VetheaBlockHelper.darkEverstone.blockID);
		world.setBlock(i + 2, j + 9, k + 20, VetheaBlockHelper.darkEverstone.blockID);
		world.setBlock(i + 2, j + 9, k + 23, VetheaBlockHelper.darkEverstone.blockID);
		world.setBlock(i + 2, j + 9, k + 27, VetheaBlockHelper.darkEverstone.blockID);
		world.setBlock(i + 2, j + 9, k + 30, VetheaBlockHelper.darkEverstone.blockID);
		world.setBlock(i + 2, j + 9, k + 33, VetheaBlockHelper.darkEverstone.blockID);
		world.setBlock(i + 3, j + 0, k + 2, VetheaBlockHelper.hallWall.blockID);
		world.setBlock(i + 3, j + 0, k + 3, VetheaBlockHelper.hallWall.blockID);
		world.setBlock(i + 3, j + 0, k + 4, VetheaBlockHelper.hallWall.blockID);
		world.setBlock(i + 3, j + 0, k + 5, VetheaBlockHelper.hallWall.blockID);
		world.setBlock(i + 3, j + 0, k + 6, VetheaBlockHelper.hallWall.blockID);
		world.setBlock(i + 3, j + 0, k + 7, VetheaBlockHelper.hallWall.blockID);
		world.setBlock(i + 3, j + 0, k + 8, VetheaBlockHelper.hallWall.blockID);
		world.setBlock(i + 3, j + 0, k + 9, VetheaBlockHelper.hallWall.blockID);
		world.setBlock(i + 3, j + 0, k + 10, VetheaBlockHelper.hallWall.blockID);
		world.setBlock(i + 3, j + 0, k + 11, VetheaBlockHelper.hallWall.blockID);
		world.setBlock(i + 3, j + 0, k + 12, VetheaBlockHelper.hallWall.blockID);
		world.setBlock(i + 3, j + 0, k + 13, VetheaBlockHelper.hallWall.blockID);
		world.setBlock(i + 3, j + 0, k + 14, VetheaBlockHelper.hallWall.blockID);
		world.setBlock(i + 3, j + 0, k + 15, VetheaBlockHelper.hallWall.blockID);
		world.setBlock(i + 3, j + 0, k + 16, VetheaBlockHelper.hallWall.blockID);
		world.setBlock(i + 3, j + 0, k + 17, VetheaBlockHelper.firecrystal.blockID);
		world.setBlock(i + 3, j + 0, k + 18, VetheaBlockHelper.firecrystal.blockID);
		world.setBlock(i + 3, j + 0, k + 19, VetheaBlockHelper.firecrystal.blockID);
		world.setBlock(i + 3, j + 0, k + 20, VetheaBlockHelper.firecrystal.blockID);
		world.setBlock(i + 3, j + 0, k + 21, VetheaBlockHelper.firecrystal.blockID);
		world.setBlock(i + 3, j + 0, k + 22, VetheaBlockHelper.firecrystal.blockID);
		world.setBlock(i + 3, j + 0, k + 23, VetheaBlockHelper.firecrystal.blockID);
		world.setBlock(i + 3, j + 0, k + 24, VetheaBlockHelper.firecrystal.blockID);
		world.setBlock(i + 3, j + 0, k + 25, VetheaBlockHelper.firecrystal.blockID);
		world.setBlock(i + 3, j + 0, k + 26, VetheaBlockHelper.firecrystal.blockID);
		world.setBlock(i + 3, j + 0, k + 27, VetheaBlockHelper.firecrystal.blockID);
		world.setBlock(i + 3, j + 0, k + 28, VetheaBlockHelper.firecrystal.blockID);
		world.setBlock(i + 3, j + 0, k + 29, VetheaBlockHelper.firecrystal.blockID);
		world.setBlock(i + 3, j + 0, k + 30, VetheaBlockHelper.firecrystal.blockID);
		world.setBlock(i + 3, j + 0, k + 31, VetheaBlockHelper.firecrystal.blockID);
		world.setBlock(i + 3, j + 0, k + 32, VetheaBlockHelper.firecrystal.blockID);
		world.setBlock(i + 3, j + 0, k + 33, VetheaBlockHelper.firecrystal.blockID);
		world.setBlock(i + 3, j + 0, k + 34, VetheaBlockHelper.firecrystal.blockID);
		world.setBlock(i + 3, j + 0, k + 35, VetheaBlockHelper.firecrystal.blockID);
		world.setBlock(i + 3, j + 0, k + 36, VetheaBlockHelper.hallWall.blockID);
		world.setBlock(i + 3, j + 1, k + 2, VetheaBlockHelper.hallWall.blockID);
		world.setBlock(i + 3, j + 1, k + 3, VetheaBlockHelper.hallWall.blockID);
		world.setBlock(i + 3, j + 1, k + 4, VetheaBlockHelper.hallWall.blockID);
		world.setBlock(i + 3, j + 1, k + 5, VetheaBlockHelper.hallWall.blockID);
		world.setBlock(i + 3, j + 1, k + 6, VetheaBlockHelper.hallWall.blockID);
		world.setBlock(i + 3, j + 1, k + 7, VetheaBlockHelper.hallWall.blockID);
		world.setBlock(i + 3, j + 1, k + 8, VetheaBlockHelper.hallWall.blockID);
		world.setBlock(i + 3, j + 1, k + 9, VetheaBlockHelper.hallWall.blockID);
		world.setBlock(i + 3, j + 1, k + 10, VetheaBlockHelper.hallWall.blockID);
		world.setBlock(i + 3, j + 1, k + 11, VetheaBlockHelper.hallWall.blockID);
		world.setBlock(i + 3, j + 1, k + 12, VetheaBlockHelper.hallWall.blockID);
		world.setBlock(i + 3, j + 1, k + 13, VetheaBlockHelper.hallWall.blockID);
		world.setBlock(i + 3, j + 1, k + 14, VetheaBlockHelper.hallWall.blockID);
		world.setBlock(i + 3, j + 1, k + 15, VetheaBlockHelper.hallWall.blockID);
		world.setBlock(i + 3, j + 1, k + 16, VetheaBlockHelper.hallWall.blockID);
		world.setBlock(i + 3, j + 1, k + 36, VetheaBlockHelper.hallWall.blockID);
		world.setBlock(i + 3, j + 2, k + 2, VetheaBlockHelper.hallWall.blockID);
		world.setBlock(i + 3, j + 2, k + 3, VetheaBlockHelper.hallWall.blockID);
		world.setBlock(i + 3, j + 2, k + 4, VetheaBlockHelper.hallWall.blockID);
		world.setBlock(i + 3, j + 2, k + 5, VetheaBlockHelper.hallWall.blockID);
		world.setBlock(i + 3, j + 2, k + 6, VetheaBlockHelper.hallWall.blockID);
		world.setBlock(i + 3, j + 2, k + 7, VetheaBlockHelper.hallWall.blockID);
		world.setBlock(i + 3, j + 2, k + 8, VetheaBlockHelper.hallWall.blockID);
		world.setBlock(i + 3, j + 2, k + 9, VetheaBlockHelper.hallWall.blockID);
		world.setBlock(i + 3, j + 2, k + 10, VetheaBlockHelper.hallWall.blockID);
		world.setBlock(i + 3, j + 2, k + 11, VetheaBlockHelper.hallWall.blockID);
		world.setBlock(i + 3, j + 2, k + 12, VetheaBlockHelper.hallWall.blockID);
		world.setBlock(i + 3, j + 2, k + 13, VetheaBlockHelper.hallWall.blockID);
		world.setBlock(i + 3, j + 2, k + 14, VetheaBlockHelper.hallWall.blockID);
		world.setBlock(i + 3, j + 2, k + 15, VetheaBlockHelper.hallWall.blockID);
		world.setBlock(i + 3, j + 2, k + 16, VetheaBlockHelper.hallWall.blockID);
		world.setBlock(i + 3, j + 2, k + 36, VetheaBlockHelper.hallWall.blockID);
		world.setBlock(i + 3, j + 3, k + 2, VetheaBlockHelper.hallWall.blockID);
		world.setBlock(i + 3, j + 3, k + 3, VetheaBlockHelper.hallWall.blockID);
		world.setBlock(i + 3, j + 3, k + 4, VetheaBlockHelper.hallWall.blockID);
		world.setBlock(i + 3, j + 3, k + 5, VetheaBlockHelper.hallWall.blockID);
		world.setBlock(i + 3, j + 3, k + 6, VetheaBlockHelper.hallWall.blockID);
		world.setBlock(i + 3, j + 3, k + 7, VetheaBlockHelper.hallWall.blockID);
		world.setBlock(i + 3, j + 3, k + 8, VetheaBlockHelper.hallWall.blockID);
		world.setBlock(i + 3, j + 3, k + 9, VetheaBlockHelper.hallWall.blockID);
		world.setBlock(i + 3, j + 3, k + 10, VetheaBlockHelper.hallWall.blockID);
		world.setBlock(i + 3, j + 3, k + 11, VetheaBlockHelper.hallWall.blockID);
		world.setBlock(i + 3, j + 3, k + 12, VetheaBlockHelper.hallWall.blockID);
		world.setBlock(i + 3, j + 3, k + 13, VetheaBlockHelper.hallWall.blockID);
		world.setBlock(i + 3, j + 3, k + 14, VetheaBlockHelper.hallWall.blockID);
		world.setBlock(i + 3, j + 3, k + 15, VetheaBlockHelper.hallWall.blockID);
		world.setBlock(i + 3, j + 3, k + 16, VetheaBlockHelper.hallWall.blockID);
		world.setBlock(i + 3, j + 3, k + 17, VetheaBlockHelper.hallWall.blockID);
		world.setBlock(i + 3, j + 3, k + 18, VetheaBlockHelper.hallWall.blockID);
		world.setBlock(i + 3, j + 3, k + 19, VetheaBlockHelper.hallWall.blockID);
		world.setBlock(i + 3, j + 3, k + 20, VetheaBlockHelper.hallWall.blockID);
		world.setBlock(i + 3, j + 3, k + 21, VetheaBlockHelper.hallWall.blockID);
		world.setBlock(i + 3, j + 3, k + 22, VetheaBlockHelper.hallWall.blockID);
		world.setBlock(i + 3, j + 3, k + 23, VetheaBlockHelper.hallWall.blockID);
		world.setBlock(i + 3, j + 3, k + 24, VetheaBlockHelper.hallWall.blockID);
		world.setBlock(i + 3, j + 3, k + 25, VetheaBlockHelper.hallWall.blockID);
		world.setBlock(i + 3, j + 3, k + 26, VetheaBlockHelper.hallWall.blockID);
		world.setBlock(i + 3, j + 3, k + 27, VetheaBlockHelper.hallWall.blockID);
		world.setBlock(i + 3, j + 3, k + 28, VetheaBlockHelper.hallWall.blockID);
		world.setBlock(i + 3, j + 3, k + 29, VetheaBlockHelper.hallWall.blockID);
		world.setBlock(i + 3, j + 3, k + 30, VetheaBlockHelper.hallWall.blockID);
		world.setBlock(i + 3, j + 3, k + 31, VetheaBlockHelper.hallWall.blockID);
		world.setBlock(i + 3, j + 3, k + 32, VetheaBlockHelper.hallWall.blockID);
		world.setBlock(i + 3, j + 3, k + 33, VetheaBlockHelper.hallWall.blockID);
		world.setBlock(i + 3, j + 3, k + 34, VetheaBlockHelper.hallWall.blockID);
		world.setBlock(i + 3, j + 3, k + 35, VetheaBlockHelper.hallWall.blockID);
		world.setBlock(i + 3, j + 3, k + 36, VetheaBlockHelper.hallWall.blockID);
		world.setBlock(i + 3, j + 4, k + 2, VetheaBlockHelper.hallWall.blockID);
		world.setBlock(i + 3, j + 4, k + 3, VetheaBlockHelper.hallWall.blockID);
		world.setBlock(i + 3, j + 4, k + 4, VetheaBlockHelper.hallWall.blockID);
		world.setBlock(i + 3, j + 4, k + 5, VetheaBlockHelper.hallWall.blockID);
		world.setBlock(i + 3, j + 4, k + 6, VetheaBlockHelper.hallWall.blockID);
		world.setBlock(i + 3, j + 4, k + 7, VetheaBlockHelper.hallWall.blockID);
		world.setBlock(i + 3, j + 4, k + 8, VetheaBlockHelper.hallWall.blockID);
		world.setBlock(i + 3, j + 4, k + 9, VetheaBlockHelper.hallWall.blockID);
		world.setBlock(i + 3, j + 4, k + 10, VetheaBlockHelper.hallWall.blockID);
		world.setBlock(i + 3, j + 4, k + 11, VetheaBlockHelper.hallWall.blockID);
		world.setBlock(i + 3, j + 4, k + 12, VetheaBlockHelper.hallWall.blockID);
		world.setBlock(i + 3, j + 4, k + 13, VetheaBlockHelper.hallWall.blockID);
		world.setBlock(i + 3, j + 4, k + 14, VetheaBlockHelper.hallWall.blockID);
		world.setBlock(i + 3, j + 4, k + 15, VetheaBlockHelper.hallWall.blockID);
		world.setBlock(i + 3, j + 4, k + 16, VetheaBlockHelper.hallWall.blockID);
		world.setBlock(i + 3, j + 4, k + 17, VetheaBlockHelper.hallWall.blockID);
		world.setBlock(i + 3, j + 4, k + 18, VetheaBlockHelper.hallWall.blockID);
		world.setBlock(i + 3, j + 4, k + 19, VetheaBlockHelper.hallWall.blockID);
		world.setBlock(i + 3, j + 4, k + 20, VetheaBlockHelper.hallWall.blockID);
		world.setBlock(i + 3, j + 4, k + 21, VetheaBlockHelper.hallWall.blockID);
		world.setBlock(i + 3, j + 4, k + 22, VetheaBlockHelper.hallWall.blockID);
		world.setBlock(i + 3, j + 4, k + 23, VetheaBlockHelper.hallWall.blockID);
		world.setBlock(i + 3, j + 4, k + 24, VetheaBlockHelper.hallWall.blockID);
		world.setBlock(i + 3, j + 4, k + 25, VetheaBlockHelper.hallWall.blockID);
		world.setBlock(i + 3, j + 4, k + 26, VetheaBlockHelper.hallWall.blockID);
		world.setBlock(i + 3, j + 4, k + 27, VetheaBlockHelper.hallWall.blockID);
		world.setBlock(i + 3, j + 4, k + 28, VetheaBlockHelper.hallWall.blockID);
		world.setBlock(i + 3, j + 4, k + 29, VetheaBlockHelper.hallWall.blockID);
		world.setBlock(i + 3, j + 4, k + 30, VetheaBlockHelper.hallWall.blockID);
		world.setBlock(i + 3, j + 4, k + 31, VetheaBlockHelper.hallWall.blockID);
		world.setBlock(i + 3, j + 4, k + 32, VetheaBlockHelper.hallWall.blockID);
		world.setBlock(i + 3, j + 4, k + 33, VetheaBlockHelper.hallWall.blockID);
		world.setBlock(i + 3, j + 4, k + 34, VetheaBlockHelper.hallWall.blockID);
		world.setBlock(i + 3, j + 4, k + 35, VetheaBlockHelper.hallWall.blockID);
		world.setBlock(i + 3, j + 5, k + 1, VetheaBlockHelper.hallWall.blockID);
		world.setBlock(i + 3, j + 5, k + 2, VetheaBlockHelper.firecrystal.blockID);
		world.setBlock(i + 3, j + 5, k + 3, VetheaBlockHelper.firecrystal.blockID);
		world.setBlock(i + 3, j + 5, k + 4, VetheaBlockHelper.firecrystal.blockID);
		world.setBlock(i + 3, j + 5, k + 5, VetheaBlockHelper.firecrystal.blockID);
		world.setBlock(i + 3, j + 5, k + 6, VetheaBlockHelper.firecrystal.blockID);
		world.setBlock(i + 3, j + 5, k + 7, VetheaBlockHelper.firecrystal.blockID);
		world.setBlock(i + 3, j + 5, k + 8, VetheaBlockHelper.firecrystal.blockID);
		world.setBlock(i + 3, j + 5, k + 9, VetheaBlockHelper.firecrystal.blockID);
		world.setBlock(i + 3, j + 5, k + 10, VetheaBlockHelper.firecrystal.blockID);
		world.setBlock(i + 3, j + 5, k + 11, VetheaBlockHelper.firecrystal.blockID);
		world.setBlock(i + 3, j + 5, k + 12, VetheaBlockHelper.firecrystal.blockID);
		world.setBlock(i + 3, j + 5, k + 13, VetheaBlockHelper.firecrystal.blockID);
		world.setBlock(i + 3, j + 5, k + 14, VetheaBlockHelper.firecrystal.blockID);
		world.setBlock(i + 3, j + 5, k + 15, VetheaBlockHelper.hallWall.blockID);
		world.setBlock(i + 3, j + 5, k + 16, VetheaBlockHelper.hallWall.blockID);
		world.setBlock(i + 3, j + 5, k + 17, VetheaBlockHelper.hallWall.blockID);
		world.setBlock(i + 3, j + 5, k + 18, VetheaBlockHelper.hallWall.blockID);
		world.setBlock(i + 3, j + 5, k + 19, VetheaBlockHelper.hallWall.blockID);
		world.setBlock(i + 3, j + 5, k + 20, VetheaBlockHelper.hallWall.blockID);
		world.setBlock(i + 3, j + 5, k + 21, VetheaBlockHelper.hallWall.blockID);
		world.setBlock(i + 3, j + 5, k + 22, VetheaBlockHelper.hallWall.blockID);
		world.setBlock(i + 3, j + 5, k + 23, VetheaBlockHelper.hallWall.blockID);
		world.setBlock(i + 3, j + 5, k + 24, VetheaBlockHelper.hallWall.blockID);
		world.setBlock(i + 3, j + 5, k + 25, VetheaBlockHelper.hallWall.blockID);
		world.setBlock(i + 3, j + 5, k + 26, VetheaBlockHelper.hallWall.blockID);
		world.setBlock(i + 3, j + 5, k + 27, VetheaBlockHelper.hallWall.blockID);
		world.setBlock(i + 3, j + 5, k + 28, VetheaBlockHelper.hallWall.blockID);
		world.setBlock(i + 3, j + 5, k + 29, VetheaBlockHelper.hallWall.blockID);
		world.setBlock(i + 3, j + 5, k + 30, VetheaBlockHelper.hallWall.blockID);
		world.setBlock(i + 3, j + 5, k + 31, VetheaBlockHelper.hallWall.blockID);
		world.setBlock(i + 3, j + 5, k + 32, VetheaBlockHelper.hallWall.blockID);
		world.setBlock(i + 3, j + 5, k + 33, VetheaBlockHelper.hallWall.blockID);
		world.setBlock(i + 3, j + 5, k + 34, VetheaBlockHelper.hallWall.blockID);
		world.setBlock(i + 3, j + 5, k + 35, VetheaBlockHelper.hallWall.blockID);
		world.setBlock(i + 3, j + 6, k + 1, VetheaBlockHelper.hallWall.blockID);
		world.setBlock(i + 3, j + 6, k + 15, VetheaBlockHelper.hallWall.blockID);
		world.setBlock(i + 3, j + 6, k + 16, VetheaBlockHelper.hallWall.blockID);
		world.setBlock(i + 3, j + 6, k + 17, VetheaBlockHelper.hallWall.blockID);
		world.setBlock(i + 3, j + 6, k + 18, VetheaBlockHelper.hallWall.blockID);
		world.setBlock(i + 3, j + 6, k + 19, VetheaBlockHelper.hallWall.blockID);
		world.setBlock(i + 3, j + 6, k + 20, VetheaBlockHelper.hallWall.blockID);
		world.setBlock(i + 3, j + 6, k + 21, VetheaBlockHelper.hallWall.blockID);
		world.setBlock(i + 3, j + 6, k + 22, VetheaBlockHelper.hallWall.blockID);
		world.setBlock(i + 3, j + 6, k + 23, VetheaBlockHelper.hallWall.blockID);
		world.setBlock(i + 3, j + 6, k + 24, VetheaBlockHelper.hallWall.blockID);
		world.setBlock(i + 3, j + 6, k + 25, VetheaBlockHelper.hallWall.blockID);
		world.setBlock(i + 3, j + 6, k + 26, VetheaBlockHelper.hallWall.blockID);
		world.setBlock(i + 3, j + 6, k + 27, VetheaBlockHelper.hallWall.blockID);
		world.setBlock(i + 3, j + 6, k + 28, VetheaBlockHelper.hallWall.blockID);
		world.setBlock(i + 3, j + 6, k + 29, VetheaBlockHelper.hallWall.blockID);
		world.setBlock(i + 3, j + 6, k + 30, VetheaBlockHelper.hallWall.blockID);
		world.setBlock(i + 3, j + 6, k + 31, VetheaBlockHelper.hallWall.blockID);
		world.setBlock(i + 3, j + 6, k + 32, VetheaBlockHelper.hallWall.blockID);
		world.setBlock(i + 3, j + 6, k + 33, VetheaBlockHelper.hallWall.blockID);
		world.setBlock(i + 3, j + 6, k + 34, VetheaBlockHelper.hallWall.blockID);
		world.setBlock(i + 3, j + 6, k + 35, VetheaBlockHelper.hallWall.blockID);
		world.setBlock(i + 3, j + 7, k + 0, VetheaBlockHelper.hallWall.blockID);
		world.setBlock(i + 3, j + 7, k + 1, VetheaBlockHelper.darkEverstone.blockID);
		world.setBlock(i + 3, j + 7, k + 15, VetheaBlockHelper.hallWall.blockID);
		world.setBlock(i + 3, j + 7, k + 16, VetheaBlockHelper.hallWall.blockID);
		world.setBlock(i + 3, j + 7, k + 17, VetheaBlockHelper.hallWall.blockID);
		world.setBlock(i + 3, j + 7, k + 18, VetheaBlockHelper.hallWall.blockID);
		world.setBlock(i + 3, j + 7, k + 19, VetheaBlockHelper.hallWall.blockID);
		world.setBlock(i + 3, j + 7, k + 20, VetheaBlockHelper.hallWall.blockID);
		world.setBlock(i + 3, j + 7, k + 21, VetheaBlockHelper.hallWall.blockID);
		world.setBlock(i + 3, j + 7, k + 22, VetheaBlockHelper.hallWall.blockID);
		world.setBlock(i + 3, j + 7, k + 23, VetheaBlockHelper.hallWall.blockID);
		world.setBlock(i + 3, j + 7, k + 24, VetheaBlockHelper.hallWall.blockID);
		world.setBlock(i + 3, j + 7, k + 25, VetheaBlockHelper.hallWall.blockID);
		world.setBlock(i + 3, j + 7, k + 26, VetheaBlockHelper.hallWall.blockID);
		world.setBlock(i + 3, j + 7, k + 27, VetheaBlockHelper.hallWall.blockID);
		world.setBlock(i + 3, j + 7, k + 28, VetheaBlockHelper.hallWall.blockID);
		world.setBlock(i + 3, j + 7, k + 29, VetheaBlockHelper.hallWall.blockID);
		world.setBlock(i + 3, j + 7, k + 30, VetheaBlockHelper.hallWall.blockID);
		world.setBlock(i + 3, j + 7, k + 31, VetheaBlockHelper.hallWall.blockID);
		world.setBlock(i + 3, j + 7, k + 32, VetheaBlockHelper.hallWall.blockID);
		world.setBlock(i + 3, j + 7, k + 33, VetheaBlockHelper.hallWall.blockID);
		world.setBlock(i + 3, j + 7, k + 34, VetheaBlockHelper.hallWall.blockID);
		world.setBlock(i + 3, j + 7, k + 35, VetheaBlockHelper.hallWall.blockID);
		world.setBlock(i + 3, j + 8, k + 1, VetheaBlockHelper.hallWall.blockID);
		world.setBlock(i + 3, j + 8, k + 15, VetheaBlockHelper.hallWall.blockID);
		world.setBlock(i + 3, j + 8, k + 16, VetheaBlockHelper.hallWall.blockID);
		world.setBlock(i + 3, j + 8, k + 17, VetheaBlockHelper.hallWall.blockID);
		world.setBlock(i + 3, j + 8, k + 18, VetheaBlockHelper.hallWall.blockID);
		world.setBlock(i + 3, j + 8, k + 19, VetheaBlockHelper.hallWall.blockID);
		world.setBlock(i + 3, j + 8, k + 20, VetheaBlockHelper.hallWall.blockID);
		world.setBlock(i + 3, j + 8, k + 21, VetheaBlockHelper.hallWall.blockID);
		world.setBlock(i + 3, j + 8, k + 22, VetheaBlockHelper.hallWall.blockID);
		world.setBlock(i + 3, j + 8, k + 23, VetheaBlockHelper.hallWall.blockID);
		world.setBlock(i + 3, j + 8, k + 24, VetheaBlockHelper.hallWall.blockID);
		world.setBlock(i + 3, j + 8, k + 25, VetheaBlockHelper.hallWall.blockID);
		world.setBlock(i + 3, j + 8, k + 26, VetheaBlockHelper.hallWall.blockID);
		world.setBlock(i + 3, j + 8, k + 27, VetheaBlockHelper.hallWall.blockID);
		world.setBlock(i + 3, j + 8, k + 28, VetheaBlockHelper.hallWall.blockID);
		world.setBlock(i + 3, j + 8, k + 29, VetheaBlockHelper.hallWall.blockID);
		world.setBlock(i + 3, j + 8, k + 30, VetheaBlockHelper.hallWall.blockID);
		world.setBlock(i + 3, j + 8, k + 31, VetheaBlockHelper.hallWall.blockID);
		world.setBlock(i + 3, j + 8, k + 32, VetheaBlockHelper.hallWall.blockID);
		world.setBlock(i + 3, j + 8, k + 33, VetheaBlockHelper.hallWall.blockID);
		world.setBlock(i + 3, j + 8, k + 34, VetheaBlockHelper.hallWall.blockID);
		world.setBlock(i + 3, j + 8, k + 35, VetheaBlockHelper.hallWall.blockID);
		world.setBlock(i + 3, j + 9, k + 2, VetheaBlockHelper.hallWall.blockID);
		world.setBlock(i + 3, j + 9, k + 3, VetheaBlockHelper.hallWall.blockID);
		world.setBlock(i + 3, j + 9, k + 4, VetheaBlockHelper.hallWall.blockID);
		world.setBlock(i + 3, j + 9, k + 5, VetheaBlockHelper.hallWall.blockID);
		world.setBlock(i + 3, j + 9, k + 6, VetheaBlockHelper.hallWall.blockID);
		world.setBlock(i + 3, j + 9, k + 7, VetheaBlockHelper.hallWall.blockID);
		world.setBlock(i + 3, j + 9, k + 8, VetheaBlockHelper.hallWall.blockID);
		world.setBlock(i + 3, j + 9, k + 9, VetheaBlockHelper.hallWall.blockID);
		world.setBlock(i + 3, j + 9, k + 10, VetheaBlockHelper.hallWall.blockID);
		world.setBlock(i + 3, j + 9, k + 11, VetheaBlockHelper.hallWall.blockID);
		world.setBlock(i + 3, j + 9, k + 12, VetheaBlockHelper.hallWall.blockID);
		world.setBlock(i + 3, j + 9, k + 13, VetheaBlockHelper.hallWall.blockID);
		world.setBlock(i + 3, j + 9, k + 14, VetheaBlockHelper.hallWall.blockID);
		world.setBlock(i + 3, j + 9, k + 17, VetheaBlockHelper.darkEverstone.blockID);
		world.setBlock(i + 3, j + 9, k + 20, VetheaBlockHelper.darkEverstone.blockID);
		world.setBlock(i + 3, j + 9, k + 23, VetheaBlockHelper.darkEverstone.blockID);
		world.setBlock(i + 3, j + 9, k + 27, VetheaBlockHelper.darkEverstone.blockID);
		world.setBlock(i + 3, j + 9, k + 30, VetheaBlockHelper.darkEverstone.blockID);
		world.setBlock(i + 3, j + 9, k + 33, VetheaBlockHelper.darkEverstone.blockID);
		world.setBlock(i + 4, j + 0, k + 1, VetheaBlockHelper.darkEverstone.blockID);
		world.setBlock(i + 4, j + 0, k + 2, VetheaBlockHelper.hallWall.blockID);
		world.setBlock(i + 4, j + 0, k + 14, VetheaBlockHelper.hallWall.blockID);
		world.setBlock(i + 4, j + 0, k + 16, VetheaBlockHelper.hallWall.blockID);
		world.setBlock(i + 4, j + 0, k + 17, VetheaBlockHelper.hallWall.blockID);
		world.setBlock(i + 4, j + 0, k + 18, VetheaBlockHelper.hallWall.blockID);
		world.setBlock(i + 4, j + 0, k + 19, VetheaBlockHelper.hallWall.blockID);
		world.setBlock(i + 4, j + 0, k + 20, VetheaBlockHelper.hallWall.blockID);
		world.setBlock(i + 4, j + 0, k + 21, VetheaBlockHelper.hallWall.blockID);
		world.setBlock(i + 4, j + 0, k + 22, VetheaBlockHelper.hallWall.blockID);
		world.setBlock(i + 4, j + 0, k + 23, VetheaBlockHelper.hallWall.blockID);
		world.setBlock(i + 4, j + 0, k + 24, VetheaBlockHelper.hallWall.blockID);
		world.setBlock(i + 4, j + 0, k + 25, VetheaBlockHelper.hallWall.blockID);
		world.setBlock(i + 4, j + 0, k + 26, VetheaBlockHelper.hallWall.blockID);
		world.setBlock(i + 4, j + 0, k + 27, VetheaBlockHelper.hallWall.blockID);
		world.setBlock(i + 4, j + 0, k + 28, VetheaBlockHelper.hallWall.blockID);
		world.setBlock(i + 4, j + 0, k + 29, VetheaBlockHelper.hallWall.blockID);
		world.setBlock(i + 4, j + 0, k + 30, VetheaBlockHelper.hallWall.blockID);
		world.setBlock(i + 4, j + 0, k + 31, VetheaBlockHelper.hallWall.blockID);
		world.setBlock(i + 4, j + 0, k + 32, VetheaBlockHelper.hallWall.blockID);
		world.setBlock(i + 4, j + 0, k + 33, VetheaBlockHelper.hallWall.blockID);
		world.setBlock(i + 4, j + 0, k + 34, VetheaBlockHelper.firecrystal.blockID);
		world.setBlock(i + 4, j + 0, k + 35, VetheaBlockHelper.firecrystal.blockID);
		world.setBlock(i + 4, j + 0, k + 36, VetheaBlockHelper.hallWall.blockID);
		world.setBlock(i + 4, j + 1, k + 1, VetheaBlockHelper.darkEverstone.blockID);
		world.setBlock(i + 4, j + 1, k + 2, VetheaBlockHelper.hallWall.blockID);
		world.setBlock(i + 4, j + 1, k + 14, VetheaBlockHelper.hallWall.blockID);
		world.setBlock(i + 4, j + 1, k + 16, VetheaBlockHelper.hallWall.blockID);
		world.setBlock(i + 4, j + 1, k + 17, VetheaBlockHelper.hallWall.blockID);
		world.setBlock(i + 4, j + 1, k + 18, VetheaBlockHelper.hallWall.blockID);
		world.setBlock(i + 4, j + 1, k + 19, VetheaBlockHelper.hallWall.blockID);
		world.setBlock(i + 4, j + 1, k + 20, VetheaBlockHelper.hallWall.blockID);
		world.setBlock(i + 4, j + 1, k + 21, VetheaBlockHelper.hallWall.blockID);
		world.setBlock(i + 4, j + 1, k + 22, VetheaBlockHelper.hallWall.blockID);
		world.setBlock(i + 4, j + 1, k + 23, VetheaBlockHelper.hallWall.blockID);
		world.setBlock(i + 4, j + 1, k + 24, VetheaBlockHelper.hallWall.blockID);
		world.setBlock(i + 4, j + 1, k + 25, VetheaBlockHelper.hallWall.blockID);
		world.setBlock(i + 4, j + 1, k + 26, VetheaBlockHelper.hallWall.blockID);
		world.setBlock(i + 4, j + 1, k + 27, VetheaBlockHelper.hallWall.blockID);
		world.setBlock(i + 4, j + 1, k + 28, VetheaBlockHelper.hallWall.blockID);
		world.setBlock(i + 4, j + 1, k + 29, VetheaBlockHelper.hallWall.blockID);
		world.setBlock(i + 4, j + 1, k + 30, VetheaBlockHelper.hallWall.blockID);
		world.setBlock(i + 4, j + 1, k + 31, VetheaBlockHelper.hallWall.blockID);
		world.setBlock(i + 4, j + 1, k + 32, VetheaBlockHelper.hallWall.blockID);
		world.setBlock(i + 4, j + 1, k + 33, VetheaBlockHelper.hallWall.blockID);
		world.setBlock(i + 4, j + 1, k + 36, VetheaBlockHelper.hallWall.blockID);
		world.setBlock(i + 4, j + 2, k + 1, VetheaBlockHelper.darkEverstone.blockID);
		world.setBlock(i + 4, j + 2, k + 2, VetheaBlockHelper.hallWall.blockID);
		world.setBlock(i + 4, j + 2, k + 14, VetheaBlockHelper.hallWall.blockID);
		world.setBlock(i + 4, j + 2, k + 16, VetheaBlockHelper.hallWall.blockID);
		world.setBlock(i + 4, j + 2, k + 17, VetheaBlockHelper.hallWall.blockID);
		world.setBlock(i + 4, j + 2, k + 18, VetheaBlockHelper.hallWall.blockID);
		world.setBlock(i + 4, j + 2, k + 19, VetheaBlockHelper.hallWall.blockID);
		world.setBlock(i + 4, j + 2, k + 20, VetheaBlockHelper.hallWall.blockID);
		world.setBlock(i + 4, j + 2, k + 21, VetheaBlockHelper.hallWall.blockID);
		world.setBlock(i + 4, j + 2, k + 22, VetheaBlockHelper.hallWall.blockID);
		world.setBlock(i + 4, j + 2, k + 23, VetheaBlockHelper.hallWall.blockID);
		world.setBlock(i + 4, j + 2, k + 24, VetheaBlockHelper.hallWall.blockID);
		world.setBlock(i + 4, j + 2, k + 25, VetheaBlockHelper.hallWall.blockID);
		world.setBlock(i + 4, j + 2, k + 26, VetheaBlockHelper.hallWall.blockID);
		world.setBlock(i + 4, j + 2, k + 27, VetheaBlockHelper.hallWall.blockID);
		world.setBlock(i + 4, j + 2, k + 28, VetheaBlockHelper.hallWall.blockID);
		world.setBlock(i + 4, j + 2, k + 29, VetheaBlockHelper.hallWall.blockID);
		world.setBlock(i + 4, j + 2, k + 30, VetheaBlockHelper.hallWall.blockID);
		world.setBlock(i + 4, j + 2, k + 31, VetheaBlockHelper.hallWall.blockID);
		world.setBlock(i + 4, j + 2, k + 32, VetheaBlockHelper.hallWall.blockID);
		world.setBlock(i + 4, j + 2, k + 33, VetheaBlockHelper.hallWall.blockID);
		world.setBlock(i + 4, j + 2, k + 36, VetheaBlockHelper.hallWall.blockID);
		world.setBlock(i + 4, j + 3, k + 1, VetheaBlockHelper.darkEverstone.blockID);
		world.setBlock(i + 4, j + 3, k + 2, VetheaBlockHelper.hallWall.blockID);
		world.setBlock(i + 4, j + 3, k + 14, VetheaBlockHelper.hallWall.blockID);
		world.setBlock(i + 4, j + 3, k + 15, VetheaBlockHelper.hallWall.blockID);
		world.setBlock(i + 4, j + 3, k + 16, VetheaBlockHelper.hallWall.blockID);
		world.setBlock(i + 4, j + 3, k + 17, VetheaBlockHelper.hallWall.blockID);
		world.setBlock(i + 4, j + 3, k + 18, VetheaBlockHelper.hallWall.blockID);
		world.setBlock(i + 4, j + 3, k + 19, VetheaBlockHelper.hallWall.blockID);
		world.setBlock(i + 4, j + 3, k + 20, VetheaBlockHelper.hallWall.blockID);
		world.setBlock(i + 4, j + 3, k + 21, VetheaBlockHelper.hallWall.blockID);
		world.setBlock(i + 4, j + 3, k + 22, VetheaBlockHelper.hallWall.blockID);
		world.setBlock(i + 4, j + 3, k + 23, VetheaBlockHelper.hallWall.blockID);
		world.setBlock(i + 4, j + 3, k + 24, VetheaBlockHelper.hallWall.blockID);
		world.setBlock(i + 4, j + 3, k + 25, VetheaBlockHelper.hallWall.blockID);
		world.setBlock(i + 4, j + 3, k + 26, VetheaBlockHelper.hallWall.blockID);
		world.setBlock(i + 4, j + 3, k + 27, VetheaBlockHelper.hallWall.blockID);
		world.setBlock(i + 4, j + 3, k + 28, VetheaBlockHelper.hallWall.blockID);
		world.setBlock(i + 4, j + 3, k + 29, VetheaBlockHelper.hallWall.blockID);
		world.setBlock(i + 4, j + 3, k + 30, VetheaBlockHelper.hallWall.blockID);
		world.setBlock(i + 4, j + 3, k + 31, VetheaBlockHelper.hallWall.blockID);
		world.setBlock(i + 4, j + 3, k + 32, VetheaBlockHelper.hallWall.blockID);
		world.setBlock(i + 4, j + 3, k + 33, VetheaBlockHelper.hallWall.blockID);
		world.setBlock(i + 4, j + 3, k + 34, VetheaBlockHelper.hallWall.blockID);
		world.setBlock(i + 4, j + 3, k + 35, VetheaBlockHelper.hallWall.blockID);
		world.setBlock(i + 4, j + 3, k + 36, VetheaBlockHelper.hallWall.blockID);
		world.setBlock(i + 4, j + 4, k + 0, VetheaBlockHelper.darkEverstone.blockID);
		world.setBlock(i + 4, j + 4, k + 1, VetheaBlockHelper.darkEverstone.blockID);
		world.setBlock(i + 4, j + 4, k + 2, VetheaBlockHelper.hallWall.blockID);
		world.setBlock(i + 4, j + 4, k + 14, VetheaBlockHelper.hallWall.blockID);
		world.setBlock(i + 4, j + 4, k + 15, VetheaBlockHelper.hallWall.blockID);
		world.setBlock(i + 4, j + 4, k + 16, VetheaBlockHelper.bacterialAcid.blockID);
		world.setBlock(i + 4, j + 4, k + 17, VetheaBlockHelper.bacterialAcid.blockID);
		world.setBlock(i + 4, j + 4, k + 18, VetheaBlockHelper.bacterialAcid.blockID);
		world.setBlock(i + 4, j + 4, k + 19, VetheaBlockHelper.bacterialAcid.blockID);
		world.setBlock(i + 4, j + 4, k + 20, VetheaBlockHelper.bacterialAcid.blockID);
		world.setBlock(i + 4, j + 4, k + 21, VetheaBlockHelper.bacterialAcid.blockID);
		world.setBlock(i + 4, j + 4, k + 22, VetheaBlockHelper.bacterialAcid.blockID);
		world.setBlock(i + 4, j + 4, k + 23, VetheaBlockHelper.bacterialAcid.blockID);
		world.setBlock(i + 4, j + 4, k + 24, VetheaBlockHelper.bacterialAcid.blockID);
		world.setBlock(i + 4, j + 4, k + 25, VetheaBlockHelper.bacterialAcid.blockID);
		world.setBlock(i + 4, j + 4, k + 26, VetheaBlockHelper.bacterialAcid.blockID);
		world.setBlock(i + 4, j + 4, k + 27, VetheaBlockHelper.bacterialAcid.blockID);
		world.setBlock(i + 4, j + 4, k + 28, VetheaBlockHelper.bacterialAcid.blockID);
		world.setBlock(i + 4, j + 4, k + 29, VetheaBlockHelper.bacterialAcid.blockID);
		world.setBlock(i + 4, j + 4, k + 30, VetheaBlockHelper.bacterialAcid.blockID);
		world.setBlock(i + 4, j + 4, k + 31, VetheaBlockHelper.bacterialAcid.blockID);
		world.setBlock(i + 4, j + 4, k + 32, VetheaBlockHelper.bacterialAcid.blockID);
		world.setBlock(i + 4, j + 4, k + 35, VetheaBlockHelper.hallWall.blockID);
		world.setBlock(i + 4, j + 5, k + 0, VetheaBlockHelper.darkEverstone.blockID);
		world.setBlock(i + 4, j + 5, k + 1, VetheaBlockHelper.hallWall.blockID);
		world.setBlock(i + 4, j + 5, k + 2, VetheaBlockHelper.firecrystal.blockID);
		world.setBlock(i + 4, j + 5, k + 3, VetheaBlockHelper.firecrystal.blockID);
		world.setBlock(i + 4, j + 5, k + 4, VetheaBlockHelper.firecrystal.blockID);
		world.setBlock(i + 4, j + 5, k + 5, VetheaBlockHelper.firecrystal.blockID);
		world.setBlock(i + 4, j + 5, k + 6, VetheaBlockHelper.firecrystal.blockID);
		world.setBlock(i + 4, j + 5, k + 7, VetheaBlockHelper.firecrystal.blockID);
		world.setBlock(i + 4, j + 5, k + 8, VetheaBlockHelper.firecrystal.blockID);
		world.setBlock(i + 4, j + 5, k + 9, VetheaBlockHelper.firecrystal.blockID);
		world.setBlock(i + 4, j + 5, k + 10, VetheaBlockHelper.firecrystal.blockID);
		world.setBlock(i + 4, j + 5, k + 11, VetheaBlockHelper.firecrystal.blockID);
		world.setBlock(i + 4, j + 5, k + 12, VetheaBlockHelper.firecrystal.blockID);
		world.setBlock(i + 4, j + 5, k + 13, VetheaBlockHelper.firecrystal.blockID);
		world.setBlock(i + 4, j + 5, k + 14, VetheaBlockHelper.firecrystal.blockID);
		world.setBlock(i + 4, j + 5, k + 15, VetheaBlockHelper.firecrystal.blockID);
		world.setBlock(i + 4, j + 5, k + 16, VetheaBlockHelper.hallWall.blockID);
		world.setBlock(i + 4, j + 5, k + 17, VetheaBlockHelper.firecrystal.blockID);
		world.setBlock(i + 4, j + 5, k + 19, VetheaBlockHelper.firecrystal.blockID);
		world.setBlock(i + 4, j + 5, k + 21, VetheaBlockHelper.firecrystal.blockID);
		world.setBlock(i + 4, j + 5, k + 23, VetheaBlockHelper.firecrystal.blockID);
		world.setBlock(i + 4, j + 5, k + 25, VetheaBlockHelper.firecrystal.blockID);
		world.setBlock(i + 4, j + 5, k + 27, VetheaBlockHelper.firecrystal.blockID);
		world.setBlock(i + 4, j + 5, k + 29, VetheaBlockHelper.firecrystal.blockID);
		world.setBlock(i + 4, j + 5, k + 31, VetheaBlockHelper.firecrystal.blockID);
		world.setBlock(i + 4, j + 5, k + 33, VetheaBlockHelper.firecrystal.blockID);
		world.setBlock(i + 4, j + 5, k + 34, VetheaBlockHelper.firecrystal.blockID);
		world.setBlock(i + 4, j + 5, k + 35, VetheaBlockHelper.hallWall.blockID);
		world.setBlock(i + 4, j + 6, k + 0, VetheaBlockHelper.darkEverstone.blockID);
		world.setBlock(i + 4, j + 6, k + 1, VetheaBlockHelper.hallWall.blockID);
		world.setBlock(i + 4, j + 6, k + 35, VetheaBlockHelper.hallWall.blockID);
		world.setBlock(i + 4, j + 7, k + 0, VetheaBlockHelper.hallWall.blockID);
		world.setBlock(i + 4, j + 7, k + 1, VetheaBlockHelper.darkEverstone.blockID);
		world.setBlock(i + 4, j + 7, k + 35, VetheaBlockHelper.hallWall.blockID);
		world.setBlock(i + 4, j + 8, k + 1, VetheaBlockHelper.hallWall.blockID);
		world.setBlock(i + 4, j + 8, k + 35, VetheaBlockHelper.hallWall.blockID);
		world.setBlock(i + 4, j + 9, k + 2, VetheaBlockHelper.hallWall.blockID);
		world.setBlock(i + 4, j + 9, k + 3, VetheaBlockHelper.hallWall.blockID);
		world.setBlock(i + 4, j + 9, k + 4, VetheaBlockHelper.hallWall.blockID);
		world.setBlock(i + 4, j + 9, k + 5, VetheaBlockHelper.hallWall.blockID);
		world.setBlock(i + 4, j + 9, k + 6, VetheaBlockHelper.hallWall.blockID);
		world.setBlock(i + 4, j + 9, k + 7, VetheaBlockHelper.hallWall.blockID);
		world.setBlock(i + 4, j + 9, k + 8, VetheaBlockHelper.hallWall.blockID);
		world.setBlock(i + 4, j + 9, k + 9, VetheaBlockHelper.hallWall.blockID);
		world.setBlock(i + 4, j + 9, k + 10, VetheaBlockHelper.hallWall.blockID);
		world.setBlock(i + 4, j + 9, k + 11, VetheaBlockHelper.hallWall.blockID);
		world.setBlock(i + 4, j + 9, k + 12, VetheaBlockHelper.hallWall.blockID);
		world.setBlock(i + 4, j + 9, k + 13, VetheaBlockHelper.hallWall.blockID);
		world.setBlock(i + 4, j + 9, k + 14, VetheaBlockHelper.hallWall.blockID);
		world.setBlock(i + 4, j + 9, k + 15, VetheaBlockHelper.hallWall.blockID);
		world.setBlock(i + 4, j + 9, k + 16, VetheaBlockHelper.hallWall.blockID);
		world.setBlock(i + 4, j + 9, k + 17, VetheaBlockHelper.hallWall.blockID);
		world.setBlock(i + 4, j + 9, k + 18, VetheaBlockHelper.hallWall.blockID);
		world.setBlock(i + 4, j + 9, k + 19, VetheaBlockHelper.hallWall.blockID);
		world.setBlock(i + 4, j + 9, k + 20, VetheaBlockHelper.hallWall.blockID);
		world.setBlock(i + 4, j + 9, k + 21, VetheaBlockHelper.hallWall.blockID);
		world.setBlock(i + 4, j + 9, k + 22, VetheaBlockHelper.hallWall.blockID);
		world.setBlock(i + 4, j + 9, k + 23, VetheaBlockHelper.hallWall.blockID);
		world.setBlock(i + 4, j + 9, k + 24, VetheaBlockHelper.hallWall.blockID);
		world.setBlock(i + 4, j + 9, k + 25, VetheaBlockHelper.hallWall.blockID);
		world.setBlock(i + 4, j + 9, k + 26, VetheaBlockHelper.hallWall.blockID);
		world.setBlock(i + 4, j + 9, k + 27, VetheaBlockHelper.hallWall.blockID);
		world.setBlock(i + 4, j + 9, k + 28, VetheaBlockHelper.hallWall.blockID);
		world.setBlock(i + 4, j + 9, k + 29, VetheaBlockHelper.hallWall.blockID);
		world.setBlock(i + 4, j + 9, k + 30, VetheaBlockHelper.hallWall.blockID);
		world.setBlock(i + 4, j + 9, k + 31, VetheaBlockHelper.hallWall.blockID);
		world.setBlock(i + 4, j + 9, k + 32, VetheaBlockHelper.hallWall.blockID);
		world.setBlock(i + 4, j + 9, k + 33, VetheaBlockHelper.hallWall.blockID);
		world.setBlock(i + 4, j + 9, k + 34, VetheaBlockHelper.hallWall.blockID);
		world.setBlock(i + 5, j + 0, k + 2, VetheaBlockHelper.hallWall.blockID);
		world.setBlock(i + 5, j + 0, k + 14, VetheaBlockHelper.hallWall.blockID);
		world.setBlock(i + 5, j + 0, k + 16, VetheaBlockHelper.hallWall.blockID);
		world.setBlock(i + 5, j + 0, k + 17, VetheaBlockHelper.hallWall.blockID);
		world.setBlock(i + 5, j + 0, k + 18, VetheaBlockHelper.hallWall.blockID);
		world.setBlock(i + 5, j + 0, k + 33, VetheaBlockHelper.hallWall.blockID);
		world.setBlock(i + 5, j + 0, k + 34, VetheaBlockHelper.firecrystal.blockID);
		world.setBlock(i + 5, j + 0, k + 35, VetheaBlockHelper.firecrystal.blockID);
		world.setBlock(i + 5, j + 0, k + 36, VetheaBlockHelper.hallWall.blockID);
		world.setBlock(i + 5, j + 1, k + 2, VetheaBlockHelper.hallWall.blockID);
		world.setBlock(i + 5, j + 1, k + 14, VetheaBlockHelper.hallWall.blockID);
		world.setBlock(i + 5, j + 1, k + 16, VetheaBlockHelper.hallWall.blockID);
		world.setBlock(i + 5, j + 1, k + 17, VetheaBlockHelper.hallWall.blockID);
		world.setBlock(i + 5, j + 1, k + 18, VetheaBlockHelper.hallWall.blockID);
		world.setBlock(i + 5, j + 1, k + 33, VetheaBlockHelper.hallWall.blockID);
		world.setBlock(i + 5, j + 1, k + 36, VetheaBlockHelper.hallWall.blockID);
		world.setBlock(i + 5, j + 2, k + 2, VetheaBlockHelper.hallWall.blockID);
		world.setBlock(i + 5, j + 2, k + 14, VetheaBlockHelper.hallWall.blockID);
		world.setBlock(i + 5, j + 2, k + 16, VetheaBlockHelper.hallWall.blockID);
		world.setBlock(i + 5, j + 2, k + 17, VetheaBlockHelper.hallWall.blockID);
		world.setBlock(i + 5, j + 2, k + 33, VetheaBlockHelper.hallWall.blockID);
		world.setBlock(i + 5, j + 2, k + 36, VetheaBlockHelper.hallWall.blockID);
		world.setBlock(i + 5, j + 3, k + 2, VetheaBlockHelper.hallWall.blockID);
		world.setBlock(i + 5, j + 3, k + 14, VetheaBlockHelper.hallWall.blockID);
		world.setBlock(i + 5, j + 3, k + 15, VetheaBlockHelper.hallWall.blockID);
		world.setBlock(i + 5, j + 3, k + 16, VetheaBlockHelper.hallWall.blockID);
		world.setBlock(i + 5, j + 3, k + 18, VetheaBlockHelper.hallWall.blockID);
		world.setBlock(i + 5, j + 3, k + 33, VetheaBlockHelper.hallWall.blockID);
		world.setBlock(i + 5, j + 3, k + 34, VetheaBlockHelper.hallWall.blockID);
		world.setBlock(i + 5, j + 3, k + 35, VetheaBlockHelper.hallWall.blockID);
		world.setBlock(i + 5, j + 3, k + 36, VetheaBlockHelper.hallWall.blockID);
		world.setBlock(i + 5, j + 4, k + 2, VetheaBlockHelper.hallWall.blockID);
		world.setBlock(i + 5, j + 4, k + 14, VetheaBlockHelper.hallWall.blockID);
		world.setBlock(i + 5, j + 4, k + 15, VetheaBlockHelper.hallWall.blockID);
		world.setBlock(i + 5, j + 4, k + 16, VetheaBlockHelper.bacterialAcid.blockID);
		world.setBlock(i + 5, j + 4, k + 17, VetheaBlockHelper.bacterialAcid.blockID);
		world.setBlock(i + 5, j + 4, k + 18, VetheaBlockHelper.bacterialAcid.blockID);
		world.setBlock(i + 5, j + 4, k + 19, VetheaBlockHelper.bacterialAcid.blockID);
		world.setBlock(i + 5, j + 4, k + 20, VetheaBlockHelper.bacterialAcid.blockID);
		world.setBlock(i + 5, j + 4, k + 21, VetheaBlockHelper.bacterialAcid.blockID);
		world.setBlock(i + 5, j + 4, k + 22, VetheaBlockHelper.bacterialAcid.blockID);
		world.setBlock(i + 5, j + 4, k + 23, VetheaBlockHelper.bacterialAcid.blockID);
		world.setBlock(i + 5, j + 4, k + 24, VetheaBlockHelper.bacterialAcid.blockID);
		world.setBlock(i + 5, j + 4, k + 25, VetheaBlockHelper.bacterialAcid.blockID);
		world.setBlock(i + 5, j + 4, k + 26, VetheaBlockHelper.bacterialAcid.blockID);
		world.setBlock(i + 5, j + 4, k + 27, VetheaBlockHelper.bacterialAcid.blockID);
		world.setBlock(i + 5, j + 4, k + 28, VetheaBlockHelper.bacterialAcid.blockID);
		world.setBlock(i + 5, j + 4, k + 29, VetheaBlockHelper.bacterialAcid.blockID);
		world.setBlock(i + 5, j + 4, k + 30, VetheaBlockHelper.bacterialAcid.blockID);
		world.setBlock(i + 5, j + 4, k + 31, VetheaBlockHelper.bacterialAcid.blockID);
		world.setBlock(i + 5, j + 4, k + 33, VetheaBlockHelper.bacterialAcid.blockID);
		world.setBlock(i + 5, j + 4, k + 34, VetheaBlockHelper.bacterialAcid.blockID);
		world.setBlock(i + 5, j + 4, k + 35, VetheaBlockHelper.hallWall.blockID);
		world.setBlock(i + 5, j + 5, k + 1, VetheaBlockHelper.hallWall.blockID);
		world.setBlock(i + 5, j + 5, k + 2, VetheaBlockHelper.firecrystal.blockID);
		world.setBlock(i + 5, j + 5, k + 3, VetheaBlockHelper.firecrystal.blockID);
		world.setBlock(i + 5, j + 5, k + 4, VetheaBlockHelper.firecrystal.blockID);
		world.setBlock(i + 5, j + 5, k + 5, VetheaBlockHelper.firecrystal.blockID);
		world.setBlock(i + 5, j + 5, k + 6, VetheaBlockHelper.firecrystal.blockID);
		world.setBlock(i + 5, j + 5, k + 7, VetheaBlockHelper.firecrystal.blockID);
		world.setBlock(i + 5, j + 5, k + 8, VetheaBlockHelper.firecrystal.blockID);
		world.setBlock(i + 5, j + 5, k + 9, VetheaBlockHelper.firecrystal.blockID);
		world.setBlock(i + 5, j + 5, k + 10, VetheaBlockHelper.firecrystal.blockID);
		world.setBlock(i + 5, j + 5, k + 11, VetheaBlockHelper.firecrystal.blockID);
		world.setBlock(i + 5, j + 5, k + 12, VetheaBlockHelper.firecrystal.blockID);
		world.setBlock(i + 5, j + 5, k + 13, VetheaBlockHelper.firecrystal.blockID);
		world.setBlock(i + 5, j + 5, k + 14, VetheaBlockHelper.firecrystal.blockID);
		world.setBlock(i + 5, j + 5, k + 15, VetheaBlockHelper.firecrystal.blockID);
		world.setBlock(i + 5, j + 5, k + 16, VetheaBlockHelper.firecrystal.blockID);
		world.setBlock(i + 5, j + 5, k + 18, VetheaBlockHelper.firecrystal.blockID);
		world.setBlock(i + 5, j + 5, k + 20, VetheaBlockHelper.firecrystal.blockID);
		world.setBlock(i + 5, j + 5, k + 22, VetheaBlockHelper.firecrystal.blockID);
		world.setBlock(i + 5, j + 5, k + 24, VetheaBlockHelper.firecrystal.blockID);
		world.setBlock(i + 5, j + 5, k + 26, VetheaBlockHelper.firecrystal.blockID);
		world.setBlock(i + 5, j + 5, k + 28, VetheaBlockHelper.firecrystal.blockID);
		world.setBlock(i + 5, j + 5, k + 30, VetheaBlockHelper.firecrystal.blockID);
		world.setBlock(i + 5, j + 5, k + 32, VetheaBlockHelper.firecrystal.blockID);
		world.setBlock(i + 5, j + 5, k + 34, VetheaBlockHelper.firecrystal.blockID);
		world.setBlock(i + 5, j + 5, k + 35, VetheaBlockHelper.hallWall.blockID);
		world.setBlock(i + 5, j + 6, k + 1, VetheaBlockHelper.hallWall.blockID);
		world.setBlock(i + 5, j + 6, k + 35, VetheaBlockHelper.hallWall.blockID);
		world.setBlock(i + 5, j + 7, k + 0, VetheaBlockHelper.hallWall.blockID);
		world.setBlock(i + 5, j + 7, k + 1, VetheaBlockHelper.darkEverstone.blockID);
		world.setBlock(i + 5, j + 7, k + 35, VetheaBlockHelper.hallWall.blockID);
		world.setBlock(i + 5, j + 8, k + 1, VetheaBlockHelper.hallWall.blockID);
		world.setBlock(i + 5, j + 8, k + 35, VetheaBlockHelper.hallWall.blockID);
		world.setBlock(i + 5, j + 9, k + 2, VetheaBlockHelper.hallWall.blockID);
		world.setBlock(i + 5, j + 9, k + 3, VetheaBlockHelper.hallWall.blockID);
		world.setBlock(i + 5, j + 9, k + 4, VetheaBlockHelper.hallWall.blockID);
		world.setBlock(i + 5, j + 9, k + 5, VetheaBlockHelper.hallWall.blockID);
		world.setBlock(i + 5, j + 9, k + 6, VetheaBlockHelper.hallWall.blockID);
		world.setBlock(i + 5, j + 9, k + 7, VetheaBlockHelper.hallWall.blockID);
		world.setBlock(i + 5, j + 9, k + 8, VetheaBlockHelper.hallWall.blockID);
		world.setBlock(i + 5, j + 9, k + 9, VetheaBlockHelper.hallWall.blockID);
		world.setBlock(i + 5, j + 9, k + 10, VetheaBlockHelper.hallWall.blockID);
		world.setBlock(i + 5, j + 9, k + 11, VetheaBlockHelper.hallWall.blockID);
		world.setBlock(i + 5, j + 9, k + 12, VetheaBlockHelper.hallWall.blockID);
		world.setBlock(i + 5, j + 9, k + 13, VetheaBlockHelper.hallWall.blockID);
		world.setBlock(i + 5, j + 9, k + 14, VetheaBlockHelper.hallWall.blockID);
		world.setBlock(i + 5, j + 9, k + 15, VetheaBlockHelper.hallWall.blockID);
		world.setBlock(i + 5, j + 9, k + 16, VetheaBlockHelper.hallWall.blockID);
		world.setBlock(i + 5, j + 9, k + 17, VetheaBlockHelper.hallWall.blockID);
		world.setBlock(i + 5, j + 9, k + 18, VetheaBlockHelper.hallWall.blockID);
		world.setBlock(i + 5, j + 9, k + 19, VetheaBlockHelper.hallWall.blockID);
		world.setBlock(i + 5, j + 9, k + 20, VetheaBlockHelper.hallWall.blockID);
		world.setBlock(i + 5, j + 9, k + 21, VetheaBlockHelper.hallWall.blockID);
		world.setBlock(i + 5, j + 9, k + 22, VetheaBlockHelper.hallWall.blockID);
		world.setBlock(i + 5, j + 9, k + 23, VetheaBlockHelper.hallWall.blockID);
		world.setBlock(i + 5, j + 9, k + 24, VetheaBlockHelper.hallWall.blockID);
		world.setBlock(i + 5, j + 9, k + 25, VetheaBlockHelper.hallWall.blockID);
		world.setBlock(i + 5, j + 9, k + 26, VetheaBlockHelper.hallWall.blockID);
		world.setBlock(i + 5, j + 9, k + 27, VetheaBlockHelper.hallWall.blockID);
		world.setBlock(i + 5, j + 9, k + 28, VetheaBlockHelper.hallWall.blockID);
		world.setBlock(i + 5, j + 9, k + 29, VetheaBlockHelper.hallWall.blockID);
		world.setBlock(i + 5, j + 9, k + 30, VetheaBlockHelper.hallWall.blockID);
		world.setBlock(i + 5, j + 9, k + 31, VetheaBlockHelper.hallWall.blockID);
		world.setBlock(i + 5, j + 9, k + 32, VetheaBlockHelper.hallWall.blockID);
		world.setBlock(i + 5, j + 9, k + 33, VetheaBlockHelper.hallWall.blockID);
		world.setBlock(i + 5, j + 9, k + 34, VetheaBlockHelper.hallWall.blockID);
		world.setBlock(i + 6, j + 0, k + 2, VetheaBlockHelper.hallWall.blockID);
		world.setBlock(i + 6, j + 0, k + 14, VetheaBlockHelper.hallWall.blockID);
		world.setBlock(i + 6, j + 0, k + 15, VetheaBlockHelper.hallWall.blockID);
		world.setBlock(i + 6, j + 0, k + 16, VetheaBlockHelper.hallWall.blockID);
		world.setBlock(i + 6, j + 0, k + 17, VetheaBlockHelper.hallWall.blockID);
		world.setBlock(i + 6, j + 0, k + 18, VetheaBlockHelper.hallWall.blockID);
		world.setBlock(i + 6, j + 0, k + 33, VetheaBlockHelper.hallWall.blockID);
		world.setBlock(i + 6, j + 0, k + 34, VetheaBlockHelper.firecrystal.blockID);
		world.setBlock(i + 6, j + 0, k + 35, VetheaBlockHelper.firecrystal.blockID);
		world.setBlock(i + 6, j + 0, k + 36, VetheaBlockHelper.hallWall.blockID);
		world.setBlock(i + 6, j + 1, k + 2, VetheaBlockHelper.hallWall.blockID);
		world.setBlock(i + 6, j + 1, k + 14, VetheaBlockHelper.hallWall.blockID);
		world.setBlock(i + 6, j + 1, k + 15, VetheaBlockHelper.hallWall.blockID);
		world.setBlock(i + 6, j + 1, k + 16, VetheaBlockHelper.hallWall.blockID);
		world.setBlock(i + 6, j + 1, k + 17, VetheaBlockHelper.hallWall.blockID);
		world.setBlock(i + 6, j + 1, k + 18, VetheaBlockHelper.hallWall.blockID);
		world.setBlock(i + 6, j + 1, k + 33, VetheaBlockHelper.hallWall.blockID);
		world.setBlock(i + 6, j + 1, k + 36, VetheaBlockHelper.hallWall.blockID);
		world.setBlock(i + 6, j + 2, k + 2, VetheaBlockHelper.hallWall.blockID);
		world.setBlock(i + 6, j + 2, k + 14, VetheaBlockHelper.hallWall.blockID);
		world.setBlock(i + 6, j + 2, k + 15, VetheaBlockHelper.hallWall.blockID);
		world.setBlock(i + 6, j + 2, k + 16, VetheaBlockHelper.hallWall.blockID);
		world.setBlock(i + 6, j + 2, k + 17, VetheaBlockHelper.hallWall.blockID);
		world.setBlock(i + 6, j + 2, k + 18, VetheaBlockHelper.hallWall.blockID);
		world.setBlock(i + 6, j + 2, k + 33, VetheaBlockHelper.hallWall.blockID);
		world.setBlock(i + 6, j + 2, k + 36, VetheaBlockHelper.hallWall.blockID);
		world.setBlock(i + 6, j + 3, k + 2, VetheaBlockHelper.hallWall.blockID);
		world.setBlock(i + 6, j + 3, k + 14, VetheaBlockHelper.hallWall.blockID);
		world.setBlock(i + 6, j + 3, k + 15, VetheaBlockHelper.hallWall.blockID);
		world.setBlock(i + 6, j + 3, k + 16, VetheaBlockHelper.hallWall.blockID);
		world.setBlock(i + 6, j + 3, k + 17, VetheaBlockHelper.hallWall.blockID);
		world.setBlock(i + 6, j + 3, k + 18, VetheaBlockHelper.hallWall.blockID);
		world.setBlock(i + 6, j + 3, k + 33, VetheaBlockHelper.hallWall.blockID);
		world.setBlock(i + 6, j + 3, k + 34, VetheaBlockHelper.hallWall.blockID);
		world.setBlock(i + 6, j + 3, k + 35, VetheaBlockHelper.hallWall.blockID);
		world.setBlock(i + 6, j + 3, k + 36, VetheaBlockHelper.hallWall.blockID);
		world.setBlock(i + 6, j + 4, k + 2, VetheaBlockHelper.hallWall.blockID);
		world.setBlock(i + 6, j + 4, k + 14, VetheaBlockHelper.hallWall.blockID);
		world.setBlock(i + 6, j + 4, k + 15, VetheaBlockHelper.hallWall.blockID);
		world.setBlock(i + 6, j + 4, k + 16, VetheaBlockHelper.hallWall.blockID);
		world.setBlock(i + 6, j + 4, k + 17, VetheaBlockHelper.hallWall.blockID);
		world.setBlock(i + 6, j + 4, k + 18, VetheaBlockHelper.hallWall.blockID);
		world.setBlock(i + 6, j + 4, k + 19, VetheaBlockHelper.hallWall.blockID);
		world.setBlock(i + 6, j + 4, k + 20, VetheaBlockHelper.hallWall.blockID);
		world.setBlock(i + 6, j + 4, k + 21, VetheaBlockHelper.hallWall.blockID);
		world.setBlock(i + 6, j + 4, k + 22, VetheaBlockHelper.hallWall.blockID);
		world.setBlock(i + 6, j + 4, k + 23, VetheaBlockHelper.hallWall.blockID);
		world.setBlock(i + 6, j + 4, k + 24, VetheaBlockHelper.hallWall.blockID);
		world.setBlock(i + 6, j + 4, k + 25, VetheaBlockHelper.hallWall.blockID);
		world.setBlock(i + 6, j + 4, k + 26, VetheaBlockHelper.hallWall.blockID);
		world.setBlock(i + 6, j + 4, k + 27, VetheaBlockHelper.hallWall.blockID);
		world.setBlock(i + 6, j + 4, k + 28, VetheaBlockHelper.hallWall.blockID);
		world.setBlock(i + 6, j + 4, k + 29, VetheaBlockHelper.hallWall.blockID);
		world.setBlock(i + 6, j + 4, k + 30, VetheaBlockHelper.hallWall.blockID);
		world.setBlock(i + 6, j + 4, k + 31, VetheaBlockHelper.hallWall.blockID);
		world.setBlock(i + 6, j + 4, k + 32, VetheaBlockHelper.hallWall.blockID);
		world.setBlock(i + 6, j + 4, k + 33, VetheaBlockHelper.bacterialAcid.blockID);
		world.setBlock(i + 6, j + 4, k + 34, VetheaBlockHelper.bacterialAcid.blockID);
		world.setBlock(i + 6, j + 4, k + 35, VetheaBlockHelper.hallWall.blockID);
		world.setBlock(i + 6, j + 5, k + 1, VetheaBlockHelper.hallWall.blockID);
		world.setBlock(i + 6, j + 5, k + 2, VetheaBlockHelper.firecrystal.blockID);
		world.setBlock(i + 6, j + 5, k + 3, VetheaBlockHelper.firecrystal.blockID);
		world.setBlock(i + 6, j + 5, k + 4, VetheaBlockHelper.firecrystal.blockID);
		world.setBlock(i + 6, j + 5, k + 5, VetheaBlockHelper.firecrystal.blockID);
		world.setBlock(i + 6, j + 5, k + 6, VetheaBlockHelper.firecrystal.blockID);
		world.setBlock(i + 6, j + 5, k + 7, VetheaBlockHelper.firecrystal.blockID);
		world.setBlock(i + 6, j + 5, k + 8, VetheaBlockHelper.firecrystal.blockID);
		world.setBlock(i + 6, j + 5, k + 9, VetheaBlockHelper.firecrystal.blockID);
		world.setBlock(i + 6, j + 5, k + 10, VetheaBlockHelper.firecrystal.blockID);
		world.setBlock(i + 6, j + 5, k + 11, VetheaBlockHelper.firecrystal.blockID);
		world.setBlock(i + 6, j + 5, k + 12, VetheaBlockHelper.firecrystal.blockID);
		world.setBlock(i + 6, j + 5, k + 13, VetheaBlockHelper.firecrystal.blockID);
		world.setBlock(i + 6, j + 5, k + 14, VetheaBlockHelper.firecrystal.blockID);
		world.setBlock(i + 6, j + 5, k + 15, VetheaBlockHelper.hallWall.blockID);
		world.setBlock(i + 6, j + 5, k + 16, VetheaBlockHelper.hallWall.blockID);
		world.setBlock(i + 6, j + 5, k + 17, VetheaBlockHelper.hallWall.blockID);
		world.setBlock(i + 6, j + 5, k + 18, VetheaBlockHelper.hallWall.blockID);
		world.setBlock(i + 6, j + 5, k + 19, VetheaBlockHelper.hallWall.blockID);
		world.setBlock(i + 6, j + 5, k + 20, VetheaBlockHelper.hallWall.blockID);
		world.setBlock(i + 6, j + 5, k + 21, VetheaBlockHelper.hallWall.blockID);
		world.setBlock(i + 6, j + 5, k + 22, VetheaBlockHelper.hallWall.blockID);
		world.setBlock(i + 6, j + 5, k + 23, VetheaBlockHelper.hallWall.blockID);
		world.setBlock(i + 6, j + 5, k + 24, VetheaBlockHelper.hallWall.blockID);
		world.setBlock(i + 6, j + 5, k + 25, VetheaBlockHelper.hallWall.blockID);
		world.setBlock(i + 6, j + 5, k + 26, VetheaBlockHelper.hallWall.blockID);
		world.setBlock(i + 6, j + 5, k + 27, VetheaBlockHelper.hallWall.blockID);
		world.setBlock(i + 6, j + 5, k + 28, VetheaBlockHelper.hallWall.blockID);
		world.setBlock(i + 6, j + 5, k + 29, VetheaBlockHelper.hallWall.blockID);
		world.setBlock(i + 6, j + 5, k + 30, VetheaBlockHelper.hallWall.blockID);
		world.setBlock(i + 6, j + 5, k + 31, VetheaBlockHelper.hallWall.blockID);
		world.setBlock(i + 6, j + 5, k + 32, VetheaBlockHelper.hallWall.blockID);
		world.setBlock(i + 6, j + 5, k + 35, VetheaBlockHelper.hallWall.blockID);
		world.setBlock(i + 6, j + 6, k + 1, VetheaBlockHelper.hallWall.blockID);
		world.setBlock(i + 6, j + 6, k + 6, VetheaBlockHelper.hallWall.blockID);
		world.setBlock(i + 6, j + 6, k + 7, VetheaBlockHelper.hallWall.blockID);
		world.setBlock(i + 6, j + 6, k + 15, VetheaBlockHelper.hallWall.blockID);
		world.setBlock(i + 6, j + 6, k + 16, VetheaBlockHelper.hallWall.blockID);
		world.setBlock(i + 6, j + 6, k + 17, VetheaBlockHelper.hallWall.blockID);
		world.setBlock(i + 6, j + 6, k + 18, VetheaBlockHelper.hallWall.blockID);
		world.setBlock(i + 6, j + 6, k + 19, VetheaBlockHelper.hallWall.blockID);
		world.setBlock(i + 6, j + 6, k + 20, VetheaBlockHelper.hallWall.blockID);
		world.setBlock(i + 6, j + 6, k + 21, VetheaBlockHelper.hallWall.blockID);
		world.setBlock(i + 6, j + 6, k + 22, VetheaBlockHelper.hallWall.blockID);
		world.setBlock(i + 6, j + 6, k + 23, VetheaBlockHelper.hallWall.blockID);
		world.setBlock(i + 6, j + 6, k + 24, VetheaBlockHelper.hallWall.blockID);
		world.setBlock(i + 6, j + 6, k + 25, VetheaBlockHelper.hallWall.blockID);
		world.setBlock(i + 6, j + 6, k + 26, VetheaBlockHelper.hallWall.blockID);
		world.setBlock(i + 6, j + 6, k + 27, VetheaBlockHelper.hallWall.blockID);
		world.setBlock(i + 6, j + 6, k + 28, VetheaBlockHelper.hallWall.blockID);
		world.setBlock(i + 6, j + 6, k + 29, VetheaBlockHelper.hallWall.blockID);
		world.setBlock(i + 6, j + 6, k + 30, VetheaBlockHelper.hallWall.blockID);
		world.setBlock(i + 6, j + 6, k + 31, VetheaBlockHelper.hallWall.blockID);
		world.setBlock(i + 6, j + 6, k + 32, VetheaBlockHelper.hallWall.blockID);
		world.setBlock(i + 6, j + 6, k + 35, VetheaBlockHelper.hallWall.blockID);
		world.setBlock(i + 6, j + 7, k + 0, VetheaBlockHelper.hallWall.blockID);
		world.setBlock(i + 6, j + 7, k + 1, VetheaBlockHelper.darkEverstone.blockID);
		world.setBlock(i + 6, j + 7, k + 6, VetheaBlockHelper.hallWall.blockID);
		world.setBlock(i + 6, j + 7, k + 7, VetheaBlockHelper.hallWall.blockID);
		world.setBlock(i + 6, j + 7, k + 15, VetheaBlockHelper.hallWall.blockID);
		world.setBlock(i + 6, j + 7, k + 16, VetheaBlockHelper.hallWall.blockID);
		world.setBlock(i + 6, j + 7, k + 17, VetheaBlockHelper.hallWall.blockID);
		world.setBlock(i + 6, j + 7, k + 18, VetheaBlockHelper.hallWall.blockID);
		world.setBlock(i + 6, j + 7, k + 19, VetheaBlockHelper.hallWall.blockID);
		world.setBlock(i + 6, j + 7, k + 20, VetheaBlockHelper.hallWall.blockID);
		world.setBlock(i + 6, j + 7, k + 21, VetheaBlockHelper.hallWall.blockID);
		world.setBlock(i + 6, j + 7, k + 22, VetheaBlockHelper.hallWall.blockID);
		world.setBlock(i + 6, j + 7, k + 23, VetheaBlockHelper.hallWall.blockID);
		world.setBlock(i + 6, j + 7, k + 24, VetheaBlockHelper.hallWall.blockID);
		world.setBlock(i + 6, j + 7, k + 25, VetheaBlockHelper.hallWall.blockID);
		world.setBlock(i + 6, j + 7, k + 26, VetheaBlockHelper.hallWall.blockID);
		world.setBlock(i + 6, j + 7, k + 27, VetheaBlockHelper.hallWall.blockID);
		world.setBlock(i + 6, j + 7, k + 28, VetheaBlockHelper.hallWall.blockID);
		world.setBlock(i + 6, j + 7, k + 29, VetheaBlockHelper.hallWall.blockID);
		world.setBlock(i + 6, j + 7, k + 30, VetheaBlockHelper.hallWall.blockID);
		world.setBlock(i + 6, j + 7, k + 31, VetheaBlockHelper.hallWall.blockID);
		world.setBlock(i + 6, j + 7, k + 32, VetheaBlockHelper.hallWall.blockID);
		world.setBlock(i + 6, j + 7, k + 35, VetheaBlockHelper.hallWall.blockID);
		world.setBlock(i + 6, j + 8, k + 1, VetheaBlockHelper.hallWall.blockID);
		world.setBlock(i + 6, j + 8, k + 6, VetheaBlockHelper.hallWall.blockID);
		world.setBlock(i + 6, j + 8, k + 7, VetheaBlockHelper.hallWall.blockID);
		world.setBlock(i + 6, j + 8, k + 15, VetheaBlockHelper.hallWall.blockID);
		world.setBlock(i + 6, j + 8, k + 16, VetheaBlockHelper.hallWall.blockID);
		world.setBlock(i + 6, j + 8, k + 17, VetheaBlockHelper.hallWall.blockID);
		world.setBlock(i + 6, j + 8, k + 18, VetheaBlockHelper.hallWall.blockID);
		world.setBlock(i + 6, j + 8, k + 19, VetheaBlockHelper.hallWall.blockID);
		world.setBlock(i + 6, j + 8, k + 20, VetheaBlockHelper.hallWall.blockID);
		world.setBlock(i + 6, j + 8, k + 21, VetheaBlockHelper.hallWall.blockID);
		world.setBlock(i + 6, j + 8, k + 22, VetheaBlockHelper.hallWall.blockID);
		world.setBlock(i + 6, j + 8, k + 23, VetheaBlockHelper.hallWall.blockID);
		world.setBlock(i + 6, j + 8, k + 24, VetheaBlockHelper.hallWall.blockID);
		world.setBlock(i + 6, j + 8, k + 25, VetheaBlockHelper.hallWall.blockID);
		world.setBlock(i + 6, j + 8, k + 26, VetheaBlockHelper.hallWall.blockID);
		world.setBlock(i + 6, j + 8, k + 27, VetheaBlockHelper.hallWall.blockID);
		world.setBlock(i + 6, j + 8, k + 28, VetheaBlockHelper.hallWall.blockID);
		world.setBlock(i + 6, j + 8, k + 29, VetheaBlockHelper.hallWall.blockID);
		world.setBlock(i + 6, j + 8, k + 30, VetheaBlockHelper.hallWall.blockID);
		world.setBlock(i + 6, j + 8, k + 31, VetheaBlockHelper.hallWall.blockID);
		world.setBlock(i + 6, j + 8, k + 32, VetheaBlockHelper.hallWall.blockID);
		world.setBlock(i + 6, j + 8, k + 35, VetheaBlockHelper.hallWall.blockID);
		world.setBlock(i + 6, j + 9, k + 2, VetheaBlockHelper.hallWall.blockID);
		world.setBlock(i + 6, j + 9, k + 3, VetheaBlockHelper.hallWall.blockID);
		world.setBlock(i + 6, j + 9, k + 4, VetheaBlockHelper.hallWall.blockID);
		world.setBlock(i + 6, j + 9, k + 5, VetheaBlockHelper.hallWall.blockID);
		world.setBlock(i + 6, j + 9, k + 6, VetheaBlockHelper.hallWall.blockID);
		world.setBlock(i + 6, j + 9, k + 7, VetheaBlockHelper.hallWall.blockID);
		world.setBlock(i + 6, j + 9, k + 8, VetheaBlockHelper.hallWall.blockID);
		world.setBlock(i + 6, j + 9, k + 9, VetheaBlockHelper.hallWall.blockID);
		world.setBlock(i + 6, j + 9, k + 10, VetheaBlockHelper.hallWall.blockID);
		world.setBlock(i + 6, j + 9, k + 11, VetheaBlockHelper.hallWall.blockID);
		world.setBlock(i + 6, j + 9, k + 12, VetheaBlockHelper.hallWall.blockID);
		world.setBlock(i + 6, j + 9, k + 13, VetheaBlockHelper.hallWall.blockID);
		world.setBlock(i + 6, j + 9, k + 14, VetheaBlockHelper.hallWall.blockID);
		world.setBlock(i + 6, j + 9, k + 33, VetheaBlockHelper.hallWall.blockID);
		world.setBlock(i + 6, j + 9, k + 34, VetheaBlockHelper.hallWall.blockID);
		world.setBlock(i + 7, j + 0, k + 2, VetheaBlockHelper.hallWall.blockID);
		world.setBlock(i + 7, j + 0, k + 14, VetheaBlockHelper.hallWall.blockID);
		world.setBlock(i + 7, j + 0, k + 19, VetheaBlockHelper.hallWall.blockID);
		world.setBlock(i + 7, j + 0, k + 20, VetheaBlockHelper.hallWall.blockID);
		world.setBlock(i + 7, j + 0, k + 21, VetheaBlockHelper.hallWall.blockID);
		world.setBlock(i + 7, j + 0, k + 22, VetheaBlockHelper.hallWall.blockID);
		world.setBlock(i + 7, j + 0, k + 23, VetheaBlockHelper.hallWall.blockID);
		world.setBlock(i + 7, j + 0, k + 24, VetheaBlockHelper.hallWall.blockID);
		world.setBlock(i + 7, j + 0, k + 25, VetheaBlockHelper.hallWall.blockID);
		world.setBlock(i + 7, j + 0, k + 26, VetheaBlockHelper.hallWall.blockID);
		world.setBlock(i + 7, j + 0, k + 27, VetheaBlockHelper.hallWall.blockID);
		world.setBlock(i + 7, j + 0, k + 28, VetheaBlockHelper.hallWall.blockID);
		world.setBlock(i + 7, j + 0, k + 29, VetheaBlockHelper.hallWall.blockID);
		world.setBlock(i + 7, j + 0, k + 30, VetheaBlockHelper.hallWall.blockID);
		world.setBlock(i + 7, j + 0, k + 33, VetheaBlockHelper.hallWall.blockID);
		world.setBlock(i + 7, j + 0, k + 34, VetheaBlockHelper.firecrystal.blockID);
		world.setBlock(i + 7, j + 0, k + 35, VetheaBlockHelper.firecrystal.blockID);
		world.setBlock(i + 7, j + 0, k + 36, VetheaBlockHelper.hallWall.blockID);
		world.setBlock(i + 7, j + 1, k + 2, VetheaBlockHelper.hallWall.blockID);
		world.setBlock(i + 7, j + 1, k + 14, VetheaBlockHelper.hallWall.blockID);
		world.setBlock(i + 7, j + 1, k + 19, VetheaBlockHelper.hallWall.blockID);
		world.setBlock(i + 7, j + 1, k + 20, VetheaBlockHelper.hallWall.blockID);
		world.setBlock(i + 7, j + 1, k + 21, VetheaBlockHelper.hallWall.blockID);
		world.setBlock(i + 7, j + 1, k + 22, VetheaBlockHelper.hallWall.blockID);
		world.setBlock(i + 7, j + 1, k + 23, VetheaBlockHelper.hallWall.blockID);
		world.setBlock(i + 7, j + 1, k + 24, VetheaBlockHelper.hallWall.blockID);
		world.setBlock(i + 7, j + 1, k + 25, VetheaBlockHelper.hallWall.blockID);
		world.setBlock(i + 7, j + 1, k + 26, VetheaBlockHelper.hallWall.blockID);
		world.setBlock(i + 7, j + 1, k + 27, VetheaBlockHelper.hallWall.blockID);
		world.setBlock(i + 7, j + 1, k + 28, VetheaBlockHelper.hallWall.blockID);
		world.setBlock(i + 7, j + 1, k + 29, VetheaBlockHelper.hallWall.blockID);
		world.setBlock(i + 7, j + 1, k + 30, VetheaBlockHelper.hallWall.blockID);
		world.setBlock(i + 7, j + 1, k + 33, VetheaBlockHelper.hallWall.blockID);
		world.setBlock(i + 7, j + 1, k + 36, VetheaBlockHelper.hallWall.blockID);
		world.setBlock(i + 7, j + 2, k + 2, VetheaBlockHelper.hallWall.blockID);
		world.setBlock(i + 7, j + 2, k + 14, VetheaBlockHelper.hallWall.blockID);
		world.setBlock(i + 7, j + 2, k + 19, VetheaBlockHelper.hallWall.blockID);
		world.setBlock(i + 7, j + 2, k + 20, VetheaBlockHelper.hallWall.blockID);
		world.setBlock(i + 7, j + 2, k + 21, VetheaBlockHelper.hallWall.blockID);
		world.setBlock(i + 7, j + 2, k + 22, VetheaBlockHelper.hallWall.blockID);
		world.setBlock(i + 7, j + 2, k + 23, VetheaBlockHelper.hallWall.blockID);
		world.setBlock(i + 7, j + 2, k + 24, VetheaBlockHelper.hallWall.blockID);
		world.setBlock(i + 7, j + 2, k + 25, VetheaBlockHelper.hallWall.blockID);
		world.setBlock(i + 7, j + 2, k + 26, VetheaBlockHelper.hallWall.blockID);
		world.setBlock(i + 7, j + 2, k + 27, VetheaBlockHelper.hallWall.blockID);
		world.setBlock(i + 7, j + 2, k + 28, VetheaBlockHelper.hallWall.blockID);
		world.setBlock(i + 7, j + 2, k + 29, VetheaBlockHelper.hallWall.blockID);
		world.setBlock(i + 7, j + 2, k + 30, VetheaBlockHelper.hallWall.blockID);
		world.setBlock(i + 7, j + 2, k + 31, VetheaBlockHelper.hallWall.blockID);
		world.setBlock(i + 7, j + 2, k + 33, VetheaBlockHelper.hallWall.blockID);
		world.setBlock(i + 7, j + 2, k + 36, VetheaBlockHelper.hallWall.blockID);
		world.setBlock(i + 7, j + 3, k + 2, VetheaBlockHelper.hallWall.blockID);
		world.setBlock(i + 7, j + 3, k + 14, VetheaBlockHelper.hallWall.blockID);
		world.setBlock(i + 7, j + 3, k + 19, VetheaBlockHelper.hallWall.blockID);
		world.setBlock(i + 7, j + 3, k + 20, VetheaBlockHelper.hallWall.blockID);
		world.setBlock(i + 7, j + 3, k + 21, VetheaBlockHelper.hallWall.blockID);
		world.setBlock(i + 7, j + 3, k + 22, VetheaBlockHelper.hallWall.blockID);
		world.setBlock(i + 7, j + 3, k + 23, VetheaBlockHelper.hallWall.blockID);
		world.setBlock(i + 7, j + 3, k + 24, VetheaBlockHelper.hallWall.blockID);
		world.setBlock(i + 7, j + 3, k + 25, VetheaBlockHelper.hallWall.blockID);
		world.setBlock(i + 7, j + 3, k + 26, VetheaBlockHelper.hallWall.blockID);
		world.setBlock(i + 7, j + 3, k + 27, VetheaBlockHelper.hallWall.blockID);
		world.setBlock(i + 7, j + 3, k + 28, VetheaBlockHelper.hallWall.blockID);
		world.setBlock(i + 7, j + 3, k + 29, VetheaBlockHelper.hallWall.blockID);
		world.setBlock(i + 7, j + 3, k + 30, VetheaBlockHelper.hallWall.blockID);
		world.setBlock(i + 7, j + 3, k + 31, VetheaBlockHelper.hallWall.blockID);
		world.setBlock(i + 7, j + 3, k + 33, VetheaBlockHelper.hallWall.blockID);
		world.setBlock(i + 7, j + 3, k + 34, VetheaBlockHelper.hallWall.blockID);
		world.setBlock(i + 7, j + 3, k + 35, VetheaBlockHelper.hallWall.blockID);
		world.setBlock(i + 7, j + 3, k + 36, VetheaBlockHelper.hallWall.blockID);
		world.setBlock(i + 7, j + 4, k + 2, VetheaBlockHelper.hallWall.blockID);
		world.setBlock(i + 7, j + 4, k + 14, VetheaBlockHelper.hallWall.blockID);
		world.setBlock(i + 7, j + 4, k + 19, VetheaBlockHelper.hallWall.blockID);
		world.setBlock(i + 7, j + 4, k + 20, VetheaBlockHelper.hallWall.blockID);
		world.setBlock(i + 7, j + 4, k + 21, VetheaBlockHelper.hallWall.blockID);
		world.setBlock(i + 7, j + 4, k + 22, VetheaBlockHelper.hallWall.blockID);
		world.setBlock(i + 7, j + 4, k + 23, VetheaBlockHelper.hallWall.blockID);
		world.setBlock(i + 7, j + 4, k + 24, VetheaBlockHelper.hallWall.blockID);
		world.setBlock(i + 7, j + 4, k + 25, VetheaBlockHelper.hallWall.blockID);
		world.setBlock(i + 7, j + 4, k + 26, VetheaBlockHelper.hallWall.blockID);
		world.setBlock(i + 7, j + 4, k + 27, VetheaBlockHelper.hallWall.blockID);
		world.setBlock(i + 7, j + 4, k + 28, VetheaBlockHelper.hallWall.blockID);
		world.setBlock(i + 7, j + 4, k + 29, VetheaBlockHelper.hallWall.blockID);
		world.setBlock(i + 7, j + 4, k + 30, VetheaBlockHelper.hallWall.blockID);
		world.setBlock(i + 7, j + 4, k + 31, VetheaBlockHelper.hallWall.blockID);
		world.setBlock(i + 7, j + 4, k + 32, VetheaBlockHelper.hallWall.blockID);
		world.setBlock(i + 7, j + 4, k + 33, VetheaBlockHelper.bacterialAcid.blockID);
		world.setBlock(i + 7, j + 4, k + 34, VetheaBlockHelper.bacterialAcid.blockID);
		world.setBlock(i + 7, j + 4, k + 35, VetheaBlockHelper.hallWall.blockID);
		world.setBlock(i + 7, j + 5, k + 1, VetheaBlockHelper.hallWall.blockID);
		world.setBlock(i + 7, j + 5, k + 2, VetheaBlockHelper.firecrystal.blockID);
		world.setBlock(i + 7, j + 5, k + 3, VetheaBlockHelper.firecrystal.blockID);
		world.setBlock(i + 7, j + 5, k + 4, VetheaBlockHelper.firecrystal.blockID);
		world.setBlock(i + 7, j + 5, k + 5, VetheaBlockHelper.firecrystal.blockID);
		world.setBlock(i + 7, j + 5, k + 6, VetheaBlockHelper.firecrystal.blockID);
		world.setBlock(i + 7, j + 5, k + 7, VetheaBlockHelper.firecrystal.blockID);
		world.setBlock(i + 7, j + 5, k + 8, VetheaBlockHelper.firecrystal.blockID);
		world.setBlock(i + 7, j + 5, k + 9, VetheaBlockHelper.firecrystal.blockID);
		world.setBlock(i + 7, j + 5, k + 10, VetheaBlockHelper.firecrystal.blockID);
		world.setBlock(i + 7, j + 5, k + 11, VetheaBlockHelper.firecrystal.blockID);
		world.setBlock(i + 7, j + 5, k + 12, VetheaBlockHelper.firecrystal.blockID);
		world.setBlock(i + 7, j + 5, k + 13, VetheaBlockHelper.firecrystal.blockID);
		world.setBlock(i + 7, j + 5, k + 14, VetheaBlockHelper.firecrystal.blockID);
		world.setBlock(i + 7, j + 5, k + 15, VetheaBlockHelper.hallWall.blockID);
		world.setBlock(i + 7, j + 5, k + 19, VetheaBlockHelper.hallWall.blockID);
		world.setBlock(i + 7, j + 5, k + 20, VetheaBlockHelper.hallWall.blockID);
		world.setBlock(i + 7, j + 5, k + 21, VetheaBlockHelper.hallWall.blockID);
		world.setBlock(i + 7, j + 5, k + 22, VetheaBlockHelper.hallWall.blockID);
		world.setBlock(i + 7, j + 5, k + 23, VetheaBlockHelper.hallWall.blockID);
		world.setBlock(i + 7, j + 5, k + 24, VetheaBlockHelper.hallWall.blockID);
		world.setBlock(i + 7, j + 5, k + 25, VetheaBlockHelper.hallWall.blockID);
		world.setBlock(i + 7, j + 5, k + 26, VetheaBlockHelper.hallWall.blockID);
		world.setBlock(i + 7, j + 5, k + 27, VetheaBlockHelper.hallWall.blockID);
		world.setBlock(i + 7, j + 5, k + 28, VetheaBlockHelper.hallWall.blockID);
		world.setBlock(i + 7, j + 5, k + 29, VetheaBlockHelper.hallWall.blockID);
		world.setBlock(i + 7, j + 5, k + 30, VetheaBlockHelper.hallWall.blockID);
		world.setBlock(i + 7, j + 5, k + 31, VetheaBlockHelper.hallWall.blockID);
		world.setBlock(i + 7, j + 5, k + 32, VetheaBlockHelper.hallWall.blockID);
		world.setBlock(i + 7, j + 5, k + 35, VetheaBlockHelper.hallWall.blockID);
		world.setBlock(i + 7, j + 6, k + 1, VetheaBlockHelper.hallWall.blockID);
		world.setBlock(i + 7, j + 6, k + 6, VetheaBlockHelper.hallWall.blockID);
		world.setBlock(i + 7, j + 6, k + 7, VetheaBlockHelper.hallWall.blockID);
		world.setBlock(i + 7, j + 6, k + 15, VetheaBlockHelper.hallWall.blockID);
		world.setBlock(i + 7, j + 6, k + 19, VetheaBlockHelper.hallWall.blockID);
		world.setBlock(i + 7, j + 6, k + 20, VetheaBlockHelper.hallWall.blockID);
		world.setBlock(i + 7, j + 6, k + 21, VetheaBlockHelper.hallWall.blockID);
		world.setBlock(i + 7, j + 6, k + 22, VetheaBlockHelper.hallWall.blockID);
		world.setBlock(i + 7, j + 6, k + 23, VetheaBlockHelper.hallWall.blockID);
		world.setBlock(i + 7, j + 6, k + 24, VetheaBlockHelper.hallWall.blockID);
		world.setBlock(i + 7, j + 6, k + 25, VetheaBlockHelper.hallWall.blockID);
		world.setBlock(i + 7, j + 6, k + 26, VetheaBlockHelper.hallWall.blockID);
		world.setBlock(i + 7, j + 6, k + 27, VetheaBlockHelper.hallWall.blockID);
		world.setBlock(i + 7, j + 6, k + 28, VetheaBlockHelper.hallWall.blockID);
		world.setBlock(i + 7, j + 6, k + 29, VetheaBlockHelper.hallWall.blockID);
		world.setBlock(i + 7, j + 6, k + 30, VetheaBlockHelper.hallWall.blockID);
		world.setBlock(i + 7, j + 6, k + 31, VetheaBlockHelper.hallWall.blockID);
		world.setBlock(i + 7, j + 6, k + 32, VetheaBlockHelper.hallWall.blockID);
		world.setBlock(i + 7, j + 6, k + 35, VetheaBlockHelper.hallWall.blockID);
		world.setBlock(i + 7, j + 7, k + 0, VetheaBlockHelper.hallWall.blockID);
		world.setBlock(i + 7, j + 7, k + 1, VetheaBlockHelper.darkEverstone.blockID);
		world.setBlock(i + 7, j + 7, k + 6, VetheaBlockHelper.hallWall.blockID);
		world.setBlock(i + 7, j + 7, k + 7, VetheaBlockHelper.hallWall.blockID);
		world.setBlock(i + 7, j + 7, k + 15, VetheaBlockHelper.darkEverstone.blockID);
		world.setBlock(i + 7, j + 7, k + 16, VetheaBlockHelper.hallWall.blockID);
		world.setBlock(i + 7, j + 7, k + 19, VetheaBlockHelper.hallWall.blockID);
		world.setBlock(i + 7, j + 7, k + 20, VetheaBlockHelper.hallWall.blockID);
		world.setBlock(i + 7, j + 7, k + 21, VetheaBlockHelper.hallWall.blockID);
		world.setBlock(i + 7, j + 7, k + 22, VetheaBlockHelper.hallWall.blockID);
		world.setBlock(i + 7, j + 7, k + 23, VetheaBlockHelper.hallWall.blockID);
		world.setBlock(i + 7, j + 7, k + 24, VetheaBlockHelper.hallWall.blockID);
		world.setBlock(i + 7, j + 7, k + 25, VetheaBlockHelper.hallWall.blockID);
		world.setBlock(i + 7, j + 7, k + 26, VetheaBlockHelper.hallWall.blockID);
		world.setBlock(i + 7, j + 7, k + 27, VetheaBlockHelper.hallWall.blockID);
		world.setBlock(i + 7, j + 7, k + 28, VetheaBlockHelper.hallWall.blockID);
		world.setBlock(i + 7, j + 7, k + 29, VetheaBlockHelper.hallWall.blockID);
		world.setBlock(i + 7, j + 7, k + 30, VetheaBlockHelper.hallWall.blockID);
		world.setBlock(i + 7, j + 7, k + 31, VetheaBlockHelper.hallWall.blockID);
		world.setBlock(i + 7, j + 7, k + 32, VetheaBlockHelper.hallWall.blockID);
		world.setBlock(i + 7, j + 7, k + 35, VetheaBlockHelper.hallWall.blockID);
		world.setBlock(i + 7, j + 8, k + 1, VetheaBlockHelper.hallWall.blockID);
		world.setBlock(i + 7, j + 8, k + 6, VetheaBlockHelper.hallWall.blockID);
		world.setBlock(i + 7, j + 8, k + 7, VetheaBlockHelper.hallWall.blockID);
		world.setBlock(i + 7, j + 8, k + 15, VetheaBlockHelper.hallWall.blockID);
		world.setBlock(i + 7, j + 8, k + 25, VetheaBlockHelper.hallWall.blockID);
		world.setBlock(i + 7, j + 8, k + 26, VetheaBlockHelper.hallWall.blockID);
		world.setBlock(i + 7, j + 8, k + 27, VetheaBlockHelper.hallWall.blockID);
		world.setBlock(i + 7, j + 8, k + 28, VetheaBlockHelper.hallWall.blockID);
		world.setBlock(i + 7, j + 8, k + 29, VetheaBlockHelper.hallWall.blockID);
		world.setBlock(i + 7, j + 8, k + 30, VetheaBlockHelper.hallWall.blockID);
		world.setBlock(i + 7, j + 8, k + 31, VetheaBlockHelper.hallWall.blockID);
		world.setBlock(i + 7, j + 8, k + 32, VetheaBlockHelper.hallWall.blockID);
		world.setBlock(i + 7, j + 8, k + 35, VetheaBlockHelper.hallWall.blockID);
		world.setBlock(i + 7, j + 9, k + 2, VetheaBlockHelper.hallWall.blockID);
		world.setBlock(i + 7, j + 9, k + 3, VetheaBlockHelper.hallWall.blockID);
		world.setBlock(i + 7, j + 9, k + 4, VetheaBlockHelper.hallWall.blockID);
		world.setBlock(i + 7, j + 9, k + 5, VetheaBlockHelper.hallWall.blockID);
		world.setBlock(i + 7, j + 9, k + 6, VetheaBlockHelper.hallWall.blockID);
		world.setBlock(i + 7, j + 9, k + 7, VetheaBlockHelper.hallWall.blockID);
		world.setBlock(i + 7, j + 9, k + 8, VetheaBlockHelper.hallWall.blockID);
		world.setBlock(i + 7, j + 9, k + 9, VetheaBlockHelper.hallWall.blockID);
		world.setBlock(i + 7, j + 9, k + 10, VetheaBlockHelper.hallWall.blockID);
		world.setBlock(i + 7, j + 9, k + 11, VetheaBlockHelper.hallWall.blockID);
		world.setBlock(i + 7, j + 9, k + 12, VetheaBlockHelper.hallWall.blockID);
		world.setBlock(i + 7, j + 9, k + 13, VetheaBlockHelper.hallWall.blockID);
		world.setBlock(i + 7, j + 9, k + 14, VetheaBlockHelper.hallWall.blockID);
		world.setBlock(i + 7, j + 9, k + 33, VetheaBlockHelper.hallWall.blockID);
		world.setBlock(i + 7, j + 9, k + 34, VetheaBlockHelper.hallWall.blockID);
		world.setBlock(i + 8, j + 0, k + 1, VetheaBlockHelper.darkEverstone.blockID);
		world.setBlock(i + 8, j + 0, k + 2, VetheaBlockHelper.hallWall.blockID);
		world.setBlock(i + 8, j + 0, k + 14, VetheaBlockHelper.hallWall.blockID);
		world.setBlock(i + 8, j + 0, k + 19, VetheaBlockHelper.hallWall.blockID);
		world.setBlock(i + 8, j + 0, k + 20, VetheaBlockHelper.bacterialAcid.blockID);
		world.setBlock(i + 8, j + 0, k + 21, VetheaBlockHelper.bacterialAcid.blockID);
		world.setBlock(i + 8, j + 0, k + 22, VetheaBlockHelper.bacterialAcid.blockID);
		world.setBlock(i + 8, j + 0, k + 23, VetheaBlockHelper.bacterialAcid.blockID);
		world.setBlock(i + 8, j + 0, k + 24, VetheaBlockHelper.bacterialAcid.blockID);
		world.setBlock(i + 8, j + 0, k + 25, VetheaBlockHelper.bacterialAcid.blockID);
		world.setBlock(i + 8, j + 0, k + 26, VetheaBlockHelper.bacterialAcid.blockID);
		world.setBlock(i + 8, j + 0, k + 27, VetheaBlockHelper.bacterialAcid.blockID);
		world.setBlock(i + 8, j + 0, k + 28, VetheaBlockHelper.bacterialAcid.blockID);
		world.setBlock(i + 8, j + 0, k + 29, VetheaBlockHelper.bacterialAcid.blockID);
		world.setBlock(i + 8, j + 0, k + 30, VetheaBlockHelper.bacterialAcid.blockID);
		world.setBlock(i + 8, j + 0, k + 33, VetheaBlockHelper.hallWall.blockID);
		world.setBlock(i + 8, j + 0, k + 34, VetheaBlockHelper.firecrystal.blockID);
		world.setBlock(i + 8, j + 0, k + 35, VetheaBlockHelper.firecrystal.blockID);
		world.setBlock(i + 8, j + 0, k + 36, VetheaBlockHelper.hallWall.blockID);
		world.setBlock(i + 8, j + 1, k + 1, VetheaBlockHelper.darkEverstone.blockID);
		world.setBlock(i + 8, j + 1, k + 2, VetheaBlockHelper.hallWall.blockID);
		world.setBlock(i + 8, j + 1, k + 14, VetheaBlockHelper.hallWall.blockID);
		world.setBlock(i + 8, j + 1, k + 19, VetheaBlockHelper.hallWall.blockID);
		world.setBlock(i + 8, j + 1, k + 30, VetheaBlockHelper.bacterialAcid.blockID);
		world.setBlock(i + 8, j + 1, k + 31, VetheaBlockHelper.bacterialAcid.blockID);
		world.setBlock(i + 8, j + 1, k + 33, VetheaBlockHelper.hallWall.blockID);
		world.setBlock(i + 8, j + 1, k + 36, VetheaBlockHelper.hallWall.blockID);
		world.setBlock(i + 8, j + 2, k + 1, VetheaBlockHelper.darkEverstone.blockID);
		world.setBlock(i + 8, j + 2, k + 2, VetheaBlockHelper.hallWall.blockID);
		world.setBlock(i + 8, j + 2, k + 14, VetheaBlockHelper.hallWall.blockID);
		world.setBlock(i + 8, j + 2, k + 19, VetheaBlockHelper.hallWall.blockID);
		world.setBlock(i + 8, j + 2, k + 31, VetheaBlockHelper.bacterialAcid.blockID);
		world.setBlock(i + 8, j + 2, k + 32, VetheaBlockHelper.bacterialAcid.blockID);
		world.setBlock(i + 8, j + 2, k + 33, VetheaBlockHelper.hallWall.blockID);
		world.setBlock(i + 8, j + 2, k + 36, VetheaBlockHelper.hallWall.blockID);
		world.setBlock(i + 8, j + 3, k + 1, VetheaBlockHelper.darkEverstone.blockID);
		world.setBlock(i + 8, j + 3, k + 2, VetheaBlockHelper.hallWall.blockID);
		world.setBlock(i + 8, j + 3, k + 14, VetheaBlockHelper.hallWall.blockID);
		world.setBlock(i + 8, j + 3, k + 19, VetheaBlockHelper.hallWall.blockID);
		world.setBlock(i + 8, j + 3, k + 32, VetheaBlockHelper.bacterialAcid.blockID);
		world.setBlock(i + 8, j + 3, k + 33, VetheaBlockHelper.hallWall.blockID);
		world.setBlock(i + 8, j + 3, k + 34, VetheaBlockHelper.hallWall.blockID);
		world.setBlock(i + 8, j + 3, k + 35, VetheaBlockHelper.hallWall.blockID);
		world.setBlock(i + 8, j + 3, k + 36, VetheaBlockHelper.hallWall.blockID);
		world.setBlock(i + 8, j + 4, k + 0, VetheaBlockHelper.darkEverstone.blockID);
		world.setBlock(i + 8, j + 4, k + 1, VetheaBlockHelper.darkEverstone.blockID);
		world.setBlock(i + 8, j + 4, k + 2, VetheaBlockHelper.hallWall.blockID);
		world.setBlock(i + 8, j + 4, k + 14, VetheaBlockHelper.hallWall.blockID);
		world.setBlock(i + 8, j + 4, k + 19, VetheaBlockHelper.hallWall.blockID);
		world.setBlock(i + 8, j + 4, k + 22, VetheaBlockHelper.firecrystal.blockID);
		world.setBlock(i + 8, j + 4, k + 26, VetheaBlockHelper.firecrystal.blockID);
		world.setBlock(i + 8, j + 4, k + 35, VetheaBlockHelper.hallWall.blockID);
		world.setBlock(i + 8, j + 5, k + 0, VetheaBlockHelper.darkEverstone.blockID);
		world.setBlock(i + 8, j + 5, k + 1, VetheaBlockHelper.hallWall.blockID);
		world.setBlock(i + 8, j + 5, k + 2, VetheaBlockHelper.firecrystal.blockID);
		world.setBlock(i + 8, j + 5, k + 3, VetheaBlockHelper.firecrystal.blockID);
		world.setBlock(i + 8, j + 5, k + 4, VetheaBlockHelper.firecrystal.blockID);
		world.setBlock(i + 8, j + 5, k + 5, VetheaBlockHelper.firecrystal.blockID);
		world.setBlock(i + 8, j + 5, k + 6, VetheaBlockHelper.firecrystal.blockID);
		world.setBlock(i + 8, j + 5, k + 7, VetheaBlockHelper.firecrystal.blockID);
		world.setBlock(i + 8, j + 5, k + 8, VetheaBlockHelper.firecrystal.blockID);
		world.setBlock(i + 8, j + 5, k + 9, VetheaBlockHelper.firecrystal.blockID);
		world.setBlock(i + 8, j + 5, k + 10, VetheaBlockHelper.firecrystal.blockID);
		world.setBlock(i + 8, j + 5, k + 11, VetheaBlockHelper.firecrystal.blockID);
		world.setBlock(i + 8, j + 5, k + 12, VetheaBlockHelper.firecrystal.blockID);
		world.setBlock(i + 8, j + 5, k + 13, VetheaBlockHelper.firecrystal.blockID);
		world.setBlock(i + 8, j + 5, k + 14, VetheaBlockHelper.firecrystal.blockID);
		world.setBlock(i + 8, j + 5, k + 15, VetheaBlockHelper.hallWall.blockID);
		world.setBlock(i + 8, j + 5, k + 19, VetheaBlockHelper.hallWall.blockID);
		world.setBlock(i + 8, j + 5, k + 30, VetheaBlockHelper.firecrystal.blockID);
		world.setBlock(i + 8, j + 5, k + 33, VetheaBlockHelper.firecrystal.blockID);
		world.setBlock(i + 8, j + 5, k + 34, VetheaBlockHelper.firecrystal.blockID);
		world.setBlock(i + 8, j + 5, k + 35, VetheaBlockHelper.hallWall.blockID);
		world.setBlock(i + 8, j + 6, k + 0, VetheaBlockHelper.darkEverstone.blockID);
		world.setBlock(i + 8, j + 6, k + 1, VetheaBlockHelper.hallWall.blockID);
		world.setBlock(i + 8, j + 6, k + 15, VetheaBlockHelper.hallWall.blockID);
		world.setBlock(i + 8, j + 6, k + 19, VetheaBlockHelper.hallWall.blockID);
		world.setBlock(i + 8, j + 6, k + 35, VetheaBlockHelper.hallWall.blockID);
		world.setBlock(i + 8, j + 7, k + 0, VetheaBlockHelper.hallWall.blockID);
		world.setBlock(i + 8, j + 7, k + 1, VetheaBlockHelper.darkEverstone.blockID);
