package xolova.blued00r.divinerpg.generation.vethea.layer3;
import java.util.Random;

import xolova.blued00r.divinerpg.DivineRPG;

import net.minecraft.world.World;
import net.minecraft.world.gen.feature.WorldGenerator;

public class KarosMadhouse extends WorldGenerator
{
	protected int[] GetValidSpawnBlocks() {
		return new int[] {
		};
	}

	public KarosMadhouse() { }

	public boolean generate(World world, Random rand, int i, int j, int k) {

		world.setBlock(i + 0, j + 0, k + 2, DivineRPGTwilight.karosBricks2.blockID);
		world.setBlock(i + 0, j + 0, k + 3, DivineRPGTwilight.karosBricks2.blockID);
		world.setBlock(i + 0, j + 0, k + 4, DivineRPGTwilight.karosBricks2.blockID);
		world.setBlock(i + 0, j + 0, k + 5, DivineRPGTwilight.karosBricks2.blockID);
		world.setBlock(i + 0, j + 0, k + 6, DivineRPGTwilight.karosBricks2.blockID);
		world.setBlock(i + 0, j + 0, k + 7, DivineRPGTwilight.karosBricks2.blockID);
		world.setBlock(i + 0, j + 0, k + 8, DivineRPGTwilight.karosBricks2.blockID);
		world.setBlock(i + 0, j + 0, k + 9, DivineRPGTwilight.karosBricks2.blockID);
		world.setBlock(i + 0, j + 0, k + 10, DivineRPGTwilight.karosBricks2.blockID);
		world.setBlock(i + 0, j + 0, k + 11, DivineRPGTwilight.karosBricks2.blockID);
		world.setBlock(i + 0, j + 1, k + 3, DivineRPGTwilight.karosBricks2.blockID);
		world.setBlock(i + 0, j + 1, k + 4, DivineRPGTwilight.karosBricks2.blockID);
		world.setBlock(i + 0, j + 1, k + 5, DivineRPGTwilight.karosBricks2.blockID);
		world.setBlock(i + 0, j + 1, k + 6, DivineRPGTwilight.karosBricks2.blockID);
		world.setBlock(i + 0, j + 1, k + 7, DivineRPGTwilight.karosBricks2.blockID);
		world.setBlock(i + 0, j + 1, k + 8, DivineRPGTwilight.karosBricks2.blockID);
		world.setBlock(i + 0, j + 1, k + 9, DivineRPGTwilight.karosBricks2.blockID);
		world.setBlock(i + 0, j + 1, k + 10, DivineRPGTwilight.karosBricks2.blockID);
		world.setBlock(i + 0, j + 1, k + 11, DivineRPGTwilight.karosBricks2.blockID);
		world.setBlock(i + 0, j + 2, k + 4, DivineRPGTwilight.karosBricks2.blockID);
		world.setBlock(i + 0, j + 2, k + 5, DivineRPGTwilight.karosBricks.blockID);
		world.setBlock(i + 0, j + 2, k + 6, DivineRPGTwilight.karosBricks.blockID);
		world.setBlock(i + 0, j + 2, k + 7, DivineRPGTwilight.karosBricks.blockID);
		world.setBlock(i + 0, j + 2, k + 8, DivineRPGTwilight.karosBricks.blockID);
		world.setBlock(i + 0, j + 2, k + 9, DivineRPGTwilight.karosBricks.blockID);
		world.setBlock(i + 0, j + 2, k + 10, DivineRPGTwilight.karosBricks.blockID);
		world.setBlock(i + 0, j + 2, k + 11, DivineRPGTwilight.karosBricks.blockID);
		world.setBlock(i + 1, j + 0, k + 4, DivineRPGTwilight.karosBricks2.blockID);
		world.setBlock(i + 1, j + 0, k + 5, DivineRPGTwilight.karosHeatTileRed.blockID);
		world.setBlock(i + 1, j + 0, k + 6, DivineRPGTwilight.karosHeatTileGreen.blockID);
		world.setBlock(i + 1, j + 0, k + 7, DivineRPGTwilight.karosHeatTileRed.blockID);
		world.setBlock(i + 1, j + 0, k + 8, DivineRPGTwilight.karosHeatTileGreen.blockID);
		world.setBlock(i + 1, j + 0, k + 9, DivineRPGTwilight.karosHeatTileRed.blockID);
		world.setBlock(i + 1, j + 0, k + 10, DivineRPGTwilight.karosHeatTileGreen.blockID);
		world.setBlock(i + 1, j + 0, k + 11, DivineRPGTwilight.karosBricks2.blockID);
		world.setBlock(i + 1, j + 1, k + 11, DivineRPGTwilight.karosBricks2.blockID);
		world.setBlock(i + 1, j + 2, k + 11, DivineRPGTwilight.karosBricks.blockID);
		world.setBlock(i + 1, j + 3, k + 5, DivineRPGTwilight.karosBricks2.blockID);
		world.setBlock(i + 1, j + 3, k + 6, DivineRPGTwilight.karosBricks2.blockID);
		world.setBlock(i + 1, j + 3, k + 7, DivineRPGTwilight.karosBricks2.blockID);
		world.setBlock(i + 1, j + 3, k + 8, DivineRPGTwilight.karosBricks2.blockID);
		world.setBlock(i + 1, j + 3, k + 9, DivineRPGTwilight.karosBricks2.blockID);
		world.setBlock(i + 1, j + 3, k + 10, DivineRPGTwilight.karosBricks2.blockID);
		world.setBlock(i + 2, j + 0, k + 4, DivineRPGTwilight.karosBricks2.blockID);
		world.setBlock(i + 2, j + 0, k + 5, DivineRPGTwilight.karosHeatTileGreen.blockID);
		world.setBlock(i + 2, j + 0, k + 6, DivineRPGTwilight.karosHeatTileRed.blockID);
		world.setBlock(i + 2, j + 0, k + 7, DivineRPGTwilight.karosHeatTileGreen.blockID);
		world.setBlock(i + 2, j + 0, k + 8, DivineRPGTwilight.karosHeatTileRed.blockID);
		world.setBlock(i + 2, j + 0, k + 9, DivineRPGTwilight.karosHeatTileGreen.blockID);
		world.setBlock(i + 2, j + 0, k + 10, DivineRPGTwilight.karosHeatTileRed.blockID);
		world.setBlock(i + 2, j + 0, k + 11, DivineRPGTwilight.karosBricks2.blockID);
		world.setBlock(i + 2, j + 1, k + 11, DivineRPGTwilight.karosBricks2.blockID);
		world.setBlock(i + 2, j + 2, k + 11, DivineRPGTwilight.karosBricks.blockID);
		world.setBlock(i + 2, j + 3, k + 5, DivineRPGTwilight.karosBricks2.blockID);
		world.setBlock(i + 2, j + 3, k + 6, DivineRPGTwilight.karosBricks2.blockID);
		world.setBlock(i + 2, j + 3, k + 7, DivineRPGTwilight.karosBricks2.blockID);
		world.setBlock(i + 2, j + 3, k + 8, DivineRPGTwilight.karosBricks2.blockID);
		world.setBlock(i + 2, j + 3, k + 9, DivineRPGTwilight.karosBricks2.blockID);
		world.setBlock(i + 2, j + 3, k + 10, DivineRPGTwilight.karosBricks2.blockID);
		world.setBlock(i + 3, j + 0, k + 2, DivineRPGTwilight.karosBricks2.blockID);
		world.setBlock(i + 3, j + 0, k + 3, DivineRPGTwilight.karosBricks2.blockID);
		world.setBlock(i + 3, j + 0, k + 4, DivineRPGTwilight.karosBricks2.blockID);
		world.setBlock(i + 3, j + 0, k + 5, DivineRPGTwilight.karosBricks2.blockID);
		world.setBlock(i + 3, j + 0, k + 6, DivineRPGTwilight.karosBricks2.blockID);
		world.setBlock(i + 3, j + 0, k + 7, DivineRPGTwilight.karosBricks2.blockID);
		world.setBlock(i + 3, j + 0, k + 8, DivineRPGTwilight.karosBricks2.blockID);
		world.setBlock(i + 3, j + 0, k + 9, DivineRPGTwilight.karosHeatTileRed.blockID);
		world.setBlock(i + 3, j + 0, k + 10, DivineRPGTwilight.karosHeatTileGreen.blockID);
		world.setBlock(i + 3, j + 0, k + 11, DivineRPGTwilight.karosBricks2.blockID);
		world.setBlock(i + 3, j + 1, k + 3, DivineRPGTwilight.karosBricks2.blockID);
		world.setBlock(i + 3, j + 1, k + 4, DivineRPGTwilight.karosBricks2.blockID);
		world.setBlock(i + 3, j + 1, k + 5, DivineRPGTwilight.karosBricks2.blockID);
		world.setBlock(i + 3, j + 1, k + 6, DivineRPGTwilight.karosBricks2.blockID);
		world.setBlock(i + 3, j + 1, k + 7, DivineRPGTwilight.karosBricks2.blockID);
		world.setBlock(i + 3, j + 1, k + 8, DivineRPGTwilight.karosBricks2.blockID);
		world.setBlock(i + 3, j + 1, k + 11, DivineRPGTwilight.karosBricks2.blockID);
		world.setBlock(i + 3, j + 2, k + 4, DivineRPGTwilight.karosBricks2.blockID);
		world.setBlock(i + 3, j + 2, k + 5, DivineRPGTwilight.karosBricks.blockID);
		world.setBlock(i + 3, j + 2, k + 6, DivineRPGTwilight.karosBricks.blockID);
		world.setBlock(i + 3, j + 2, k + 7, DivineRPGTwilight.karosBricks.blockID);
		world.setBlock(i + 3, j + 2, k + 8, DivineRPGTwilight.karosBricks.blockID);
		world.setBlock(i + 3, j + 2, k + 11, DivineRPGTwilight.karosBricks.blockID);
		world.setBlock(i + 3, j + 3, k + 9, DivineRPGTwilight.karosBricks2.blockID);
		world.setBlock(i + 3, j + 3, k + 10, DivineRPGTwilight.karosBricks2.blockID);
		world.setBlock(i + 4, j + 0, k + 8, DivineRPGTwilight.karosBricks2.blockID);
		world.setBlock(i + 4, j + 0, k + 9, DivineRPGTwilight.karosHeatTileGreen.blockID);
		world.setBlock(i + 4, j + 0, k + 10, DivineRPGTwilight.karosHeatTileRed.blockID);
		world.setBlock(i + 4, j + 0, k + 11, DivineRPGTwilight.karosBricks2.blockID);
		world.setBlock(i + 4, j + 1, k + 8, DivineRPGTwilight.karosBricks2.blockID);
		world.setBlock(i + 4, j + 1, k + 11, DivineRPGTwilight.karosBricks2.blockID);
		world.setBlock(i + 4, j + 2, k + 8, DivineRPGTwilight.karosBricks.blockID);
		world.setBlock(i + 4, j + 2, k + 11, DivineRPGTwilight.karosBricks.blockID);
		world.setBlock(i + 4, j + 3, k + 9, DivineRPGTwilight.karosBricks2.blockID);
		world.setBlock(i + 4, j + 3, k + 10, DivineRPGTwilight.karosBricks2.blockID);
		world.setBlock(i + 5, j + 0, k + 8, DivineRPGTwilight.karosBricks2.blockID);
		world.setBlock(i + 5, j + 0, k + 9, DivineRPGTwilight.karosHeatTileRed.blockID);
		world.setBlock(i + 5, j + 0, k + 10, DivineRPGTwilight.karosHeatTileGreen.blockID);
		world.setBlock(i + 5, j + 0, k + 11, DivineRPGTwilight.karosBricks2.blockID);
		world.setBlock(i + 5, j + 1, k + 8, DivineRPGTwilight.karosBricks2.blockID);
		world.setBlock(i + 5, j + 1, k + 11, DivineRPGTwilight.karosBricks2.blockID);
		world.setBlock(i + 5, j + 2, k + 8, DivineRPGTwilight.karosBricks.blockID);
		world.setBlock(i + 5, j + 2, k + 11, DivineRPGTwilight.karosBricks.blockID);
		world.setBlock(i + 5, j + 3, k + 9, DivineRPGTwilight.karosBricks2.blockID);
		world.setBlock(i + 5, j + 3, k + 10, DivineRPGTwilight.karosBricks2.blockID);
		world.setBlock(i + 6, j + 0, k + 8, DivineRPGTwilight.karosBricks2.blockID);
		world.setBlock(i + 6, j + 0, k + 9, DivineRPGTwilight.karosHeatTileGreen.blockID);
		world.setBlock(i + 6, j + 0, k + 10, DivineRPGTwilight.karosHeatTileRed.blockID);
		world.setBlock(i + 6, j + 0, k + 11, DivineRPGTwilight.karosBricks2.blockID);
		world.setBlock(i + 6, j + 1, k + 8, DivineRPGTwilight.karosBricks2.blockID);
		world.setBlock(i + 6, j + 1, k + 11, DivineRPGTwilight.karosBricks2.blockID);
		world.setBlock(i + 6, j + 2, k + 8, DivineRPGTwilight.karosBricks.blockID);
		world.setBlock(i + 6, j + 2, k + 11, DivineRPGTwilight.karosBricks.blockID);
		world.setBlock(i + 6, j + 3, k + 9, DivineRPGTwilight.karosBricks2.blockID);
		world.setBlock(i + 6, j + 3, k + 10, DivineRPGTwilight.karosBricks2.blockID);
		world.setBlock(i + 7, j + 0, k + 8, DivineRPGTwilight.karosBricks2.blockID);
		world.setBlock(i + 7, j + 0, k + 9, DivineRPGTwilight.karosHeatTileRed.blockID);
		world.setBlock(i + 7, j + 0, k + 10, DivineRPGTwilight.karosHeatTileGreen.blockID);
		world.setBlock(i + 7, j + 0, k + 11, DivineRPGTwilight.karosBricks2.blockID);
		world.setBlock(i + 7, j + 1, k + 8, DivineRPGTwilight.karosBricks2.blockID);
		world.setBlock(i + 7, j + 1, k + 11, DivineRPGTwilight.karosBricks2.blockID);
		world.setBlock(i + 7, j + 2, k + 8, DivineRPGTwilight.karosBricks.blockID);
		world.setBlock(i + 7, j + 2, k + 11, DivineRPGTwilight.karosBricks.blockID);
		world.setBlock(i + 7, j + 3, k + 9, DivineRPGTwilight.karosBricks2.blockID);
		world.setBlock(i + 7, j + 3, k + 10, DivineRPGTwilight.karosBricks2.blockID);
		world.setBlock(i + 8, j + 0, k + 8, DivineRPGTwilight.karosBricks2.blockID);
		world.setBlock(i + 8, j + 0, k + 9, DivineRPGTwilight.karosHeatTileGreen.blockID);
		world.setBlock(i + 8, j + 0, k + 10, DivineRPGTwilight.karosHeatTileRed.blockID);
		world.setBlock(i + 8, j + 0, k + 11, DivineRPGTwilight.karosBricks2.blockID);
		world.setBlock(i + 8, j + 1, k + 8, DivineRPGTwilight.karosBricks2.blockID);
		world.setBlock(i + 8, j + 1, k + 11, DivineRPGTwilight.karosBricks2.blockID);
		world.setBlock(i + 8, j + 2, k + 8, DivineRPGTwilight.karosBricks.blockID);
		world.setBlock(i + 8, j + 2, k + 11, DivineRPGTwilight.karosBricks.blockID);
		world.setBlock(i + 8, j + 3, k + 8, DivineRPGTwilight.karosBricks.blockID);
		world.setBlock(i + 8, j + 3, k + 9, DivineRPGTwilight.karosBricks2.blockID);
		world.setBlock(i + 8, j + 3, k + 10, DivineRPGTwilight.karosBricks2.blockID);
		world.setBlock(i + 8, j + 3, k + 11, DivineRPGTwilight.karosBricks.blockID);
		world.setBlock(i + 8, j + 4, k + 8, DivineRPGTwilight.karosBricks.blockID);
		world.setBlock(i + 8, j + 4, k + 11, DivineRPGTwilight.karosBricks.blockID);
		world.setBlock(i + 9, j + 0, k + 3, DivineRPGTwilight.karosBricks2.blockID);
		world.setBlock(i + 9, j + 0, k + 5, DivineRPGTwilight.karosBricks2.blockID);
		world.setBlock(i + 9, j + 0, k + 7, DivineRPGTwilight.karosBricks2.blockID);
		world.setBlock(i + 9, j + 0, k + 8, DivineRPGTwilight.karosBricks2.blockID);
		world.setBlock(i + 9, j + 0, k + 9, DivineRPGTwilight.karosHeatTileRed.blockID);
		world.setBlock(i + 9, j + 0, k + 10, DivineRPGTwilight.karosHeatTileGreen.blockID);
		world.setBlock(i + 9, j + 0, k + 11, DivineRPGTwilight.karosBricks2.blockID);
		world.setBlock(i + 9, j + 0, k + 12, DivineRPGTwilight.karosBricks2.blockID);
		world.setBlock(i + 9, j + 0, k + 14, DivineRPGTwilight.karosBricks2.blockID);
		world.setBlock(i + 9, j + 0, k + 16, DivineRPGTwilight.karosBricks2.blockID);
		world.setBlock(i + 9, j + 1, k + 3, DivineRPGTwilight.karosBricks2.blockID);
		world.setBlock(i + 9, j + 1, k + 5, DivineRPGTwilight.karosBricks2.blockID);
		world.setBlock(i + 9, j + 1, k + 7, DivineRPGTwilight.karosBricks2.blockID);
		world.setBlock(i + 9, j + 1, k + 8, DivineRPGTwilight.karosBricks2.blockID);
		world.setBlock(i + 9, j + 1, k + 11, DivineRPGTwilight.karosBricks2.blockID);
		world.setBlock(i + 9, j + 1, k + 12, DivineRPGTwilight.karosBricks2.blockID);
		world.setBlock(i + 9, j + 1, k + 14, DivineRPGTwilight.karosBricks2.blockID);
		world.setBlock(i + 9, j + 1, k + 16, DivineRPGTwilight.karosBricks2.blockID);
		world.setBlock(i + 9, j + 2, k + 3, DivineRPGTwilight.karosBricks2.blockID);
		world.setBlock(i + 9, j + 2, k + 5, DivineRPGTwilight.karosBricks2.blockID);
		world.setBlock(i + 9, j + 2, k + 7, DivineRPGTwilight.karosBricks2.blockID);
		world.setBlock(i + 9, j + 2, k + 8, DivineRPGTwilight.karosBricks2.blockID);
		world.setBlock(i + 9, j + 2, k + 11, DivineRPGTwilight.karosBricks2.blockID);
		world.setBlock(i + 9, j + 2, k + 12, DivineRPGTwilight.karosBricks2.blockID);
		world.setBlock(i + 9, j + 2, k + 14, DivineRPGTwilight.karosBricks2.blockID);
		world.setBlock(i + 9, j + 2, k + 16, DivineRPGTwilight.karosBricks2.blockID);
		world.setBlock(i + 9, j + 3, k + 8, DivineRPGTwilight.karosBricks2.blockID);
		world.setBlock(i + 9, j + 3, k + 9, DivineRPGTwilight.karosBricks2.blockID);
		world.setBlock(i + 9, j + 3, k + 10, DivineRPGTwilight.karosBricks2.blockID);
		world.setBlock(i + 9, j + 3, k + 11, DivineRPGTwilight.karosBricks2.blockID);
		world.setBlock(i + 9, j + 4, k + 8, DivineRPGTwilight.karosBricks.blockID);
		world.setBlock(i + 9, j + 4, k + 11, DivineRPGTwilight.karosBricks.blockID);
		world.setBlock(i + 10, j + 0, k + 1, DivineRPGTwilight.karosBricks2.blockID);
		world.setBlock(i + 10, j + 0, k + 2, DivineRPGTwilight.karosBricks2.blockID);
		world.setBlock(i + 10, j + 0, k + 3, DivineRPGTwilight.karosBricks2.blockID);
		world.setBlock(i + 10, j + 0, k + 4, DivineRPGTwilight.karosBricks2.blockID);
		world.setBlock(i + 10, j + 0, k + 5, DivineRPGTwilight.karosBricks2.blockID);
		world.setBlock(i + 10, j + 0, k + 6, DivineRPGTwilight.karosBricks2.blockID);
		world.setBlock(i + 10, j + 0, k + 7, DivineRPGTwilight.karosBricks2.blockID);
		world.setBlock(i + 10, j + 0, k + 8, DivineRPGTwilight.karosBricks2.blockID);
		world.setBlock(i + 10, j + 0, k + 9, DivineRPGTwilight.karosHeatTileGreen.blockID);
		world.setBlock(i + 10, j + 0, k + 10, DivineRPGTwilight.karosHeatTileRed.blockID);
		world.setBlock(i + 10, j + 0, k + 11, DivineRPGTwilight.karosBricks2.blockID);
		world.setBlock(i + 10, j + 0, k + 12, DivineRPGTwilight.karosBricks2.blockID);
		world.setBlock(i + 10, j + 0, k + 13, DivineRPGTwilight.karosBricks2.blockID);
		world.setBlock(i + 10, j + 0, k + 14, DivineRPGTwilight.karosBricks2.blockID);
		world.setBlock(i + 10, j + 0, k + 15, DivineRPGTwilight.karosBricks2.blockID);
		world.setBlock(i + 10, j + 0, k + 16, DivineRPGTwilight.karosBricks2.blockID);
		world.setBlock(i + 10, j + 0, k + 17, DivineRPGTwilight.karosBricks2.blockID);
		world.setBlock(i + 10, j + 0, k + 18, DivineRPGTwilight.karosBricks2.blockID);
		world.setBlock(i + 10, j + 1, k + 1, DivineRPGTwilight.karosBricks2.blockID);
		world.setBlock(i + 10, j + 1, k + 2, DivineRPGTwilight.karosBricks2.blockID);
		world.setBlock(i + 10, j + 1, k + 3, DivineRPGTwilight.karosBricks2.blockID);
		world.setBlock(i + 10, j + 1, k + 4, DivineRPGTwilight.karosBricks2.blockID);
		world.setBlock(i + 10, j + 1, k + 5, DivineRPGTwilight.karosBricks2.blockID);
		world.setBlock(i + 10, j + 1, k + 6, DivineRPGTwilight.karosBricks2.blockID);
		world.setBlock(i + 10, j + 1, k + 7, DivineRPGTwilight.karosBricks2.blockID);
		world.setBlock(i + 10, j + 1, k + 8, DivineRPGTwilight.karosBricks2.blockID);
		world.setBlock(i + 10, j + 1, k + 11, DivineRPGTwilight.karosBricks2.blockID);
		world.setBlock(i + 10, j + 1, k + 12, DivineRPGTwilight.karosBricks2.blockID);
		world.setBlock(i + 10, j + 1, k + 13, DivineRPGTwilight.karosBricks2.blockID);
		world.setBlock(i + 10, j + 1, k + 14, DivineRPGTwilight.karosBricks2.blockID);
		world.setBlock(i + 10, j + 1, k + 15, DivineRPGTwilight.karosBricks2.blockID);
		world.setBlock(i + 10, j + 1, k + 16, DivineRPGTwilight.karosBricks2.blockID);
		world.setBlock(i + 10, j + 1, k + 17, DivineRPGTwilight.karosBricks2.blockID);
		world.setBlock(i + 10, j + 1, k + 18, DivineRPGTwilight.karosBricks2.blockID);
		world.setBlock(i + 10, j + 2, k + 1, DivineRPGTwilight.karosBricks.blockID);
		world.setBlock(i + 10, j + 2, k + 2, DivineRPGTwilight.karosBricks.blockID);
		world.setBlockAndMetadata(i + 10, j + 2, k + 3, DivineRPGTwilight.karosCannon.blockID, 5);
		world.setBlock(i + 10, j + 2, k + 4, DivineRPGTwilight.karosBricks.blockID);
		world.setBlockAndMetadata(i + 10, j + 2, k + 5, DivineRPGTwilight.karosCannon.blockID, 5);
		world.setBlock(i + 10, j + 2, k + 6, DivineRPGTwilight.karosBricks.blockID);
		world.setBlockAndMetadata(i + 10, j + 2, k + 7, DivineRPGTwilight.karosCannon.blockID, 5);
		world.setBlock(i + 10, j + 2, k + 8, DivineRPGTwilight.karosBricks2.blockID);
		world.setBlock(i + 10, j + 2, k + 11, DivineRPGTwilight.karosBricks2.blockID);
		world.setBlockAndMetadata(i + 10, j + 2, k + 12, DivineRPGTwilight.karosCannon.blockID, 5);
		world.setBlock(i + 10, j + 2, k + 13, DivineRPGTwilight.karosBricks.blockID);
		world.setBlockAndMetadata(i + 10, j + 2, k + 14, DivineRPGTwilight.karosCannon.blockID, 5);
		world.setBlock(i + 10, j + 2, k + 15, DivineRPGTwilight.karosBricks.blockID);
		world.setBlockAndMetadata(i + 10, j + 2, k + 16, DivineRPGTwilight.karosCannon.blockID, 5);
		world.setBlock(i + 10, j + 2, k + 17, DivineRPGTwilight.karosBricks.blockID);
		world.setBlock(i + 10, j + 2, k + 18, DivineRPGTwilight.karosBricks.blockID);
		world.setBlock(i + 10, j + 3, k + 1, DivineRPGTwilight.karosBricks.blockID);
		world.setBlock(i + 10, j + 3, k + 2, DivineRPGTwilight.karosBricks.blockID);
		world.setBlock(i + 10, j + 3, k + 3, DivineRPGTwilight.karosBricks.blockID);
		world.setBlock(i + 10, j + 3, k + 4, DivineRPGTwilight.karosBricks.blockID);
		world.setBlock(i + 10, j + 3, k + 5, DivineRPGTwilight.karosBricks.blockID);
		world.setBlock(i + 10, j + 3, k + 6, DivineRPGTwilight.karosBricks.blockID);
		world.setBlock(i + 10, j + 3, k + 7, DivineRPGTwilight.karosBricks.blockID);
		world.setBlock(i + 10, j + 3, k + 8, DivineRPGTwilight.karosBricks2.blockID);
		world.setBlock(i + 10, j + 3, k + 9, DivineRPGTwilight.karosBricks2.blockID);
		world.setBlock(i + 10, j + 3, k + 10, DivineRPGTwilight.karosBricks2.blockID);
		world.setBlock(i + 10, j + 3, k + 11, DivineRPGTwilight.karosBricks2.blockID);
		world.setBlock(i + 10, j + 3, k + 12, DivineRPGTwilight.karosBricks.blockID);
		world.setBlock(i + 10, j + 3, k + 13, DivineRPGTwilight.karosBricks.blockID);
		world.setBlock(i + 10, j + 3, k + 14, DivineRPGTwilight.karosBricks.blockID);
		world.setBlock(i + 10, j + 3, k + 15, DivineRPGTwilight.karosBricks.blockID);
		world.setBlock(i + 10, j + 3, k + 16, DivineRPGTwilight.karosBricks.blockID);
		world.setBlock(i + 10, j + 3, k + 17, DivineRPGTwilight.karosBricks.blockID);
		world.setBlock(i + 10, j + 3, k + 18, DivineRPGTwilight.karosBricks.blockID);
		world.setBlock(i + 10, j + 4, k + 8, DivineRPGTwilight.karosBricks.blockID);
		world.setBlock(i + 10, j + 4, k + 11, DivineRPGTwilight.karosBricks.blockID);
		world.setBlock(i + 11, j + 0, k + 1, DivineRPGTwilight.karosBricks2.blockID);
		world.setBlock(i + 11, j + 0, k + 2, DivineRPGTwilight.karosHeatTileGreen.blockID);
		world.setBlock(i + 11, j + 0, k + 3, DivineRPGTwilight.karosHeatTileGreen.blockID);
		world.setBlock(i + 11, j + 0, k + 4, DivineRPGTwilight.karosHeatTileRed.blockID);
		world.setBlock(i + 11, j + 0, k + 5, DivineRPGTwilight.karosHeatTileRed.blockID);
		world.setBlock(i + 11, j + 0, k + 6, DivineRPGTwilight.karosHeatTileGreen.blockID);
		world.setBlock(i + 11, j + 0, k + 7, DivineRPGTwilight.karosHeatTileGreen.blockID);
		world.setBlock(i + 11, j + 0, k + 8, DivineRPGTwilight.karosHeatTileRed.blockID);
		world.setBlock(i + 11, j + 0, k + 9, DivineRPGTwilight.karosHeatTileRed.blockID);
		world.setBlock(i + 11, j + 0, k + 10, DivineRPGTwilight.karosHeatTileGreen.blockID);
		world.setBlock(i + 11, j + 0, k + 11, DivineRPGTwilight.karosHeatTileGreen.blockID);
		world.setBlock(i + 11, j + 0, k + 12, DivineRPGTwilight.karosHeatTileRed.blockID);
		world.setBlock(i + 11, j + 0, k + 13, DivineRPGTwilight.karosHeatTileRed.blockID);
		world.setBlock(i + 11, j + 0, k + 14, DivineRPGTwilight.karosHeatTileGreen.blockID);
		world.setBlock(i + 11, j + 0, k + 15, DivineRPGTwilight.karosHeatTileGreen.blockID);
		world.setBlock(i + 11, j + 0, k + 16, DivineRPGTwilight.karosHeatTileRed.blockID);
		world.setBlock(i + 11, j + 0, k + 17, DivineRPGTwilight.karosHeatTileRed.blockID);
		world.setBlock(i + 11, j + 0, k + 18, DivineRPGTwilight.karosBricks2.blockID);
		world.setBlock(i + 11, j + 1, k + 1, DivineRPGTwilight.karosBricks2.blockID);
		world.setBlock(i + 11, j + 1, k + 18, DivineRPGTwilight.karosBricks2.blockID);
		world.setBlock(i + 11, j + 2, k + 1, DivineRPGTwilight.karosBricks.blockID);
		world.setBlock(i + 11, j + 2, k + 18, DivineRPGTwilight.karosBricks.blockID);
		world.setBlock(i + 11, j + 3, k + 1, DivineRPGTwilight.karosBricks.blockID);
		world.setBlock(i + 11, j + 3, k + 18, DivineRPGTwilight.karosBricks.blockID);
		world.setBlock(i + 11, j + 4, k + 2, DivineRPGTwilight.karosBricks.blockID);
		world.setBlock(i + 11, j + 4, k + 3, DivineRPGTwilight.karosBricks.blockID);
		world.setBlock(i + 11, j + 4, k + 4, DivineRPGTwilight.karosBricks.blockID);
		world.setBlock(i + 11, j + 4, k + 5, DivineRPGTwilight.karosBricks.blockID);
		world.setBlock(i + 11, j + 4, k + 6, DivineRPGTwilight.karosBricks.blockID);
		world.setBlock(i + 11, j + 4, k + 7, DivineRPGTwilight.karosBricks.blockID);
		world.setBlock(i + 11, j + 4, k + 8, DivineRPGTwilight.karosBricks.blockID);
		world.setBlock(i + 11, j + 4, k + 9, DivineRPGTwilight.karosBricks.blockID);
		world.setBlock(i + 11, j + 4, k + 10, DivineRPGTwilight.karosBricks.blockID);
		world.setBlock(i + 11, j + 4, k + 11, DivineRPGTwilight.karosBricks.blockID);
		world.setBlock(i + 11, j + 4, k + 12, DivineRPGTwilight.karosBricks.blockID);
		world.setBlock(i + 11, j + 4, k + 13, DivineRPGTwilight.karosBricks.blockID);
		world.setBlock(i + 11, j + 4, k + 14, DivineRPGTwilight.karosBricks.blockID);
		world.setBlock(i + 11, j + 4, k + 15, DivineRPGTwilight.karosBricks.blockID);
		world.setBlock(i + 11, j + 4, k + 16, DivineRPGTwilight.karosBricks.blockID);
		world.setBlock(i + 11, j + 4, k + 17, DivineRPGTwilight.karosBricks.blockID);
		world.setBlock(i + 12, j + 0, k + 0, DivineRPGTwilight.karosBricks2.blockID);
		world.setBlock(i + 12, j + 0, k + 1, DivineRPGTwilight.karosBricks2.blockID);
		world.setBlock(i + 12, j + 0, k + 2, DivineRPGTwilight.karosHeatTileGreen.blockID);
		world.setBlock(i + 12, j + 0, k + 3, DivineRPGTwilight.karosHeatTileGreen.blockID);
		world.setBlock(i + 12, j + 0, k + 4, DivineRPGTwilight.karosHeatTileRed.blockID);
		world.setBlock(i + 12, j + 0, k + 5, DivineRPGTwilight.karosHeatTileRed.blockID);
		world.setBlock(i + 12, j + 0, k + 6, DivineRPGTwilight.karosHeatTileGreen.blockID);
		world.setBlock(i + 12, j + 0, k + 7, DivineRPGTwilight.karosHeatTileGreen.blockID);
		world.setBlock(i + 12, j + 0, k + 8, DivineRPGTwilight.karosHeatTileRed.blockID);
		world.setBlock(i + 12, j + 0, k + 9, DivineRPGTwilight.karosHeatTileRed.blockID);
		world.setBlock(i + 12, j + 0, k + 10, DivineRPGTwilight.karosHeatTileGreen.blockID);
		world.setBlock(i + 12, j + 0, k + 11, DivineRPGTwilight.karosHeatTileGreen.blockID);
		world.setBlock(i + 12, j + 0, k + 12, DivineRPGTwilight.karosHeatTileRed.blockID);
		world.setBlock(i + 12, j + 0, k + 13, DivineRPGTwilight.karosHeatTileRed.blockID);
		world.setBlock(i + 12, j + 0, k + 14, DivineRPGTwilight.karosHeatTileGreen.blockID);
		world.setBlock(i + 12, j + 0, k + 15, DivineRPGTwilight.karosHeatTileGreen.blockID);
		world.setBlock(i + 12, j + 0, k + 16, DivineRPGTwilight.karosHeatTileRed.blockID);
		world.setBlock(i + 12, j + 0, k + 17, DivineRPGTwilight.karosHeatTileRed.blockID);
		world.setBlock(i + 12, j + 0, k + 18, DivineRPGTwilight.karosBricks2.blockID);
		world.setBlock(i + 12, j + 0, k + 19, DivineRPGTwilight.karosBricks2.blockID);
		world.setBlock(i + 12, j + 1, k + 0, DivineRPGTwilight.karosBricks2.blockID);
		world.setBlock(i + 12, j + 1, k + 1, DivineRPGTwilight.karosBricks2.blockID);
		world.setBlock(i + 12, j + 1, k + 18, DivineRPGTwilight.karosBricks2.blockID);
		world.setBlock(i + 12, j + 1, k + 19, DivineRPGTwilight.karosBricks2.blockID);
		world.setBlock(i + 12, j + 2, k + 0, DivineRPGTwilight.karosBricks2.blockID);
		world.setBlockAndMetadata(i + 12, j + 2, k + 1, DivineRPGTwilight.karosCannon.blockID, 3);
		world.setBlockAndMetadata(i + 12, j + 2, k + 18, DivineRPGTwilight.karosCannon.blockID, 2);
		world.setBlock(i + 12, j + 2, k + 19, DivineRPGTwilight.karosBricks2.blockID);
		world.setBlock(i + 12, j + 3, k + 1, DivineRPGTwilight.karosBricks.blockID);
		world.setBlock(i + 12, j + 3, k + 18, DivineRPGTwilight.karosBricks.blockID);
		world.setBlock(i + 12, j + 4, k + 2, DivineRPGTwilight.karosBricks.blockID);
		world.setBlock(i + 12, j + 4, k + 17, DivineRPGTwilight.karosBricks.blockID);
		world.setBlock(i + 12, j + 5, k + 3, DivineRPGTwilight.karosBricks.blockID);
		world.setBlock(i + 12, j + 5, k + 4, DivineRPGTwilight.karosBricks.blockID);
		world.setBlock(i + 12, j + 5, k + 5, DivineRPGTwilight.karosBricks.blockID);
		world.setBlock(i + 12, j + 5, k + 6, DivineRPGTwilight.karosBricks.blockID);
		world.setBlock(i + 12, j + 5, k + 7, DivineRPGTwilight.karosBricks.blockID);
		world.setBlock(i + 12, j + 5, k + 8, DivineRPGTwilight.karosBricks.blockID);
		world.setBlock(i + 12, j + 5, k + 9, DivineRPGTwilight.karosBricks.blockID);
		world.setBlock(i + 12, j + 5, k + 10, DivineRPGTwilight.karosBricks.blockID);
		world.setBlock(i + 12, j + 5, k + 11, DivineRPGTwilight.karosBricks.blockID);
		world.setBlock(i + 12, j + 5, k + 12, DivineRPGTwilight.karosBricks.blockID);
		world.setBlock(i + 12, j + 5, k + 13, DivineRPGTwilight.karosBricks.blockID);
		world.setBlock(i + 12, j + 5, k + 14, DivineRPGTwilight.karosBricks.blockID);
		world.setBlock(i + 12, j + 5, k + 15, DivineRPGTwilight.karosBricks.blockID);
		world.setBlock(i + 12, j + 5, k + 16, DivineRPGTwilight.karosBricks.blockID);
		world.setBlock(i + 13, j + 0, k + 1, DivineRPGTwilight.karosBricks2.blockID);
		world.setBlock(i + 13, j + 0, k + 2, DivineRPGTwilight.karosHeatTileRed.blockID);
		world.setBlock(i + 13, j + 0, k + 3, DivineRPGTwilight.karosHeatTileRed.blockID);
		world.setBlock(i + 13, j + 0, k + 4, DivineRPGTwilight.karosHeatTileGreen.blockID);
		world.setBlock(i + 13, j + 0, k + 5, DivineRPGTwilight.karosHeatTileGreen.blockID);
		world.setBlock(i + 13, j + 0, k + 6, DivineRPGTwilight.karosHeatTileRed.blockID);
		world.setBlock(i + 13, j + 0, k + 7, DivineRPGTwilight.karosHeatTileRed.blockID);
		world.setBlock(i + 13, j + 0, k + 8, DivineRPGTwilight.karosHeatTileGreen.blockID);
		world.setBlock(i + 13, j + 0, k + 9, DivineRPGTwilight.karosHeatTileGreen.blockID);
		world.setBlock(i + 13, j + 0, k + 10, DivineRPGTwilight.karosHeatTileRed.blockID);
		world.setBlock(i + 13, j + 0, k + 11, DivineRPGTwilight.karosHeatTileRed.blockID);
		world.setBlock(i + 13, j + 0, k + 12, DivineRPGTwilight.karosHeatTileGreen.blockID);
		world.setBlock(i + 13, j + 0, k + 13, DivineRPGTwilight.karosHeatTileGreen.blockID);
		world.setBlock(i + 13, j + 0, k + 14, DivineRPGTwilight.karosHeatTileRed.blockID);
		world.setBlock(i + 13, j + 0, k + 15, DivineRPGTwilight.karosHeatTileRed.blockID);
		world.setBlock(i + 13, j + 0, k + 16, DivineRPGTwilight.karosHeatTileGreen.blockID);
		world.setBlock(i + 13, j + 0, k + 17, DivineRPGTwilight.karosHeatTileGreen.blockID);
		world.setBlock(i + 13, j + 0, k + 18, DivineRPGTwilight.karosBricks2.blockID);
		world.setBlock(i + 13, j + 1, k + 1, DivineRPGTwilight.karosBricks2.blockID);
		world.setBlock(i + 13, j + 1, k + 18, DivineRPGTwilight.karosBricks2.blockID);
		world.setBlock(i + 13, j + 2, k + 1, DivineRPGTwilight.karosBricks.blockID);
		world.setBlock(i + 13, j + 2, k + 18, DivineRPGTwilight.karosBricks.blockID);
		world.setBlock(i + 13, j + 3, k + 1, DivineRPGTwilight.karosBricks.blockID);
		world.setBlock(i + 13, j + 3, k + 18, DivineRPGTwilight.karosBricks.blockID);
		world.setBlock(i + 13, j + 4, k + 2, DivineRPGTwilight.karosBricks.blockID);
		world.setBlock(i + 13, j + 4, k + 4, DivineRPGTwilight.helioticBeam.blockID);
		world.setBlock(i + 13, j + 4, k + 5, DivineRPGTwilight.helioticBeam.blockID);
		world.setBlock(i + 13, j + 4, k + 6, DivineRPGTwilight.helioticBeam.blockID);
		world.setBlock(i + 13, j + 4, k + 14, DivineRPGTwilight.helioticBeam.blockID);
		world.setBlock(i + 13, j + 4, k + 15, DivineRPGTwilight.helioticBeam.blockID);
		world.setBlock(i + 13, j + 4, k + 16, DivineRPGTwilight.helioticBeam.blockID);
		world.setBlock(i + 13, j + 4, k + 17, DivineRPGTwilight.karosBricks.blockID);
		world.setBlock(i + 13, j + 5, k + 3, DivineRPGTwilight.karosBricks.blockID);
		world.setBlock(i + 13, j + 5, k + 4, DivineRPGTwilight.karosBricks2.blockID);
		world.setBlock(i + 13, j + 5, k + 5, DivineRPGTwilight.karosBricks2.blockID);
		world.setBlock(i + 13, j + 5, k + 6, DivineRPGTwilight.karosBricks2.blockID);
		world.setBlock(i + 13, j + 5, k + 7, DivineRPGTwilight.karosBricks2.blockID);
		world.setBlock(i + 13, j + 5, k + 8, DivineRPGTwilight.karosBricks2.blockID);
		world.setBlock(i + 13, j + 5, k + 9, DivineRPGTwilight.karosBricks2.blockID);
		world.setBlock(i + 13, j + 5, k + 10, DivineRPGTwilight.karosBricks2.blockID);
		world.setBlock(i + 13, j + 5, k + 11, DivineRPGTwilight.karosBricks2.blockID);
		world.setBlock(i + 13, j + 5, k + 12, DivineRPGTwilight.karosBricks2.blockID);
		world.setBlock(i + 13, j + 5, k + 13, DivineRPGTwilight.karosBricks2.blockID);
		world.setBlock(i + 13, j + 5, k + 14, DivineRPGTwilight.karosBricks2.blockID);
		world.setBlock(i + 13, j + 5, k + 15, DivineRPGTwilight.karosBricks2.blockID);
		world.setBlock(i + 13, j + 5, k + 16, DivineRPGTwilight.karosBricks.blockID);
		world.setBlock(i + 14, j + 0, k + 0, DivineRPGTwilight.karosBricks2.blockID);
		world.setBlock(i + 14, j + 0, k + 1, DivineRPGTwilight.karosBricks2.blockID);
		world.setBlock(i + 14, j + 0, k + 2, DivineRPGTwilight.karosHeatTileRed.blockID);
		world.setBlock(i + 14, j + 0, k + 3, DivineRPGTwilight.karosHeatTileRed.blockID);
		world.setBlock(i + 14, j + 0, k + 4, DivineRPGTwilight.karosHeatTileGreen.blockID);
		world.setBlock(i + 14, j + 0, k + 5, DivineRPGTwilight.karosHeatTileGreen.blockID);
		world.setBlock(i + 14, j + 0, k + 6, DivineRPGTwilight.karosHeatTileRed.blockID);
		world.setBlock(i + 14, j + 0, k + 7, DivineRPGTwilight.karosHeatTileRed.blockID);
		world.setBlock(i + 14, j + 0, k + 8, DivineRPGTwilight.karosHeatTileGreen.blockID);
		world.setBlock(i + 14, j + 0, k + 9, DivineRPGTwilight.karosHeatTileGreen.blockID);
		world.setBlock(i + 14, j + 0, k + 10, DivineRPGTwilight.karosHeatTileRed.blockID);
		world.setBlock(i + 14, j + 0, k + 11, DivineRPGTwilight.karosHeatTileRed.blockID);
		world.setBlock(i + 14, j + 0, k + 12, DivineRPGTwilight.karosHeatTileGreen.blockID);
		world.setBlock(i + 14, j + 0, k + 13, DivineRPGTwilight.karosHeatTileGreen.blockID);
		world.setBlock(i + 14, j + 0, k + 14, DivineRPGTwilight.karosHeatTileRed.blockID);
		world.setBlock(i + 14, j + 0, k + 15, DivineRPGTwilight.karosHeatTileRed.blockID);
		world.setBlock(i + 14, j + 0, k + 16, DivineRPGTwilight.karosHeatTileGreen.blockID);
		world.setBlock(i + 14, j + 0, k + 17, DivineRPGTwilight.karosHeatTileGreen.blockID);
		world.setBlock(i + 14, j + 0, k + 18, DivineRPGTwilight.karosBricks2.blockID);
		world.setBlock(i + 14, j + 0, k + 19, DivineRPGTwilight.karosBricks2.blockID);
		world.setBlock(i + 14, j + 1, k + 0, DivineRPGTwilight.karosBricks2.blockID);
		world.setBlock(i + 14, j + 1, k + 1, DivineRPGTwilight.karosBricks2.blockID);
		world.setBlock(i + 14, j + 1, k + 18, DivineRPGTwilight.karosBricks2.blockID);
		world.setBlock(i + 14, j + 1, k + 19, DivineRPGTwilight.karosBricks2.blockID);
		world.setBlock(i + 14, j + 2, k + 0, DivineRPGTwilight.karosBricks2.blockID);
		world.setBlockAndMetadata(i + 14, j + 2, k + 1, DivineRPGTwilight.karosCannon.blockID, 3);
		world.setBlockAndMetadata(i + 14, j + 2, k + 18, DivineRPGTwilight.karosCannon.blockID, 2);
		world.setBlock(i + 14, j + 2, k + 19, DivineRPGTwilight.karosBricks2.blockID);
		world.setBlock(i + 14, j + 3, k + 1, DivineRPGTwilight.karosBricks.blockID);
		world.setBlock(i + 14, j + 3, k + 18, DivineRPGTwilight.karosBricks.blockID);
		world.setBlock(i + 14, j + 4, k + 2, DivineRPGTwilight.karosBricks.blockID);
		world.setBlock(i + 14, j + 4, k + 4, DivineRPGTwilight.helioticBeam.blockID);
		world.setBlock(i + 14, j + 4, k + 5, DivineRPGTwilight.helioticBeam.blockID);
		world.setBlock(i + 14, j + 4, k + 6, DivineRPGTwilight.helioticBeam.blockID);
		world.setBlock(i + 14, j + 4, k + 14, DivineRPGTwilight.helioticBeam.blockID);
		world.setBlock(i + 14, j + 4, k + 15, DivineRPGTwilight.helioticBeam.blockID);
		world.setBlock(i + 14, j + 4, k + 16, DivineRPGTwilight.helioticBeam.blockID);
		world.setBlock(i + 14, j + 4, k + 17, DivineRPGTwilight.karosBricks.blockID);
		world.setBlock(i + 14, j + 5, k + 3, DivineRPGTwilight.karosBricks.blockID);
		world.setBlock(i + 14, j + 5, k + 4, DivineRPGTwilight.karosBricks2.blockID);
		world.setBlock(i + 14, j + 5, k + 5, DivineRPGTwilight.karosBricks.blockID);
		world.setBlock(i + 14, j + 5, k + 6, DivineRPGTwilight.karosBricks.blockID);
		world.setBlock(i + 14, j + 5, k + 7, DivineRPGTwilight.karosBricks.blockID);
		world.setBlock(i + 14, j + 5, k + 8, DivineRPGTwilight.karosBricks.blockID);
		world.setBlock(i + 14, j + 5, k + 9, DivineRPGTwilight.karosBricks.blockID);
		world.setBlock(i + 14, j + 5, k + 10, DivineRPGTwilight.karosBricks.blockID);
		world.setBlock(i + 14, j + 5, k + 11, DivineRPGTwilight.karosBricks.blockID);
		world.setBlock(i + 14, j + 5, k + 12, DivineRPGTwilight.karosBricks.blockID);
		world.setBlock(i + 14, j + 5, k + 13, DivineRPGTwilight.karosBricks.blockID);
		world.setBlock(i + 14, j + 5, k + 14, DivineRPGTwilight.karosBricks.blockID);
		world.setBlock(i + 14, j + 5, k + 15, DivineRPGTwilight.karosBricks2.blockID);
		world.setBlock(i + 14, j + 5, k + 16, DivineRPGTwilight.karosBricks.blockID);
		world.setBlock(i + 15, j + 0, k + 1, DivineRPGTwilight.karosBricks2.blockID);
		world.setBlock(i + 15, j + 0, k + 2, DivineRPGTwilight.karosHeatTileGreen.blockID);
		world.setBlock(i + 15, j + 0, k + 3, DivineRPGTwilight.karosHeatTileGreen.blockID);
		world.setBlock(i + 15, j + 0, k + 4, DivineRPGTwilight.karosHeatTileRed.blockID);
		world.setBlock(i + 15, j + 0, k + 5, DivineRPGTwilight.karosHeatTileRed.blockID);
		world.setBlock(i + 15, j + 0, k + 6, DivineRPGTwilight.karosHeatTileGreen.blockID);
		world.setBlock(i + 15, j + 0, k + 7, DivineRPGTwilight.karosHeatTileGreen.blockID);
		world.setBlock(i + 15, j + 0, k + 8, DivineRPGTwilight.karosHeatTileRed.blockID);
		world.setBlock(i + 15, j + 0, k + 9, DivineRPGTwilight.karosHeatTileRed.blockID);
		world.setBlock(i + 15, j + 0, k + 10, DivineRPGTwilight.karosHeatTileGreen.blockID);
		world.setBlock(i + 15, j + 0, k + 11, DivineRPGTwilight.karosHeatTileGreen.blockID);
		world.setBlock(i + 15, j + 0, k + 12, DivineRPGTwilight.karosHeatTileRed.blockID);
		world.setBlock(i + 15, j + 0, k + 13, DivineRPGTwilight.karosHeatTileRed.blockID);
		world.setBlock(i + 15, j + 0, k + 14, DivineRPGTwilight.karosHeatTileGreen.blockID);
		world.setBlock(i + 15, j + 0, k + 15, DivineRPGTwilight.karosHeatTileGreen.blockID);
		world.setBlock(i + 15, j + 0, k + 16, DivineRPGTwilight.karosHeatTileRed.blockID);
		world.setBlock(i + 15, j + 0, k + 17, DivineRPGTwilight.karosHeatTileRed.blockID);
		world.setBlock(i + 15, j + 0, k + 18, DivineRPGTwilight.karosBricks2.blockID);
		world.setBlock(i + 15, j + 1, k + 1, DivineRPGTwilight.karosBricks2.blockID);
		world.setBlock(i + 15, j + 1, k + 18, DivineRPGTwilight.karosBricks2.blockID);
		world.setBlock(i + 15, j + 2, k + 1, DivineRPGTwilight.karosBricks.blockID);
		world.setBlock(i + 15, j + 2, k + 18, DivineRPGTwilight.karosBricks.blockID);
		world.setBlock(i + 15, j + 3, k + 1, DivineRPGTwilight.karosBricks.blockID);
		world.setBlock(i + 15, j + 3, k + 18, DivineRPGTwilight.karosBricks.blockID);
		world.setBlock(i + 15, j + 4, k + 2, DivineRPGTwilight.karosBricks.blockID);
		world.setBlock(i + 15, j + 4, k + 4, DivineRPGTwilight.helioticBeam.blockID);
		world.setBlock(i + 15, j + 4, k + 5, DivineRPGTwilight.helioticBeam.blockID);
		world.setBlock(i + 15, j + 4, k + 6, DivineRPGTwilight.helioticBeam.blockID);
		world.setBlock(i + 15, j + 4, k + 14, DivineRPGTwilight.helioticBeam.blockID);
		world.setBlock(i + 15, j + 4, k + 15, DivineRPGTwilight.helioticBeam.blockID);
		world.setBlock(i + 15, j + 4, k + 16, DivineRPGTwilight.helioticBeam.blockID);
		world.setBlock(i + 15, j + 4, k + 17, DivineRPGTwilight.karosBricks.blockID);
		world.setBlock(i + 15, j + 5, k + 3, DivineRPGTwilight.karosBricks.blockID);
		world.setBlock(i + 15, j + 5, k + 4, DivineRPGTwilight.karosBricks2.blockID);
		world.setBlock(i + 15, j + 5, k + 5, DivineRPGTwilight.karosBricks.blockID);
		world.setBlock(i + 15, j + 5, k + 6, DivineRPGTwilight.karosBricks2.blockID);
		world.setBlock(i + 15, j + 5, k + 7, DivineRPGTwilight.karosBricks2.blockID);
		world.setBlock(i + 15, j + 5, k + 8, DivineRPGTwilight.karosBricks2.blockID);
		world.setBlock(i + 15, j + 5, k + 9, DivineRPGTwilight.karosBricks2.blockID);
		world.setBlock(i + 15, j + 5, k + 10, DivineRPGTwilight.karosBricks2.blockID);
		world.setBlock(i + 15, j + 5, k + 11, DivineRPGTwilight.karosBricks2.blockID);
		world.setBlock(i + 15, j + 5, k + 12, DivineRPGTwilight.karosBricks2.blockID);
		world.setBlock(i + 15, j + 5, k + 13, DivineRPGTwilight.karosBricks2.blockID);
		world.setBlock(i + 15, j + 5, k + 14, DivineRPGTwilight.karosBricks.blockID);
		world.setBlock(i + 15, j + 5, k + 15, DivineRPGTwilight.karosBricks2.blockID);
		world.setBlock(i + 15, j + 5, k + 16, DivineRPGTwilight.karosBricks.blockID);
		world.setBlock(i + 16, j + 0, k + 0, DivineRPGTwilight.karosBricks2.blockID);
		world.setBlock(i + 16, j + 0, k + 1, DivineRPGTwilight.karosBricks2.blockID);
		world.setBlock(i + 16, j + 0, k + 2, DivineRPGTwilight.karosHeatTileGreen.blockID);
		world.setBlock(i + 16, j + 0, k + 3, DivineRPGTwilight.karosHeatTileGreen.blockID);
		world.setBlock(i + 16, j + 0, k + 4, DivineRPGTwilight.karosHeatTileRed.blockID);
		world.setBlock(i + 16, j + 0, k + 5, DivineRPGTwilight.karosHeatTileRed.blockID);
		world.setBlock(i + 16, j + 0, k + 6, DivineRPGTwilight.karosHeatTileGreen.blockID);
		world.setBlock(i + 16, j + 0, k + 7, DivineRPGTwilight.karosHeatTileGreen.blockID);
		world.setBlock(i + 16, j + 0, k + 8, DivineRPGTwilight.karosHeatTileRed.blockID);
		world.setBlock(i + 16, j + 0, k + 9, DivineRPGTwilight.karosHeatTileRed.blockID);
		world.setBlock(i + 16, j + 0, k + 10, DivineRPGTwilight.karosHeatTileGreen.blockID);
		world.setBlock(i + 16, j + 0, k + 11, DivineRPGTwilight.karosHeatTileGreen.blockID);
		world.setBlock(i + 16, j + 0, k + 12, DivineRPGTwilight.karosHeatTileRed.blockID);
		world.setBlock(i + 16, j + 0, k + 13, DivineRPGTwilight.karosHeatTileRed.blockID);
		world.setBlock(i + 16, j + 0, k + 14, DivineRPGTwilight.karosHeatTileGreen.blockID);
		world.setBlock(i + 16, j + 0, k + 15, DivineRPGTwilight.karosHeatTileGreen.blockID);
		world.setBlock(i + 16, j + 0, k + 16, DivineRPGTwilight.karosHeatTileRed.blockID);
		world.setBlock(i + 16, j + 0, k + 17, DivineRPGTwilight.karosHeatTileRed.blockID);
		world.setBlock(i + 16, j + 0, k + 18, DivineRPGTwilight.karosBricks2.blockID);
		world.setBlock(i + 16, j + 0, k + 19, DivineRPGTwilight.karosBricks2.blockID);
		world.setBlock(i + 16, j + 1, k + 0, DivineRPGTwilight.karosBricks2.blockID);
		world.setBlock(i + 16, j + 1, k + 1, DivineRPGTwilight.karosBricks2.blockID);
		world.setBlock(i + 16, j + 1, k + 18, DivineRPGTwilight.karosBricks2.blockID);
		world.setBlock(i + 16, j + 1, k + 19, DivineRPGTwilight.karosBricks2.blockID);
		world.setBlock(i + 16, j + 2, k + 0, DivineRPGTwilight.karosBricks2.blockID);
		world.setBlockAndMetadata(i + 16, j + 2, k + 1, DivineRPGTwilight.karosCannon.blockID, 3);
		world.setBlockAndMetadata(i + 16, j + 2, k + 18, DivineRPGTwilight.karosCannon.blockID, 2);
		world.setBlock(i + 16, j + 2, k + 19, DivineRPGTwilight.karosBricks2.blockID);
		world.setBlock(i + 16, j + 3, k + 1, DivineRPGTwilight.karosBricks.blockID);
		world.setBlock(i + 16, j + 3, k + 18, DivineRPGTwilight.karosBricks.blockID);
		world.setBlock(i + 16, j + 4, k + 2, DivineRPGTwilight.karosBricks.blockID);
		world.setBlock(i + 16, j + 4, k + 17, DivineRPGTwilight.karosBricks.blockID);
		world.setBlock(i + 16, j + 5, k + 3, DivineRPGTwilight.karosBricks.blockID);
		world.setBlock(i + 16, j + 5, k + 4, DivineRPGTwilight.karosBricks2.blockID);
		world.setBlock(i + 16, j + 5, k + 5, DivineRPGTwilight.karosBricks.blockID);
		world.setBlock(i + 16, j + 5, k + 6, DivineRPGTwilight.karosBricks2.blockID);
		world.setBlock(i + 16, j + 5, k + 7, DivineRPGTwilight.karosBricks.blockID);
		world.setBlock(i + 16, j + 5, k + 8, DivineRPGTwilight.karosBricks2.blockID);
		world.setBlock(i + 16, j + 5, k + 9, DivineRPGTwilight.karosBricks2.blockID);
		world.setBlock(i + 16, j + 5, k + 10, DivineRPGTwilight.karosBricks2.blockID);
		world.setBlock(i + 16, j + 5, k + 11, DivineRPGTwilight.karosBricks.blockID);
		world.setBlock(i + 16, j + 5, k + 12, DivineRPGTwilight.karosBricks2.blockID);
		world.setBlock(i + 16, j + 5, k + 13, DivineRPGTwilight.karosBricks2.blockID);
		world.setBlock(i + 16, j + 5, k + 14, DivineRPGTwilight.karosBricks.blockID);
		world.setBlock(i + 16, j + 5, k + 15, DivineRPGTwilight.karosBricks2.blockID);
		world.setBlock(i + 16, j + 5, k + 16, DivineRPGTwilight.karosBricks.blockID);
		world.setBlock(i + 17, j + 0, k + 1, DivineRPGTwilight.karosBricks2.blockID);
		world.setBlock(i + 17, j + 0, k + 2, DivineRPGTwilight.karosHeatTileRed.blockID);
		world.setBlock(i + 17, j + 0, k + 3, DivineRPGTwilight.karosHeatTileRed.blockID);
		world.setBlock(i + 17, j + 0, k + 4, DivineRPGTwilight.karosHeatTileGreen.blockID);
		world.setBlock(i + 17, j + 0, k + 5, DivineRPGTwilight.karosHeatTileGreen.blockID);
		world.setBlock(i + 17, j + 0, k + 6, DivineRPGTwilight.karosHeatTileRed.blockID);
		world.setBlock(i + 17, j + 0, k + 7, DivineRPGTwilight.karosHeatTileRed.blockID);
		world.setBlock(i + 17, j + 0, k + 8, DivineRPGTwilight.karosHeatTileGreen.blockID);
		world.setBlock(i + 17, j + 0, k + 9, DivineRPGTwilight.karosHeatTileGreen.blockID);
		world.setBlock(i + 17, j + 0, k + 10, DivineRPGTwilight.karosHeatTileRed.blockID);
		world.setBlock(i + 17, j + 0, k + 11, DivineRPGTwilight.karosHeatTileRed.blockID);
		world.setBlock(i + 17, j + 0, k + 12, DivineRPGTwilight.karosHeatTileGreen.blockID);
		world.setBlock(i + 17, j + 0, k + 13, DivineRPGTwilight.karosHeatTileGreen.blockID);
		world.setBlock(i + 17, j + 0, k + 14, DivineRPGTwilight.karosHeatTileRed.blockID);
		world.setBlock(i + 17, j + 0, k + 15, DivineRPGTwilight.karosHeatTileRed.blockID);
		world.setBlock(i + 17, j + 0, k + 16, DivineRPGTwilight.karosHeatTileGreen.blockID);
		world.setBlock(i + 17, j + 0, k + 17, DivineRPGTwilight.karosHeatTileGreen.blockID);
		world.setBlock(i + 17, j + 0, k + 18, DivineRPGTwilight.karosBricks2.blockID);
		world.setBlock(i + 17, j + 1, k + 1, DivineRPGTwilight.karosBricks2.blockID);
		world.setBlock(i + 17, j + 1, k + 18, DivineRPGTwilight.karosBricks2.blockID);
		world.setBlock(i + 17, j + 2, k + 1, DivineRPGTwilight.karosBricks.blockID);
		world.setBlock(i + 17, j + 2, k + 18, DivineRPGTwilight.karosBricks.blockID);
		world.setBlock(i + 17, j + 3, k + 1, DivineRPGTwilight.karosBricks.blockID);
		world.setBlock(i + 17, j + 3, k + 18, DivineRPGTwilight.karosBricks.blockID);
		world.setBlock(i + 17, j + 4, k + 2, DivineRPGTwilight.karosBricks.blockID);
		world.setBlock(i + 17, j + 4, k + 17, DivineRPGTwilight.karosBricks.blockID);
		world.setBlock(i + 17, j + 5, k + 3, DivineRPGTwilight.karosBricks.blockID);
		world.setBlock(i + 17, j + 5, k + 4, DivineRPGTwilight.karosBricks2.blockID);
		world.setBlock(i + 17, j + 5, k + 5, DivineRPGTwilight.karosBricks.blockID);
		world.setBlock(i + 17, j + 5, k + 6, DivineRPGTwilight.karosBricks2.blockID);
		world.setBlock(i + 17, j + 5, k + 7, DivineRPGTwilight.karosBricks.blockID);
		world.setBlock(i + 17, j + 5, k + 8, DivineRPGTwilight.karosBricks2.blockID);
		world.setBlock(i + 17, j + 5, k + 9, DivineRPGTwilight.karosBricks2.blockID);
		world.setBlock(i + 17, j + 5, k + 10, DivineRPGTwilight.karosBricks.blockID);
		world.setBlock(i + 17, j + 5, k + 11, DivineRPGTwilight.karosBricks2.blockID);
		world.setBlock(i + 17, j + 5, k + 12, DivineRPGTwilight.karosBricks2.blockID);
		world.setBlock(i + 17, j + 5, k + 13, DivineRPGTwilight.karosBricks2.blockID);
		world.setBlock(i + 17, j + 5, k + 14, DivineRPGTwilight.karosBricks.blockID);
		world.setBlock(i + 17, j + 5, k + 15, DivineRPGTwilight.karosBricks2.blockID);
		world.setBlock(i + 17, j + 5, k + 16, DivineRPGTwilight.karosBricks.blockID);
		world.setBlock(i + 18, j + 0, k + 0, DivineRPGTwilight.karosBricks2.blockID);
		world.setBlock(i + 18, j + 0, k + 1, DivineRPGTwilight.karosBricks2.blockID);
		world.setBlock(i + 18, j + 0, k + 2, DivineRPGTwilight.karosHeatTileRed.blockID);
		world.setBlock(i + 18, j + 0, k + 3, DivineRPGTwilight.karosHeatTileRed.blockID);
		world.setBlock(i + 18, j + 0, k + 4, DivineRPGTwilight.karosHeatTileGreen.blockID);
		world.setBlock(i + 18, j + 0, k + 5, DivineRPGTwilight.karosHeatTileGreen.blockID);
		world.setBlock(i + 18, j + 0, k + 6, DivineRPGTwilight.karosHeatTileRed.blockID);
		world.setBlock(i + 18, j + 0, k + 7, DivineRPGTwilight.karosHeatTileRed.blockID);
		world.setBlock(i + 18, j + 0, k + 8, DivineRPGTwilight.karosHeatTileGreen.blockID);
		world.setBlock(i + 18, j + 0, k + 9, DivineRPGTwilight.karosHeatTileGreen.blockID);
		world.setBlock(i + 18, j + 0, k + 10, DivineRPGTwilight.karosHeatTileRed.blockID);
		world.setBlock(i + 18, j + 0, k + 11, DivineRPGTwilight.karosHeatTileRed.blockID);
		world.setBlock(i + 18, j + 0, k + 12, DivineRPGTwilight.karosHeatTileGreen.blockID);
		world.setBlock(i + 18, j + 0, k + 13, DivineRPGTwilight.karosHeatTileGreen.blockID);
		world.setBlock(i + 18, j + 0, k + 14, DivineRPGTwilight.karosHeatTileRed.blockID);
		world.setBlock(i + 18, j + 0, k + 15, DivineRPGTwilight.karosHeatTileRed.blockID);
		world.setBlock(i + 18, j + 0, k + 16, DivineRPGTwilight.karosHeatTileGreen.blockID);
		world.setBlock(i + 18, j + 0, k + 17, DivineRPGTwilight.karosHeatTileGreen.blockID);
		world.setBlock(i + 18, j + 0, k + 18, DivineRPGTwilight.karosBricks2.blockID);
		world.setBlock(i + 18, j + 0, k + 19, DivineRPGTwilight.karosBricks2.blockID);
		world.setBlock(i + 18, j + 1, k + 0, DivineRPGTwilight.karosBricks2.blockID);
		world.setBlock(i + 18, j + 1, k + 1, DivineRPGTwilight.karosBricks2.blockID);
		world.setBlock(i + 18, j + 1, k + 18, DivineRPGTwilight.karosBricks2.blockID);
		world.setBlock(i + 18, j + 1, k + 19, DivineRPGTwilight.karosBricks2.blockID);
		world.setBlock(i + 18, j + 2, k + 0, DivineRPGTwilight.karosBricks2.blockID);
		world.setBlockAndMetadata(i + 18, j + 2, k + 1, DivineRPGTwilight.karosCannon.blockID, 3);
		world.setBlockAndMetadata(i + 18, j + 2, k + 18, DivineRPGTwilight.karosCannon.blockID, 2);
		world.setBlock(i + 18, j + 2, k + 19, DivineRPGTwilight.karosBricks2.blockID);
		world.setBlock(i + 18, j + 3, k + 1, DivineRPGTwilight.karosBricks.blockID);
		world.setBlock(i + 18, j + 3, k + 18, DivineRPGTwilight.karosBricks.blockID);
		world.setBlock(i + 18, j + 4, k + 2, DivineRPGTwilight.karosBricks.blockID);
		world.setBlock(i + 18, j + 4, k + 9, DivineRPGTwilight.helioticBeam.blockID);
		world.setBlock(i + 18, j + 4, k + 10, DivineRPGTwilight.helioticBeam.blockID);
		world.setBlock(i + 18, j + 4, k + 11, DivineRPGTwilight.helioticBeam.blockID);
		world.setBlock(i + 18, j + 4, k + 17, DivineRPGTwilight.karosBricks.blockID);
		world.setBlock(i + 18, j + 5, k + 3, DivineRPGTwilight.karosBricks.blockID);
		world.setBlock(i + 18, j + 5, k + 4, DivineRPGTwilight.karosBricks2.blockID);
		world.setBlock(i + 18, j + 5, k + 5, DivineRPGTwilight.karosBricks.blockID);
		world.setBlock(i + 18, j + 5, k + 6, DivineRPGTwilight.karosBricks2.blockID);
		world.setBlock(i + 18, j + 5, k + 7, DivineRPGTwilight.karosBricks.blockID);
		world.setBlock(i + 18, j + 5, k + 8, DivineRPGTwilight.karosBricks2.blockID);
		world.setBlock(i + 18, j + 5, k + 9, DivineRPGTwilight.karosBricks.blockID);
		world.setBlock(i + 18, j + 5, k + 10, DivineRPGTwilight.karosBricks2.blockID);
		world.setBlock(i + 18, j + 5, k + 11, DivineRPGTwilight.karosBricks2.blockID);
		world.setBlock(i + 18, j + 5, k + 12, DivineRPGTwilight.karosBricks2.blockID);
		world.setBlock(i + 18, j + 5, k + 13, DivineRPGTwilight.karosBricks2.blockID);
		world.setBlock(i + 18, j + 5, k + 14, DivineRPGTwilight.karosBricks.blockID);
		world.setBlock(i + 18, j + 5, k + 15, DivineRPGTwilight.karosBricks2.blockID);
		world.setBlock(i + 18, j + 5, k + 16, DivineRPGTwilight.karosBricks.blockID);
		world.setBlock(i + 19, j + 0, k + 1, DivineRPGTwilight.karosBricks2.blockID);
		world.setBlock(i + 19, j + 0, k + 2, DivineRPGTwilight.karosHeatTileGreen.blockID);
		world.setBlock(i + 19, j + 0, k + 3, DivineRPGTwilight.karosHeatTileGreen.blockID);
		world.setBlock(i + 19, j + 0, k + 4, DivineRPGTwilight.karosHeatTileRed.blockID);
		world.setBlock(i + 19, j + 0, k + 5, DivineRPGTwilight.karosHeatTileRed.blockID);
		world.setBlock(i + 19, j + 0, k + 6, DivineRPGTwilight.karosHeatTileGreen.blockID);
		world.setBlock(i + 19, j + 0, k + 7, DivineRPGTwilight.karosHeatTileGreen.blockID);
		world.setBlock(i + 19, j + 0, k + 8, DivineRPGTwilight.karosHeatTileRed.blockID);
		world.setBlock(i + 19, j + 0, k + 9, DivineRPGTwilight.karosHeatTileRed.blockID);
		world.setBlock(i + 19, j + 0, k + 10, DivineRPGTwilight.karosHeatTileGreen.blockID);
		world.setBlock(i + 19, j + 0, k + 11, DivineRPGTwilight.karosHeatTileGreen.blockID);
		world.setBlock(i + 19, j + 0, k + 12, DivineRPGTwilight.karosHeatTileRed.blockID);
		world.setBlock(i + 19, j + 0, k + 13, DivineRPGTwilight.karosHeatTileRed.blockID);
		world.setBlock(i + 19, j + 0, k + 14, DivineRPGTwilight.karosHeatTileGreen.blockID);
		world.setBlock(i + 19, j + 0, k + 15, DivineRPGTwilight.karosHeatTileGreen.blockID);
		world.setBlock(i + 19, j + 0, k + 16, DivineRPGTwilight.karosHeatTileRed.blockID);
		world.setBlock(i + 19, j + 0, k + 17, DivineRPGTwilight.karosHeatTileRed.blockID);
		world.setBlock(i + 19, j + 0, k + 18, DivineRPGTwilight.karosBricks2.blockID);
		world.setBlock(i + 19, j + 1, k + 1, DivineRPGTwilight.karosBricks2.blockID);
		world.setBlock(i + 19, j + 1, k + 18, DivineRPGTwilight.karosBricks2.blockID);
		world.setBlock(i + 19, j + 2, k + 1, DivineRPGTwilight.karosBricks.blockID);
		world.setBlock(i + 19, j + 2, k + 18, DivineRPGTwilight.karosBricks.blockID);
		world.setBlock(i + 19, j + 3, k + 1, DivineRPGTwilight.karosBricks.blockID);
		world.setBlock(i + 19, j + 3, k + 18, DivineRPGTwilight.karosBricks.blockID);
		world.setBlock(i + 19, j + 4, k + 2, DivineRPGTwilight.karosBricks.blockID);
		world.setBlock(i + 19, j + 4, k + 9, DivineRPGTwilight.helioticBeam.blockID);
		world.setBlock(i + 19, j + 4, k + 10, DivineRPGTwilight.helioticBeam.blockID);
		world.setBlock(i + 19, j + 4, k + 11, DivineRPGTwilight.helioticBeam.blockID);
		world.setBlock(i + 19, j + 4, k + 17, DivineRPGTwilight.karosBricks.blockID);
		world.setBlock(i + 19, j + 5, k + 3, DivineRPGTwilight.karosBricks.blockID);
		world.setBlock(i + 19, j + 5, k + 4, DivineRPGTwilight.karosBricks2.blockID);
		world.setBlock(i + 19, j + 5, k + 5, DivineRPGTwilight.karosBricks.blockID);
		world.setBlock(i + 19, j + 5, k + 6, DivineRPGTwilight.karosBricks2.blockID);
		world.setBlock(i + 19, j + 5, k + 7, DivineRPGTwilight.karosBricks.blockID);
		world.setBlock(i + 19, j + 5, k + 8, DivineRPGTwilight.karosBricks.blockID);
		world.setBlock(i + 19, j + 5, k + 9, DivineRPGTwilight.karosBricks2.blockID);
		world.setBlock(i + 19, j + 5, k + 10, DivineRPGTwilight.karosBricks2.blockID);
		world.setBlock(i + 19, j + 5, k + 11, DivineRPGTwilight.karosBricks2.blockID);
		world.setBlock(i + 19, j + 5, k + 12, DivineRPGTwilight.karosBricks2.blockID);
		world.setBlock(i + 19, j + 5, k + 13, DivineRPGTwilight.karosBricks2.blockID);
		world.setBlock(i + 19, j + 5, k + 14, DivineRPGTwilight.karosBricks.blockID);
		world.setBlock(i + 19, j + 5, k + 15, DivineRPGTwilight.karosBricks2.blockID);
		world.setBlock(i + 19, j + 5, k + 16, DivineRPGTwilight.karosBricks.blockID);
		world.setBlock(i + 20, j + 0, k + 0, DivineRPGTwilight.karosBricks2.blockID);
		world.setBlock(i + 20, j + 0, k + 1, DivineRPGTwilight.karosBricks2.blockID);
		world.setBlock(i + 20, j + 0, k + 2, DivineRPGTwilight.karosHeatTileGreen.blockID);
		world.setBlock(i + 20, j + 0, k + 3, DivineRPGTwilight.karosHeatTileGreen.blockID);
		world.setBlock(i + 20, j + 0, k + 4, DivineRPGTwilight.karosHeatTileRed.blockID);
		world.setBlock(i + 20, j + 0, k + 5, DivineRPGTwilight.karosHeatTileRed.blockID);
		world.setBlock(i + 20, j + 0, k + 6, DivineRPGTwilight.karosHeatTileGreen.blockID);
		world.setBlock(i + 20, j + 0, k + 7, DivineRPGTwilight.karosHeatTileGreen.blockID);
		world.setBlock(i + 20, j + 0, k + 8, DivineRPGTwilight.karosHeatTileRed.blockID);
		world.setBlock(i + 20, j + 0, k + 9, DivineRPGTwilight.karosHeatTileRed.blockID);
		world.setBlock(i + 20, j + 0, k + 10, DivineRPGTwilight.karosHeatTileGreen.blockID);
		world.setBlock(i + 20, j + 0, k + 11, DivineRPGTwilight.karosHeatTileGreen.blockID);
		world.setBlock(i + 20, j + 0, k + 12, DivineRPGTwilight.karosHeatTileRed.blockID);
		world.setBlock(i + 20, j + 0, k + 13, DivineRPGTwilight.karosHeatTileRed.blockID);
		world.setBlock(i + 20, j + 0, k + 14, DivineRPGTwilight.karosHeatTileGreen.blockID);
		world.setBlock(i + 20, j + 0, k + 15, DivineRPGTwilight.karosHeatTileGreen.blockID);
		world.setBlock(i + 20, j + 0, k + 16, DivineRPGTwilight.karosHeatTileRed.blockID);
		world.setBlock(i + 20, j + 0, k + 17, DivineRPGTwilight.karosHeatTileRed.blockID);
		world.setBlock(i + 20, j + 0, k + 18, DivineRPGTwilight.karosBricks2.blockID);
		world.setBlock(i + 20, j + 0, k + 19, DivineRPGTwilight.karosBricks2.blockID);
		world.setBlock(i + 20, j + 1, k + 0, DivineRPGTwilight.karosBricks2.blockID);
		world.setBlock(i + 20, j + 1, k + 1, DivineRPGTwilight.karosBricks2.blockID);
		world.setBlock(i + 20, j + 1, k + 18, DivineRPGTwilight.karosBricks2.blockID);
		world.setBlock(i + 20, j + 1, k + 19, DivineRPGTwilight.karosBricks2.blockID);
		world.setBlock(i + 20, j + 2, k + 0, DivineRPGTwilight.karosBricks2.blockID);
		world.setBlockAndMetadata(i + 20, j + 2, k + 1, DivineRPGTwilight.karosCannon.blockID, 3);
		world.setBlockAndMetadata(i + 20, j + 2, k + 18, DivineRPGTwilight.karosCannon.blockID, 2);
		world.setBlock(i + 20, j + 2, k + 19, DivineRPGTwilight.karosBricks2.blockID);
		world.setBlock(i + 20, j + 3, k + 1, DivineRPGTwilight.karosBricks.blockID);
		world.setBlock(i + 20, j + 3, k + 18, DivineRPGTwilight.karosBricks.blockID);
		world.setBlock(i + 20, j + 4, k + 2, DivineRPGTwilight.karosBricks.blockID);
		world.setBlock(i + 20, j + 4, k + 9, DivineRPGTwilight.helioticBeam.blockID);
		world.setBlock(i + 20, j + 4, k + 10, DivineRPGTwilight.helioticBeam.blockID);
		world.setBlock(i + 20, j + 4, k + 11, DivineRPGTwilight.helioticBeam.blockID);
		world.setBlock(i + 20, j + 4, k + 17, DivineRPGTwilight.karosBricks.blockID);
		world.setBlock(i + 20, j + 5, k + 3, DivineRPGTwilight.karosBricks.blockID);
		world.setBlock(i + 20, j + 5, k + 4, DivineRPGTwilight.karosBricks2.blockID);
		world.setBlock(i + 20, j + 5, k + 5, DivineRPGTwilight.karosBricks.blockID);
		world.setBlock(i + 20, j + 5, k + 6, DivineRPGTwilight.karosBricks2.blockID);
		world.setBlock(i + 20, j + 5, k + 7, DivineRPGTwilight.karosBricks.blockID);
		world.setBlock(i + 20, j + 5, k + 8, DivineRPGTwilight.karosBricks2.blockID);
		world.setBlock(i + 20, j + 5, k + 9, DivineRPGTwilight.karosBricks2.blockID);
		world.setBlock(i + 20, j + 5, k + 10, DivineRPGTwilight.karosBricks2.blockID);
		world.setBlock(i + 20, j + 5, k + 11, DivineRPGTwilight.karosBricks2.blockID);
		world.setBlock(i + 20, j + 5, k + 12, DivineRPGTwilight.karosBricks2.blockID);
		world.setBlock(i + 20, j + 5, k + 13, DivineRPGTwilight.karosBricks2.blockID);
		world.setBlock(i + 20, j + 5, k + 14, DivineRPGTwilight.karosBricks.blockID);
		world.setBlock(i + 20, j + 5, k + 15, DivineRPGTwilight.karosBricks2.blockID);
		world.setBlock(i + 20, j + 5, k + 16, DivineRPGTwilight.karosBricks.blockID);
		world.setBlock(i + 21, j + 0, k + 1, DivineRPGTwilight.karosBricks2.blockID);
		world.setBlock(i + 21, j + 0, k + 2, DivineRPGTwilight.karosHeatTileRed.blockID);
		world.setBlock(i + 21, j + 0, k + 3, DivineRPGTwilight.karosHeatTileRed.blockID);
		world.setBlock(i + 21, j + 0, k + 4, DivineRPGTwilight.karosHeatTileGreen.blockID);
		world.setBlock(i + 21, j + 0, k + 5, DivineRPGTwilight.karosHeatTileGreen.blockID);
		world.setBlock(i + 21, j + 0, k + 6, DivineRPGTwilight.karosHeatTileRed.blockID);
		world.setBlock(i + 21, j + 0, k + 7, DivineRPGTwilight.karosHeatTileRed.blockID);
		world.setBlock(i + 21, j + 0, k + 8, DivineRPGTwilight.karosHeatTileGreen.blockID);
		world.setBlock(i + 21, j + 0, k + 9, DivineRPGTwilight.karosHeatTileGreen.blockID);
		world.setBlock(i + 21, j + 0, k + 10, DivineRPGTwilight.karosHeatTileRed.blockID);
		world.setBlock(i + 21, j + 0, k + 11, DivineRPGTwilight.karosHeatTileRed.blockID);
		world.setBlock(i + 21, j + 0, k + 12, DivineRPGTwilight.karosHeatTileGreen.blockID);
		world.setBlock(i + 21, j + 0, k + 13, DivineRPGTwilight.karosHeatTileGreen.blockID);
		world.setBlock(i + 21, j + 0, k + 14, DivineRPGTwilight.karosHeatTileRed.blockID);
		world.setBlock(i + 21, j + 0, k + 15, DivineRPGTwilight.karosHeatTileRed.blockID);
		world.setBlock(i + 21, j + 0, k + 16, DivineRPGTwilight.karosHeatTileGreen.blockID);
		world.setBlock(i + 21, j + 0, k + 17, DivineRPGTwilight.karosHeatTileGreen.blockID);
		world.setBlock(i + 21, j + 0, k + 18, DivineRPGTwilight.karosBricks2.blockID);
		world.setBlock(i + 21, j + 1, k + 1, DivineRPGTwilight.karosBricks2.blockID);
		world.setBlock(i + 21, j + 1, k + 18, DivineRPGTwilight.karosBricks2.blockID);
		world.setBlock(i + 21, j + 2, k + 1, DivineRPGTwilight.karosBricks.blockID);
		world.setBlock(i + 21, j + 2, k + 18, DivineRPGTwilight.karosBricks.blockID);
		world.setBlock(i + 21, j + 3, k + 1, DivineRPGTwilight.karosBricks.blockID);
		world.setBlock(i + 21, j + 3, k + 18, DivineRPGTwilight.karosBricks.blockID);
		world.setBlock(i + 21, j + 4, k + 2, DivineRPGTwilight.karosBricks.blockID);
		world.setBlock(i + 21, j + 4, k + 17, DivineRPGTwilight.karosBricks.blockID);
		world.setBlock(i + 21, j + 5, k + 3, DivineRPGTwilight.karosBricks.blockID);
		world.setBlock(i + 21, j + 5, k + 4, DivineRPGTwilight.karosBricks2.blockID);
		world.setBlock(i + 21, j + 5, k + 5, DivineRPGTwilight.karosBricks.blockID);
		world.setBlock(i + 21, j + 5, k + 6, DivineRPGTwilight.karosBricks2.blockID);
		world.setBlock(i + 21, j + 5, k + 7, DivineRPGTwilight.karosBricks.blockID);
		world.setBlock(i + 21, j + 5, k + 8, DivineRPGTwilight.karosBricks.blockID);
		world.setBlock(i + 21, j + 5, k + 9, DivineRPGTwilight.karosBricks2.blockID);
		world.setBlock(i + 21, j + 5, k + 10, DivineRPGTwilight.karosBricks2.blockID);
		world.setBlock(i + 21, j + 5, k + 11, DivineRPGTwilight.karosBricks2.blockID);
		world.setBlock(i + 21, j + 5, k + 12, DivineRPGTwilight.karosBricks2.blockID);
		world.setBlock(i + 21, j + 5, k + 13, DivineRPGTwilight.karosBricks2.blockID);
		world.setBlock(i + 21, j + 5, k + 14, DivineRPGTwilight.karosBricks.blockID);
		world.setBlock(i + 21, j + 5, k + 15, DivineRPGTwilight.karosBricks2.blockID);
		world.setBlock(i + 21, j + 5, k + 16, DivineRPGTwilight.karosBricks.blockID);
		world.setBlock(i + 22, j + 0, k + 0, DivineRPGTwilight.karosBricks2.blockID);
		world.setBlock(i + 22, j + 0, k + 1, DivineRPGTwilight.karosBricks2.blockID);
		world.setBlock(i + 22, j + 0, k + 2, DivineRPGTwilight.karosHeatTileRed.blockID);
		world.setBlock(i + 22, j + 0, k + 3, DivineRPGTwilight.karosHeatTileRed.blockID);
		world.setBlock(i + 22, j + 0, k + 4, DivineRPGTwilight.karosHeatTileGreen.blockID);
		world.setBlock(i + 22, j + 0, k + 5, DivineRPGTwilight.karosHeatTileGreen.blockID);
		world.setBlock(i + 22, j + 0, k + 6, DivineRPGTwilight.karosHeatTileRed.blockID);
		world.setBlock(i + 22, j + 0, k + 7, DivineRPGTwilight.karosHeatTileRed.blockID);
		world.setBlock(i + 22, j + 0, k + 8, DivineRPGTwilight.karosHeatTileGreen.blockID);
		world.setBlock(i + 22, j + 0, k + 9, DivineRPGTwilight.karosHeatTileGreen.blockID);
		world.setBlock(i + 22, j + 0, k + 10, DivineRPGTwilight.karosHeatTileRed.blockID);
		world.setBlock(i + 22, j + 0, k + 11, DivineRPGTwilight.karosHeatTileRed.blockID);
		world.setBlock(i + 22, j + 0, k + 12, DivineRPGTwilight.karosHeatTileGreen.blockID);
		world.setBlock(i + 22, j + 0, k + 13, DivineRPGTwilight.karosHeatTileGreen.blockID);
		world.setBlock(i + 22, j + 0, k + 14, DivineRPGTwilight.karosHeatTileRed.blockID);
		world.setBlock(i + 22, j + 0, k + 15, DivineRPGTwilight.karosHeatTileRed.blockID);
		world.setBlock(i + 22, j + 0, k + 16, DivineRPGTwilight.karosHeatTileGreen.blockID);
		world.setBlock(i + 22, j + 0, k + 17, DivineRPGTwilight.karosHeatTileGreen.blockID);
		world.setBlock(i + 22, j + 0, k + 18, DivineRPGTwilight.karosBricks2.blockID);
		world.setBlock(i + 22, j + 0, k + 19, DivineRPGTwilight.karosBricks2.blockID);
		world.setBlock(i + 22, j + 1, k + 0, DivineRPGTwilight.karosBricks2.blockID);
		world.setBlock(i + 22, j + 1, k + 1, DivineRPGTwilight.karosBricks2.blockID);
		world.setBlock(i + 22, j + 1, k + 18, DivineRPGTwilight.karosBricks2.blockID);
		world.setBlock(i + 22, j + 1, k + 19, DivineRPGTwilight.karosBricks2.blockID);
		world.setBlock(i + 22, j + 2, k + 0, DivineRPGTwilight.karosBricks2.blockID);
		world.setBlockAndMetadata(i + 22, j + 2, k + 1, DivineRPGTwilight.karosCannon.blockID, 3);
		world.setBlockAndMetadata(i + 22, j + 2, k + 18, DivineRPGTwilight.karosCannon.blockID, 2);
		world.setBlock(i + 22, j + 2, k + 19, DivineRPGTwilight.karosBricks2.blockID);
		world.setBlock(i + 22, j + 3, k + 1, DivineRPGTwilight.karosBricks.blockID);
		world.setBlock(i + 22, j + 3, k + 18, DivineRPGTwilight.karosBricks.blockID);
		world.setBlock(i + 22, j + 4, k + 2, DivineRPGTwilight.karosBricks.blockID);
		world.setBlock(i + 22, j + 4, k + 12, DivineRPGTwilight.helioticBeam.blockID);
		world.setBlock(i + 22, j + 4, k + 13, DivineRPGTwilight.helioticBeam.blockID);
		world.setBlock(i + 22, j + 4, k + 14, DivineRPGTwilight.helioticBeam.blockID);
		world.setBlock(i + 22, j + 4, k + 17, DivineRPGTwilight.karosBricks.blockID);
		world.setBlock(i + 22, j + 5, k + 3, DivineRPGTwilight.karosBricks.blockID);
		world.setBlock(i + 22, j + 5, k + 4, DivineRPGTwilight.karosBricks2.blockID);
		world.setBlock(i + 22, j + 5, k + 5, DivineRPGTwilight.karosBricks.blockID);
		world.setBlock(i + 22, j + 5, k + 6, DivineRPGTwilight.karosBricks2.blockID);
		world.setBlock(i + 22, j + 5, k + 7, DivineRPGTwilight.karosBricks.blockID);
		world.setBlock(i + 22, j + 5, k + 8, DivineRPGTwilight.karosBricks2.blockID);
		world.setBlock(i + 22, j + 5, k + 9, DivineRPGTwilight.karosBricks.blockID);
		world.setBlock(i + 22, j + 5, k + 10, DivineRPGTwilight.karosBricks2.blockID);
		world.setBlock(i + 22, j + 5, k + 11, DivineRPGTwilight.karosBricks2.blockID);
		world.setBlock(i + 22, j + 5, k + 12, DivineRPGTwilight.karosBricks2.blockID);
		world.setBlock(i + 22, j + 5, k + 13, DivineRPGTwilight.karosBricks2.blockID);
		world.setBlock(i + 22, j + 5, k + 14, DivineRPGTwilight.karosBricks.blockID);
		world.setBlock(i + 22, j + 5, k + 15, DivineRPGTwilight.karosBricks2.blockID);
		world.setBlock(i + 22, j + 5, k + 16, DivineRPGTwilight.karosBricks.blockID);
		world.setBlock(i + 23, j + 0, k + 1, DivineRPGTwilight.karosBricks2.blockID);
		world.setBlock(i + 23, j + 0, k + 2, DivineRPGTwilight.karosHeatTileGreen.blockID);
		world.setBlock(i + 23, j + 0, k + 3, DivineRPGTwilight.karosHeatTileGreen.blockID);
		world.setBlock(i + 23, j + 0, k + 4, DivineRPGTwilight.karosHeatTileRed.blockID);
		world.setBlock(i + 23, j + 0, k + 5, DivineRPGTwilight.karosHeatTileRed.blockID);
		world.setBlock(i + 23, j + 0, k + 6, DivineRPGTwilight.karosHeatTileGreen.blockID);
		world.setBlock(i + 23, j + 0, k + 7, DivineRPGTwilight.karosHeatTileGreen.blockID);
		world.setBlock(i + 23, j + 0, k + 8, DivineRPGTwilight.karosHeatTileRed.blockID);
		world.setBlock(i + 23, j + 0, k + 9, DivineRPGTwilight.karosHeatTileRed.blockID);
		world.setBlock(i + 23, j + 0, k + 10, DivineRPGTwilight.karosHeatTileGreen.blockID);
		world.setBlock(i + 23, j + 0, k + 11, DivineRPGTwilight.karosHeatTileGreen.blockID);
		world.setBlock(i + 23, j + 0, k + 12, DivineRPGTwilight.karosHeatTileRed.blockID);
		world.setBlock(i + 23, j + 0, k + 13, DivineRPGTwilight.karosHeatTileRed.blockID);
		world.setBlock(i + 23, j + 0, k + 14, DivineRPGTwilight.karosHeatTileGreen.blockID);
		world.setBlock(i + 23, j + 0, k + 15, DivineRPGTwilight.karosHeatTileGreen.blockID);
		world.setBlock(i + 23, j + 0, k + 16, DivineRPGTwilight.karosHeatTileRed.blockID);
		world.setBlock(i + 23, j + 0, k + 17, DivineRPGTwilight.karosHeatTileRed.blockID);
		world.setBlock(i + 23, j + 0, k + 18, DivineRPGTwilight.karosBricks2.blockID);
		world.setBlock(i + 23, j + 1, k + 1, DivineRPGTwilight.karosBricks2.blockID);
		world.setBlock(i + 23, j + 1, k + 18, DivineRPGTwilight.karosBricks2.blockID);
		world.setBlock(i + 23, j + 2, k + 1, DivineRPGTwilight.karosBricks.blockID);
		world.setBlock(i + 23, j + 2, k + 18, DivineRPGTwilight.karosBricks.blockID);
		world.setBlock(i + 23, j + 3, k + 1, DivineRPGTwilight.karosBricks.blockID);
		world.setBlock(i + 23, j + 3, k + 18, DivineRPGTwilight.karosBricks.blockID);
		world.setBlock(i + 23, j + 4, k + 2, DivineRPGTwilight.karosBricks.blockID);
		world.setBlock(i + 23, j + 4, k + 4, DivineRPGTwilight.helioticBeam.blockID);
		world.setBlock(i + 23, j + 4, k + 5, DivineRPGTwilight.helioticBeam.blockID);
		world.setBlock(i + 23, j + 4, k + 6, DivineRPGTwilight.helioticBeam.blockID);
		world.setBlock(i + 23, j + 4, k + 12, DivineRPGTwilight.helioticBeam.blockID);
		world.setBlock(i + 23, j + 4, k + 13, DivineRPGTwilight.helioticBeam.blockID);
		world.setBlock(i + 23, j + 4, k + 14, DivineRPGTwilight.helioticBeam.blockID);
		world.setBlock(i + 23, j + 4, k + 17, DivineRPGTwilight.karosBricks.blockID);
		world.setBlock(i + 23, j + 5, k + 3, DivineRPGTwilight.karosBricks.blockID);
		world.setBlock(i + 23, j + 5, k + 4, DivineRPGTwilight.karosBricks2.blockID);
		world.setBlock(i + 23, j + 5, k + 5, DivineRPGTwilight.karosBricks.blockID);
		world.setBlock(i + 23, j + 5, k + 6, DivineRPGTwilight.karosBricks2.blockID);
		world.setBlock(i + 23, j + 5, k + 7, DivineRPGTwilight.karosBricks.blockID);
		world.setBlock(i + 23, j + 5, k + 8, DivineRPGTwilight.karosBricks2.blockID);
		world.setBlock(i + 23, j + 5, k + 9, DivineRPGTwilight.karosBricks2.blockID);
		world.setBlock(i + 23, j + 5, k + 10, DivineRPGTwilight.karosBricks.blockID);
		world.setBlock(i + 23, j + 5, k + 11, DivineRPGTwilight.karosBricks2.blockID);
		world.setBlock(i + 23, j + 5, k + 12, DivineRPGTwilight.karosBricks2.blockID);
		world.setBlock(i + 23, j + 5, k + 13, DivineRPGTwilight.karosBricks2.blockID);
		world.setBlock(i + 23, j + 5, k + 14, DivineRPGTwilight.karosBricks.blockID);
		world.setBlock(i + 23, j + 5, k + 15, DivineRPGTwilight.karosBricks2.blockID);
		world.setBlock(i + 23, j + 5, k + 16, DivineRPGTwilight.karosBricks.blockID);
		world.setBlock(i + 24, j + 0, k + 0, DivineRPGTwilight.karosBricks2.blockID);
		world.setBlock(i + 24, j + 0, k + 1, DivineRPGTwilight.karosBricks2.blockID);
		world.setBlock(i + 24, j + 0, k + 2, DivineRPGTwilight.karosHeatTileGreen.blockID);
		world.setBlock(i + 24, j + 0, k + 3, DivineRPGTwilight.karosHeatTileGreen.blockID);
		world.setBlock(i + 24, j + 0, k + 4, DivineRPGTwilight.karosHeatTileRed.blockID);
		world.setBlock(i + 24, j + 0, k + 5, DivineRPGTwilight.karosHeatTileRed.blockID);
		world.setBlock(i + 24, j + 0, k + 6, DivineRPGTwilight.karosHeatTileGreen.blockID);
		world.setBlock(i + 24, j + 0, k + 7, DivineRPGTwilight.karosHeatTileGreen.blockID);
		world.setBlock(i + 24, j + 0, k + 8, DivineRPGTwilight.karosHeatTileRed.blockID);
		world.setBlock(i + 24, j + 0, k + 9, DivineRPGTwilight.karosHeatTileRed.blockID);
		world.setBlock(i + 24, j + 0, k + 10, DivineRPGTwilight.karosHeatTileGreen.blockID);
		world.setBlock(i + 24, j + 0, k + 11, DivineRPGTwilight.karosHeatTileGreen.blockID);
		world.setBlock(i + 24, j + 0, k + 12, DivineRPGTwilight.karosHeatTileRed.blockID);
		world.setBlock(i + 24, j + 0, k + 13, DivineRPGTwilight.karosHeatTileRed.blockID);
		world.setBlock(i + 24, j + 0, k + 14, DivineRPGTwilight.karosHeatTileGreen.blockID);
		world.setBlock(i + 24, j + 0, k + 15, DivineRPGTwilight.karosHeatTileGreen.blockID);
		world.setBlock(i + 24, j + 0, k + 16, DivineRPGTwilight.karosHeatTileRed.blockID);
		world.setBlock(i + 24, j + 0, k + 17, DivineRPGTwilight.karosHeatTileRed.blockID);
		world.setBlock(i + 24, j + 0, k + 18, DivineRPGTwilight.karosBricks2.blockID);
		world.setBlock(i + 24, j + 0, k + 19, DivineRPGTwilight.karosBricks2.blockID);
		world.setBlock(i + 24, j + 1, k + 0, DivineRPGTwilight.karosBricks2.blockID);
		world.setBlock(i + 24, j + 1, k + 1, DivineRPGTwilight.karosBricks2.blockID);
		world.setBlock(i + 24, j + 1, k + 18, DivineRPGTwilight.karosBricks2.blockID);
		world.setBlock(i + 24, j + 1, k + 19, DivineRPGTwilight.karosBricks2.blockID);
		world.setBlock(i + 24, j + 2, k + 0, DivineRPGTwilight.karosBricks2.blockID);
		world.setBlockAndMetadata(i + 24, j + 2, k + 1, DivineRPGTwilight.karosCannon.blockID, 3);
		world.setBlockAndMetadata(i + 24, j + 2, k + 18, DivineRPGTwilight.karosCannon.blockID, 2);
		world.setBlock(i + 24, j + 2, k + 19, DivineRPGTwilight.karosBricks2.blockID);
		world.setBlock(i + 24, j + 3, k + 1, DivineRPGTwilight.karosBricks.blockID);
		world.setBlock(i + 24, j + 3, k + 18, DivineRPGTwilight.karosBricks.blockID);
		world.setBlock(i + 24, j + 4, k + 2, DivineRPGTwilight.karosBricks.blockID);
		world.setBlock(i + 24, j + 4, k + 4, DivineRPGTwilight.helioticBeam.blockID);
		world.setBlock(i + 24, j + 4, k + 5, DivineRPGTwilight.helioticBeam.blockID);
		world.setBlock(i + 24, j + 4, k + 6, DivineRPGTwilight.helioticBeam.blockID);
		world.setBlock(i + 24, j + 4, k + 12, DivineRPGTwilight.helioticBeam.blockID);
		world.setBlock(i + 24, j + 4, k + 13, DivineRPGTwilight.helioticBeam.blockID);
		world.setBlock(i + 24, j + 4, k + 14, DivineRPGTwilight.helioticBeam.blockID);
		world.setBlock(i + 24, j + 4, k + 17, DivineRPGTwilight.karosBricks.blockID);
		world.setBlock(i + 24, j + 5, k + 3, DivineRPGTwilight.karosBricks.blockID);
		world.setBlock(i + 24, j + 5, k + 4, DivineRPGTwilight.karosBricks2.blockID);
		world.setBlock(i + 24, j + 5, k + 5, DivineRPGTwilight.karosBricks.blockID);
		world.setBlock(i + 24, j + 5, k + 6, DivineRPGTwilight.karosBricks2.blockID);
		world.setBlock(i + 24, j + 5, k + 7, DivineRPGTwilight.karosBricks2.blockID);
		world.setBlock(i + 24, j + 5, k + 8, DivineRPGTwilight.karosBricks2.blockID);
		world.setBlock(i + 24, j + 5, k + 9, DivineRPGTwilight.karosBricks2.blockID);
		world.setBlock(i + 24, j + 5, k + 10, DivineRPGTwilight.karosBricks2.blockID);
		world.setBlock(i + 24, j + 5, k + 11, DivineRPGTwilight.karosBricks2.blockID);
		world.setBlock(i + 24, j + 5, k + 12, DivineRPGTwilight.karosBricks2.blockID);
		world.setBlock(i + 24, j + 5, k + 13, DivineRPGTwilight.karosBricks2.blockID);
		world.setBlock(i + 24, j + 5, k + 14, DivineRPGTwilight.karosBricks.blockID);
		world.setBlock(i + 24, j + 5, k + 15, DivineRPGTwilight.karosBricks2.blockID);
		world.setBlock(i + 24, j + 5, k + 16, DivineRPGTwilight.karosBricks.blockID);
		world.setBlock(i + 25, j + 0, k + 1, DivineRPGTwilight.karosBricks2.blockID);
		world.setBlock(i + 25, j + 0, k + 2, DivineRPGTwilight.karosHeatTileRed.blockID);
		world.setBlock(i + 25, j + 0, k + 3, DivineRPGTwilight.karosHeatTileRed.blockID);
		world.setBlock(i + 25, j + 0, k + 4, DivineRPGTwilight.karosHeatTileGreen.blockID);
		world.setBlock(i + 25, j + 0, k + 5, DivineRPGTwilight.karosHeatTileGreen.blockID);
		world.setBlock(i + 25, j + 0, k + 6, DivineRPGTwilight.karosHeatTileRed.blockID);
		world.setBlock(i + 25, j + 0, k + 7, DivineRPGTwilight.karosHeatTileRed.blockID);
		world.setBlock(i + 25, j + 0, k + 8, DivineRPGTwilight.karosHeatTileGreen.blockID);
		world.setBlock(i + 25, j + 0, k + 9, DivineRPGTwilight.karosHeatTileGreen.blockID);
		world.setBlock(i + 25, j + 0, k + 10, DivineRPGTwilight.karosHeatTileRed.blockID);
		world.setBlock(i + 25, j + 0, k + 11, DivineRPGTwilight.karosHeatTileRed.blockID);
		world.setBlock(i + 25, j + 0, k + 12, DivineRPGTwilight.karosHeatTileGreen.blockID);
		world.setBlock(i + 25, j + 0, k + 13, DivineRPGTwilight.karosHeatTileGreen.blockID);
		world.setBlock(i + 25, j + 0, k + 14, DivineRPGTwilight.karosHeatTileRed.blockID);
		world.setBlock(i + 25, j + 0, k + 15, DivineRPGTwilight.karosHeatTileRed.blockID);
		world.setBlock(i + 25, j + 0, k + 16, DivineRPGTwilight.karosHeatTileGreen.blockID);
		world.setBlock(i + 25, j + 0, k + 17, DivineRPGTwilight.karosHeatTileGreen.blockID);
		world.setBlock(i + 25, j + 0, k + 18, DivineRPGTwilight.karosBricks2.blockID);
		world.setBlock(i + 25, j + 1, k + 1, DivineRPGTwilight.karosBricks2.blockID);
		world.setBlock(i + 25, j + 1, k + 18, DivineRPGTwilight.karosBricks2.blockID);
		world.setBlock(i + 25, j + 2, k + 1, DivineRPGTwilight.karosBricks.blockID);
		world.setBlock(i + 25, j + 2, k + 18, DivineRPGTwilight.karosBricks.blockID);
		world.setBlock(i + 25, j + 3, k + 1, DivineRPGTwilight.karosBricks.blockID);
		world.setBlock(i + 25, j + 3, k + 18, DivineRPGTwilight.karosBricks.blockID);
		world.setBlock(i + 25, j + 4, k + 2, DivineRPGTwilight.karosBricks.blockID);
		world.setBlock(i + 25, j + 4, k + 4, DivineRPGTwilight.helioticBeam.blockID);
		world.setBlock(i + 25, j + 4, k + 5, DivineRPGTwilight.helioticBeam.blockID);
		world.setBlock(i + 25, j + 4, k + 6, DivineRPGTwilight.helioticBeam.blockID);
		world.setBlock(i + 25, j + 4, k + 17, DivineRPGTwilight.karosBricks.blockID);
		world.setBlock(i + 25, j + 5, k + 3, DivineRPGTwilight.karosBricks.blockID);
		world.setBlock(i + 25, j + 5, k + 4, DivineRPGTwilight.karosBricks2.blockID);
		world.setBlock(i + 25, j + 5, k + 5, DivineRPGTwilight.karosBricks.blockID);
		world.setBlock(i + 25, j + 5, k + 6, DivineRPGTwilight.karosBricks.blockID);
		world.setBlock(i + 25, j + 5, k + 7, DivineRPGTwilight.karosBricks.blockID);
		world.setBlock(i + 25, j + 5, k + 8, DivineRPGTwilight.karosBricks.blockID);
		world.setBlock(i + 25, j + 5, k + 9, DivineRPGTwilight.karosBricks.blockID);
		world.setBlock(i + 25, j + 5, k + 10, DivineRPGTwilight.karosBricks.blockID);
		world.setBlock(i + 25, j + 5, k + 11, DivineRPGTwilight.karosBricks.blockID);
		world.setBlock(i + 25, j + 5, k + 12, DivineRPGTwilight.karosBricks.blockID);
		world.setBlock(i + 25, j + 5, k + 13, DivineRPGTwilight.karosBricks.blockID);
		world.setBlock(i + 25, j + 5, k + 14, DivineRPGTwilight.karosBricks.blockID);
		world.setBlock(i + 25, j + 5, k + 15, DivineRPGTwilight.karosBricks2.blockID);
		world.setBlock(i + 25, j + 5, k + 16, DivineRPGTwilight.karosBricks.blockID);
		world.setBlock(i + 26, j + 0, k + 0, DivineRPGTwilight.karosBricks2.blockID);
		world.setBlock(i + 26, j + 0, k + 1, DivineRPGTwilight.karosBricks2.blockID);
		world.setBlock(i + 26, j + 0, k + 2, DivineRPGTwilight.karosHeatTileRed.blockID);
		world.setBlock(i + 26, j + 0, k + 3, DivineRPGTwilight.karosHeatTileRed.blockID);
		world.setBlock(i + 26, j + 0, k + 4, DivineRPGTwilight.karosHeatTileGreen.blockID);
		world.setBlock(i + 26, j + 0, k + 5, DivineRPGTwilight.karosHeatTileGreen.blockID);
		world.setBlock(i + 26, j + 0, k + 6, DivineRPGTwilight.karosHeatTileRed.blockID);
		world.setBlock(i + 26, j + 0, k + 7, DivineRPGTwilight.karosHeatTileRed.blockID);
		world.setBlock(i + 26, j + 0, k + 8, DivineRPGTwilight.karosHeatTileGreen.blockID);
		world.setBlock(i + 26, j + 0, k + 9, DivineRPGTwilight.karosHeatTileGreen.blockID);
		world.setBlock(i + 26, j + 0, k + 10, DivineRPGTwilight.karosHeatTileRed.blockID);
		world.setBlock(i + 26, j + 0, k + 11, DivineRPGTwilight.karosHeatTileRed.blockID);
		world.setBlock(i + 26, j + 0, k + 12, DivineRPGTwilight.karosHeatTileGreen.blockID);
		world.setBlock(i + 26, j + 0, k + 13, DivineRPGTwilight.karosHeatTileGreen.blockID);
		world.setBlock(i + 26, j + 0, k + 14, DivineRPGTwilight.karosHeatTileRed.blockID);
		world.setBlock(i + 26, j + 0, k + 15, DivineRPGTwilight.karosHeatTileRed.blockID);
		world.setBlock(i + 26, j + 0, k + 16, DivineRPGTwilight.karosHeatTileGreen.blockID);
		world.setBlock(i + 26, j + 0, k + 17, DivineRPGTwilight.karosHeatTileGreen.blockID);
		world.setBlock(i + 26, j + 0, k + 18, DivineRPGTwilight.karosBricks2.blockID);
		world.setBlock(i + 26, j + 0, k + 19, DivineRPGTwilight.karosBricks2.blockID);
		world.setBlock(i + 26, j + 1, k + 0, DivineRPGTwilight.karosBricks2.blockID);
		world.setBlock(i + 26, j + 1, k + 1, DivineRPGTwilight.karosBricks2.blockID);
		world.setBlock(i + 26, j + 1, k + 9, DivineRPGTwilight.villageLamp.blockID);
		world.setBlock(i + 26, j + 1, k + 10, DivineRPGTwilight.villageLamp.blockID);
		world.setBlock(i + 26, j + 1, k + 18, DivineRPGTwilight.karosBricks2.blockID);
		world.setBlock(i + 26, j + 1, k + 19, DivineRPGTwilight.karosBricks2.blockID);
		world.setBlock(i + 26, j + 2, k + 0, DivineRPGTwilight.karosBricks2.blockID);
		world.setBlockAndMetadata(i + 26, j + 2, k + 1, DivineRPGTwilight.karosCannon.blockID, 3);
		world.setBlockAndMetadata(i + 26, j + 2, k + 18, DivineRPGTwilight.karosCannon.blockID, 2);
		world.setBlock(i + 26, j + 2, k + 19, DivineRPGTwilight.karosBricks2.blockID);
		world.setBlock(i + 26, j + 3, k + 1, DivineRPGTwilight.karosBricks.blockID);
		world.setBlock(i + 26, j + 3, k + 18, DivineRPGTwilight.karosBricks.blockID);
		world.setBlock(i + 26, j + 4, k + 2, DivineRPGTwilight.karosBricks.blockID);
		world.setBlock(i + 26, j + 4, k + 17, DivineRPGTwilight.karosBricks.blockID);
		world.setBlock(i + 26, j + 5, k + 3, DivineRPGTwilight.karosBricks.blockID);
		world.setBlock(i + 26, j + 5, k + 4, DivineRPGTwilight.karosBricks2.blockID);
		world.setBlock(i + 26, j + 5, k + 5, DivineRPGTwilight.karosBricks2.blockID);
		world.setBlock(i + 26, j + 5, k + 6, DivineRPGTwilight.karosBricks2.blockID);
		world.setBlock(i + 26, j + 5, k + 7, DivineRPGTwilight.karosBricks2.blockID);
		world.setBlock(i + 26, j + 5, k + 8, DivineRPGTwilight.karosBricks2.blockID);
		world.setBlock(i + 26, j + 5, k + 9, DivineRPGTwilight.karosBricks2.blockID);
		world.setBlock(i + 26, j + 5, k + 10, DivineRPGTwilight.karosBricks2.blockID);
		world.setBlock(i + 26, j + 5, k + 11, DivineRPGTwilight.karosBricks2.blockID);
		world.setBlock(i + 26, j + 5, k + 12, DivineRPGTwilight.karosBricks2.blockID);
		world.setBlock(i + 26, j + 5, k + 13, DivineRPGTwilight.karosBricks2.blockID);
		world.setBlock(i + 26, j + 5, k + 14, DivineRPGTwilight.karosBricks2.blockID);
		world.setBlock(i + 26, j + 5, k + 15, DivineRPGTwilight.karosBricks2.blockID);
		world.setBlock(i + 26, j + 5, k + 16, DivineRPGTwilight.karosBricks.blockID);
		world.setBlock(i + 27, j + 0, k + 1, DivineRPGTwilight.karosBricks2.blockID);
		world.setBlock(i + 27, j + 0, k + 2, DivineRPGTwilight.karosHeatTileGreen.blockID);
		world.setBlock(i + 27, j + 0, k + 3, DivineRPGTwilight.karosHeatTileGreen.blockID);
		world.setBlock(i + 27, j + 0, k + 4, DivineRPGTwilight.karosHeatTileRed.blockID);
		world.setBlock(i + 27, j + 0, k + 5, DivineRPGTwilight.karosHeatTileRed.blockID);
		world.setBlock(i + 27, j + 0, k + 6, DivineRPGTwilight.karosHeatTileGreen.blockID);
		world.setBlock(i + 27, j + 0, k + 7, DivineRPGTwilight.karosHeatTileGreen.blockID);
		world.setBlock(i + 27, j + 0, k + 8, DivineRPGTwilight.karosHeatTileRed.blockID);
		world.setBlock(i + 27, j + 0, k + 9, DivineRPGTwilight.karosHeatTileRed.blockID);
		world.setBlock(i + 27, j + 0, k + 10, DivineRPGTwilight.karosHeatTileGreen.blockID);
		world.setBlock(i + 27, j + 0, k + 11, DivineRPGTwilight.karosHeatTileGreen.blockID);
		world.setBlock(i + 27, j + 0, k + 12, DivineRPGTwilight.karosHeatTileRed.blockID);
		world.setBlock(i + 27, j + 0, k + 13, DivineRPGTwilight.karosHeatTileRed.blockID);
		world.setBlock(i + 27, j + 0, k + 14, DivineRPGTwilight.karosHeatTileGreen.blockID);
		world.setBlock(i + 27, j + 0, k + 15, DivineRPGTwilight.karosHeatTileGreen.blockID);
		world.setBlock(i + 27, j + 0, k + 16, DivineRPGTwilight.karosHeatTileRed.blockID);
		world.setBlock(i + 27, j + 0, k + 17, DivineRPGTwilight.karosHeatTileRed.blockID);
		world.setBlock(i + 27, j + 0, k + 18, DivineRPGTwilight.karosBricks2.blockID);
		world.setBlock(i + 27, j + 1, k + 1, DivineRPGTwilight.karosBricks2.blockID);
		world.setBlock(i + 27, j + 1, k + 9, DivineRPGTwilight.villageLamp.blockID);
		world.setBlock(i + 27, j + 1, k + 10, DivineRPGTwilight.villageLamp.blockID);
		world.setBlock(i + 27, j + 1, k + 18, DivineRPGTwilight.karosBricks2.blockID);
		world.setBlock(i + 27, j + 2, k + 1, DivineRPGTwilight.karosBricks.blockID);
		world.setBlock(i + 27, j + 2, k + 9, DivineRPGTwilight.karosAltar.blockID);
		world.setBlock(i + 27, j + 2, k + 18, DivineRPGTwilight.karosBricks.blockID);
		world.setBlock(i + 27, j + 3, k + 1, DivineRPGTwilight.karosBricks.blockID);
		world.setBlock(i + 27, j + 3, k + 18, DivineRPGTwilight.karosBricks.blockID);
		world.setBlock(i + 27, j + 4, k + 2, DivineRPGTwilight.karosBricks.blockID);
		world.setBlock(i + 27, j + 4, k + 17, DivineRPGTwilight.karosBricks.blockID);
		world.setBlock(i + 27, j + 5, k + 3, DivineRPGTwilight.karosBricks.blockID);
		world.setBlock(i + 27, j + 5, k + 4, DivineRPGTwilight.karosBricks.blockID);
		world.setBlock(i + 27, j + 5, k + 5, DivineRPGTwilight.karosBricks.blockID);
		world.setBlock(i + 27, j + 5, k + 6, DivineRPGTwilight.karosBricks.blockID);
		world.setBlock(i + 27, j + 5, k + 7, DivineRPGTwilight.karosBricks.blockID);
		world.setBlock(i + 27, j + 5, k + 8, DivineRPGTwilight.karosBricks.blockID);
		world.setBlock(i + 27, j + 5, k + 9, DivineRPGTwilight.karosBricks.blockID);
		world.setBlock(i + 27, j + 5, k + 10, DivineRPGTwilight.karosBricks.blockID);
		world.setBlock(i + 27, j + 5, k + 11, DivineRPGTwilight.karosBricks.blockID);
		world.setBlock(i + 27, j + 5, k + 12, DivineRPGTwilight.karosBricks.blockID);
		world.setBlock(i + 27, j + 5, k + 13, DivineRPGTwilight.karosBricks.blockID);
		world.setBlock(i + 27, j + 5, k + 14, DivineRPGTwilight.karosBricks.blockID);
		world.setBlock(i + 27, j + 5, k + 15, DivineRPGTwilight.karosBricks.blockID);
		world.setBlock(i + 27, j + 5, k + 16, DivineRPGTwilight.karosBricks.blockID);
		world.setBlock(i + 28, j + 0, k + 0, DivineRPGTwilight.karosBricks2.blockID);
		world.setBlock(i + 28, j + 0, k + 1, DivineRPGTwilight.karosBricks2.blockID);
		world.setBlock(i + 28, j + 0, k + 2, DivineRPGTwilight.karosHeatTileGreen.blockID);
		world.setBlock(i + 28, j + 0, k + 3, DivineRPGTwilight.karosHeatTileGreen.blockID);
		world.setBlock(i + 28, j + 0, k + 4, DivineRPGTwilight.karosHeatTileRed.blockID);
		world.setBlock(i + 28, j + 0, k + 5, DivineRPGTwilight.karosHeatTileRed.blockID);
		world.setBlock(i + 28, j + 0, k + 6, DivineRPGTwilight.karosHeatTileGreen.blockID);
		world.setBlock(i + 28, j + 0, k + 7, DivineRPGTwilight.karosHeatTileGreen.blockID);
		world.setBlock(i + 28, j + 0, k + 8, DivineRPGTwilight.karosHeatTileRed.blockID);
		world.setBlock(i + 28, j + 0, k + 9, DivineRPGTwilight.karosHeatTileRed.blockID);
		world.setBlock(i + 28, j + 0, k + 10, DivineRPGTwilight.karosHeatTileGreen.blockID);
		world.setBlock(i + 28, j + 0, k + 11, DivineRPGTwilight.karosHeatTileGreen.blockID);
		world.setBlock(i + 28, j + 0, k + 12, DivineRPGTwilight.karosHeatTileRed.blockID);
		world.setBlock(i + 28, j + 0, k + 13, DivineRPGTwilight.karosHeatTileRed.blockID);
		world.setBlock(i + 28, j + 0, k + 14, DivineRPGTwilight.karosHeatTileGreen.blockID);
		world.setBlock(i + 28, j + 0, k + 15, DivineRPGTwilight.karosHeatTileGreen.blockID);
		world.setBlock(i + 28, j + 0, k + 16, DivineRPGTwilight.karosHeatTileRed.blockID);
		world.setBlock(i + 28, j + 0, k + 17, DivineRPGTwilight.karosHeatTileRed.blockID);
		world.setBlock(i + 28, j + 0, k + 18, DivineRPGTwilight.karosBricks2.blockID);
		world.setBlock(i + 28, j + 0, k + 19, DivineRPGTwilight.karosBricks2.blockID);
		world.setBlock(i + 28, j + 1, k + 0, DivineRPGTwilight.karosBricks2.blockID);
		world.setBlock(i + 28, j + 1, k + 1, DivineRPGTwilight.karosBricks2.blockID);
		world.setBlock(i + 28, j + 1, k + 9, DivineRPGTwilight.villageLamp.blockID);
		world.setBlock(i + 28, j + 1, k + 10, DivineRPGTwilight.villageLamp.blockID);
		world.setBlock(i + 28, j + 1, k + 18, DivineRPGTwilight.karosBricks2.blockID);
		world.setBlock(i + 28, j + 1, k + 19, DivineRPGTwilight.karosBricks2.blockID);
		world.setBlock(i + 28, j + 2, k + 0, DivineRPGTwilight.karosBricks2.blockID);
		world.setBlockAndMetadata(i + 28, j + 2, k + 1, DivineRPGTwilight.karosCannon.blockID, 3);
		world.setBlockAndMetadata(i + 28, j + 2, k + 18, DivineRPGTwilight.karosCannon.blockID, 2);
		world.setBlock(i + 28, j + 2, k + 19, DivineRPGTwilight.karosBricks2.blockID);
		world.setBlock(i + 28, j + 3, k + 1, DivineRPGTwilight.karosBricks.blockID);
		world.setBlockAndMetadata(i + 28, j + 3, k + 9, DivineRPGTwilight.karosCannon.blockID, 4);
		world.setBlockAndMetadata(i + 28, j + 3, k + 10, DivineRPGTwilight.karosCannon.blockID, 4);
		world.setBlock(i + 28, j + 3, k + 18, DivineRPGTwilight.karosBricks.blockID);
		world.setBlock(i + 28, j + 4, k + 2, DivineRPGTwilight.karosBricks.blockID);
		world.setBlock(i + 28, j + 4, k + 3, DivineRPGTwilight.karosBricks.blockID);
		world.setBlock(i + 28, j + 4, k + 4, DivineRPGTwilight.karosBricks.blockID);
		world.setBlock(i + 28, j + 4, k + 5, DivineRPGTwilight.karosBricks.blockID);
		world.setBlock(i + 28, j + 4, k + 6, DivineRPGTwilight.karosBricks.blockID);
		world.setBlock(i + 28, j + 4, k + 7, DivineRPGTwilight.karosBricks.blockID);
		world.setBlock(i + 28, j + 4, k + 8, DivineRPGTwilight.karosBricks.blockID);
		world.setBlock(i + 28, j + 4, k + 9, DivineRPGTwilight.karosBricks.blockID);
		world.setBlock(i + 28, j + 4, k + 10, DivineRPGTwilight.karosBricks.blockID);
		world.setBlock(i + 28, j + 4, k + 11, DivineRPGTwilight.karosBricks.blockID);
		world.setBlock(i + 28, j + 4, k + 12, DivineRPGTwilight.karosBricks.blockID);
		world.setBlock(i + 28, j + 4, k + 13, DivineRPGTwilight.karosBricks.blockID);
		world.setBlock(i + 28, j + 4, k + 14, DivineRPGTwilight.karosBricks.blockID);
		world.setBlock(i + 28, j + 4, k + 15, DivineRPGTwilight.karosBricks.blockID);
		world.setBlock(i + 28, j + 4, k + 16, DivineRPGTwilight.karosBricks.blockID);
		world.setBlock(i + 28, j + 4, k + 17, DivineRPGTwilight.karosBricks.blockID);
		world.setBlock(i + 29, j + 0, k + 1, DivineRPGTwilight.karosBricks2.blockID);
		world.setBlock(i + 29, j + 0, k + 2, DivineRPGTwilight.karosBricks2.blockID);
		world.setBlock(i + 29, j + 0, k + 3, DivineRPGTwilight.karosBricks2.blockID);
		world.setBlock(i + 29, j + 0, k + 4, DivineRPGTwilight.karosBricks2.blockID);
		world.setBlock(i + 29, j + 0, k + 5, DivineRPGTwilight.karosBricks2.blockID);
		world.setBlock(i + 29, j + 0, k + 6, DivineRPGTwilight.karosBricks2.blockID);
		world.setBlock(i + 29, j + 0, k + 7, DivineRPGTwilight.karosBricks2.blockID);
		world.setBlock(i + 29, j + 0, k + 8, DivineRPGTwilight.karosBricks2.blockID);
		world.setBlock(i + 29, j + 0, k + 9, DivineRPGTwilight.karosBricks2.blockID);
		world.setBlock(i + 29, j + 0, k + 10, DivineRPGTwilight.karosBricks2.blockID);
		world.setBlock(i + 29, j + 0, k + 11, DivineRPGTwilight.karosBricks2.blockID);
		world.setBlock(i + 29, j + 0, k + 12, DivineRPGTwilight.karosBricks2.blockID);
		world.setBlock(i + 29, j + 0, k + 13, DivineRPGTwilight.karosBricks2.blockID);
		world.setBlock(i + 29, j + 0, k + 14, DivineRPGTwilight.karosBricks2.blockID);
		world.setBlock(i + 29, j + 0, k + 15, DivineRPGTwilight.karosBricks2.blockID);
		world.setBlock(i + 29, j + 0, k + 16, DivineRPGTwilight.karosBricks2.blockID);
		world.setBlock(i + 29, j + 0, k + 17, DivineRPGTwilight.karosBricks2.blockID);
		world.setBlock(i + 29, j + 0, k + 18, DivineRPGTwilight.karosBricks2.blockID);
		world.setBlock(i + 29, j + 1, k + 1, DivineRPGTwilight.karosBricks2.blockID);
		world.setBlock(i + 29, j + 1, k + 2, DivineRPGTwilight.karosBricks2.blockID);
		world.setBlock(i + 29, j + 1, k + 3, DivineRPGTwilight.karosBricks2.blockID);
		world.setBlock(i + 29, j + 1, k + 4, DivineRPGTwilight.karosBricks2.blockID);
		world.setBlock(i + 29, j + 1, k + 5, DivineRPGTwilight.karosBricks2.blockID);
		world.setBlock(i + 29, j + 1, k + 6, DivineRPGTwilight.karosBricks2.blockID);
		world.setBlock(i + 29, j + 1, k + 7, DivineRPGTwilight.karosBricks2.blockID);
		world.setBlock(i + 29, j + 1, k + 8, DivineRPGTwilight.karosBricks2.blockID);
		world.setBlock(i + 29, j + 1, k + 9, DivineRPGTwilight.karosBricks2.blockID);
		world.setBlock(i + 29, j + 1, k + 10, DivineRPGTwilight.karosBricks2.blockID);
		world.setBlock(i + 29, j + 1, k + 11, DivineRPGTwilight.karosBricks2.blockID);
		world.setBlock(i + 29, j + 1, k + 12, DivineRPGTwilight.karosBricks2.blockID);
		world.setBlock(i + 29, j + 1, k + 13, DivineRPGTwilight.karosBricks2.blockID);
		world.setBlock(i + 29, j + 1, k + 14, DivineRPGTwilight.karosBricks2.blockID);
		world.setBlock(i + 29, j + 1, k + 15, DivineRPGTwilight.karosBricks2.blockID);
		world.setBlock(i + 29, j + 1, k + 16, DivineRPGTwilight.karosBricks2.blockID);
		world.setBlock(i + 29, j + 1, k + 17, DivineRPGTwilight.karosBricks2.blockID);
		world.setBlock(i + 29, j + 1, k + 18, DivineRPGTwilight.karosBricks2.blockID);
		world.setBlock(i + 29, j + 2, k + 1, DivineRPGTwilight.karosBricks.blockID);
		world.setBlockAndMetadata(i + 29, j + 2, k + 2, DivineRPGTwilight.karosCannon.blockID, 4);
		world.setBlock(i + 29, j + 2, k + 3, DivineRPGTwilight.karosBricks.blockID);
		world.setBlockAndMetadata(i + 29, j + 2, k + 4, DivineRPGTwilight.karosCannon.blockID, 4);
		world.setBlock(i + 29, j + 2, k + 5, DivineRPGTwilight.karosBricks.blockID);
		world.setBlockAndMetadata(i + 29, j + 2, k + 6, DivineRPGTwilight.karosCannon.blockID, 4);
		world.setBlock(i + 29, j + 2, k + 7, DivineRPGTwilight.karosBricks.blockID);
		world.setBlockAndMetadata(i + 29, j + 2, k + 8, DivineRPGTwilight.karosCannon.blockID, 4);
		world.setBlockAndMetadata(i + 29, j + 2, k + 9, DivineRPGTwilight.karosCannon.blockID, 4);
		world.setBlockAndMetadata(i + 29, j + 2, k + 10, DivineRPGTwilight.karosCannon.blockID, 4);
		world.setBlockAndMetadata(i + 29, j + 2, k + 11, DivineRPGTwilight.karosCannon.blockID, 4);
		world.setBlock(i + 29, j + 2, k + 12, DivineRPGTwilight.karosBricks.blockID);
		world.setBlockAndMetadata(i + 29, j + 2, k + 13, DivineRPGTwilight.karosCannon.blockID, 4);
		world.setBlock(i + 29, j + 2, k + 14, DivineRPGTwilight.karosBricks.blockID);
		world.setBlockAndMetadata(i + 29, j + 2, k + 15, DivineRPGTwilight.karosCannon.blockID, 4);
		world.setBlock(i + 29, j + 2, k + 16, DivineRPGTwilight.karosBricks.blockID);
		world.setBlockAndMetadata(i + 29, j + 2, k + 17, DivineRPGTwilight.karosCannon.blockID, 4);
		world.setBlock(i + 29, j + 2, k + 18, DivineRPGTwilight.karosBricks.blockID);
		world.setBlock(i + 29, j + 3, k + 1, DivineRPGTwilight.karosBricks.blockID);
		world.setBlock(i + 29, j + 3, k + 2, DivineRPGTwilight.karosBricks.blockID);
		world.setBlock(i + 29, j + 3, k + 3, DivineRPGTwilight.karosBricks.blockID);
		world.setBlock(i + 29, j + 3, k + 4, DivineRPGTwilight.karosBricks.blockID);
		world.setBlock(i + 29, j + 3, k + 5, DivineRPGTwilight.karosBricks.blockID);
		world.setBlock(i + 29, j + 3, k + 6, DivineRPGTwilight.karosBricks.blockID);
		world.setBlock(i + 29, j + 3, k + 7, DivineRPGTwilight.karosBricks.blockID);
		world.setBlock(i + 29, j + 3, k + 8, DivineRPGTwilight.karosBricks.blockID);
		world.setBlock(i + 29, j + 3, k + 9, DivineRPGTwilight.karosBricks.blockID);
		world.setBlock(i + 29, j + 3, k + 10, DivineRPGTwilight.karosBricks.blockID);
		world.setBlock(i + 29, j + 3, k + 11, DivineRPGTwilight.karosBricks.blockID);
		world.setBlock(i + 29, j + 3, k + 12, DivineRPGTwilight.karosBricks.blockID);
		world.setBlock(i + 29, j + 3, k + 13, DivineRPGTwilight.karosBricks.blockID);
		world.setBlock(i + 29, j + 3, k + 14, DivineRPGTwilight.karosBricks.blockID);
		world.setBlock(i + 29, j + 3, k + 15, DivineRPGTwilight.karosBricks.blockID);
		world.setBlock(i + 29, j + 3, k + 16, DivineRPGTwilight.karosBricks.blockID);
		world.setBlock(i + 29, j + 3, k + 17, DivineRPGTwilight.karosBricks.blockID);
		world.setBlock(i + 29, j + 3, k + 18, DivineRPGTwilight.karosBricks.blockID);
		world.setBlock(i + 30, j + 0, k + 2, DivineRPGTwilight.karosBricks2.blockID);
		world.setBlock(i + 30, j + 0, k + 4, DivineRPGTwilight.karosBricks2.blockID);
		world.setBlock(i + 30, j + 0, k + 6, DivineRPGTwilight.karosBricks2.blockID);
		world.setBlock(i + 30, j + 0, k + 8, DivineRPGTwilight.karosBricks2.blockID);
		world.setBlock(i + 30, j + 0, k + 11, DivineRPGTwilight.karosBricks2.blockID);
		world.setBlock(i + 30, j + 0, k + 13, DivineRPGTwilight.karosBricks2.blockID);
		world.setBlock(i + 30, j + 0, k + 15, DivineRPGTwilight.karosBricks2.blockID);
		world.setBlock(i + 30, j + 0, k + 17, DivineRPGTwilight.karosBricks2.blockID);
		world.setBlock(i + 30, j + 1, k + 2, DivineRPGTwilight.karosBricks2.blockID);
		world.setBlock(i + 30, j + 1, k + 4, DivineRPGTwilight.karosBricks2.blockID);
		world.setBlock(i + 30, j + 1, k + 6, DivineRPGTwilight.karosBricks2.blockID);
		world.setBlock(i + 30, j + 1, k + 8, DivineRPGTwilight.karosBricks2.blockID);
		world.setBlock(i + 30, j + 1, k + 11, DivineRPGTwilight.karosBricks2.blockID);
		world.setBlock(i + 30, j + 1, k + 13, DivineRPGTwilight.karosBricks2.blockID);
		world.setBlock(i + 30, j + 1, k + 15, DivineRPGTwilight.karosBricks2.blockID);
		world.setBlock(i + 30, j + 1, k + 17, DivineRPGTwilight.karosBricks2.blockID);
		world.setBlock(i + 30, j + 2, k + 2, DivineRPGTwilight.karosBricks2.blockID);
		world.setBlock(i + 30, j + 2, k + 4, DivineRPGTwilight.karosBricks2.blockID);
		world.setBlock(i + 30, j + 2, k + 6, DivineRPGTwilight.karosBricks2.blockID);
		world.setBlock(i + 30, j + 2, k + 8, DivineRPGTwilight.karosBricks2.blockID);
		world.setBlock(i + 30, j + 2, k + 9, DivineRPGTwilight.karosBricks2.blockID);
		world.setBlock(i + 30, j + 2, k + 10, DivineRPGTwilight.karosBricks2.blockID);
		world.setBlock(i + 30, j + 2, k + 11, DivineRPGTwilight.karosBricks2.blockID);
		world.setBlock(i + 30, j + 2, k + 13, DivineRPGTwilight.karosBricks2.blockID);
		world.setBlock(i + 30, j + 2, k + 15, DivineRPGTwilight.karosBricks2.blockID);
		world.setBlock(i + 30, j + 2, k + 17, DivineRPGTwilight.karosBricks2.blockID);

		return true;
	}
}