package xolova.divinerpg.worldgen.vethea.layer3;
import java.util.Random;

import net.minecraft.world.World;
import net.minecraft.world.gen.feature.WorldGenerator;
import xolova.divinerpg.utils.helpers.block.VetheaBlockHelper;
import xolova.divinerpg.worldgen.vethea.WorldAddition;

public class KarosMadhouse extends WorldGenerator
{
	protected int[] GetValidSpawnBlocks() {
		return new int[] {
		};
	}
	
	private WorldAddition world1;

	public KarosMadhouse() { }

	public boolean generate(World world, Random rand, int i, int j, int k) {

		world.setBlock(i + 0, j + 0, k + 2, VetheaBlockHelper.karosBricks2.blockID);
		world.setBlock(i + 0, j + 0, k + 3, VetheaBlockHelper.karosBricks2.blockID);
		world.setBlock(i + 0, j + 0, k + 4, VetheaBlockHelper.karosBricks2.blockID);
		world.setBlock(i + 0, j + 0, k + 5, VetheaBlockHelper.karosBricks2.blockID);
		world.setBlock(i + 0, j + 0, k + 6, VetheaBlockHelper.karosBricks2.blockID);
		world.setBlock(i + 0, j + 0, k + 7, VetheaBlockHelper.karosBricks2.blockID);
		world.setBlock(i + 0, j + 0, k + 8, VetheaBlockHelper.karosBricks2.blockID);
		world.setBlock(i + 0, j + 0, k + 9, VetheaBlockHelper.karosBricks2.blockID);
		world.setBlock(i + 0, j + 0, k + 10, VetheaBlockHelper.karosBricks2.blockID);
		world.setBlock(i + 0, j + 0, k + 11, VetheaBlockHelper.karosBricks2.blockID);
		world.setBlock(i + 0, j + 1, k + 3, VetheaBlockHelper.karosBricks2.blockID);
		world.setBlock(i + 0, j + 1, k + 4, VetheaBlockHelper.karosBricks2.blockID);
		world.setBlock(i + 0, j + 1, k + 5, VetheaBlockHelper.karosBricks2.blockID);
		world.setBlock(i + 0, j + 1, k + 6, VetheaBlockHelper.karosBricks2.blockID);
		world.setBlock(i + 0, j + 1, k + 7, VetheaBlockHelper.karosBricks2.blockID);
		world.setBlock(i + 0, j + 1, k + 8, VetheaBlockHelper.karosBricks2.blockID);
		world.setBlock(i + 0, j + 1, k + 9, VetheaBlockHelper.karosBricks2.blockID);
		world.setBlock(i + 0, j + 1, k + 10, VetheaBlockHelper.karosBricks2.blockID);
		world.setBlock(i + 0, j + 1, k + 11, VetheaBlockHelper.karosBricks2.blockID);
		world.setBlock(i + 0, j + 2, k + 4, VetheaBlockHelper.karosBricks2.blockID);
		world.setBlock(i + 0, j + 2, k + 5, VetheaBlockHelper.karosBricks.blockID);
		world.setBlock(i + 0, j + 2, k + 6, VetheaBlockHelper.karosBricks.blockID);
		world.setBlock(i + 0, j + 2, k + 7, VetheaBlockHelper.karosBricks.blockID);
		world.setBlock(i + 0, j + 2, k + 8, VetheaBlockHelper.karosBricks.blockID);
		world.setBlock(i + 0, j + 2, k + 9, VetheaBlockHelper.karosBricks.blockID);
		world.setBlock(i + 0, j + 2, k + 10, VetheaBlockHelper.karosBricks.blockID);
		world.setBlock(i + 0, j + 2, k + 11, VetheaBlockHelper.karosBricks.blockID);
		world.setBlock(i + 1, j + 0, k + 4, VetheaBlockHelper.karosBricks2.blockID);
		world.setBlock(i + 1, j + 0, k + 5, VetheaBlockHelper.karosHeatTileRed.blockID);
		world.setBlock(i + 1, j + 0, k + 6, VetheaBlockHelper.karosHeatTileGreen.blockID);
		world.setBlock(i + 1, j + 0, k + 7, VetheaBlockHelper.karosHeatTileRed.blockID);
		world.setBlock(i + 1, j + 0, k + 8, VetheaBlockHelper.karosHeatTileGreen.blockID);
		world.setBlock(i + 1, j + 0, k + 9, VetheaBlockHelper.karosHeatTileRed.blockID);
		world.setBlock(i + 1, j + 0, k + 10, VetheaBlockHelper.karosHeatTileGreen.blockID);
		world.setBlock(i + 1, j + 0, k + 11, VetheaBlockHelper.karosBricks2.blockID);
		world.setBlock(i + 1, j + 1, k + 11, VetheaBlockHelper.karosBricks2.blockID);
		world.setBlock(i + 1, j + 2, k + 11, VetheaBlockHelper.karosBricks.blockID);
		world.setBlock(i + 1, j + 3, k + 5, VetheaBlockHelper.karosBricks2.blockID);
		world.setBlock(i + 1, j + 3, k + 6, VetheaBlockHelper.karosBricks2.blockID);
		world.setBlock(i + 1, j + 3, k + 7, VetheaBlockHelper.karosBricks2.blockID);
		world.setBlock(i + 1, j + 3, k + 8, VetheaBlockHelper.karosBricks2.blockID);
		world.setBlock(i + 1, j + 3, k + 9, VetheaBlockHelper.karosBricks2.blockID);
		world.setBlock(i + 1, j + 3, k + 10, VetheaBlockHelper.karosBricks2.blockID);
		world.setBlock(i + 2, j + 0, k + 4, VetheaBlockHelper.karosBricks2.blockID);
		world.setBlock(i + 2, j + 0, k + 5, VetheaBlockHelper.karosHeatTileGreen.blockID);
		world.setBlock(i + 2, j + 0, k + 6, VetheaBlockHelper.karosHeatTileRed.blockID);
		world.setBlock(i + 2, j + 0, k + 7, VetheaBlockHelper.karosHeatTileGreen.blockID);
		world.setBlock(i + 2, j + 0, k + 8, VetheaBlockHelper.karosHeatTileRed.blockID);
		world.setBlock(i + 2, j + 0, k + 9, VetheaBlockHelper.karosHeatTileGreen.blockID);
		world.setBlock(i + 2, j + 0, k + 10, VetheaBlockHelper.karosHeatTileRed.blockID);
		world.setBlock(i + 2, j + 0, k + 11, VetheaBlockHelper.karosBricks2.blockID);
		world.setBlock(i + 2, j + 1, k + 11, VetheaBlockHelper.karosBricks2.blockID);
		world.setBlock(i + 2, j + 2, k + 11, VetheaBlockHelper.karosBricks.blockID);
		world.setBlock(i + 2, j + 3, k + 5, VetheaBlockHelper.karosBricks2.blockID);
		world.setBlock(i + 2, j + 3, k + 6, VetheaBlockHelper.karosBricks2.blockID);
		world.setBlock(i + 2, j + 3, k + 7, VetheaBlockHelper.karosBricks2.blockID);
		world.setBlock(i + 2, j + 3, k + 8, VetheaBlockHelper.karosBricks2.blockID);
		world.setBlock(i + 2, j + 3, k + 9, VetheaBlockHelper.karosBricks2.blockID);
		world.setBlock(i + 2, j + 3, k + 10, VetheaBlockHelper.karosBricks2.blockID);
		world.setBlock(i + 3, j + 0, k + 2, VetheaBlockHelper.karosBricks2.blockID);
		world.setBlock(i + 3, j + 0, k + 3, VetheaBlockHelper.karosBricks2.blockID);
		world.setBlock(i + 3, j + 0, k + 4, VetheaBlockHelper.karosBricks2.blockID);
		world.setBlock(i + 3, j + 0, k + 5, VetheaBlockHelper.karosBricks2.blockID);
		world.setBlock(i + 3, j + 0, k + 6, VetheaBlockHelper.karosBricks2.blockID);
		world.setBlock(i + 3, j + 0, k + 7, VetheaBlockHelper.karosBricks2.blockID);
		world.setBlock(i + 3, j + 0, k + 8, VetheaBlockHelper.karosBricks2.blockID);
		world.setBlock(i + 3, j + 0, k + 9, VetheaBlockHelper.karosHeatTileRed.blockID);
		world.setBlock(i + 3, j + 0, k + 10, VetheaBlockHelper.karosHeatTileGreen.blockID);
		world.setBlock(i + 3, j + 0, k + 11, VetheaBlockHelper.karosBricks2.blockID);
		world.setBlock(i + 3, j + 1, k + 3, VetheaBlockHelper.karosBricks2.blockID);
		world.setBlock(i + 3, j + 1, k + 4, VetheaBlockHelper.karosBricks2.blockID);
		world.setBlock(i + 3, j + 1, k + 5, VetheaBlockHelper.karosBricks2.blockID);
		world.setBlock(i + 3, j + 1, k + 6, VetheaBlockHelper.karosBricks2.blockID);
		world.setBlock(i + 3, j + 1, k + 7, VetheaBlockHelper.karosBricks2.blockID);
		world.setBlock(i + 3, j + 1, k + 8, VetheaBlockHelper.karosBricks2.blockID);
		world.setBlock(i + 3, j + 1, k + 11, VetheaBlockHelper.karosBricks2.blockID);
		world.setBlock(i + 3, j + 2, k + 4, VetheaBlockHelper.karosBricks2.blockID);
		world.setBlock(i + 3, j + 2, k + 5, VetheaBlockHelper.karosBricks.blockID);
		world.setBlock(i + 3, j + 2, k + 6, VetheaBlockHelper.karosBricks.blockID);
		world.setBlock(i + 3, j + 2, k + 7, VetheaBlockHelper.karosBricks.blockID);
		world.setBlock(i + 3, j + 2, k + 8, VetheaBlockHelper.karosBricks.blockID);
		world.setBlock(i + 3, j + 2, k + 11, VetheaBlockHelper.karosBricks.blockID);
		world.setBlock(i + 3, j + 3, k + 9, VetheaBlockHelper.karosBricks2.blockID);
		world.setBlock(i + 3, j + 3, k + 10, VetheaBlockHelper.karosBricks2.blockID);
		world.setBlock(i + 4, j + 0, k + 8, VetheaBlockHelper.karosBricks2.blockID);
		world.setBlock(i + 4, j + 0, k + 9, VetheaBlockHelper.karosHeatTileGreen.blockID);
		world.setBlock(i + 4, j + 0, k + 10, VetheaBlockHelper.karosHeatTileRed.blockID);
		world.setBlock(i + 4, j + 0, k + 11, VetheaBlockHelper.karosBricks2.blockID);
		world.setBlock(i + 4, j + 1, k + 8, VetheaBlockHelper.karosBricks2.blockID);
		world.setBlock(i + 4, j + 1, k + 11, VetheaBlockHelper.karosBricks2.blockID);
		world.setBlock(i + 4, j + 2, k + 8, VetheaBlockHelper.karosBricks.blockID);
		world.setBlock(i + 4, j + 2, k + 11, VetheaBlockHelper.karosBricks.blockID);
		world.setBlock(i + 4, j + 3, k + 9, VetheaBlockHelper.karosBricks2.blockID);
		world.setBlock(i + 4, j + 3, k + 10, VetheaBlockHelper.karosBricks2.blockID);
		world.setBlock(i + 5, j + 0, k + 8, VetheaBlockHelper.karosBricks2.blockID);
		world.setBlock(i + 5, j + 0, k + 9, VetheaBlockHelper.karosHeatTileRed.blockID);
		world.setBlock(i + 5, j + 0, k + 10, VetheaBlockHelper.karosHeatTileGreen.blockID);
		world.setBlock(i + 5, j + 0, k + 11, VetheaBlockHelper.karosBricks2.blockID);
		world.setBlock(i + 5, j + 1, k + 8, VetheaBlockHelper.karosBricks2.blockID);
		world.setBlock(i + 5, j + 1, k + 11, VetheaBlockHelper.karosBricks2.blockID);
		world.setBlock(i + 5, j + 2, k + 8, VetheaBlockHelper.karosBricks.blockID);
		world.setBlock(i + 5, j + 2, k + 11, VetheaBlockHelper.karosBricks.blockID);
		world.setBlock(i + 5, j + 3, k + 9, VetheaBlockHelper.karosBricks2.blockID);
		world.setBlock(i + 5, j + 3, k + 10, VetheaBlockHelper.karosBricks2.blockID);
		world.setBlock(i + 6, j + 0, k + 8, VetheaBlockHelper.karosBricks2.blockID);
		world.setBlock(i + 6, j + 0, k + 9, VetheaBlockHelper.karosHeatTileGreen.blockID);
		world.setBlock(i + 6, j + 0, k + 10, VetheaBlockHelper.karosHeatTileRed.blockID);
		world.setBlock(i + 6, j + 0, k + 11, VetheaBlockHelper.karosBricks2.blockID);
		world.setBlock(i + 6, j + 1, k + 8, VetheaBlockHelper.karosBricks2.blockID);
		world.setBlock(i + 6, j + 1, k + 11, VetheaBlockHelper.karosBricks2.blockID);
		world.setBlock(i + 6, j + 2, k + 8, VetheaBlockHelper.karosBricks.blockID);
		world.setBlock(i + 6, j + 2, k + 11, VetheaBlockHelper.karosBricks.blockID);
		world.setBlock(i + 6, j + 3, k + 9, VetheaBlockHelper.karosBricks2.blockID);
		world.setBlock(i + 6, j + 3, k + 10, VetheaBlockHelper.karosBricks2.blockID);
		world.setBlock(i + 7, j + 0, k + 8, VetheaBlockHelper.karosBricks2.blockID);
		world.setBlock(i + 7, j + 0, k + 9, VetheaBlockHelper.karosHeatTileRed.blockID);
		world.setBlock(i + 7, j + 0, k + 10, VetheaBlockHelper.karosHeatTileGreen.blockID);
		world.setBlock(i + 7, j + 0, k + 11, VetheaBlockHelper.karosBricks2.blockID);
		world.setBlock(i + 7, j + 1, k + 8, VetheaBlockHelper.karosBricks2.blockID);
		world.setBlock(i + 7, j + 1, k + 11, VetheaBlockHelper.karosBricks2.blockID);
		world.setBlock(i + 7, j + 2, k + 8, VetheaBlockHelper.karosBricks.blockID);
		world.setBlock(i + 7, j + 2, k + 11, VetheaBlockHelper.karosBricks.blockID);
		world.setBlock(i + 7, j + 3, k + 9, VetheaBlockHelper.karosBricks2.blockID);
		world.setBlock(i + 7, j + 3, k + 10, VetheaBlockHelper.karosBricks2.blockID);
		world.setBlock(i + 8, j + 0, k + 8, VetheaBlockHelper.karosBricks2.blockID);
		world.setBlock(i + 8, j + 0, k + 9, VetheaBlockHelper.karosHeatTileGreen.blockID);
		world.setBlock(i + 8, j + 0, k + 10, VetheaBlockHelper.karosHeatTileRed.blockID);
		world.setBlock(i + 8, j + 0, k + 11, VetheaBlockHelper.karosBricks2.blockID);
		world.setBlock(i + 8, j + 1, k + 8, VetheaBlockHelper.karosBricks2.blockID);
		world.setBlock(i + 8, j + 1, k + 11, VetheaBlockHelper.karosBricks2.blockID);
		world.setBlock(i + 8, j + 2, k + 8, VetheaBlockHelper.karosBricks.blockID);
		world.setBlock(i + 8, j + 2, k + 11, VetheaBlockHelper.karosBricks.blockID);
		world.setBlock(i + 8, j + 3, k + 8, VetheaBlockHelper.karosBricks.blockID);
		world.setBlock(i + 8, j + 3, k + 9, VetheaBlockHelper.karosBricks2.blockID);
		world.setBlock(i + 8, j + 3, k + 10, VetheaBlockHelper.karosBricks2.blockID);
		world.setBlock(i + 8, j + 3, k + 11, VetheaBlockHelper.karosBricks.blockID);
		world.setBlock(i + 8, j + 4, k + 8, VetheaBlockHelper.karosBricks.blockID);
		world.setBlock(i + 8, j + 4, k + 11, VetheaBlockHelper.karosBricks.blockID);
		world.setBlock(i + 9, j + 0, k + 3, VetheaBlockHelper.karosBricks2.blockID);
		world.setBlock(i + 9, j + 0, k + 5, VetheaBlockHelper.karosBricks2.blockID);
		world.setBlock(i + 9, j + 0, k + 7, VetheaBlockHelper.karosBricks2.blockID);
		world.setBlock(i + 9, j + 0, k + 8, VetheaBlockHelper.karosBricks2.blockID);
		world.setBlock(i + 9, j + 0, k + 9, VetheaBlockHelper.karosHeatTileRed.blockID);
		world.setBlock(i + 9, j + 0, k + 10, VetheaBlockHelper.karosHeatTileGreen.blockID);
		world.setBlock(i + 9, j + 0, k + 11, VetheaBlockHelper.karosBricks2.blockID);
		world.setBlock(i + 9, j + 0, k + 12, VetheaBlockHelper.karosBricks2.blockID);
		world.setBlock(i + 9, j + 0, k + 14, VetheaBlockHelper.karosBricks2.blockID);
		world.setBlock(i + 9, j + 0, k + 16, VetheaBlockHelper.karosBricks2.blockID);
		world.setBlock(i + 9, j + 1, k + 3, VetheaBlockHelper.karosBricks2.blockID);
		world.setBlock(i + 9, j + 1, k + 5, VetheaBlockHelper.karosBricks2.blockID);
		world.setBlock(i + 9, j + 1, k + 7, VetheaBlockHelper.karosBricks2.blockID);
		world.setBlock(i + 9, j + 1, k + 8, VetheaBlockHelper.karosBricks2.blockID);
		world.setBlock(i + 9, j + 1, k + 11, VetheaBlockHelper.karosBricks2.blockID);
		world.setBlock(i + 9, j + 1, k + 12, VetheaBlockHelper.karosBricks2.blockID);
		world.setBlock(i + 9, j + 1, k + 14, VetheaBlockHelper.karosBricks2.blockID);
		world.setBlock(i + 9, j + 1, k + 16, VetheaBlockHelper.karosBricks2.blockID);
		world.setBlock(i + 9, j + 2, k + 3, VetheaBlockHelper.karosBricks2.blockID);
		world.setBlock(i + 9, j + 2, k + 5, VetheaBlockHelper.karosBricks2.blockID);
		world.setBlock(i + 9, j + 2, k + 7, VetheaBlockHelper.karosBricks2.blockID);
		world.setBlock(i + 9, j + 2, k + 8, VetheaBlockHelper.karosBricks2.blockID);
		world.setBlock(i + 9, j + 2, k + 11, VetheaBlockHelper.karosBricks2.blockID);
		world.setBlock(i + 9, j + 2, k + 12, VetheaBlockHelper.karosBricks2.blockID);
		world.setBlock(i + 9, j + 2, k + 14, VetheaBlockHelper.karosBricks2.blockID);
		world.setBlock(i + 9, j + 2, k + 16, VetheaBlockHelper.karosBricks2.blockID);
		world.setBlock(i + 9, j + 3, k + 8, VetheaBlockHelper.karosBricks2.blockID);
		world.setBlock(i + 9, j + 3, k + 9, VetheaBlockHelper.karosBricks2.blockID);
		world.setBlock(i + 9, j + 3, k + 10, VetheaBlockHelper.karosBricks2.blockID);
		world.setBlock(i + 9, j + 3, k + 11, VetheaBlockHelper.karosBricks2.blockID);
		world.setBlock(i + 9, j + 4, k + 8, VetheaBlockHelper.karosBricks.blockID);
		world.setBlock(i + 9, j + 4, k + 11, VetheaBlockHelper.karosBricks.blockID);
		world.setBlock(i + 10, j + 0, k + 1, VetheaBlockHelper.karosBricks2.blockID);
		world.setBlock(i + 10, j + 0, k + 2, VetheaBlockHelper.karosBricks2.blockID);
		world.setBlock(i + 10, j + 0, k + 3, VetheaBlockHelper.karosBricks2.blockID);
		world.setBlock(i + 10, j + 0, k + 4, VetheaBlockHelper.karosBricks2.blockID);
		world.setBlock(i + 10, j + 0, k + 5, VetheaBlockHelper.karosBricks2.blockID);
		world.setBlock(i + 10, j + 0, k + 6, VetheaBlockHelper.karosBricks2.blockID);
		world.setBlock(i + 10, j + 0, k + 7, VetheaBlockHelper.karosBricks2.blockID);
		world.setBlock(i + 10, j + 0, k + 8, VetheaBlockHelper.karosBricks2.blockID);
		world.setBlock(i + 10, j + 0, k + 9, VetheaBlockHelper.karosHeatTileGreen.blockID);
		world.setBlock(i + 10, j + 0, k + 10, VetheaBlockHelper.karosHeatTileRed.blockID);
		world.setBlock(i + 10, j + 0, k + 11, VetheaBlockHelper.karosBricks2.blockID);
		world.setBlock(i + 10, j + 0, k + 12, VetheaBlockHelper.karosBricks2.blockID);
		world.setBlock(i + 10, j + 0, k + 13, VetheaBlockHelper.karosBricks2.blockID);
		world.setBlock(i + 10, j + 0, k + 14, VetheaBlockHelper.karosBricks2.blockID);
		world.setBlock(i + 10, j + 0, k + 15, VetheaBlockHelper.karosBricks2.blockID);
		world.setBlock(i + 10, j + 0, k + 16, VetheaBlockHelper.karosBricks2.blockID);
		world.setBlock(i + 10, j + 0, k + 17, VetheaBlockHelper.karosBricks2.blockID);
		world.setBlock(i + 10, j + 0, k + 18, VetheaBlockHelper.karosBricks2.blockID);
		world.setBlock(i + 10, j + 1, k + 1, VetheaBlockHelper.karosBricks2.blockID);
		world.setBlock(i + 10, j + 1, k + 2, VetheaBlockHelper.karosBricks2.blockID);
		world.setBlock(i + 10, j + 1, k + 3, VetheaBlockHelper.karosBricks2.blockID);
		world.setBlock(i + 10, j + 1, k + 4, VetheaBlockHelper.karosBricks2.blockID);
		world.setBlock(i + 10, j + 1, k + 5, VetheaBlockHelper.karosBricks2.blockID);
		world.setBlock(i + 10, j + 1, k + 6, VetheaBlockHelper.karosBricks2.blockID);
		world.setBlock(i + 10, j + 1, k + 7, VetheaBlockHelper.karosBricks2.blockID);
		world.setBlock(i + 10, j + 1, k + 8, VetheaBlockHelper.karosBricks2.blockID);
		world.setBlock(i + 10, j + 1, k + 11, VetheaBlockHelper.karosBricks2.blockID);
		world.setBlock(i + 10, j + 1, k + 12, VetheaBlockHelper.karosBricks2.blockID);
		world.setBlock(i + 10, j + 1, k + 13, VetheaBlockHelper.karosBricks2.blockID);
		world.setBlock(i + 10, j + 1, k + 14, VetheaBlockHelper.karosBricks2.blockID);
		world.setBlock(i + 10, j + 1, k + 15, VetheaBlockHelper.karosBricks2.blockID);
		world.setBlock(i + 10, j + 1, k + 16, VetheaBlockHelper.karosBricks2.blockID);
		world.setBlock(i + 10, j + 1, k + 17, VetheaBlockHelper.karosBricks2.blockID);
		world.setBlock(i + 10, j + 1, k + 18, VetheaBlockHelper.karosBricks2.blockID);
		world.setBlock(i + 10, j + 2, k + 1, VetheaBlockHelper.karosBricks.blockID);
		world.setBlock(i + 10, j + 2, k + 2, VetheaBlockHelper.karosBricks.blockID);
		world1.setBlockWithMetadata(i + 10, j + 2, k + 3, VetheaBlockHelper.karosCannon.blockID, 5);
		world.setBlock(i + 10, j + 2, k + 4, VetheaBlockHelper.karosBricks.blockID);
		world1.setBlockWithMetadata(i + 10, j + 2, k + 5, VetheaBlockHelper.karosCannon.blockID, 5);
		world.setBlock(i + 10, j + 2, k + 6, VetheaBlockHelper.karosBricks.blockID);
		world1.setBlockWithMetadata(i + 10, j + 2, k + 7, VetheaBlockHelper.karosCannon.blockID, 5);
		world.setBlock(i + 10, j + 2, k + 8, VetheaBlockHelper.karosBricks2.blockID);
		world.setBlock(i + 10, j + 2, k + 11, VetheaBlockHelper.karosBricks2.blockID);
		world1.setBlockWithMetadata(i + 10, j + 2, k + 12, VetheaBlockHelper.karosCannon.blockID, 5);
		world.setBlock(i + 10, j + 2, k + 13, VetheaBlockHelper.karosBricks.blockID);
		world1.setBlockWithMetadata(i + 10, j + 2, k + 14, VetheaBlockHelper.karosCannon.blockID, 5);
		world.setBlock(i + 10, j + 2, k + 15, VetheaBlockHelper.karosBricks.blockID);
		world1.setBlockWithMetadata(i + 10, j + 2, k + 16, VetheaBlockHelper.karosCannon.blockID, 5);
		world.setBlock(i + 10, j + 2, k + 17, VetheaBlockHelper.karosBricks.blockID);
		world.setBlock(i + 10, j + 2, k + 18, VetheaBlockHelper.karosBricks.blockID);
		world.setBlock(i + 10, j + 3, k + 1, VetheaBlockHelper.karosBricks.blockID);
		world.setBlock(i + 10, j + 3, k + 2, VetheaBlockHelper.karosBricks.blockID);
		world.setBlock(i + 10, j + 3, k + 3, VetheaBlockHelper.karosBricks.blockID);
		world.setBlock(i + 10, j + 3, k + 4, VetheaBlockHelper.karosBricks.blockID);
		world.setBlock(i + 10, j + 3, k + 5, VetheaBlockHelper.karosBricks.blockID);
		world.setBlock(i + 10, j + 3, k + 6, VetheaBlockHelper.karosBricks.blockID);
		world.setBlock(i + 10, j + 3, k + 7, VetheaBlockHelper.karosBricks.blockID);
		world.setBlock(i + 10, j + 3, k + 8, VetheaBlockHelper.karosBricks2.blockID);
		world.setBlock(i + 10, j + 3, k + 9, VetheaBlockHelper.karosBricks2.blockID);
		world.setBlock(i + 10, j + 3, k + 10, VetheaBlockHelper.karosBricks2.blockID);
		world.setBlock(i + 10, j + 3, k + 11, VetheaBlockHelper.karosBricks2.blockID);
		world.setBlock(i + 10, j + 3, k + 12, VetheaBlockHelper.karosBricks.blockID);
		world.setBlock(i + 10, j + 3, k + 13, VetheaBlockHelper.karosBricks.blockID);
		world.setBlock(i + 10, j + 3, k + 14, VetheaBlockHelper.karosBricks.blockID);
		world.setBlock(i + 10, j + 3, k + 15, VetheaBlockHelper.karosBricks.blockID);
		world.setBlock(i + 10, j + 3, k + 16, VetheaBlockHelper.karosBricks.blockID);
		world.setBlock(i + 10, j + 3, k + 17, VetheaBlockHelper.karosBricks.blockID);
		world.setBlock(i + 10, j + 3, k + 18, VetheaBlockHelper.karosBricks.blockID);
		world.setBlock(i + 10, j + 4, k + 8, VetheaBlockHelper.karosBricks.blockID);
		world.setBlock(i + 10, j + 4, k + 11, VetheaBlockHelper.karosBricks.blockID);
		world.setBlock(i + 11, j + 0, k + 1, VetheaBlockHelper.karosBricks2.blockID);
		world.setBlock(i + 11, j + 0, k + 2, VetheaBlockHelper.karosHeatTileGreen.blockID);
		world.setBlock(i + 11, j + 0, k + 3, VetheaBlockHelper.karosHeatTileGreen.blockID);
		world.setBlock(i + 11, j + 0, k + 4, VetheaBlockHelper.karosHeatTileRed.blockID);
		world.setBlock(i + 11, j + 0, k + 5, VetheaBlockHelper.karosHeatTileRed.blockID);
		world.setBlock(i + 11, j + 0, k + 6, VetheaBlockHelper.karosHeatTileGreen.blockID);
		world.setBlock(i + 11, j + 0, k + 7, VetheaBlockHelper.karosHeatTileGreen.blockID);
		world.setBlock(i + 11, j + 0, k + 8, VetheaBlockHelper.karosHeatTileRed.blockID);
		world.setBlock(i + 11, j + 0, k + 9, VetheaBlockHelper.karosHeatTileRed.blockID);
		world.setBlock(i + 11, j + 0, k + 10, VetheaBlockHelper.karosHeatTileGreen.blockID);
		world.setBlock(i + 11, j + 0, k + 11, VetheaBlockHelper.karosHeatTileGreen.blockID);
		world.setBlock(i + 11, j + 0, k + 12, VetheaBlockHelper.karosHeatTileRed.blockID);
		world.setBlock(i + 11, j + 0, k + 13, VetheaBlockHelper.karosHeatTileRed.blockID);
		world.setBlock(i + 11, j + 0, k + 14, VetheaBlockHelper.karosHeatTileGreen.blockID);
		world.setBlock(i + 11, j + 0, k + 15, VetheaBlockHelper.karosHeatTileGreen.blockID);
		world.setBlock(i + 11, j + 0, k + 16, VetheaBlockHelper.karosHeatTileRed.blockID);
		world.setBlock(i + 11, j + 0, k + 17, VetheaBlockHelper.karosHeatTileRed.blockID);
		world.setBlock(i + 11, j + 0, k + 18, VetheaBlockHelper.karosBricks2.blockID);
		world.setBlock(i + 11, j + 1, k + 1, VetheaBlockHelper.karosBricks2.blockID);
		world.setBlock(i + 11, j + 1, k + 18, VetheaBlockHelper.karosBricks2.blockID);
		world.setBlock(i + 11, j + 2, k + 1, VetheaBlockHelper.karosBricks.blockID);
		world.setBlock(i + 11, j + 2, k + 18, VetheaBlockHelper.karosBricks.blockID);
		world.setBlock(i + 11, j + 3, k + 1, VetheaBlockHelper.karosBricks.blockID);
		world.setBlock(i + 11, j + 3, k + 18, VetheaBlockHelper.karosBricks.blockID);
		world.setBlock(i + 11, j + 4, k + 2, VetheaBlockHelper.karosBricks.blockID);
		world.setBlock(i + 11, j + 4, k + 3, VetheaBlockHelper.karosBricks.blockID);
		world.setBlock(i + 11, j + 4, k + 4, VetheaBlockHelper.karosBricks.blockID);
		world.setBlock(i + 11, j + 4, k + 5, VetheaBlockHelper.karosBricks.blockID);
		world.setBlock(i + 11, j + 4, k + 6, VetheaBlockHelper.karosBricks.blockID);
		world.setBlock(i + 11, j + 4, k + 7, VetheaBlockHelper.karosBricks.blockID);
		world.setBlock(i + 11, j + 4, k + 8, VetheaBlockHelper.karosBricks.blockID);
		world.setBlock(i + 11, j + 4, k + 9, VetheaBlockHelper.karosBricks.blockID);
		world.setBlock(i + 11, j + 4, k + 10, VetheaBlockHelper.karosBricks.blockID);
		world.setBlock(i + 11, j + 4, k + 11, VetheaBlockHelper.karosBricks.blockID);
		world.setBlock(i + 11, j + 4, k + 12, VetheaBlockHelper.karosBricks.blockID);
		world.setBlock(i + 11, j + 4, k + 13, VetheaBlockHelper.karosBricks.blockID);
		world.setBlock(i + 11, j + 4, k + 14, VetheaBlockHelper.karosBricks.blockID);
		world.setBlock(i + 11, j + 4, k + 15, VetheaBlockHelper.karosBricks.blockID);
		world.setBlock(i + 11, j + 4, k + 16, VetheaBlockHelper.karosBricks.blockID);
		world.setBlock(i + 11, j + 4, k + 17, VetheaBlockHelper.karosBricks.blockID);
		world.setBlock(i + 12, j + 0, k + 0, VetheaBlockHelper.karosBricks2.blockID);
		world.setBlock(i + 12, j + 0, k + 1, VetheaBlockHelper.karosBricks2.blockID);
		world.setBlock(i + 12, j + 0, k + 2, VetheaBlockHelper.karosHeatTileGreen.blockID);
		world.setBlock(i + 12, j + 0, k + 3, VetheaBlockHelper.karosHeatTileGreen.blockID);
		world.setBlock(i + 12, j + 0, k + 4, VetheaBlockHelper.karosHeatTileRed.blockID);
		world.setBlock(i + 12, j + 0, k + 5, VetheaBlockHelper.karosHeatTileRed.blockID);
		world.setBlock(i + 12, j + 0, k + 6, VetheaBlockHelper.karosHeatTileGreen.blockID);
		world.setBlock(i + 12, j + 0, k + 7, VetheaBlockHelper.karosHeatTileGreen.blockID);
		world.setBlock(i + 12, j + 0, k + 8, VetheaBlockHelper.karosHeatTileRed.blockID);
		world.setBlock(i + 12, j + 0, k + 9, VetheaBlockHelper.karosHeatTileRed.blockID);
		world.setBlock(i + 12, j + 0, k + 10, VetheaBlockHelper.karosHeatTileGreen.blockID);
		world.setBlock(i + 12, j + 0, k + 11, VetheaBlockHelper.karosHeatTileGreen.blockID);
		world.setBlock(i + 12, j + 0, k + 12, VetheaBlockHelper.karosHeatTileRed.blockID);
		world.setBlock(i + 12, j + 0, k + 13, VetheaBlockHelper.karosHeatTileRed.blockID);
		world.setBlock(i + 12, j + 0, k + 14, VetheaBlockHelper.karosHeatTileGreen.blockID);
		world.setBlock(i + 12, j + 0, k + 15, VetheaBlockHelper.karosHeatTileGreen.blockID);
		world.setBlock(i + 12, j + 0, k + 16, VetheaBlockHelper.karosHeatTileRed.blockID);
		world.setBlock(i + 12, j + 0, k + 17, VetheaBlockHelper.karosHeatTileRed.blockID);
		world.setBlock(i + 12, j + 0, k + 18, VetheaBlockHelper.karosBricks2.blockID);
		world.setBlock(i + 12, j + 0, k + 19, VetheaBlockHelper.karosBricks2.blockID);
		world.setBlock(i + 12, j + 1, k + 0, VetheaBlockHelper.karosBricks2.blockID);
		world.setBlock(i + 12, j + 1, k + 1, VetheaBlockHelper.karosBricks2.blockID);
		world.setBlock(i + 12, j + 1, k + 18, VetheaBlockHelper.karosBricks2.blockID);
		world.setBlock(i + 12, j + 1, k + 19, VetheaBlockHelper.karosBricks2.blockID);
		world.setBlock(i + 12, j + 2, k + 0, VetheaBlockHelper.karosBricks2.blockID);
		world1.setBlockWithMetadata(i + 12, j + 2, k + 1, VetheaBlockHelper.karosCannon.blockID, 3);
		world1.setBlockWithMetadata(i + 12, j + 2, k + 18, VetheaBlockHelper.karosCannon.blockID, 2);
		world.setBlock(i + 12, j + 2, k + 19, VetheaBlockHelper.karosBricks2.blockID);
		world.setBlock(i + 12, j + 3, k + 1, VetheaBlockHelper.karosBricks.blockID);
		world.setBlock(i + 12, j + 3, k + 18, VetheaBlockHelper.karosBricks.blockID);
		world.setBlock(i + 12, j + 4, k + 2, VetheaBlockHelper.karosBricks.blockID);
		world.setBlock(i + 12, j + 4, k + 17, VetheaBlockHelper.karosBricks.blockID);
		world.setBlock(i + 12, j + 5, k + 3, VetheaBlockHelper.karosBricks.blockID);
		world.setBlock(i + 12, j + 5, k + 4, VetheaBlockHelper.karosBricks.blockID);
		world.setBlock(i + 12, j + 5, k + 5, VetheaBlockHelper.karosBricks.blockID);
		world.setBlock(i + 12, j + 5, k + 6, VetheaBlockHelper.karosBricks.blockID);
		world.setBlock(i + 12, j + 5, k + 7, VetheaBlockHelper.karosBricks.blockID);
		world.setBlock(i + 12, j + 5, k + 8, VetheaBlockHelper.karosBricks.blockID);
		world.setBlock(i + 12, j + 5, k + 9, VetheaBlockHelper.karosBricks.blockID);
		world.setBlock(i + 12, j + 5, k + 10, VetheaBlockHelper.karosBricks.blockID);
		world.setBlock(i + 12, j + 5, k + 11, VetheaBlockHelper.karosBricks.blockID);
		world.setBlock(i + 12, j + 5, k + 12, VetheaBlockHelper.karosBricks.blockID);
		world.setBlock(i + 12, j + 5, k + 13, VetheaBlockHelper.karosBricks.blockID);
		world.setBlock(i + 12, j + 5, k + 14, VetheaBlockHelper.karosBricks.blockID);
		world.setBlock(i + 12, j + 5, k + 15, VetheaBlockHelper.karosBricks.blockID);
		world.setBlock(i + 12, j + 5, k + 16, VetheaBlockHelper.karosBricks.blockID);
		world.setBlock(i + 13, j + 0, k + 1, VetheaBlockHelper.karosBricks2.blockID);
		world.setBlock(i + 13, j + 0, k + 2, VetheaBlockHelper.karosHeatTileRed.blockID);
		world.setBlock(i + 13, j + 0, k + 3, VetheaBlockHelper.karosHeatTileRed.blockID);
		world.setBlock(i + 13, j + 0, k + 4, VetheaBlockHelper.karosHeatTileGreen.blockID);
		world.setBlock(i + 13, j + 0, k + 5, VetheaBlockHelper.karosHeatTileGreen.blockID);
		world.setBlock(i + 13, j + 0, k + 6, VetheaBlockHelper.karosHeatTileRed.blockID);
		world.setBlock(i + 13, j + 0, k + 7, VetheaBlockHelper.karosHeatTileRed.blockID);
		world.setBlock(i + 13, j + 0, k + 8, VetheaBlockHelper.karosHeatTileGreen.blockID);
		world.setBlock(i + 13, j + 0, k + 9, VetheaBlockHelper.karosHeatTileGreen.blockID);
		world.setBlock(i + 13, j + 0, k + 10, VetheaBlockHelper.karosHeatTileRed.blockID);
		world.setBlock(i + 13, j + 0, k + 11, VetheaBlockHelper.karosHeatTileRed.blockID);
		world.setBlock(i + 13, j + 0, k + 12, VetheaBlockHelper.karosHeatTileGreen.blockID);
		world.setBlock(i + 13, j + 0, k + 13, VetheaBlockHelper.karosHeatTileGreen.blockID);
		world.setBlock(i + 13, j + 0, k + 14, VetheaBlockHelper.karosHeatTileRed.blockID);
		world.setBlock(i + 13, j + 0, k + 15, VetheaBlockHelper.karosHeatTileRed.blockID);
		world.setBlock(i + 13, j + 0, k + 16, VetheaBlockHelper.karosHeatTileGreen.blockID);
		world.setBlock(i + 13, j + 0, k + 17, VetheaBlockHelper.karosHeatTileGreen.blockID);
		world.setBlock(i + 13, j + 0, k + 18, VetheaBlockHelper.karosBricks2.blockID);
		world.setBlock(i + 13, j + 1, k + 1, VetheaBlockHelper.karosBricks2.blockID);
		world.setBlock(i + 13, j + 1, k + 18, VetheaBlockHelper.karosBricks2.blockID);
		world.setBlock(i + 13, j + 2, k + 1, VetheaBlockHelper.karosBricks.blockID);
		world.setBlock(i + 13, j + 2, k + 18, VetheaBlockHelper.karosBricks.blockID);
		world.setBlock(i + 13, j + 3, k + 1, VetheaBlockHelper.karosBricks.blockID);
		world.setBlock(i + 13, j + 3, k + 18, VetheaBlockHelper.karosBricks.blockID);
		world.setBlock(i + 13, j + 4, k + 2, VetheaBlockHelper.karosBricks.blockID);
		world.setBlock(i + 13, j + 4, k + 4, VetheaBlockHelper.helioticBeam.blockID);
		world.setBlock(i + 13, j + 4, k + 5, VetheaBlockHelper.helioticBeam.blockID);
		world.setBlock(i + 13, j + 4, k + 6, VetheaBlockHelper.helioticBeam.blockID);
		world.setBlock(i + 13, j + 4, k + 14, VetheaBlockHelper.helioticBeam.blockID);
		world.setBlock(i + 13, j + 4, k + 15, VetheaBlockHelper.helioticBeam.blockID);
		world.setBlock(i + 13, j + 4, k + 16, VetheaBlockHelper.helioticBeam.blockID);
		world.setBlock(i + 13, j + 4, k + 17, VetheaBlockHelper.karosBricks.blockID);
		world.setBlock(i + 13, j + 5, k + 3, VetheaBlockHelper.karosBricks.blockID);
		world.setBlock(i + 13, j + 5, k + 4, VetheaBlockHelper.karosBricks2.blockID);
		world.setBlock(i + 13, j + 5, k + 5, VetheaBlockHelper.karosBricks2.blockID);
		world.setBlock(i + 13, j + 5, k + 6, VetheaBlockHelper.karosBricks2.blockID);
		world.setBlock(i + 13, j + 5, k + 7, VetheaBlockHelper.karosBricks2.blockID);
		world.setBlock(i + 13, j + 5, k + 8, VetheaBlockHelper.karosBricks2.blockID);
		world.setBlock(i + 13, j + 5, k + 9, VetheaBlockHelper.karosBricks2.blockID);
		world.setBlock(i + 13, j + 5, k + 10, VetheaBlockHelper.karosBricks2.blockID);
		world.setBlock(i + 13, j + 5, k + 11, VetheaBlockHelper.karosBricks2.blockID);
		world.setBlock(i + 13, j + 5, k + 12, VetheaBlockHelper.karosBricks2.blockID);
		world.setBlock(i + 13, j + 5, k + 13, VetheaBlockHelper.karosBricks2.blockID);
		world.setBlock(i + 13, j + 5, k + 14, VetheaBlockHelper.karosBricks2.blockID);
		world.setBlock(i + 13, j + 5, k + 15, VetheaBlockHelper.karosBricks2.blockID);
		world.setBlock(i + 13, j + 5, k + 16, VetheaBlockHelper.karosBricks.blockID);
		world.setBlock(i + 14, j + 0, k + 0, VetheaBlockHelper.karosBricks2.blockID);
		world.setBlock(i + 14, j + 0, k + 1, VetheaBlockHelper.karosBricks2.blockID);
		world.setBlock(i + 14, j + 0, k + 2, VetheaBlockHelper.karosHeatTileRed.blockID);
		world.setBlock(i + 14, j + 0, k + 3, VetheaBlockHelper.karosHeatTileRed.blockID);
		world.setBlock(i + 14, j + 0, k + 4, VetheaBlockHelper.karosHeatTileGreen.blockID);
		world.setBlock(i + 14, j + 0, k + 5, VetheaBlockHelper.karosHeatTileGreen.blockID);
		world.setBlock(i + 14, j + 0, k + 6, VetheaBlockHelper.karosHeatTileRed.blockID);
		world.setBlock(i + 14, j + 0, k + 7, VetheaBlockHelper.karosHeatTileRed.blockID);
		world.setBlock(i + 14, j + 0, k + 8, VetheaBlockHelper.karosHeatTileGreen.blockID);
		world.setBlock(i + 14, j + 0, k + 9, VetheaBlockHelper.karosHeatTileGreen.blockID);
		world.setBlock(i + 14, j + 0, k + 10, VetheaBlockHelper.karosHeatTileRed.blockID);
		world.setBlock(i + 14, j + 0, k + 11, VetheaBlockHelper.karosHeatTileRed.blockID);
		world.setBlock(i + 14, j + 0, k + 12, VetheaBlockHelper.karosHeatTileGreen.blockID);
		world.setBlock(i + 14, j + 0, k + 13, VetheaBlockHelper.karosHeatTileGreen.blockID);
		world.setBlock(i + 14, j + 0, k + 14, VetheaBlockHelper.karosHeatTileRed.blockID);
		world.setBlock(i + 14, j + 0, k + 15, VetheaBlockHelper.karosHeatTileRed.blockID);
		world.setBlock(i + 14, j + 0, k + 16, VetheaBlockHelper.karosHeatTileGreen.blockID);
		world.setBlock(i + 14, j + 0, k + 17, VetheaBlockHelper.karosHeatTileGreen.blockID);
		world.setBlock(i + 14, j + 0, k + 18, VetheaBlockHelper.karosBricks2.blockID);
		world.setBlock(i + 14, j + 0, k + 19, VetheaBlockHelper.karosBricks2.blockID);
		world.setBlock(i + 14, j + 1, k + 0, VetheaBlockHelper.karosBricks2.blockID);
		world.setBlock(i + 14, j + 1, k + 1, VetheaBlockHelper.karosBricks2.blockID);
		world.setBlock(i + 14, j + 1, k + 18, VetheaBlockHelper.karosBricks2.blockID);
		world.setBlock(i + 14, j + 1, k + 19, VetheaBlockHelper.karosBricks2.blockID);
		world.setBlock(i + 14, j + 2, k + 0, VetheaBlockHelper.karosBricks2.blockID);
		world1.setBlockWithMetadata(i + 14, j + 2, k + 1, VetheaBlockHelper.karosCannon.blockID, 3);
		world1.setBlockWithMetadata(i + 14, j + 2, k + 18, VetheaBlockHelper.karosCannon.blockID, 2);
		world.setBlock(i + 14, j + 2, k + 19, VetheaBlockHelper.karosBricks2.blockID);
		world.setBlock(i + 14, j + 3, k + 1, VetheaBlockHelper.karosBricks.blockID);
		world.setBlock(i + 14, j + 3, k + 18, VetheaBlockHelper.karosBricks.blockID);
		world.setBlock(i + 14, j + 4, k + 2, VetheaBlockHelper.karosBricks.blockID);
		world.setBlock(i + 14, j + 4, k + 4, VetheaBlockHelper.helioticBeam.blockID);
		world.setBlock(i + 14, j + 4, k + 5, VetheaBlockHelper.helioticBeam.blockID);
		world.setBlock(i + 14, j + 4, k + 6, VetheaBlockHelper.helioticBeam.blockID);
		world.setBlock(i + 14, j + 4, k + 14, VetheaBlockHelper.helioticBeam.blockID);
		world.setBlock(i + 14, j + 4, k + 15, VetheaBlockHelper.helioticBeam.blockID);
		world.setBlock(i + 14, j + 4, k + 16, VetheaBlockHelper.helioticBeam.blockID);
		world.setBlock(i + 14, j + 4, k + 17, VetheaBlockHelper.karosBricks.blockID);
		world.setBlock(i + 14, j + 5, k + 3, VetheaBlockHelper.karosBricks.blockID);
		world.setBlock(i + 14, j + 5, k + 4, VetheaBlockHelper.karosBricks2.blockID);
		world.setBlock(i + 14, j + 5, k + 5, VetheaBlockHelper.karosBricks.blockID);
		world.setBlock(i + 14, j + 5, k + 6, VetheaBlockHelper.karosBricks.blockID);
		world.setBlock(i + 14, j + 5, k + 7, VetheaBlockHelper.karosBricks.blockID);
		world.setBlock(i + 14, j + 5, k + 8, VetheaBlockHelper.karosBricks.blockID);
		world.setBlock(i + 14, j + 5, k + 9, VetheaBlockHelper.karosBricks.blockID);
		world.setBlock(i + 14, j + 5, k + 10, VetheaBlockHelper.karosBricks.blockID);
		world.setBlock(i + 14, j + 5, k + 11, VetheaBlockHelper.karosBricks.blockID);
		world.setBlock(i + 14, j + 5, k + 12, VetheaBlockHelper.karosBricks.blockID);
		world.setBlock(i + 14, j + 5, k + 13, VetheaBlockHelper.karosBricks.blockID);
		world.setBlock(i + 14, j + 5, k + 14, VetheaBlockHelper.karosBricks.blockID);
		world.setBlock(i + 14, j + 5, k + 15, VetheaBlockHelper.karosBricks2.blockID);
		world.setBlock(i + 14, j + 5, k + 16, VetheaBlockHelper.karosBricks.blockID);
		world.setBlock(i + 15, j + 0, k + 1, VetheaBlockHelper.karosBricks2.blockID);
		world.setBlock(i + 15, j + 0, k + 2, VetheaBlockHelper.karosHeatTileGreen.blockID);
		world.setBlock(i + 15, j + 0, k + 3, VetheaBlockHelper.karosHeatTileGreen.blockID);
		world.setBlock(i + 15, j + 0, k + 4, VetheaBlockHelper.karosHeatTileRed.blockID);
		world.setBlock(i + 15, j + 0, k + 5, VetheaBlockHelper.karosHeatTileRed.blockID);
		world.setBlock(i + 15, j + 0, k + 6, VetheaBlockHelper.karosHeatTileGreen.blockID);
		world.setBlock(i + 15, j + 0, k + 7, VetheaBlockHelper.karosHeatTileGreen.blockID);
		world.setBlock(i + 15, j + 0, k + 8, VetheaBlockHelper.karosHeatTileRed.blockID);
		world.setBlock(i + 15, j + 0, k + 9, VetheaBlockHelper.karosHeatTileRed.blockID);
		world.setBlock(i + 15, j + 0, k + 10, VetheaBlockHelper.karosHeatTileGreen.blockID);
		world.setBlock(i + 15, j + 0, k + 11, VetheaBlockHelper.karosHeatTileGreen.blockID);
		world.setBlock(i + 15, j + 0, k + 12, VetheaBlockHelper.karosHeatTileRed.blockID);
		world.setBlock(i + 15, j + 0, k + 13, VetheaBlockHelper.karosHeatTileRed.blockID);
		world.setBlock(i + 15, j + 0, k + 14, VetheaBlockHelper.karosHeatTileGreen.blockID);
		world.setBlock(i + 15, j + 0, k + 15, VetheaBlockHelper.karosHeatTileGreen.blockID);
		world.setBlock(i + 15, j + 0, k + 16, VetheaBlockHelper.karosHeatTileRed.blockID);
		world.setBlock(i + 15, j + 0, k + 17, VetheaBlockHelper.karosHeatTileRed.blockID);
		world.setBlock(i + 15, j + 0, k + 18, VetheaBlockHelper.karosBricks2.blockID);
		world.setBlock(i + 15, j + 1, k + 1, VetheaBlockHelper.karosBricks2.blockID);
		world.setBlock(i + 15, j + 1, k + 18, VetheaBlockHelper.karosBricks2.blockID);
		world.setBlock(i + 15, j + 2, k + 1, VetheaBlockHelper.karosBricks.blockID);
		world.setBlock(i + 15, j + 2, k + 18, VetheaBlockHelper.karosBricks.blockID);
		world.setBlock(i + 15, j + 3, k + 1, VetheaBlockHelper.karosBricks.blockID);
		world.setBlock(i + 15, j + 3, k + 18, VetheaBlockHelper.karosBricks.blockID);
		world.setBlock(i + 15, j + 4, k + 2, VetheaBlockHelper.karosBricks.blockID);
		world.setBlock(i + 15, j + 4, k + 4, VetheaBlockHelper.helioticBeam.blockID);
		world.setBlock(i + 15, j + 4, k + 5, VetheaBlockHelper.helioticBeam.blockID);
		world.setBlock(i + 15, j + 4, k + 6, VetheaBlockHelper.helioticBeam.blockID);
		world.setBlock(i + 15, j + 4, k + 14, VetheaBlockHelper.helioticBeam.blockID);
		world.setBlock(i + 15, j + 4, k + 15, VetheaBlockHelper.helioticBeam.blockID);
		world.setBlock(i + 15, j + 4, k + 16, VetheaBlockHelper.helioticBeam.blockID);
		world.setBlock(i + 15, j + 4, k + 17, VetheaBlockHelper.karosBricks.blockID);
		world.setBlock(i + 15, j + 5, k + 3, VetheaBlockHelper.karosBricks.blockID);
		world.setBlock(i + 15, j + 5, k + 4, VetheaBlockHelper.karosBricks2.blockID);
		world.setBlock(i + 15, j + 5, k + 5, VetheaBlockHelper.karosBricks.blockID);
		world.setBlock(i + 15, j + 5, k + 6, VetheaBlockHelper.karosBricks2.blockID);
		world.setBlock(i + 15, j + 5, k + 7, VetheaBlockHelper.karosBricks2.blockID);
		world.setBlock(i + 15, j + 5, k + 8, VetheaBlockHelper.karosBricks2.blockID);
		world.setBlock(i + 15, j + 5, k + 9, VetheaBlockHelper.karosBricks2.blockID);
		world.setBlock(i + 15, j + 5, k + 10, VetheaBlockHelper.karosBricks2.blockID);
		world.setBlock(i + 15, j + 5, k + 11, VetheaBlockHelper.karosBricks2.blockID);
		world.setBlock(i + 15, j + 5, k + 12, VetheaBlockHelper.karosBricks2.blockID);
		world.setBlock(i + 15, j + 5, k + 13, VetheaBlockHelper.karosBricks2.blockID);
		world.setBlock(i + 15, j + 5, k + 14, VetheaBlockHelper.karosBricks.blockID);
		world.setBlock(i + 15, j + 5, k + 15, VetheaBlockHelper.karosBricks2.blockID);
		world.setBlock(i + 15, j + 5, k + 16, VetheaBlockHelper.karosBricks.blockID);
		world.setBlock(i + 16, j + 0, k + 0, VetheaBlockHelper.karosBricks2.blockID);
		world.setBlock(i + 16, j + 0, k + 1, VetheaBlockHelper.karosBricks2.blockID);
		world.setBlock(i + 16, j + 0, k + 2, VetheaBlockHelper.karosHeatTileGreen.blockID);
		world.setBlock(i + 16, j + 0, k + 3, VetheaBlockHelper.karosHeatTileGreen.blockID);
		world.setBlock(i + 16, j + 0, k + 4, VetheaBlockHelper.karosHeatTileRed.blockID);
		world.setBlock(i + 16, j + 0, k + 5, VetheaBlockHelper.karosHeatTileRed.blockID);
		world.setBlock(i + 16, j + 0, k + 6, VetheaBlockHelper.karosHeatTileGreen.blockID);
		world.setBlock(i + 16, j + 0, k + 7, VetheaBlockHelper.karosHeatTileGreen.blockID);
		world.setBlock(i + 16, j + 0, k + 8, VetheaBlockHelper.karosHeatTileRed.blockID);
		world.setBlock(i + 16, j + 0, k + 9, VetheaBlockHelper.karosHeatTileRed.blockID);
		world.setBlock(i + 16, j + 0, k + 10, VetheaBlockHelper.karosHeatTileGreen.blockID);
		world.setBlock(i + 16, j + 0, k + 11, VetheaBlockHelper.karosHeatTileGreen.blockID);
		world.setBlock(i + 16, j + 0, k + 12, VetheaBlockHelper.karosHeatTileRed.blockID);
		world.setBlock(i + 16, j + 0, k + 13, VetheaBlockHelper.karosHeatTileRed.blockID);
		world.setBlock(i + 16, j + 0, k + 14, VetheaBlockHelper.karosHeatTileGreen.blockID);
		world.setBlock(i + 16, j + 0, k + 15, VetheaBlockHelper.karosHeatTileGreen.blockID);
		world.setBlock(i + 16, j + 0, k + 16, VetheaBlockHelper.karosHeatTileRed.blockID);
		world.setBlock(i + 16, j + 0, k + 17, VetheaBlockHelper.karosHeatTileRed.blockID);
		world.setBlock(i + 16, j + 0, k + 18, VetheaBlockHelper.karosBricks2.blockID);
		world.setBlock(i + 16, j + 0, k + 19, VetheaBlockHelper.karosBricks2.blockID);
		world.setBlock(i + 16, j + 1, k + 0, VetheaBlockHelper.karosBricks2.blockID);
		world.setBlock(i + 16, j + 1, k + 1, VetheaBlockHelper.karosBricks2.blockID);
		world.setBlock(i + 16, j + 1, k + 18, VetheaBlockHelper.karosBricks2.blockID);
		world.setBlock(i + 16, j + 1, k + 19, VetheaBlockHelper.karosBricks2.blockID);
		world.setBlock(i + 16, j + 2, k + 0, VetheaBlockHelper.karosBricks2.blockID);
		world1.setBlockWithMetadata(i + 16, j + 2, k + 1, VetheaBlockHelper.karosCannon.blockID, 3);
		world1.setBlockWithMetadata(i + 16, j + 2, k + 18, VetheaBlockHelper.karosCannon.blockID, 2);
		world.setBlock(i + 16, j + 2, k + 19, VetheaBlockHelper.karosBricks2.blockID);
		world.setBlock(i + 16, j + 3, k + 1, VetheaBlockHelper.karosBricks.blockID);
		world.setBlock(i + 16, j + 3, k + 18, VetheaBlockHelper.karosBricks.blockID);
		world.setBlock(i + 16, j + 4, k + 2, VetheaBlockHelper.karosBricks.blockID);
		world.setBlock(i + 16, j + 4, k + 17, VetheaBlockHelper.karosBricks.blockID);
		world.setBlock(i + 16, j + 5, k + 3, VetheaBlockHelper.karosBricks.blockID);
		world.setBlock(i + 16, j + 5, k + 4, VetheaBlockHelper.karosBricks2.blockID);
		world.setBlock(i + 16, j + 5, k + 5, VetheaBlockHelper.karosBricks.blockID);
		world.setBlock(i + 16, j + 5, k + 6, VetheaBlockHelper.karosBricks2.blockID);
		world.setBlock(i + 16, j + 5, k + 7, VetheaBlockHelper.karosBricks.blockID);
		world.setBlock(i + 16, j + 5, k + 8, VetheaBlockHelper.karosBricks2.blockID);
		world.setBlock(i + 16, j + 5, k + 9, VetheaBlockHelper.karosBricks2.blockID);
		world.setBlock(i + 16, j + 5, k + 10, VetheaBlockHelper.karosBricks2.blockID);
		world.setBlock(i + 16, j + 5, k + 11, VetheaBlockHelper.karosBricks.blockID);
		world.setBlock(i + 16, j + 5, k + 12, VetheaBlockHelper.karosBricks2.blockID);
		world.setBlock(i + 16, j + 5, k + 13, VetheaBlockHelper.karosBricks2.blockID);
		world.setBlock(i + 16, j + 5, k + 14, VetheaBlockHelper.karosBricks.blockID);
		world.setBlock(i + 16, j + 5, k + 15, VetheaBlockHelper.karosBricks2.blockID);
		world.setBlock(i + 16, j + 5, k + 16, VetheaBlockHelper.karosBricks.blockID);
		world.setBlock(i + 17, j + 0, k + 1, VetheaBlockHelper.karosBricks2.blockID);
		world.setBlock(i + 17, j + 0, k + 2, VetheaBlockHelper.karosHeatTileRed.blockID);
		world.setBlock(i + 17, j + 0, k + 3, VetheaBlockHelper.karosHeatTileRed.blockID);
		world.setBlock(i + 17, j + 0, k + 4, VetheaBlockHelper.karosHeatTileGreen.blockID);
		world.setBlock(i + 17, j + 0, k + 5, VetheaBlockHelper.karosHeatTileGreen.blockID);
		world.setBlock(i + 17, j + 0, k + 6, VetheaBlockHelper.karosHeatTileRed.blockID);
		world.setBlock(i + 17, j + 0, k + 7, VetheaBlockHelper.karosHeatTileRed.blockID);
		world.setBlock(i + 17, j + 0, k + 8, VetheaBlockHelper.karosHeatTileGreen.blockID);
		world.setBlock(i + 17, j + 0, k + 9, VetheaBlockHelper.karosHeatTileGreen.blockID);
		world.setBlock(i + 17, j + 0, k + 10, VetheaBlockHelper.karosHeatTileRed.blockID);
		world.setBlock(i + 17, j + 0, k + 11, VetheaBlockHelper.karosHeatTileRed.blockID);
		world.setBlock(i + 17, j + 0, k + 12, VetheaBlockHelper.karosHeatTileGreen.blockID);
		world.setBlock(i + 17, j + 0, k + 13, VetheaBlockHelper.karosHeatTileGreen.blockID);
		world.setBlock(i + 17, j + 0, k + 14, VetheaBlockHelper.karosHeatTileRed.blockID);
		world.setBlock(i + 17, j + 0, k + 15, VetheaBlockHelper.karosHeatTileRed.blockID);
		world.setBlock(i + 17, j + 0, k + 16, VetheaBlockHelper.karosHeatTileGreen.blockID);
		world.setBlock(i + 17, j + 0, k + 17, VetheaBlockHelper.karosHeatTileGreen.blockID);
		world.setBlock(i + 17, j + 0, k + 18, VetheaBlockHelper.karosBricks2.blockID);
		world.setBlock(i + 17, j + 1, k + 1, VetheaBlockHelper.karosBricks2.blockID);
		world.setBlock(i + 17, j + 1, k + 18, VetheaBlockHelper.karosBricks2.blockID);
		world.setBlock(i + 17, j + 2, k + 1, VetheaBlockHelper.karosBricks.blockID);
		world.setBlock(i + 17, j + 2, k + 18, VetheaBlockHelper.karosBricks.blockID);
		world.setBlock(i + 17, j + 3, k + 1, VetheaBlockHelper.karosBricks.blockID);
		world.setBlock(i + 17, j + 3, k + 18, VetheaBlockHelper.karosBricks.blockID);
		world.setBlock(i + 17, j + 4, k + 2, VetheaBlockHelper.karosBricks.blockID);
		world.setBlock(i + 17, j + 4, k + 17, VetheaBlockHelper.karosBricks.blockID);
		world.setBlock(i + 17, j + 5, k + 3, VetheaBlockHelper.karosBricks.blockID);
		world.setBlock(i + 17, j + 5, k + 4, VetheaBlockHelper.karosBricks2.blockID);
		world.setBlock(i + 17, j + 5, k + 5, VetheaBlockHelper.karosBricks.blockID);
		world.setBlock(i + 17, j + 5, k + 6, VetheaBlockHelper.karosBricks2.blockID);
		world.setBlock(i + 17, j + 5, k + 7, VetheaBlockHelper.karosBricks.blockID);
		world.setBlock(i + 17, j + 5, k + 8, VetheaBlockHelper.karosBricks2.blockID);
		world.setBlock(i + 17, j + 5, k + 9, VetheaBlockHelper.karosBricks2.blockID);
		world.setBlock(i + 17, j + 5, k + 10, VetheaBlockHelper.karosBricks.blockID);
		world.setBlock(i + 17, j + 5, k + 11, VetheaBlockHelper.karosBricks2.blockID);
		world.setBlock(i + 17, j + 5, k + 12, VetheaBlockHelper.karosBricks2.blockID);
		world.setBlock(i + 17, j + 5, k + 13, VetheaBlockHelper.karosBricks2.blockID);
		world.setBlock(i + 17, j + 5, k + 14, VetheaBlockHelper.karosBricks.blockID);
		world.setBlock(i + 17, j + 5, k + 15, VetheaBlockHelper.karosBricks2.blockID);
		world.setBlock(i + 17, j + 5, k + 16, VetheaBlockHelper.karosBricks.blockID);
		world.setBlock(i + 18, j + 0, k + 0, VetheaBlockHelper.karosBricks2.blockID);
		world.setBlock(i + 18, j + 0, k + 1, VetheaBlockHelper.karosBricks2.blockID);
		world.setBlock(i + 18, j + 0, k + 2, VetheaBlockHelper.karosHeatTileRed.blockID);
		world.setBlock(i + 18, j + 0, k + 3, VetheaBlockHelper.karosHeatTileRed.blockID);
		world.setBlock(i + 18, j + 0, k + 4, VetheaBlockHelper.karosHeatTileGreen.blockID);
		world.setBlock(i + 18, j + 0, k + 5, VetheaBlockHelper.karosHeatTileGreen.blockID);
		world.setBlock(i + 18, j + 0, k + 6, VetheaBlockHelper.karosHeatTileRed.blockID);
		world.setBlock(i + 18, j + 0, k + 7, VetheaBlockHelper.karosHeatTileRed.blockID);
		world.setBlock(i + 18, j + 0, k + 8, VetheaBlockHelper.karosHeatTileGreen.blockID);
		world.setBlock(i + 18, j + 0, k + 9, VetheaBlockHelper.karosHeatTileGreen.blockID);
		world.setBlock(i + 18, j + 0, k + 10, VetheaBlockHelper.karosHeatTileRed.blockID);
		world.setBlock(i + 18, j + 0, k + 11, VetheaBlockHelper.karosHeatTileRed.blockID);
		world.setBlock(i + 18, j + 0, k + 12, VetheaBlockHelper.karosHeatTileGreen.blockID);
		world.setBlock(i + 18, j + 0, k + 13, VetheaBlockHelper.karosHeatTileGreen.blockID);
		world.setBlock(i + 18, j + 0, k + 14, VetheaBlockHelper.karosHeatTileRed.blockID);
		world.setBlock(i + 18, j + 0, k + 15, VetheaBlockHelper.karosHeatTileRed.blockID);
		world.setBlock(i + 18, j + 0, k + 16, VetheaBlockHelper.karosHeatTileGreen.blockID);
		world.setBlock(i + 18, j + 0, k + 17, VetheaBlockHelper.karosHeatTileGreen.blockID);
		world.setBlock(i + 18, j + 0, k + 18, VetheaBlockHelper.karosBricks2.blockID);
		world.setBlock(i + 18, j + 0, k + 19, VetheaBlockHelper.karosBricks2.blockID);
		world.setBlock(i + 18, j + 1, k + 0, VetheaBlockHelper.karosBricks2.blockID);
		world.setBlock(i + 18, j + 1, k + 1, VetheaBlockHelper.karosBricks2.blockID);
		world.setBlock(i + 18, j + 1, k + 18, VetheaBlockHelper.karosBricks2.blockID);
		world.setBlock(i + 18, j + 1, k + 19, VetheaBlockHelper.karosBricks2.blockID);
		world.setBlock(i + 18, j + 2, k + 0, VetheaBlockHelper.karosBricks2.blockID);
		world1.setBlockWithMetadata(i + 18, j + 2, k + 1, VetheaBlockHelper.karosCannon.blockID, 3);
		world1.setBlockWithMetadata(i + 18, j + 2, k + 18, VetheaBlockHelper.karosCannon.blockID, 2);
		world.setBlock(i + 18, j + 2, k + 19, VetheaBlockHelper.karosBricks2.blockID);
		world.setBlock(i + 18, j + 3, k + 1, VetheaBlockHelper.karosBricks.blockID);
		world.setBlock(i + 18, j + 3, k + 18, VetheaBlockHelper.karosBricks.blockID);
		world.setBlock(i + 18, j + 4, k + 2, VetheaBlockHelper.karosBricks.blockID);
		world.setBlock(i + 18, j + 4, k + 9, VetheaBlockHelper.helioticBeam.blockID);
		world.setBlock(i + 18, j + 4, k + 10, VetheaBlockHelper.helioticBeam.blockID);
		world.setBlock(i + 18, j + 4, k + 11, VetheaBlockHelper.helioticBeam.blockID);
		world.setBlock(i + 18, j + 4, k + 17, VetheaBlockHelper.karosBricks.blockID);
		world.setBlock(i + 18, j + 5, k + 3, VetheaBlockHelper.karosBricks.blockID);
		world.setBlock(i + 18, j + 5, k + 4, VetheaBlockHelper.karosBricks2.blockID);
		world.setBlock(i + 18, j + 5, k + 5, VetheaBlockHelper.karosBricks.blockID);
		world.setBlock(i + 18, j + 5, k + 6, VetheaBlockHelper.karosBricks2.blockID);
		world.setBlock(i + 18, j + 5, k + 7, VetheaBlockHelper.karosBricks.blockID);
		world.setBlock(i + 18, j + 5, k + 8, VetheaBlockHelper.karosBricks2.blockID);
		world.setBlock(i + 18, j + 5, k + 9, VetheaBlockHelper.karosBricks.blockID);
		world.setBlock(i + 18, j + 5, k + 10, VetheaBlockHelper.karosBricks2.blockID);
		world.setBlock(i + 18, j + 5, k + 11, VetheaBlockHelper.karosBricks2.blockID);
		world.setBlock(i + 18, j + 5, k + 12, VetheaBlockHelper.karosBricks2.blockID);
		world.setBlock(i + 18, j + 5, k + 13, VetheaBlockHelper.karosBricks2.blockID);
		world.setBlock(i + 18, j + 5, k + 14, VetheaBlockHelper.karosBricks.blockID);
		world.setBlock(i + 18, j + 5, k + 15, VetheaBlockHelper.karosBricks2.blockID);
		world.setBlock(i + 18, j + 5, k + 16, VetheaBlockHelper.karosBricks.blockID);
		world.setBlock(i + 19, j + 0, k + 1, VetheaBlockHelper.karosBricks2.blockID);
		world.setBlock(i + 19, j + 0, k + 2, VetheaBlockHelper.karosHeatTileGreen.blockID);
		world.setBlock(i + 19, j + 0, k + 3, VetheaBlockHelper.karosHeatTileGreen.blockID);
		world.setBlock(i + 19, j + 0, k + 4, VetheaBlockHelper.karosHeatTileRed.blockID);
		world.setBlock(i + 19, j + 0, k + 5, VetheaBlockHelper.karosHeatTileRed.blockID);
		world.setBlock(i + 19, j + 0, k + 6, VetheaBlockHelper.karosHeatTileGreen.blockID);
		world.setBlock(i + 19, j + 0, k + 7, VetheaBlockHelper.karosHeatTileGreen.blockID);
		world.setBlock(i + 19, j + 0, k + 8, VetheaBlockHelper.karosHeatTileRed.blockID);
		world.setBlock(i + 19, j + 0, k + 9, VetheaBlockHelper.karosHeatTileRed.blockID);
		world.setBlock(i + 19, j + 0, k + 10, VetheaBlockHelper.karosHeatTileGreen.blockID);
		world.setBlock(i + 19, j + 0, k + 11, VetheaBlockHelper.karosHeatTileGreen.blockID);
		world.setBlock(i + 19, j + 0, k + 12, VetheaBlockHelper.karosHeatTileRed.blockID);
		world.setBlock(i + 19, j + 0, k + 13, VetheaBlockHelper.karosHeatTileRed.blockID);
		world.setBlock(i + 19, j + 0, k + 14, VetheaBlockHelper.karosHeatTileGreen.blockID);
		world.setBlock(i + 19, j + 0, k + 15, VetheaBlockHelper.karosHeatTileGreen.blockID);
		world.setBlock(i + 19, j + 0, k + 16, VetheaBlockHelper.karosHeatTileRed.blockID);
		world.setBlock(i + 19, j + 0, k + 17, VetheaBlockHelper.karosHeatTileRed.blockID);
		world.setBlock(i + 19, j + 0, k + 18, VetheaBlockHelper.karosBricks2.blockID);
		world.setBlock(i + 19, j + 1, k + 1, VetheaBlockHelper.karosBricks2.blockID);
		world.setBlock(i + 19, j + 1, k + 18, VetheaBlockHelper.karosBricks2.blockID);
		world.setBlock(i + 19, j + 2, k + 1, VetheaBlockHelper.karosBricks.blockID);
		world.setBlock(i + 19, j + 2, k + 18, VetheaBlockHelper.karosBricks.blockID);
		world.setBlock(i + 19, j + 3, k + 1, VetheaBlockHelper.karosBricks.blockID);
		world.setBlock(i + 19, j + 3, k + 18, VetheaBlockHelper.karosBricks.blockID);
		world.setBlock(i + 19, j + 4, k + 2, VetheaBlockHelper.karosBricks.blockID);
		world.setBlock(i + 19, j + 4, k + 9, VetheaBlockHelper.helioticBeam.blockID);
		world.setBlock(i + 19, j + 4, k + 10, VetheaBlockHelper.helioticBeam.blockID);
		world.setBlock(i + 19, j + 4, k + 11, VetheaBlockHelper.helioticBeam.blockID);
		world.setBlock(i + 19, j + 4, k + 17, VetheaBlockHelper.karosBricks.blockID);
		world.setBlock(i + 19, j + 5, k + 3, VetheaBlockHelper.karosBricks.blockID);
		world.setBlock(i + 19, j + 5, k + 4, VetheaBlockHelper.karosBricks2.blockID);
		world.setBlock(i + 19, j + 5, k + 5, VetheaBlockHelper.karosBricks.blockID);
		world.setBlock(i + 19, j + 5, k + 6, VetheaBlockHelper.karosBricks2.blockID);
		world.setBlock(i + 19, j + 5, k + 7, VetheaBlockHelper.karosBricks.blockID);
		world.setBlock(i + 19, j + 5, k + 8, VetheaBlockHelper.karosBricks.blockID);
		world.setBlock(i + 19, j + 5, k + 9, VetheaBlockHelper.karosBricks2.blockID);
		world.setBlock(i + 19, j + 5, k + 10, VetheaBlockHelper.karosBricks2.blockID);
		world.setBlock(i + 19, j + 5, k + 11, VetheaBlockHelper.karosBricks2.blockID);
		world.setBlock(i + 19, j + 5, k + 12, VetheaBlockHelper.karosBricks2.blockID);
		world.setBlock(i + 19, j + 5, k + 13, VetheaBlockHelper.karosBricks2.blockID);
		world.setBlock(i + 19, j + 5, k + 14, VetheaBlockHelper.karosBricks.blockID);
		world.setBlock(i + 19, j + 5, k + 15, VetheaBlockHelper.karosBricks2.blockID);
		world.setBlock(i + 19, j + 5, k + 16, VetheaBlockHelper.karosBricks.blockID);
		world.setBlock(i + 20, j + 0, k + 0, VetheaBlockHelper.karosBricks2.blockID);
		world.setBlock(i + 20, j + 0, k + 1, VetheaBlockHelper.karosBricks2.blockID);
		world.setBlock(i + 20, j + 0, k + 2, VetheaBlockHelper.karosHeatTileGreen.blockID);
		world.setBlock(i + 20, j + 0, k + 3, VetheaBlockHelper.karosHeatTileGreen.blockID);
		world.setBlock(i + 20, j + 0, k + 4, VetheaBlockHelper.karosHeatTileRed.blockID);
		world.setBlock(i + 20, j + 0, k + 5, VetheaBlockHelper.karosHeatTileRed.blockID);
		world.setBlock(i + 20, j + 0, k + 6, VetheaBlockHelper.karosHeatTileGreen.blockID);
		world.setBlock(i + 20, j + 0, k + 7, VetheaBlockHelper.karosHeatTileGreen.blockID);
		world.setBlock(i + 20, j + 0, k + 8, VetheaBlockHelper.karosHeatTileRed.blockID);
		world.setBlock(i + 20, j + 0, k + 9, VetheaBlockHelper.karosHeatTileRed.blockID);
		world.setBlock(i + 20, j + 0, k + 10, VetheaBlockHelper.karosHeatTileGreen.blockID);
		world.setBlock(i + 20, j + 0, k + 11, VetheaBlockHelper.karosHeatTileGreen.blockID);
		world.setBlock(i + 20, j + 0, k + 12, VetheaBlockHelper.karosHeatTileRed.blockID);
		world.setBlock(i + 20, j + 0, k + 13, VetheaBlockHelper.karosHeatTileRed.blockID);
		world.setBlock(i + 20, j + 0, k + 14, VetheaBlockHelper.karosHeatTileGreen.blockID);
		world.setBlock(i + 20, j + 0, k + 15, VetheaBlockHelper.karosHeatTileGreen.blockID);
		world.setBlock(i + 20, j + 0, k + 16, VetheaBlockHelper.karosHeatTileRed.blockID);
		world.setBlock(i + 20, j + 0, k + 17, VetheaBlockHelper.karosHeatTileRed.blockID);
		world.setBlock(i + 20, j + 0, k + 18, VetheaBlockHelper.karosBricks2.blockID);
		world.setBlock(i + 20, j + 0, k + 19, VetheaBlockHelper.karosBricks2.blockID);
		world.setBlock(i + 20, j + 1, k + 0, VetheaBlockHelper.karosBricks2.blockID);
		world.setBlock(i + 20, j + 1, k + 1, VetheaBlockHelper.karosBricks2.blockID);
		world.setBlock(i + 20, j + 1, k + 18, VetheaBlockHelper.karosBricks2.blockID);
		world.setBlock(i + 20, j + 1, k + 19, VetheaBlockHelper.karosBricks2.blockID);
		world.setBlock(i + 20, j + 2, k + 0, VetheaBlockHelper.karosBricks2.blockID);
		world1.setBlockWithMetadata(i + 20, j + 2, k + 1, VetheaBlockHelper.karosCannon.blockID, 3);
		world1.setBlockWithMetadata(i + 20, j + 2, k + 18, VetheaBlockHelper.karosCannon.blockID, 2);
		world.setBlock(i + 20, j + 2, k + 19, VetheaBlockHelper.karosBricks2.blockID);
		world.setBlock(i + 20, j + 3, k + 1, VetheaBlockHelper.karosBricks.blockID);
		world.setBlock(i + 20, j + 3, k + 18, VetheaBlockHelper.karosBricks.blockID);
		world.setBlock(i + 20, j + 4, k + 2, VetheaBlockHelper.karosBricks.blockID);
		world.setBlock(i + 20, j + 4, k + 9, VetheaBlockHelper.helioticBeam.blockID);
		world.setBlock(i + 20, j + 4, k + 10, VetheaBlockHelper.helioticBeam.blockID);
		world.setBlock(i + 20, j + 4, k + 11, VetheaBlockHelper.helioticBeam.blockID);
		world.setBlock(i + 20, j + 4, k + 17, VetheaBlockHelper.karosBricks.blockID);
		world.setBlock(i + 20, j + 5, k + 3, VetheaBlockHelper.karosBricks.blockID);
		world.setBlock(i + 20, j + 5, k + 4, VetheaBlockHelper.karosBricks2.blockID);
		world.setBlock(i + 20, j + 5, k + 5, VetheaBlockHelper.karosBricks.blockID);
		world.setBlock(i + 20, j + 5, k + 6, VetheaBlockHelper.karosBricks2.blockID);
		world.setBlock(i + 20, j + 5, k + 7, VetheaBlockHelper.karosBricks.blockID);
		world.setBlock(i + 20, j + 5, k + 8, VetheaBlockHelper.karosBricks2.blockID);
		world.setBlock(i + 20, j + 5, k + 9, VetheaBlockHelper.karosBricks2.blockID);
		world.setBlock(i + 20, j + 5, k + 10, VetheaBlockHelper.karosBricks2.blockID);
		world.setBlock(i + 20, j + 5, k + 11, VetheaBlockHelper.karosBricks2.blockID);
		world.setBlock(i + 20, j + 5, k + 12, VetheaBlockHelper.karosBricks2.blockID);
		world.setBlock(i + 20, j + 5, k + 13, VetheaBlockHelper.karosBricks2.blockID);
		world.setBlock(i + 20, j + 5, k + 14, VetheaBlockHelper.karosBricks.blockID);
		world.setBlock(i + 20, j + 5, k + 15, VetheaBlockHelper.karosBricks2.blockID);
		world.setBlock(i + 20, j + 5, k + 16, VetheaBlockHelper.karosBricks.blockID);
		world.setBlock(i + 21, j + 0, k + 1, VetheaBlockHelper.karosBricks2.blockID);
		world.setBlock(i + 21, j + 0, k + 2, VetheaBlockHelper.karosHeatTileRed.blockID);
		world.setBlock(i + 21, j + 0, k + 3, VetheaBlockHelper.karosHeatTileRed.blockID);
		world.setBlock(i + 21, j + 0, k + 4, VetheaBlockHelper.karosHeatTileGreen.blockID);
		world.setBlock(i + 21, j + 0, k + 5, VetheaBlockHelper.karosHeatTileGreen.blockID);
		world.setBlock(i + 21, j + 0, k + 6, VetheaBlockHelper.karosHeatTileRed.blockID);
		world.setBlock(i + 21, j + 0, k + 7, VetheaBlockHelper.karosHeatTileRed.blockID);
		world.setBlock(i + 21, j + 0, k + 8, VetheaBlockHelper.karosHeatTileGreen.blockID);
		world.setBlock(i + 21, j + 0, k + 9, VetheaBlockHelper.karosHeatTileGreen.blockID);
		world.setBlock(i + 21, j + 0, k + 10, VetheaBlockHelper.karosHeatTileRed.blockID);
		world.setBlock(i + 21, j + 0, k + 11, VetheaBlockHelper.karosHeatTileRed.blockID);
		world.setBlock(i + 21, j + 0, k + 12, VetheaBlockHelper.karosHeatTileGreen.blockID);
		world.setBlock(i + 21, j + 0, k + 13, VetheaBlockHelper.karosHeatTileGreen.blockID);
		world.setBlock(i + 21, j + 0, k + 14, VetheaBlockHelper.karosHeatTileRed.blockID);
		world.setBlock(i + 21, j + 0, k + 15, VetheaBlockHelper.karosHeatTileRed.blockID);
		world.setBlock(i + 21, j + 0, k + 16, VetheaBlockHelper.karosHeatTileGreen.blockID);
		world.setBlock(i + 21, j + 0, k + 17, VetheaBlockHelper.karosHeatTileGreen.blockID);
		world.setBlock(i + 21, j + 0, k + 18, VetheaBlockHelper.karosBricks2.blockID);
		world.setBlock(i + 21, j + 1, k + 1, VetheaBlockHelper.karosBricks2.blockID);
		world.setBlock(i + 21, j + 1, k + 18, VetheaBlockHelper.karosBricks2.blockID);
		world.setBlock(i + 21, j + 2, k + 1, VetheaBlockHelper.karosBricks.blockID);
		world.setBlock(i + 21, j + 2, k + 18, VetheaBlockHelper.karosBricks.blockID);
		world.setBlock(i + 21, j + 3, k + 1, VetheaBlockHelper.karosBricks.blockID);
		world.setBlock(i + 21, j + 3, k + 18, VetheaBlockHelper.karosBricks.blockID);
		world.setBlock(i + 21, j + 4, k + 2, VetheaBlockHelper.karosBricks.blockID);
		world.setBlock(i + 21, j + 4, k + 17, VetheaBlockHelper.karosBricks.blockID);
		world.setBlock(i + 21, j + 5, k + 3, VetheaBlockHelper.karosBricks.blockID);
		world.setBlock(i + 21, j + 5, k + 4, VetheaBlockHelper.karosBricks2.blockID);
		world.setBlock(i + 21, j + 5, k + 5, VetheaBlockHelper.karosBricks.blockID);
		world.setBlock(i + 21, j + 5, k + 6, VetheaBlockHelper.karosBricks2.blockID);
		world.setBlock(i + 21, j + 5, k + 7, VetheaBlockHelper.karosBricks.blockID);
		world.setBlock(i + 21, j + 5, k + 8, VetheaBlockHelper.karosBricks.blockID);
		world.setBlock(i + 21, j + 5, k + 9, VetheaBlockHelper.karosBricks2.blockID);
		world.setBlock(i + 21, j + 5, k + 10, VetheaBlockHelper.karosBricks2.blockID);
		world.setBlock(i + 21, j + 5, k + 11, VetheaBlockHelper.karosBricks2.blockID);
		world.setBlock(i + 21, j + 5, k + 12, VetheaBlockHelper.karosBricks2.blockID);
		world.setBlock(i + 21, j + 5, k + 13, VetheaBlockHelper.karosBricks2.blockID);
		world.setBlock(i + 21, j + 5, k + 14, VetheaBlockHelper.karosBricks.blockID);
		world.setBlock(i + 21, j + 5, k + 15, VetheaBlockHelper.karosBricks2.blockID);
		world.setBlock(i + 21, j + 5, k + 16, VetheaBlockHelper.karosBricks.blockID);
		world.setBlock(i + 22, j + 0, k + 0, VetheaBlockHelper.karosBricks2.blockID);
		world.setBlock(i + 22, j + 0, k + 1, VetheaBlockHelper.karosBricks2.blockID);
		world.setBlock(i + 22, j + 0, k + 2, VetheaBlockHelper.karosHeatTileRed.blockID);
		world.setBlock(i + 22, j + 0, k + 3, VetheaBlockHelper.karosHeatTileRed.blockID);
		world.setBlock(i + 22, j + 0, k + 4, VetheaBlockHelper.karosHeatTileGreen.blockID);
		world.setBlock(i + 22, j + 0, k + 5, VetheaBlockHelper.karosHeatTileGreen.blockID);
		world.setBlock(i + 22, j + 0, k + 6, VetheaBlockHelper.karosHeatTileRed.blockID);
		world.setBlock(i + 22, j + 0, k + 7, VetheaBlockHelper.karosHeatTileRed.blockID);
		world.setBlock(i + 22, j + 0, k + 8, VetheaBlockHelper.karosHeatTileGreen.blockID);
		world.setBlock(i + 22, j + 0, k + 9, VetheaBlockHelper.karosHeatTileGreen.blockID);
		world.setBlock(i + 22, j + 0, k + 10, VetheaBlockHelper.karosHeatTileRed.blockID);
		world.setBlock(i + 22, j + 0, k + 11, VetheaBlockHelper.karosHeatTileRed.blockID);
		world.setBlock(i + 22, j + 0, k + 12, VetheaBlockHelper.karosHeatTileGreen.blockID);
		world.setBlock(i + 22, j + 0, k + 13, VetheaBlockHelper.karosHeatTileGreen.blockID);
		world.setBlock(i + 22, j + 0, k + 14, VetheaBlockHelper.karosHeatTileRed.blockID);
		world.setBlock(i + 22, j + 0, k + 15, VetheaBlockHelper.karosHeatTileRed.blockID);
		world.setBlock(i + 22, j + 0, k + 16, VetheaBlockHelper.karosHeatTileGreen.blockID);
		world.setBlock(i + 22, j + 0, k + 17, VetheaBlockHelper.karosHeatTileGreen.blockID);
		world.setBlock(i + 22, j + 0, k + 18, VetheaBlockHelper.karosBricks2.blockID);
		world.setBlock(i + 22, j + 0, k + 19, VetheaBlockHelper.karosBricks2.blockID);
		world.setBlock(i + 22, j + 1, k + 0, VetheaBlockHelper.karosBricks2.blockID);
		world.setBlock(i + 22, j + 1, k + 1, VetheaBlockHelper.karosBricks2.blockID);
		world.setBlock(i + 22, j + 1, k + 18, VetheaBlockHelper.karosBricks2.blockID);
		world.setBlock(i + 22, j + 1, k + 19, VetheaBlockHelper.karosBricks2.blockID);
		world.setBlock(i + 22, j + 2, k + 0, VetheaBlockHelper.karosBricks2.blockID);
		world1.setBlockWithMetadata(i + 22, j + 2, k + 1, VetheaBlockHelper.karosCannon.blockID, 3);
		world1.setBlockWithMetadata(i + 22, j + 2, k + 18, VetheaBlockHelper.karosCannon.blockID, 2);
		world.setBlock(i + 22, j + 2, k + 19, VetheaBlockHelper.karosBricks2.blockID);
		world.setBlock(i + 22, j + 3, k + 1, VetheaBlockHelper.karosBricks.blockID);
		world.setBlock(i + 22, j + 3, k + 18, VetheaBlockHelper.karosBricks.blockID);
		world.setBlock(i + 22, j + 4, k + 2, VetheaBlockHelper.karosBricks.blockID);
		world.setBlock(i + 22, j + 4, k + 12, VetheaBlockHelper.helioticBeam.blockID);
		world.setBlock(i + 22, j + 4, k + 13, VetheaBlockHelper.helioticBeam.blockID);
		world.setBlock(i + 22, j + 4, k + 14, VetheaBlockHelper.helioticBeam.blockID);
		world.setBlock(i + 22, j + 4, k + 17, VetheaBlockHelper.karosBricks.blockID);
		world.setBlock(i + 22, j + 5, k + 3, VetheaBlockHelper.karosBricks.blockID);
		world.setBlock(i + 22, j + 5, k + 4, VetheaBlockHelper.karosBricks2.blockID);
		world.setBlock(i + 22, j + 5, k + 5, VetheaBlockHelper.karosBricks.blockID);
		world.setBlock(i + 22, j + 5, k + 6, VetheaBlockHelper.karosBricks2.blockID);
		world.setBlock(i + 22, j + 5, k + 7, VetheaBlockHelper.karosBricks.blockID);
		world.setBlock(i + 22, j + 5, k + 8, VetheaBlockHelper.karosBricks2.blockID);
		world.setBlock(i + 22, j + 5, k + 9, VetheaBlockHelper.karosBricks.blockID);
		world.setBlock(i + 22, j + 5, k + 10, VetheaBlockHelper.karosBricks2.blockID);
		world.setBlock(i + 22, j + 5, k + 11, VetheaBlockHelper.karosBricks2.blockID);
		world.setBlock(i + 22, j + 5, k + 12, VetheaBlockHelper.karosBricks2.blockID);
		world.setBlock(i + 22, j + 5, k + 13, VetheaBlockHelper.karosBricks2.blockID);
		world.setBlock(i + 22, j + 5, k + 14, VetheaBlockHelper.karosBricks.blockID);
		world.setBlock(i + 22, j + 5, k + 15, VetheaBlockHelper.karosBricks2.blockID);
		world.setBlock(i + 22, j + 5, k + 16, VetheaBlockHelper.karosBricks.blockID);
		world.setBlock(i + 23, j + 0, k + 1, VetheaBlockHelper.karosBricks2.blockID);
		world.setBlock(i + 23, j + 0, k + 2, VetheaBlockHelper.karosHeatTileGreen.blockID);
		world.setBlock(i + 23, j + 0, k + 3, VetheaBlockHelper.karosHeatTileGreen.blockID);
		world.setBlock(i + 23, j + 0, k + 4, VetheaBlockHelper.karosHeatTileRed.blockID);
		world.setBlock(i + 23, j + 0, k + 5, VetheaBlockHelper.karosHeatTileRed.blockID);
		world.setBlock(i + 23, j + 0, k + 6, VetheaBlockHelper.karosHeatTileGreen.blockID);
		world.setBlock(i + 23, j + 0, k + 7, VetheaBlockHelper.karosHeatTileGreen.blockID);
		world.setBlock(i + 23, j + 0, k + 8, VetheaBlockHelper.karosHeatTileRed.blockID);
		world.setBlock(i + 23, j + 0, k + 9, VetheaBlockHelper.karosHeatTileRed.blockID);
		world.setBlock(i + 23, j + 0, k + 10, VetheaBlockHelper.karosHeatTileGreen.blockID);
		world.setBlock(i + 23, j + 0, k + 11, VetheaBlockHelper.karosHeatTileGreen.blockID);
		world.setBlock(i + 23, j + 0, k + 12, VetheaBlockHelper.karosHeatTileRed.blockID);
		world.setBlock(i + 23, j + 0, k + 13, VetheaBlockHelper.karosHeatTileRed.blockID);
		world.setBlock(i + 23, j + 0, k + 14, VetheaBlockHelper.karosHeatTileGreen.blockID);
		world.setBlock(i + 23, j + 0, k + 15, VetheaBlockHelper.karosHeatTileGreen.blockID);
		world.setBlock(i + 23, j + 0, k + 16, VetheaBlockHelper.karosHeatTileRed.blockID);
		world.setBlock(i + 23, j + 0, k + 17, VetheaBlockHelper.karosHeatTileRed.blockID);
		world.setBlock(i + 23, j + 0, k + 18, VetheaBlockHelper.karosBricks2.blockID);
		world.setBlock(i + 23, j + 1, k + 1, VetheaBlockHelper.karosBricks2.blockID);
		world.setBlock(i + 23, j + 1, k + 18, VetheaBlockHelper.karosBricks2.blockID);
		world.setBlock(i + 23, j + 2, k + 1, VetheaBlockHelper.karosBricks.blockID);
		world.setBlock(i + 23, j + 2, k + 18, VetheaBlockHelper.karosBricks.blockID);
		world.setBlock(i + 23, j + 3, k + 1, VetheaBlockHelper.karosBricks.blockID);
		world.setBlock(i + 23, j + 3, k + 18, VetheaBlockHelper.karosBricks.blockID);
		world.setBlock(i + 23, j + 4, k + 2, VetheaBlockHelper.karosBricks.blockID);
		world.setBlock(i + 23, j + 4, k + 4, VetheaBlockHelper.helioticBeam.blockID);
		world.setBlock(i + 23, j + 4, k + 5, VetheaBlockHelper.helioticBeam.blockID);
		world.setBlock(i + 23, j + 4, k + 6, VetheaBlockHelper.helioticBeam.blockID);
		world.setBlock(i + 23, j + 4, k + 12, VetheaBlockHelper.helioticBeam.blockID);
		world.setBlock(i + 23, j + 4, k + 13, VetheaBlockHelper.helioticBeam.blockID);
		world.setBlock(i + 23, j + 4, k + 14, VetheaBlockHelper.helioticBeam.blockID);
		world.setBlock(i + 23, j + 4, k + 17, VetheaBlockHelper.karosBricks.blockID);
		world.setBlock(i + 23, j + 5, k + 3, VetheaBlockHelper.karosBricks.blockID);
		world.setBlock(i + 23, j + 5, k + 4, VetheaBlockHelper.karosBricks2.blockID);
		world.setBlock(i + 23, j + 5, k + 5, VetheaBlockHelper.karosBricks.blockID);
		world.setBlock(i + 23, j + 5, k + 6, VetheaBlockHelper.karosBricks2.blockID);
		world.setBlock(i + 23, j + 5, k + 7, VetheaBlockHelper.karosBricks.blockID);
		world.setBlock(i + 23, j + 5, k + 8, VetheaBlockHelper.karosBricks2.blockID);
		world.setBlock(i + 23, j + 5, k + 9, VetheaBlockHelper.karosBricks2.blockID);
		world.setBlock(i + 23, j + 5, k + 10, VetheaBlockHelper.karosBricks.blockID);
		world.setBlock(i + 23, j + 5, k + 11, VetheaBlockHelper.karosBricks2.blockID);
		world.setBlock(i + 23, j + 5, k + 12, VetheaBlockHelper.karosBricks2.blockID);
		world.setBlock(i + 23, j + 5, k + 13, VetheaBlockHelper.karosBricks2.blockID);
		world.setBlock(i + 23, j + 5, k + 14, VetheaBlockHelper.karosBricks.blockID);
		world.setBlock(i + 23, j + 5, k + 15, VetheaBlockHelper.karosBricks2.blockID);
		world.setBlock(i + 23, j + 5, k + 16, VetheaBlockHelper.karosBricks.blockID);
		world.setBlock(i + 24, j + 0, k + 0, VetheaBlockHelper.karosBricks2.blockID);
		world.setBlock(i + 24, j + 0, k + 1, VetheaBlockHelper.karosBricks2.blockID);
		world.setBlock(i + 24, j + 0, k + 2, VetheaBlockHelper.karosHeatTileGreen.blockID);
		world.setBlock(i + 24, j + 0, k + 3, VetheaBlockHelper.karosHeatTileGreen.blockID);
		world.setBlock(i + 24, j + 0, k + 4, VetheaBlockHelper.karosHeatTileRed.blockID);
		world.setBlock(i + 24, j + 0, k + 5, VetheaBlockHelper.karosHeatTileRed.blockID);
		world.setBlock(i + 24, j + 0, k + 6, VetheaBlockHelper.karosHeatTileGreen.blockID);
		world.setBlock(i + 24, j + 0, k + 7, VetheaBlockHelper.karosHeatTileGreen.blockID);
		world.setBlock(i + 24, j + 0, k + 8, VetheaBlockHelper.karosHeatTileRed.blockID);
		world.setBlock(i + 24, j + 0, k + 9, VetheaBlockHelper.karosHeatTileRed.blockID);
		world.setBlock(i + 24, j + 0, k + 10, VetheaBlockHelper.karosHeatTileGreen.blockID);
		world.setBlock(i + 24, j + 0, k + 11, VetheaBlockHelper.karosHeatTileGreen.blockID);
		world.setBlock(i + 24, j + 0, k + 12, VetheaBlockHelper.karosHeatTileRed.blockID);
		world.setBlock(i + 24, j + 0, k + 13, VetheaBlockHelper.karosHeatTileRed.blockID);
		world.setBlock(i + 24, j + 0, k + 14, VetheaBlockHelper.karosHeatTileGreen.blockID);
		world.setBlock(i + 24, j + 0, k + 15, VetheaBlockHelper.karosHeatTileGreen.blockID);
		world.setBlock(i + 24, j + 0, k + 16, VetheaBlockHelper.karosHeatTileRed.blockID);
		world.setBlock(i + 24, j + 0, k + 17, VetheaBlockHelper.karosHeatTileRed.blockID);
		world.setBlock(i + 24, j + 0, k + 18, VetheaBlockHelper.karosBricks2.blockID);
		world.setBlock(i + 24, j + 0, k + 19, VetheaBlockHelper.karosBricks2.blockID);
		world.setBlock(i + 24, j + 1, k + 0, VetheaBlockHelper.karosBricks2.blockID);
		world.setBlock(i + 24, j + 1, k + 1, VetheaBlockHelper.karosBricks2.blockID);
		world.setBlock(i + 24, j + 1, k + 18, VetheaBlockHelper.karosBricks2.blockID);
		world.setBlock(i + 24, j + 1, k + 19, VetheaBlockHelper.karosBricks2.blockID);
		world.setBlock(i + 24, j + 2, k + 0, VetheaBlockHelper.karosBricks2.blockID);
		world1.setBlockWithMetadata(i + 24, j + 2, k + 1, VetheaBlockHelper.karosCannon.blockID, 3);
		world1.setBlockWithMetadata(i + 24, j + 2, k + 18, VetheaBlockHelper.karosCannon.blockID, 2);
		world.setBlock(i + 24, j + 2, k + 19, VetheaBlockHelper.karosBricks2.blockID);
		world.setBlock(i + 24, j + 3, k + 1, VetheaBlockHelper.karosBricks.blockID);
		world.setBlock(i + 24, j + 3, k + 18, VetheaBlockHelper.karosBricks.blockID);
		world.setBlock(i + 24, j + 4, k + 2, VetheaBlockHelper.karosBricks.blockID);
		world.setBlock(i + 24, j + 4, k + 4, VetheaBlockHelper.helioticBeam.blockID);
		world.setBlock(i + 24, j + 4, k + 5, VetheaBlockHelper.helioticBeam.blockID);
		world.setBlock(i + 24, j + 4, k + 6, VetheaBlockHelper.helioticBeam.blockID);
		world.setBlock(i + 24, j + 4, k + 12, VetheaBlockHelper.helioticBeam.blockID);
		world.setBlock(i + 24, j + 4, k + 13, VetheaBlockHelper.helioticBeam.blockID);
		world.setBlock(i + 24, j + 4, k + 14, VetheaBlockHelper.helioticBeam.blockID);
		world.setBlock(i + 24, j + 4, k + 17, VetheaBlockHelper.karosBricks.blockID);
		world.setBlock(i + 24, j + 5, k + 3, VetheaBlockHelper.karosBricks.blockID);
		world.setBlock(i + 24, j + 5, k + 4, VetheaBlockHelper.karosBricks2.blockID);
		world.setBlock(i + 24, j + 5, k + 5, VetheaBlockHelper.karosBricks.blockID);
		world.setBlock(i + 24, j + 5, k + 6, VetheaBlockHelper.karosBricks2.blockID);
		world.setBlock(i + 24, j + 5, k + 7, VetheaBlockHelper.karosBricks2.blockID);
		world.setBlock(i + 24, j + 5, k + 8, VetheaBlockHelper.karosBricks2.blockID);
		world.setBlock(i + 24, j + 5, k + 9, VetheaBlockHelper.karosBricks2.blockID);
		world.setBlock(i + 24, j + 5, k + 10, VetheaBlockHelper.karosBricks2.blockID);
		world.setBlock(i + 24, j + 5, k + 11, VetheaBlockHelper.karosBricks2.blockID);
		world.setBlock(i + 24, j + 5, k + 12, VetheaBlockHelper.karosBricks2.blockID);
		world.setBlock(i + 24, j + 5, k + 13, VetheaBlockHelper.karosBricks2.blockID);
		world.setBlock(i + 24, j + 5, k + 14, VetheaBlockHelper.karosBricks.blockID);
		world.setBlock(i + 24, j + 5, k + 15, VetheaBlockHelper.karosBricks2.blockID);
		world.setBlock(i + 24, j + 5, k + 16, VetheaBlockHelper.karosBricks.blockID);
		world.setBlock(i + 25, j + 0, k + 1, VetheaBlockHelper.karosBricks2.blockID);
		world.setBlock(i + 25, j + 0, k + 2, VetheaBlockHelper.karosHeatTileRed.blockID);
		world.setBlock(i + 25, j + 0, k + 3, VetheaBlockHelper.karosHeatTileRed.blockID);
		world.setBlock(i + 25, j + 0, k + 4, VetheaBlockHelper.karosHeatTileGreen.blockID);
		world.setBlock(i + 25, j + 0, k + 5, VetheaBlockHelper.karosHeatTileGreen.blockID);
		world.setBlock(i + 25, j + 0, k + 6, VetheaBlockHelper.karosHeatTileRed.blockID);
		world.setBlock(i + 25, j + 0, k + 7, VetheaBlockHelper.karosHeatTileRed.blockID);
		world.setBlock(i + 25, j + 0, k + 8, VetheaBlockHelper.karosHeatTileGreen.blockID);
		world.setBlock(i + 25, j + 0, k + 9, VetheaBlockHelper.karosHeatTileGreen.blockID);
		world.setBlock(i + 25, j + 0, k + 10, VetheaBlockHelper.karosHeatTileRed.blockID);
		world.setBlock(i + 25, j + 0, k + 11, VetheaBlockHelper.karosHeatTileRed.blockID);
		world.setBlock(i + 25, j + 0, k + 12, VetheaBlockHelper.karosHeatTileGreen.blockID);
		world.setBlock(i + 25, j + 0, k + 13, VetheaBlockHelper.karosHeatTileGreen.blockID);
		world.setBlock(i + 25, j + 0, k + 14, VetheaBlockHelper.karosHeatTileRed.blockID);
		world.setBlock(i + 25, j + 0, k + 15, VetheaBlockHelper.karosHeatTileRed.blockID);
		world.setBlock(i + 25, j + 0, k + 16, VetheaBlockHelper.karosHeatTileGreen.blockID);
		world.setBlock(i + 25, j + 0, k + 17, VetheaBlockHelper.karosHeatTileGreen.blockID);
		world.setBlock(i + 25, j + 0, k + 18, VetheaBlockHelper.karosBricks2.blockID);
		world.setBlock(i + 25, j + 1, k + 1, VetheaBlockHelper.karosBricks2.blockID);
		world.setBlock(i + 25, j + 1, k + 18, VetheaBlockHelper.karosBricks2.blockID);
		world.setBlock(i + 25, j + 2, k + 1, VetheaBlockHelper.karosBricks.blockID);
		world.setBlock(i + 25, j + 2, k + 18, VetheaBlockHelper.karosBricks.blockID);
		world.setBlock(i + 25, j + 3, k + 1, VetheaBlockHelper.karosBricks.blockID);
		world.setBlock(i + 25, j + 3, k + 18, VetheaBlockHelper.karosBricks.blockID);
		world.setBlock(i + 25, j + 4, k + 2, VetheaBlockHelper.karosBricks.blockID);
		world.setBlock(i + 25, j + 4, k + 4, VetheaBlockHelper.helioticBeam.blockID);
		world.setBlock(i + 25, j + 4, k + 5, VetheaBlockHelper.helioticBeam.blockID);
		world.setBlock(i + 25, j + 4, k + 6, VetheaBlockHelper.helioticBeam.blockID);
		world.setBlock(i + 25, j + 4, k + 17, VetheaBlockHelper.karosBricks.blockID);
		world.setBlock(i + 25, j + 5, k + 3, VetheaBlockHelper.karosBricks.blockID);
		world.setBlock(i + 25, j + 5, k + 4, VetheaBlockHelper.karosBricks2.blockID);
		world.setBlock(i + 25, j + 5, k + 5, VetheaBlockHelper.karosBricks.blockID);
		world.setBlock(i + 25, j + 5, k + 6, VetheaBlockHelper.karosBricks.blockID);
		world.setBlock(i + 25, j + 5, k + 7, VetheaBlockHelper.karosBricks.blockID);
		world.setBlock(i + 25, j + 5, k + 8, VetheaBlockHelper.karosBricks.blockID);
		world.setBlock(i + 25, j + 5, k + 9, VetheaBlockHelper.karosBricks.blockID);
		world.setBlock(i + 25, j + 5, k + 10, VetheaBlockHelper.karosBricks.blockID);
		world.setBlock(i + 25, j + 5, k + 11, VetheaBlockHelper.karosBricks.blockID);
		world.setBlock(i + 25, j + 5, k + 12, VetheaBlockHelper.karosBricks.blockID);
		world.setBlock(i + 25, j + 5, k + 13, VetheaBlockHelper.karosBricks.blockID);
		world.setBlock(i + 25, j + 5, k + 14, VetheaBlockHelper.karosBricks.blockID);
		world.setBlock(i + 25, j + 5, k + 15, VetheaBlockHelper.karosBricks2.blockID);
		world.setBlock(i + 25, j + 5, k + 16, VetheaBlockHelper.karosBricks.blockID);
		world.setBlock(i + 26, j + 0, k + 0, VetheaBlockHelper.karosBricks2.blockID);
		world.setBlock(i + 26, j + 0, k + 1, VetheaBlockHelper.karosBricks2.blockID);
		world.setBlock(i + 26, j + 0, k + 2, VetheaBlockHelper.karosHeatTileRed.blockID);
		world.setBlock(i + 26, j + 0, k + 3, VetheaBlockHelper.karosHeatTileRed.blockID);
		world.setBlock(i + 26, j + 0, k + 4, VetheaBlockHelper.karosHeatTileGreen.blockID);
		world.setBlock(i + 26, j + 0, k + 5, VetheaBlockHelper.karosHeatTileGreen.blockID);
		world.setBlock(i + 26, j + 0, k + 6, VetheaBlockHelper.karosHeatTileRed.blockID);
		world.setBlock(i + 26, j + 0, k + 7, VetheaBlockHelper.karosHeatTileRed.blockID);
		world.setBlock(i + 26, j + 0, k + 8, VetheaBlockHelper.karosHeatTileGreen.blockID);
		world.setBlock(i + 26, j + 0, k + 9, VetheaBlockHelper.karosHeatTileGreen.blockID);
		world.setBlock(i + 26, j + 0, k + 10, VetheaBlockHelper.karosHeatTileRed.blockID);
		world.setBlock(i + 26, j + 0, k + 11, VetheaBlockHelper.karosHeatTileRed.blockID);
		world.setBlock(i + 26, j + 0, k + 12, VetheaBlockHelper.karosHeatTileGreen.blockID);
		world.setBlock(i + 26, j + 0, k + 13, VetheaBlockHelper.karosHeatTileGreen.blockID);
		world.setBlock(i + 26, j + 0, k + 14, VetheaBlockHelper.karosHeatTileRed.blockID);
		world.setBlock(i + 26, j + 0, k + 15, VetheaBlockHelper.karosHeatTileRed.blockID);
		world.setBlock(i + 26, j + 0, k + 16, VetheaBlockHelper.karosHeatTileGreen.blockID);
		world.setBlock(i + 26, j + 0, k + 17, VetheaBlockHelper.karosHeatTileGreen.blockID);
		world.setBlock(i + 26, j + 0, k + 18, VetheaBlockHelper.karosBricks2.blockID);
		world.setBlock(i + 26, j + 0, k + 19, VetheaBlockHelper.karosBricks2.blockID);
		world.setBlock(i + 26, j + 1, k + 0, VetheaBlockHelper.karosBricks2.blockID);
		world.setBlock(i + 26, j + 1, k + 1, VetheaBlockHelper.karosBricks2.blockID);
		world.setBlock(i + 26, j + 1, k + 9, VetheaBlockHelper.villageLamp.blockID);
		world.setBlock(i + 26, j + 1, k + 10, VetheaBlockHelper.villageLamp.blockID);
		world.setBlock(i + 26, j + 1, k + 18, VetheaBlockHelper.karosBricks2.blockID);
		world.setBlock(i + 26, j + 1, k + 19, VetheaBlockHelper.karosBricks2.blockID);
		world.setBlock(i + 26, j + 2, k + 0, VetheaBlockHelper.karosBricks2.blockID);
		world1.setBlockWithMetadata(i + 26, j + 2, k + 1, VetheaBlockHelper.karosCannon.blockID, 3);
		world1.setBlockWithMetadata(i + 26, j + 2, k + 18, VetheaBlockHelper.karosCannon.blockID, 2);
		world.setBlock(i + 26, j + 2, k + 19, VetheaBlockHelper.karosBricks2.blockID);
		world.setBlock(i + 26, j + 3, k + 1, VetheaBlockHelper.karosBricks.blockID);
		world.setBlock(i + 26, j + 3, k + 18, VetheaBlockHelper.karosBricks.blockID);
		world.setBlock(i + 26, j + 4, k + 2, VetheaBlockHelper.karosBricks.blockID);
		world.setBlock(i + 26, j + 4, k + 17, VetheaBlockHelper.karosBricks.blockID);
		world.setBlock(i + 26, j + 5, k + 3, VetheaBlockHelper.karosBricks.blockID);
		world.setBlock(i + 26, j + 5, k + 4, VetheaBlockHelper.karosBricks2.blockID);
		world.setBlock(i + 26, j + 5, k + 5, VetheaBlockHelper.karosBricks2.blockID);
		world.setBlock(i + 26, j + 5, k + 6, VetheaBlockHelper.karosBricks2.blockID);
		world.setBlock(i + 26, j + 5, k + 7, VetheaBlockHelper.karosBricks2.blockID);
		world.setBlock(i + 26, j + 5, k + 8, VetheaBlockHelper.karosBricks2.blockID);
		world.setBlock(i + 26, j + 5, k + 9, VetheaBlockHelper.karosBricks2.blockID);
		world.setBlock(i + 26, j + 5, k + 10, VetheaBlockHelper.karosBricks2.blockID);
		world.setBlock(i + 26, j + 5, k + 11, VetheaBlockHelper.karosBricks2.blockID);
		world.setBlock(i + 26, j + 5, k + 12, VetheaBlockHelper.karosBricks2.blockID);
		world.setBlock(i + 26, j + 5, k + 13, VetheaBlockHelper.karosBricks2.blockID);
		world.setBlock(i + 26, j + 5, k + 14, VetheaBlockHelper.karosBricks2.blockID);
		world.setBlock(i + 26, j + 5, k + 15, VetheaBlockHelper.karosBricks2.blockID);
		world.setBlock(i + 26, j + 5, k + 16, VetheaBlockHelper.karosBricks.blockID);
		world.setBlock(i + 27, j + 0, k + 1, VetheaBlockHelper.karosBricks2.blockID);
		world.setBlock(i + 27, j + 0, k + 2, VetheaBlockHelper.karosHeatTileGreen.blockID);
		world.setBlock(i + 27, j + 0, k + 3, VetheaBlockHelper.karosHeatTileGreen.blockID);
		world.setBlock(i + 27, j + 0, k + 4, VetheaBlockHelper.karosHeatTileRed.blockID);
		world.setBlock(i + 27, j + 0, k + 5, VetheaBlockHelper.karosHeatTileRed.blockID);
		world.setBlock(i + 27, j + 0, k + 6, VetheaBlockHelper.karosHeatTileGreen.blockID);
		world.setBlock(i + 27, j + 0, k + 7, VetheaBlockHelper.karosHeatTileGreen.blockID);
		world.setBlock(i + 27, j + 0, k + 8, VetheaBlockHelper.karosHeatTileRed.blockID);
		world.setBlock(i + 27, j + 0, k + 9, VetheaBlockHelper.karosHeatTileRed.blockID);
		world.setBlock(i + 27, j + 0, k + 10, VetheaBlockHelper.karosHeatTileGreen.blockID);
		world.setBlock(i + 27, j + 0, k + 11, VetheaBlockHelper.karosHeatTileGreen.blockID);
		world.setBlock(i + 27, j + 0, k + 12, VetheaBlockHelper.karosHeatTileRed.blockID);
		world.setBlock(i + 27, j + 0, k + 13, VetheaBlockHelper.karosHeatTileRed.blockID);
		world.setBlock(i + 27, j + 0, k + 14, VetheaBlockHelper.karosHeatTileGreen.blockID);
		world.setBlock(i + 27, j + 0, k + 15, VetheaBlockHelper.karosHeatTileGreen.blockID);
		world.setBlock(i + 27, j + 0, k + 16, VetheaBlockHelper.karosHeatTileRed.blockID);
		world.setBlock(i + 27, j + 0, k + 17, VetheaBlockHelper.karosHeatTileRed.blockID);
		world.setBlock(i + 27, j + 0, k + 18, VetheaBlockHelper.karosBricks2.blockID);
		world.setBlock(i + 27, j + 1, k + 1, VetheaBlockHelper.karosBricks2.blockID);
		world.setBlock(i + 27, j + 1, k + 9, VetheaBlockHelper.villageLamp.blockID);
		world.setBlock(i + 27, j + 1, k + 10, VetheaBlockHelper.villageLamp.blockID);
		world.setBlock(i + 27, j + 1, k + 18, VetheaBlockHelper.karosBricks2.blockID);
		world.setBlock(i + 27, j + 2, k + 1, VetheaBlockHelper.karosBricks.blockID);
		world.setBlock(i + 27, j + 2, k + 9, VetheaBlockHelper.karosAltar.blockID);
		world.setBlock(i + 27, j + 2, k + 18, VetheaBlockHelper.karosBricks.blockID);
		world.setBlock(i + 27, j + 3, k + 1, VetheaBlockHelper.karosBricks.blockID);
		world.setBlock(i + 27, j + 3, k + 18, VetheaBlockHelper.karosBricks.blockID);
		world.setBlock(i + 27, j + 4, k + 2, VetheaBlockHelper.karosBricks.blockID);
		world.setBlock(i + 27, j + 4, k + 17, VetheaBlockHelper.karosBricks.blockID);
		world.setBlock(i + 27, j + 5, k + 3, VetheaBlockHelper.karosBricks.blockID);
		world.setBlock(i + 27, j + 5, k + 4, VetheaBlockHelper.karosBricks.blockID);
		world.setBlock(i + 27, j + 5, k + 5, VetheaBlockHelper.karosBricks.blockID);
		world.setBlock(i + 27, j + 5, k + 6, VetheaBlockHelper.karosBricks.blockID);
		world.setBlock(i + 27, j + 5, k + 7, VetheaBlockHelper.karosBricks.blockID);
		world.setBlock(i + 27, j + 5, k + 8, VetheaBlockHelper.karosBricks.blockID);
		world.setBlock(i + 27, j + 5, k + 9, VetheaBlockHelper.karosBricks.blockID);
		world.setBlock(i + 27, j + 5, k + 10, VetheaBlockHelper.karosBricks.blockID);
		world.setBlock(i + 27, j + 5, k + 11, VetheaBlockHelper.karosBricks.blockID);
		world.setBlock(i + 27, j + 5, k + 12, VetheaBlockHelper.karosBricks.blockID);
		world.setBlock(i + 27, j + 5, k + 13, VetheaBlockHelper.karosBricks.blockID);
		world.setBlock(i + 27, j + 5, k + 14, VetheaBlockHelper.karosBricks.blockID);
		world.setBlock(i + 27, j + 5, k + 15, VetheaBlockHelper.karosBricks.blockID);
		world.setBlock(i + 27, j + 5, k + 16, VetheaBlockHelper.karosBricks.blockID);
		world.setBlock(i + 28, j + 0, k + 0, VetheaBlockHelper.karosBricks2.blockID);
		world.setBlock(i + 28, j + 0, k + 1, VetheaBlockHelper.karosBricks2.blockID);
		world.setBlock(i + 28, j + 0, k + 2, VetheaBlockHelper.karosHeatTileGreen.blockID);
		world.setBlock(i + 28, j + 0, k + 3, VetheaBlockHelper.karosHeatTileGreen.blockID);
		world.setBlock(i + 28, j + 0, k + 4, VetheaBlockHelper.karosHeatTileRed.blockID);
		world.setBlock(i + 28, j + 0, k + 5, VetheaBlockHelper.karosHeatTileRed.blockID);
		world.setBlock(i + 28, j + 0, k + 6, VetheaBlockHelper.karosHeatTileGreen.blockID);
		world.setBlock(i + 28, j + 0, k + 7, VetheaBlockHelper.karosHeatTileGreen.blockID);
		world.setBlock(i + 28, j + 0, k + 8, VetheaBlockHelper.karosHeatTileRed.blockID);
		world.setBlock(i + 28, j + 0, k + 9, VetheaBlockHelper.karosHeatTileRed.blockID);
		world.setBlock(i + 28, j + 0, k + 10, VetheaBlockHelper.karosHeatTileGreen.blockID);
		world.setBlock(i + 28, j + 0, k + 11, VetheaBlockHelper.karosHeatTileGreen.blockID);
		world.setBlock(i + 28, j + 0, k + 12, VetheaBlockHelper.karosHeatTileRed.blockID);
		world.setBlock(i + 28, j + 0, k + 13, VetheaBlockHelper.karosHeatTileRed.blockID);
		world.setBlock(i + 28, j + 0, k + 14, VetheaBlockHelper.karosHeatTileGreen.blockID);
		world.setBlock(i + 28, j + 0, k + 15, VetheaBlockHelper.karosHeatTileGreen.blockID);
		world.setBlock(i + 28, j + 0, k + 16, VetheaBlockHelper.karosHeatTileRed.blockID);
		world.setBlock(i + 28, j + 0, k + 17, VetheaBlockHelper.karosHeatTileRed.blockID);
		world.setBlock(i + 28, j + 0, k + 18, VetheaBlockHelper.karosBricks2.blockID);
		world.setBlock(i + 28, j + 0, k + 19, VetheaBlockHelper.karosBricks2.blockID);
		world.setBlock(i + 28, j + 1, k + 0, VetheaBlockHelper.karosBricks2.blockID);
		world.setBlock(i + 28, j + 1, k + 1, VetheaBlockHelper.karosBricks2.blockID);
		world.setBlock(i + 28, j + 1, k + 9, VetheaBlockHelper.villageLamp.blockID);
		world.setBlock(i + 28, j + 1, k + 10, VetheaBlockHelper.villageLamp.blockID);
		world.setBlock(i + 28, j + 1, k + 18, VetheaBlockHelper.karosBricks2.blockID);
		world.setBlock(i + 28, j + 1, k + 19, VetheaBlockHelper.karosBricks2.blockID);
		world.setBlock(i + 28, j + 2, k + 0, VetheaBlockHelper.karosBricks2.blockID);
		world1.setBlockWithMetadata(i + 28, j + 2, k + 1, VetheaBlockHelper.karosCannon.blockID, 3);
		world1.setBlockWithMetadata(i + 28, j + 2, k + 18, VetheaBlockHelper.karosCannon.blockID, 2);
		world.setBlock(i + 28, j + 2, k + 19, VetheaBlockHelper.karosBricks2.blockID);
		world.setBlock(i + 28, j + 3, k + 1, VetheaBlockHelper.karosBricks.blockID);
		world1.setBlockWithMetadata(i + 28, j + 3, k + 9, VetheaBlockHelper.karosCannon.blockID, 4);
		world1.setBlockWithMetadata(i + 28, j + 3, k + 10, VetheaBlockHelper.karosCannon.blockID, 4);
		world.setBlock(i + 28, j + 3, k + 18, VetheaBlockHelper.karosBricks.blockID);
		world.setBlock(i + 28, j + 4, k + 2, VetheaBlockHelper.karosBricks.blockID);
		world.setBlock(i + 28, j + 4, k + 3, VetheaBlockHelper.karosBricks.blockID);
		world.setBlock(i + 28, j + 4, k + 4, VetheaBlockHelper.karosBricks.blockID);
		world.setBlock(i + 28, j + 4, k + 5, VetheaBlockHelper.karosBricks.blockID);
		world.setBlock(i + 28, j + 4, k + 6, VetheaBlockHelper.karosBricks.blockID);
		world.setBlock(i + 28, j + 4, k + 7, VetheaBlockHelper.karosBricks.blockID);
		world.setBlock(i + 28, j + 4, k + 8, VetheaBlockHelper.karosBricks.blockID);
		world.setBlock(i + 28, j + 4, k + 9, VetheaBlockHelper.karosBricks.blockID);
		world.setBlock(i + 28, j + 4, k + 10, VetheaBlockHelper.karosBricks.blockID);
		world.setBlock(i + 28, j + 4, k + 11, VetheaBlockHelper.karosBricks.blockID);
		world.setBlock(i + 28, j + 4, k + 12, VetheaBlockHelper.karosBricks.blockID);
		world.setBlock(i + 28, j + 4, k + 13, VetheaBlockHelper.karosBricks.blockID);
		world.setBlock(i + 28, j + 4, k + 14, VetheaBlockHelper.karosBricks.blockID);
		world.setBlock(i + 28, j + 4, k + 15, VetheaBlockHelper.karosBricks.blockID);
		world.setBlock(i + 28, j + 4, k + 16, VetheaBlockHelper.karosBricks.blockID);
		world.setBlock(i + 28, j + 4, k + 17, VetheaBlockHelper.karosBricks.blockID);
		world.setBlock(i + 29, j + 0, k + 1, VetheaBlockHelper.karosBricks2.blockID);
		world.setBlock(i + 29, j + 0, k + 2, VetheaBlockHelper.karosBricks2.blockID);
		world.setBlock(i + 29, j + 0, k + 3, VetheaBlockHelper.karosBricks2.blockID);
		world.setBlock(i + 29, j + 0, k + 4, VetheaBlockHelper.karosBricks2.blockID);
		world.setBlock(i + 29, j + 0, k + 5, VetheaBlockHelper.karosBricks2.blockID);
		world.setBlock(i + 29, j + 0, k + 6, VetheaBlockHelper.karosBricks2.blockID);
		world.setBlock(i + 29, j + 0, k + 7, VetheaBlockHelper.karosBricks2.blockID);
		world.setBlock(i + 29, j + 0, k + 8, VetheaBlockHelper.karosBricks2.blockID);
		world.setBlock(i + 29, j + 0, k + 9, VetheaBlockHelper.karosBricks2.blockID);
		world.setBlock(i + 29, j + 0, k + 10, VetheaBlockHelper.karosBricks2.blockID);
		world.setBlock(i + 29, j + 0, k + 11, VetheaBlockHelper.karosBricks2.blockID);
		world.setBlock(i + 29, j + 0, k + 12, VetheaBlockHelper.karosBricks2.blockID);
		world.setBlock(i + 29, j + 0, k + 13, VetheaBlockHelper.karosBricks2.blockID);
		world.setBlock(i + 29, j + 0, k + 14, VetheaBlockHelper.karosBricks2.blockID);
		world.setBlock(i + 29, j + 0, k + 15, VetheaBlockHelper.karosBricks2.blockID);
		world.setBlock(i + 29, j + 0, k + 16, VetheaBlockHelper.karosBricks2.blockID);
		world.setBlock(i + 29, j + 0, k + 17, VetheaBlockHelper.karosBricks2.blockID);
		world.setBlock(i + 29, j + 0, k + 18, VetheaBlockHelper.karosBricks2.blockID);
		world.setBlock(i + 29, j + 1, k + 1, VetheaBlockHelper.karosBricks2.blockID);
		world.setBlock(i + 29, j + 1, k + 2, VetheaBlockHelper.karosBricks2.blockID);
		world.setBlock(i + 29, j + 1, k + 3, VetheaBlockHelper.karosBricks2.blockID);
		world.setBlock(i + 29, j + 1, k + 4, VetheaBlockHelper.karosBricks2.blockID);
		world.setBlock(i + 29, j + 1, k + 5, VetheaBlockHelper.karosBricks2.blockID);
		world.setBlock(i + 29, j + 1, k + 6, VetheaBlockHelper.karosBricks2.blockID);
		world.setBlock(i + 29, j + 1, k + 7, VetheaBlockHelper.karosBricks2.blockID);
		world.setBlock(i + 29, j + 1, k + 8, VetheaBlockHelper.karosBricks2.blockID);
		world.setBlock(i + 29, j + 1, k + 9, VetheaBlockHelper.karosBricks2.blockID);
		world.setBlock(i + 29, j + 1, k + 10, VetheaBlockHelper.karosBricks2.blockID);
		world.setBlock(i + 29, j + 1, k + 11, VetheaBlockHelper.karosBricks2.blockID);
		world.setBlock(i + 29, j + 1, k + 12, VetheaBlockHelper.karosBricks2.blockID);
		world.setBlock(i + 29, j + 1, k + 13, VetheaBlockHelper.karosBricks2.blockID);
		world.setBlock(i + 29, j + 1, k + 14, VetheaBlockHelper.karosBricks2.blockID);
		world.setBlock(i + 29, j + 1, k + 15, VetheaBlockHelper.karosBricks2.blockID);
		world.setBlock(i + 29, j + 1, k + 16, VetheaBlockHelper.karosBricks2.blockID);
		world.setBlock(i + 29, j + 1, k + 17, VetheaBlockHelper.karosBricks2.blockID);
		world.setBlock(i + 29, j + 1, k + 18, VetheaBlockHelper.karosBricks2.blockID);
		world.setBlock(i + 29, j + 2, k + 1, VetheaBlockHelper.karosBricks.blockID);
		world1.setBlockWithMetadata(i + 29, j + 2, k + 2, VetheaBlockHelper.karosCannon.blockID, 4);
		world.setBlock(i + 29, j + 2, k + 3, VetheaBlockHelper.karosBricks.blockID);
		world1.setBlockWithMetadata(i + 29, j + 2, k + 4, VetheaBlockHelper.karosCannon.blockID, 4);
		world.setBlock(i + 29, j + 2, k + 5, VetheaBlockHelper.karosBricks.blockID);
		world1.setBlockWithMetadata(i + 29, j + 2, k + 6, VetheaBlockHelper.karosCannon.blockID, 4);
		world.setBlock(i + 29, j + 2, k + 7, VetheaBlockHelper.karosBricks.blockID);
		world1.setBlockWithMetadata(i + 29, j + 2, k + 8, VetheaBlockHelper.karosCannon.blockID, 4);
		world1.setBlockWithMetadata(i + 29, j + 2, k + 9, VetheaBlockHelper.karosCannon.blockID, 4);
		world1.setBlockWithMetadata(i + 29, j + 2, k + 10, VetheaBlockHelper.karosCannon.blockID, 4);
		world1.setBlockWithMetadata(i + 29, j + 2, k + 11, VetheaBlockHelper.karosCannon.blockID, 4);
		world.setBlock(i + 29, j + 2, k + 12, VetheaBlockHelper.karosBricks.blockID);
		world1.setBlockWithMetadata(i + 29, j + 2, k + 13, VetheaBlockHelper.karosCannon.blockID, 4);
		world.setBlock(i + 29, j + 2, k + 14, VetheaBlockHelper.karosBricks.blockID);
		world1.setBlockWithMetadata(i + 29, j + 2, k + 15, VetheaBlockHelper.karosCannon.blockID, 4);
		world.setBlock(i + 29, j + 2, k + 16, VetheaBlockHelper.karosBricks.blockID);
		world1.setBlockWithMetadata(i + 29, j + 2, k + 17, VetheaBlockHelper.karosCannon.blockID, 4);
		world.setBlock(i + 29, j + 2, k + 18, VetheaBlockHelper.karosBricks.blockID);
		world.setBlock(i + 29, j + 3, k + 1, VetheaBlockHelper.karosBricks.blockID);
		world.setBlock(i + 29, j + 3, k + 2, VetheaBlockHelper.karosBricks.blockID);
		world.setBlock(i + 29, j + 3, k + 3, VetheaBlockHelper.karosBricks.blockID);
		world.setBlock(i + 29, j + 3, k + 4, VetheaBlockHelper.karosBricks.blockID);
		world.setBlock(i + 29, j + 3, k + 5, VetheaBlockHelper.karosBricks.blockID);
		world.setBlock(i + 29, j + 3, k + 6, VetheaBlockHelper.karosBricks.blockID);
		world.setBlock(i + 29, j + 3, k + 7, VetheaBlockHelper.karosBricks.blockID);
		world.setBlock(i + 29, j + 3, k + 8, VetheaBlockHelper.karosBricks.blockID);
		world.setBlock(i + 29, j + 3, k + 9, VetheaBlockHelper.karosBricks.blockID);
		world.setBlock(i + 29, j + 3, k + 10, VetheaBlockHelper.karosBricks.blockID);
		world.setBlock(i + 29, j + 3, k + 11, VetheaBlockHelper.karosBricks.blockID);
		world.setBlock(i + 29, j + 3, k + 12, VetheaBlockHelper.karosBricks.blockID);
		world.setBlock(i + 29, j + 3, k + 13, VetheaBlockHelper.karosBricks.blockID);
		world.setBlock(i + 29, j + 3, k + 14, VetheaBlockHelper.karosBricks.blockID);
		world.setBlock(i + 29, j + 3, k + 15, VetheaBlockHelper.karosBricks.blockID);
		world.setBlock(i + 29, j + 3, k + 16, VetheaBlockHelper.karosBricks.blockID);
		world.setBlock(i + 29, j + 3, k + 17, VetheaBlockHelper.karosBricks.blockID);
		world.setBlock(i + 29, j + 3, k + 18, VetheaBlockHelper.karosBricks.blockID);
		world.setBlock(i + 30, j + 0, k + 2, VetheaBlockHelper.karosBricks2.blockID);
		world.setBlock(i + 30, j + 0, k + 4, VetheaBlockHelper.karosBricks2.blockID);
		world.setBlock(i + 30, j + 0, k + 6, VetheaBlockHelper.karosBricks2.blockID);
		world.setBlock(i + 30, j + 0, k + 8, VetheaBlockHelper.karosBricks2.blockID);
		world.setBlock(i + 30, j + 0, k + 11, VetheaBlockHelper.karosBricks2.blockID);
		world.setBlock(i + 30, j + 0, k + 13, VetheaBlockHelper.karosBricks2.blockID);
		world.setBlock(i + 30, j + 0, k + 15, VetheaBlockHelper.karosBricks2.blockID);
		world.setBlock(i + 30, j + 0, k + 17, VetheaBlockHelper.karosBricks2.blockID);
		world.setBlock(i + 30, j + 1, k + 2, VetheaBlockHelper.karosBricks2.blockID);
		world.setBlock(i + 30, j + 1, k + 4, VetheaBlockHelper.karosBricks2.blockID);
		world.setBlock(i + 30, j + 1, k + 6, VetheaBlockHelper.karosBricks2.blockID);
		world.setBlock(i + 30, j + 1, k + 8, VetheaBlockHelper.karosBricks2.blockID);
		world.setBlock(i + 30, j + 1, k + 11, VetheaBlockHelper.karosBricks2.blockID);
		world.setBlock(i + 30, j + 1, k + 13, VetheaBlockHelper.karosBricks2.blockID);
		world.setBlock(i + 30, j + 1, k + 15, VetheaBlockHelper.karosBricks2.blockID);
		world.setBlock(i + 30, j + 1, k + 17, VetheaBlockHelper.karosBricks2.blockID);
		world.setBlock(i + 30, j + 2, k + 2, VetheaBlockHelper.karosBricks2.blockID);
		world.setBlock(i + 30, j + 2, k + 4, VetheaBlockHelper.karosBricks2.blockID);
		world.setBlock(i + 30, j + 2, k + 6, VetheaBlockHelper.karosBricks2.blockID);
		world.setBlock(i + 30, j + 2, k + 8, VetheaBlockHelper.karosBricks2.blockID);
		world.setBlock(i + 30, j + 2, k + 9, VetheaBlockHelper.karosBricks2.blockID);
		world.setBlock(i + 30, j + 2, k + 10, VetheaBlockHelper.karosBricks2.blockID);
		world.setBlock(i + 30, j + 2, k + 11, VetheaBlockHelper.karosBricks2.blockID);
		world.setBlock(i + 30, j + 2, k + 13, VetheaBlockHelper.karosBricks2.blockID);
		world.setBlock(i + 30, j + 2, k + 15, VetheaBlockHelper.karosBricks2.blockID);
		world.setBlock(i + 30, j + 2, k + 17, VetheaBlockHelper.karosBricks2.blockID);

		return true;
	}
}