/*
*** MADE BY MITHION'S .SCHEMATIC TO JAVA CONVERTING TOOL v1.6 ***
*/

package xolova.blued00r.divinerpg.generation.vethea.layer3;
import java.util.Random;

import xolova.blued00r.divinerpg.DivineRPG;

import net.minecraft.world.World;
import net.minecraft.world.gen.feature.WorldGenerator;

public class QuadroticPost extends WorldGenerator
{
	protected int[] GetValidSpawnBlocks() {
		return new int[] {
		};
	}

	public QuadroticPost() { }

	public boolean generate(World world, Random rand, int i, int j, int k) {

		world.setBlock(i + 0, j + 5, k + 0, DivineRPGTwilight.dreambricks2.blockID);
		world.setBlock(i + 0, j + 5, k + 1, DivineRPGTwilight.firelight.blockID);
		world.setBlock(i + 0, j + 5, k + 2, DivineRPGTwilight.firelight.blockID);
		world.setBlock(i + 0, j + 5, k + 3, DivineRPGTwilight.dreambricks2.blockID);
		world.setBlock(i + 1, j + 5, k + 0, DivineRPGTwilight.firelight.blockID);
		world.setBlock(i + 1, j + 5, k + 1, DivineRPGTwilight.dreambricks2.blockID);
		world.setBlock(i + 1, j + 5, k + 2, DivineRPGTwilight.dreambricks2.blockID);
		world.setBlock(i + 1, j + 5, k + 3, DivineRPGTwilight.firelight.blockID);
		world.setBlock(i + 1, j + 6, k + 1, DivineRPGTwilight.dreambricks2.blockID);
		world.setBlock(i + 1, j + 6, k + 2, DivineRPGTwilight.dreambricks2.blockID);
		world.setBlock(i + 1, j + 7, k + 1, DivineRPGTwilight.quadroticAltar.blockID);
		world.setBlock(i + 1, j + 7, k + 2, DivineRPGTwilight.quadroticAltar.blockID);
		world.setBlock(i + 2, j + 5, k + 0, DivineRPGTwilight.firelight.blockID);
		world.setBlock(i + 2, j + 5, k + 1, DivineRPGTwilight.dreambricks2.blockID);
		world.setBlock(i + 2, j + 5, k + 2, DivineRPGTwilight.dreambricks2.blockID);
		world.setBlock(i + 2, j + 5, k + 3, DivineRPGTwilight.firelight.blockID);
		world.setBlock(i + 2, j + 6, k + 1, DivineRPGTwilight.dreambricks2.blockID);
		world.setBlock(i + 2, j + 6, k + 2, DivineRPGTwilight.dreambricks2.blockID);
		world.setBlock(i + 2, j + 7, k + 1, DivineRPGTwilight.quadroticAltar.blockID);
		world.setBlock(i + 2, j + 7, k + 2, DivineRPGTwilight.quadroticAltar.blockID);
		world.setBlock(i + 3, j + 5, k + 0, DivineRPGTwilight.dreambricks2.blockID);
		world.setBlock(i + 3, j + 5, k + 1, DivineRPGTwilight.firelight.blockID);
		world.setBlock(i + 3, j + 5, k + 2, DivineRPGTwilight.firelight.blockID);
		world.setBlock(i + 3, j + 5, k + 3, DivineRPGTwilight.dreambricks2.blockID);
		world.setBlock(i + 3, j + 6, k + 0, DivineRPGTwilight.dreambricks2.blockID);
		world.setBlock(i + 3, j + 6, k + 3, DivineRPGTwilight.dreambricks2.blockID);
		world.setBlock(i + 4, j + 4, k + 1, DivineRPGTwilight.dreambricks2.blockID);
		world.setBlock(i + 4, j + 4, k + 2, DivineRPGTwilight.dreambricks2.blockID);
		world.setBlock(i + 4, j + 5, k + 0, DivineRPGTwilight.dreambricks2.blockID);
		world.setBlock(i + 4, j + 5, k + 1, DivineRPGTwilight.dreambricks2.blockID);
		world.setBlock(i + 4, j + 5, k + 2, DivineRPGTwilight.dreambricks2.blockID);
		world.setBlock(i + 4, j + 5, k + 3, DivineRPGTwilight.dreambricks2.blockID);
		world.setBlock(i + 5, j + 3, k + 1, DivineRPGTwilight.dreambricks2.blockID);
		world.setBlock(i + 5, j + 3, k + 2, DivineRPGTwilight.dreambricks2.blockID);
		world.setBlock(i + 5, j + 4, k + 0, DivineRPGTwilight.dreambricks2.blockID);
		world.setBlock(i + 5, j + 4, k + 1, DivineRPGTwilight.dreambricks2.blockID);
		world.setBlock(i + 5, j + 4, k + 2, DivineRPGTwilight.dreambricks2.blockID);
		world.setBlock(i + 5, j + 4, k + 3, DivineRPGTwilight.dreambricks2.blockID);
		world.setBlock(i + 5, j + 5, k + 0, DivineRPGTwilight.dreambricks2.blockID);
		world.setBlock(i + 5, j + 5, k + 3, DivineRPGTwilight.dreambricks2.blockID);
		world.setBlock(i + 6, j + 2, k + 1, DivineRPGTwilight.dreambricks2.blockID);
		world.setBlock(i + 6, j + 2, k + 2, DivineRPGTwilight.dreambricks2.blockID);
		world.setBlock(i + 6, j + 3, k + 0, DivineRPGTwilight.dreambricks2.blockID);
		world.setBlock(i + 6, j + 3, k + 1, DivineRPGTwilight.dreambricks2.blockID);
		world.setBlock(i + 6, j + 3, k + 2, DivineRPGTwilight.dreambricks2.blockID);
		world.setBlock(i + 6, j + 3, k + 3, DivineRPGTwilight.dreambricks2.blockID);
		world.setBlock(i + 6, j + 4, k + 0, DivineRPGTwilight.dreambricks2.blockID);
		world.setBlock(i + 6, j + 4, k + 3, DivineRPGTwilight.dreambricks2.blockID);
		world.setBlock(i + 7, j + 1, k + 1, DivineRPGTwilight.dreambricks2.blockID);
		world.setBlock(i + 7, j + 1, k + 2, DivineRPGTwilight.dreambricks2.blockID);
		world.setBlock(i + 7, j + 2, k + 0, DivineRPGTwilight.dreambricks2.blockID);
		world.setBlock(i + 7, j + 2, k + 1, DivineRPGTwilight.dreambricks2.blockID);
		world.setBlock(i + 7, j + 2, k + 2, DivineRPGTwilight.dreambricks2.blockID);
		world.setBlock(i + 7, j + 2, k + 3, DivineRPGTwilight.dreambricks2.blockID);
		world.setBlock(i + 7, j + 3, k + 0, DivineRPGTwilight.dreambricks2.blockID);
		world.setBlock(i + 7, j + 3, k + 3, DivineRPGTwilight.dreambricks2.blockID);
		world.setBlock(i + 8, j + 0, k + 1, DivineRPGTwilight.dreambricks2.blockID);
		world.setBlock(i + 8, j + 0, k + 2, DivineRPGTwilight.dreambricks2.blockID);
		world.setBlock(i + 8, j + 1, k + 0, DivineRPGTwilight.dreambricks2.blockID);
		world.setBlock(i + 8, j + 1, k + 1, DivineRPGTwilight.dreambricks2.blockID);
		world.setBlock(i + 8, j + 1, k + 2, DivineRPGTwilight.dreambricks2.blockID);
		world.setBlock(i + 8, j + 1, k + 3, DivineRPGTwilight.dreambricks2.blockID);
		world.setBlock(i + 8, j + 2, k + 0, DivineRPGTwilight.dreambricks2.blockID);
		world.setBlock(i + 8, j + 2, k + 3, DivineRPGTwilight.dreambricks2.blockID);
		world.setBlock(i + 9, j + 0, k + 0, DivineRPGTwilight.dreambricks2.blockID);
		world.setBlock(i + 9, j + 0, k + 1, DivineRPGTwilight.dreambricks2.blockID);
		world.setBlock(i + 9, j + 0, k + 2, DivineRPGTwilight.dreambricks2.blockID);
		world.setBlock(i + 9, j + 0, k + 3, DivineRPGTwilight.dreambricks2.blockID);
		world.setBlock(i + 9, j + 1, k + 0, DivineRPGTwilight.dreambricks2.blockID);
		world.setBlock(i + 9, j + 1, k + 3, DivineRPGTwilight.dreambricks2.blockID);
		world.setBlock(i + 10, j + 0, k + 0, DivineRPGTwilight.dreambricks2.blockID);
		world.setBlock(i + 10, j + 0, k + 3, DivineRPGTwilight.dreambricks2.blockID);

		return true;
	}
}