/*
*** MADE BY MITHION'S .SCHEMATIC TO JAVA CONVERTING TOOL v1.6 ***
*/

package xolova.blued00r.divinerpg.generation.vethea.village;
import java.util.Random;

import xolova.blued00r.divinerpg.DivineRPG;

import net.minecraft.world.World;
import net.minecraft.world.gen.feature.WorldGenerator;

public class HouseUp5 extends WorldGenerator
{
	protected int[] GetValidSpawnBlocks() {
		return new int[] {
		};
	}

	public HouseUp5() { }

	public boolean generate(World world, Random rand, int i, int j, int k) {

		world.setBlock(i + 0, j + 0, k + 0, DivineRPGTwilight.dreambricks2.blockID);
		world.setBlock(i + 0, j + 0, k + 1, DivineRPGTwilight.dreambricks2.blockID);
		world.setBlock(i + 0, j + 0, k + 5, DivineRPGTwilight.dreambricks2.blockID);
		world.setBlock(i + 0, j + 0, k + 15, DivineRPGTwilight.dreambricks2.blockID);
		world.setBlock(i + 0, j + 1, k + 1, DivineRPGTwilight.dreambricks2.blockID);
		world.setBlock(i + 0, j + 1, k + 2, DivineRPGTwilight.dreambricks2.blockID);
		world.setBlock(i + 0, j + 2, k + 1, DivineRPGTwilight.dreambricks2.blockID);
		world.setBlock(i + 0, j + 2, k + 2, DivineRPGTwilight.dreambricks2.blockID);
		world.setBlock(i + 0, j + 3, k + 0, DivineRPGTwilight.dreambricks2.blockID);
		world.setBlock(i + 0, j + 3, k + 5, DivineRPGTwilight.dreambricks2.blockID);
		world.setBlock(i + 0, j + 3, k + 15, DivineRPGTwilight.dreambricks2.blockID);
		world.setBlock(i + 1, j + 0, k + 1, DivineRPGTwilight.dreambricks2.blockID);
		world.setBlock(i + 1, j + 0, k + 2, DivineRPGTwilight.dreambricks2.blockID);
		world.setBlock(i + 1, j + 0, k + 5, DivineRPGTwilight.dreambricks2.blockID);
		world.setBlock(i + 1, j + 0, k + 15, DivineRPGTwilight.dreambricks2.blockID);
		world.setBlock(i + 1, j + 1, k + 2, DivineRPGTwilight.dreambricks2.blockID);
		world.setBlock(i + 1, j + 1, k + 3, DivineRPGTwilight.dreambricks2.blockID);
		world.setBlock(i + 1, j + 1, k + 6, DivineRPGTwilight.dreambricks2.blockID);
		world.setBlock(i + 1, j + 1, k + 7, DivineRPGTwilight.dreambricks2.blockID);
		world.setBlock(i + 1, j + 1, k + 8, DivineRPGTwilight.dreambricks2.blockID);
		world.setBlock(i + 1, j + 1, k + 9, DivineRPGTwilight.dreambricks2.blockID);
		world.setBlock(i + 1, j + 1, k + 10, DivineRPGTwilight.dreambricks2.blockID);
		world.setBlock(i + 1, j + 1, k + 11, DivineRPGTwilight.dreambricks2.blockID);
		world.setBlock(i + 1, j + 1, k + 12, DivineRPGTwilight.dreambricks2.blockID);
		world.setBlock(i + 1, j + 1, k + 13, DivineRPGTwilight.dreambricks2.blockID);
		world.setBlock(i + 1, j + 1, k + 14, DivineRPGTwilight.dreambricks2.blockID);
		world.setBlock(i + 1, j + 2, k + 2, DivineRPGTwilight.dreambricks2.blockID);
		world.setBlock(i + 1, j + 2, k + 3, DivineRPGTwilight.dreambricks2.blockID);
		world.setBlock(i + 1, j + 2, k + 6, DivineRPGTwilight.dreambricks2.blockID);
		world.setBlock(i + 1, j + 2, k + 7, DivineRPGTwilight.dreambricks2.blockID);
		world.setBlock(i + 1, j + 2, k + 8, DivineRPGTwilight.dreambricks2.blockID);
		world.setBlock(i + 1, j + 2, k + 9, DivineRPGTwilight.dreambricks2.blockID);
		world.setBlock(i + 1, j + 2, k + 10, DivineRPGTwilight.dreambricks2.blockID);
		world.setBlock(i + 1, j + 2, k + 11, DivineRPGTwilight.dreambricks2.blockID);
		world.setBlock(i + 1, j + 2, k + 12, DivineRPGTwilight.dreambricks2.blockID);
		world.setBlock(i + 1, j + 2, k + 13, DivineRPGTwilight.dreambricks2.blockID);
		world.setBlock(i + 1, j + 2, k + 14, DivineRPGTwilight.dreambricks2.blockID);
		world.setBlock(i + 1, j + 3, k + 0, DivineRPGTwilight.dreambricks2.blockID);
		world.setBlock(i + 1, j + 3, k + 1, DivineRPGTwilight.dreambricks2.blockID);
		world.setBlock(i + 1, j + 3, k + 5, DivineRPGTwilight.dreambricks2.blockID);
		world.setBlock(i + 1, j + 3, k + 15, DivineRPGTwilight.dreambricks2.blockID);
		world.setBlock(i + 2, j + 0, k + 2, DivineRPGTwilight.dreambricks2.blockID);
		world.setBlock(i + 2, j + 0, k + 3, DivineRPGTwilight.dreambricks2.blockID);
		world.setBlock(i + 2, j + 0, k + 5, DivineRPGTwilight.dreambricks2.blockID);
		world.setBlock(i + 2, j + 0, k + 6, DivineRPGTwilight.dreambricks2.blockID);
		world.setBlock(i + 2, j + 0, k + 7, DivineRPGTwilight.dreambricks2.blockID);
		world.setBlock(i + 2, j + 0, k + 8, DivineRPGTwilight.dreambricks2.blockID);
		world.setBlock(i + 2, j + 0, k + 9, DivineRPGTwilight.dreambricks2.blockID);
		world.setBlock(i + 2, j + 0, k + 10, DivineRPGTwilight.dreambricks2.blockID);
		world.setBlock(i + 2, j + 0, k + 11, DivineRPGTwilight.dreambricks2.blockID);
		world.setBlock(i + 2, j + 0, k + 12, DivineRPGTwilight.dreambricks2.blockID);
		world.setBlock(i + 2, j + 0, k + 13, DivineRPGTwilight.dreambricks2.blockID);
		world.setBlock(i + 2, j + 0, k + 14, DivineRPGTwilight.dreambricks2.blockID);
		world.setBlock(i + 2, j + 0, k + 15, DivineRPGTwilight.dreambricks2.blockID);
		world.setBlock(i + 2, j + 1, k + 3, DivineRPGTwilight.dreambricks2.blockID);
		world.setBlock(i + 2, j + 1, k + 4, DivineRPGTwilight.dreambricks2.blockID);
		world.setBlock(i + 2, j + 1, k + 5, DivineRPGTwilight.dreambricks2.blockID);
		world.setBlock(i + 2, j + 1, k + 6, DivineRPGTwilight.lunastone.blockID);
		world.setBlock(i + 2, j + 1, k + 7, DivineRPGTwilight.lunastone.blockID);
		world.setBlock(i + 2, j + 1, k + 8, DivineRPGTwilight.lunastone.blockID);
		world.setBlock(i + 2, j + 1, k + 9, DivineRPGTwilight.lunastone.blockID);
		world.setBlock(i + 2, j + 1, k + 10, DivineRPGTwilight.lunastone.blockID);
		world.setBlock(i + 2, j + 1, k + 11, DivineRPGTwilight.lunastone.blockID);
		world.setBlock(i + 2, j + 1, k + 12, DivineRPGTwilight.lunastone.blockID);
		world.setBlock(i + 2, j + 1, k + 13, DivineRPGTwilight.lunastone.blockID);
		world.setBlock(i + 2, j + 1, k + 14, DivineRPGTwilight.lunastone.blockID);
		world.setBlock(i + 2, j + 1, k + 15, DivineRPGTwilight.dreambricks2.blockID);
		world.setBlock(i + 2, j + 2, k + 3, DivineRPGTwilight.dreambricks2.blockID);
		world.setBlock(i + 2, j + 2, k + 4, DivineRPGTwilight.dreambricks2.blockID);
		world.setBlock(i + 2, j + 2, k + 5, DivineRPGTwilight.dreambricks2.blockID);
		world.setBlock(i + 2, j + 2, k + 6, DivineRPGTwilight.lunastone.blockID);
		world.setBlock(i + 2, j + 2, k + 7, DivineRPGTwilight.lunastone.blockID);
		world.setBlock(i + 2, j + 2, k + 8, DivineRPGTwilight.lunastone.blockID);
		world.setBlock(i + 2, j + 2, k + 9, DivineRPGTwilight.lunastone.blockID);
		world.setBlock(i + 2, j + 2, k + 10, DivineRPGTwilight.lunastone.blockID);
		world.setBlock(i + 2, j + 2, k + 11, DivineRPGTwilight.lunastone.blockID);
		world.setBlock(i + 2, j + 2, k + 12, DivineRPGTwilight.lunastone.blockID);
		world.setBlock(i + 2, j + 2, k + 13, DivineRPGTwilight.lunastone.blockID);
		world.setBlock(i + 2, j + 2, k + 14, DivineRPGTwilight.lunastone.blockID);
		world.setBlock(i + 2, j + 2, k + 15, DivineRPGTwilight.dreambricks2.blockID);
		world.setBlock(i + 2, j + 3, k + 1, DivineRPGTwilight.dreambricks2.blockID);
		world.setBlock(i + 2, j + 3, k + 2, DivineRPGTwilight.dreambricks2.blockID);
		world.setBlock(i + 2, j + 3, k + 5, DivineRPGTwilight.dreambricks2.blockID);
		world.setBlock(i + 2, j + 3, k + 6, DivineRPGTwilight.dreambricks2.blockID);
		world.setBlock(i + 2, j + 3, k + 7, DivineRPGTwilight.dreambricks2.blockID);
		world.setBlock(i + 2, j + 3, k + 8, DivineRPGTwilight.dreambricks2.blockID);
		world.setBlock(i + 2, j + 3, k + 9, DivineRPGTwilight.dreambricks2.blockID);
		world.setBlock(i + 2, j + 3, k + 10, DivineRPGTwilight.dreambricks2.blockID);
		world.setBlock(i + 2, j + 3, k + 11, DivineRPGTwilight.dreambricks2.blockID);
		world.setBlock(i + 2, j + 3, k + 12, DivineRPGTwilight.dreambricks2.blockID);
		world.setBlock(i + 2, j + 3, k + 13, DivineRPGTwilight.dreambricks2.blockID);
		world.setBlock(i + 2, j + 3, k + 14, DivineRPGTwilight.dreambricks2.blockID);
		world.setBlock(i + 2, j + 3, k + 15, DivineRPGTwilight.dreambricks2.blockID);
		world.setBlock(i + 3, j + 0, k + 3, DivineRPGTwilight.dreambricks2.blockID);
		world.setBlock(i + 3, j + 0, k + 4, DivineRPGTwilight.dreambricks2.blockID);
		world.setBlock(i + 3, j + 0, k + 5, DivineRPGTwilight.dreambricks2.blockID);
		world.setBlock(i + 3, j + 0, k + 6,  DivineRPGTwilight.smoothGlass.blockID);
		world.setBlock(i + 3, j + 0, k + 7,  DivineRPGTwilight.smoothGlass.blockID);
		world.setBlock(i + 3, j + 0, k + 8,  DivineRPGTwilight.smoothGlass.blockID);
		world.setBlock(i + 3, j + 0, k + 9,  DivineRPGTwilight.smoothGlass.blockID);
		world.setBlock(i + 3, j + 0, k + 10,  DivineRPGTwilight.smoothGlass.blockID);
		world.setBlock(i + 3, j + 0, k + 11,  DivineRPGTwilight.smoothGlass.blockID);
		world.setBlock(i + 3, j + 0, k + 12,  DivineRPGTwilight.smoothGlass.blockID);
		world.setBlock(i + 3, j + 0, k + 13,  DivineRPGTwilight.smoothGlass.blockID);
		world.setBlock(i + 3, j + 0, k + 14,  DivineRPGTwilight.smoothGlass.blockID);
		world.setBlock(i + 3, j + 0, k + 15, DivineRPGTwilight.dreambricks2.blockID);
		world.setBlock(i + 3, j + 1, k + 15, DivineRPGTwilight.dreambricks2.blockID);
		world.setBlock(i + 3, j + 2, k + 15, DivineRPGTwilight.dreambricks2.blockID);
		world.setBlock(i + 3, j + 3, k + 2, DivineRPGTwilight.dreambricks2.blockID);
		world.setBlock(i + 3, j + 3, k + 3, DivineRPGTwilight.dreambricks2.blockID);
		world.setBlock(i + 3, j + 3, k + 4, DivineRPGTwilight.dreambricks2.blockID);
		world.setBlock(i + 3, j + 3, k + 5, DivineRPGTwilight.dreambricks2.blockID);
		world.setBlock(i + 3, j + 3, k + 6,  DivineRPGTwilight.smoothGlass.blockID);
		world.setBlock(i + 3, j + 3, k + 7,  DivineRPGTwilight.smoothGlass.blockID);
		world.setBlock(i + 3, j + 3, k + 8,  DivineRPGTwilight.smoothGlass.blockID);
		world.setBlock(i + 3, j + 3, k + 9,  DivineRPGTwilight.smoothGlass.blockID);
		world.setBlock(i + 3, j + 3, k + 10,  DivineRPGTwilight.smoothGlass.blockID);
		world.setBlock(i + 3, j + 3, k + 11,  DivineRPGTwilight.smoothGlass.blockID);
		world.setBlock(i + 3, j + 3, k + 12,  DivineRPGTwilight.smoothGlass.blockID);
		world.setBlock(i + 3, j + 3, k + 13,  DivineRPGTwilight.smoothGlass.blockID);
		world.setBlock(i + 3, j + 3, k + 14,  DivineRPGTwilight.smoothGlass.blockID);
		world.setBlock(i + 3, j + 3, k + 15, DivineRPGTwilight.dreambricks2.blockID);
		world.setBlock(i + 4, j + 0, k + 5, DivineRPGTwilight.dreambricks2.blockID);
		world.setBlock(i + 4, j + 0, k + 6,  DivineRPGTwilight.smoothGlass.blockID);
		world.setBlock(i + 4, j + 0, k + 7,  DivineRPGTwilight.smoothGlass.blockID);
		world.setBlock(i + 4, j + 0, k + 8,  DivineRPGTwilight.smoothGlass.blockID);
		world.setBlock(i + 4, j + 0, k + 9,  DivineRPGTwilight.smoothGlass.blockID);
		world.setBlock(i + 4, j + 0, k + 10,  DivineRPGTwilight.smoothGlass.blockID);
		world.setBlock(i + 4, j + 0, k + 11,  DivineRPGTwilight.smoothGlass.blockID);
		world.setBlock(i + 4, j + 0, k + 12,  DivineRPGTwilight.smoothGlass.blockID);
		world.setBlock(i + 4, j + 0, k + 13,  DivineRPGTwilight.smoothGlass.blockID);
		world.setBlock(i + 4, j + 0, k + 14,  DivineRPGTwilight.smoothGlass.blockID);
		world.setBlock(i + 4, j + 0, k + 15, DivineRPGTwilight.dreambricks2.blockID);
		world.setBlock(i + 4, j + 1, k + 15,  DivineRPGTwilight.smoothGlass.blockID);
		world.setBlock(i + 4, j + 2, k + 15,  DivineRPGTwilight.smoothGlass.blockID);
		world.setBlock(i + 4, j + 3, k + 5, DivineRPGTwilight.dreambricks2.blockID);
		world.setBlock(i + 4, j + 3, k + 6,  DivineRPGTwilight.smoothGlass.blockID);
		world.setBlock(i + 4, j + 3, k + 7,  DivineRPGTwilight.smoothGlass.blockID);
		world.setBlock(i + 4, j + 3, k + 8,  DivineRPGTwilight.smoothGlass.blockID);
		world.setBlock(i + 4, j + 3, k + 9,  DivineRPGTwilight.smoothGlass.blockID);
		world.setBlock(i + 4, j + 3, k + 10,  DivineRPGTwilight.smoothGlass.blockID);
		world.setBlock(i + 4, j + 3, k + 11,  DivineRPGTwilight.smoothGlass.blockID);
		world.setBlock(i + 4, j + 3, k + 12,  DivineRPGTwilight.smoothGlass.blockID);
		world.setBlock(i + 4, j + 3, k + 13,  DivineRPGTwilight.smoothGlass.blockID);
		world.setBlock(i + 4, j + 3, k + 14,  DivineRPGTwilight.smoothGlass.blockID);
		world.setBlock(i + 4, j + 3, k + 15, DivineRPGTwilight.dreambricks2.blockID);
		world.setBlock(i + 5, j + 0, k + 5, DivineRPGTwilight.dreambricks2.blockID);
		world.setBlock(i + 5, j + 0, k + 6, DivineRPGTwilight.dreambricks2.blockID);
		world.setBlock(i + 5, j + 0, k + 7, DivineRPGTwilight.dreambricks2.blockID);
		world.setBlock(i + 5, j + 0, k + 8, DivineRPGTwilight.dreambricks2.blockID);
		world.setBlock(i + 5, j + 0, k + 9, DivineRPGTwilight.dreambricks2.blockID);
		world.setBlock(i + 5, j + 0, k + 10, DivineRPGTwilight.dreambricks2.blockID);
		world.setBlock(i + 5, j + 0, k + 11, DivineRPGTwilight.dreambricks2.blockID);
		world.setBlock(i + 5, j + 0, k + 12, DivineRPGTwilight.dreambricks2.blockID);
		world.setBlock(i + 5, j + 0, k + 13, DivineRPGTwilight.dreambricks2.blockID);
		world.setBlock(i + 5, j + 0, k + 14, DivineRPGTwilight.dreambricks2.blockID);
		world.setBlock(i + 5, j + 0, k + 15, DivineRPGTwilight.dreambricks2.blockID);
		world.setBlock(i + 5, j + 1, k + 5, DivineRPGTwilight.dreambricks2.blockID);
		world.setBlock(i + 5, j + 1, k + 15, DivineRPGTwilight.dreambricks2.blockID);
		world.setBlock(i + 5, j + 2, k + 5, DivineRPGTwilight.dreambricks2.blockID);
		world.setBlock(i + 5, j + 2, k + 6, DivineRPGTwilight.firelight.blockID);
		world.setBlock(i + 5, j + 2, k + 14, DivineRPGTwilight.firelight.blockID);
		world.setBlock(i + 5, j + 2, k + 15, DivineRPGTwilight.dreambricks2.blockID);
		world.setBlock(i + 5, j + 3, k + 5, DivineRPGTwilight.dreambricks2.blockID);
		world.setBlock(i + 5, j + 3, k + 6, DivineRPGTwilight.dreambricks2.blockID);
		world.setBlock(i + 5, j + 3, k + 7, DivineRPGTwilight.dreambricks2.blockID);
		world.setBlock(i + 5, j + 3, k + 8, DivineRPGTwilight.dreambricks2.blockID);
		world.setBlock(i + 5, j + 3, k + 9, DivineRPGTwilight.dreambricks2.blockID);
		world.setBlock(i + 5, j + 3, k + 10, DivineRPGTwilight.dreambricks2.blockID);
		world.setBlock(i + 5, j + 3, k + 11, DivineRPGTwilight.dreambricks2.blockID);
		world.setBlock(i + 5, j + 3, k + 12, DivineRPGTwilight.dreambricks2.blockID);
		world.setBlock(i + 5, j + 3, k + 13, DivineRPGTwilight.dreambricks2.blockID);
		world.setBlock(i + 5, j + 3, k + 14, DivineRPGTwilight.dreambricks2.blockID);
		world.setBlock(i + 5, j + 3, k + 15, DivineRPGTwilight.dreambricks2.blockID);
		world.setBlock(i + 6, j + 1, k + 5, DivineRPGTwilight.dreambricks2.blockID);
		world.setBlock(i + 6, j + 1, k + 6, DivineRPGTwilight.dreambricks2.blockID);
		world.setBlock(i + 6, j + 1, k + 7, DivineRPGTwilight.dreambricks2.blockID);
		world.setBlock(i + 6, j + 1, k + 8, DivineRPGTwilight.dreambricks2.blockID);
		world.setBlock(i + 6, j + 1, k + 9, DivineRPGTwilight.dreambricks2.blockID);
		world.setBlock(i + 6, j + 1, k + 10, DivineRPGTwilight.dreambricks2.blockID);
		world.setBlock(i + 6, j + 1, k + 11, DivineRPGTwilight.dreambricks2.blockID);
		world.setBlock(i + 6, j + 1, k + 12, DivineRPGTwilight.dreambricks2.blockID);
		world.setBlock(i + 6, j + 1, k + 13, DivineRPGTwilight.dreambricks2.blockID);
		world.setBlock(i + 6, j + 1, k + 14, DivineRPGTwilight.dreambricks2.blockID);
		world.setBlock(i + 6, j + 1, k + 15, DivineRPGTwilight.dreambricks2.blockID);
		world.setBlock(i + 6, j + 2, k + 5, DivineRPGTwilight.dreambricks2.blockID);
		world.setBlock(i + 6, j + 2, k + 6, DivineRPGTwilight.dreambricks2.blockID);
		world.setBlock(i + 6, j + 2, k + 7, DivineRPGTwilight.dreambricks2.blockID);
		world.setBlock(i + 6, j + 2, k + 8, DivineRPGTwilight.dreambricks2.blockID);
		world.setBlock(i + 6, j + 2, k + 9, DivineRPGTwilight.dreambricks2.blockID);
		world.setBlock(i + 6, j + 2, k + 10, DivineRPGTwilight.dreambricks2.blockID);
		world.setBlock(i + 6, j + 2, k + 11, DivineRPGTwilight.dreambricks2.blockID);
		world.setBlock(i + 6, j + 2, k + 12, DivineRPGTwilight.dreambricks2.blockID);
		world.setBlock(i + 6, j + 2, k + 13, DivineRPGTwilight.dreambricks2.blockID);
		world.setBlock(i + 6, j + 2, k + 14, DivineRPGTwilight.dreambricks2.blockID);
		world.setBlock(i + 6, j + 2, k + 15, DivineRPGTwilight.dreambricks2.blockID);

		return true;
	}
}