/*
*** MADE BY MITHION'S .SCHEMATIC TO JAVA CONVERTING TOOL v1.6 ***
*/

package xolova.blued00r.divinerpg.generation.vethea.village;
import java.util.Random;

import xolova.blued00r.divinerpg.DivineRPG;

import net.minecraft.world.World;
import net.minecraft.world.gen.feature.WorldGenerator;

public class HouseUp4 extends WorldGenerator
{
	protected int[] GetValidSpawnBlocks() {
		return new int[] {
		};
	}

	public HouseUp4() { }

	public boolean generate(World world, Random rand, int i, int j, int k) {

		world.setBlock(i + 0, j + 2, k + 0, DivineRPGTwilight.dreambricks2.blockID);
		world.setBlock(i + 0, j + 2, k + 1, DivineRPGTwilight.dreambricks2.blockID);
		world.setBlock(i + 0, j + 2, k + 2, DivineRPGTwilight.dreambricks2.blockID);
		world.setBlock(i + 0, j + 2, k + 3, DivineRPGTwilight.dreambricks2.blockID);
		world.setBlock(i + 0, j + 2, k + 4, DivineRPGTwilight.dreambricks2.blockID);
		world.setBlock(i + 0, j + 2, k + 5, DivineRPGTwilight.dreambricks2.blockID);
		world.setBlock(i + 0, j + 3, k + 0, DivineRPGTwilight.dreambricks2.blockID);
		world.setBlock(i + 0, j + 3, k + 1, DivineRPGTwilight.dreambricks.blockID);
		world.setBlock(i + 0, j + 3, k + 2, DivineRPGTwilight.dreambricks.blockID);
		world.setBlock(i + 0, j + 3, k + 3, DivineRPGTwilight.dreambricks.blockID);
		world.setBlock(i + 0, j + 3, k + 4, DivineRPGTwilight.dreambricks.blockID);
		world.setBlock(i + 0, j + 3, k + 5, DivineRPGTwilight.dreambricks2.blockID);
		world.setBlock(i + 0, j + 4, k + 0, DivineRPGTwilight.dreambricks2.blockID);
		world.setBlock(i + 0, j + 4, k + 1, DivineRPGTwilight.dreambricks.blockID);
		world.setBlock(i + 0, j + 4, k + 2, DivineRPGTwilight.smoothGlass.blockID);
		world.setBlock(i + 0, j + 4, k + 3, DivineRPGTwilight.smoothGlass.blockID);
		world.setBlock(i + 0, j + 4, k + 4, DivineRPGTwilight.dreambricks.blockID);
		world.setBlock(i + 0, j + 4, k + 5, DivineRPGTwilight.dreambricks2.blockID);
		world.setBlock(i + 0, j + 5, k + 0, DivineRPGTwilight.dreambricks2.blockID);
		world.setBlock(i + 0, j + 5, k + 1, DivineRPGTwilight.dreambricks2.blockID);
		world.setBlock(i + 0, j + 5, k + 2, DivineRPGTwilight.dreambricks2.blockID);
		world.setBlock(i + 0, j + 5, k + 3, DivineRPGTwilight.dreambricks2.blockID);
		world.setBlock(i + 0, j + 5, k + 4, DivineRPGTwilight.dreambricks2.blockID);
		world.setBlock(i + 0, j + 5, k + 5, DivineRPGTwilight.dreambricks2.blockID);
		world.setBlock(i + 1, j + 2, k + 0, DivineRPGTwilight.dreambricks2.blockID);
		world.setBlock(i + 1, j + 2, k + 1, DivineRPGTwilight.smoothGlass.blockID);
		world.setBlock(i + 1, j + 2, k + 2, DivineRPGTwilight.smoothGlass.blockID);
		world.setBlock(i + 1, j + 2, k + 3, DivineRPGTwilight.smoothGlass.blockID);
		world.setBlock(i + 1, j + 2, k + 4, DivineRPGTwilight.smoothGlass.blockID);
		world.setBlock(i + 1, j + 2, k + 5, DivineRPGTwilight.dreambricks2.blockID);
		world.setBlock(i + 1, j + 3, k + 0, DivineRPGTwilight.dreambricks.blockID);
		world.setBlock(i + 1, j + 3, k + 5, DivineRPGTwilight.dreambricks.blockID);
		world.setBlock(i + 1, j + 4, k + 0, DivineRPGTwilight.dreambricks.blockID);
		world.setBlock(i + 1, j + 4, k + 5, DivineRPGTwilight.dreambricks.blockID);
		world.setBlock(i + 1, j + 5, k + 0, DivineRPGTwilight.dreambricks2.blockID);
		world.setBlock(i + 1, j + 5, k + 1, DivineRPGTwilight.firelight.blockID);
		world.setBlock(i + 1, j + 5, k + 4, DivineRPGTwilight.firelight.blockID);
		world.setBlock(i + 1, j + 5, k + 5, DivineRPGTwilight.dreambricks2.blockID);
		world.setBlock(i + 1, j + 6, k + 0, DivineRPGTwilight.dreambricks2.blockID);
		world.setBlock(i + 1, j + 6, k + 1, DivineRPGTwilight.dreambricks2.blockID);
		world.setBlock(i + 1, j + 6, k + 2, DivineRPGTwilight.dreambricks2.blockID);
		world.setBlock(i + 1, j + 6, k + 3, DivineRPGTwilight.dreambricks2.blockID);
		world.setBlock(i + 1, j + 6, k + 4, DivineRPGTwilight.dreambricks2.blockID);
		world.setBlock(i + 1, j + 6, k + 5, DivineRPGTwilight.dreambricks2.blockID);
		world.setBlock(i + 2, j + 2, k + 0, DivineRPGTwilight.dreambricks2.blockID);
		world.setBlock(i + 2, j + 2, k + 1, DivineRPGTwilight.smoothGlass.blockID);
		world.setBlock(i + 2, j + 2, k + 2, DivineRPGTwilight.smoothGlass.blockID);
		world.setBlock(i + 2, j + 2, k + 3, DivineRPGTwilight.smoothGlass.blockID);
		world.setBlock(i + 2, j + 2, k + 4, DivineRPGTwilight.smoothGlass.blockID);
		world.setBlock(i + 2, j + 2, k + 5, DivineRPGTwilight.dreambricks2.blockID);
		world.setBlock(i + 2, j + 3, k + 0, DivineRPGTwilight.dreambricks.blockID);
		world.setBlock(i + 2, j + 3, k + 5, DivineRPGTwilight.dreambricks.blockID);
		world.setBlock(i + 2, j + 4, k + 0, DivineRPGTwilight.dreambricks.blockID);
		world.setBlock(i + 2, j + 4, k + 5, DivineRPGTwilight.dreambricks.blockID);
		world.setBlock(i + 2, j + 5, k + 0, DivineRPGTwilight.dreambricks.blockID);
		world.setBlock(i + 2, j + 5, k + 5, DivineRPGTwilight.dreambricks.blockID);
		world.setBlock(i + 2, j + 6, k + 0, DivineRPGTwilight.dreambricks2.blockID);
		world.setBlock(i + 2, j + 6, k + 5, DivineRPGTwilight.dreambricks2.blockID);
		world.setBlock(i + 2, j + 7, k + 0, DivineRPGTwilight.dreambricks2.blockID);
		world.setBlock(i + 2, j + 7, k + 1, DivineRPGTwilight.dreambricks2.blockID);
		world.setBlock(i + 2, j + 7, k + 2, DivineRPGTwilight.dreambricks2.blockID);
		world.setBlock(i + 2, j + 7, k + 3, DivineRPGTwilight.dreambricks2.blockID);
		world.setBlock(i + 2, j + 7, k + 4, DivineRPGTwilight.dreambricks2.blockID);
		world.setBlock(i + 2, j + 7, k + 5, DivineRPGTwilight.dreambricks2.blockID);
		world.setBlock(i + 3, j + 2, k + 0, DivineRPGTwilight.dreambricks2.blockID);
		world.setBlock(i + 3, j + 2, k + 1, DivineRPGTwilight.smoothGlass.blockID);
		world.setBlock(i + 3, j + 2, k + 2, DivineRPGTwilight.smoothGlass.blockID);
		world.setBlock(i + 3, j + 2, k + 3, DivineRPGTwilight.smoothGlass.blockID);
		world.setBlock(i + 3, j + 2, k + 4, DivineRPGTwilight.smoothGlass.blockID);
		world.setBlock(i + 3, j + 2, k + 5, DivineRPGTwilight.dreambricks2.blockID);
		world.setBlock(i + 3, j + 3, k + 0, DivineRPGTwilight.dreambricks.blockID);
		world.setBlock(i + 3, j + 3, k + 2, DivineRPGTwilight.dreambricks.blockID);
		world.setBlock(i + 3, j + 3, k + 3, DivineRPGTwilight.dreambricks.blockID);
		world.setBlock(i + 3, j + 3, k + 5, DivineRPGTwilight.dreambricks.blockID);
		world.setBlock(i + 3, j + 4, k + 0, DivineRPGTwilight.dreambricks.blockID);
		world.setBlock(i + 3, j + 4, k + 5, DivineRPGTwilight.dreambricks.blockID);
		world.setBlock(i + 3, j + 5, k + 0, DivineRPGTwilight.dreambricks.blockID);
		world.setBlock(i + 3, j + 5, k + 5, DivineRPGTwilight.dreambricks.blockID);
		world.setBlock(i + 3, j + 6, k + 0, DivineRPGTwilight.dreambricks.blockID);
		world.setBlock(i + 3, j + 6, k + 5, DivineRPGTwilight.dreambricks.blockID);
		world.setBlock(i + 3, j + 7, k + 0, DivineRPGTwilight.dreambricks2.blockID);
		world.setBlock(i + 3, j + 7, k + 1, DivineRPGTwilight.smoothGlass.blockID);
		world.setBlock(i + 3, j + 7, k + 2, DivineRPGTwilight.smoothGlass.blockID);
		world.setBlock(i + 3, j + 7, k + 3, DivineRPGTwilight.smoothGlass.blockID);
		world.setBlock(i + 3, j + 7, k + 4, DivineRPGTwilight.smoothGlass.blockID);
		world.setBlock(i + 3, j + 7, k + 5, DivineRPGTwilight.dreambricks2.blockID);
		world.setBlock(i + 4, j + 2, k + 0, DivineRPGTwilight.dreambricks2.blockID);
		world.setBlock(i + 4, j + 2, k + 1, DivineRPGTwilight.dreambricks2.blockID);
		world.setBlock(i + 4, j + 2, k + 2, DivineRPGTwilight.dreambricks2.blockID);
		world.setBlock(i + 4, j + 2, k + 3, DivineRPGTwilight.dreambricks2.blockID);
		world.setBlock(i + 4, j + 2, k + 4, DivineRPGTwilight.dreambricks2.blockID);
		world.setBlock(i + 4, j + 2, k + 5, DivineRPGTwilight.dreambricks2.blockID);
		world.setBlock(i + 4, j + 3, k + 0, DivineRPGTwilight.dreambricks2.blockID);
		world.setBlock(i + 4, j + 3, k + 1, DivineRPGTwilight.dreambricks2.blockID);
		world.setBlock(i + 4, j + 3, k + 2, DivineRPGTwilight.dreambricks2.blockID);
		world.setBlock(i + 4, j + 3, k + 3, DivineRPGTwilight.dreambricks2.blockID);
		world.setBlock(i + 4, j + 3, k + 4, DivineRPGTwilight.dreambricks2.blockID);
		world.setBlock(i + 4, j + 3, k + 5, DivineRPGTwilight.dreambricks2.blockID);
		world.setBlock(i + 4, j + 4, k + 0, DivineRPGTwilight.dreambricks2.blockID);
		world.setBlock(i + 4, j + 4, k + 1, DivineRPGTwilight.dreambricks2.blockID);
		world.setBlock(i + 4, j + 4, k + 2, DivineRPGTwilight.dreambricks2.blockID);
		world.setBlock(i + 4, j + 4, k + 3, DivineRPGTwilight.dreambricks2.blockID);
		world.setBlock(i + 4, j + 4, k + 4, DivineRPGTwilight.dreambricks2.blockID);
		world.setBlock(i + 4, j + 4, k + 5, DivineRPGTwilight.dreambricks2.blockID);
		world.setBlock(i + 4, j + 5, k + 0, DivineRPGTwilight.dreambricks.blockID);
		world.setBlock(i + 4, j + 5, k + 5, DivineRPGTwilight.dreambricks.blockID);
		world.setBlock(i + 4, j + 6, k + 0, DivineRPGTwilight.dreambricks.blockID);
		world.setBlock(i + 4, j + 6, k + 5, DivineRPGTwilight.dreambricks.blockID);
		world.setBlock(i + 4, j + 7, k + 0, DivineRPGTwilight.dreambricks2.blockID);
		world.setBlock(i + 4, j + 7, k + 1, DivineRPGTwilight.smoothGlass.blockID);
		world.setBlock(i + 4, j + 7, k + 2, DivineRPGTwilight.smoothGlass.blockID);
		world.setBlock(i + 4, j + 7, k + 3, DivineRPGTwilight.smoothGlass.blockID);
		world.setBlock(i + 4, j + 7, k + 4, DivineRPGTwilight.smoothGlass.blockID);
		world.setBlock(i + 4, j + 7, k + 5, DivineRPGTwilight.dreambricks2.blockID);
		world.setBlock(i + 5, j + 3, k + 1, DivineRPGTwilight.dreambricks2.blockID);
		world.setBlock(i + 5, j + 3, k + 2, DivineRPGTwilight.dreambricks2.blockID);
		world.setBlock(i + 5, j + 3, k + 3, DivineRPGTwilight.dreambricks2.blockID);
		world.setBlock(i + 5, j + 3, k + 4, DivineRPGTwilight.dreambricks2.blockID);
		world.setBlock(i + 5, j + 4, k + 0, DivineRPGTwilight.dreambricks2.blockID);
		world.setBlock(i + 5, j + 4, k + 1, DivineRPGTwilight.lunastone.blockID);
		world.setBlock(i + 5, j + 4, k + 2, DivineRPGTwilight.lunastone.blockID);
		world.setBlock(i + 5, j + 4, k + 3, DivineRPGTwilight.lunastone.blockID);
		world.setBlock(i + 5, j + 4, k + 4, DivineRPGTwilight.lunastone.blockID);
		world.setBlock(i + 5, j + 4, k + 5, DivineRPGTwilight.dreambricks2.blockID);
		world.setBlock(i + 5, j + 5, k + 0, DivineRPGTwilight.dreambricks.blockID);
		world.setBlock(i + 5, j + 5, k + 5, DivineRPGTwilight.dreambricks.blockID);
		world.setBlock(i + 5, j + 6, k + 0, DivineRPGTwilight.smoothGlass.blockID);
		world.setBlock(i + 5, j + 6, k + 5, DivineRPGTwilight.smoothGlass.blockID);
		world.setBlock(i + 5, j + 7, k + 0, DivineRPGTwilight.dreambricks2.blockID);
		world.setBlock(i + 5, j + 7, k + 1, DivineRPGTwilight.smoothGlass.blockID);
		world.setBlock(i + 5, j + 7, k + 2, DivineRPGTwilight.smoothGlass.blockID);
		world.setBlock(i + 5, j + 7, k + 3, DivineRPGTwilight.smoothGlass.blockID);
		world.setBlock(i + 5, j + 7, k + 4, DivineRPGTwilight.smoothGlass.blockID);
		world.setBlock(i + 5, j + 7, k + 5, DivineRPGTwilight.dreambricks2.blockID);
		world.setBlock(i + 6, j + 3, k + 1, DivineRPGTwilight.dreambricks2.blockID);
		world.setBlock(i + 6, j + 3, k + 2, DivineRPGTwilight.dreambricks2.blockID);
		world.setBlock(i + 6, j + 3, k + 3, DivineRPGTwilight.dreambricks2.blockID);
		world.setBlock(i + 6, j + 3, k + 4, DivineRPGTwilight.dreambricks2.blockID);
		world.setBlock(i + 6, j + 4, k + 0, DivineRPGTwilight.dreambricks2.blockID);
		world.setBlock(i + 6, j + 4, k + 1, DivineRPGTwilight.lunastone.blockID);
		world.setBlock(i + 6, j + 4, k + 2, DivineRPGTwilight.lunastone.blockID);
		world.setBlock(i + 6, j + 4, k + 3, DivineRPGTwilight.lunastone.blockID);
		world.setBlock(i + 6, j + 4, k + 4, DivineRPGTwilight.lunastone.blockID);
		world.setBlock(i + 6, j + 4, k + 5, DivineRPGTwilight.dreambricks2.blockID);
		world.setBlock(i + 6, j + 5, k + 0, DivineRPGTwilight.dreambricks.blockID);
		world.setBlock(i + 6, j + 5, k + 5, DivineRPGTwilight.dreambricks.blockID);
		world.setBlock(i + 6, j + 6, k + 0, DivineRPGTwilight.smoothGlass.blockID);
		world.setBlock(i + 6, j + 6, k + 5, DivineRPGTwilight.smoothGlass.blockID);
		world.setBlock(i + 6, j + 7, k + 0, DivineRPGTwilight.dreambricks2.blockID);
		world.setBlock(i + 6, j + 7, k + 1, DivineRPGTwilight.smoothGlass.blockID);
		world.setBlock(i + 6, j + 7, k + 2, DivineRPGTwilight.smoothGlass.blockID);
		world.setBlock(i + 6, j + 7, k + 3, DivineRPGTwilight.smoothGlass.blockID);
		world.setBlock(i + 6, j + 7, k + 4, DivineRPGTwilight.smoothGlass.blockID);
		world.setBlock(i + 6, j + 7, k + 5, DivineRPGTwilight.dreambricks2.blockID);
		world.setBlock(i + 7, j + 3, k + 1, DivineRPGTwilight.dreambricks2.blockID);
		world.setBlock(i + 7, j + 3, k + 2, DivineRPGTwilight.dreambricks2.blockID);
		world.setBlock(i + 7, j + 3, k + 3, DivineRPGTwilight.dreambricks2.blockID);
		world.setBlock(i + 7, j + 3, k + 4, DivineRPGTwilight.dreambricks2.blockID);
		world.setBlock(i + 7, j + 4, k + 0, DivineRPGTwilight.dreambricks2.blockID);
		world.setBlock(i + 7, j + 4, k + 1, DivineRPGTwilight.lunastone.blockID);
		world.setBlock(i + 7, j + 4, k + 2, DivineRPGTwilight.lunastone.blockID);
		world.setBlock(i + 7, j + 4, k + 3, DivineRPGTwilight.lunastone.blockID);
		world.setBlock(i + 7, j + 4, k + 4, DivineRPGTwilight.lunastone.blockID);
		world.setBlock(i + 7, j + 4, k + 5, DivineRPGTwilight.dreambricks2.blockID);
		world.setBlock(i + 7, j + 5, k + 0, DivineRPGTwilight.dreambricks.blockID);
		world.setBlock(i + 7, j + 5, k + 5, DivineRPGTwilight.dreambricks.blockID);
		world.setBlock(i + 7, j + 6, k + 0, DivineRPGTwilight.smoothGlass.blockID);
		world.setBlock(i + 7, j + 6, k + 5, DivineRPGTwilight.smoothGlass.blockID);
		world.setBlock(i + 7, j + 7, k + 0, DivineRPGTwilight.dreambricks2.blockID);
		world.setBlock(i + 7, j + 7, k + 1, DivineRPGTwilight.smoothGlass.blockID);
		world.setBlock(i + 7, j + 7, k + 2, DivineRPGTwilight.smoothGlass.blockID);
		world.setBlock(i + 7, j + 7, k + 3, DivineRPGTwilight.smoothGlass.blockID);
		world.setBlock(i + 7, j + 7, k + 4, DivineRPGTwilight.smoothGlass.blockID);
		world.setBlock(i + 7, j + 7, k + 5, DivineRPGTwilight.dreambricks2.blockID);
		world.setBlock(i + 8, j + 0, k + 0, DivineRPGTwilight.dreambricks2.blockID);
		world.setBlock(i + 8, j + 0, k + 1, DivineRPGTwilight.dreambricks2.blockID);
		world.setBlock(i + 8, j + 0, k + 2, DivineRPGTwilight.dreambricks2.blockID);
		world.setBlock(i + 8, j + 0, k + 3, DivineRPGTwilight.dreambricks2.blockID);
		world.setBlock(i + 8, j + 0, k + 4, DivineRPGTwilight.dreambricks2.blockID);
		world.setBlock(i + 8, j + 0, k + 5, DivineRPGTwilight.dreambricks2.blockID);
		world.setBlock(i + 8, j + 1, k + 0, DivineRPGTwilight.dreambricks2.blockID);
		world.setBlock(i + 8, j + 1, k + 1, DivineRPGTwilight.dreambricks2.blockID);
		world.setBlock(i + 8, j + 1, k + 2, DivineRPGTwilight.dreambricks2.blockID);
		world.setBlock(i + 8, j + 1, k + 3, DivineRPGTwilight.dreambricks2.blockID);
		world.setBlock(i + 8, j + 1, k + 4, DivineRPGTwilight.dreambricks2.blockID);
		world.setBlock(i + 8, j + 1, k + 5, DivineRPGTwilight.dreambricks2.blockID);
		world.setBlock(i + 8, j + 2, k + 0, DivineRPGTwilight.dreambricks2.blockID);
		world.setBlock(i + 8, j + 2, k + 1, DivineRPGTwilight.dreambricks.blockID);
		world.setBlock(i + 8, j + 2, k + 2, DivineRPGTwilight.dreambricks.blockID);
		world.setBlock(i + 8, j + 2, k + 3, DivineRPGTwilight.dreambricks.blockID);
		world.setBlock(i + 8, j + 2, k + 4, DivineRPGTwilight.dreambricks.blockID);
		world.setBlock(i + 8, j + 2, k + 5, DivineRPGTwilight.dreambricks2.blockID);
		world.setBlock(i + 8, j + 3, k + 0, DivineRPGTwilight.dreambricks2.blockID);
		world.setBlock(i + 8, j + 3, k + 1, DivineRPGTwilight.dreambricks.blockID);
		world.setBlock(i + 8, j + 3, k + 2, DivineRPGTwilight.dreambricks.blockID);
		world.setBlock(i + 8, j + 3, k + 3, DivineRPGTwilight.dreambricks.blockID);
		world.setBlock(i + 8, j + 3, k + 4, DivineRPGTwilight.dreambricks.blockID);
		world.setBlock(i + 8, j + 3, k + 5, DivineRPGTwilight.dreambricks2.blockID);
		world.setBlock(i + 8, j + 4, k + 0, DivineRPGTwilight.dreambricks2.blockID);
		world.setBlock(i + 8, j + 4, k + 1, DivineRPGTwilight.dreambricks2.blockID);
		world.setBlock(i + 8, j + 4, k + 2, DivineRPGTwilight.dreambricks2.blockID);
		world.setBlock(i + 8, j + 4, k + 3, DivineRPGTwilight.dreambricks2.blockID);
		world.setBlock(i + 8, j + 4, k + 4, DivineRPGTwilight.dreambricks2.blockID);
		world.setBlock(i + 8, j + 4, k + 5, DivineRPGTwilight.dreambricks2.blockID);
		world.setBlock(i + 8, j + 5, k + 0, DivineRPGTwilight.dreambricks.blockID);
		world.setBlock(i + 8, j + 5, k + 5, DivineRPGTwilight.dreambricks.blockID);
		world.setBlock(i + 8, j + 6, k + 0, DivineRPGTwilight.dreambricks.blockID);
		world.setBlock(i + 8, j + 6, k + 5, DivineRPGTwilight.dreambricks.blockID);
		world.setBlock(i + 8, j + 7, k + 0, DivineRPGTwilight.dreambricks2.blockID);
		world.setBlock(i + 8, j + 7, k + 1, DivineRPGTwilight.smoothGlass.blockID);
		world.setBlock(i + 8, j + 7, k + 2, DivineRPGTwilight.smoothGlass.blockID);
		world.setBlock(i + 8, j + 7, k + 3, DivineRPGTwilight.smoothGlass.blockID);
		world.setBlock(i + 8, j + 7, k + 4, DivineRPGTwilight.smoothGlass.blockID);
		world.setBlock(i + 8, j + 7, k + 5, DivineRPGTwilight.dreambricks2.blockID);
		world.setBlock(i + 9, j + 0, k + 0, DivineRPGTwilight.dreambricks2.blockID);
		world.setBlock(i + 9, j + 0, k + 1, DivineRPGTwilight.lunastone.blockID);
		world.setBlock(i + 9, j + 0, k + 2, DivineRPGTwilight.lunastone.blockID);
		world.setBlock(i + 9, j + 0, k + 3, DivineRPGTwilight.lunastone.blockID);
		world.setBlock(i + 9, j + 0, k + 4, DivineRPGTwilight.lunastone.blockID);
		world.setBlock(i + 9, j + 0, k + 5, DivineRPGTwilight.dreambricks2.blockID);
		world.setBlock(i + 9, j + 1, k + 0, DivineRPGTwilight.dreambricks.blockID);
		world.setBlock(i + 9, j + 1, k + 3, DivineRPGTwilight.dreambricks.blockID);
		world.setBlock(i + 9, j + 1, k + 4, DivineRPGTwilight.dreambricks.blockID);
		world.setBlock(i + 9, j + 1, k + 5, DivineRPGTwilight.dreambricks.blockID);
		world.setBlock(i + 9, j + 2, k + 0, DivineRPGTwilight.smoothGlass.blockID);
		world.setBlock(i + 9, j + 2, k + 3, DivineRPGTwilight.dreambricks.blockID);
		world.setBlock(i + 9, j + 2, k + 4, DivineRPGTwilight.dreambricks.blockID);
		world.setBlock(i + 9, j + 2, k + 5, DivineRPGTwilight.dreambricks.blockID);
		world.setBlock(i + 9, j + 3, k + 0, DivineRPGTwilight.dreambricks.blockID);
		world.setBlock(i + 9, j + 3, k + 3, DivineRPGTwilight.dreambricks.blockID);
		world.setBlock(i + 9, j + 3, k + 4, DivineRPGTwilight.dreambricks.blockID);
		world.setBlock(i + 9, j + 3, k + 5, DivineRPGTwilight.dreambricks.blockID);
		world.setBlock(i + 9, j + 4, k + 0, DivineRPGTwilight.dreambricks2.blockID);
		world.setBlock(i + 9, j + 4, k + 5, DivineRPGTwilight.dreambricks2.blockID);
		world.setBlock(i + 9, j + 5, k + 0, DivineRPGTwilight.dreambricks.blockID);
		world.setBlock(i + 9, j + 5, k + 5, DivineRPGTwilight.dreambricks.blockID);
		world.setBlock(i + 9, j + 6, k + 0, DivineRPGTwilight.dreambricks.blockID);
		world.setBlock(i + 9, j + 6, k + 5, DivineRPGTwilight.dreambricks.blockID);
		world.setBlock(i + 9, j + 7, k + 0, DivineRPGTwilight.dreambricks2.blockID);
		world.setBlock(i + 9, j + 7, k + 1, DivineRPGTwilight.smoothGlass.blockID);
		world.setBlock(i + 9, j + 7, k + 2, DivineRPGTwilight.smoothGlass.blockID);
		world.setBlock(i + 9, j + 7, k + 3, DivineRPGTwilight.smoothGlass.blockID);
		world.setBlock(i + 9, j + 7, k + 4, DivineRPGTwilight.smoothGlass.blockID);
		world.setBlock(i + 9, j + 7, k + 5, DivineRPGTwilight.dreambricks2.blockID);
		world.setBlock(i + 10, j + 0, k + 0, DivineRPGTwilight.dreambricks2.blockID);
		world.setBlock(i + 10, j + 0, k + 1, DivineRPGTwilight.lunastone.blockID);
		world.setBlock(i + 10, j + 0, k + 2, DivineRPGTwilight.lunastone.blockID);
		world.setBlock(i + 10, j + 0, k + 3, DivineRPGTwilight.lunastone.blockID);
		world.setBlock(i + 10, j + 0, k + 4, DivineRPGTwilight.lunastone.blockID);
		world.setBlock(i + 10, j + 0, k + 5, DivineRPGTwilight.dreambricks2.blockID);
		world.setBlock(i + 10, j + 1, k + 0, DivineRPGTwilight.dreambricks.blockID);
		world.setBlock(i + 10, j + 1, k + 3, DivineRPGTwilight.dreambricks.blockID);
		world.setBlock(i + 10, j + 1, k + 4, DivineRPGTwilight.dreambricks.blockID);
		world.setBlock(i + 10, j + 1, k + 5, DivineRPGTwilight.dreambricks.blockID);
		world.setBlock(i + 10, j + 2, k + 0, DivineRPGTwilight.dreambricks.blockID);
		world.setBlock(i + 10, j + 2, k + 3, DivineRPGTwilight.dreambricks.blockID);
		world.setBlock(i + 10, j + 2, k + 4, DivineRPGTwilight.dreambricks.blockID);
		world.setBlock(i + 10, j + 2, k + 5, DivineRPGTwilight.dreambricks.blockID);
		world.setBlock(i + 10, j + 3, k + 0, DivineRPGTwilight.dreambricks.blockID);
		world.setBlock(i + 10, j + 3, k + 5, DivineRPGTwilight.dreambricks.blockID);
		world.setBlock(i + 10, j + 4, k + 0, DivineRPGTwilight.dreambricks2.blockID);
		world.setBlock(i + 10, j + 4, k + 5, DivineRPGTwilight.dreambricks2.blockID);
		world.setBlock(i + 10, j + 5, k + 0, DivineRPGTwilight.dreambricks.blockID);
		world.setBlock(i + 10, j + 5, k + 5, DivineRPGTwilight.dreambricks.blockID);
		world.setBlock(i + 10, j + 6, k + 0, DivineRPGTwilight.dreambricks2.blockID);
		world.setBlock(i + 10, j + 6, k + 1, DivineRPGTwilight.firelight.blockID);
		world.setBlock(i + 10, j + 6, k + 5, DivineRPGTwilight.dreambricks2.blockID);
		world.setBlock(i + 10, j + 7, k + 0, DivineRPGTwilight.dreambricks2.blockID);
		world.setBlock(i + 10, j + 7, k + 1, DivineRPGTwilight.dreambricks2.blockID);
		world.setBlock(i + 10, j + 7, k + 2, DivineRPGTwilight.dreambricks2.blockID);
		world.setBlock(i + 10, j + 7, k + 3, DivineRPGTwilight.dreambricks2.blockID);
		world.setBlock(i + 10, j + 7, k + 4, DivineRPGTwilight.dreambricks2.blockID);
		world.setBlock(i + 10, j + 7, k + 5, DivineRPGTwilight.dreambricks2.blockID);
		world.setBlock(i + 11, j + 0, k + 0, DivineRPGTwilight.dreambricks2.blockID);
		world.setBlock(i + 11, j + 0, k + 1, DivineRPGTwilight.lunastone.blockID);
		world.setBlock(i + 11, j + 0, k + 2, DivineRPGTwilight.lunastone.blockID);
		world.setBlock(i + 11, j + 0, k + 3, DivineRPGTwilight.lunastone.blockID);
		world.setBlock(i + 11, j + 0, k + 4, DivineRPGTwilight.lunastone.blockID);
		world.setBlock(i + 11, j + 0, k + 5, DivineRPGTwilight.dreambricks2.blockID);
		world.setBlock(i + 11, j + 1, k + 3, DivineRPGTwilight.dreambricks.blockID);
		world.setBlock(i + 11, j + 1, k + 4, DivineRPGTwilight.dreambricks.blockID);
		world.setBlock(i + 11, j + 1, k + 5, DivineRPGTwilight.dreambricks.blockID);
		world.setBlock(i + 11, j + 2, k + 5, DivineRPGTwilight.dreambricks.blockID);
		world.setBlock(i + 11, j + 3, k + 0, DivineRPGTwilight.dreambricks.blockID);
		world.setBlock(i + 11, j + 3, k + 5, DivineRPGTwilight.dreambricks.blockID);
		world.setBlock(i + 11, j + 4, k + 0, DivineRPGTwilight.dreambricks2.blockID);
		world.setBlock(i + 11, j + 4, k + 5, DivineRPGTwilight.dreambricks2.blockID);
		world.setBlock(i + 11, j + 5, k + 0, DivineRPGTwilight.dreambricks2.blockID);
		world.setBlock(i + 11, j + 5, k + 5, DivineRPGTwilight.dreambricks2.blockID);
		world.setBlock(i + 11, j + 6, k + 0, DivineRPGTwilight.dreambricks2.blockID);
		world.setBlock(i + 11, j + 6, k + 1, DivineRPGTwilight.dreambricks2.blockID);
		world.setBlock(i + 11, j + 6, k + 2, DivineRPGTwilight.dreambricks2.blockID);
		world.setBlock(i + 11, j + 6, k + 3, DivineRPGTwilight.dreambricks2.blockID);
		world.setBlock(i + 11, j + 6, k + 4, DivineRPGTwilight.dreambricks2.blockID);
		world.setBlock(i + 11, j + 6, k + 5, DivineRPGTwilight.dreambricks2.blockID);
		world.setBlock(i + 12, j + 0, k + 0, DivineRPGTwilight.dreambricks2.blockID);
		world.setBlock(i + 12, j + 0, k + 1, DivineRPGTwilight.lunastone.blockID);
		world.setBlock(i + 12, j + 0, k + 2, DivineRPGTwilight.lunastone.blockID);
		world.setBlock(i + 12, j + 0, k + 3, DivineRPGTwilight.lunastone.blockID);
		world.setBlock(i + 12, j + 0, k + 4, DivineRPGTwilight.lunastone.blockID);
		world.setBlock(i + 12, j + 0, k + 5, DivineRPGTwilight.dreambricks2.blockID);
		world.setBlock(i + 12, j + 1, k + 0, DivineRPGTwilight.dreambricks.blockID);
		world.setBlock(i + 12, j + 1, k + 5, DivineRPGTwilight.dreambricks.blockID);
		world.setBlock(i + 12, j + 2, k + 0, DivineRPGTwilight.dreambricks.blockID);
		world.setBlock(i + 12, j + 2, k + 5, DivineRPGTwilight.dreambricks.blockID);
		world.setBlock(i + 12, j + 3, k + 0, DivineRPGTwilight.dreambricks.blockID);
		world.setBlock(i + 12, j + 3, k + 5, DivineRPGTwilight.dreambricks.blockID);
		world.setBlock(i + 12, j + 4, k + 0, DivineRPGTwilight.dreambricks2.blockID);
		world.setBlock(i + 12, j + 4, k + 5, DivineRPGTwilight.dreambricks2.blockID);
		world.setBlock(i + 12, j + 5, k + 0, DivineRPGTwilight.dreambricks2.blockID);
		world.setBlock(i + 12, j + 5, k + 1, DivineRPGTwilight.dreambricks2.blockID);
		world.setBlock(i + 12, j + 5, k + 2, DivineRPGTwilight.dreambricks2.blockID);
		world.setBlock(i + 12, j + 5, k + 3, DivineRPGTwilight.dreambricks2.blockID);
		world.setBlock(i + 12, j + 5, k + 4, DivineRPGTwilight.dreambricks2.blockID);
		world.setBlock(i + 12, j + 5, k + 5, DivineRPGTwilight.dreambricks2.blockID);
		world.setBlock(i + 13, j + 0, k + 0, DivineRPGTwilight.dreambricks2.blockID);
		world.setBlock(i + 13, j + 0, k + 1, DivineRPGTwilight.dreambricks2.blockID);
		world.setBlock(i + 13, j + 0, k + 2, DivineRPGTwilight.dreambricks2.blockID);
		world.setBlock(i + 13, j + 0, k + 3, DivineRPGTwilight.dreambricks2.blockID);
		world.setBlock(i + 13, j + 0, k + 4, DivineRPGTwilight.dreambricks2.blockID);
		world.setBlock(i + 13, j + 0, k + 5, DivineRPGTwilight.dreambricks2.blockID);
		world.setBlock(i + 13, j + 1, k + 0, DivineRPGTwilight.dreambricks2.blockID);
		world.setBlock(i + 13, j + 1, k + 1, DivineRPGTwilight.dreambricks.blockID);
		world.setBlock(i + 13, j + 1, k + 2, DivineRPGTwilight.dreambricks.blockID);
		world.setBlock(i + 13, j + 1, k + 3, DivineRPGTwilight.dreambricks.blockID);
		world.setBlock(i + 13, j + 1, k + 4, DivineRPGTwilight.dreambricks.blockID);
		world.setBlock(i + 13, j + 1, k + 5, DivineRPGTwilight.dreambricks2.blockID);
		world.setBlock(i + 13, j + 2, k + 0, DivineRPGTwilight.dreambricks2.blockID);
		world.setBlock(i + 13, j + 2, k + 1, DivineRPGTwilight.dreambricks.blockID);
		world.setBlock(i + 13, j + 2, k + 2, DivineRPGTwilight.smoothGlass.blockID);
		world.setBlock(i + 13, j + 2, k + 3, DivineRPGTwilight.smoothGlass.blockID);
		world.setBlock(i + 13, j + 2, k + 4, DivineRPGTwilight.dreambricks.blockID);
		world.setBlock(i + 13, j + 2, k + 5, DivineRPGTwilight.dreambricks2.blockID);
		world.setBlock(i + 13, j + 3, k + 0, DivineRPGTwilight.dreambricks2.blockID);
		world.setBlock(i + 13, j + 3, k + 1, DivineRPGTwilight.dreambricks.blockID);
		world.setBlock(i + 13, j + 3, k + 2, DivineRPGTwilight.dreambricks.blockID);
		world.setBlock(i + 13, j + 3, k + 3, DivineRPGTwilight.dreambricks.blockID);
		world.setBlock(i + 13, j + 3, k + 4, DivineRPGTwilight.dreambricks.blockID);
		world.setBlock(i + 13, j + 3, k + 5, DivineRPGTwilight.dreambricks2.blockID);
		world.setBlock(i + 13, j + 4, k + 0, DivineRPGTwilight.dreambricks2.blockID);
		world.setBlock(i + 13, j + 4, k + 1, DivineRPGTwilight.dreambricks2.blockID);
		world.setBlock(i + 13, j + 4, k + 2, DivineRPGTwilight.dreambricks2.blockID);
		world.setBlock(i + 13, j + 4, k + 3, DivineRPGTwilight.dreambricks2.blockID);
		world.setBlock(i + 13, j + 4, k + 4, DivineRPGTwilight.dreambricks2.blockID);
		world.setBlock(i + 13, j + 4, k + 5, DivineRPGTwilight.dreambricks2.blockID);

		return true;
	}
}