/*
 *** MADE BY MITHION'S .SCHEMATIC TO JAVA CONVERTING TOOL v1.6 ***
 */

package net.divinerpg.worldgen.iceika;
import java.util.Random;

import net.divinerpg.blocks.overworld.tileentities.TileEntitySkeletonChest;
import net.divinerpg.utils.helpers.block.IceikaBlockHelper;
import net.divinerpg.utils.helpers.item.IceikaItemHelper;
import net.minecraft.block.Block;
import net.minecraft.item.ItemStack;
import net.minecraft.world.World;
import net.minecraft.world.gen.feature.WorldGenerator;

public class WorldGenIceikaDungeon extends WorldGenerator
{

	protected int[] GetValidSpawnBlocks() {
		return new int[] {
				IceikaBlockHelper.icyStone.blockID
		};
	}

	public boolean LocationIsValidSpawn(World world, int i, int j, int k){
		int distanceToAir = 0;
		int checkID = world.getBlockId(i, j, k);

		while (checkID != 0){
			distanceToAir++;
			checkID = world.getBlockId(i, j + distanceToAir, k);
		}

		if (distanceToAir > 3){
			return false;
		}
		j += distanceToAir - 1;

		int blockID = world.getBlockId(i, j, k);
		int blockIDAbove = world.getBlockId(i, j+1, k);
		int blockIDBelow = world.getBlockId(i, j-1, k);
		for (int x : GetValidSpawnBlocks()){
			if (blockIDAbove != 0){
				return false;
			}
			if (blockID == x){
				return true;
			}else if (blockID == Block.snow.blockID && blockIDBelow == x){
				return true;
			}
		}
		return false;
	}

	public WorldGenIceikaDungeon() { }

	public boolean generate(World world, Random rand, int i, int j, int k) {
		//check that each corner is one of the valid spawn blocks

		world.setBlock(i + 0, j + 0, k + 11, IceikaBlockHelper.snowyBricks.blockID);
		world.setBlock(i + 0, j + 0, k + 12, IceikaBlockHelper.snowyBricks.blockID);
		world.setBlock(i + 0, j + 0, k + 13, IceikaBlockHelper.snowyBricks.blockID);
		world.setBlock(i + 0, j + 0, k + 14, IceikaBlockHelper.snowyBricks.blockID);
		world.setBlock(i + 0, j + 0, k + 15, IceikaBlockHelper.snowyBricks.blockID);
		world.setBlock(i + 0, j + 0, k + 16, IceikaBlockHelper.snowyBricks.blockID);
		world.setBlock(i + 0, j + 0, k + 17, IceikaBlockHelper.snowyBricks.blockID);
		world.setBlock(i + 0, j + 0, k + 18, IceikaBlockHelper.snowyBricks.blockID);
		world.setBlock(i + 0, j + 0, k + 19, IceikaBlockHelper.snowyBricks.blockID);
		world.setBlock(i + 0, j + 0, k + 20, IceikaBlockHelper.snowyBricks.blockID);
		world.setBlock(i + 0, j + 0, k + 21, IceikaBlockHelper.snowyBricks.blockID);
		world.setBlock(i + 0, j + 0, k + 22, IceikaBlockHelper.snowyBricks.blockID);
		world.setBlock(i + 0, j + 1, k + 11, IceikaBlockHelper.snowyBricks.blockID);
		world.setBlock(i + 0, j + 1, k + 12, IceikaBlockHelper.snowyBricks.blockID);
		world.setBlock(i + 0, j + 1, k + 13, IceikaBlockHelper.snowyBricks.blockID);
		world.setBlock(i + 0, j + 1, k + 14, IceikaBlockHelper.snowyBricks.blockID);
		world.setBlock(i + 0, j + 1, k + 15, IceikaBlockHelper.snowyBricks.blockID);
		world.setBlock(i + 0, j + 1, k + 16, IceikaBlockHelper.snowyBricks.blockID);
		world.setBlock(i + 0, j + 1, k + 17, IceikaBlockHelper.snowyBricks.blockID);
		world.setBlock(i + 0, j + 1, k + 18, IceikaBlockHelper.snowyBricks.blockID);
		world.setBlock(i + 0, j + 1, k + 19, IceikaBlockHelper.snowyBricks.blockID);
		world.setBlock(i + 0, j + 1, k + 20, IceikaBlockHelper.snowyBricks.blockID);
		world.setBlock(i + 0, j + 1, k + 21, IceikaBlockHelper.snowyBricks.blockID);
		world.setBlock(i + 0, j + 1, k + 22, IceikaBlockHelper.snowyBricks.blockID);
		world.setBlock(i + 0, j + 2, k + 11, IceikaBlockHelper.snowyBricks.blockID);
		world.setBlock(i + 0, j + 2, k + 12, IceikaBlockHelper.snowyBricks.blockID);
		world.setBlock(i + 0, j + 2, k + 13, IceikaBlockHelper.snowyBricks.blockID);
		world.setBlock(i + 0, j + 2, k + 14, IceikaBlockHelper.snowyBricks.blockID);
		world.setBlock(i + 0, j + 2, k + 15, IceikaBlockHelper.snowyBricks.blockID);
		world.setBlock(i + 0, j + 2, k + 16, IceikaBlockHelper.snowyBricks.blockID);
		world.setBlock(i + 0, j + 2, k + 17, IceikaBlockHelper.snowyBricks.blockID);
		world.setBlock(i + 0, j + 2, k + 18, IceikaBlockHelper.snowyBricks.blockID);
		world.setBlock(i + 0, j + 2, k + 19, IceikaBlockHelper.snowyBricks.blockID);
		world.setBlock(i + 0, j + 2, k + 20, IceikaBlockHelper.snowyBricks.blockID);
		world.setBlock(i + 0, j + 2, k + 21, IceikaBlockHelper.snowyBricks.blockID);
		world.setBlock(i + 0, j + 2, k + 22, IceikaBlockHelper.snowyBricks.blockID);
		world.setBlock(i + 0, j + 3, k + 11, IceikaBlockHelper.snowyBricks.blockID);
		world.setBlock(i + 0, j + 3, k + 12, IceikaBlockHelper.snowyBricks.blockID);
		world.setBlock(i + 0, j + 3, k + 13, IceikaBlockHelper.snowyBricks.blockID);
		world.setBlock(i + 0, j + 3, k + 14, IceikaBlockHelper.snowyBricks.blockID);
		world.setBlock(i + 0, j + 3, k + 15, IceikaBlockHelper.snowyBricks.blockID);
		world.setBlock(i + 0, j + 3, k + 16, IceikaBlockHelper.snowyBricks.blockID);
		world.setBlock(i + 0, j + 3, k + 17, IceikaBlockHelper.snowyBricks.blockID);
		world.setBlock(i + 0, j + 3, k + 18, IceikaBlockHelper.snowyBricks.blockID);
		world.setBlock(i + 0, j + 3, k + 19, IceikaBlockHelper.snowyBricks.blockID);
		world.setBlock(i + 0, j + 3, k + 20, IceikaBlockHelper.snowyBricks.blockID);
		world.setBlock(i + 0, j + 3, k + 21, IceikaBlockHelper.snowyBricks.blockID);
		world.setBlock(i + 0, j + 3, k + 22, IceikaBlockHelper.snowyBricks.blockID);
		world.setBlock(i + 1, j + 0, k + 11, IceikaBlockHelper.snowyBricks.blockID);
		world.setBlock(i + 1, j + 0, k + 12, IceikaBlockHelper.frostedStone.blockID);
		world.setBlock(i + 1, j + 0, k + 13, IceikaBlockHelper.frostedStone.blockID);
		world.setBlock(i + 1, j + 0, k + 14, IceikaBlockHelper.frostedStone.blockID);
		world.setBlock(i + 1, j + 0, k + 15, IceikaBlockHelper.frostedStone.blockID);
		world.setBlock(i + 1, j + 0, k + 16, IceikaBlockHelper.frostedStone.blockID);
		world.setBlock(i + 1, j + 0, k + 17, IceikaBlockHelper.frostedStone.blockID);
		world.setBlock(i + 1, j + 0, k + 18, IceikaBlockHelper.frostedStone.blockID);
		world.setBlock(i + 1, j + 0, k + 19, IceikaBlockHelper.frostedStone.blockID);
		world.setBlock(i + 1, j + 0, k + 20, IceikaBlockHelper.frostedStone.blockID);
		world.setBlock(i + 1, j + 0, k + 21, IceikaBlockHelper.frostedStone.blockID);
		world.setBlock(i + 1, j + 0, k + 22, IceikaBlockHelper.snowyBricks.blockID);
		world.setBlock(i + 1, j + 1, k + 11, IceikaBlockHelper.snowyBricks.blockID);
		world.setBlock(i + 1, j + 1, k + 12, 0);
		world.setBlock(i + 1, j + 1, k + 13, 0);
		world.setBlock(i + 1, j + 1, k + 14, 0);
		world.setBlock(i + 1, j + 1, k + 15, 0);
		world.setBlock(i + 1, j + 1, k + 16, 0);
		world.setBlock(i + 1, j + 1, k + 17, 0);
		world.setBlock(i + 1, j + 1, k + 18, 0);
		world.setBlock(i + 1, j + 1, k + 19, 0);
		world.setBlock(i + 1, j + 1, k + 20, 0);
		world.setBlock(i + 1, j + 1, k + 21, 0);
		world.setBlock(i + 1, j + 1, k + 22, IceikaBlockHelper.snowyBricks.blockID);
		world.setBlock(i + 1, j + 2, k + 11, IceikaBlockHelper.snowyBricks.blockID);
		world.setBlock(i + 1, j + 2, k + 12, 0);
		world.setBlock(i + 1, j + 2, k + 13, 0);
		world.setBlock(i + 1, j + 2, k + 14, 0);
		world.setBlock(i + 1, j + 2, k + 15, 0);
		world.setBlock(i + 1, j + 2, k + 16, 0);
		world.setBlock(i + 1, j + 2, k + 17, 0);
		world.setBlock(i + 1, j + 2, k + 18, 0);
		world.setBlock(i + 1, j + 2, k + 19, 0);
		world.setBlock(i + 1, j + 2, k + 20, 0);
		world.setBlock(i + 1, j + 2, k + 21, 0);
		world.setBlock(i + 1, j + 2, k + 22, IceikaBlockHelper.snowyBricks.blockID);
		world.setBlock(i + 1, j + 3, k + 11, IceikaBlockHelper.snowyBricks.blockID);
		world.setBlock(i + 1, j + 3, k + 12, 0);
		world.setBlock(i + 1, j + 3, k + 13, 0);
		world.setBlock(i + 1, j + 3, k + 14, 0);
		world.setBlock(i + 1, j + 3, k + 15, 0);
		world.setBlock(i + 1, j + 3, k + 16, 0);
		world.setBlock(i + 1, j + 3, k + 17, 0);
		world.setBlock(i + 1, j + 3, k + 18, 0);
		world.setBlock(i + 1, j + 3, k + 19, 0);
		world.setBlock(i + 1, j + 3, k + 20, 0);
		world.setBlock(i + 1, j + 3, k + 21, 0);
		world.setBlock(i + 1, j + 3, k + 22, IceikaBlockHelper.snowyBricks.blockID);
		world.setBlock(i + 1, j + 4, k + 12, IceikaBlockHelper.snowyBricks.blockID);
		world.setBlock(i + 1, j + 4, k + 13, IceikaBlockHelper.snowyBricks.blockID);
		world.setBlock(i + 1, j + 4, k + 14, IceikaBlockHelper.snowyBricks.blockID);
		world.setBlock(i + 1, j + 4, k + 15, IceikaBlockHelper.snowyBricks.blockID);
		world.setBlock(i + 1, j + 4, k + 16, IceikaBlockHelper.snowyBricks.blockID);
		world.setBlock(i + 1, j + 4, k + 17, IceikaBlockHelper.snowyBricks.blockID);
		world.setBlock(i + 1, j + 4, k + 18, IceikaBlockHelper.snowyBricks.blockID);
		world.setBlock(i + 1, j + 4, k + 19, IceikaBlockHelper.snowyBricks.blockID);
		world.setBlock(i + 1, j + 4, k + 20, IceikaBlockHelper.snowyBricks.blockID);
		world.setBlock(i + 1, j + 4, k + 21, IceikaBlockHelper.snowyBricks.blockID);
		world.setBlock(i + 2, j + 0, k + 11, IceikaBlockHelper.snowyBricks.blockID);
		world.setBlock(i + 2, j + 0, k + 12, IceikaBlockHelper.frostedStone.blockID);
		world.setBlock(i + 2, j + 0, k + 13, IceikaBlockHelper.frostedStone.blockID);
		world.setBlock(i + 2, j + 0, k + 14, IceikaBlockHelper.frostedStone.blockID);
		world.setBlock(i + 2, j + 0, k + 15, IceikaBlockHelper.frostedStone.blockID);
		world.setBlock(i + 2, j + 0, k + 16, IceikaBlockHelper.frostedStone.blockID);
		world.setBlock(i + 2, j + 0, k + 17, IceikaBlockHelper.frostedStone.blockID);
		world.setBlock(i + 2, j + 0, k + 18, IceikaBlockHelper.frostedStone.blockID);
		world.setBlock(i + 2, j + 0, k + 19, IceikaBlockHelper.frostedStone.blockID);
		world.setBlock(i + 2, j + 0, k + 20, IceikaBlockHelper.frostedStone.blockID);
		world.setBlock(i + 2, j + 0, k + 21, IceikaBlockHelper.frostedStone.blockID);
		world.setBlock(i + 2, j + 0, k + 22, IceikaBlockHelper.snowyBricks.blockID);
		world.setBlock(i + 2, j + 1, k + 11, IceikaBlockHelper.snowyBricks.blockID);
		world.setBlock(i + 2, j + 1, k + 12, 0);
		world.setBlock(i + 2, j + 1, k + 13, 0);
		world.setBlock(i + 2, j + 1, k + 14, 0);
		world.setBlock(i + 2, j + 1, k + 15, 0);
		world.setBlock(i + 2, j + 1, k + 16, 0);
		world.setBlock(i + 2, j + 1, k + 17, 0);
		world.setBlock(i + 2, j + 1, k + 18, 0);
		world.setBlock(i + 2, j + 1, k + 19, 0);
		world.setBlock(i + 2, j + 1, k + 20, 0);
		world.setBlock(i + 2, j + 1, k + 21, 0);
		world.setBlock(i + 2, j + 1, k + 22, IceikaBlockHelper.snowyBricks.blockID);
		world.setBlock(i + 2, j + 2, k + 11, IceikaBlockHelper.snowyBricks.blockID);
		world.setBlock(i + 2, j + 2, k + 12, 0);
		world.setBlock(i + 2, j + 2, k + 13, 0);
		world.setBlock(i + 2, j + 2, k + 14, 0);
		world.setBlock(i + 2, j + 2, k + 15, 0);
		world.setBlock(i + 2, j + 2, k + 16, 0);
		world.setBlock(i + 2, j + 2, k + 17, 0);
		world.setBlock(i + 2, j + 2, k + 18, 0);
		world.setBlock(i + 2, j + 2, k + 19, 0);
		world.setBlock(i + 2, j + 2, k + 20, 0);
		world.setBlock(i + 2, j + 2, k + 21, 0);
		world.setBlock(i + 2, j + 2, k + 22, IceikaBlockHelper.snowyBricks.blockID);
		world.setBlock(i + 2, j + 3, k + 11, IceikaBlockHelper.snowyBricks.blockID);
		world.setBlock(i + 2, j + 3, k + 12, 0);
		world.setBlock(i + 2, j + 3, k + 13, 0);
		world.setBlock(i + 2, j + 3, k + 14, 0);
		world.setBlock(i + 2, j + 3, k + 15, 0);
		world.setBlock(i + 2, j + 3, k + 16, 0);
		world.setBlock(i + 2, j + 3, k + 17, 0);
		world.setBlock(i + 2, j + 3, k + 18, 0);
		world.setBlock(i + 2, j + 3, k + 19, 0);
		world.setBlock(i + 2, j + 3, k + 20, 0);
		world.setBlock(i + 2, j + 3, k + 21, 0);
		world.setBlock(i + 2, j + 3, k + 22, IceikaBlockHelper.snowyBricks.blockID);
		world.setBlock(i + 2, j + 4, k + 12, IceikaBlockHelper.snowyBricks.blockID);
		world.setBlock(i + 2, j + 4, k + 13, IceikaBlockHelper.snowyBricks.blockID);
		world.setBlock(i + 2, j + 4, k + 14, IceikaBlockHelper.snowyBricks.blockID);
		world.setBlock(i + 2, j + 4, k + 15, IceikaBlockHelper.snowyBricks.blockID);
		world.setBlock(i + 2, j + 4, k + 16, IceikaBlockHelper.snowyBricks.blockID);
		world.setBlock(i + 2, j + 4, k + 17, IceikaBlockHelper.snowyBricks.blockID);
		world.setBlock(i + 2, j + 4, k + 18, IceikaBlockHelper.snowyBricks.blockID);
		world.setBlock(i + 2, j + 4, k + 19, IceikaBlockHelper.snowyBricks.blockID);
		world.setBlock(i + 2, j + 4, k + 20, IceikaBlockHelper.snowyBricks.blockID);
		world.setBlock(i + 2, j + 4, k + 21, IceikaBlockHelper.snowyBricks.blockID);
		world.setBlock(i + 3, j + 0, k + 11, IceikaBlockHelper.snowyBricks.blockID);
		world.setBlock(i + 3, j + 0, k + 12, IceikaBlockHelper.frostedStone.blockID);
		world.setBlock(i + 3, j + 0, k + 13, IceikaBlockHelper.frostedStone.blockID);
		world.setBlock(i + 3, j + 0, k + 14, IceikaBlockHelper.frostedStone.blockID);
		world.setBlock(i + 3, j + 0, k + 15, IceikaBlockHelper.frostedStone.blockID);
		world.setBlock(i + 3, j + 0, k + 16, IceikaBlockHelper.frostedStone.blockID);
		world.setBlock(i + 3, j + 0, k + 17, IceikaBlockHelper.frostedStone.blockID);
		world.setBlock(i + 3, j + 0, k + 18, IceikaBlockHelper.snowyBricks.blockID);
		world.setBlock(i + 3, j + 0, k + 19, IceikaBlockHelper.snowyBricks.blockID);
		world.setBlock(i + 3, j + 0, k + 20, IceikaBlockHelper.frostedStone.blockID);
		world.setBlock(i + 3, j + 0, k + 21, IceikaBlockHelper.frostedStone.blockID);
		world.setBlock(i + 3, j + 0, k + 22, IceikaBlockHelper.snowyBricks.blockID);
		world.setBlock(i + 3, j + 1, k + 11, IceikaBlockHelper.snowyBricks.blockID);
		world.setBlock(i + 3, j + 1, k + 12, 0);
		world.setBlock(i + 3, j + 1, k + 13, 0);
		world.setBlock(i + 3, j + 1, k + 14, 0);
		world.setBlock(i + 3, j + 1, k + 15, 0);
		world.setBlock(i + 3, j + 1, k + 16, 0);
		world.setBlock(i + 3, j + 1, k + 17, 0);
		world.setBlock(i + 3, j + 1, k + 18, IceikaBlockHelper.snowyBricks.blockID);
		world.setBlock(i + 3, j + 1, k + 19, IceikaBlockHelper.snowyBricks.blockID);
		world.setBlock(i + 3, j + 1, k + 20, 0);
		world.setBlock(i + 3, j + 1, k + 21, 0);
		world.setBlock(i + 3, j + 1, k + 22, IceikaBlockHelper.snowyBricks.blockID);
		world.setBlock(i + 3, j + 2, k + 11, IceikaBlockHelper.snowyBricks.blockID);
		world.setBlock(i + 3, j + 2, k + 12, 0);
		world.setBlock(i + 3, j + 2, k + 13, 0);
		world.setBlock(i + 3, j + 2, k + 14, 0);
		world.setBlock(i + 3, j + 2, k + 15, 0);
		world.setBlock(i + 3, j + 2, k + 16, 0);
		world.setBlock(i + 3, j + 2, k + 17, 0);
		world.setBlock(i + 3, j + 2, k + 18, IceikaBlockHelper.snowyBricks.blockID);
		world.setBlock(i + 3, j + 2, k + 19, IceikaBlockHelper.snowyBricks.blockID);
		world.setBlock(i + 3, j + 2, k + 20, 0);
		world.setBlock(i + 3, j + 2, k + 21, 0);
		world.setBlock(i + 3, j + 2, k + 22, IceikaBlockHelper.snowyBricks.blockID);
		world.setBlock(i + 3, j + 3, k + 11, IceikaBlockHelper.snowyBricks.blockID);
		world.setBlock(i + 3, j + 3, k + 12, 0);
		world.setBlock(i + 3, j + 3, k + 13, 0);
		world.setBlock(i + 3, j + 3, k + 14, 0);
		world.setBlock(i + 3, j + 3, k + 15, 0);
		world.setBlock(i + 3, j + 3, k + 16, 0);
		world.setBlock(i + 3, j + 3, k + 17, 0);
		world.setBlock(i + 3, j + 3, k + 18, IceikaBlockHelper.snowyBricks.blockID);
		world.setBlock(i + 3, j + 3, k + 19, IceikaBlockHelper.snowyBricks.blockID);
		world.setBlock(i + 3, j + 3, k + 20, 0);
		world.setBlock(i + 3, j + 3, k + 21, 0);
		world.setBlock(i + 3, j + 3, k + 22, IceikaBlockHelper.snowyBricks.blockID);
		world.setBlock(i + 3, j + 4, k + 12, IceikaBlockHelper.snowyBricks.blockID);
		world.setBlock(i + 3, j + 4, k + 13, IceikaBlockHelper.snowyBricks.blockID);
		world.setBlock(i + 3, j + 4, k + 14, IceikaBlockHelper.snowyBricks.blockID);
		world.setBlock(i + 3, j + 4, k + 15, IceikaBlockHelper.snowyBricks.blockID);
		world.setBlock(i + 3, j + 4, k + 16, IceikaBlockHelper.snowyBricks.blockID);
		world.setBlock(i + 3, j + 4, k + 17, IceikaBlockHelper.snowyBricks.blockID);
		world.setBlock(i + 3, j + 4, k + 20, IceikaBlockHelper.snowyBricks.blockID);
		world.setBlock(i + 3, j + 4, k + 21, IceikaBlockHelper.snowyBricks.blockID);
		world.setBlock(i + 4, j + 0, k + 11, IceikaBlockHelper.snowyBricks.blockID);
		world.setBlock(i + 4, j + 0, k + 12, IceikaBlockHelper.frostedStone.blockID);
		world.setBlock(i + 4, j + 0, k + 13, IceikaBlockHelper.frostedStone.blockID);
		world.setBlock(i + 4, j + 0, k + 14, IceikaBlockHelper.frostedStone.blockID);
		world.setBlock(i + 4, j + 0, k + 15, IceikaBlockHelper.frostedStone.blockID);
		world.setBlock(i + 4, j + 0, k + 16, IceikaBlockHelper.frostedStone.blockID);
		world.setBlock(i + 4, j + 0, k + 17, IceikaBlockHelper.frostedStone.blockID);
		world.setBlock(i + 4, j + 0, k + 18, IceikaBlockHelper.snowyBricks.blockID);
		world.setBlock(i + 4, j + 0, k + 19, IceikaBlockHelper.snowyBricks.blockID);
		world.setBlock(i + 4, j + 0, k + 20, IceikaBlockHelper.frostedStone.blockID);
		world.setBlock(i + 4, j + 0, k + 21, IceikaBlockHelper.frostedStone.blockID);
		world.setBlock(i + 4, j + 0, k + 22, IceikaBlockHelper.snowyBricks.blockID);
		world.setBlock(i + 4, j + 0, k + 23, IceikaBlockHelper.snowyBricks.blockID);
		world.setBlock(i + 4, j + 0, k + 24, IceikaBlockHelper.snowyBricks.blockID);
		world.setBlock(i + 4, j + 0, k + 25, IceikaBlockHelper.snowyBricks.blockID);
		world.setBlock(i + 4, j + 1, k + 11, IceikaBlockHelper.snowyBricks.blockID);
		world.setBlock(i + 4, j + 1, k + 12, 0);
		world.setBlock(i + 4, j + 1, k + 13, 0);
		world.setBlock(i + 4, j + 1, k + 14, IceikaBlockHelper.glacideSpawner.blockID);
		world.setBlock(i + 4, j + 1, k + 15, 0);
		world.setBlock(i + 4, j + 1, k + 16, 0);
		world.setBlock(i + 4, j + 1, k + 17, 0);
		world.setBlock(i + 4, j + 1, k + 18, IceikaBlockHelper.snowyBricks.blockID);
		world.setBlock(i + 4, j + 1, k + 19, IceikaBlockHelper.snowyBricks.blockID);
		world.setBlock(i + 4, j + 1, k + 20, 0);
		world.setBlock(i + 4, j + 1, k + 21, 0);
		world.setBlock(i + 4, j + 1, k + 22, IceikaBlockHelper.snowyBricks.blockID);
		world.setBlock(i + 4, j + 1, k + 23, IceikaBlockHelper.snowyBricks.blockID);
		world.setBlock(i + 4, j + 1, k + 24, IceikaBlockHelper.snowyBricks.blockID);
		world.setBlock(i + 4, j + 1, k + 25, IceikaBlockHelper.snowyBricks.blockID);
		world.setBlock(i + 4, j + 2, k + 11, IceikaBlockHelper.snowyBricks.blockID);
		world.setBlock(i + 4, j + 2, k + 12, 0);
		world.setBlock(i + 4, j + 2, k + 13, 0);
		world.setBlock(i + 4, j + 2, k + 14, 0);
		world.setBlock(i + 4, j + 2, k + 15, 0);
		world.setBlock(i + 4, j + 2, k + 16, 0);
		world.setBlock(i + 4, j + 2, k + 17, 0);
		world.setBlock(i + 4, j + 2, k + 18, IceikaBlockHelper.snowyBricks.blockID);
		world.setBlock(i + 4, j + 2, k + 19, IceikaBlockHelper.snowyBricks.blockID);
		world.setBlock(i + 4, j + 2, k + 20, 0);
		world.setBlock(i + 4, j + 2, k + 21, 0);
		world.setBlock(i + 4, j + 2, k + 22, IceikaBlockHelper.snowyBricks.blockID);
		world.setBlock(i + 4, j + 2, k + 23, IceikaBlockHelper.snowyBricks.blockID);
		world.setBlock(i + 4, j + 2, k + 24, IceikaBlockHelper.snowyBricks.blockID);
		world.setBlock(i + 4, j + 2, k + 25, IceikaBlockHelper.snowyBricks.blockID);
		world.setBlock(i + 4, j + 3, k + 11, IceikaBlockHelper.snowyBricks.blockID);
		world.setBlock(i + 4, j + 3, k + 12, 0);
		world.setBlock(i + 4, j + 3, k + 13, 0);
		world.setBlock(i + 4, j + 3, k + 14, 0);
		world.setBlock(i + 4, j + 3, k + 15, 0);
		world.setBlock(i + 4, j + 3, k + 16, 0);
		world.setBlock(i + 4, j + 3, k + 17, 0);
		world.setBlock(i + 4, j + 3, k + 18, IceikaBlockHelper.snowyBricks.blockID);
		world.setBlock(i + 4, j + 3, k + 19, IceikaBlockHelper.snowyBricks.blockID);
		world.setBlock(i + 4, j + 3, k + 20, 0);
		world.setBlock(i + 4, j + 3, k + 21, 0);
		world.setBlock(i + 4, j + 3, k + 22, IceikaBlockHelper.snowyBricks.blockID);
		world.setBlock(i + 4, j + 3, k + 23, IceikaBlockHelper.snowyBricks.blockID);
		world.setBlock(i + 4, j + 3, k + 24, IceikaBlockHelper.snowyBricks.blockID);
		world.setBlock(i + 4, j + 3, k + 25, IceikaBlockHelper.snowyBricks.blockID);
		world.setBlock(i + 4, j + 4, k + 12, IceikaBlockHelper.snowyBricks.blockID);
		world.setBlock(i + 4, j + 4, k + 13, IceikaBlockHelper.snowyBricks.blockID);
		world.setBlock(i + 4, j + 4, k + 14, IceikaBlockHelper.snowyBricks.blockID);
		world.setBlock(i + 4, j + 4, k + 15, IceikaBlockHelper.snowyBricks.blockID);
		world.setBlock(i + 4, j + 4, k + 16, IceikaBlockHelper.snowyBricks.blockID);
		world.setBlock(i + 4, j + 4, k + 17, IceikaBlockHelper.snowyBricks.blockID);
		world.setBlock(i + 4, j + 4, k + 20, IceikaBlockHelper.snowyBricks.blockID);
		world.setBlock(i + 4, j + 4, k + 21, IceikaBlockHelper.snowyBricks.blockID);
		world.setBlock(i + 5, j + 0, k + 11, IceikaBlockHelper.snowyBricks.blockID);
		world.setBlock(i + 5, j + 0, k + 12, IceikaBlockHelper.frostedStone.blockID);
		world.setBlock(i + 5, j + 0, k + 13, IceikaBlockHelper.frostedStone.blockID);
		world.setBlock(i + 5, j + 0, k + 14, IceikaBlockHelper.frostedStone.blockID);
		world.setBlock(i + 5, j + 0, k + 15, IceikaBlockHelper.frostedStone.blockID);
		world.setBlock(i + 5, j + 0, k + 16, IceikaBlockHelper.frostedStone.blockID);
		world.setBlock(i + 5, j + 0, k + 17, IceikaBlockHelper.frostedStone.blockID);
		world.setBlock(i + 5, j + 0, k + 18, IceikaBlockHelper.snowyBricks.blockID);
		world.setBlock(i + 5, j + 0, k + 19, IceikaBlockHelper.snowyBricks.blockID);
		world.setBlock(i + 5, j + 0, k + 20, IceikaBlockHelper.frostedStone.blockID);
		world.setBlock(i + 5, j + 0, k + 21, IceikaBlockHelper.frostedStone.blockID);
		world.setBlock(i + 5, j + 0, k + 22, IceikaBlockHelper.frostedStone.blockID);
		world.setBlock(i + 5, j + 0, k + 23, IceikaBlockHelper.frostedStone.blockID);
		world.setBlock(i + 5, j + 0, k + 24, IceikaBlockHelper.frostedStone.blockID);
		world.setBlock(i + 5, j + 0, k + 25, IceikaBlockHelper.frostedStone.blockID);
		world.setBlock(i + 5, j + 1, k + 11, IceikaBlockHelper.snowyBricks.blockID);
		world.setBlock(i + 5, j + 1, k + 12, 0);
		world.setBlock(i + 5, j + 1, k + 13, 0);
		world.setBlock(i + 5, j + 1, k + 14, 0);
		world.setBlock(i + 5, j + 1, k + 15, 0);
		world.setBlock(i + 5, j + 1, k + 16, 0);
		world.setBlock(i + 5, j + 1, k + 17, 0);
		world.setBlock(i + 5, j + 1, k + 18, IceikaBlockHelper.snowyBricks.blockID);
		world.setBlock(i + 5, j + 1, k + 19, IceikaBlockHelper.snowyBricks.blockID);
		world.setBlock(i + 5, j + 1, k + 20, 0);
		world.setBlock(i + 5, j + 1, k + 21, 0);
		world.setBlock(i + 5, j + 1, k + 22, 0);
		world.setBlock(i + 5, j + 1, k + 23, 0);
		world.setBlock(i + 5, j + 1, k + 24, 0);
		world.setBlock(i + 5, j + 2, k + 11, IceikaBlockHelper.snowyBricks.blockID);
		world.setBlock(i + 5, j + 2, k + 12, 0);
		world.setBlock(i + 5, j + 2, k + 13, 0);
		world.setBlock(i + 5, j + 2, k + 14, 0);
		world.setBlock(i + 5, j + 2, k + 15, 0);
		world.setBlock(i + 5, j + 2, k + 16, 0);
		world.setBlock(i + 5, j + 2, k + 17, 0);
		world.setBlock(i + 5, j + 2, k + 18, IceikaBlockHelper.snowyBricks.blockID);
		world.setBlock(i + 5, j + 2, k + 19, IceikaBlockHelper.snowyBricks.blockID);
		world.setBlock(i + 5, j + 2, k + 20, 0);
		world.setBlock(i + 5, j + 2, k + 21, 0);
		world.setBlock(i + 5, j + 2, k + 22, 0);
		world.setBlock(i + 5, j + 2, k + 23, 0);
		world.setBlock(i + 5, j + 2, k + 24, 0);
		world.setBlock(i + 5, j + 3, k + 11, IceikaBlockHelper.snowyBricks.blockID);
		world.setBlock(i + 5, j + 3, k + 12, 0);
		world.setBlock(i + 5, j + 3, k + 13, 0);
		world.setBlock(i + 5, j + 3, k + 14, 0);
		world.setBlock(i + 5, j + 3, k + 15, 0);
		world.setBlock(i + 5, j + 3, k + 16, 0);
		world.setBlock(i + 5, j + 3, k + 17, 0);
		world.setBlock(i + 5, j + 3, k + 18, IceikaBlockHelper.snowyBricks.blockID);
		world.setBlock(i + 5, j + 3, k + 19, IceikaBlockHelper.snowyBricks.blockID);
		world.setBlock(i + 5, j + 3, k + 20, 0);
		world.setBlock(i + 5, j + 3, k + 21, 0);
		world.setBlock(i + 5, j + 3, k + 22, 0);
		world.setBlock(i + 5, j + 3, k + 23, 0);
		world.setBlock(i + 5, j + 3, k + 24, 0);
		world.setBlock(i + 5, j + 4, k + 12, IceikaBlockHelper.snowyBricks.blockID);
		world.setBlock(i + 5, j + 4, k + 13, IceikaBlockHelper.snowyBricks.blockID);
		world.setBlock(i + 5, j + 4, k + 14, IceikaBlockHelper.snowyBricks.blockID);
		world.setBlock(i + 5, j + 4, k + 15, IceikaBlockHelper.snowyBricks.blockID);
		world.setBlock(i + 5, j + 4, k + 16, IceikaBlockHelper.snowyBricks.blockID);
		world.setBlock(i + 5, j + 4, k + 17, IceikaBlockHelper.snowyBricks.blockID);
		world.setBlock(i + 5, j + 4, k + 20, IceikaBlockHelper.snowyBricks.blockID);
		world.setBlock(i + 5, j + 4, k + 21, IceikaBlockHelper.snowyBricks.blockID);
		world.setBlock(i + 5, j + 4, k + 22, IceikaBlockHelper.snowyBricks.blockID);
		world.setBlock(i + 5, j + 4, k + 23, IceikaBlockHelper.snowyBricks.blockID);
		world.setBlock(i + 5, j + 4, k + 24, IceikaBlockHelper.snowyBricks.blockID);
		world.setBlock(i + 5, j + 4, k + 25, IceikaBlockHelper.snowyBricks.blockID);
		world.setBlock(i + 6, j + 0, k + 11, IceikaBlockHelper.snowyBricks.blockID);
		world.setBlock(i + 6, j + 0, k + 12, IceikaBlockHelper.frostedStone.blockID);
		world.setBlock(i + 6, j + 0, k + 13, IceikaBlockHelper.frostedStone.blockID);
		world.setBlock(i + 6, j + 0, k + 14, IceikaBlockHelper.frostedStone.blockID);
		world.setBlock(i + 6, j + 0, k + 15, IceikaBlockHelper.frostedStone.blockID);
		world.setBlock(i + 6, j + 0, k + 16, IceikaBlockHelper.frostedStone.blockID);
		world.setBlock(i + 6, j + 0, k + 17, IceikaBlockHelper.frostedStone.blockID);
		world.setBlock(i + 6, j + 0, k + 18, IceikaBlockHelper.snowyBricks.blockID);
		world.setBlock(i + 6, j + 0, k + 19, IceikaBlockHelper.snowyBricks.blockID);
		world.setBlock(i + 6, j + 0, k + 20, IceikaBlockHelper.frostedStone.blockID);
		world.setBlock(i + 6, j + 0, k + 21, IceikaBlockHelper.frostedStone.blockID);
		world.setBlock(i + 6, j + 0, k + 22, IceikaBlockHelper.frostedStone.blockID);
		world.setBlock(i + 6, j + 0, k + 23, IceikaBlockHelper.frostedStone.blockID);
		world.setBlock(i + 6, j + 0, k + 24, IceikaBlockHelper.frostedStone.blockID);
		world.setBlock(i + 6, j + 0, k + 25, IceikaBlockHelper.frostedStone.blockID);
		world.setBlock(i + 6, j + 1, k + 11, IceikaBlockHelper.snowyBricks.blockID);
		world.setBlock(i + 6, j + 1, k + 12, 0);
		world.setBlock(i + 6, j + 1, k + 13, 0);
		world.setBlock(i + 6, j + 1, k + 14, 0);
		world.setBlock(i + 6, j + 1, k + 15, 0);
		world.setBlock(i + 6, j + 1, k + 16, 0);
		world.setBlock(i + 6, j + 1, k + 17, 0);
		world.setBlock(i + 6, j + 1, k + 18, IceikaBlockHelper.snowyBricks.blockID);
		world.setBlock(i + 6, j + 1, k + 19, IceikaBlockHelper.snowyBricks.blockID);
		world.setBlock(i + 6, j + 1, k + 20, 0);
		world.setBlock(i + 6, j + 1, k + 21, 0);
		world.setBlock(i + 6, j + 1, k + 22, 0);
		world.setBlock(i + 6, j + 1, k + 23, 0);
		world.setBlock(i + 6, j + 1, k + 24, 0);
		world.setBlock(i + 6, j + 2, k + 11, IceikaBlockHelper.snowyBricks.blockID);
		world.setBlock(i + 6, j + 2, k + 12, 0);
		world.setBlock(i + 6, j + 2, k + 13, 0);
		world.setBlock(i + 6, j + 2, k + 14, 0);
		world.setBlock(i + 6, j + 2, k + 15, 0);
		world.setBlock(i + 6, j + 2, k + 16, 0);
		world.setBlock(i + 6, j + 2, k + 17, 0);
		world.setBlock(i + 6, j + 2, k + 18, IceikaBlockHelper.snowyBricks.blockID);
		world.setBlock(i + 6, j + 2, k + 19, IceikaBlockHelper.snowyBricks.blockID);
		world.setBlock(i + 6, j + 2, k + 20, 0);
		world.setBlock(i + 6, j + 2, k + 21, 0);
		world.setBlock(i + 6, j + 2, k + 22, 0);
		world.setBlock(i + 6, j + 2, k + 23, 0);
		world.setBlock(i + 6, j + 2, k + 24, 0);
		world.setBlock(i + 6, j + 3, k + 11, IceikaBlockHelper.snowyBricks.blockID);
		world.setBlock(i + 6, j + 3, k + 12, 0);
		world.setBlock(i + 6, j + 3, k + 13, 0);
		world.setBlock(i + 6, j + 3, k + 14, 0);
		world.setBlock(i + 6, j + 3, k + 15, 0);
		world.setBlock(i + 6, j + 3, k + 16, 0);
		world.setBlock(i + 6, j + 3, k + 17, 0);
		world.setBlock(i + 6, j + 3, k + 18, IceikaBlockHelper.snowyBricks.blockID);
		world.setBlock(i + 6, j + 3, k + 19, IceikaBlockHelper.snowyBricks.blockID);
		world.setBlock(i + 6, j + 3, k + 20, 0);
		world.setBlock(i + 6, j + 3, k + 21, 0);
		world.setBlock(i + 6, j + 3, k + 22, 0);
		world.setBlock(i + 6, j + 3, k + 23, 0);
		world.setBlock(i + 6, j + 3, k + 24, 0);
		world.setBlock(i + 6, j + 4, k + 12, IceikaBlockHelper.snowyBricks.blockID);
		world.setBlock(i + 6, j + 4, k + 13, IceikaBlockHelper.snowyBricks.blockID);
		world.setBlock(i + 6, j + 4, k + 14, IceikaBlockHelper.snowyBricks.blockID);
		world.setBlock(i + 6, j + 4, k + 15, IceikaBlockHelper.snowyBricks.blockID);
		world.setBlock(i + 6, j + 4, k + 16, IceikaBlockHelper.snowyBricks.blockID);
		world.setBlock(i + 6, j + 4, k + 17, IceikaBlockHelper.snowyBricks.blockID);
		world.setBlock(i + 6, j + 4, k + 20, IceikaBlockHelper.snowyBricks.blockID);
		world.setBlock(i + 6, j + 4, k + 21, IceikaBlockHelper.snowyBricks.blockID);
		world.setBlock(i + 6, j + 4, k + 22, IceikaBlockHelper.snowyBricks.blockID);
		world.setBlock(i + 6, j + 4, k + 23, IceikaBlockHelper.snowyBricks.blockID);
		world.setBlock(i + 6, j + 4, k + 24, IceikaBlockHelper.snowyBricks.blockID);
		world.setBlock(i + 6, j + 4, k + 25, IceikaBlockHelper.snowyBricks.blockID);
		world.setBlock(i + 7, j + 0, k + 0, IceikaBlockHelper.snowyBricks.blockID);
		world.setBlock(i + 7, j + 0, k + 1, IceikaBlockHelper.snowyBricks.blockID);
		world.setBlock(i + 7, j + 0, k + 2, IceikaBlockHelper.snowyBricks.blockID);
		world.setBlock(i + 7, j + 0, k + 3, IceikaBlockHelper.snowyBricks.blockID);
		world.setBlock(i + 7, j + 0, k + 4, IceikaBlockHelper.snowyBricks.blockID);
		world.setBlock(i + 7, j + 0, k + 5, IceikaBlockHelper.snowyBricks.blockID);
		world.setBlock(i + 7, j + 0, k + 6, IceikaBlockHelper.snowyBricks.blockID);
		world.setBlock(i + 7, j + 0, k + 7, IceikaBlockHelper.snowyBricks.blockID);
		world.setBlock(i + 7, j + 0, k + 8, IceikaBlockHelper.snowyBricks.blockID);
		world.setBlock(i + 7, j + 0, k + 11, IceikaBlockHelper.snowyBricks.blockID);
		world.setBlock(i + 7, j + 0, k + 12, IceikaBlockHelper.snowyBricks.blockID);
		world.setBlock(i + 7, j + 0, k + 13, IceikaBlockHelper.snowyBricks.blockID);
		world.setBlock(i + 7, j + 0, k + 14, IceikaBlockHelper.frostedStone.blockID);
		world.setBlock(i + 7, j + 0, k + 15, IceikaBlockHelper.frostedStone.blockID);
		world.setBlock(i + 7, j + 0, k + 16, IceikaBlockHelper.snowyBricks.blockID);
		world.setBlock(i + 7, j + 0, k + 17, IceikaBlockHelper.snowyBricks.blockID);
		world.setBlock(i + 7, j + 0, k + 18, IceikaBlockHelper.snowyBricks.blockID);
		world.setBlock(i + 7, j + 0, k + 19, IceikaBlockHelper.snowyBricks.blockID);
		world.setBlock(i + 7, j + 0, k + 20, IceikaBlockHelper.snowyBricks.blockID);
		world.setBlock(i + 7, j + 0, k + 21, IceikaBlockHelper.snowyBricks.blockID);
		world.setBlock(i + 7, j + 0, k + 22, IceikaBlockHelper.snowyBricks.blockID);
		world.setBlock(i + 7, j + 0, k + 23, IceikaBlockHelper.snowyBricks.blockID);
		world.setBlock(i + 7, j + 0, k + 24, IceikaBlockHelper.snowyBricks.blockID);
		world.setBlock(i + 7, j + 0, k + 25, IceikaBlockHelper.snowyBricks.blockID);
		world.setBlock(i + 7, j + 1, k + 0, IceikaBlockHelper.snowyBricks.blockID);
		world.setBlock(i + 7, j + 1, k + 1, IceikaBlockHelper.snowyBricks.blockID);
		world.setBlock(i + 7, j + 1, k + 2, IceikaBlockHelper.snowyBricks.blockID);
		world.setBlock(i + 7, j + 1, k + 3, IceikaBlockHelper.snowyBricks.blockID);
		world.setBlock(i + 7, j + 1, k + 4, IceikaBlockHelper.snowyBricks.blockID);
		world.setBlock(i + 7, j + 1, k + 5, IceikaBlockHelper.snowyBricks.blockID);
		world.setBlock(i + 7, j + 1, k + 6, IceikaBlockHelper.snowyBricks.blockID);
		world.setBlock(i + 7, j + 1, k + 7, IceikaBlockHelper.snowyBricks.blockID);
		world.setBlock(i + 7, j + 1, k + 8, IceikaBlockHelper.snowyBricks.blockID);
		world.setBlock(i + 7, j + 1, k + 11, IceikaBlockHelper.snowyBricks.blockID);
		world.setBlock(i + 7, j + 1, k + 12, IceikaBlockHelper.snowyBricks.blockID);
		world.setBlock(i + 7, j + 1, k + 13, IceikaBlockHelper.snowyBricks.blockID);
		world.setBlock(i + 7, j + 1, k + 14, 0);
		world.setBlock(i + 7, j + 1, k + 15, 0);
		world.setBlock(i + 7, j + 1, k + 16, IceikaBlockHelper.snowyBricks.blockID);
		world.setBlock(i + 7, j + 1, k + 17, IceikaBlockHelper.snowyBricks.blockID);
		world.setBlock(i + 7, j + 1, k + 18, IceikaBlockHelper.snowyBricks.blockID);
		world.setBlock(i + 7, j + 1, k + 19, IceikaBlockHelper.snowyBricks.blockID);
		world.setBlock(i + 7, j + 1, k + 20, IceikaBlockHelper.snowyBricks.blockID);
		world.setBlock(i + 7, j + 1, k + 21, IceikaBlockHelper.snowyBricks.blockID);
		world.setBlock(i + 7, j + 1, k + 22, IceikaBlockHelper.snowyBricks.blockID);
		world.setBlock(i + 7, j + 1, k + 23, IceikaBlockHelper.snowyBricks.blockID);
		world.setBlock(i + 7, j + 1, k + 24, IceikaBlockHelper.snowyBricks.blockID);
		world.setBlock(i + 7, j + 1, k + 25, IceikaBlockHelper.snowyBricks.blockID);
		world.setBlock(i + 7, j + 2, k + 0, IceikaBlockHelper.snowyBricks.blockID);
		world.setBlock(i + 7, j + 2, k + 1, IceikaBlockHelper.snowyBricks.blockID);
		world.setBlock(i + 7, j + 2, k + 2, IceikaBlockHelper.snowyBricks.blockID);
		world.setBlock(i + 7, j + 2, k + 3, IceikaBlockHelper.snowyBricks.blockID);
		world.setBlock(i + 7, j + 2, k + 4, IceikaBlockHelper.snowyBricks.blockID);
		world.setBlock(i + 7, j + 2, k + 5, IceikaBlockHelper.snowyBricks.blockID);
		world.setBlock(i + 7, j + 2, k + 6, IceikaBlockHelper.snowyBricks.blockID);
		world.setBlock(i + 7, j + 2, k + 7, IceikaBlockHelper.snowyBricks.blockID);
		world.setBlock(i + 7, j + 2, k + 8, IceikaBlockHelper.snowyBricks.blockID);
		world.setBlock(i + 7, j + 2, k + 11, IceikaBlockHelper.snowyBricks.blockID);
		world.setBlock(i + 7, j + 2, k + 12, IceikaBlockHelper.snowyBricks.blockID);
		world.setBlock(i + 7, j + 2, k + 13, IceikaBlockHelper.snowyBricks.blockID);
		world.setBlock(i + 7, j + 2, k + 14, 0);
		world.setBlock(i + 7, j + 2, k + 15, 0);
		world.setBlock(i + 7, j + 2, k + 16, IceikaBlockHelper.snowyBricks.blockID);
		world.setBlock(i + 7, j + 2, k + 17, IceikaBlockHelper.snowyBricks.blockID);
		world.setBlock(i + 7, j + 2, k + 18, IceikaBlockHelper.snowyBricks.blockID);
		world.setBlock(i + 7, j + 2, k + 19, IceikaBlockHelper.snowyBricks.blockID);
		world.setBlock(i + 7, j + 2, k + 20, IceikaBlockHelper.snowyBricks.blockID);
		world.setBlock(i + 7, j + 2, k + 21, IceikaBlockHelper.snowyBricks.blockID);
		world.setBlock(i + 7, j + 2, k + 22, IceikaBlockHelper.snowyBricks.blockID);
		world.setBlock(i + 7, j + 2, k + 23, IceikaBlockHelper.snowyBricks.blockID);
		world.setBlock(i + 7, j + 2, k + 24, IceikaBlockHelper.snowyBricks.blockID);
		world.setBlock(i + 7, j + 2, k + 25, IceikaBlockHelper.snowyBricks.blockID);
		world.setBlock(i + 7, j + 3, k + 0, IceikaBlockHelper.snowyBricks.blockID);
		world.setBlock(i + 7, j + 3, k + 1, IceikaBlockHelper.snowyBricks.blockID);
		world.setBlock(i + 7, j + 3, k + 2, IceikaBlockHelper.snowyBricks.blockID);
		world.setBlock(i + 7, j + 3, k + 3, IceikaBlockHelper.snowyBricks.blockID);
		world.setBlock(i + 7, j + 3, k + 4, IceikaBlockHelper.snowyBricks.blockID);
		world.setBlock(i + 7, j + 3, k + 5, IceikaBlockHelper.snowyBricks.blockID);
		world.setBlock(i + 7, j + 3, k + 6, IceikaBlockHelper.snowyBricks.blockID);
		world.setBlock(i + 7, j + 3, k + 7, IceikaBlockHelper.snowyBricks.blockID);
		world.setBlock(i + 7, j + 3, k + 8, IceikaBlockHelper.snowyBricks.blockID);
		world.setBlock(i + 7, j + 3, k + 11, IceikaBlockHelper.snowyBricks.blockID);
		world.setBlock(i + 7, j + 3, k + 12, IceikaBlockHelper.snowyBricks.blockID);
		world.setBlock(i + 7, j + 3, k + 13, IceikaBlockHelper.snowyBricks.blockID);
		world.setBlock(i + 7, j + 3, k + 14, 0);
		world.setBlock(i + 7, j + 3, k + 15, 0);
		world.setBlock(i + 7, j + 3, k + 16, IceikaBlockHelper.snowyBricks.blockID);
		world.setBlock(i + 7, j + 3, k + 17, IceikaBlockHelper.snowyBricks.blockID);
		world.setBlock(i + 7, j + 3, k + 18, IceikaBlockHelper.snowyBricks.blockID);
		world.setBlock(i + 7, j + 3, k + 19, IceikaBlockHelper.snowyBricks.blockID);
		world.setBlock(i + 7, j + 3, k + 20, IceikaBlockHelper.snowyBricks.blockID);
		world.setBlock(i + 7, j + 3, k + 21, IceikaBlockHelper.snowyBricks.blockID);
		world.setBlock(i + 7, j + 3, k + 22, IceikaBlockHelper.snowyBricks.blockID);
		world.setBlock(i + 7, j + 3, k + 23, IceikaBlockHelper.snowyBricks.blockID);
		world.setBlock(i + 7, j + 3, k + 24, IceikaBlockHelper.snowyBricks.blockID);
		world.setBlock(i + 7, j + 3, k + 25, IceikaBlockHelper.snowyBricks.blockID);
		world.setBlock(i + 7, j + 4, k + 14, IceikaBlockHelper.snowyBricks.blockID);
		world.setBlock(i + 7, j + 4, k + 15, IceikaBlockHelper.snowyBricks.blockID);
		world.setBlock(i + 8, j + 0, k + 0, IceikaBlockHelper.snowyBricks.blockID);
		world.setBlock(i + 8, j + 0, k + 1, IceikaBlockHelper.frostedStone.blockID);
		world.setBlock(i + 8, j + 0, k + 2, IceikaBlockHelper.frostedStone.blockID);
		world.setBlock(i + 8, j + 0, k + 3, IceikaBlockHelper.frostedStone.blockID);
		world.setBlock(i + 8, j + 0, k + 4, IceikaBlockHelper.frostedStone.blockID);
		world.setBlock(i + 8, j + 0, k + 5, IceikaBlockHelper.frostedStone.blockID);
		world.setBlock(i + 8, j + 0, k + 6, IceikaBlockHelper.frostedStone.blockID);
		world.setBlock(i + 8, j + 0, k + 7, IceikaBlockHelper.frostedStone.blockID);
		world.setBlock(i + 8, j + 0, k + 8, IceikaBlockHelper.snowyBricks.blockID);
		world.setBlock(i + 8, j + 0, k + 13, IceikaBlockHelper.snowyBricks.blockID);
		world.setBlock(i + 8, j + 0, k + 14, IceikaBlockHelper.frostedStone.blockID);
		world.setBlock(i + 8, j + 0, k + 15, IceikaBlockHelper.frostedStone.blockID);
		world.setBlock(i + 8, j + 0, k + 16, IceikaBlockHelper.snowyBricks.blockID);
		world.setBlock(i + 8, j + 1, k + 0, IceikaBlockHelper.snowyBricks.blockID);
		world.setBlock(i + 8, j + 1, k + 1, IceikaBlockHelper.frostedChest.blockID);
		world.setBlock(i + 8, j + 1, k + 2, 0);
		world.setBlock(i + 8, j + 1, k + 3, 0);
		world.setBlock(i + 8, j + 1, k + 4, 0);
		world.setBlock(i + 8, j + 1, k + 5, 0);
		world.setBlock(i + 8, j + 1, k + 6, 0);
		world.setBlock(i + 8, j + 1, k + 7, 0);
		world.setBlock(i + 8, j + 1, k + 8, IceikaBlockHelper.snowyBricks.blockID);
		world.setBlock(i + 8, j + 1, k + 13, IceikaBlockHelper.snowyBricks.blockID);
		world.setBlock(i + 8, j + 1, k + 14, 0);
		world.setBlock(i + 8, j + 1, k + 15, 0);
		world.setBlock(i + 8, j + 1, k + 16, IceikaBlockHelper.snowyBricks.blockID);
		world.setBlock(i + 8, j + 2, k + 0, IceikaBlockHelper.snowyBricks.blockID);
		world.setBlock(i + 8, j + 2, k + 1, 0);
		world.setBlock(i + 8, j + 2, k + 2, 0);
		world.setBlock(i + 8, j + 2, k + 3, 0);
		world.setBlock(i + 8, j + 2, k + 4, 0);
		world.setBlock(i + 8, j + 2, k + 5, 0);
		world.setBlock(i + 8, j + 2, k + 6, 0);
		world.setBlock(i + 8, j + 2, k + 7, 0);
		world.setBlock(i + 8, j + 2, k + 8, IceikaBlockHelper.snowyBricks.blockID);
		world.setBlock(i + 8, j + 2, k + 13, IceikaBlockHelper.snowyBricks.blockID);
		world.setBlock(i + 8, j + 2, k + 14, 0);
		world.setBlock(i + 8, j + 2, k + 15, 0);
		world.setBlock(i + 8, j + 2, k + 16, IceikaBlockHelper.snowyBricks.blockID);
		world.setBlock(i + 8, j + 3, k + 0, IceikaBlockHelper.snowyBricks.blockID);
		world.setBlock(i + 8, j + 3, k + 1, 0);
		world.setBlock(i + 8, j + 3, k + 2, 0);
		world.setBlock(i + 8, j + 3, k + 3, 0);
		world.setBlock(i + 8, j + 3, k + 4, 0);
		world.setBlock(i + 8, j + 3, k + 5, 0);
		world.setBlock(i + 8, j + 3, k + 6, 0);
		world.setBlock(i + 8, j + 3, k + 7, 0);
		world.setBlock(i + 8, j + 3, k + 8, IceikaBlockHelper.snowyBricks.blockID);
		world.setBlock(i + 8, j + 3, k + 13, IceikaBlockHelper.snowyBricks.blockID);
		world.setBlock(i + 8, j + 3, k + 14, 0);
		world.setBlock(i + 8, j + 3, k + 15, 0);
		world.setBlock(i + 8, j + 3, k + 16, IceikaBlockHelper.snowyBricks.blockID);
		world.setBlock(i + 8, j + 4, k + 1, IceikaBlockHelper.snowyBricks.blockID);
		world.setBlock(i + 8, j + 4, k + 2, IceikaBlockHelper.snowyBricks.blockID);
		world.setBlock(i + 8, j + 4, k + 3, IceikaBlockHelper.snowyBricks.blockID);
		world.setBlock(i + 8, j + 4, k + 4, IceikaBlockHelper.snowyBricks.blockID);
		world.setBlock(i + 8, j + 4, k + 5, IceikaBlockHelper.snowyBricks.blockID);
		world.setBlock(i + 8, j + 4, k + 6, IceikaBlockHelper.snowyBricks.blockID);
		world.setBlock(i + 8, j + 4, k + 7, IceikaBlockHelper.snowyBricks.blockID);
		world.setBlock(i + 8, j + 4, k + 14, IceikaBlockHelper.snowyBricks.blockID);
		world.setBlock(i + 8, j + 4, k + 15, IceikaBlockHelper.snowyBricks.blockID);
		world.setBlock(i + 9, j + 0, k + 0, IceikaBlockHelper.snowyBricks.blockID);
		world.setBlock(i + 9, j + 0, k + 1, IceikaBlockHelper.frostedStone.blockID);
		world.setBlock(i + 9, j + 0, k + 2, IceikaBlockHelper.frostedStone.blockID);
		world.setBlock(i + 9, j + 0, k + 3, IceikaBlockHelper.frostedStone.blockID);
		world.setBlock(i + 9, j + 0, k + 4, IceikaBlockHelper.frostedStone.blockID);
		world.setBlock(i + 9, j + 0, k + 5, IceikaBlockHelper.frostedStone.blockID);
		world.setBlock(i + 9, j + 0, k + 6, IceikaBlockHelper.frostedStone.blockID);
		world.setBlock(i + 9, j + 0, k + 7, IceikaBlockHelper.frostedStone.blockID);
		world.setBlock(i + 9, j + 0, k + 8, IceikaBlockHelper.snowyBricks.blockID);
		world.setBlock(i + 9, j + 0, k + 9, IceikaBlockHelper.snowyBricks.blockID);
		world.setBlock(i + 9, j + 0, k + 10, IceikaBlockHelper.snowyBricks.blockID);
		world.setBlock(i + 9, j + 0, k + 11, IceikaBlockHelper.snowyBricks.blockID);
		world.setBlock(i + 9, j + 0, k + 12, IceikaBlockHelper.snowyBricks.blockID);
		world.setBlock(i + 9, j + 0, k + 13, IceikaBlockHelper.snowyBricks.blockID);
		world.setBlock(i + 9, j + 0, k + 14, IceikaBlockHelper.frostedStone.blockID);
		world.setBlock(i + 9, j + 0, k + 15, IceikaBlockHelper.frostedStone.blockID);
		world.setBlock(i + 9, j + 0, k + 16, IceikaBlockHelper.snowyBricks.blockID);
		world.setBlock(i + 9, j + 1, k + 0, IceikaBlockHelper.snowyBricks.blockID);
		world.setBlock(i + 9, j + 1, k + 1, 0);
		world.setBlock(i + 9, j + 1, k + 2, 0);
		world.setBlock(i + 9, j + 1, k + 3, 0);
		world.setBlock(i + 9, j + 1, k + 4, IceikaBlockHelper.glacideSpawner.blockID);
		world.setBlock(i + 9, j + 1, k + 5, 0);
		world.setBlock(i + 9, j + 1, k + 6, 0);
		world.setBlock(i + 9, j + 1, k + 7, 0);
		world.setBlock(i + 9, j + 1, k + 8, IceikaBlockHelper.snowyBricks.blockID);
		world.setBlock(i + 9, j + 1, k + 9, IceikaBlockHelper.snowyBricks.blockID);
		world.setBlock(i + 9, j + 1, k + 10, IceikaBlockHelper.snowyBricks.blockID);
		world.setBlock(i + 9, j + 1, k + 11, IceikaBlockHelper.snowyBricks.blockID);
		world.setBlock(i + 9, j + 1, k + 12, IceikaBlockHelper.snowyBricks.blockID);
		world.setBlock(i + 9, j + 1, k + 13, IceikaBlockHelper.snowyBricks.blockID);
		world.setBlock(i + 9, j + 1, k + 14, 0);
		world.setBlock(i + 9, j + 1, k + 15, 0);
		world.setBlock(i + 9, j + 1, k + 16, IceikaBlockHelper.snowyBricks.blockID);
		world.setBlock(i + 9, j + 2, k + 0, IceikaBlockHelper.snowyBricks.blockID);
		world.setBlock(i + 9, j + 2, k + 1, 0);
		world.setBlock(i + 9, j + 2, k + 2, 0);
		world.setBlock(i + 9, j + 2, k + 3, 0);
		world.setBlock(i + 9, j + 2, k + 4, 0);
		world.setBlock(i + 9, j + 2, k + 5, 0);
		world.setBlock(i + 9, j + 2, k + 6, 0);
		world.setBlock(i + 9, j + 2, k + 7, 0);
		world.setBlock(i + 9, j + 2, k + 8, IceikaBlockHelper.snowyBricks.blockID);
		world.setBlock(i + 9, j + 2, k + 9, IceikaBlockHelper.snowyBricks.blockID);
		world.setBlock(i + 9, j + 2, k + 10, IceikaBlockHelper.snowyBricks.blockID);
		world.setBlock(i + 9, j + 2, k + 11, IceikaBlockHelper.snowyBricks.blockID);
		world.setBlock(i + 9, j + 2, k + 12, IceikaBlockHelper.snowyBricks.blockID);
		world.setBlock(i + 9, j + 2, k + 13, IceikaBlockHelper.snowyBricks.blockID);
		world.setBlock(i + 9, j + 2, k + 14, 0);
		world.setBlock(i + 9, j + 2, k + 15, 0);
		world.setBlock(i + 9, j + 2, k + 16, IceikaBlockHelper.snowyBricks.blockID);
		world.setBlock(i + 9, j + 3, k + 0, IceikaBlockHelper.snowyBricks.blockID);
		world.setBlock(i + 9, j + 3, k + 1, 0);
		world.setBlock(i + 9, j + 3, k + 2, 0);
		world.setBlock(i + 9, j + 3, k + 3, 0);
		world.setBlock(i + 9, j + 3, k + 4, 0);
		world.setBlock(i + 9, j + 3, k + 5, 0);
		world.setBlock(i + 9, j + 3, k + 6, 0);
		world.setBlock(i + 9, j + 3, k + 7, 0);
		world.setBlock(i + 9, j + 3, k + 8, IceikaBlockHelper.snowyBricks.blockID);
		world.setBlock(i + 9, j + 3, k + 9, IceikaBlockHelper.snowyBricks.blockID);
		world.setBlock(i + 9, j + 3, k + 10, IceikaBlockHelper.snowyBricks.blockID);
		world.setBlock(i + 9, j + 3, k + 11, IceikaBlockHelper.snowyBricks.blockID);
		world.setBlock(i + 9, j + 3, k + 12, IceikaBlockHelper.snowyBricks.blockID);
		world.setBlock(i + 9, j + 3, k + 13, IceikaBlockHelper.snowyBricks.blockID);
		world.setBlock(i + 9, j + 3, k + 14, 0);
		world.setBlock(i + 9, j + 3, k + 15, 0);
		world.setBlock(i + 9, j + 3, k + 16, IceikaBlockHelper.snowyBricks.blockID);
		world.setBlock(i + 9, j + 4, k + 1, IceikaBlockHelper.snowyBricks.blockID);
		world.setBlock(i + 9, j + 4, k + 2, IceikaBlockHelper.snowyBricks.blockID);
		world.setBlock(i + 9, j + 4, k + 3, IceikaBlockHelper.snowyBricks.blockID);
		world.setBlock(i + 9, j + 4, k + 4, IceikaBlockHelper.snowyBricks.blockID);
		world.setBlock(i + 9, j + 4, k + 5, IceikaBlockHelper.snowyBricks.blockID);
		world.setBlock(i + 9, j + 4, k + 6, IceikaBlockHelper.snowyBricks.blockID);
		world.setBlock(i + 9, j + 4, k + 7, IceikaBlockHelper.snowyBricks.blockID);
		world.setBlock(i + 9, j + 4, k + 14, IceikaBlockHelper.snowyBricks.blockID);
		world.setBlock(i + 9, j + 4, k + 15, IceikaBlockHelper.snowyBricks.blockID);
		world.setBlock(i + 10, j + 0, k + 0, IceikaBlockHelper.snowyBricks.blockID);
		world.setBlock(i + 10, j + 0, k + 1, IceikaBlockHelper.frostedStone.blockID);
		world.setBlock(i + 10, j + 0, k + 2, IceikaBlockHelper.frostedStone.blockID);
		world.setBlock(i + 10, j + 0, k + 3, IceikaBlockHelper.frostedStone.blockID);
		world.setBlock(i + 10, j + 0, k + 4, IceikaBlockHelper.frostedStone.blockID);
		world.setBlock(i + 10, j + 0, k + 5, IceikaBlockHelper.frostedStone.blockID);
		world.setBlock(i + 10, j + 0, k + 6, IceikaBlockHelper.frostedStone.blockID);
		world.setBlock(i + 10, j + 0, k + 7, IceikaBlockHelper.frostedStone.blockID);
		world.setBlock(i + 10, j + 0, k + 8, IceikaBlockHelper.frostedStone.blockID);
		world.setBlock(i + 10, j + 0, k + 9, IceikaBlockHelper.frostedStone.blockID);
		world.setBlock(i + 10, j + 0, k + 10, IceikaBlockHelper.frostedStone.blockID);
		world.setBlock(i + 10, j + 0, k + 11, IceikaBlockHelper.frostedStone.blockID);
		world.setBlock(i + 10, j + 0, k + 12, IceikaBlockHelper.frostedStone.blockID);
		world.setBlock(i + 10, j + 0, k + 13, IceikaBlockHelper.frostedStone.blockID);
		world.setBlock(i + 10, j + 0, k + 14, IceikaBlockHelper.frostedStone.blockID);
		world.setBlock(i + 10, j + 0, k + 15, IceikaBlockHelper.frostedStone.blockID);
		world.setBlock(i + 10, j + 0, k + 16, IceikaBlockHelper.snowyBricks.blockID);
		world.setBlock(i + 10, j + 1, k + 0, IceikaBlockHelper.snowyBricks.blockID);
		world.setBlock(i + 10, j + 1, k + 1, 0);
		world.setBlock(i + 10, j + 1, k + 2, 0);
		world.setBlock(i + 10, j + 1, k + 3, 0);
		world.setBlock(i + 10, j + 1, k + 4, 0);
		world.setBlock(i + 10, j + 1, k + 5, 0);
		world.setBlock(i + 10, j + 1, k + 6, 0);
		world.setBlock(i + 10, j + 1, k + 7, 0);
		world.setBlock(i + 10, j + 1, k + 8, 0);
		world.setBlock(i + 10, j + 1, k + 9, 0);
		world.setBlock(i + 10, j + 1, k + 10, 0);
		world.setBlock(i + 10, j + 1, k + 11, 0);
		world.setBlock(i + 10, j + 1, k + 12, 0);
		world.setBlock(i + 10, j + 1, k + 13, 0);
		world.setBlock(i + 10, j + 1, k + 14, 0);
		world.setBlock(i + 10, j + 1, k + 15, 0);
		world.setBlock(i + 10, j + 1, k + 16, IceikaBlockHelper.snowyBricks.blockID);
		world.setBlock(i + 10, j + 2, k + 0, IceikaBlockHelper.snowyBricks.blockID);
		world.setBlock(i + 10, j + 2, k + 1, 0);
		world.setBlock(i + 10, j + 2, k + 2, 0);
		world.setBlock(i + 10, j + 2, k + 3, 0);
		world.setBlock(i + 10, j + 2, k + 4, 0);
		world.setBlock(i + 10, j + 2, k + 5, 0);
		world.setBlock(i + 10, j + 2, k + 6, 0);
		world.setBlock(i + 10, j + 2, k + 7, 0);
		world.setBlock(i + 10, j + 2, k + 8, 0);
		world.setBlock(i + 10, j + 2, k + 9, 0);
		world.setBlock(i + 10, j + 2, k + 10, 0);
		world.setBlock(i + 10, j + 2, k + 11, 0);
		world.setBlock(i + 10, j + 2, k + 12, 0);
		world.setBlock(i + 10, j + 2, k + 13, 0);
		world.setBlock(i + 10, j + 2, k + 14, 0);
		world.setBlock(i + 10, j + 2, k + 15, 0);
		world.setBlock(i + 10, j + 2, k + 16, IceikaBlockHelper.snowyBricks.blockID);
		world.setBlock(i + 10, j + 3, k + 0, IceikaBlockHelper.snowyBricks.blockID);
		world.setBlock(i + 10, j + 3, k + 1, 0);
		world.setBlock(i + 10, j + 3, k + 2, 0);
		world.setBlock(i + 10, j + 3, k + 3, 0);
		world.setBlock(i + 10, j + 3, k + 4, 0);
		world.setBlock(i + 10, j + 3, k + 5, 0);
		world.setBlock(i + 10, j + 3, k + 6, 0);
		world.setBlock(i + 10, j + 3, k + 7, 0);
		world.setBlock(i + 10, j + 3, k + 8, 0);
		world.setBlock(i + 10, j + 3, k + 9, 0);
		world.setBlock(i + 10, j + 3, k + 10, 0);
		world.setBlock(i + 10, j + 3, k + 11, 0);
		world.setBlock(i + 10, j + 3, k + 12, 0);
		world.setBlock(i + 10, j + 3, k + 13, 0);
		world.setBlock(i + 10, j + 3, k + 14, 0);
		world.setBlock(i + 10, j + 3, k + 15, 0);
		world.setBlock(i + 10, j + 3, k + 16, IceikaBlockHelper.snowyBricks.blockID);
		world.setBlock(i + 10, j + 4, k + 1, IceikaBlockHelper.snowyBricks.blockID);
		world.setBlock(i + 10, j + 4, k + 2, IceikaBlockHelper.snowyBricks.blockID);
		world.setBlock(i + 10, j + 4, k + 3, IceikaBlockHelper.snowyBricks.blockID);
		world.setBlock(i + 10, j + 4, k + 4, IceikaBlockHelper.snowyBricks.blockID);
		world.setBlock(i + 10, j + 4, k + 5, IceikaBlockHelper.snowyBricks.blockID);
		world.setBlock(i + 10, j + 4, k + 6, IceikaBlockHelper.snowyBricks.blockID);
		world.setBlock(i + 10, j + 4, k + 7, IceikaBlockHelper.snowyBricks.blockID);
		world.setBlock(i + 10, j + 4, k + 8, IceikaBlockHelper.snowyBricks.blockID);
		world.setBlock(i + 10, j + 4, k + 9, IceikaBlockHelper.snowyBricks.blockID);
		world.setBlock(i + 10, j + 4, k + 10, IceikaBlockHelper.snowyBricks.blockID);
		world.setBlock(i + 10, j + 4, k + 11, IceikaBlockHelper.snowyBricks.blockID);
		world.setBlock(i + 10, j + 4, k + 12, IceikaBlockHelper.snowyBricks.blockID);
		world.setBlock(i + 10, j + 4, k + 13, IceikaBlockHelper.snowyBricks.blockID);
		world.setBlock(i + 10, j + 4, k + 14, IceikaBlockHelper.snowyBricks.blockID);
		world.setBlock(i + 10, j + 4, k + 15, IceikaBlockHelper.snowyBricks.blockID);
		world.setBlock(i + 11, j + 0, k + 0, IceikaBlockHelper.snowyBricks.blockID);
		world.setBlock(i + 11, j + 0, k + 1, IceikaBlockHelper.frostedStone.blockID);
		world.setBlock(i + 11, j + 0, k + 2, IceikaBlockHelper.frostedStone.blockID);
		world.setBlock(i + 11, j + 0, k + 3, IceikaBlockHelper.frostedStone.blockID);
		world.setBlock(i + 11, j + 0, k + 4, IceikaBlockHelper.frostedStone.blockID);
		world.setBlock(i + 11, j + 0, k + 5, IceikaBlockHelper.frostedStone.blockID);
		world.setBlock(i + 11, j + 0, k + 6, IceikaBlockHelper.frostedStone.blockID);
		world.setBlock(i + 11, j + 0, k + 7, IceikaBlockHelper.frostedStone.blockID);
		world.setBlock(i + 11, j + 0, k + 8, IceikaBlockHelper.frostedStone.blockID);
		world.setBlock(i + 11, j + 0, k + 9, IceikaBlockHelper.frostedStone.blockID);
		world.setBlock(i + 11, j + 0, k + 10, IceikaBlockHelper.frostedStone.blockID);
		world.setBlock(i + 11, j + 0, k + 11, IceikaBlockHelper.frostedStone.blockID);
		world.setBlock(i + 11, j + 0, k + 12, IceikaBlockHelper.frostedStone.blockID);
		world.setBlock(i + 11, j + 0, k + 13, IceikaBlockHelper.frostedStone.blockID);
		world.setBlock(i + 11, j + 0, k + 14, IceikaBlockHelper.frostedStone.blockID);
		world.setBlock(i + 11, j + 0, k + 15, IceikaBlockHelper.frostedStone.blockID);
		world.setBlock(i + 11, j + 0, k + 16, IceikaBlockHelper.snowyBricks.blockID);
		world.setBlock(i + 11, j + 1, k + 0, IceikaBlockHelper.snowyBricks.blockID);
		world.setBlock(i + 11, j + 1, k + 1, 0);
		world.setBlock(i + 11, j + 1, k + 2, 0);
		world.setBlock(i + 11, j + 1, k + 3, 0);
		world.setBlock(i + 11, j + 1, k + 4, 0);
		world.setBlock(i + 11, j + 1, k + 5, 0);
		world.setBlock(i + 11, j + 1, k + 6, 0);
		world.setBlock(i + 11, j + 1, k + 7, 0);
		world.setBlock(i + 11, j + 1, k + 8, 0);
		world.setBlock(i + 11, j + 1, k + 9, 0);
		world.setBlock(i + 11, j + 1, k + 10, 0);
		world.setBlock(i + 11, j + 1, k + 11, 0);
		world.setBlock(i + 11, j + 1, k + 12, 0);
		world.setBlock(i + 11, j + 1, k + 13, 0);
		world.setBlock(i + 11, j + 1, k + 14, 0);
		world.setBlock(i + 11, j + 1, k + 15, 0);
		world.setBlock(i + 11, j + 1, k + 16, IceikaBlockHelper.snowyBricks.blockID);
		world.setBlock(i + 11, j + 2, k + 0, IceikaBlockHelper.snowyBricks.blockID);
		world.setBlock(i + 11, j + 2, k + 1, 0);
		world.setBlock(i + 11, j + 2, k + 2, 0);
		world.setBlock(i + 11, j + 2, k + 3, 0);
		world.setBlock(i + 11, j + 2, k + 4, 0);
		world.setBlock(i + 11, j + 2, k + 5, 0);
		world.setBlock(i + 11, j + 2, k + 6, 0);
		world.setBlock(i + 11, j + 2, k + 7, 0);
		world.setBlock(i + 11, j + 2, k + 8, 0);
		world.setBlock(i + 11, j + 2, k + 9, 0);
		world.setBlock(i + 11, j + 2, k + 10, 0);
		world.setBlock(i + 11, j + 2, k + 11, 0);
		world.setBlock(i + 11, j + 2, k + 12, 0);
		world.setBlock(i + 11, j + 2, k + 13, 0);
		world.setBlock(i + 11, j + 2, k + 14, 0);
		world.setBlock(i + 11, j + 2, k + 15, 0);
		world.setBlock(i + 11, j + 2, k + 16, IceikaBlockHelper.snowyBricks.blockID);
		world.setBlock(i + 11, j + 3, k + 0, IceikaBlockHelper.snowyBricks.blockID);
		world.setBlock(i + 11, j + 3, k + 1, 0);
		world.setBlock(i + 11, j + 3, k + 2, 0);
		world.setBlock(i + 11, j + 3, k + 3, 0);
		world.setBlock(i + 11, j + 3, k + 4, 0);
		world.setBlock(i + 11, j + 3, k + 5, 0);
		world.setBlock(i + 11, j + 3, k + 6, 0);
		world.setBlock(i + 11, j + 3, k + 7, 0);
		world.setBlock(i + 11, j + 3, k + 8, 0);
		world.setBlock(i + 11, j + 3, k + 9, 0);
		world.setBlock(i + 11, j + 3, k + 10, 0);
		world.setBlock(i + 11, j + 3, k + 11, 0);
		world.setBlock(i + 11, j + 3, k + 12, 0);
		world.setBlock(i + 11, j + 3, k + 13, 0);
		world.setBlock(i + 11, j + 3, k + 14, 0);
		world.setBlock(i + 11, j + 3, k + 15, 0);
		world.setBlock(i + 11, j + 3, k + 16, IceikaBlockHelper.snowyBricks.blockID);
		world.setBlock(i + 11, j + 4, k + 1, IceikaBlockHelper.snowyBricks.blockID);
		world.setBlock(i + 11, j + 4, k + 2, IceikaBlockHelper.snowyBricks.blockID);
		world.setBlock(i + 11, j + 4, k + 3, IceikaBlockHelper.snowyBricks.blockID);
		world.setBlock(i + 11, j + 4, k + 4, IceikaBlockHelper.snowyBricks.blockID);
		world.setBlock(i + 11, j + 4, k + 5, IceikaBlockHelper.snowyBricks.blockID);
		world.setBlock(i + 11, j + 4, k + 6, IceikaBlockHelper.snowyBricks.blockID);
		world.setBlock(i + 11, j + 4, k + 7, IceikaBlockHelper.snowyBricks.blockID);
		world.setBlock(i + 11, j + 4, k + 8, IceikaBlockHelper.snowyBricks.blockID);
		world.setBlock(i + 11, j + 4, k + 9, IceikaBlockHelper.snowyBricks.blockID);
		world.setBlock(i + 11, j + 4, k + 10, IceikaBlockHelper.snowyBricks.blockID);
		world.setBlock(i + 11, j + 4, k + 11, IceikaBlockHelper.snowyBricks.blockID);
		world.setBlock(i + 11, j + 4, k + 12, IceikaBlockHelper.snowyBricks.blockID);
		world.setBlock(i + 11, j + 4, k + 13, IceikaBlockHelper.snowyBricks.blockID);
		world.setBlock(i + 11, j + 4, k + 14, IceikaBlockHelper.snowyBricks.blockID);
		world.setBlock(i + 11, j + 4, k + 15, IceikaBlockHelper.snowyBricks.blockID);
		world.setBlock(i + 12, j + 0, k + 0, IceikaBlockHelper.snowyBricks.blockID);
		world.setBlock(i + 12, j + 0, k + 1, IceikaBlockHelper.frostedStone.blockID);
		world.setBlock(i + 12, j + 0, k + 2, IceikaBlockHelper.frostedStone.blockID);
		world.setBlock(i + 12, j + 0, k + 3, IceikaBlockHelper.frostedStone.blockID);
		world.setBlock(i + 12, j + 0, k + 4, IceikaBlockHelper.frostedStone.blockID);
		world.setBlock(i + 12, j + 0, k + 5, IceikaBlockHelper.frostedStone.blockID);
		world.setBlock(i + 12, j + 0, k + 6, IceikaBlockHelper.frostedStone.blockID);
		world.setBlock(i + 12, j + 0, k + 7, IceikaBlockHelper.frostedStone.blockID);
		world.setBlock(i + 12, j + 0, k + 8, IceikaBlockHelper.snowyBricks.blockID);
		world.setBlock(i + 12, j + 0, k + 9, IceikaBlockHelper.snowyBricks.blockID);
		world.setBlock(i + 12, j + 0, k + 10, IceikaBlockHelper.snowyBricks.blockID);
		world.setBlock(i + 12, j + 0, k + 11, IceikaBlockHelper.snowyBricks.blockID);
		world.setBlock(i + 12, j + 0, k + 12, IceikaBlockHelper.snowyBricks.blockID);
		world.setBlock(i + 12, j + 0, k + 13, IceikaBlockHelper.snowyBricks.blockID);
		world.setBlock(i + 12, j + 0, k + 14, IceikaBlockHelper.snowyBricks.blockID);
		world.setBlock(i + 12, j + 0, k + 15, IceikaBlockHelper.snowyBricks.blockID);
		world.setBlock(i + 12, j + 0, k + 16, IceikaBlockHelper.snowyBricks.blockID);
		world.setBlock(i + 12, j + 1, k + 0, IceikaBlockHelper.snowyBricks.blockID);
		world.setBlock(i + 12, j + 1, k + 1, 0);
		world.setBlock(i + 12, j + 1, k + 2, 0);
		world.setBlock(i + 12, j + 1, k + 3, 0);
		world.setBlock(i + 12, j + 1, k + 4, IceikaBlockHelper.glacideSpawner.blockID);
		world.setBlock(i + 12, j + 1, k + 5, 0);
		world.setBlock(i + 12, j + 1, k + 6, 0);
		world.setBlock(i + 12, j + 1, k + 7, 0);
		world.setBlock(i + 12, j + 1, k + 8, IceikaBlockHelper.snowyBricks.blockID);
		world.setBlock(i + 12, j + 1, k + 9, IceikaBlockHelper.snowyBricks.blockID);
		world.setBlock(i + 12, j + 1, k + 10, IceikaBlockHelper.snowyBricks.blockID);
		world.setBlock(i + 12, j + 1, k + 11, IceikaBlockHelper.snowyBricks.blockID);
		world.setBlock(i + 12, j + 1, k + 12, IceikaBlockHelper.snowyBricks.blockID);
		world.setBlock(i + 12, j + 1, k + 13, IceikaBlockHelper.snowyBricks.blockID);
		world.setBlock(i + 12, j + 1, k + 14, IceikaBlockHelper.snowyBricks.blockID);
		world.setBlock(i + 12, j + 1, k + 15, IceikaBlockHelper.snowyBricks.blockID);
		world.setBlock(i + 12, j + 1, k + 16, IceikaBlockHelper.snowyBricks.blockID);
		world.setBlock(i + 12, j + 2, k + 0, IceikaBlockHelper.snowyBricks.blockID);
		world.setBlock(i + 12, j + 2, k + 1, 0);
		world.setBlock(i + 12, j + 2, k + 2, 0);
		world.setBlock(i + 12, j + 2, k + 3, 0);
		world.setBlock(i + 12, j + 2, k + 4, 0);
		world.setBlock(i + 12, j + 2, k + 5, 0);
		world.setBlock(i + 12, j + 2, k + 6, 0);
		world.setBlock(i + 12, j + 2, k + 7, 0);
		world.setBlock(i + 12, j + 2, k + 8, IceikaBlockHelper.snowyBricks.blockID);
		world.setBlock(i + 12, j + 2, k + 9, IceikaBlockHelper.snowyBricks.blockID);
		world.setBlock(i + 12, j + 2, k + 10, IceikaBlockHelper.snowyBricks.blockID);
		world.setBlock(i + 12, j + 2, k + 11, IceikaBlockHelper.snowyBricks.blockID);
		world.setBlock(i + 12, j + 2, k + 12, IceikaBlockHelper.snowyBricks.blockID);
		world.setBlock(i + 12, j + 2, k + 13, IceikaBlockHelper.snowyBricks.blockID);
		world.setBlock(i + 12, j + 2, k + 14, IceikaBlockHelper.snowyBricks.blockID);
		world.setBlock(i + 12, j + 2, k + 15, IceikaBlockHelper.snowyBricks.blockID);
		world.setBlock(i + 12, j + 2, k + 16, IceikaBlockHelper.snowyBricks.blockID);
		world.setBlock(i + 12, j + 3, k + 0, IceikaBlockHelper.snowyBricks.blockID);
		world.setBlock(i + 12, j + 3, k + 1, 0);
		world.setBlock(i + 12, j + 3, k + 2, 0);
		world.setBlock(i + 12, j + 3, k + 3, 0);
		world.setBlock(i + 12, j + 3, k + 4, 0);
		world.setBlock(i + 12, j + 3, k + 5, 0);
		world.setBlock(i + 12, j + 3, k + 6, 0);
		world.setBlock(i + 12, j + 3, k + 7, 0);
		world.setBlock(i + 12, j + 3, k + 8, IceikaBlockHelper.snowyBricks.blockID);
		world.setBlock(i + 12, j + 3, k + 9, IceikaBlockHelper.snowyBricks.blockID);
		world.setBlock(i + 12, j + 3, k + 10, IceikaBlockHelper.snowyBricks.blockID);
		world.setBlock(i + 12, j + 3, k + 11, IceikaBlockHelper.snowyBricks.blockID);
		world.setBlock(i + 12, j + 3, k + 12, IceikaBlockHelper.snowyBricks.blockID);
		world.setBlock(i + 12, j + 3, k + 13, IceikaBlockHelper.snowyBricks.blockID);
		world.setBlock(i + 12, j + 3, k + 14, IceikaBlockHelper.snowyBricks.blockID);
		world.setBlock(i + 12, j + 3, k + 15, IceikaBlockHelper.snowyBricks.blockID);
		world.setBlock(i + 12, j + 3, k + 16, IceikaBlockHelper.snowyBricks.blockID);
		world.setBlock(i + 12, j + 4, k + 1, IceikaBlockHelper.snowyBricks.blockID);
		world.setBlock(i + 12, j + 4, k + 2, IceikaBlockHelper.snowyBricks.blockID);
		world.setBlock(i + 12, j + 4, k + 3, IceikaBlockHelper.snowyBricks.blockID);
		world.setBlock(i + 12, j + 4, k + 4, IceikaBlockHelper.snowyBricks.blockID);
		world.setBlock(i + 12, j + 4, k + 5, IceikaBlockHelper.snowyBricks.blockID);
		world.setBlock(i + 12, j + 4, k + 6, IceikaBlockHelper.snowyBricks.blockID);
		world.setBlock(i + 12, j + 4, k + 7, IceikaBlockHelper.snowyBricks.blockID);
		world.setBlock(i + 13, j + 0, k + 0, IceikaBlockHelper.snowyBricks.blockID);
		world.setBlock(i + 13, j + 0, k + 1, IceikaBlockHelper.frostedStone.blockID);
		world.setBlock(i + 13, j + 0, k + 2, IceikaBlockHelper.frostedStone.blockID);
		world.setBlock(i + 13, j + 0, k + 3, IceikaBlockHelper.frostedStone.blockID);
		world.setBlock(i + 13, j + 0, k + 4, IceikaBlockHelper.frostedStone.blockID);
		world.setBlock(i + 13, j + 0, k + 5, IceikaBlockHelper.frostedStone.blockID);
		world.setBlock(i + 13, j + 0, k + 6, IceikaBlockHelper.frostedStone.blockID);
		world.setBlock(i + 13, j + 0, k + 7, IceikaBlockHelper.frostedStone.blockID);
		world.setBlock(i + 13, j + 0, k + 8, IceikaBlockHelper.snowyBricks.blockID);
		world.setBlock(i + 13, j + 1, k + 0, IceikaBlockHelper.snowyBricks.blockID);
		world.setBlock(i + 13, j + 1, k + 1, IceikaBlockHelper.frostedChest.blockID);
		world.setBlock(i + 13, j + 1, k + 2, 0);
		world.setBlock(i + 13, j + 1, k + 3, 0);
		world.setBlock(i + 13, j + 1, k + 4, 0);
		world.setBlock(i + 13, j + 1, k + 5, 0);
		world.setBlock(i + 13, j + 1, k + 6, 0);
		world.setBlock(i + 13, j + 1, k + 7, 0);
		world.setBlock(i + 13, j + 1, k + 8, IceikaBlockHelper.snowyBricks.blockID);
		world.setBlock(i + 13, j + 2, k + 0, IceikaBlockHelper.snowyBricks.blockID);
		world.setBlock(i + 13, j + 2, k + 1, 0);
		world.setBlock(i + 13, j + 2, k + 2, 0);
		world.setBlock(i + 13, j + 2, k + 3, 0);
		world.setBlock(i + 13, j + 2, k + 4, 0);
		world.setBlock(i + 13, j + 2, k + 5, 0);
		world.setBlock(i + 13, j + 2, k + 6, 0);
		world.setBlock(i + 13, j + 2, k + 7, 0);
		world.setBlock(i + 13, j + 2, k + 8, IceikaBlockHelper.snowyBricks.blockID);
		world.setBlock(i + 13, j + 3, k + 0, IceikaBlockHelper.snowyBricks.blockID);
		world.setBlock(i + 13, j + 3, k + 1, 0);
		world.setBlock(i + 13, j + 3, k + 2, 0);
		world.setBlock(i + 13, j + 3, k + 3, 0);
		world.setBlock(i + 13, j + 3, k + 4, 0);
		world.setBlock(i + 13, j + 3, k + 5, 0);
		world.setBlock(i + 13, j + 3, k + 6, 0);
		world.setBlock(i + 13, j + 3, k + 7, 0);
		world.setBlock(i + 13, j + 3, k + 8, IceikaBlockHelper.snowyBricks.blockID);
		world.setBlock(i + 13, j + 4, k + 1, IceikaBlockHelper.snowyBricks.blockID);
		world.setBlock(i + 13, j + 4, k + 2, IceikaBlockHelper.snowyBricks.blockID);
		world.setBlock(i + 13, j + 4, k + 3, IceikaBlockHelper.snowyBricks.blockID);
		world.setBlock(i + 13, j + 4, k + 4, IceikaBlockHelper.snowyBricks.blockID);
		world.setBlock(i + 13, j + 4, k + 5, IceikaBlockHelper.snowyBricks.blockID);
		world.setBlock(i + 13, j + 4, k + 6, IceikaBlockHelper.snowyBricks.blockID);
		world.setBlock(i + 13, j + 4, k + 7, IceikaBlockHelper.snowyBricks.blockID);
		world.setBlock(i + 14, j + 0, k + 0, IceikaBlockHelper.snowyBricks.blockID);
		world.setBlock(i + 14, j + 0, k + 1, IceikaBlockHelper.snowyBricks.blockID);
		world.setBlock(i + 14, j + 0, k + 2, IceikaBlockHelper.snowyBricks.blockID);
		world.setBlock(i + 14, j + 0, k + 3, IceikaBlockHelper.snowyBricks.blockID);
		world.setBlock(i + 14, j + 0, k + 4, IceikaBlockHelper.snowyBricks.blockID);
		world.setBlock(i + 14, j + 0, k + 5, IceikaBlockHelper.snowyBricks.blockID);
		world.setBlock(i + 14, j + 0, k + 6, IceikaBlockHelper.snowyBricks.blockID);
		world.setBlock(i + 14, j + 0, k + 7, IceikaBlockHelper.snowyBricks.blockID);
		world.setBlock(i + 14, j + 0, k + 8, IceikaBlockHelper.snowyBricks.blockID);
		world.setBlock(i + 14, j + 1, k + 0, IceikaBlockHelper.snowyBricks.blockID);
		world.setBlock(i + 14, j + 1, k + 1, IceikaBlockHelper.snowyBricks.blockID);
		world.setBlock(i + 14, j + 1, k + 2, IceikaBlockHelper.snowyBricks.blockID);
		world.setBlock(i + 14, j + 1, k + 3, IceikaBlockHelper.snowyBricks.blockID);
		world.setBlock(i + 14, j + 1, k + 4, IceikaBlockHelper.snowyBricks.blockID);
		world.setBlock(i + 14, j + 1, k + 5, IceikaBlockHelper.snowyBricks.blockID);
		world.setBlock(i + 14, j + 1, k + 6, IceikaBlockHelper.snowyBricks.blockID);
		world.setBlock(i + 14, j + 1, k + 7, IceikaBlockHelper.snowyBricks.blockID);
		world.setBlock(i + 14, j + 1, k + 8, IceikaBlockHelper.snowyBricks.blockID);
		world.setBlock(i + 14, j + 2, k + 0, IceikaBlockHelper.snowyBricks.blockID);
		world.setBlock(i + 14, j + 2, k + 1, IceikaBlockHelper.snowyBricks.blockID);
		world.setBlock(i + 14, j + 2, k + 2, IceikaBlockHelper.snowyBricks.blockID);
		world.setBlock(i + 14, j + 2, k + 3, IceikaBlockHelper.snowyBricks.blockID);
		world.setBlock(i + 14, j + 2, k + 4, IceikaBlockHelper.snowyBricks.blockID);
		world.setBlock(i + 14, j + 2, k + 5, IceikaBlockHelper.snowyBricks.blockID);
		world.setBlock(i + 14, j + 2, k + 6, IceikaBlockHelper.snowyBricks.blockID);
		world.setBlock(i + 14, j + 2, k + 7, IceikaBlockHelper.snowyBricks.blockID);
		world.setBlock(i + 14, j + 2, k + 8, IceikaBlockHelper.snowyBricks.blockID);
		world.setBlock(i + 14, j + 3, k + 0, IceikaBlockHelper.snowyBricks.blockID);
		world.setBlock(i + 14, j + 3, k + 1, IceikaBlockHelper.snowyBricks.blockID);
		world.setBlock(i + 14, j + 3, k + 2, IceikaBlockHelper.snowyBricks.blockID);
		world.setBlock(i + 14, j + 3, k + 4, IceikaBlockHelper.snowyBricks.blockID);
		world.setBlock(i + 14, j + 3, k + 5, IceikaBlockHelper.snowyBricks.blockID);
		world.setBlock(i + 14, j + 3, k + 6, IceikaBlockHelper.snowyBricks.blockID);
		world.setBlock(i + 14, j + 3, k + 7, IceikaBlockHelper.snowyBricks.blockID);
		world.setBlock(i + 14, j + 3, k + 8, IceikaBlockHelper.snowyBricks.blockID);

		TileEntitySkeletonChest var16 = (TileEntitySkeletonChest)world.getBlockTileEntity(i,j,k);

		if (var16 != null)
		{      
			var16.setInventorySlotContents(rand.nextInt(var16.getSizeInventory()), new ItemStack(IceikaItemHelper.snowFlake.itemID, 1, 1));
		}

		//this.generate1(world, i, j, k);
		//this.generate2(world, i, j, k);
		//this.generate3(world, i, j, k);
		//this.generate4(world, i, j, k);

		return true;
	}

	public static void generate1(World world, int i, int j, int k)
	{
		//world.setBlockAndMetadata(i + 13, j + 1, k + 1, DivineRPG.iceikaChest.blockID, 3);
		world.setBlock(i + 13, j + 1, k + 8, IceikaBlockHelper.snowyBricks.blockID);
		world.setBlock(i + 13, j + 2, k + 0, IceikaBlockHelper.snowyBricks.blockID);
		world.setBlock(i + 13, j + 2, k + 8, IceikaBlockHelper.snowyBricks.blockID);
		world.setBlock(i + 13, j + 3, k + 0, IceikaBlockHelper.snowyBricks.blockID);
		world.setBlock(i + 13, j + 3, k + 8, IceikaBlockHelper.snowyBricks.blockID);
		world.setBlock(i + 13, j + 4, k + 1, IceikaBlockHelper.snowyBricks.blockID);
		world.setBlock(i + 13, j + 4, k + 2, IceikaBlockHelper.snowyBricks.blockID);
		world.setBlock(i + 13, j + 4, k + 3, IceikaBlockHelper.snowyBricks.blockID);
		world.setBlock(i + 13, j + 4, k + 4, IceikaBlockHelper.snowyBricks.blockID);
		world.setBlock(i + 13, j + 4, k + 5, IceikaBlockHelper.snowyBricks.blockID);
		world.setBlock(i + 13, j + 4, k + 6, IceikaBlockHelper.snowyBricks.blockID);
		world.setBlock(i + 13, j + 4, k + 7, IceikaBlockHelper.snowyBricks.blockID);
		world.setBlock(i + 14, j + 0, k + 0, IceikaBlockHelper.snowyBricks.blockID);
		world.setBlock(i + 14, j + 0, k + 1, IceikaBlockHelper.snowyBricks.blockID);
		world.setBlock(i + 14, j + 0, k + 2, IceikaBlockHelper.snowyBricks.blockID);
		world.setBlock(i + 14, j + 0, k + 3, IceikaBlockHelper.snowyBricks.blockID);
		world.setBlock(i + 14, j + 0, k + 4, IceikaBlockHelper.snowyBricks.blockID);
		world.setBlock(i + 14, j + 0, k + 5, IceikaBlockHelper.snowyBricks.blockID);
		world.setBlock(i + 14, j + 0, k + 6, IceikaBlockHelper.snowyBricks.blockID);
		world.setBlock(i + 14, j + 0, k + 7, IceikaBlockHelper.snowyBricks.blockID);
		world.setBlock(i + 14, j + 0, k + 8, IceikaBlockHelper.snowyBricks.blockID);
		world.setBlock(i + 14, j + 1, k + 0, IceikaBlockHelper.snowyBricks.blockID);
		world.setBlock(i + 14, j + 1, k + 1, IceikaBlockHelper.snowyBricks.blockID);
		world.setBlock(i + 14, j + 1, k + 2, IceikaBlockHelper.snowyBricks.blockID);
		world.setBlock(i + 14, j + 1, k + 3, IceikaBlockHelper.snowyBricks.blockID);
		world.setBlock(i + 14, j + 1, k + 4, IceikaBlockHelper.snowyBricks.blockID);
		world.setBlock(i + 14, j + 1, k + 5, IceikaBlockHelper.snowyBricks.blockID);
		world.setBlock(i + 14, j + 1, k + 6, IceikaBlockHelper.snowyBricks.blockID);
		world.setBlock(i + 14, j + 1, k + 7, IceikaBlockHelper.snowyBricks.blockID);
		world.setBlock(i + 14, j + 1, k + 8, IceikaBlockHelper.snowyBricks.blockID);
		world.setBlock(i + 14, j + 2, k + 0, IceikaBlockHelper.snowyBricks.blockID);
		world.setBlock(i + 14, j + 2, k + 1, IceikaBlockHelper.snowyBricks.blockID);
		world.setBlock(i + 14, j + 2, k + 2, IceikaBlockHelper.snowyBricks.blockID);
		world.setBlock(i + 14, j + 2, k + 3, IceikaBlockHelper.snowyBricks.blockID);
		world.setBlock(i + 14, j + 2, k + 4, IceikaBlockHelper.snowyBricks.blockID);
		world.setBlock(i + 14, j + 2, k + 5, IceikaBlockHelper.snowyBricks.blockID);
		world.setBlock(i + 14, j + 2, k + 6, IceikaBlockHelper.snowyBricks.blockID);
		world.setBlock(i + 14, j + 2, k + 7, IceikaBlockHelper.snowyBricks.blockID);
		world.setBlock(i + 14, j + 2, k + 8, IceikaBlockHelper.snowyBricks.blockID);
		world.setBlock(i + 14, j + 3, k + 0, IceikaBlockHelper.snowyBricks.blockID);
		world.setBlock(i + 14, j + 3, k + 1, IceikaBlockHelper.snowyBricks.blockID);
		world.setBlock(i + 14, j + 3, k + 2, IceikaBlockHelper.snowyBricks.blockID);
		world.setBlock(i + 14, j + 3, k + 3, IceikaBlockHelper.snowyBricks.blockID);
		world.setBlock(i + 14, j + 3, k + 4, IceikaBlockHelper.snowyBricks.blockID);
		world.setBlock(i + 14, j + 3, k + 5, IceikaBlockHelper.snowyBricks.blockID);
		world.setBlock(i + 14, j + 3, k + 6, IceikaBlockHelper.snowyBricks.blockID);
		world.setBlock(i + 14, j + 3, k + 7, IceikaBlockHelper.snowyBricks.blockID);
		world.setBlock(i + 14, j + 3, k + 8, IceikaBlockHelper.snowyBricks.blockID);

	}

	public static void generate2(World world, int i, int j, int k)
	{
		world.setBlock(i + 9, j + 0, k + 5, IceikaBlockHelper.frostedStone.blockID);
		world.setBlock(i + 9, j + 0, k + 6, IceikaBlockHelper.frostedStone.blockID);
		world.setBlock(i + 9, j + 0, k + 7, IceikaBlockHelper.frostedStone.blockID);
		world.setBlock(i + 9, j + 0, k + 8, IceikaBlockHelper.snowyBricks.blockID);
		world.setBlock(i + 9, j + 0, k + 9, IceikaBlockHelper.snowyBricks.blockID);
		world.setBlock(i + 9, j + 0, k + 10, IceikaBlockHelper.snowyBricks.blockID);
		world.setBlock(i + 9, j + 0, k + 11, IceikaBlockHelper.snowyBricks.blockID);
		world.setBlock(i + 9, j + 0, k + 12, IceikaBlockHelper.snowyBricks.blockID);
		world.setBlock(i + 9, j + 0, k + 13, IceikaBlockHelper.snowyBricks.blockID);
		world.setBlock(i + 9, j + 0, k + 14, IceikaBlockHelper.frostedStone.blockID);
		world.setBlock(i + 9, j + 0, k + 15, IceikaBlockHelper.frostedStone.blockID);
		world.setBlock(i + 9, j + 0, k + 16, IceikaBlockHelper.snowyBricks.blockID);
		world.setBlock(i + 9, j + 1, k + 0, IceikaBlockHelper.snowyBricks.blockID);
		world.setBlock(i + 9, j + 1, k + 4, IceikaBlockHelper.glacideSpawner.blockID);
		world.setBlock(i + 9, j + 1, k + 8, IceikaBlockHelper.snowyBricks.blockID);
		world.setBlock(i + 9, j + 1, k + 9, IceikaBlockHelper.snowyBricks.blockID);
		world.setBlock(i + 9, j + 1, k + 10, IceikaBlockHelper.snowyBricks.blockID);
		world.setBlock(i + 9, j + 1, k + 11, IceikaBlockHelper.snowyBricks.blockID);
		world.setBlock(i + 9, j + 1, k + 12, IceikaBlockHelper.snowyBricks.blockID);
		world.setBlock(i + 9, j + 1, k + 13, IceikaBlockHelper.snowyBricks.blockID);
		world.setBlock(i + 9, j + 1, k + 16, IceikaBlockHelper.snowyBricks.blockID);
		world.setBlock(i + 9, j + 2, k + 0, IceikaBlockHelper.snowyBricks.blockID);
		world.setBlock(i + 9, j + 2, k + 8, IceikaBlockHelper.snowyBricks.blockID);
		world.setBlock(i + 9, j + 2, k + 9, IceikaBlockHelper.snowyBricks.blockID);
		world.setBlock(i + 9, j + 2, k + 10, IceikaBlockHelper.snowyBricks.blockID);
		world.setBlock(i + 9, j + 2, k + 11, IceikaBlockHelper.snowyBricks.blockID);
		world.setBlock(i + 9, j + 2, k + 12, IceikaBlockHelper.snowyBricks.blockID);
		world.setBlock(i + 9, j + 2, k + 13, IceikaBlockHelper.snowyBricks.blockID);
		world.setBlock(i + 9, j + 2, k + 16, IceikaBlockHelper.snowyBricks.blockID);
		world.setBlock(i + 9, j + 3, k + 0, IceikaBlockHelper.snowyBricks.blockID);
		world.setBlock(i + 9, j + 3, k + 8, IceikaBlockHelper.snowyBricks.blockID);
		world.setBlock(i + 9, j + 3, k + 9, IceikaBlockHelper.snowyBricks.blockID);
		world.setBlock(i + 9, j + 3, k + 10, IceikaBlockHelper.snowyBricks.blockID);
		world.setBlock(i + 9, j + 3, k + 11, IceikaBlockHelper.snowyBricks.blockID);
		world.setBlock(i + 9, j + 3, k + 12, IceikaBlockHelper.snowyBricks.blockID);
		world.setBlock(i + 9, j + 3, k + 13, IceikaBlockHelper.snowyBricks.blockID);
		world.setBlock(i + 9, j + 3, k + 16, IceikaBlockHelper.snowyBricks.blockID);
		world.setBlock(i + 9, j + 4, k + 1, IceikaBlockHelper.snowyBricks.blockID);
		world.setBlock(i + 9, j + 4, k + 2, IceikaBlockHelper.snowyBricks.blockID);
		world.setBlock(i + 9, j + 4, k + 3, IceikaBlockHelper.snowyBricks.blockID);
		world.setBlock(i + 9, j + 4, k + 4, IceikaBlockHelper.snowyBricks.blockID);
		world.setBlock(i + 9, j + 4, k + 5, IceikaBlockHelper.snowyBricks.blockID);
		world.setBlock(i + 9, j + 4, k + 6, IceikaBlockHelper.snowyBricks.blockID);
		world.setBlock(i + 9, j + 4, k + 7, IceikaBlockHelper.snowyBricks.blockID);
		world.setBlock(i + 9, j + 4, k + 14, IceikaBlockHelper.snowyBricks.blockID);
		world.setBlock(i + 9, j + 4, k + 15, IceikaBlockHelper.snowyBricks.blockID);
		world.setBlock(i + 10, j + 0, k + 0, IceikaBlockHelper.snowyBricks.blockID);
		world.setBlock(i + 10, j + 0, k + 1, IceikaBlockHelper.frostedStone.blockID);
		world.setBlock(i + 10, j + 0, k + 2, IceikaBlockHelper.frostedStone.blockID);
		world.setBlock(i + 10, j + 0, k + 3, IceikaBlockHelper.frostedStone.blockID);
		world.setBlock(i + 10, j + 0, k + 4, IceikaBlockHelper.frostedStone.blockID);
		world.setBlock(i + 10, j + 0, k + 5, IceikaBlockHelper.frostedStone.blockID);
		world.setBlock(i + 10, j + 0, k + 6, IceikaBlockHelper.frostedStone.blockID);
		world.setBlock(i + 10, j + 0, k + 7, IceikaBlockHelper.frostedStone.blockID);
		world.setBlock(i + 10, j + 0, k + 8, IceikaBlockHelper.frostedStone.blockID);
		world.setBlock(i + 10, j + 0, k + 9, IceikaBlockHelper.frostedStone.blockID);
		world.setBlock(i + 10, j + 0, k + 10, IceikaBlockHelper.frostedStone.blockID);
		world.setBlock(i + 10, j + 0, k + 11, IceikaBlockHelper.frostedStone.blockID);
		world.setBlock(i + 10, j + 0, k + 12, IceikaBlockHelper.frostedStone.blockID);
		world.setBlock(i + 10, j + 0, k + 13, IceikaBlockHelper.frostedStone.blockID);
		world.setBlock(i + 10, j + 0, k + 14, IceikaBlockHelper.frostedStone.blockID);
		world.setBlock(i + 10, j + 0, k + 15, IceikaBlockHelper.frostedStone.blockID);
		world.setBlock(i + 10, j + 0, k + 16, IceikaBlockHelper.snowyBricks.blockID);
		world.setBlock(i + 10, j + 1, k + 0, IceikaBlockHelper.snowyBricks.blockID);
		world.setBlock(i + 10, j + 1, k + 16, IceikaBlockHelper.snowyBricks.blockID);
		world.setBlock(i + 10, j + 2, k + 0, IceikaBlockHelper.snowyBricks.blockID);
		world.setBlock(i + 10, j + 2, k + 16, IceikaBlockHelper.snowyBricks.blockID);
		world.setBlock(i + 10, j + 3, k + 0, IceikaBlockHelper.snowyBricks.blockID);
		world.setBlock(i + 10, j + 3, k + 16, IceikaBlockHelper.snowyBricks.blockID);
		world.setBlock(i + 10, j + 4, k + 1, IceikaBlockHelper.snowyBricks.blockID);
		world.setBlock(i + 10, j + 4, k + 2, IceikaBlockHelper.snowyBricks.blockID);
		world.setBlock(i + 10, j + 4, k + 3, IceikaBlockHelper.snowyBricks.blockID);
		world.setBlock(i + 10, j + 4, k + 4, IceikaBlockHelper.snowyBricks.blockID);
		world.setBlock(i + 10, j + 4, k + 5, IceikaBlockHelper.snowyBricks.blockID);
		world.setBlock(i + 10, j + 4, k + 6, IceikaBlockHelper.snowyBricks.blockID);
		world.setBlock(i + 10, j + 4, k + 7, IceikaBlockHelper.snowyBricks.blockID);
		world.setBlock(i + 10, j + 4, k + 8, IceikaBlockHelper.snowyBricks.blockID);
		world.setBlock(i + 10, j + 4, k + 9, IceikaBlockHelper.snowyBricks.blockID);
		world.setBlock(i + 10, j + 4, k + 10, IceikaBlockHelper.snowyBricks.blockID);
		world.setBlock(i + 10, j + 4, k + 11, IceikaBlockHelper.snowyBricks.blockID);
		world.setBlock(i + 10, j + 4, k + 12, IceikaBlockHelper.snowyBricks.blockID);
		world.setBlock(i + 10, j + 4, k + 13, IceikaBlockHelper.snowyBricks.blockID);
		world.setBlock(i + 10, j + 4, k + 14, IceikaBlockHelper.snowyBricks.blockID);
		world.setBlock(i + 10, j + 4, k + 15, IceikaBlockHelper.snowyBricks.blockID);
		world.setBlock(i + 11, j + 0, k + 0, IceikaBlockHelper.snowyBricks.blockID);
		world.setBlock(i + 11, j + 0, k + 1, IceikaBlockHelper.frostedStone.blockID);
		world.setBlock(i + 11, j + 0, k + 2, IceikaBlockHelper.frostedStone.blockID);
		world.setBlock(i + 11, j + 0, k + 3, IceikaBlockHelper.frostedStone.blockID);
		world.setBlock(i + 11, j + 0, k + 4, IceikaBlockHelper.frostedStone.blockID);
		world.setBlock(i + 11, j + 0, k + 5, IceikaBlockHelper.frostedStone.blockID);
		world.setBlock(i + 11, j + 0, k + 6, IceikaBlockHelper.frostedStone.blockID);
		world.setBlock(i + 11, j + 0, k + 7, IceikaBlockHelper.frostedStone.blockID);
		world.setBlock(i + 11, j + 0, k + 8, IceikaBlockHelper.frostedStone.blockID);
		world.setBlock(i + 11, j + 0, k + 9, IceikaBlockHelper.frostedStone.blockID);
		world.setBlock(i + 11, j + 0, k + 10, IceikaBlockHelper.frostedStone.blockID);
		world.setBlock(i + 11, j + 0, k + 11, IceikaBlockHelper.frostedStone.blockID);
		world.setBlock(i + 11, j + 0, k + 12, IceikaBlockHelper.frostedStone.blockID);
		world.setBlock(i + 11, j + 0, k + 13, IceikaBlockHelper.frostedStone.blockID);
		world.setBlock(i + 11, j + 0, k + 14, IceikaBlockHelper.frostedStone.blockID);
		world.setBlock(i + 11, j + 0, k + 15, IceikaBlockHelper.frostedStone.blockID);
		world.setBlock(i + 11, j + 0, k + 16, IceikaBlockHelper.snowyBricks.blockID);
		world.setBlock(i + 11, j + 1, k + 0, IceikaBlockHelper.snowyBricks.blockID);
		world.setBlock(i + 11, j + 1, k + 16, IceikaBlockHelper.snowyBricks.blockID);
		world.setBlock(i + 11, j + 2, k + 0, IceikaBlockHelper.snowyBricks.blockID);
		world.setBlock(i + 11, j + 2, k + 16, IceikaBlockHelper.snowyBricks.blockID);
		world.setBlock(i + 11, j + 3, k + 0, IceikaBlockHelper.snowyBricks.blockID);
		world.setBlock(i + 11, j + 3, k + 16, IceikaBlockHelper.snowyBricks.blockID);
		world.setBlock(i + 11, j + 4, k + 1, IceikaBlockHelper.snowyBricks.blockID);
		world.setBlock(i + 11, j + 4, k + 2, IceikaBlockHelper.snowyBricks.blockID);
		world.setBlock(i + 11, j + 4, k + 3, IceikaBlockHelper.snowyBricks.blockID);
		world.setBlock(i + 11, j + 4, k + 4, IceikaBlockHelper.snowyBricks.blockID);
		world.setBlock(i + 11, j + 4, k + 5, IceikaBlockHelper.snowyBricks.blockID);
		world.setBlock(i + 11, j + 4, k + 6, IceikaBlockHelper.snowyBricks.blockID);
		world.setBlock(i + 11, j + 4, k + 7, IceikaBlockHelper.snowyBricks.blockID);
		world.setBlock(i + 11, j + 4, k + 8, IceikaBlockHelper.snowyBricks.blockID);
		world.setBlock(i + 11, j + 4, k + 9, IceikaBlockHelper.snowyBricks.blockID);
		world.setBlock(i + 11, j + 4, k + 10, IceikaBlockHelper.snowyBricks.blockID);
		world.setBlock(i + 11, j + 4, k + 11, IceikaBlockHelper.snowyBricks.blockID);
		world.setBlock(i + 11, j + 4, k + 12, IceikaBlockHelper.snowyBricks.blockID);
		world.setBlock(i + 11, j + 4, k + 13, IceikaBlockHelper.snowyBricks.blockID);
		world.setBlock(i + 11, j + 4, k + 14, IceikaBlockHelper.snowyBricks.blockID);
		world.setBlock(i + 11, j + 4, k + 15, IceikaBlockHelper.snowyBricks.blockID);
		world.setBlock(i + 12, j + 0, k + 0, IceikaBlockHelper.snowyBricks.blockID);
		world.setBlock(i + 12, j + 0, k + 1, IceikaBlockHelper.frostedStone.blockID);
		world.setBlock(i + 12, j + 0, k + 2, IceikaBlockHelper.frostedStone.blockID);
		world.setBlock(i + 12, j + 0, k + 3, IceikaBlockHelper.frostedStone.blockID);
		world.setBlock(i + 12, j + 0, k + 4, IceikaBlockHelper.frostedStone.blockID);
		world.setBlock(i + 12, j + 0, k + 5, IceikaBlockHelper.frostedStone.blockID);
		world.setBlock(i + 12, j + 0, k + 6, IceikaBlockHelper.frostedStone.blockID);
		world.setBlock(i + 12, j + 0, k + 7, IceikaBlockHelper.frostedStone.blockID);
		world.setBlock(i + 12, j + 0, k + 8, IceikaBlockHelper.snowyBricks.blockID);
		world.setBlock(i + 12, j + 0, k + 9, IceikaBlockHelper.snowyBricks.blockID);
		world.setBlock(i + 12, j + 0, k + 10, IceikaBlockHelper.snowyBricks.blockID);
		world.setBlock(i + 12, j + 0, k + 11, IceikaBlockHelper.snowyBricks.blockID);
		world.setBlock(i + 12, j + 0, k + 12, IceikaBlockHelper.snowyBricks.blockID);
		world.setBlock(i + 12, j + 0, k + 13, IceikaBlockHelper.snowyBricks.blockID);
		world.setBlock(i + 12, j + 0, k + 14, IceikaBlockHelper.snowyBricks.blockID);
		world.setBlock(i + 12, j + 0, k + 15, IceikaBlockHelper.snowyBricks.blockID);
		world.setBlock(i + 12, j + 0, k + 16, IceikaBlockHelper.snowyBricks.blockID);
		world.setBlock(i + 12, j + 1, k + 0, IceikaBlockHelper.snowyBricks.blockID);
		world.setBlock(i + 12, j + 1, k + 4, IceikaBlockHelper.glacideSpawner.blockID);
		world.setBlock(i + 12, j + 1, k + 8, IceikaBlockHelper.snowyBricks.blockID);
		world.setBlock(i + 12, j + 1, k + 9, IceikaBlockHelper.snowyBricks.blockID);
		world.setBlock(i + 12, j + 1, k + 10, IceikaBlockHelper.snowyBricks.blockID);
		world.setBlock(i + 12, j + 1, k + 11, IceikaBlockHelper.snowyBricks.blockID);
		world.setBlock(i + 12, j + 1, k + 12, IceikaBlockHelper.snowyBricks.blockID);
		world.setBlock(i + 12, j + 1, k + 13, IceikaBlockHelper.snowyBricks.blockID);
		world.setBlock(i + 12, j + 1, k + 14, IceikaBlockHelper.snowyBricks.blockID);
		world.setBlock(i + 12, j + 1, k + 15, IceikaBlockHelper.snowyBricks.blockID);
		world.setBlock(i + 12, j + 1, k + 16, IceikaBlockHelper.snowyBricks.blockID);
		world.setBlock(i + 12, j + 2, k + 0, IceikaBlockHelper.snowyBricks.blockID);
		world.setBlock(i + 12, j + 2, k + 8, IceikaBlockHelper.snowyBricks.blockID);
		world.setBlock(i + 12, j + 2, k + 9, IceikaBlockHelper.snowyBricks.blockID);
		world.setBlock(i + 12, j + 2, k + 10, IceikaBlockHelper.snowyBricks.blockID);
		world.setBlock(i + 12, j + 2, k + 11, IceikaBlockHelper.snowyBricks.blockID);
		world.setBlock(i + 12, j + 2, k + 12, IceikaBlockHelper.snowyBricks.blockID);
		world.setBlock(i + 12, j + 2, k + 13, IceikaBlockHelper.snowyBricks.blockID);
		world.setBlock(i + 12, j + 2, k + 14, IceikaBlockHelper.snowyBricks.blockID);
		world.setBlock(i + 12, j + 2, k + 15, IceikaBlockHelper.snowyBricks.blockID);
		world.setBlock(i + 12, j + 2, k + 16, IceikaBlockHelper.snowyBricks.blockID);
		world.setBlock(i + 12, j + 3, k + 0, IceikaBlockHelper.snowyBricks.blockID);
		world.setBlock(i + 12, j + 3, k + 8, IceikaBlockHelper.snowyBricks.blockID);
		world.setBlock(i + 12, j + 3, k + 9, IceikaBlockHelper.snowyBricks.blockID);
		world.setBlock(i + 12, j + 3, k + 10, IceikaBlockHelper.snowyBricks.blockID);
		world.setBlock(i + 12, j + 3, k + 11, IceikaBlockHelper.snowyBricks.blockID);
		world.setBlock(i + 12, j + 3, k + 12, IceikaBlockHelper.snowyBricks.blockID);
		world.setBlock(i + 12, j + 3, k + 13, IceikaBlockHelper.snowyBricks.blockID);
		world.setBlock(i + 12, j + 3, k + 14, IceikaBlockHelper.snowyBricks.blockID);
		world.setBlock(i + 12, j + 3, k + 15, IceikaBlockHelper.snowyBricks.blockID);
		world.setBlock(i + 12, j + 3, k + 16, IceikaBlockHelper.snowyBricks.blockID);
		world.setBlock(i + 12, j + 4, k + 1, IceikaBlockHelper.snowyBricks.blockID);
		world.setBlock(i + 12, j + 4, k + 2, IceikaBlockHelper.snowyBricks.blockID);
		world.setBlock(i + 12, j + 4, k + 3, IceikaBlockHelper.snowyBricks.blockID);
		world.setBlock(i + 12, j + 4, k + 4, IceikaBlockHelper.snowyBricks.blockID);
		world.setBlock(i + 12, j + 4, k + 5, IceikaBlockHelper.snowyBricks.blockID);
		world.setBlock(i + 12, j + 4, k + 6, IceikaBlockHelper.snowyBricks.blockID);
		world.setBlock(i + 12, j + 4, k + 7, IceikaBlockHelper.snowyBricks.blockID);
		world.setBlock(i + 13, j + 0, k + 0, IceikaBlockHelper.snowyBricks.blockID);
		world.setBlock(i + 13, j + 0, k + 1, IceikaBlockHelper.frostedStone.blockID);
		world.setBlock(i + 13, j + 0, k + 2, IceikaBlockHelper.frostedStone.blockID);
		world.setBlock(i + 13, j + 0, k + 3, IceikaBlockHelper.frostedStone.blockID);
		world.setBlock(i + 13, j + 0, k + 4, IceikaBlockHelper.frostedStone.blockID);
		world.setBlock(i + 13, j + 0, k + 5, IceikaBlockHelper.frostedStone.blockID);
		world.setBlock(i + 13, j + 0, k + 6, IceikaBlockHelper.frostedStone.blockID);
		world.setBlock(i + 13, j + 0, k + 7, IceikaBlockHelper.frostedStone.blockID);
		world.setBlock(i + 13, j + 0, k + 8, IceikaBlockHelper.snowyBricks.blockID);
		world.setBlock(i + 13, j + 1, k + 0, IceikaBlockHelper.snowyBricks.blockID);
	}

	public static void generate3(World world, int i, int j, int k)
	{
		world.setBlock(i + 3, j + 4, k + 12, IceikaBlockHelper.snowyBricks.blockID);
		world.setBlock(i + 3, j + 4, k + 13, IceikaBlockHelper.snowyBricks.blockID);
		world.setBlock(i + 3, j + 4, k + 14, IceikaBlockHelper.snowyBricks.blockID);
		world.setBlock(i + 3, j + 4, k + 15, IceikaBlockHelper.snowyBricks.blockID);
		world.setBlock(i + 3, j + 4, k + 16, IceikaBlockHelper.snowyBricks.blockID);
		world.setBlock(i + 3, j + 4, k + 17, IceikaBlockHelper.snowyBricks.blockID);
		world.setBlock(i + 3, j + 4, k + 20, IceikaBlockHelper.snowyBricks.blockID);
		world.setBlock(i + 3, j + 4, k + 21, IceikaBlockHelper.snowyBricks.blockID);
		world.setBlock(i + 4, j + 0, k + 11, IceikaBlockHelper.snowyBricks.blockID);
		world.setBlock(i + 4, j + 0, k + 12, IceikaBlockHelper.frostedStone.blockID);
		world.setBlock(i + 4, j + 0, k + 13, IceikaBlockHelper.frostedStone.blockID);
		world.setBlock(i + 4, j + 0, k + 14, IceikaBlockHelper.frostedStone.blockID);
		world.setBlock(i + 4, j + 0, k + 15, IceikaBlockHelper.frostedStone.blockID);
		world.setBlock(i + 4, j + 0, k + 16, IceikaBlockHelper.frostedStone.blockID);
		world.setBlock(i + 4, j + 0, k + 17, IceikaBlockHelper.frostedStone.blockID);
		world.setBlock(i + 4, j + 0, k + 18, IceikaBlockHelper.snowyBricks.blockID);
		world.setBlock(i + 4, j + 0, k + 19, IceikaBlockHelper.snowyBricks.blockID);
		world.setBlock(i + 4, j + 0, k + 20, IceikaBlockHelper.frostedStone.blockID);
		world.setBlock(i + 4, j + 0, k + 21, IceikaBlockHelper.frostedStone.blockID);
		world.setBlock(i + 4, j + 0, k + 22, IceikaBlockHelper.snowyBricks.blockID);
		world.setBlock(i + 4, j + 0, k + 23, IceikaBlockHelper.snowyBricks.blockID);
		world.setBlock(i + 4, j + 0, k + 24, IceikaBlockHelper.snowyBricks.blockID);
		world.setBlock(i + 4, j + 0, k + 25, IceikaBlockHelper.snowyBricks.blockID);
		world.setBlock(i + 4, j + 1, k + 11, IceikaBlockHelper.snowyBricks.blockID);
		world.setBlock(i + 4, j + 1, k + 14, IceikaBlockHelper.glacideSpawner.blockID);
		world.setBlock(i + 4, j + 1, k + 18, IceikaBlockHelper.snowyBricks.blockID);
		world.setBlock(i + 4, j + 1, k + 19, IceikaBlockHelper.snowyBricks.blockID);
		world.setBlock(i + 4, j + 1, k + 22, IceikaBlockHelper.snowyBricks.blockID);
		world.setBlock(i + 4, j + 1, k + 23, IceikaBlockHelper.snowyBricks.blockID);
		world.setBlock(i + 4, j + 1, k + 24, IceikaBlockHelper.snowyBricks.blockID);
		world.setBlock(i + 4, j + 1, k + 25, IceikaBlockHelper.snowyBricks.blockID);
		world.setBlock(i + 4, j + 2, k + 11, IceikaBlockHelper.snowyBricks.blockID);
		world.setBlock(i + 4, j + 2, k + 18, IceikaBlockHelper.snowyBricks.blockID);
		world.setBlock(i + 4, j + 2, k + 19, IceikaBlockHelper.snowyBricks.blockID);
		world.setBlock(i + 4, j + 2, k + 22, IceikaBlockHelper.snowyBricks.blockID);
		world.setBlock(i + 4, j + 2, k + 23, IceikaBlockHelper.snowyBricks.blockID);
		world.setBlock(i + 4, j + 2, k + 24, IceikaBlockHelper.snowyBricks.blockID);
		world.setBlock(i + 4, j + 2, k + 25, IceikaBlockHelper.snowyBricks.blockID);
		world.setBlock(i + 4, j + 3, k + 11, IceikaBlockHelper.snowyBricks.blockID);
		world.setBlock(i + 4, j + 3, k + 18, IceikaBlockHelper.snowyBricks.blockID);
		world.setBlock(i + 4, j + 3, k + 19, IceikaBlockHelper.snowyBricks.blockID);
		world.setBlock(i + 4, j + 3, k + 22, IceikaBlockHelper.snowyBricks.blockID);
		world.setBlock(i + 4, j + 3, k + 23, IceikaBlockHelper.snowyBricks.blockID);
		world.setBlock(i + 4, j + 3, k + 24, IceikaBlockHelper.snowyBricks.blockID);
		world.setBlock(i + 4, j + 3, k + 25, IceikaBlockHelper.snowyBricks.blockID);
		world.setBlock(i + 4, j + 4, k + 12, IceikaBlockHelper.snowyBricks.blockID);
		world.setBlock(i + 4, j + 4, k + 13, IceikaBlockHelper.snowyBricks.blockID);
		world.setBlock(i + 4, j + 4, k + 14, IceikaBlockHelper.snowyBricks.blockID);
		world.setBlock(i + 4, j + 4, k + 15, IceikaBlockHelper.snowyBricks.blockID);
		world.setBlock(i + 4, j + 4, k + 16, IceikaBlockHelper.snowyBricks.blockID);
		world.setBlock(i + 4, j + 4, k + 17, IceikaBlockHelper.snowyBricks.blockID);
		world.setBlock(i + 4, j + 4, k + 20, IceikaBlockHelper.snowyBricks.blockID);
		world.setBlock(i + 4, j + 4, k + 21, IceikaBlockHelper.snowyBricks.blockID);
		world.setBlock(i + 5, j + 0, k + 11, IceikaBlockHelper.snowyBricks.blockID);
		world.setBlock(i + 5, j + 0, k + 12, IceikaBlockHelper.frostedStone.blockID);
		world.setBlock(i + 5, j + 0, k + 13, IceikaBlockHelper.frostedStone.blockID);
		world.setBlock(i + 5, j + 0, k + 14, IceikaBlockHelper.frostedStone.blockID);
		world.setBlock(i + 5, j + 0, k + 15, IceikaBlockHelper.frostedStone.blockID);
		world.setBlock(i + 5, j + 0, k + 16, IceikaBlockHelper.frostedStone.blockID);
		world.setBlock(i + 5, j + 0, k + 17, IceikaBlockHelper.frostedStone.blockID);
		world.setBlock(i + 5, j + 0, k + 18, IceikaBlockHelper.snowyBricks.blockID);
		world.setBlock(i + 5, j + 0, k + 19, IceikaBlockHelper.snowyBricks.blockID);
		world.setBlock(i + 5, j + 0, k + 20, IceikaBlockHelper.frostedStone.blockID);
		world.setBlock(i + 5, j + 0, k + 21, IceikaBlockHelper.frostedStone.blockID);
		world.setBlock(i + 5, j + 0, k + 22, IceikaBlockHelper.frostedStone.blockID);
		world.setBlock(i + 5, j + 0, k + 23, IceikaBlockHelper.frostedStone.blockID);
		world.setBlock(i + 5, j + 0, k + 24, IceikaBlockHelper.frostedStone.blockID);
		world.setBlock(i + 5, j + 0, k + 25, IceikaBlockHelper.frostedStone.blockID);
		world.setBlock(i + 5, j + 1, k + 11, IceikaBlockHelper.snowyBricks.blockID);
		world.setBlock(i + 5, j + 1, k + 18, IceikaBlockHelper.snowyBricks.blockID);
		world.setBlock(i + 5, j + 1, k + 19, IceikaBlockHelper.snowyBricks.blockID);
		world.setBlock(i + 5, j + 2, k + 11, IceikaBlockHelper.snowyBricks.blockID);
		world.setBlock(i + 5, j + 2, k + 18, IceikaBlockHelper.snowyBricks.blockID);
		world.setBlock(i + 5, j + 2, k + 19, IceikaBlockHelper.snowyBricks.blockID);
		world.setBlock(i + 5, j + 3, k + 11, IceikaBlockHelper.snowyBricks.blockID);
		world.setBlock(i + 5, j + 3, k + 18, IceikaBlockHelper.snowyBricks.blockID);
		world.setBlock(i + 5, j + 3, k + 19, IceikaBlockHelper.snowyBricks.blockID);
		world.setBlock(i + 5, j + 4, k + 12, IceikaBlockHelper.snowyBricks.blockID);
		world.setBlock(i + 5, j + 4, k + 13, IceikaBlockHelper.snowyBricks.blockID);
		world.setBlock(i + 5, j + 4, k + 14, IceikaBlockHelper.snowyBricks.blockID);
		world.setBlock(i + 5, j + 4, k + 15, IceikaBlockHelper.snowyBricks.blockID);
		world.setBlock(i + 5, j + 4, k + 16, IceikaBlockHelper.snowyBricks.blockID);
		world.setBlock(i + 5, j + 4, k + 17, IceikaBlockHelper.snowyBricks.blockID);
		world.setBlock(i + 5, j + 4, k + 20, IceikaBlockHelper.snowyBricks.blockID);
		world.setBlock(i + 5, j + 4, k + 21, IceikaBlockHelper.snowyBricks.blockID);
		world.setBlock(i + 5, j + 4, k + 22, IceikaBlockHelper.snowyBricks.blockID);
		world.setBlock(i + 5, j + 4, k + 23, IceikaBlockHelper.snowyBricks.blockID);
		world.setBlock(i + 5, j + 4, k + 24, IceikaBlockHelper.snowyBricks.blockID);
		world.setBlock(i + 5, j + 4, k + 25, IceikaBlockHelper.snowyBricks.blockID);
		world.setBlock(i + 6, j + 0, k + 11, IceikaBlockHelper.snowyBricks.blockID);
		world.setBlock(i + 6, j + 0, k + 12, IceikaBlockHelper.frostedStone.blockID);
		world.setBlock(i + 6, j + 0, k + 13, IceikaBlockHelper.frostedStone.blockID);
		world.setBlock(i + 6, j + 0, k + 14, IceikaBlockHelper.frostedStone.blockID);
		world.setBlock(i + 6, j + 0, k + 15, IceikaBlockHelper.frostedStone.blockID);
		world.setBlock(i + 6, j + 0, k + 16, IceikaBlockHelper.frostedStone.blockID);
		world.setBlock(i + 6, j + 0, k + 17, IceikaBlockHelper.frostedStone.blockID);
		world.setBlock(i + 6, j + 0, k + 18, IceikaBlockHelper.snowyBricks.blockID);
		world.setBlock(i + 6, j + 0, k + 19, IceikaBlockHelper.snowyBricks.blockID);
		world.setBlock(i + 6, j + 0, k + 20, IceikaBlockHelper.frostedStone.blockID);
		world.setBlock(i + 6, j + 0, k + 21, IceikaBlockHelper.frostedStone.blockID);
		world.setBlock(i + 6, j + 0, k + 22, IceikaBlockHelper.frostedStone.blockID);
		world.setBlock(i + 6, j + 0, k + 23, IceikaBlockHelper.frostedStone.blockID);
		world.setBlock(i + 6, j + 0, k + 24, IceikaBlockHelper.frostedStone.blockID);
		world.setBlock(i + 6, j + 0, k + 25, IceikaBlockHelper.frostedStone.blockID);
		world.setBlock(i + 6, j + 1, k + 11, IceikaBlockHelper.snowyBricks.blockID);
		world.setBlock(i + 6, j + 1, k + 18, IceikaBlockHelper.snowyBricks.blockID);
		world.setBlock(i + 6, j + 1, k + 19, IceikaBlockHelper.snowyBricks.blockID);
		world.setBlock(i + 6, j + 2, k + 11, IceikaBlockHelper.snowyBricks.blockID);
		world.setBlock(i + 6, j + 2, k + 18, IceikaBlockHelper.snowyBricks.blockID);
		world.setBlock(i + 6, j + 2, k + 19, IceikaBlockHelper.snowyBricks.blockID);
		world.setBlock(i + 6, j + 3, k + 11, IceikaBlockHelper.snowyBricks.blockID);
		world.setBlock(i + 6, j + 3, k + 18, IceikaBlockHelper.snowyBricks.blockID);
		world.setBlock(i + 6, j + 3, k + 19, IceikaBlockHelper.snowyBricks.blockID);
		world.setBlock(i + 6, j + 4, k + 12, IceikaBlockHelper.snowyBricks.blockID);
		world.setBlock(i + 6, j + 4, k + 13, IceikaBlockHelper.snowyBricks.blockID);
		world.setBlock(i + 6, j + 4, k + 14, IceikaBlockHelper.snowyBricks.blockID);
		world.setBlock(i + 6, j + 4, k + 15, IceikaBlockHelper.snowyBricks.blockID);
		world.setBlock(i + 6, j + 4, k + 16, IceikaBlockHelper.snowyBricks.blockID);
		world.setBlock(i + 6, j + 4, k + 17, IceikaBlockHelper.snowyBricks.blockID);
		world.setBlock(i + 6, j + 4, k + 20, IceikaBlockHelper.snowyBricks.blockID);
		world.setBlock(i + 6, j + 4, k + 21, IceikaBlockHelper.snowyBricks.blockID);
		world.setBlock(i + 6, j + 4, k + 22, IceikaBlockHelper.snowyBricks.blockID);
		world.setBlock(i + 6, j + 4, k + 23, IceikaBlockHelper.snowyBricks.blockID);
		world.setBlock(i + 6, j + 4, k + 24, IceikaBlockHelper.snowyBricks.blockID);
		world.setBlock(i + 6, j + 4, k + 25, IceikaBlockHelper.snowyBricks.blockID);
		world.setBlock(i + 7, j + 0, k + 0, IceikaBlockHelper.snowyBricks.blockID);
		world.setBlock(i + 7, j + 0, k + 1, IceikaBlockHelper.snowyBricks.blockID);
		world.setBlock(i + 7, j + 0, k + 2, IceikaBlockHelper.snowyBricks.blockID);
		world.setBlock(i + 7, j + 0, k + 3, IceikaBlockHelper.snowyBricks.blockID);
		world.setBlock(i + 7, j + 0, k + 4, IceikaBlockHelper.snowyBricks.blockID);
		world.setBlock(i + 7, j + 0, k + 5, IceikaBlockHelper.snowyBricks.blockID);
		world.setBlock(i + 7, j + 0, k + 6, IceikaBlockHelper.snowyBricks.blockID);
		world.setBlock(i + 7, j + 0, k + 7, IceikaBlockHelper.snowyBricks.blockID);
		world.setBlock(i + 7, j + 0, k + 8, IceikaBlockHelper.snowyBricks.blockID);
		world.setBlock(i + 7, j + 0, k + 11, IceikaBlockHelper.snowyBricks.blockID);
		world.setBlock(i + 7, j + 0, k + 12, IceikaBlockHelper.snowyBricks.blockID);
		world.setBlock(i + 7, j + 0, k + 13, IceikaBlockHelper.snowyBricks.blockID);
		world.setBlock(i + 7, j + 0, k + 14, IceikaBlockHelper.frostedStone.blockID);
		world.setBlock(i + 7, j + 0, k + 15, IceikaBlockHelper.frostedStone.blockID);
		world.setBlock(i + 7, j + 0, k + 16, IceikaBlockHelper.snowyBricks.blockID);
		world.setBlock(i + 7, j + 0, k + 17, IceikaBlockHelper.snowyBricks.blockID);
		world.setBlock(i + 7, j + 0, k + 18, IceikaBlockHelper.snowyBricks.blockID);
		world.setBlock(i + 7, j + 0, k + 19, IceikaBlockHelper.snowyBricks.blockID);
		world.setBlock(i + 7, j + 0, k + 20, IceikaBlockHelper.snowyBricks.blockID);
		world.setBlock(i + 7, j + 0, k + 21, IceikaBlockHelper.snowyBricks.blockID);
		world.setBlock(i + 7, j + 0, k + 22, IceikaBlockHelper.snowyBricks.blockID);
		world.setBlock(i + 7, j + 0, k + 23, IceikaBlockHelper.snowyBricks.blockID);
		world.setBlock(i + 7, j + 0, k + 24, IceikaBlockHelper.snowyBricks.blockID);
		world.setBlock(i + 7, j + 0, k + 25, IceikaBlockHelper.snowyBricks.blockID);
		world.setBlock(i + 7, j + 1, k + 0, IceikaBlockHelper.snowyBricks.blockID);
		world.setBlock(i + 7, j + 1, k + 1, IceikaBlockHelper.snowyBricks.blockID);
		world.setBlock(i + 7, j + 1, k + 2, IceikaBlockHelper.snowyBricks.blockID);
		world.setBlock(i + 7, j + 1, k + 3, IceikaBlockHelper.snowyBricks.blockID);
		world.setBlock(i + 7, j + 1, k + 4, IceikaBlockHelper.snowyBricks.blockID);
		world.setBlock(i + 7, j + 1, k + 5, IceikaBlockHelper.snowyBricks.blockID);
		world.setBlock(i + 7, j + 1, k + 6, IceikaBlockHelper.snowyBricks.blockID);
		world.setBlock(i + 7, j + 1, k + 7, IceikaBlockHelper.snowyBricks.blockID);
		world.setBlock(i + 7, j + 1, k + 8, IceikaBlockHelper.snowyBricks.blockID);
		world.setBlock(i + 7, j + 1, k + 11, IceikaBlockHelper.snowyBricks.blockID);
		world.setBlock(i + 7, j + 1, k + 12, IceikaBlockHelper.snowyBricks.blockID);
		world.setBlock(i + 7, j + 1, k + 13, IceikaBlockHelper.snowyBricks.blockID);
		world.setBlock(i + 7, j + 1, k + 16, IceikaBlockHelper.snowyBricks.blockID);
		world.setBlock(i + 7, j + 1, k + 17, IceikaBlockHelper.snowyBricks.blockID);
		world.setBlock(i + 7, j + 1, k + 18, IceikaBlockHelper.snowyBricks.blockID);
		world.setBlock(i + 7, j + 1, k + 19, IceikaBlockHelper.snowyBricks.blockID);
		world.setBlock(i + 7, j + 1, k + 20, IceikaBlockHelper.snowyBricks.blockID);
		world.setBlock(i + 7, j + 1, k + 21, IceikaBlockHelper.snowyBricks.blockID);
		world.setBlock(i + 7, j + 1, k + 22, IceikaBlockHelper.snowyBricks.blockID);
		world.setBlock(i + 7, j + 1, k + 23, IceikaBlockHelper.snowyBricks.blockID);
		world.setBlock(i + 7, j + 1, k + 24, IceikaBlockHelper.snowyBricks.blockID);
		world.setBlock(i + 7, j + 1, k + 25, IceikaBlockHelper.snowyBricks.blockID);
		world.setBlock(i + 7, j + 2, k + 0, IceikaBlockHelper.snowyBricks.blockID);
		world.setBlock(i + 7, j + 2, k + 1, IceikaBlockHelper.snowyBricks.blockID);
		world.setBlock(i + 7, j + 2, k + 2, IceikaBlockHelper.snowyBricks.blockID);
		world.setBlock(i + 7, j + 2, k + 3, IceikaBlockHelper.snowyBricks.blockID);
		world.setBlock(i + 7, j + 2, k + 4, IceikaBlockHelper.snowyBricks.blockID);
		world.setBlock(i + 7, j + 2, k + 5, IceikaBlockHelper.snowyBricks.blockID);
		world.setBlock(i + 7, j + 2, k + 6, IceikaBlockHelper.snowyBricks.blockID);
		world.setBlock(i + 7, j + 2, k + 7, IceikaBlockHelper.snowyBricks.blockID);
		world.setBlock(i + 7, j + 2, k + 8, IceikaBlockHelper.snowyBricks.blockID);
		world.setBlock(i + 7, j + 2, k + 11, IceikaBlockHelper.snowyBricks.blockID);
		world.setBlock(i + 7, j + 2, k + 12, IceikaBlockHelper.snowyBricks.blockID);
		world.setBlock(i + 7, j + 2, k + 13, IceikaBlockHelper.snowyBricks.blockID);
