/*
*** MADE BY MITHION'S .SCHEMATIC TO JAVA CONVERTING TOOL v1.6 ***
*/

package xolova.blued00r.divinerpg.generation.vethea.layer4;
import java.util.Random;

import xolova.blued00r.divinerpg.DivineRPG;

import net.minecraft.world.World;
import net.minecraft.world.gen.feature.WorldGenerator;

public class Tree1 extends WorldGenerator
{
	protected int[] GetValidSpawnBlocks() {
		return new int[] {
		};
	}

	public Tree1() { }

	public boolean generate(World world, Random rand, int i, int j, int k) {

		world.setBlock(i + 0, j + 3, k + 8, DivineRPGTwilight.firewoodLeaves.blockID);
		world.setBlock(i + 0, j + 3, k + 9, DivineRPGTwilight.firewoodLeaves.blockID);
		world.setBlock(i + 0, j + 3, k + 10, DivineRPGTwilight.firewoodLeaves.blockID);
		world.setBlock(i + 0, j + 4, k + 8, DivineRPGTwilight.firewoodLeaves.blockID);
		world.setBlock(i + 0, j + 4, k + 9, DivineRPGTwilight.firewoodLeaves.blockID);
		world.setBlock(i + 0, j + 4, k + 10, DivineRPGTwilight.firewoodLeaves.blockID);
		world.setBlock(i + 0, j + 5, k + 8, DivineRPGTwilight.firewoodLeaves.blockID);
		world.setBlock(i + 0, j + 5, k + 9, DivineRPGTwilight.firewoodLeaves.blockID);
		world.setBlock(i + 0, j + 5, k + 10, DivineRPGTwilight.firewoodLeaves.blockID);
		world.setBlock(i + 1, j + 2, k + 7, DivineRPGTwilight.firewoodLeaves.blockID);
		world.setBlock(i + 1, j + 2, k + 8, DivineRPGTwilight.firewoodLeaves.blockID);
		world.setBlock(i + 1, j + 2, k + 9, DivineRPGTwilight.firewoodLeaves.blockID);
		world.setBlock(i + 1, j + 2, k + 10, DivineRPGTwilight.firewoodLeaves.blockID);
		world.setBlock(i + 1, j + 2, k + 11, DivineRPGTwilight.firewoodLeaves.blockID);
		world.setBlock(i + 1, j + 3, k + 7, DivineRPGTwilight.firewoodLeaves.blockID);
		world.setBlock(i + 1, j + 3, k + 8, DivineRPGTwilight.firewoodLeaves.blockID);
		world.setBlock(i + 1, j + 3, k + 9, DivineRPGTwilight.firewoodLeaves.blockID);
		world.setBlock(i + 1, j + 3, k + 10, DivineRPGTwilight.firewoodLeaves.blockID);
		world.setBlock(i + 1, j + 3, k + 11, DivineRPGTwilight.firewoodLeaves.blockID);
		world.setBlock(i + 1, j + 4, k + 7, DivineRPGTwilight.firewoodLeaves.blockID);
		world.setBlock(i + 1, j + 4, k + 8, DivineRPGTwilight.firewoodLeaves.blockID);
		world.setBlock(i + 1, j + 4, k + 9, DivineRPGTwilight.firewoodLeaves.blockID);
		world.setBlock(i + 1, j + 4, k + 10, DivineRPGTwilight.firewoodLeaves.blockID);
		world.setBlock(i + 1, j + 4, k + 11, DivineRPGTwilight.firewoodLeaves.blockID);
		world.setBlock(i + 1, j + 5, k + 7, DivineRPGTwilight.firewoodLeaves.blockID);
		world.setBlock(i + 1, j + 5, k + 8, DivineRPGTwilight.firewoodLeaves.blockID);
		world.setBlock(i + 1, j + 5, k + 9, DivineRPGTwilight.firewoodLeaves.blockID);
		world.setBlock(i + 1, j + 5, k + 10, DivineRPGTwilight.firewoodLeaves.blockID);
		world.setBlock(i + 1, j + 5, k + 11, DivineRPGTwilight.firewoodLeaves.blockID);
		world.setBlock(i + 1, j + 6, k + 7, DivineRPGTwilight.firewoodLeaves.blockID);
		world.setBlock(i + 1, j + 6, k + 8, DivineRPGTwilight.firewoodLeaves.blockID);
		world.setBlock(i + 1, j + 6, k + 9, DivineRPGTwilight.firewoodLeaves.blockID);
		world.setBlock(i + 1, j + 6, k + 10, DivineRPGTwilight.firewoodLeaves.blockID);
		world.setBlock(i + 1, j + 6, k + 11, DivineRPGTwilight.firewoodLeaves.blockID);
		world.setBlock(i + 2, j + 1, k + 8, DivineRPGTwilight.firewoodLeaves.blockID);
		world.setBlock(i + 2, j + 1, k + 9, DivineRPGTwilight.firewoodLeaves.blockID);
		world.setBlock(i + 2, j + 1, k + 10, DivineRPGTwilight.firewoodLeaves.blockID);
		world.setBlock(i + 2, j + 2, k + 7, DivineRPGTwilight.firewoodLeaves.blockID);
		world.setBlock(i + 2, j + 2, k + 8, DivineRPGTwilight.firewoodLeaves.blockID);
		world.setBlock(i + 2, j + 2, k + 9, DivineRPGTwilight.firewoodLeaves.blockID);
		world.setBlock(i + 2, j + 2, k + 10, DivineRPGTwilight.firewoodLeaves.blockID);
		world.setBlock(i + 2, j + 2, k + 11, DivineRPGTwilight.firewoodLeaves.blockID);
		world.setBlock(i + 2, j + 3, k + 6, DivineRPGTwilight.firewoodLeaves.blockID);
		world.setBlock(i + 2, j + 3, k + 7, DivineRPGTwilight.firewoodLeaves.blockID);
		world.setBlock(i + 2, j + 3, k + 8, DivineRPGTwilight.firewoodLeaves.blockID);
		world.setBlock(i + 2, j + 3, k + 9, DivineRPGTwilight.firewoodLeaves.blockID);
		world.setBlock(i + 2, j + 3, k + 10, DivineRPGTwilight.firewoodLeaves.blockID);
		world.setBlock(i + 2, j + 3, k + 11, DivineRPGTwilight.firewoodLeaves.blockID);
		world.setBlock(i + 2, j + 3, k + 12, DivineRPGTwilight.firewoodLeaves.blockID);
		world.setBlock(i + 2, j + 4, k + 6, DivineRPGTwilight.firewoodLeaves.blockID);
		world.setBlock(i + 2, j + 4, k + 7, DivineRPGTwilight.firewoodLeaves.blockID);
		world.setBlock(i + 2, j + 4, k + 8, DivineRPGTwilight.firewoodLeaves.blockID);
		world.setBlock(i + 2, j + 4, k + 9, DivineRPGTwilight.firewoodLeaves.blockID);
		world.setBlock(i + 2, j + 4, k + 10, DivineRPGTwilight.firewoodLeaves.blockID);
		world.setBlock(i + 2, j + 4, k + 11, DivineRPGTwilight.firewoodLeaves.blockID);
		world.setBlock(i + 2, j + 4, k + 12, DivineRPGTwilight.firewoodLeaves.blockID);
		world.setBlock(i + 2, j + 5, k + 6, DivineRPGTwilight.firewoodLeaves.blockID);
		world.setBlock(i + 2, j + 5, k + 7, DivineRPGTwilight.firewoodLeaves.blockID);
		world.setBlock(i + 2, j + 5, k + 8, DivineRPGTwilight.firewoodLeaves.blockID);
		world.setBlock(i + 2, j + 5, k + 9, DivineRPGTwilight.firewoodLeaves.blockID);
		world.setBlock(i + 2, j + 5, k + 10, DivineRPGTwilight.firewoodLeaves.blockID);
		world.setBlock(i + 2, j + 5, k + 11, DivineRPGTwilight.firewoodLeaves.blockID);
		world.setBlock(i + 2, j + 5, k + 12, DivineRPGTwilight.firewoodLeaves.blockID);
		world.setBlock(i + 2, j + 6, k + 7, DivineRPGTwilight.firewoodLeaves.blockID);
		world.setBlock(i + 2, j + 6, k + 8, DivineRPGTwilight.firewoodLeaves.blockID);
		world.setBlock(i + 2, j + 6, k + 9, DivineRPGTwilight.firewoodLeaves.blockID);
		world.setBlock(i + 2, j + 6, k + 10, DivineRPGTwilight.firewoodLeaves.blockID);
		world.setBlock(i + 2, j + 6, k + 11, DivineRPGTwilight.firewoodLeaves.blockID);
		world.setBlock(i + 2, j + 7, k + 8, DivineRPGTwilight.firewoodLeaves.blockID);
		world.setBlock(i + 2, j + 7, k + 9, DivineRPGTwilight.firewoodLeaves.blockID);
		world.setBlock(i + 2, j + 7, k + 10, DivineRPGTwilight.firewoodLeaves.blockID);
		world.setBlock(i + 3, j + 1, k + 8, DivineRPGTwilight.firewoodLeaves.blockID);
		world.setBlock(i + 3, j + 1, k + 9, DivineRPGTwilight.firewoodLeaves.blockID);
		world.setBlock(i + 3, j + 1, k + 10, DivineRPGTwilight.firewoodLeaves.blockID);
		world.setBlock(i + 3, j + 2, k + 7, DivineRPGTwilight.firewoodLeaves.blockID);
		world.setBlock(i + 3, j + 2, k + 8, DivineRPGTwilight.firewoodLeaves.blockID);
		world.setBlock(i + 3, j + 2, k + 9, DivineRPGTwilight.firewoodLeaves.blockID);
		world.setBlock(i + 3, j + 2, k + 10, DivineRPGTwilight.firewoodLeaves.blockID);
		world.setBlock(i + 3, j + 2, k + 11, DivineRPGTwilight.firewoodLeaves.blockID);
		world.setBlock(i + 3, j + 3, k + 6, DivineRPGTwilight.firewoodLeaves.blockID);
		world.setBlock(i + 3, j + 3, k + 7, DivineRPGTwilight.firewoodLeaves.blockID);
		world.setBlock(i + 3, j + 3, k + 8, DivineRPGTwilight.firewoodLeaves.blockID);
		world.setBlock(i + 3, j + 3, k + 9, DivineRPGTwilight.firewoodLeaves.blockID);
		world.setBlock(i + 3, j + 3, k + 10, DivineRPGTwilight.firewoodLeaves.blockID);
		world.setBlock(i + 3, j + 3, k + 11, DivineRPGTwilight.firewoodLeaves.blockID);
		world.setBlock(i + 3, j + 3, k + 12, DivineRPGTwilight.firewoodLeaves.blockID);
		world.setBlock(i + 3, j + 4, k + 6, DivineRPGTwilight.firewoodLeaves.blockID);
		world.setBlock(i + 3, j + 4, k + 7, DivineRPGTwilight.firewoodLeaves.blockID);
		world.setBlock(i + 3, j + 4, k + 8, DivineRPGTwilight.firewoodLeaves.blockID);
		world.setBlock(i + 3, j + 4, k + 10, DivineRPGTwilight.firewoodLeaves.blockID);
		world.setBlock(i + 3, j + 4, k + 11, DivineRPGTwilight.firewoodLeaves.blockID);
		world.setBlock(i + 3, j + 4, k + 12, DivineRPGTwilight.firewoodLeaves.blockID);
		world.setBlock(i + 3, j + 5, k + 6, DivineRPGTwilight.firewoodLeaves.blockID);
		world.setBlock(i + 3, j + 5, k + 7, DivineRPGTwilight.firewoodLeaves.blockID);
		world.setBlock(i + 3, j + 5, k + 8, DivineRPGTwilight.firewoodLeaves.blockID);
		world.setBlock(i + 3, j + 5, k + 10, DivineRPGTwilight.firewoodLeaves.blockID);
		world.setBlock(i + 3, j + 5, k + 11, DivineRPGTwilight.firewoodLeaves.blockID);
		world.setBlock(i + 3, j + 5, k + 12, DivineRPGTwilight.firewoodLeaves.blockID);
		world.setBlock(i + 3, j + 6, k + 7, DivineRPGTwilight.firewoodLeaves.blockID);
		world.setBlock(i + 3, j + 6, k + 8, DivineRPGTwilight.firewoodLeaves.blockID);
		world.setBlock(i + 3, j + 6, k + 10, DivineRPGTwilight.firewoodLeaves.blockID);
		world.setBlock(i + 3, j + 6, k + 11, DivineRPGTwilight.firewoodLeaves.blockID);
		world.setBlock(i + 3, j + 7, k + 8, DivineRPGTwilight.firewoodLeaves.blockID);
		world.setBlock(i + 3, j + 7, k + 9, DivineRPGTwilight.firewoodLeaves.blockID);
		world.setBlock(i + 3, j + 7, k + 10, DivineRPGTwilight.firewoodLeaves.blockID);
		world.setBlock(i + 3, j + 8, k + 8, DivineRPGTwilight.firewood.blockID);
		world.setBlock(i + 3, j + 8, k + 9, DivineRPGTwilight.firewood.blockID);
		world.setBlock(i + 3, j + 9, k + 8, DivineRPGTwilight.firewood.blockID);
		world.setBlock(i + 3, j + 9, k + 9, DivineRPGTwilight.firewood.blockID);
		world.setBlock(i + 3, j + 10, k + 8, DivineRPGTwilight.firewood.blockID);
		world.setBlock(i + 3, j + 10, k + 9, DivineRPGTwilight.firewood.blockID);
		world.setBlock(i + 3, j + 11, k + 8, DivineRPGTwilight.firewood.blockID);
		world.setBlock(i + 3, j + 11, k + 9, DivineRPGTwilight.firewood.blockID);
		world.setBlock(i + 3, j + 12, k + 8, DivineRPGTwilight.firewood.blockID);
		world.setBlock(i + 3, j + 12, k + 9, DivineRPGTwilight.firewood.blockID);
		world.setBlock(i + 4, j + 1, k + 8, DivineRPGTwilight.firewoodLeaves.blockID);
		world.setBlock(i + 4, j + 1, k + 9, DivineRPGTwilight.firewoodLeaves.blockID);
		world.setBlock(i + 4, j + 1, k + 10, DivineRPGTwilight.firewoodLeaves.blockID);
		world.setBlock(i + 4, j + 2, k + 7, DivineRPGTwilight.firewoodLeaves.blockID);
		world.setBlock(i + 4, j + 2, k + 8, DivineRPGTwilight.firewoodLeaves.blockID);
		world.setBlock(i + 4, j + 2, k + 10, DivineRPGTwilight.firewoodLeaves.blockID);
		world.setBlock(i + 4, j + 2, k + 11, DivineRPGTwilight.firewoodLeaves.blockID);
		world.setBlock(i + 4, j + 3, k + 6, DivineRPGTwilight.firewoodLeaves.blockID);
		world.setBlock(i + 4, j + 3, k + 7, DivineRPGTwilight.firewoodLeaves.blockID);
		world.setBlock(i + 4, j + 3, k + 8, DivineRPGTwilight.firewoodLeaves.blockID);
		world.setBlock(i + 4, j + 3, k + 9, DivineRPGTwilight.firewoodLeaves.blockID);
		world.setBlock(i + 4, j + 3, k + 10, DivineRPGTwilight.firewoodLeaves.blockID);
		world.setBlock(i + 4, j + 3, k + 11, DivineRPGTwilight.firewoodLeaves.blockID);
		world.setBlock(i + 4, j + 3, k + 12, DivineRPGTwilight.firewoodLeaves.blockID);
		world.setBlock(i + 4, j + 4, k + 6, DivineRPGTwilight.firewoodLeaves.blockID);
		world.setBlock(i + 4, j + 4, k + 7, DivineRPGTwilight.firewoodLeaves.blockID);
		world.setBlock(i + 4, j + 4, k + 8, DivineRPGTwilight.firewoodLeaves.blockID);
		world.setBlock(i + 4, j + 4, k + 9, DivineRPGTwilight.firewoodLeaves.blockID);
		world.setBlock(i + 4, j + 4, k + 10, DivineRPGTwilight.firewoodLeaves.blockID);
		world.setBlock(i + 4, j + 4, k + 11, DivineRPGTwilight.firewoodLeaves.blockID);
		world.setBlock(i + 4, j + 4, k + 12, DivineRPGTwilight.firewoodLeaves.blockID);
		world.setBlock(i + 4, j + 5, k + 6, DivineRPGTwilight.firewoodLeaves.blockID);
		world.setBlock(i + 4, j + 5, k + 7, DivineRPGTwilight.firewoodLeaves.blockID);
		world.setBlock(i + 4, j + 5, k + 8, DivineRPGTwilight.firewoodLeaves.blockID);
		world.setBlock(i + 4, j + 5, k + 10, DivineRPGTwilight.firewoodLeaves.blockID);
		world.setBlock(i + 4, j + 5, k + 11, DivineRPGTwilight.firewoodLeaves.blockID);
		world.setBlock(i + 4, j + 5, k + 12, DivineRPGTwilight.firewoodLeaves.blockID);
		world.setBlock(i + 4, j + 6, k + 7, DivineRPGTwilight.firewoodLeaves.blockID);
		world.setBlock(i + 4, j + 6, k + 8, DivineRPGTwilight.firewoodLeaves.blockID);
		world.setBlock(i + 4, j + 6, k + 9, DivineRPGTwilight.firewoodLeaves.blockID);
		world.setBlock(i + 4, j + 6, k + 10, DivineRPGTwilight.firewoodLeaves.blockID);
		world.setBlock(i + 4, j + 6, k + 11, DivineRPGTwilight.firewoodLeaves.blockID);
		world.setBlock(i + 4, j + 7, k + 8, DivineRPGTwilight.firewoodLeaves.blockID);
		world.setBlock(i + 4, j + 7, k + 9, DivineRPGTwilight.firewoodLeaves.blockID);
		world.setBlock(i + 4, j + 7, k + 10, DivineRPGTwilight.firewoodLeaves.blockID);
		world.setBlock(i + 4, j + 8, k + 8, DivineRPGTwilight.firewood.blockID);
		world.setBlock(i + 4, j + 8, k + 9, DivineRPGTwilight.firewood.blockID);
		world.setBlock(i + 4, j + 9, k + 8, DivineRPGTwilight.firewood.blockID);
		world.setBlock(i + 4, j + 9, k + 9, DivineRPGTwilight.firewood.blockID);
		world.setBlock(i + 4, j + 10, k + 8, DivineRPGTwilight.firewood.blockID);
		world.setBlock(i + 4, j + 10, k + 9, DivineRPGTwilight.firewood.blockID);
		world.setBlock(i + 4, j + 11, k + 8, DivineRPGTwilight.firewood.blockID);
		world.setBlock(i + 4, j + 11, k + 9, DivineRPGTwilight.firewood.blockID);
		world.setBlock(i + 4, j + 12, k + 8, DivineRPGTwilight.firewood.blockID);
		world.setBlock(i + 4, j + 12, k + 9, DivineRPGTwilight.firewood.blockID);
		world.setBlock(i + 5, j + 2, k + 7, DivineRPGTwilight.firewoodLeaves.blockID);
		world.setBlock(i + 5, j + 2, k + 8, DivineRPGTwilight.firewoodLeaves.blockID);
		world.setBlock(i + 5, j + 2, k + 9, DivineRPGTwilight.firewoodLeaves.blockID);
		world.setBlock(i + 5, j + 2, k + 10, DivineRPGTwilight.firewoodLeaves.blockID);
		world.setBlock(i + 5, j + 2, k + 11, DivineRPGTwilight.firewoodLeaves.blockID);
		world.setBlock(i + 5, j + 3, k + 7, DivineRPGTwilight.firewoodLeaves.blockID);
		world.setBlock(i + 5, j + 3, k + 8, DivineRPGTwilight.firewoodLeaves.blockID);
		world.setBlock(i + 5, j + 3, k + 9, DivineRPGTwilight.firewoodLeaves.blockID);
		world.setBlock(i + 5, j + 3, k + 10, DivineRPGTwilight.firewoodLeaves.blockID);
		world.setBlock(i + 5, j + 3, k + 11, DivineRPGTwilight.firewoodLeaves.blockID);
		world.setBlock(i + 5, j + 4, k + 7, DivineRPGTwilight.firewoodLeaves.blockID);
		world.setBlock(i + 5, j + 4, k + 8, DivineRPGTwilight.firewoodLeaves.blockID);
		world.setBlock(i + 5, j + 4, k + 9, DivineRPGTwilight.firewoodLeaves.blockID);
		world.setBlock(i + 5, j + 4, k + 10, DivineRPGTwilight.firewoodLeaves.blockID);
		world.setBlock(i + 5, j + 4, k + 11, DivineRPGTwilight.firewoodLeaves.blockID);
		world.setBlock(i + 5, j + 5, k + 7, DivineRPGTwilight.firewoodLeaves.blockID);
		world.setBlock(i + 5, j + 5, k + 8, DivineRPGTwilight.firewoodLeaves.blockID);
		world.setBlock(i + 5, j + 5, k + 9, DivineRPGTwilight.firewoodLeaves.blockID);
		world.setBlock(i + 5, j + 5, k + 10, DivineRPGTwilight.firewoodLeaves.blockID);
		world.setBlock(i + 5, j + 5, k + 11, DivineRPGTwilight.firewoodLeaves.blockID);
		world.setBlock(i + 5, j + 6, k + 7, DivineRPGTwilight.firewoodLeaves.blockID);
		world.setBlock(i + 5, j + 6, k + 8, DivineRPGTwilight.firewoodLeaves.blockID);
		world.setBlock(i + 5, j + 6, k + 9, DivineRPGTwilight.firewoodLeaves.blockID);
		world.setBlock(i + 5, j + 6, k + 10, DivineRPGTwilight.firewoodLeaves.blockID);
		world.setBlock(i + 5, j + 6, k + 11, DivineRPGTwilight.firewoodLeaves.blockID);
		world.setBlock(i + 5, j + 11, k + 8, DivineRPGTwilight.firewood.blockID);
		world.setBlock(i + 5, j + 11, k + 9, DivineRPGTwilight.firewood.blockID);
		world.setBlock(i + 5, j + 12, k + 8, DivineRPGTwilight.firewood.blockID);
		world.setBlock(i + 5, j + 12, k + 9, DivineRPGTwilight.firewood.blockID);
		world.setBlock(i + 6, j + 0, k + 8, DivineRPGTwilight.firewood.blockID);
		world.setBlock(i + 6, j + 0, k + 9, DivineRPGTwilight.firewood.blockID);
		world.setBlock(i + 6, j + 3, k + 8, DivineRPGTwilight.firewoodLeaves.blockID);
		world.setBlock(i + 6, j + 3, k + 9, DivineRPGTwilight.firewoodLeaves.blockID);
		world.setBlock(i + 6, j + 3, k + 10, DivineRPGTwilight.firewoodLeaves.blockID);
		world.setBlock(i + 6, j + 4, k + 2, DivineRPGTwilight.firewoodLeaves.blockID);
		world.setBlock(i + 6, j + 4, k + 3, DivineRPGTwilight.firewoodLeaves.blockID);
		world.setBlock(i + 6, j + 4, k + 4, DivineRPGTwilight.firewoodLeaves.blockID);
		world.setBlock(i + 6, j + 4, k + 8, DivineRPGTwilight.firewoodLeaves.blockID);
		world.setBlock(i + 6, j + 4, k + 9, DivineRPGTwilight.firewoodLeaves.blockID);
		world.setBlock(i + 6, j + 4, k + 10, DivineRPGTwilight.firewoodLeaves.blockID);
		world.setBlock(i + 6, j + 4, k + 13, DivineRPGTwilight.firewoodLeaves.blockID);
		world.setBlock(i + 6, j + 4, k + 14, DivineRPGTwilight.firewoodLeaves.blockID);
		world.setBlock(i + 6, j + 4, k + 15, DivineRPGTwilight.firewoodLeaves.blockID);
		world.setBlock(i + 6, j + 5, k + 2, DivineRPGTwilight.firewoodLeaves.blockID);
		world.setBlock(i + 6, j + 5, k + 3, DivineRPGTwilight.firewoodLeaves.blockID);
		world.setBlock(i + 6, j + 5, k + 4, DivineRPGTwilight.firewoodLeaves.blockID);
		world.setBlock(i + 6, j + 5, k + 8, DivineRPGTwilight.firewoodLeaves.blockID);
		world.setBlock(i + 6, j + 5, k + 9, DivineRPGTwilight.firewoodLeaves.blockID);
		world.setBlock(i + 6, j + 5, k + 10, DivineRPGTwilight.firewoodLeaves.blockID);
		world.setBlock(i + 6, j + 5, k + 13, DivineRPGTwilight.firewoodLeaves.blockID);
		world.setBlock(i + 6, j + 5, k + 14, DivineRPGTwilight.firewoodLeaves.blockID);
		world.setBlock(i + 6, j + 5, k + 15, DivineRPGTwilight.firewoodLeaves.blockID);
		world.setBlock(i + 6, j + 6, k + 2, DivineRPGTwilight.firewoodLeaves.blockID);
		world.setBlock(i + 6, j + 6, k + 3, DivineRPGTwilight.firewoodLeaves.blockID);
		world.setBlock(i + 6, j + 6, k + 4, DivineRPGTwilight.firewoodLeaves.blockID);
		world.setBlock(i + 6, j + 6, k + 13, DivineRPGTwilight.firewoodLeaves.blockID);
		world.setBlock(i + 6, j + 6, k + 14, DivineRPGTwilight.firewoodLeaves.blockID);
		world.setBlock(i + 6, j + 6, k + 15, DivineRPGTwilight.firewoodLeaves.blockID);
		world.setBlock(i + 6, j + 11, k + 8, DivineRPGTwilight.firewood.blockID);
		world.setBlock(i + 6, j + 11, k + 9, DivineRPGTwilight.firewood.blockID);
		world.setBlock(i + 6, j + 12, k + 8, DivineRPGTwilight.firewood.blockID);
		world.setBlock(i + 6, j + 12, k + 9, DivineRPGTwilight.firewood.blockID);
		world.setBlock(i + 6, j + 13, k + 8, DivineRPGTwilight.firewood.blockID);
		world.setBlock(i + 6, j + 13, k + 9, DivineRPGTwilight.firewood.blockID);
		world.setBlock(i + 7, j + 0, k + 7, DivineRPGTwilight.firewood.blockID);
		world.setBlock(i + 7, j + 0, k + 8, DivineRPGTwilight.firewood.blockID);
		world.setBlock(i + 7, j + 0, k + 9, DivineRPGTwilight.firewood.blockID);
		world.setBlock(i + 7, j + 0, k + 10, DivineRPGTwilight.firewood.blockID);
		world.setBlock(i + 7, j + 1, k + 8, DivineRPGTwilight.firewood.blockID);
		world.setBlock(i + 7, j + 1, k + 9, DivineRPGTwilight.firewood.blockID);
		world.setBlock(i + 7, j + 3, k + 1, DivineRPGTwilight.firewoodLeaves.blockID);
		world.setBlock(i + 7, j + 3, k + 2, DivineRPGTwilight.firewoodLeaves.blockID);
		world.setBlock(i + 7, j + 3, k + 3, DivineRPGTwilight.firewoodLeaves.blockID);
		world.setBlock(i + 7, j + 3, k + 4, DivineRPGTwilight.firewoodLeaves.blockID);
		world.setBlock(i + 7, j + 3, k + 5, DivineRPGTwilight.firewoodLeaves.blockID);
		world.setBlock(i + 7, j + 3, k + 12, DivineRPGTwilight.firewoodLeaves.blockID);
		world.setBlock(i + 7, j + 3, k + 13, DivineRPGTwilight.firewoodLeaves.blockID);
		world.setBlock(i + 7, j + 3, k + 14, DivineRPGTwilight.firewoodLeaves.blockID);
		world.setBlock(i + 7, j + 3, k + 15, DivineRPGTwilight.firewoodLeaves.blockID);
		world.setBlock(i + 7, j + 3, k + 16, DivineRPGTwilight.firewoodLeaves.blockID);
		world.setBlock(i + 7, j + 4, k + 1, DivineRPGTwilight.firewoodLeaves.blockID);
		world.setBlock(i + 7, j + 4, k + 2, DivineRPGTwilight.firewoodLeaves.blockID);
		world.setBlock(i + 7, j + 4, k + 3, DivineRPGTwilight.firewoodLeaves.blockID);
		world.setBlock(i + 7, j + 4, k + 4, DivineRPGTwilight.firewoodLeaves.blockID);
		world.setBlock(i + 7, j + 4, k + 5, DivineRPGTwilight.firewoodLeaves.blockID);
		world.setBlock(i + 7, j + 4, k + 12, DivineRPGTwilight.firewoodLeaves.blockID);
		world.setBlock(i + 7, j + 4, k + 13, DivineRPGTwilight.firewoodLeaves.blockID);
		world.setBlock(i + 7, j + 4, k + 14, DivineRPGTwilight.firewoodLeaves.blockID);
		world.setBlock(i + 7, j + 4, k + 15, DivineRPGTwilight.firewoodLeaves.blockID);
		world.setBlock(i + 7, j + 4, k + 16, DivineRPGTwilight.firewoodLeaves.blockID);
		world.setBlock(i + 7, j + 5, k + 1, DivineRPGTwilight.firewoodLeaves.blockID);
		world.setBlock(i + 7, j + 5, k + 2, DivineRPGTwilight.firewoodLeaves.blockID);
		world.setBlock(i + 7, j + 5, k + 3, DivineRPGTwilight.firewoodLeaves.blockID);
		world.setBlock(i + 7, j + 5, k + 4, DivineRPGTwilight.firewoodLeaves.blockID);
		world.setBlock(i + 7, j + 5, k + 5, DivineRPGTwilight.firewoodLeaves.blockID);
		world.setBlock(i + 7, j + 5, k + 12, DivineRPGTwilight.firewoodLeaves.blockID);
		world.setBlock(i + 7, j + 5, k + 13, DivineRPGTwilight.firewoodLeaves.blockID);
		world.setBlock(i + 7, j + 5, k + 14, DivineRPGTwilight.firewoodLeaves.blockID);
		world.setBlock(i + 7, j + 5, k + 15, DivineRPGTwilight.firewoodLeaves.blockID);
		world.setBlock(i + 7, j + 5, k + 16, DivineRPGTwilight.firewoodLeaves.blockID);
		world.setBlock(i + 7, j + 6, k + 1, DivineRPGTwilight.firewoodLeaves.blockID);
		world.setBlock(i + 7, j + 6, k + 2, DivineRPGTwilight.firewoodLeaves.blockID);
		world.setBlock(i + 7, j + 6, k + 3, DivineRPGTwilight.firewoodLeaves.blockID);
		world.setBlock(i + 7, j + 6, k + 4, DivineRPGTwilight.firewoodLeaves.blockID);
		world.setBlock(i + 7, j + 6, k + 5, DivineRPGTwilight.firewoodLeaves.blockID);
		world.setBlock(i + 7, j + 6, k + 12, DivineRPGTwilight.firewoodLeaves.blockID);
		world.setBlock(i + 7, j + 6, k + 13, DivineRPGTwilight.firewoodLeaves.blockID);
		world.setBlock(i + 7, j + 6, k + 14, DivineRPGTwilight.firewoodLeaves.blockID);
		world.setBlock(i + 7, j + 6, k + 15, DivineRPGTwilight.firewoodLeaves.blockID);
		world.setBlock(i + 7, j + 6, k + 16, DivineRPGTwilight.firewoodLeaves.blockID);
		world.setBlock(i + 7, j + 7, k + 1, DivineRPGTwilight.firewoodLeaves.blockID);
		world.setBlock(i + 7, j + 7, k + 2, DivineRPGTwilight.firewoodLeaves.blockID);
		world.setBlock(i + 7, j + 7, k + 3, DivineRPGTwilight.firewoodLeaves.blockID);
		world.setBlock(i + 7, j + 7, k + 4, DivineRPGTwilight.firewoodLeaves.blockID);
		world.setBlock(i + 7, j + 7, k + 5, DivineRPGTwilight.firewoodLeaves.blockID);
		world.setBlock(i + 7, j + 7, k + 12, DivineRPGTwilight.firewoodLeaves.blockID);
		world.setBlock(i + 7, j + 7, k + 13, DivineRPGTwilight.firewoodLeaves.blockID);
		world.setBlock(i + 7, j + 7, k + 14, DivineRPGTwilight.firewoodLeaves.blockID);
		world.setBlock(i + 7, j + 7, k + 15, DivineRPGTwilight.firewoodLeaves.blockID);
		world.setBlock(i + 7, j + 7, k + 16, DivineRPGTwilight.firewoodLeaves.blockID);
		world.setBlock(i + 7, j + 11, k + 8, DivineRPGTwilight.firewood.blockID);
		world.setBlock(i + 7, j + 11, k + 9, DivineRPGTwilight.firewood.blockID);
		world.setBlock(i + 7, j + 12, k + 8, DivineRPGTwilight.firewood.blockID);
		world.setBlock(i + 7, j + 12, k + 9, DivineRPGTwilight.firewood.blockID);
		world.setBlock(i + 7, j + 13, k + 8, DivineRPGTwilight.firewood.blockID);
		world.setBlock(i + 7, j + 13, k + 9, DivineRPGTwilight.firewood.blockID);
		world.setBlock(i + 7, j + 14, k + 8, DivineRPGTwilight.firewood.blockID);
		world.setBlock(i + 7, j + 14, k + 9, DivineRPGTwilight.firewood.blockID);
		world.setBlock(i + 8, j + 0, k + 6, DivineRPGTwilight.firewood.blockID);
		world.setBlock(i + 8, j + 0, k + 7, DivineRPGTwilight.firewood.blockID);
		world.setBlock(i + 8, j + 0, k + 8, DivineRPGTwilight.firewood.blockID);
		world.setBlock(i + 8, j + 0, k + 9, DivineRPGTwilight.firewood.blockID);
		world.setBlock(i + 8, j + 0, k + 10, DivineRPGTwilight.firewood.blockID);
		world.setBlock(i + 8, j + 0, k + 11, DivineRPGTwilight.firewood.blockID);
		world.setBlock(i + 8, j + 1, k + 7, DivineRPGTwilight.firewood.blockID);
		world.setBlock(i + 8, j + 1, k + 8, DivineRPGTwilight.firewood.blockID);
		world.setBlock(i + 8, j + 1, k + 9, DivineRPGTwilight.firewood.blockID);
		world.setBlock(i + 8, j + 1, k + 10, DivineRPGTwilight.firewood.blockID);
		world.setBlock(i + 8, j + 2, k + 2, DivineRPGTwilight.firewoodLeaves.blockID);
		world.setBlock(i + 8, j + 2, k + 3, DivineRPGTwilight.firewoodLeaves.blockID);
		world.setBlock(i + 8, j + 2, k + 4, DivineRPGTwilight.firewoodLeaves.blockID);
		world.setBlock(i + 8, j + 2, k + 8, DivineRPGTwilight.firewood.blockID);
		world.setBlock(i + 8, j + 2, k + 9, DivineRPGTwilight.firewood.blockID);
		world.setBlock(i + 8, j + 2, k + 13, DivineRPGTwilight.firewoodLeaves.blockID);
		world.setBlock(i + 8, j + 2, k + 14, DivineRPGTwilight.firewoodLeaves.blockID);
		world.setBlock(i + 8, j + 2, k + 15, DivineRPGTwilight.firewoodLeaves.blockID);
		world.setBlock(i + 8, j + 3, k + 1, DivineRPGTwilight.firewoodLeaves.blockID);
		world.setBlock(i + 8, j + 3, k + 2, DivineRPGTwilight.firewoodLeaves.blockID);
		world.setBlock(i + 8, j + 3, k + 3, DivineRPGTwilight.firewoodLeaves.blockID);
		world.setBlock(i + 8, j + 3, k + 4, DivineRPGTwilight.firewoodLeaves.blockID);
		world.setBlock(i + 8, j + 3, k + 5, DivineRPGTwilight.firewoodLeaves.blockID);
		world.setBlock(i + 8, j + 3, k + 8, DivineRPGTwilight.firewood.blockID);
		world.setBlock(i + 8, j + 3, k + 9, DivineRPGTwilight.firewood.blockID);
		world.setBlock(i + 8, j + 3, k + 12, DivineRPGTwilight.firewoodLeaves.blockID);
		world.setBlock(i + 8, j + 3, k + 13, DivineRPGTwilight.firewoodLeaves.blockID);
		world.setBlock(i + 8, j + 3, k + 14, DivineRPGTwilight.firewoodLeaves.blockID);
		world.setBlock(i + 8, j + 3, k + 15, DivineRPGTwilight.firewoodLeaves.blockID);
		world.setBlock(i + 8, j + 3, k + 16, DivineRPGTwilight.firewoodLeaves.blockID);
		world.setBlock(i + 8, j + 4, k + 0, DivineRPGTwilight.firewoodLeaves.blockID);
		world.setBlock(i + 8, j + 4, k + 1, DivineRPGTwilight.firewoodLeaves.blockID);
		world.setBlock(i + 8, j + 4, k + 2, DivineRPGTwilight.firewoodLeaves.blockID);
		world.setBlock(i + 8, j + 4, k + 3, DivineRPGTwilight.firewoodLeaves.blockID);
		world.setBlock(i + 8, j + 4, k + 4, DivineRPGTwilight.firewoodLeaves.blockID);
		world.setBlock(i + 8, j + 4, k + 5, DivineRPGTwilight.firewoodLeaves.blockID);
		world.setBlock(i + 8, j + 4, k + 6, DivineRPGTwilight.firewoodLeaves.blockID);
		world.setBlock(i + 8, j + 4, k + 8, DivineRPGTwilight.firewood.blockID);
		world.setBlock(i + 8, j + 4, k + 9, DivineRPGTwilight.firewood.blockID);
		world.setBlock(i + 8, j + 4, k + 11, DivineRPGTwilight.firewoodLeaves.blockID);
		world.setBlock(i + 8, j + 4, k + 12, DivineRPGTwilight.firewoodLeaves.blockID);
		world.setBlock(i + 8, j + 4, k + 13, DivineRPGTwilight.firewoodLeaves.blockID);
		world.setBlock(i + 8, j + 4, k + 14, DivineRPGTwilight.firewoodLeaves.blockID);
		world.setBlock(i + 8, j + 4, k + 15, DivineRPGTwilight.firewoodLeaves.blockID);
		world.setBlock(i + 8, j + 4, k + 16, DivineRPGTwilight.firewoodLeaves.blockID);
		world.setBlock(i + 8, j + 4, k + 17, DivineRPGTwilight.firewoodLeaves.blockID);
		world.setBlock(i + 8, j + 5, k + 0, DivineRPGTwilight.firewoodLeaves.blockID);
		world.setBlock(i + 8, j + 5, k + 1, DivineRPGTwilight.firewoodLeaves.blockID);
		world.setBlock(i + 8, j + 5, k + 2, DivineRPGTwilight.firewoodLeaves.blockID);
		world.setBlock(i + 8, j + 5, k + 3, DivineRPGTwilight.firewoodLeaves.blockID);
		world.setBlock(i + 8, j + 5, k + 4, DivineRPGTwilight.firewoodLeaves.blockID);
		world.setBlock(i + 8, j + 5, k + 5, DivineRPGTwilight.firewoodLeaves.blockID);
		world.setBlock(i + 8, j + 5, k + 6, DivineRPGTwilight.firewoodLeaves.blockID);
		world.setBlock(i + 8, j + 5, k + 8, DivineRPGTwilight.firewood.blockID);
		world.setBlock(i + 8, j + 5, k + 9, DivineRPGTwilight.firewood.blockID);
		world.setBlock(i + 8, j + 5, k + 11, DivineRPGTwilight.firewoodLeaves.blockID);
		world.setBlock(i + 8, j + 5, k + 12, DivineRPGTwilight.firewoodLeaves.blockID);
		world.setBlock(i + 8, j + 5, k + 13, DivineRPGTwilight.firewoodLeaves.blockID);
		world.setBlock(i + 8, j + 5, k + 14, DivineRPGTwilight.firewoodLeaves.blockID);
		world.setBlock(i + 8, j + 5, k + 15, DivineRPGTwilight.firewoodLeaves.blockID);
		world.setBlock(i + 8, j + 5, k + 16, DivineRPGTwilight.firewoodLeaves.blockID);
		world.setBlock(i + 8, j + 5, k + 17, DivineRPGTwilight.firewoodLeaves.blockID);
		world.setBlock(i + 8, j + 6, k + 0, DivineRPGTwilight.firewoodLeaves.blockID);
		world.setBlock(i + 8, j + 6, k + 1, DivineRPGTwilight.firewoodLeaves.blockID);
		world.setBlock(i + 8, j + 6, k + 2, DivineRPGTwilight.firewoodLeaves.blockID);
		world.setBlock(i + 8, j + 6, k + 3, DivineRPGTwilight.firewoodLeaves.blockID);
		world.setBlock(i + 8, j + 6, k + 4, DivineRPGTwilight.firewoodLeaves.blockID);
		world.setBlock(i + 8, j + 6, k + 5, DivineRPGTwilight.firewoodLeaves.blockID);
		world.setBlock(i + 8, j + 6, k + 6, DivineRPGTwilight.firewoodLeaves.blockID);
		world.setBlock(i + 8, j + 6, k + 8, DivineRPGTwilight.firewood.blockID);
		world.setBlock(i + 8, j + 6, k + 9, DivineRPGTwilight.firewood.blockID);
		world.setBlock(i + 8, j + 6, k + 11, DivineRPGTwilight.firewoodLeaves.blockID);
		world.setBlock(i + 8, j + 6, k + 12, DivineRPGTwilight.firewoodLeaves.blockID);
		world.setBlock(i + 8, j + 6, k + 13, DivineRPGTwilight.firewoodLeaves.blockID);
		world.setBlock(i + 8, j + 6, k + 14, DivineRPGTwilight.firewoodLeaves.blockID);
		world.setBlock(i + 8, j + 6, k + 15, DivineRPGTwilight.firewoodLeaves.blockID);
		world.setBlock(i + 8, j + 6, k + 16, DivineRPGTwilight.firewoodLeaves.blockID);
		world.setBlock(i + 8, j + 6, k + 17, DivineRPGTwilight.firewoodLeaves.blockID);
		world.setBlock(i + 8, j + 7, k + 1, DivineRPGTwilight.firewoodLeaves.blockID);
		world.setBlock(i + 8, j + 7, k + 2, DivineRPGTwilight.firewoodLeaves.blockID);
		world.setBlock(i + 8, j + 7, k + 3, DivineRPGTwilight.firewoodLeaves.blockID);
		world.setBlock(i + 8, j + 7, k + 4, DivineRPGTwilight.firewoodLeaves.blockID);
		world.setBlock(i + 8, j + 7, k + 5, DivineRPGTwilight.firewoodLeaves.blockID);
		world.setBlock(i + 8, j + 7, k + 8, DivineRPGTwilight.firewood.blockID);
		world.setBlock(i + 8, j + 7, k + 9, DivineRPGTwilight.firewood.blockID);
		world.setBlock(i + 8, j + 7, k + 12, DivineRPGTwilight.firewoodLeaves.blockID);
		world.setBlock(i + 8, j + 7, k + 13, DivineRPGTwilight.firewoodLeaves.blockID);
		world.setBlock(i + 8, j + 7, k + 14, DivineRPGTwilight.firewoodLeaves.blockID);
		world.setBlock(i + 8, j + 7, k + 15, DivineRPGTwilight.firewoodLeaves.blockID);
		world.setBlock(i + 8, j + 7, k + 16, DivineRPGTwilight.firewoodLeaves.blockID);
		world.setBlock(i + 8, j + 8, k + 2, DivineRPGTwilight.firewoodLeaves.blockID);
		world.setBlock(i + 8, j + 8, k + 3, DivineRPGTwilight.firewoodLeaves.blockID);
		world.setBlock(i + 8, j + 8, k + 4, DivineRPGTwilight.firewoodLeaves.blockID);
		world.setBlock(i + 8, j + 8, k + 8, DivineRPGTwilight.firewood.blockID);
		world.setBlock(i + 8, j + 8, k + 9, DivineRPGTwilight.firewood.blockID);
		world.setBlock(i + 8, j + 8, k + 13, DivineRPGTwilight.firewoodLeaves.blockID);
		world.setBlock(i + 8, j + 8, k + 14, DivineRPGTwilight.firewoodLeaves.blockID);
		world.setBlock(i + 8, j + 8, k + 15, DivineRPGTwilight.firewoodLeaves.blockID);
		world.setBlock(i + 8, j + 9, k + 3, DivineRPGTwilight.firewood.blockID);
		world.setBlock(i + 8, j + 9, k + 4, DivineRPGTwilight.firewood.blockID);
		world.setBlock(i + 8, j + 9, k + 8, DivineRPGTwilight.firewood.blockID);
		world.setBlock(i + 8, j + 9, k + 9, DivineRPGTwilight.firewood.blockID);
		world.setBlock(i + 8, j + 9, k + 13, DivineRPGTwilight.firewood.blockID);
		world.setBlock(i + 8, j + 9, k + 14, DivineRPGTwilight.firewood.blockID);
		world.setBlock(i + 8, j + 10, k + 3, DivineRPGTwilight.firewood.blockID);
		world.setBlock(i + 8, j + 10, k + 4, DivineRPGTwilight.firewood.blockID);
		world.setBlock(i + 8, j + 10, k + 8, DivineRPGTwilight.firewood.blockID);
		world.setBlock(i + 8, j + 10, k + 9, DivineRPGTwilight.firewood.blockID);
		world.setBlock(i + 8, j + 10, k + 13, DivineRPGTwilight.firewood.blockID);
		world.setBlock(i + 8, j + 10, k + 14, DivineRPGTwilight.firewood.blockID);
		world.setBlock(i + 8, j + 11, k + 3, DivineRPGTwilight.firewood.blockID);
		world.setBlock(i + 8, j + 11, k + 4, DivineRPGTwilight.firewood.blockID);
		world.setBlock(i + 8, j + 11, k + 5, DivineRPGTwilight.firewood.blockID);
		world.setBlock(i + 8, j + 11, k + 6, DivineRPGTwilight.firewood.blockID);
		world.setBlock(i + 8, j + 11, k + 7, DivineRPGTwilight.firewood.blockID);
		world.setBlock(i + 8, j + 11, k + 8, DivineRPGTwilight.firewood.blockID);
		world.setBlock(i + 8, j + 11, k + 9, DivineRPGTwilight.firewood.blockID);
		world.setBlock(i + 8, j + 11, k + 10, DivineRPGTwilight.firewood.blockID);
		world.setBlock(i + 8, j + 11, k + 11, DivineRPGTwilight.firewood.blockID);
		world.setBlock(i + 8, j + 11, k + 12, DivineRPGTwilight.firewood.blockID);
		world.setBlock(i + 8, j + 11, k + 13, DivineRPGTwilight.firewood.blockID);
		world.setBlock(i + 8, j + 11, k + 14, DivineRPGTwilight.firewood.blockID);
		world.setBlock(i + 8, j + 12, k + 3, DivineRPGTwilight.firewood.blockID);
		world.setBlock(i + 8, j + 12, k + 4, DivineRPGTwilight.firewood.blockID);
		world.setBlock(i + 8, j + 12, k + 5, DivineRPGTwilight.firewood.blockID);
		world.setBlock(i + 8, j + 12, k + 6, DivineRPGTwilight.firewood.blockID);
		world.setBlock(i + 8, j + 12, k + 7, DivineRPGTwilight.firewood.blockID);
		world.setBlock(i + 8, j + 12, k + 8, DivineRPGTwilight.firewood.blockID);
		world.setBlock(i + 8, j + 12, k + 9, DivineRPGTwilight.firewood.blockID);
		world.setBlock(i + 8, j + 12, k + 10, DivineRPGTwilight.firewood.blockID);
		world.setBlock(i + 8, j + 12, k + 11, DivineRPGTwilight.firewood.blockID);
		world.setBlock(i + 8, j + 12, k + 12, DivineRPGTwilight.firewood.blockID);
		world.setBlock(i + 8, j + 12, k + 13, DivineRPGTwilight.firewood.blockID);
		world.setBlock(i + 8, j + 12, k + 14, DivineRPGTwilight.firewood.blockID);
		world.setBlock(i + 8, j + 13, k + 6, DivineRPGTwilight.firewood.blockID);
		world.setBlock(i + 8, j + 13, k + 7, DivineRPGTwilight.firewood.blockID);
		world.setBlock(i + 8, j + 13, k + 8, DivineRPGTwilight.firewood.blockID);
		world.setBlock(i + 8, j + 13, k + 9, DivineRPGTwilight.firewood.blockID);
		world.setBlock(i + 8, j + 13, k + 10, DivineRPGTwilight.firewood.blockID);
		world.setBlock(i + 8, j + 13, k + 11, DivineRPGTwilight.firewood.blockID);
		world.setBlock(i + 8, j + 14, k + 7, DivineRPGTwilight.firewood.blockID);
		world.setBlock(i + 8, j + 14, k + 8, DivineRPGTwilight.firewood.blockID);
		world.setBlock(i + 8, j + 14, k + 9, DivineRPGTwilight.firewood.blockID);
		world.setBlock(i + 8, j + 14, k + 10, DivineRPGTwilight.firewood.blockID);
		world.setBlock(i + 9, j + 0, k + 6, DivineRPGTwilight.firewood.blockID);
		world.setBlock(i + 9, j + 0, k + 7, DivineRPGTwilight.firewood.blockID);
		world.setBlock(i + 9, j + 0, k + 8, DivineRPGTwilight.firewood.blockID);
		world.setBlock(i + 9, j + 0, k + 9, DivineRPGTwilight.firewood.blockID);
		world.setBlock(i + 9, j + 0, k + 10, DivineRPGTwilight.firewood.blockID);
		world.setBlock(i + 9, j + 0, k + 11, DivineRPGTwilight.firewood.blockID);
		world.setBlock(i + 9, j + 1, k + 7, DivineRPGTwilight.firewood.blockID);
		world.setBlock(i + 9, j + 1, k + 8, DivineRPGTwilight.firewood.blockID);
		world.setBlock(i + 9, j + 1, k + 9, DivineRPGTwilight.firewood.blockID);
		world.setBlock(i + 9, j + 1, k + 10, DivineRPGTwilight.firewood.blockID);
		world.setBlock(i + 9, j + 2, k + 2, DivineRPGTwilight.firewoodLeaves.blockID);
		world.setBlock(i + 9, j + 2, k + 3, DivineRPGTwilight.firewoodLeaves.blockID);
		world.setBlock(i + 9, j + 2, k + 4, DivineRPGTwilight.firewoodLeaves.blockID);
		world.setBlock(i + 9, j + 2, k + 8, DivineRPGTwilight.firewood.blockID);
		world.setBlock(i + 9, j + 2, k + 9, DivineRPGTwilight.firewood.blockID);
		world.setBlock(i + 9, j + 2, k + 13, DivineRPGTwilight.firewoodLeaves.blockID);
		world.setBlock(i + 9, j + 2, k + 14, DivineRPGTwilight.firewoodLeaves.blockID);
		world.setBlock(i + 9, j + 2, k + 15, DivineRPGTwilight.firewoodLeaves.blockID);
		world.setBlock(i + 9, j + 3, k + 1, DivineRPGTwilight.firewoodLeaves.blockID);
		world.setBlock(i + 9, j + 3, k + 2, DivineRPGTwilight.firewoodLeaves.blockID);
		world.setBlock(i + 9, j + 3, k + 3, DivineRPGTwilight.firewoodLeaves.blockID);
		world.setBlock(i + 9, j + 3, k + 4, DivineRPGTwilight.firewoodLeaves.blockID);
		world.setBlock(i + 9, j + 3, k + 5, DivineRPGTwilight.firewoodLeaves.blockID);
		world.setBlock(i + 9, j + 3, k + 8, DivineRPGTwilight.firewood.blockID);
		world.setBlock(i + 9, j + 3, k + 9, DivineRPGTwilight.firewood.blockID);
		world.setBlock(i + 9, j + 3, k + 12, DivineRPGTwilight.firewoodLeaves.blockID);
		world.setBlock(i + 9, j + 3, k + 13, DivineRPGTwilight.firewoodLeaves.blockID);
		world.setBlock(i + 9, j + 3, k + 14, DivineRPGTwilight.firewoodLeaves.blockID);
		world.setBlock(i + 9, j + 3, k + 15, DivineRPGTwilight.firewoodLeaves.blockID);
		world.setBlock(i + 9, j + 3, k + 16, DivineRPGTwilight.firewoodLeaves.blockID);
		world.setBlock(i + 9, j + 4, k + 0, DivineRPGTwilight.firewoodLeaves.blockID);
		world.setBlock(i + 9, j + 4, k + 1, DivineRPGTwilight.firewoodLeaves.blockID);
		world.setBlock(i + 9, j + 4, k + 2, DivineRPGTwilight.firewoodLeaves.blockID);
		world.setBlock(i + 9, j + 4, k + 3, DivineRPGTwilight.firewoodLeaves.blockID);
		world.setBlock(i + 9, j + 4, k + 4, DivineRPGTwilight.firewoodLeaves.blockID);
		world.setBlock(i + 9, j + 4, k + 5, DivineRPGTwilight.firewoodLeaves.blockID);
		world.setBlock(i + 9, j + 4, k + 6, DivineRPGTwilight.firewoodLeaves.blockID);
		world.setBlock(i + 9, j + 4, k + 8, DivineRPGTwilight.firewood.blockID);
		world.setBlock(i + 9, j + 4, k + 9, DivineRPGTwilight.firewood.blockID);
		world.setBlock(i + 9, j + 4, k + 11, DivineRPGTwilight.firewoodLeaves.blockID);
		world.setBlock(i + 9, j + 4, k + 12, DivineRPGTwilight.firewoodLeaves.blockID);
		world.setBlock(i + 9, j + 4, k + 13, DivineRPGTwilight.firewoodLeaves.blockID);
		world.setBlock(i + 9, j + 4, k + 14, DivineRPGTwilight.firewoodLeaves.blockID);
		world.setBlock(i + 9, j + 4, k + 15, DivineRPGTwilight.firewoodLeaves.blockID);
		world.setBlock(i + 9, j + 4, k + 16, DivineRPGTwilight.firewoodLeaves.blockID);
		world.setBlock(i + 9, j + 4, k + 17, DivineRPGTwilight.firewoodLeaves.blockID);
		world.setBlock(i + 9, j + 5, k + 0, DivineRPGTwilight.firewoodLeaves.blockID);
		world.setBlock(i + 9, j + 5, k + 1, DivineRPGTwilight.firewoodLeaves.blockID);
		world.setBlock(i + 9, j + 5, k + 2, DivineRPGTwilight.firewoodLeaves.blockID);
		world.setBlock(i + 9, j + 5, k + 3, DivineRPGTwilight.firewoodLeaves.blockID);
		world.setBlock(i + 9, j + 5, k + 4, DivineRPGTwilight.firewoodLeaves.blockID);
		world.setBlock(i + 9, j + 5, k + 5, DivineRPGTwilight.firewoodLeaves.blockID);
		world.setBlock(i + 9, j + 5, k + 6, DivineRPGTwilight.firewoodLeaves.blockID);
		world.setBlock(i + 9, j + 5, k + 8, DivineRPGTwilight.firewood.blockID);
		world.setBlock(i + 9, j + 5, k + 9, DivineRPGTwilight.firewood.blockID);
		world.setBlock(i + 9, j + 5, k + 11, DivineRPGTwilight.firewoodLeaves.blockID);
		world.setBlock(i + 9, j + 5, k + 12, DivineRPGTwilight.firewoodLeaves.blockID);
		world.setBlock(i + 9, j + 5, k + 13, DivineRPGTwilight.firewoodLeaves.blockID);
		world.setBlock(i + 9, j + 5, k + 14, DivineRPGTwilight.firewoodLeaves.blockID);
		world.setBlock(i + 9, j + 5, k + 15, DivineRPGTwilight.firewoodLeaves.blockID);
		world.setBlock(i + 9, j + 5, k + 16, DivineRPGTwilight.firewoodLeaves.blockID);
		world.setBlock(i + 9, j + 5, k + 17, DivineRPGTwilight.firewoodLeaves.blockID);
		world.setBlock(i + 9, j + 6, k + 0, DivineRPGTwilight.firewoodLeaves.blockID);
		world.setBlock(i + 9, j + 6, k + 1, DivineRPGTwilight.firewoodLeaves.blockID);
		world.setBlock(i + 9, j + 6, k + 2, DivineRPGTwilight.firewoodLeaves.blockID);
		world.setBlock(i + 9, j + 6, k + 3, DivineRPGTwilight.firewoodLeaves.blockID);
		world.setBlock(i + 9, j + 6, k + 4, DivineRPGTwilight.firewoodLeaves.blockID);
		world.setBlock(i + 9, j + 6, k + 5, DivineRPGTwilight.firewoodLeaves.blockID);
		world.setBlock(i + 9, j + 6, k + 6, DivineRPGTwilight.firewoodLeaves.blockID);
		world.setBlock(i + 9, j + 6, k + 8, DivineRPGTwilight.firewood.blockID);
		world.setBlock(i + 9, j + 6, k + 9, DivineRPGTwilight.firewood.blockID);
		world.setBlock(i + 9, j + 6, k + 11, DivineRPGTwilight.firewoodLeaves.blockID);
		world.setBlock(i + 9, j + 6, k + 12, DivineRPGTwilight.firewoodLeaves.blockID);
		world.setBlock(i + 9, j + 6, k + 13, DivineRPGTwilight.firewoodLeaves.blockID);
		world.setBlock(i + 9, j + 6, k + 14, DivineRPGTwilight.firewoodLeaves.blockID);
		world.setBlock(i + 9, j + 6, k + 15, DivineRPGTwilight.firewoodLeaves.blockID);
		world.setBlock(i + 9, j + 6, k + 16, DivineRPGTwilight.firewoodLeaves.blockID);
		world.setBlock(i + 9, j + 6, k + 17, DivineRPGTwilight.firewoodLeaves.blockID);
		world.setBlock(i + 9, j + 7, k + 1, DivineRPGTwilight.firewoodLeaves.blockID);
		world.setBlock(i + 9, j + 7, k + 2, DivineRPGTwilight.firewoodLeaves.blockID);
		world.setBlock(i + 9, j + 7, k + 3, DivineRPGTwilight.firewoodLeaves.blockID);
		world.setBlock(i + 9, j + 7, k + 4, DivineRPGTwilight.firewoodLeaves.blockID);
		world.setBlock(i + 9, j + 7, k + 5, DivineRPGTwilight.firewoodLeaves.blockID);
		world.setBlock(i + 9, j + 7, k + 8, DivineRPGTwilight.firewood.blockID);
		world.setBlock(i + 9, j + 7, k + 9, DivineRPGTwilight.firewood.blockID);
		world.setBlock(i + 9, j + 7, k + 12, DivineRPGTwilight.firewoodLeaves.blockID);
		world.setBlock(i + 9, j + 7, k + 13, DivineRPGTwilight.firewoodLeaves.blockID);
		world.setBlock(i + 9, j + 7, k + 14, DivineRPGTwilight.firewoodLeaves.blockID);
		world.setBlock(i + 9, j + 7, k + 15, DivineRPGTwilight.firewoodLeaves.blockID);
		world.setBlock(i + 9, j + 7, k + 16, DivineRPGTwilight.firewoodLeaves.blockID);
		world.setBlock(i + 9, j + 8, k + 2, DivineRPGTwilight.firewoodLeaves.blockID);
		world.setBlock(i + 9, j + 8, k + 3, DivineRPGTwilight.firewoodLeaves.blockID);
		world.setBlock(i + 9, j + 8, k + 4, DivineRPGTwilight.firewoodLeaves.blockID);
		world.setBlock(i + 9, j + 8, k + 8, DivineRPGTwilight.firewood.blockID);
		world.setBlock(i + 9, j + 8, k + 9, DivineRPGTwilight.firewood.blockID);
		world.setBlock(i + 9, j + 8, k + 13, DivineRPGTwilight.firewoodLeaves.blockID);
		world.setBlock(i + 9, j + 8, k + 14, DivineRPGTwilight.firewoodLeaves.blockID);
		world.setBlock(i + 9, j + 8, k + 15, DivineRPGTwilight.firewoodLeaves.blockID);
		world.setBlock(i + 9, j + 9, k + 3, DivineRPGTwilight.firewood.blockID);
		world.setBlock(i + 9, j + 9, k + 4, DivineRPGTwilight.firewood.blockID);
		world.setBlock(i + 9, j + 9, k + 8, DivineRPGTwilight.firewood.blockID);
		world.setBlock(i + 9, j + 9, k + 9, DivineRPGTwilight.firewood.blockID);
		world.setBlock(i + 9, j + 9, k + 13, DivineRPGTwilight.firewood.blockID);
		world.setBlock(i + 9, j + 9, k + 14, DivineRPGTwilight.firewood.blockID);
		world.setBlock(i + 9, j + 10, k + 3, DivineRPGTwilight.firewood.blockID);
		world.setBlock(i + 9, j + 10, k + 4, DivineRPGTwilight.firewood.blockID);
		world.setBlock(i + 9, j + 10, k + 8, DivineRPGTwilight.firewood.blockID);
		world.setBlock(i + 9, j + 10, k + 9, DivineRPGTwilight.firewood.blockID);
		world.setBlock(i + 9, j + 10, k + 13, DivineRPGTwilight.firewood.blockID);
		world.setBlock(i + 9, j + 10, k + 14, DivineRPGTwilight.firewood.blockID);
		world.setBlock(i + 9, j + 11, k + 3, DivineRPGTwilight.firewood.blockID);
		world.setBlock(i + 9, j + 11, k + 4, DivineRPGTwilight.firewood.blockID);
		world.setBlock(i + 9, j + 11, k + 5, DivineRPGTwilight.firewood.blockID);
		world.setBlock(i + 9, j + 11, k + 6, DivineRPGTwilight.firewood.blockID);
		world.setBlock(i + 9, j + 11, k + 7, DivineRPGTwilight.firewood.blockID);
		world.setBlock(i + 9, j + 11, k + 8, DivineRPGTwilight.firewood.blockID);
		world.setBlock(i + 9, j + 11, k + 9, DivineRPGTwilight.firewood.blockID);
		world.setBlock(i + 9, j + 11, k + 10, DivineRPGTwilight.firewood.blockID);
		world.setBlock(i + 9, j + 11, k + 11, DivineRPGTwilight.firewood.blockID);
		world.setBlock(i + 9, j + 11, k + 12, DivineRPGTwilight.firewood.blockID);
		world.setBlock(i + 9, j + 11, k + 13, DivineRPGTwilight.firewood.blockID);
		world.setBlock(i + 9, j + 11, k + 14, DivineRPGTwilight.firewood.blockID);
		world.setBlock(i + 9, j + 12, k + 3, DivineRPGTwilight.firewood.blockID);
		world.setBlock(i + 9, j + 12, k + 4, DivineRPGTwilight.firewood.blockID);
		world.setBlock(i + 9, j + 12, k + 5, DivineRPGTwilight.firewood.blockID);
		world.setBlock(i + 9, j + 12, k + 6, DivineRPGTwilight.firewood.blockID);
		world.setBlock(i + 9, j + 12, k + 7, DivineRPGTwilight.firewood.blockID);
		world.setBlock(i + 9, j + 12, k + 8, DivineRPGTwilight.firewood.blockID);
		world.setBlock(i + 9, j + 12, k + 9, DivineRPGTwilight.firewood.blockID);
		world.setBlock(i + 9, j + 12, k + 10, DivineRPGTwilight.firewood.blockID);
		world.setBlock(i + 9, j + 12, k + 11, DivineRPGTwilight.firewood.blockID);
		world.setBlock(i + 9, j + 12, k + 12, DivineRPGTwilight.firewood.blockID);
		world.setBlock(i + 9, j + 12, k + 13, DivineRPGTwilight.firewood.blockID);
		world.setBlock(i + 9, j + 12, k + 14, DivineRPGTwilight.firewood.blockID);
		world.setBlock(i + 9, j + 13, k + 6, DivineRPGTwilight.firewood.blockID);
		world.setBlock(i + 9, j + 13, k + 7, DivineRPGTwilight.firewood.blockID);
		world.setBlock(i + 9, j + 13, k + 8, DivineRPGTwilight.firewood.blockID);
		world.setBlock(i + 9, j + 13, k + 9, DivineRPGTwilight.firewood.blockID);
		world.setBlock(i + 9, j + 13, k + 10, DivineRPGTwilight.firewood.blockID);
		world.setBlock(i + 9, j + 13, k + 11, DivineRPGTwilight.firewood.blockID);
		world.setBlock(i + 9, j + 14, k + 7, DivineRPGTwilight.firewood.blockID);
		world.setBlock(i + 9, j + 14, k + 8, DivineRPGTwilight.firewood.blockID);
		world.setBlock(i + 9, j + 14, k + 9, DivineRPGTwilight.firewood.blockID);
		world.setBlock(i + 9, j + 14, k + 10, DivineRPGTwilight.firewood.blockID);
		world.setBlock(i + 10, j + 0, k + 7, DivineRPGTwilight.firewood.blockID);
		world.setBlock(i + 10, j + 0, k + 8, DivineRPGTwilight.firewood.blockID);
		world.setBlock(i + 10, j + 0, k + 9, DivineRPGTwilight.firewood.blockID);
		world.setBlock(i + 10, j + 0, k + 10, DivineRPGTwilight.firewood.blockID);
		world.setBlock(i + 10, j + 1, k + 8, DivineRPGTwilight.firewood.blockID);
		world.setBlock(i + 10, j + 1, k + 9, DivineRPGTwilight.firewood.blockID);
		world.setBlock(i + 10, j + 2, k + 2, DivineRPGTwilight.firewoodLeaves.blockID);
		world.setBlock(i + 10, j + 2, k + 3, DivineRPGTwilight.firewoodLeaves.blockID);
		world.setBlock(i + 10, j + 2, k + 4, DivineRPGTwilight.firewoodLeaves.blockID);
		world.setBlock(i + 10, j + 2, k + 13, DivineRPGTwilight.firewoodLeaves.blockID);
		world.setBlock(i + 10, j + 2, k + 14, DivineRPGTwilight.firewoodLeaves.blockID);
		world.setBlock(i + 10, j + 2, k + 15, DivineRPGTwilight.firewoodLeaves.blockID);
		world.setBlock(i + 10, j + 3, k + 1, DivineRPGTwilight.firewoodLeaves.blockID);
		world.setBlock(i + 10, j + 3, k + 2, DivineRPGTwilight.firewoodLeaves.blockID);
		world.setBlock(i + 10, j + 3, k + 3, DivineRPGTwilight.firewoodLeaves.blockID);
		world.setBlock(i + 10, j + 3, k + 4, DivineRPGTwilight.firewoodLeaves.blockID);
		world.setBlock(i + 10, j + 3, k + 5, DivineRPGTwilight.firewoodLeaves.blockID);
		world.setBlock(i + 10, j + 3, k + 12, DivineRPGTwilight.firewoodLeaves.blockID);
		world.setBlock(i + 10, j + 3, k + 13, DivineRPGTwilight.firewoodLeaves.blockID);
		world.setBlock(i + 10, j + 3, k + 14, DivineRPGTwilight.firewoodLeaves.blockID);
		world.setBlock(i + 10, j + 3, k + 15, DivineRPGTwilight.firewoodLeaves.blockID);
		world.setBlock(i + 10, j + 3, k + 16, DivineRPGTwilight.firewoodLeaves.blockID);
		world.setBlock(i + 10, j + 4, k + 0, DivineRPGTwilight.firewoodLeaves.blockID);
		world.setBlock(i + 10, j + 4, k + 1, DivineRPGTwilight.firewoodLeaves.blockID);
		world.setBlock(i + 10, j + 4, k + 2, DivineRPGTwilight.firewoodLeaves.blockID);
		world.setBlock(i + 10, j + 4, k + 3, DivineRPGTwilight.firewoodLeaves.blockID);
		world.setBlock(i + 10, j + 4, k + 4, DivineRPGTwilight.firewoodLeaves.blockID);
		world.setBlock(i + 10, j + 4, k + 5, DivineRPGTwilight.firewoodLeaves.blockID);
		world.setBlock(i + 10, j + 4, k + 6, DivineRPGTwilight.firewoodLeaves.blockID);
		world.setBlock(i + 10, j + 4, k + 11, DivineRPGTwilight.firewoodLeaves.blockID);
		world.setBlock(i + 10, j + 4, k + 12, DivineRPGTwilight.firewoodLeaves.blockID);
		world.setBlock(i + 10, j + 4, k + 13, DivineRPGTwilight.firewoodLeaves.blockID);
		world.setBlock(i + 10, j + 4, k + 14, DivineRPGTwilight.firewoodLeaves.blockID);
		world.setBlock(i + 10, j + 4, k + 15, DivineRPGTwilight.firewoodLeaves.blockID);
		world.setBlock(i + 10, j + 4, k + 16, DivineRPGTwilight.firewoodLeaves.blockID);
		world.setBlock(i + 10, j + 4, k + 17, DivineRPGTwilight.firewoodLeaves.blockID);
		world.setBlock(i + 10, j + 5, k + 0, DivineRPGTwilight.firewoodLeaves.blockID);
		world.setBlock(i + 10, j + 5, k + 1, DivineRPGTwilight.firewoodLeaves.blockID);
		world.setBlock(i + 10, j + 5, k + 2, DivineRPGTwilight.firewoodLeaves.blockID);
		world.setBlock(i + 10, j + 5, k + 3, DivineRPGTwilight.firewoodLeaves.blockID);
		world.setBlock(i + 10, j + 5, k + 4, DivineRPGTwilight.firewoodLeaves.blockID);
		world.setBlock(i + 10, j + 5, k + 5, DivineRPGTwilight.firewoodLeaves.blockID);
		world.setBlock(i + 10, j + 5, k + 6, DivineRPGTwilight.firewoodLeaves.blockID);
		world.setBlock(i + 10, j + 5, k + 11, DivineRPGTwilight.firewoodLeaves.blockID);
		world.setBlock(i + 10, j + 5, k + 12, DivineRPGTwilight.firewoodLeaves.blockID);
		world.setBlock(i + 10, j + 5, k + 13, DivineRPGTwilight.firewoodLeaves.blockID);
		world.setBlock(i + 10, j + 5, k + 14, DivineRPGTwilight.firewoodLeaves.blockID);
		world.setBlock(i + 10, j + 5, k + 15, DivineRPGTwilight.firewoodLeaves.blockID);
		world.setBlock(i + 10, j + 5, k + 16, DivineRPGTwilight.firewoodLeaves.blockID);
		world.setBlock(i + 10, j + 5, k + 17, DivineRPGTwilight.firewoodLeaves.blockID);
		world.setBlock(i + 10, j + 6, k + 0, DivineRPGTwilight.firewoodLeaves.blockID);
		world.setBlock(i + 10, j + 6, k + 1, DivineRPGTwilight.firewoodLeaves.blockID);
		world.setBlock(i + 10, j + 6, k + 2, DivineRPGTwilight.firewoodLeaves.blockID);
		world.setBlock(i + 10, j + 6, k + 3, DivineRPGTwilight.firewoodLeaves.blockID);
		world.setBlock(i + 10, j + 6, k + 4, DivineRPGTwilight.firewoodLeaves.blockID);
		world.setBlock(i + 10, j + 6, k + 5, DivineRPGTwilight.firewoodLeaves.blockID);
		world.setBlock(i + 10, j + 6, k + 6, DivineRPGTwilight.firewoodLeaves.blockID);
		world.setBlock(i + 10, j + 6, k + 11, DivineRPGTwilight.firewoodLeaves.blockID);
		world.setBlock(i + 10, j + 6, k + 12, DivineRPGTwilight.firewoodLeaves.blockID);
		world.setBlock(i + 10, j + 6, k + 13, DivineRPGTwilight.firewoodLeaves.blockID);
		world.setBlock(i + 10, j + 6, k + 14, DivineRPGTwilight.firewoodLeaves.blockID);
		world.setBlock(i + 10, j + 6, k + 15, DivineRPGTwilight.firewoodLeaves.blockID);
		world.setBlock(i + 10, j + 6, k + 16, DivineRPGTwilight.firewoodLeaves.blockID);
		world.setBlock(i + 10, j + 6, k + 17, DivineRPGTwilight.firewoodLeaves.blockID);
		world.setBlock(i + 10, j + 7, k + 1, DivineRPGTwilight.firewoodLeaves.blockID);
		world.setBlock(i + 10, j + 7, k + 2, DivineRPGTwilight.firewoodLeaves.blockID);
		world.setBlock(i + 10, j + 7, k + 3, DivineRPGTwilight.firewoodLeaves.blockID);
		world.setBlock(i + 10, j + 7, k + 4, DivineRPGTwilight.firewoodLeaves.blockID);
		world.setBlock(i + 10, j + 7, k + 5, DivineRPGTwilight.firewoodLeaves.blockID);
		world.setBlock(i + 10, j + 7, k + 12, DivineRPGTwilight.firewoodLeaves.blockID);
		world.setBlock(i + 10, j + 7, k + 13, DivineRPGTwilight.firewoodLeaves.blockID);
		world.setBlock(i + 10, j + 7, k + 14, DivineRPGTwilight.firewoodLeaves.blockID);
		world.setBlock(i + 10, j + 7, k + 15, DivineRPGTwilight.firewoodLeaves.blockID);
		world.setBlock(i + 10, j + 7, k + 16, DivineRPGTwilight.firewoodLeaves.blockID);
		world.setBlock(i + 10, j + 8, k + 2, DivineRPGTwilight.firewoodLeaves.blockID);
		world.setBlock(i + 10, j + 8, k + 3, DivineRPGTwilight.firewoodLeaves.blockID);
		world.setBlock(i + 10, j + 8, k + 4, DivineRPGTwilight.firewoodLeaves.blockID);
		world.setBlock(i + 10, j + 8, k + 13, DivineRPGTwilight.firewoodLeaves.blockID);
		world.setBlock(i + 10, j + 8, k + 14, DivineRPGTwilight.firewoodLeaves.blockID);
		world.setBlock(i + 10, j + 8, k + 15, DivineRPGTwilight.firewoodLeaves.blockID);
		world.setBlock(i + 10, j + 11, k + 8, DivineRPGTwilight.firewood.blockID);
		world.setBlock(i + 10, j + 11, k + 9, DivineRPGTwilight.firewood.blockID);
		world.setBlock(i + 10, j + 12, k + 8, DivineRPGTwilight.firewood.blockID);
		world.setBlock(i + 10, j + 12, k + 9, DivineRPGTwilight.firewood.blockID);
		world.setBlock(i + 10, j + 13, k + 8, DivineRPGTwilight.firewood.blockID);
		world.setBlock(i + 10, j + 13, k + 9, DivineRPGTwilight.firewood.blockID);
		world.setBlock(i + 10, j + 14, k + 8, DivineRPGTwilight.firewood.blockID);
		world.setBlock(i + 10, j + 14, k + 9, DivineRPGTwilight.firewood.blockID);
		world.setBlock(i + 11, j + 0, k + 8, DivineRPGTwilight.firewood.blockID);
		world.setBlock(i + 11, j + 0, k + 9, DivineRPGTwilight.firewood.blockID);
		world.setBlock(i + 11, j + 3, k + 1, DivineRPGTwilight.firewoodLeaves.blockID);
		world.setBlock(i + 11, j + 3, k + 2, DivineRPGTwilight.firewoodLeaves.blockID);
		world.setBlock(i + 11, j + 3, k + 3, DivineRPGTwilight.firewoodLeaves.blockID);
		world.setBlock(i + 11, j + 3, k + 4, DivineRPGTwilight.firewoodLeaves.blockID);
		world.setBlock(i + 11, j + 3, k + 5, DivineRPGTwilight.firewoodLeaves.blockID);
		world.setBlock(i + 11, j + 3, k + 12, DivineRPGTwilight.firewoodLeaves.blockID);
		world.setBlock(i + 11, j + 3, k + 13, DivineRPGTwilight.firewoodLeaves.blockID);
		world.setBlock(i + 11, j + 3, k + 14, DivineRPGTwilight.firewoodLeaves.blockID);
		world.setBlock(i + 11, j + 3, k + 15, DivineRPGTwilight.firewoodLeaves.blockID);
		world.setBlock(i + 11, j + 3, k + 16, DivineRPGTwilight.firewoodLeaves.blockID);
		world.setBlock(i + 11, j + 4, k + 1, DivineRPGTwilight.firewoodLeaves.blockID);
		world.setBlock(i + 11, j + 4, k + 2, DivineRPGTwilight.firewoodLeaves.blockID);
		world.setBlock(i + 11, j + 4, k + 3, DivineRPGTwilight.firewoodLeaves.blockID);
		world.setBlock(i + 11, j + 4, k + 4, DivineRPGTwilight.firewoodLeaves.blockID);
		world.setBlock(i + 11, j + 4, k + 5, DivineRPGTwilight.firewoodLeaves.blockID);
		world.setBlock(i + 11, j + 4, k + 12, DivineRPGTwilight.firewoodLeaves.blockID);
		world.setBlock(i + 11, j + 4, k + 13, DivineRPGTwilight.firewoodLeaves.blockID);
		world.setBlock(i + 11, j + 4, k + 14, DivineRPGTwilight.firewoodLeaves.blockID);
		world.setBlock(i + 11, j + 4, k + 15, DivineRPGTwilight.firewoodLeaves.blockID);
		world.setBlock(i + 11, j + 4, k + 16, DivineRPGTwilight.firewoodLeaves.blockID);
		world.setBlock(i + 11, j + 5, k + 1, DivineRPGTwilight.firewoodLeaves.blockID);
		world.setBlock(i + 11, j + 5, k + 2, DivineRPGTwilight.firewoodLeaves.blockID);
		world.setBlock(i + 11, j + 5, k + 3, DivineRPGTwilight.firewoodLeaves.blockID);
		world.setBlock(i + 11, j + 5, k + 4, DivineRPGTwilight.firewoodLeaves.blockID);
		world.setBlock(i + 11, j + 5, k + 5, DivineRPGTwilight.firewoodLeaves.blockID);
		world.setBlock(i + 11, j + 5, k + 12, DivineRPGTwilight.firewoodLeaves.blockID);
		world.setBlock(i + 11, j + 5, k + 13, DivineRPGTwilight.firewoodLeaves.blockID);
		world.setBlock(i + 11, j + 5, k + 14, DivineRPGTwilight.firewoodLeaves.blockID);
		world.setBlock(i + 11, j + 5, k + 15, DivineRPGTwilight.firewoodLeaves.blockID);
		world.setBlock(i + 11, j + 5, k + 16, DivineRPGTwilight.firewoodLeaves.blockID);
		world.setBlock(i + 11, j + 6, k + 1, DivineRPGTwilight.firewoodLeaves.blockID);
		world.setBlock(i + 11, j + 6, k + 2, DivineRPGTwilight.firewoodLeaves.blockID);
		world.setBlock(i + 11, j + 6, k + 3, DivineRPGTwilight.firewoodLeaves.blockID);
		world.setBlock(i + 11, j + 6, k + 4, DivineRPGTwilight.firewoodLeaves.blockID);
		world.setBlock(i + 11, j + 6, k + 5, DivineRPGTwilight.firewoodLeaves.blockID);
		world.setBlock(i + 11, j + 6, k + 12, DivineRPGTwilight.firewoodLeaves.blockID);
		world.setBlock(i + 11, j + 6, k + 13, DivineRPGTwilight.firewoodLeaves.blockID);
		world.setBlock(i + 11, j + 6, k + 14, DivineRPGTwilight.firewoodLeaves.blockID);
		world.setBlock(i + 11, j + 6, k + 15, DivineRPGTwilight.firewoodLeaves.blockID);
		world.setBlock(i + 11, j + 6, k + 16, DivineRPGTwilight.firewoodLeaves.blockID);
		world.setBlock(i + 11, j + 7, k + 1, DivineRPGTwilight.firewoodLeaves.blockID);
		world.setBlock(i + 11, j + 7, k + 2, DivineRPGTwilight.firewoodLeaves.blockID);
		world.setBlock(i + 11, j + 7, k + 3, DivineRPGTwilight.firewoodLeaves.blockID);
		world.setBlock(i + 11, j + 7, k + 4, DivineRPGTwilight.firewoodLeaves.blockID);
		world.setBlock(i + 11, j + 7, k + 5, DivineRPGTwilight.firewoodLeaves.blockID);
		world.setBlock(i + 11, j + 7, k + 12, DivineRPGTwilight.firewoodLeaves.blockID);
		world.setBlock(i + 11, j + 7, k + 13, DivineRPGTwilight.firewoodLeaves.blockID);
		world.setBlock(i + 11, j + 7, k + 14, DivineRPGTwilight.firewoodLeaves.blockID);
		world.setBlock(i + 11, j + 7, k + 15, DivineRPGTwilight.firewoodLeaves.blockID);
		world.setBlock(i + 11, j + 7, k + 16, DivineRPGTwilight.firewoodLeaves.blockID);
		world.setBlock(i + 11, j + 11, k + 8, DivineRPGTwilight.firewood.blockID);
		world.setBlock(i + 11, j + 11, k + 9, DivineRPGTwilight.firewood.blockID);
		world.setBlock(i + 11, j + 12, k + 8, DivineRPGTwilight.firewood.blockID);
		world.setBlock(i + 11, j + 12, k + 9, DivineRPGTwilight.firewood.blockID);
		world.setBlock(i + 11, j + 13, k + 8, DivineRPGTwilight.firewood.blockID);
		world.setBlock(i + 11, j + 13, k + 9, DivineRPGTwilight.firewood.blockID);
		world.setBlock(i + 12, j + 3, k + 8, DivineRPGTwilight.firewoodLeaves.blockID);
		world.setBlock(i + 12, j + 3, k + 9, DivineRPGTwilight.firewoodLeaves.blockID);
		world.setBlock(i + 12, j + 3, k + 10, DivineRPGTwilight.firewoodLeaves.blockID);
		world.setBlock(i + 12, j + 4, k + 2, DivineRPGTwilight.firewoodLeaves.blockID);
		world.setBlock(i + 12, j + 4, k + 3, DivineRPGTwilight.firewoodLeaves.blockID);
		world.setBlock(i + 12, j + 4, k + 4, DivineRPGTwilight.firewoodLeaves.blockID);
		world.setBlock(i + 12, j + 4, k + 8, DivineRPGTwilight.firewoodLeaves.blockID);
		world.setBlock(i + 12, j + 4, k + 9, DivineRPGTwilight.firewoodLeaves.blockID);
		world.setBlock(i + 12, j + 4, k + 10, DivineRPGTwilight.firewoodLeaves.blockID);
		world.setBlock(i + 12, j + 4, k + 13, DivineRPGTwilight.firewoodLeaves.blockID);
		world.setBlock(i + 12, j + 4, k + 14, DivineRPGTwilight.firewoodLeaves.blockID);
		world.setBlock(i + 12, j + 4, k + 15, DivineRPGTwilight.firewoodLeaves.blockID);
		world.setBlock(i + 12, j + 5, k + 2, DivineRPGTwilight.firewoodLeaves.blockID);
		world.setBlock(i + 12, j + 5, k + 3, DivineRPGTwilight.firewoodLeaves.blockID);
		world.setBlock(i + 12, j + 5, k + 4, DivineRPGTwilight.firewoodLeaves.blockID);
		world.setBlock(i + 12, j + 5, k + 8, DivineRPGTwilight.firewoodLeaves.blockID);
		world.setBlock(i + 12, j + 5, k + 9, DivineRPGTwilight.firewoodLeaves.blockID);
		world.setBlock(i + 12, j + 5, k + 10, DivineRPGTwilight.firewoodLeaves.blockID);
		world.setBlock(i + 12, j + 5, k + 13, DivineRPGTwilight.firewoodLeaves.blockID);
		world.setBlock(i + 12, j + 5, k + 14, DivineRPGTwilight.firewoodLeaves.blockID);
		world.setBlock(i + 12, j + 5, k + 15, DivineRPGTwilight.firewoodLeaves.blockID);
		world.setBlock(i + 12, j + 6, k + 2, DivineRPGTwilight.firewoodLeaves.blockID);
		world.setBlock(i + 12, j + 6, k + 3, DivineRPGTwilight.firewoodLeaves.blockID);
		world.setBlock(i + 12, j + 6, k + 4, DivineRPGTwilight.firewoodLeaves.blockID);
		world.setBlock(i + 12, j + 6, k + 13, DivineRPGTwilight.firewoodLeaves.blockID);
		world.setBlock(i + 12, j + 6, k + 14, DivineRPGTwilight.firewoodLeaves.blockID);
		world.setBlock(i + 12, j + 6, k + 15, DivineRPGTwilight.firewoodLeaves.blockID);
		world.setBlock(i + 12, j + 11, k + 8, DivineRPGTwilight.firewood.blockID);
		world.setBlock(i + 12, j + 11, k + 9, DivineRPGTwilight.firewood.blockID);
		world.setBlock(i + 12, j + 12, k + 8, DivineRPGTwilight.firewood.blockID);
		world.setBlock(i + 12, j + 12, k + 9, DivineRPGTwilight.firewood.blockID);
		world.setBlock(i + 13, j + 2, k + 7, DivineRPGTwilight.firewoodLeaves.blockID);
		world.setBlock(i + 13, j + 2, k + 8, DivineRPGTwilight.firewoodLeaves.blockID);
		world.setBlock(i + 13, j + 2, k + 9, DivineRPGTwilight.firewoodLeaves.blockID);
		world.setBlock(i + 13, j + 2, k + 10, DivineRPGTwilight.firewoodLeaves.blockID);
		world.setBlock(i + 13, j + 2, k + 11, DivineRPGTwilight.firewoodLeaves.blockID);
		world.setBlock(i + 13, j + 3, k + 7, DivineRPGTwilight.firewoodLeaves.blockID);
		world.setBlock(i + 13, j + 3, k + 8, DivineRPGTwilight.firewoodLeaves.blockID);
		world.setBlock(i + 13, j + 3, k + 9, DivineRPGTwilight.firewoodLeaves.blockID);
		world.setBlock(i + 13, j + 3, k + 10, DivineRPGTwilight.firewoodLeaves.blockID);
		world.setBlock(i + 13, j + 3, k + 11, DivineRPGTwilight.firewoodLeaves.blockID);
		world.setBlock(i + 13, j + 4, k + 7, DivineRPGTwilight.firewoodLeaves.blockID);
		world.setBlock(i + 13, j + 4, k + 8, DivineRPGTwilight.firewoodLeaves.blockID);
		world.setBlock(i + 13, j + 4, k + 9, DivineRPGTwilight.firewoodLeaves.blockID);
		world.setBlock(i + 13, j + 4, k + 10, DivineRPGTwilight.firewoodLeaves.blockID);
		world.setBlock(i + 13, j + 4, k + 11, DivineRPGTwilight.firewoodLeaves.blockID);
		world.setBlock(i + 13, j + 5, k + 7, DivineRPGTwilight.firewoodLeaves.blockID);
		world.setBlock(i + 13, j + 5, k + 8, DivineRPGTwilight.firewoodLeaves.blockID);
		world.setBlock(i + 13, j + 5, k + 9, DivineRPGTwilight.firewoodLeaves.blockID);
		world.setBlock(i + 13, j + 5, k + 10, DivineRPGTwilight.firewoodLeaves.blockID);
		world.setBlock(i + 13, j + 5, k + 11, DivineRPGTwilight.firewoodLeaves.blockID);
		world.setBlock(i + 13, j + 6, k + 7, DivineRPGTwilight.firewoodLeaves.blockID);
		world.setBlock(i + 13, j + 6, k + 8, DivineRPGTwilight.firewoodLeaves.blockID);
		world.setBlock(i + 13, j + 6, k + 9, DivineRPGTwilight.firewoodLeaves.blockID);
		world.setBlock(i + 13, j + 6, k + 10, DivineRPGTwilight.firewoodLeaves.blockID);
		world.setBlock(i + 13, j + 6, k + 11, DivineRPGTwilight.firewoodLeaves.blockID);
		world.setBlock(i + 13, j + 7, k + 8, DivineRPGTwilight.firewood.blockID);
		world.setBlock(i + 13, j + 7, k + 9, DivineRPGTwilight.firewood.blockID);
		world.setBlock(i + 13, j + 8, k + 8, DivineRPGTwilight.firewood.blockID);
		world.setBlock(i + 13, j + 8, k + 9, DivineRPGTwilight.firewood.blockID);
		world.setBlock(i + 13, j + 9, k + 8, DivineRPGTwilight.firewood.blockID);
		world.setBlock(i + 13, j + 9, k + 9, DivineRPGTwilight.firewood.blockID);
		world.setBlock(i + 13, j + 10, k + 8, DivineRPGTwilight.firewood.blockID);
		world.setBlock(i + 13, j + 10, k + 9, DivineRPGTwilight.firewood.blockID);
		world.setBlock(i + 13, j + 11, k + 8, DivineRPGTwilight.firewood.blockID);
		world.setBlock(i + 13, j + 11, k + 9, DivineRPGTwilight.firewood.blockID);
		world.setBlock(i + 13, j + 12, k + 8, DivineRPGTwilight.firewood.blockID);
		world.setBlock(i + 13, j + 12, k + 9, DivineRPGTwilight.firewood.blockID);
		world.setBlock(i + 14, j + 1, k + 8, DivineRPGTwilight.firewoodLeaves.blockID);
		world.setBlock(i + 14, j + 1, k + 9, DivineRPGTwilight.firewoodLeaves.blockID);
		world.setBlock(i + 14, j + 1, k + 10, DivineRPGTwilight.firewoodLeaves.blockID);
		world.setBlock(i + 14, j + 2, k + 7, DivineRPGTwilight.firewoodLeaves.blockID);
		world.setBlock(i + 14, j + 2, k + 8, DivineRPGTwilight.firewoodLeaves.blockID);
		world.setBlock(i + 14, j + 2, k + 9, DivineRPGTwilight.firewoodLeaves.blockID);
		world.setBlock(i + 14, j + 2, k + 10, DivineRPGTwilight.firewoodLeaves.blockID);
		world.setBlock(i + 14, j + 2, k + 11, DivineRPGTwilight.firewoodLeaves.blockID);
		world.setBlock(i + 14, j + 3, k + 6, DivineRPGTwilight.firewoodLeaves.blockID);
		world.setBlock(i + 14, j + 3, k + 7, DivineRPGTwilight.firewoodLeaves.blockID);
		world.setBlock(i + 14, j + 3, k + 8, DivineRPGTwilight.firewoodLeaves.blockID);
		world.setBlock(i + 14, j + 3, k + 9, DivineRPGTwilight.firewoodLeaves.blockID);
		world.setBlock(i + 14, j + 3, k + 10, DivineRPGTwilight.firewoodLeaves.blockID);
		world.setBlock(i + 14, j + 3, k + 11, DivineRPGTwilight.firewoodLeaves.blockID);
		world.setBlock(i + 14, j + 3, k + 12, DivineRPGTwilight.firewoodLeaves.blockID);
		world.setBlock(i + 14, j + 4, k + 6, DivineRPGTwilight.firewoodLeaves.blockID);
		world.setBlock(i + 14, j + 4, k + 7, DivineRPGTwilight.firewoodLeaves.blockID);
		world.setBlock(i + 14, j + 4, k + 8, DivineRPGTwilight.firewoodLeaves.blockID);
		world.setBlock(i + 14, j + 4, k + 9, DivineRPGTwilight.firewoodLeaves.blockID);
		world.setBlock(i + 14, j + 4, k + 10, DivineRPGTwilight.firewoodLeaves.blockID);
		world.setBlock(i + 14, j + 4, k + 11, DivineRPGTwilight.firewoodLeaves.blockID);
		world.setBlock(i + 14, j + 4, k + 12, DivineRPGTwilight.firewoodLeaves.blockID);
		world.setBlock(i + 14, j + 5, k + 6, DivineRPGTwilight.firewoodLeaves.blockID);
		world.setBlock(i + 14, j + 5, k + 7, DivineRPGTwilight.firewoodLeaves.blockID);
		world.setBlock(i + 14, j + 5, k + 8, DivineRPGTwilight.firewoodLeaves.blockID);
		world.setBlock(i + 14, j + 5, k + 9, DivineRPGTwilight.firewoodLeaves.blockID);
		world.setBlock(i + 14, j + 5, k + 10, DivineRPGTwilight.firewoodLeaves.blockID);
		world.setBlock(i + 14, j + 5, k + 11, DivineRPGTwilight.firewoodLeaves.blockID);
		world.setBlock(i + 14, j + 5, k + 12, DivineRPGTwilight.firewoodLeaves.blockID);
		world.setBlock(i + 14, j + 6, k + 7, DivineRPGTwilight.firewoodLeaves.blockID);
		world.setBlock(i + 14, j + 6, k + 8, DivineRPGTwilight.firewoodLeaves.blockID);
		world.setBlock(i + 14, j + 6, k + 9, DivineRPGTwilight.firewoodLeaves.blockID);
		world.setBlock(i + 14, j + 6, k + 10, DivineRPGTwilight.firewoodLeaves.blockID);
		world.setBlock(i + 14, j + 6, k + 11, DivineRPGTwilight.firewoodLeaves.blockID);
		world.setBlock(i + 14, j + 7, k + 8, DivineRPGTwilight.firewoodLeaves.blockID);
		world.setBlock(i + 14, j + 7, k + 9, DivineRPGTwilight.firewoodLeaves.blockID);
		world.setBlock(i + 14, j + 7, k + 10, DivineRPGTwilight.firewoodLeaves.blockID);
		world.setBlock(i + 14, j + 8, k + 8, DivineRPGTwilight.firewood.blockID);
		world.setBlock(i + 14, j + 8, k + 9, DivineRPGTwilight.firewood.blockID);
		world.setBlock(i + 14, j + 9, k + 8, DivineRPGTwilight.firewood.blockID);
		world.setBlock(i + 14, j + 9, k + 9, DivineRPGTwilight.firewood.blockID);
		world.setBlock(i + 14, j + 10, k + 8, DivineRPGTwilight.firewood.blockID);
		world.setBlock(i + 14, j + 10, k + 9, DivineRPGTwilight.firewood.blockID);
		world.setBlock(i + 14, j + 11, k + 8, DivineRPGTwilight.firewood.blockID);
		world.setBlock(i + 14, j + 11, k + 9, DivineRPGTwilight.firewood.blockID);
		world.setBlock(i + 14, j + 12, k + 8, DivineRPGTwilight.firewood.blockID);
		world.setBlock(i + 14, j + 12, k + 9, DivineRPGTwilight.firewood.blockID);
		world.setBlock(i + 15, j + 1, k + 8, DivineRPGTwilight.firewoodLeaves.blockID);
		world.setBlock(i + 15, j + 1, k + 9, DivineRPGTwilight.firewoodLeaves.blockID);
		world.setBlock(i + 15, j + 1, k + 10, DivineRPGTwilight.firewoodLeaves.blockID);
		world.setBlock(i + 15, j + 2, k + 7, DivineRPGTwilight.firewoodLeaves.blockID);
		world.setBlock(i + 15, j + 2, k + 8, DivineRPGTwilight.firewoodLeaves.blockID);
		world.setBlock(i + 15, j + 2, k + 9, DivineRPGTwilight.firewoodLeaves.blockID);
		world.setBlock(i + 15, j + 2, k + 10, DivineRPGTwilight.firewoodLeaves.blockID);
		world.setBlock(i + 15, j + 2, k + 11, DivineRPGTwilight.firewoodLeaves.blockID);
		world.setBlock(i + 15, j + 3, k + 6, DivineRPGTwilight.firewoodLeaves.blockID);
		world.setBlock(i + 15, j + 3, k + 7, DivineRPGTwilight.firewoodLeaves.blockID);
		world.setBlock(i + 15, j + 3, k + 8, DivineRPGTwilight.firewoodLeaves.blockID);
		world.setBlock(i + 15, j + 3, k + 9, DivineRPGTwilight.firewoodLeaves.blockID);
		world.setBlock(i + 15, j + 3, k + 10, DivineRPGTwilight.firewoodLeaves.blockID);
		world.setBlock(i + 15, j + 3, k + 11, DivineRPGTwilight.firewoodLeaves.blockID);
		world.setBlock(i + 15, j + 3, k + 12, DivineRPGTwilight.firewoodLeaves.blockID);
		world.setBlock(i + 15, j + 4, k + 6, DivineRPGTwilight.firewoodLeaves.blockID);
		world.setBlock(i + 15, j + 4, k + 7, DivineRPGTwilight.firewoodLeaves.blockID);
		world.setBlock(i + 15, j + 4, k + 8, DivineRPGTwilight.firewoodLeaves.blockID);
		world.setBlock(i + 15, j + 4, k + 9, DivineRPGTwilight.firewoodLeaves.blockID);
		world.setBlock(i + 15, j + 4, k + 10, DivineRPGTwilight.firewoodLeaves.blockID);
		world.setBlock(i + 15, j + 4, k + 11, DivineRPGTwilight.firewoodLeaves.blockID);
		world.setBlock(i + 15, j + 4, k + 12, DivineRPGTwilight.firewoodLeaves.blockID);
		world.setBlock(i + 15, j + 5, k + 6, DivineRPGTwilight.firewoodLeaves.blockID);
		world.setBlock(i + 15, j + 5, k + 7, DivineRPGTwilight.firewoodLeaves.blockID);
		world.setBlock(i + 15, j + 5, k + 8, DivineRPGTwilight.firewoodLeaves.blockID);
		world.setBlock(i + 15, j + 5, k + 9, DivineRPGTwilight.firewoodLeaves.blockID);
		world.setBlock(i + 15, j + 5, k + 10, DivineRPGTwilight.firewoodLeaves.blockID);
		world.setBlock(i + 15, j + 5, k + 11, DivineRPGTwilight.firewoodLeaves.blockID);
		world.setBlock(i + 15, j + 5, k + 12, DivineRPGTwilight.firewoodLeaves.blockID);
		world.setBlock(i + 15, j + 6, k + 7, DivineRPGTwilight.firewoodLeaves.blockID);
		world.setBlock(i + 15, j + 6, k + 8, DivineRPGTwilight.firewoodLeaves.blockID);
		world.setBlock(i + 15, j + 6, k + 9, DivineRPGTwilight.firewoodLeaves.blockID);
		world.setBlock(i + 15, j + 6, k + 10, DivineRPGTwilight.firewoodLeaves.blockID);
		world.setBlock(i + 15, j + 6, k + 11, DivineRPGTwilight.firewoodLeaves.blockID);
		world.setBlock(i + 15, j + 7, k + 8, DivineRPGTwilight.firewoodLeaves.blockID);
		world.setBlock(i + 15, j + 7, k + 9, DivineRPGTwilight.firewoodLeaves.blockID);
		world.setBlock(i + 15, j + 7, k + 10, DivineRPGTwilight.firewoodLeaves.blockID);
		world.setBlock(i + 16, j + 1, k + 8, DivineRPGTwilight.firewoodLeaves.blockID);
		world.setBlock(i + 16, j + 1, k + 9, DivineRPGTwilight.firewoodLeaves.blockID);
		world.setBlock(i + 16, j + 1, k + 10, DivineRPGTwilight.firewoodLeaves.blockID);
		world.setBlock(i + 16, j + 2, k + 7, DivineRPGTwilight.firewoodLeaves.blockID);
		world.setBlock(i + 16, j + 2, k + 8, DivineRPGTwilight.firewoodLeaves.blockID);
		world.setBlock(i + 16, j + 2, k + 9, DivineRPGTwilight.firewoodLeaves.blockID);
		world.setBlock(i + 16, j + 2, k + 10, DivineRPGTwilight.firewoodLeaves.blockID);
		world.setBlock(i + 16, j + 2, k + 11, DivineRPGTwilight.firewoodLeaves.blockID);
		world.setBlock(i + 16, j + 3, k + 6, DivineRPGTwilight.firewoodLeaves.blockID);
		world.setBlock(i + 16, j + 3, k + 7, DivineRPGTwilight.firewoodLeaves.blockID);
		world.setBlock(i + 16, j + 3, k + 8, DivineRPGTwilight.firewoodLeaves.blockID);
		world.setBlock(i + 16, j + 3, k + 9, DivineRPGTwilight.firewoodLeaves.blockID);
		world.setBlock(i + 16, j + 3, k + 10, DivineRPGTwilight.firewoodLeaves.blockID);
		world.setBlock(i + 16, j + 3, k + 11, DivineRPGTwilight.firewoodLeaves.blockID);
		world.setBlock(i + 16, j + 3, k + 12, DivineRPGTwilight.firewoodLeaves.blockID);
		world.setBlock(i + 16, j + 4, k + 6, DivineRPGTwilight.firewoodLeaves.blockID);
		world.setBlock(i + 16, j + 4, k + 7, DivineRPGTwilight.firewoodLeaves.blockID);
		world.setBlock(i + 16, j + 4, k + 8, DivineRPGTwilight.firewoodLeaves.blockID);
		world.setBlock(i + 16, j + 4, k + 9, DivineRPGTwilight.firewoodLeaves.blockID);
		world.setBlock(i + 16, j + 4, k + 10, DivineRPGTwilight.firewoodLeaves.blockID);
		world.setBlock(i + 16, j + 4, k + 11, DivineRPGTwilight.firewoodLeaves.blockID);
		world.setBlock(i + 16, j + 4, k + 12, DivineRPGTwilight.firewoodLeaves.blockID);
		world.setBlock(i + 16, j + 5, k + 6, DivineRPGTwilight.firewoodLeaves.blockID);
		world.setBlock(i + 16, j + 5, k + 7, DivineRPGTwilight.firewoodLeaves.blockID);
		world.setBlock(i + 16, j + 5, k + 8, DivineRPGTwilight.firewoodLeaves.blockID);
		world.setBlock(i + 16, j + 5, k + 9, DivineRPGTwilight.firewoodLeaves.blockID);
		world.setBlock(i + 16, j + 5, k + 10, DivineRPGTwilight.firewoodLeaves.blockID);
		world.setBlock(i + 16, j + 5, k + 11, DivineRPGTwilight.firewoodLeaves.blockID);
		world.setBlock(i + 16, j + 5, k + 12, DivineRPGTwilight.firewoodLeaves.blockID);
		world.setBlock(i + 16, j + 6, k + 7, DivineRPGTwilight.firewoodLeaves.blockID);
		world.setBlock(i + 16, j + 6, k + 8, DivineRPGTwilight.firewoodLeaves.blockID);
		world.setBlock(i + 16, j + 6, k + 9, DivineRPGTwilight.firewoodLeaves.blockID);
		world.setBlock(i + 16, j + 6, k + 10, DivineRPGTwilight.firewoodLeaves.blockID);
		world.setBlock(i + 16, j + 6, k + 11, DivineRPGTwilight.firewoodLeaves.blockID);
		world.setBlock(i + 16, j + 7, k + 8, DivineRPGTwilight.firewoodLeaves.blockID);
		world.setBlock(i + 16, j + 7, k + 9, DivineRPGTwilight.firewoodLeaves.blockID);
		world.setBlock(i + 16, j + 7, k + 10, DivineRPGTwilight.firewoodLeaves.blockID);
		world.setBlock(i + 17, j + 2, k + 7, DivineRPGTwilight.firewoodLeaves.blockID);
		world.setBlock(i + 17, j + 2, k + 8, DivineRPGTwilight.firewoodLeaves.blockID);
		world.setBlock(i + 17, j + 2, k + 9, DivineRPGTwilight.firewoodLeaves.blockID);
		world.setBlock(i + 17, j + 2, k + 10, DivineRPGTwilight.firewoodLeaves.blockID);
		world.setBlock(i + 17, j + 2, k + 11, DivineRPGTwilight.firewoodLeaves.blockID);
		world.setBlock(i + 17, j + 3, k + 7, DivineRPGTwilight.firewoodLeaves.blockID);
		world.setBlock(i + 17, j + 3, k + 8, DivineRPGTwilight.firewoodLeaves.blockID);
		world.setBlock(i + 17, j + 3, k + 9, DivineRPGTwilight.firewoodLeaves.blockID);
		world.setBlock(i + 17, j + 3, k + 10, DivineRPGTwilight.firewoodLeaves.blockID);
		world.setBlock(i + 17, j + 3, k + 11, DivineRPGTwilight.firewoodLeaves.blockID);
		world.setBlock(i + 17, j + 4, k + 7, DivineRPGTwilight.firewoodLeaves.blockID);
		world.setBlock(i + 17, j + 4, k + 8, DivineRPGTwilight.firewoodLeaves.blockID);
		world.setBlock(i + 17, j + 4, k + 9, DivineRPGTwilight.firewoodLeaves.blockID);
		world.setBlock(i + 17, j + 4, k + 10, DivineRPGTwilight.firewoodLeaves.blockID);
		world.setBlock(i + 17, j + 4, k + 11, DivineRPGTwilight.firewoodLeaves.blockID);
		world.setBlock(i + 17, j + 5, k + 7, DivineRPGTwilight.firewoodLeaves.blockID);
		world.setBlock(i + 17, j + 5, k + 8, DivineRPGTwilight.firewoodLeaves.blockID);
		world.setBlock(i + 17, j + 5, k + 9, DivineRPGTwilight.firewoodLeaves.blockID);
		world.setBlock(i + 17, j + 5, k + 10, DivineRPGTwilight.firewoodLeaves.blockID);
		world.setBlock(i + 17, j + 5, k + 11, DivineRPGTwilight.firewoodLeaves.blockID);
		world.setBlock(i + 17, j + 6, k + 7, DivineRPGTwilight.firewoodLeaves.blockID);
		world.setBlock(i + 17, j + 6, k + 8, DivineRPGTwilight.firewoodLeaves.blockID);
		world.setBlock(i + 17, j + 6, k + 9, DivineRPGTwilight.firewoodLeaves.blockID);
		world.setBlock(i + 17, j + 6, k + 10, DivineRPGTwilight.firewoodLeaves.blockID);
		world.setBlock(i + 17, j + 6, k + 11, DivineRPGTwilight.firewoodLeaves.blockID);
		world.setBlock(i + 18, j + 3, k + 8, DivineRPGTwilight.firewoodLeaves.blockID);
		world.setBlock(i + 18, j + 3, k + 9, DivineRPGTwilight.firewoodLeaves.blockID);
		world.setBlock(i + 18, j + 3, k + 10, DivineRPGTwilight.firewoodLeaves.blockID);
		world.setBlock(i + 18, j + 4, k + 8, DivineRPGTwilight.firewoodLeaves.blockID);
		world.setBlock(i + 18, j + 4, k + 9, DivineRPGTwilight.firewoodLeaves.blockID);
		world.setBlock(i + 18, j + 4, k + 10, DivineRPGTwilight.firewoodLeaves.blockID);
		world.setBlock(i + 18, j + 5, k + 8, DivineRPGTwilight.firewoodLeaves.blockID);
		world.setBlock(i + 18, j + 5, k + 9, DivineRPGTwilight.firewoodLeaves.blockID);
		world.setBlock(i + 18, j + 5, k + 10, DivineRPGTwilight.firewoodLeaves.blockID);

		return true;
	}
}