/*
*** MADE BY MITHION'S .SCHEMATIC TO JAVA CONVERTING TOOL v1.6 ***
*/

package xolova.blued00r.divinerpg.generation.vethea.layer4;
import java.util.Random;

import xolova.blued00r.divinerpg.DivineRPG;

import net.minecraft.world.World;
import net.minecraft.world.gen.feature.WorldGenerator;

public class WreckHall extends WorldGenerator
{
	protected int[] GetValidSpawnBlocks() {
		return new int[] {
		};
	}

	public WreckHall() { }

	public boolean generate(World world, Random rand, int i, int j, int k) {

		world.setBlock(i + 0, j + 0, k + 16, DivineRPGTwilight.hallWall.blockID);
		world.setBlock(i + 0, j + 0, k + 17, DivineRPGTwilight.firecrystal.blockID);
		world.setBlock(i + 0, j + 0, k + 18, DivineRPGTwilight.firecrystal.blockID);
		world.setBlock(i + 0, j + 0, k + 19, DivineRPGTwilight.hallWall.blockID);
		world.setBlock(i + 0, j + 0, k + 35, DivineRPGTwilight.darkEverstone.blockID);
		world.setBlock(i + 0, j + 1, k + 16, DivineRPGTwilight.hallWall.blockID);
		world.setBlock(i + 0, j + 1, k + 19, DivineRPGTwilight.hallWall.blockID);
		world.setBlock(i + 0, j + 1, k + 35, DivineRPGTwilight.darkEverstone.blockID);
		world.setBlock(i + 0, j + 2, k + 16, DivineRPGTwilight.hallWall.blockID);
		world.setBlock(i + 0, j + 2, k + 19, DivineRPGTwilight.hallWall.blockID);
		world.setBlock(i + 0, j + 2, k + 35, DivineRPGTwilight.darkEverstone.blockID);
		world.setBlock(i + 0, j + 3, k + 16, DivineRPGTwilight.hallWall.blockID);
		world.setBlock(i + 0, j + 3, k + 17, DivineRPGTwilight.hallWall.blockID);
		world.setBlock(i + 0, j + 3, k + 18, DivineRPGTwilight.hallWall.blockID);
		world.setBlock(i + 0, j + 3, k + 19, DivineRPGTwilight.hallWall.blockID);
		world.setBlock(i + 0, j + 3, k + 35, DivineRPGTwilight.darkEverstone.blockID);
		world.setBlock(i + 0, j + 4, k + 35, DivineRPGTwilight.darkEverstone.blockID);
		world.setBlock(i + 1, j + 0, k + 16, DivineRPGTwilight.hallWall.blockID);
		world.setBlock(i + 1, j + 0, k + 17, DivineRPGTwilight.firecrystal.blockID);
		world.setBlock(i + 1, j + 0, k + 18, DivineRPGTwilight.firecrystal.blockID);
		world.setBlock(i + 1, j + 0, k + 19, DivineRPGTwilight.hallWall.blockID);
		world.setBlock(i + 1, j + 0, k + 20, DivineRPGTwilight.hallWall.blockID);
		world.setBlock(i + 1, j + 0, k + 21, DivineRPGTwilight.hallWall.blockID);
		world.setBlock(i + 1, j + 0, k + 22, DivineRPGTwilight.hallWall.blockID);
		world.setBlock(i + 1, j + 0, k + 23, DivineRPGTwilight.hallWall.blockID);
		world.setBlock(i + 1, j + 0, k + 24, DivineRPGTwilight.hallWall.blockID);
		world.setBlock(i + 1, j + 0, k + 25, DivineRPGTwilight.hallWall.blockID);
		world.setBlock(i + 1, j + 0, k + 26, DivineRPGTwilight.hallWall.blockID);
		world.setBlock(i + 1, j + 0, k + 27, DivineRPGTwilight.hallWall.blockID);
		world.setBlock(i + 1, j + 0, k + 28, DivineRPGTwilight.hallWall.blockID);
		world.setBlock(i + 1, j + 0, k + 29, DivineRPGTwilight.hallWall.blockID);
		world.setBlock(i + 1, j + 0, k + 30, DivineRPGTwilight.hallWall.blockID);
		world.setBlock(i + 1, j + 0, k + 31, DivineRPGTwilight.hallWall.blockID);
		world.setBlock(i + 1, j + 0, k + 32, DivineRPGTwilight.hallWall.blockID);
		world.setBlock(i + 1, j + 0, k + 33, DivineRPGTwilight.hallWall.blockID);
		world.setBlock(i + 1, j + 0, k + 34, DivineRPGTwilight.hallWall.blockID);
		world.setBlock(i + 1, j + 0, k + 35, DivineRPGTwilight.hallWall.blockID);
		world.setBlock(i + 1, j + 0, k + 36, DivineRPGTwilight.hallWall.blockID);
		world.setBlock(i + 1, j + 1, k + 16, DivineRPGTwilight.hallWall.blockID);
		world.setBlock(i + 1, j + 1, k + 19, DivineRPGTwilight.hallWall.blockID);
		world.setBlock(i + 1, j + 1, k + 20, DivineRPGTwilight.hallWall.blockID);
		world.setBlock(i + 1, j + 1, k + 21, DivineRPGTwilight.hallWall.blockID);
		world.setBlock(i + 1, j + 1, k + 22, DivineRPGTwilight.hallWall.blockID);
		world.setBlock(i + 1, j + 1, k + 23, DivineRPGTwilight.hallWall.blockID);
		world.setBlock(i + 1, j + 1, k + 24, DivineRPGTwilight.hallWall.blockID);
		world.setBlock(i + 1, j + 1, k + 25, DivineRPGTwilight.hallWall.blockID);
		world.setBlock(i + 1, j + 1, k + 26, DivineRPGTwilight.hallWall.blockID);
		world.setBlock(i + 1, j + 1, k + 27, DivineRPGTwilight.hallWall.blockID);
		world.setBlock(i + 1, j + 1, k + 28, DivineRPGTwilight.hallWall.blockID);
		world.setBlock(i + 1, j + 1, k + 29, DivineRPGTwilight.hallWall.blockID);
		world.setBlock(i + 1, j + 1, k + 30, DivineRPGTwilight.hallWall.blockID);
		world.setBlock(i + 1, j + 1, k + 31, DivineRPGTwilight.hallWall.blockID);
		world.setBlock(i + 1, j + 1, k + 32, DivineRPGTwilight.hallWall.blockID);
		world.setBlock(i + 1, j + 1, k + 33, DivineRPGTwilight.hallWall.blockID);
		world.setBlock(i + 1, j + 1, k + 34, DivineRPGTwilight.hallWall.blockID);
		world.setBlock(i + 1, j + 1, k + 35, DivineRPGTwilight.hallWall.blockID);
		world.setBlock(i + 1, j + 1, k + 36, DivineRPGTwilight.hallWall.blockID);
		world.setBlock(i + 1, j + 2, k + 16, DivineRPGTwilight.hallWall.blockID);
		world.setBlock(i + 1, j + 2, k + 19, DivineRPGTwilight.hallWall.blockID);
		world.setBlock(i + 1, j + 2, k + 20, DivineRPGTwilight.hallWall.blockID);
		world.setBlock(i + 1, j + 2, k + 21, DivineRPGTwilight.hallWall.blockID);
		world.setBlock(i + 1, j + 2, k + 22, DivineRPGTwilight.hallWall.blockID);
		world.setBlock(i + 1, j + 2, k + 23, DivineRPGTwilight.hallWall.blockID);
		world.setBlock(i + 1, j + 2, k + 24, DivineRPGTwilight.hallWall.blockID);
		world.setBlock(i + 1, j + 2, k + 25, DivineRPGTwilight.hallWall.blockID);
		world.setBlock(i + 1, j + 2, k + 26, DivineRPGTwilight.hallWall.blockID);
		world.setBlock(i + 1, j + 2, k + 27, DivineRPGTwilight.hallWall.blockID);
		world.setBlock(i + 1, j + 2, k + 28, DivineRPGTwilight.hallWall.blockID);
		world.setBlock(i + 1, j + 2, k + 29, DivineRPGTwilight.hallWall.blockID);
		world.setBlock(i + 1, j + 2, k + 30, DivineRPGTwilight.hallWall.blockID);
		world.setBlock(i + 1, j + 2, k + 31, DivineRPGTwilight.hallWall.blockID);
		world.setBlock(i + 1, j + 2, k + 32, DivineRPGTwilight.hallWall.blockID);
		world.setBlock(i + 1, j + 2, k + 33, DivineRPGTwilight.hallWall.blockID);
		world.setBlock(i + 1, j + 2, k + 34, DivineRPGTwilight.hallWall.blockID);
		world.setBlock(i + 1, j + 2, k + 35, DivineRPGTwilight.hallWall.blockID);
		world.setBlock(i + 1, j + 2, k + 36, DivineRPGTwilight.hallWall.blockID);
		world.setBlock(i + 1, j + 3, k + 16, DivineRPGTwilight.hallWall.blockID);
		world.setBlock(i + 1, j + 3, k + 17, DivineRPGTwilight.hallWall.blockID);
		world.setBlock(i + 1, j + 3, k + 18, DivineRPGTwilight.hallWall.blockID);
		world.setBlock(i + 1, j + 3, k + 19, DivineRPGTwilight.hallWall.blockID);
		world.setBlock(i + 1, j + 3, k + 20, DivineRPGTwilight.hallWall.blockID);
		world.setBlock(i + 1, j + 3, k + 21, DivineRPGTwilight.hallWall.blockID);
		world.setBlock(i + 1, j + 3, k + 22, DivineRPGTwilight.hallWall.blockID);
		world.setBlock(i + 1, j + 3, k + 23, DivineRPGTwilight.hallWall.blockID);
		world.setBlock(i + 1, j + 3, k + 24, DivineRPGTwilight.hallWall.blockID);
		world.setBlock(i + 1, j + 3, k + 25, DivineRPGTwilight.hallWall.blockID);
		world.setBlock(i + 1, j + 3, k + 26, DivineRPGTwilight.hallWall.blockID);
		world.setBlock(i + 1, j + 3, k + 27, DivineRPGTwilight.hallWall.blockID);
		world.setBlock(i + 1, j + 3, k + 28, DivineRPGTwilight.hallWall.blockID);
		world.setBlock(i + 1, j + 3, k + 29, DivineRPGTwilight.hallWall.blockID);
		world.setBlock(i + 1, j + 3, k + 30, DivineRPGTwilight.hallWall.blockID);
		world.setBlock(i + 1, j + 3, k + 31, DivineRPGTwilight.hallWall.blockID);
		world.setBlock(i + 1, j + 3, k + 32, DivineRPGTwilight.hallWall.blockID);
		world.setBlock(i + 1, j + 3, k + 33, DivineRPGTwilight.hallWall.blockID);
		world.setBlock(i + 1, j + 3, k + 34, DivineRPGTwilight.hallWall.blockID);
		world.setBlock(i + 1, j + 3, k + 35, DivineRPGTwilight.hallWall.blockID);
		world.setBlock(i + 1, j + 3, k + 36, DivineRPGTwilight.hallWall.blockID);
		world.setBlock(i + 1, j + 4, k + 3, DivineRPGTwilight.darkEverstone.blockID);
		world.setBlock(i + 1, j + 4, k + 7, DivineRPGTwilight.darkEverstone.blockID);
		world.setBlock(i + 1, j + 4, k + 9, DivineRPGTwilight.darkEverstone.blockID);
		world.setBlock(i + 1, j + 4, k + 13, DivineRPGTwilight.darkEverstone.blockID);
		world.setBlock(i + 1, j + 4, k + 35, DivineRPGTwilight.darkEverstone.blockID);
		world.setBlock(i + 1, j + 5, k + 3, DivineRPGTwilight.darkEverstone.blockID);
		world.setBlock(i + 1, j + 5, k + 7, DivineRPGTwilight.darkEverstone.blockID);
		world.setBlock(i + 1, j + 5, k + 9, DivineRPGTwilight.darkEverstone.blockID);
		world.setBlock(i + 1, j + 5, k + 13, DivineRPGTwilight.darkEverstone.blockID);
		world.setBlock(i + 1, j + 6, k + 3, DivineRPGTwilight.darkEverstone.blockID);
		world.setBlock(i + 1, j + 6, k + 7, DivineRPGTwilight.darkEverstone.blockID);
		world.setBlock(i + 1, j + 6, k + 9, DivineRPGTwilight.darkEverstone.blockID);
		world.setBlock(i + 1, j + 6, k + 13, DivineRPGTwilight.darkEverstone.blockID);
		world.setBlock(i + 1, j + 7, k + 2, DivineRPGTwilight.hallWall.blockID);
		world.setBlock(i + 1, j + 7, k + 3, DivineRPGTwilight.hallWall.blockID);
		world.setBlock(i + 1, j + 7, k + 4, DivineRPGTwilight.hallWall.blockID);
		world.setBlock(i + 1, j + 7, k + 5, DivineRPGTwilight.hallWall.blockID);
		world.setBlock(i + 1, j + 7, k + 6, DivineRPGTwilight.hallWall.blockID);
		world.setBlock(i + 1, j + 7, k + 7, DivineRPGTwilight.hallWall.blockID);
		world.setBlock(i + 1, j + 7, k + 8, DivineRPGTwilight.hallWall.blockID);
		world.setBlock(i + 1, j + 7, k + 9, DivineRPGTwilight.hallWall.blockID);
		world.setBlock(i + 1, j + 7, k + 10, DivineRPGTwilight.hallWall.blockID);
		world.setBlock(i + 1, j + 7, k + 11, DivineRPGTwilight.hallWall.blockID);
		world.setBlock(i + 1, j + 7, k + 12, DivineRPGTwilight.hallWall.blockID);
		world.setBlock(i + 1, j + 7, k + 13, DivineRPGTwilight.hallWall.blockID);
		world.setBlock(i + 1, j + 7, k + 14, DivineRPGTwilight.hallWall.blockID);
		world.setBlock(i + 2, j + 0, k + 3, DivineRPGTwilight.darkEverstone.blockID);
		world.setBlock(i + 2, j + 0, k + 7, DivineRPGTwilight.darkEverstone.blockID);
		world.setBlock(i + 2, j + 0, k + 9, DivineRPGTwilight.darkEverstone.blockID);
		world.setBlock(i + 2, j + 0, k + 13, DivineRPGTwilight.darkEverstone.blockID);
		world.setBlock(i + 2, j + 0, k + 16, DivineRPGTwilight.hallWall.blockID);
		world.setBlock(i + 2, j + 0, k + 17, DivineRPGTwilight.firecrystal.blockID);
		world.setBlock(i + 2, j + 0, k + 18, DivineRPGTwilight.firecrystal.blockID);
		world.setBlock(i + 2, j + 0, k + 19, DivineRPGTwilight.firecrystal.blockID);
		world.setBlock(i + 2, j + 0, k + 20, DivineRPGTwilight.firecrystal.blockID);
		world.setBlock(i + 2, j + 0, k + 21, DivineRPGTwilight.firecrystal.blockID);
		world.setBlock(i + 2, j + 0, k + 22, DivineRPGTwilight.firecrystal.blockID);
		world.setBlock(i + 2, j + 0, k + 23, DivineRPGTwilight.firecrystal.blockID);
		world.setBlock(i + 2, j + 0, k + 24, DivineRPGTwilight.firecrystal.blockID);
		world.setBlock(i + 2, j + 0, k + 25, DivineRPGTwilight.firecrystal.blockID);
		world.setBlock(i + 2, j + 0, k + 26, DivineRPGTwilight.firecrystal.blockID);
		world.setBlock(i + 2, j + 0, k + 27, DivineRPGTwilight.firecrystal.blockID);
		world.setBlock(i + 2, j + 0, k + 28, DivineRPGTwilight.firecrystal.blockID);
		world.setBlock(i + 2, j + 0, k + 29, DivineRPGTwilight.firecrystal.blockID);
		world.setBlock(i + 2, j + 0, k + 30, DivineRPGTwilight.firecrystal.blockID);
		world.setBlock(i + 2, j + 0, k + 31, DivineRPGTwilight.firecrystal.blockID);
		world.setBlock(i + 2, j + 0, k + 32, DivineRPGTwilight.firecrystal.blockID);
		world.setBlock(i + 2, j + 0, k + 33, DivineRPGTwilight.firecrystal.blockID);
		world.setBlock(i + 2, j + 0, k + 34, DivineRPGTwilight.firecrystal.blockID);
		world.setBlock(i + 2, j + 0, k + 35, DivineRPGTwilight.firecrystal.blockID);
		world.setBlock(i + 2, j + 0, k + 36, DivineRPGTwilight.hallWall.blockID);
		world.setBlock(i + 2, j + 0, k + 37, DivineRPGTwilight.darkEverstone.blockID);
		world.setBlock(i + 2, j + 1, k + 3, DivineRPGTwilight.darkEverstone.blockID);
		world.setBlock(i + 2, j + 1, k + 7, DivineRPGTwilight.darkEverstone.blockID);
		world.setBlock(i + 2, j + 1, k + 9, DivineRPGTwilight.darkEverstone.blockID);
		world.setBlock(i + 2, j + 1, k + 13, DivineRPGTwilight.darkEverstone.blockID);
		world.setBlock(i + 2, j + 1, k + 16, DivineRPGTwilight.hallWall.blockID);
		world.setBlock(i + 2, j + 1, k + 36, DivineRPGTwilight.hallWall.blockID);
		world.setBlock(i + 2, j + 1, k + 37, DivineRPGTwilight.darkEverstone.blockID);
		world.setBlock(i + 2, j + 2, k + 3, DivineRPGTwilight.darkEverstone.blockID);
		world.setBlock(i + 2, j + 2, k + 7, DivineRPGTwilight.darkEverstone.blockID);
		world.setBlock(i + 2, j + 2, k + 9, DivineRPGTwilight.darkEverstone.blockID);
		world.setBlock(i + 2, j + 2, k + 13, DivineRPGTwilight.darkEverstone.blockID);
		world.setBlock(i + 2, j + 2, k + 16, DivineRPGTwilight.hallWall.blockID);
		world.setBlock(i + 2, j + 2, k + 36, DivineRPGTwilight.hallWall.blockID);
		world.setBlock(i + 2, j + 2, k + 37, DivineRPGTwilight.darkEverstone.blockID);
		world.setBlock(i + 2, j + 3, k + 3, DivineRPGTwilight.darkEverstone.blockID);
		world.setBlock(i + 2, j + 3, k + 7, DivineRPGTwilight.darkEverstone.blockID);
		world.setBlock(i + 2, j + 3, k + 9, DivineRPGTwilight.darkEverstone.blockID);
		world.setBlock(i + 2, j + 3, k + 13, DivineRPGTwilight.darkEverstone.blockID);
		world.setBlock(i + 2, j + 3, k + 16, DivineRPGTwilight.hallWall.blockID);
		world.setBlock(i + 2, j + 3, k + 17, DivineRPGTwilight.hallWall.blockID);
		world.setBlock(i + 2, j + 3, k + 18, DivineRPGTwilight.hallWall.blockID);
		world.setBlock(i + 2, j + 3, k + 19, DivineRPGTwilight.hallWall.blockID);
		world.setBlock(i + 2, j + 3, k + 20, DivineRPGTwilight.hallWall.blockID);
		world.setBlock(i + 2, j + 3, k + 21, DivineRPGTwilight.hallWall.blockID);
		world.setBlock(i + 2, j + 3, k + 22, DivineRPGTwilight.hallWall.blockID);
		world.setBlock(i + 2, j + 3, k + 23, DivineRPGTwilight.hallWall.blockID);
		world.setBlock(i + 2, j + 3, k + 24, DivineRPGTwilight.hallWall.blockID);
		world.setBlock(i + 2, j + 3, k + 25, DivineRPGTwilight.hallWall.blockID);
		world.setBlock(i + 2, j + 3, k + 26, DivineRPGTwilight.hallWall.blockID);
		world.setBlock(i + 2, j + 3, k + 27, DivineRPGTwilight.hallWall.blockID);
		world.setBlock(i + 2, j + 3, k + 28, DivineRPGTwilight.hallWall.blockID);
		world.setBlock(i + 2, j + 3, k + 29, DivineRPGTwilight.hallWall.blockID);
		world.setBlock(i + 2, j + 3, k + 30, DivineRPGTwilight.hallWall.blockID);
		world.setBlock(i + 2, j + 3, k + 31, DivineRPGTwilight.hallWall.blockID);
		world.setBlock(i + 2, j + 3, k + 32, DivineRPGTwilight.hallWall.blockID);
		world.setBlock(i + 2, j + 3, k + 33, DivineRPGTwilight.hallWall.blockID);
		world.setBlock(i + 2, j + 3, k + 34, DivineRPGTwilight.hallWall.blockID);
		world.setBlock(i + 2, j + 3, k + 35, DivineRPGTwilight.hallWall.blockID);
		world.setBlock(i + 2, j + 3, k + 36, DivineRPGTwilight.hallWall.blockID);
		world.setBlock(i + 2, j + 3, k + 37, DivineRPGTwilight.darkEverstone.blockID);
		world.setBlock(i + 2, j + 4, k + 3, DivineRPGTwilight.darkEverstone.blockID);
		world.setBlock(i + 2, j + 4, k + 7, DivineRPGTwilight.darkEverstone.blockID);
		world.setBlock(i + 2, j + 4, k + 9, DivineRPGTwilight.darkEverstone.blockID);
		world.setBlock(i + 2, j + 4, k + 13, DivineRPGTwilight.darkEverstone.blockID);
		world.setBlock(i + 2, j + 4, k + 17, DivineRPGTwilight.darkEverstone.blockID);
		world.setBlock(i + 2, j + 4, k + 20, DivineRPGTwilight.darkEverstone.blockID);
		world.setBlock(i + 2, j + 4, k + 23, DivineRPGTwilight.darkEverstone.blockID);
		world.setBlock(i + 2, j + 4, k + 27, DivineRPGTwilight.darkEverstone.blockID);
		world.setBlock(i + 2, j + 4, k + 30, DivineRPGTwilight.darkEverstone.blockID);
		world.setBlock(i + 2, j + 4, k + 33, DivineRPGTwilight.darkEverstone.blockID);
		world.setBlock(i + 2, j + 4, k + 35, DivineRPGTwilight.darkEverstone.blockID);
		world.setBlock(i + 2, j + 4, k + 36, DivineRPGTwilight.darkEverstone.blockID);
		world.setBlock(i + 2, j + 4, k + 37, DivineRPGTwilight.darkEverstone.blockID);
		world.setBlock(i + 2, j + 5, k + 1, DivineRPGTwilight.hallWall.blockID);
		world.setBlock(i + 2, j + 5, k + 2, DivineRPGTwilight.hallWall.blockID);
		world.setBlock(i + 2, j + 5, k + 3, DivineRPGTwilight.hallWall.blockID);
		world.setBlock(i + 2, j + 5, k + 4, DivineRPGTwilight.hallWall.blockID);
		world.setBlock(i + 2, j + 5, k + 5, DivineRPGTwilight.hallWall.blockID);
		world.setBlock(i + 2, j + 5, k + 6, DivineRPGTwilight.hallWall.blockID);
		world.setBlock(i + 2, j + 5, k + 7, DivineRPGTwilight.hallWall.blockID);
		world.setBlock(i + 2, j + 5, k + 8, DivineRPGTwilight.hallWall.blockID);
		world.setBlock(i + 2, j + 5, k + 9, DivineRPGTwilight.hallWall.blockID);
		world.setBlock(i + 2, j + 5, k + 10, DivineRPGTwilight.hallWall.blockID);
		world.setBlock(i + 2, j + 5, k + 11, DivineRPGTwilight.hallWall.blockID);
		world.setBlock(i + 2, j + 5, k + 12, DivineRPGTwilight.hallWall.blockID);
		world.setBlock(i + 2, j + 5, k + 13, DivineRPGTwilight.hallWall.blockID);
		world.setBlock(i + 2, j + 5, k + 14, DivineRPGTwilight.hallWall.blockID);
		world.setBlock(i + 2, j + 5, k + 15, DivineRPGTwilight.hallWall.blockID);
		world.setBlock(i + 2, j + 5, k + 17, DivineRPGTwilight.darkEverstone.blockID);
		world.setBlock(i + 2, j + 5, k + 20, DivineRPGTwilight.darkEverstone.blockID);
		world.setBlock(i + 2, j + 5, k + 23, DivineRPGTwilight.darkEverstone.blockID);
		world.setBlock(i + 2, j + 5, k + 27, DivineRPGTwilight.darkEverstone.blockID);
		world.setBlock(i + 2, j + 5, k + 30, DivineRPGTwilight.darkEverstone.blockID);
		world.setBlock(i + 2, j + 5, k + 33, DivineRPGTwilight.darkEverstone.blockID);
		world.setBlock(i + 2, j + 6, k + 1, DivineRPGTwilight.hallWall.blockID);
		world.setBlock(i + 2, j + 6, k + 2, DivineRPGTwilight.hallWall.blockID);
		world.setBlock(i + 2, j + 6, k + 3, DivineRPGTwilight.hallWall.blockID);
		world.setBlock(i + 2, j + 6, k + 4, DivineRPGTwilight.hallWall.blockID);
		world.setBlock(i + 2, j + 6, k + 5, DivineRPGTwilight.hallWall.blockID);
		world.setBlock(i + 2, j + 6, k + 6, DivineRPGTwilight.hallWall.blockID);
		world.setBlock(i + 2, j + 6, k + 7, DivineRPGTwilight.hallWall.blockID);
		world.setBlock(i + 2, j + 6, k + 8, DivineRPGTwilight.hallWall.blockID);
		world.setBlock(i + 2, j + 6, k + 9, DivineRPGTwilight.hallWall.blockID);
		world.setBlock(i + 2, j + 6, k + 10, DivineRPGTwilight.hallWall.blockID);
		world.setBlock(i + 2, j + 6, k + 11, DivineRPGTwilight.hallWall.blockID);
		world.setBlock(i + 2, j + 6, k + 12, DivineRPGTwilight.hallWall.blockID);
		world.setBlock(i + 2, j + 6, k + 13, DivineRPGTwilight.hallWall.blockID);
		world.setBlock(i + 2, j + 6, k + 14, DivineRPGTwilight.hallWall.blockID);
		world.setBlock(i + 2, j + 6, k + 15, DivineRPGTwilight.hallWall.blockID);
		world.setBlock(i + 2, j + 6, k + 17, DivineRPGTwilight.darkEverstone.blockID);
		world.setBlock(i + 2, j + 6, k + 20, DivineRPGTwilight.darkEverstone.blockID);
		world.setBlock(i + 2, j + 6, k + 23, DivineRPGTwilight.darkEverstone.blockID);
		world.setBlock(i + 2, j + 6, k + 27, DivineRPGTwilight.darkEverstone.blockID);
		world.setBlock(i + 2, j + 6, k + 30, DivineRPGTwilight.darkEverstone.blockID);
		world.setBlock(i + 2, j + 6, k + 33, DivineRPGTwilight.darkEverstone.blockID);
		world.setBlock(i + 2, j + 7, k + 1, DivineRPGTwilight.hallWall.blockID);
		world.setBlock(i + 2, j + 7, k + 2, DivineRPGTwilight.darkEverstone.blockID);
		world.setBlock(i + 2, j + 7, k + 3, DivineRPGTwilight.darkEverstone.blockID);
		world.setBlock(i + 2, j + 7, k + 4, DivineRPGTwilight.darkEverstone.blockID);
		world.setBlock(i + 2, j + 7, k + 5, DivineRPGTwilight.darkEverstone.blockID);
		world.setBlock(i + 2, j + 7, k + 6, DivineRPGTwilight.darkEverstone.blockID);
		world.setBlock(i + 2, j + 7, k + 7, DivineRPGTwilight.darkEverstone.blockID);
		world.setBlock(i + 2, j + 7, k + 8, DivineRPGTwilight.darkEverstone.blockID);
		world.setBlock(i + 2, j + 7, k + 9, DivineRPGTwilight.darkEverstone.blockID);
		world.setBlock(i + 2, j + 7, k + 10, DivineRPGTwilight.darkEverstone.blockID);
		world.setBlock(i + 2, j + 7, k + 11, DivineRPGTwilight.darkEverstone.blockID);
		world.setBlock(i + 2, j + 7, k + 12, DivineRPGTwilight.darkEverstone.blockID);
		world.setBlock(i + 2, j + 7, k + 13, DivineRPGTwilight.darkEverstone.blockID);
		world.setBlock(i + 2, j + 7, k + 14, DivineRPGTwilight.darkEverstone.blockID);
		world.setBlock(i + 2, j + 7, k + 15, DivineRPGTwilight.hallWall.blockID);
		world.setBlock(i + 2, j + 7, k + 17, DivineRPGTwilight.darkEverstone.blockID);
		world.setBlock(i + 2, j + 7, k + 20, DivineRPGTwilight.darkEverstone.blockID);
		world.setBlock(i + 2, j + 7, k + 23, DivineRPGTwilight.darkEverstone.blockID);
		world.setBlock(i + 2, j + 7, k + 27, DivineRPGTwilight.darkEverstone.blockID);
		world.setBlock(i + 2, j + 7, k + 30, DivineRPGTwilight.darkEverstone.blockID);
		world.setBlock(i + 2, j + 7, k + 33, DivineRPGTwilight.darkEverstone.blockID);
		world.setBlock(i + 2, j + 8, k + 1, DivineRPGTwilight.hallWall.blockID);
		world.setBlock(i + 2, j + 8, k + 2, DivineRPGTwilight.hallWall.blockID);
		world.setBlock(i + 2, j + 8, k + 3, DivineRPGTwilight.hallWall.blockID);
		world.setBlock(i + 2, j + 8, k + 4, DivineRPGTwilight.hallWall.blockID);
		world.setBlock(i + 2, j + 8, k + 5, DivineRPGTwilight.hallWall.blockID);
		world.setBlock(i + 2, j + 8, k + 6, DivineRPGTwilight.hallWall.blockID);
		world.setBlock(i + 2, j + 8, k + 7, DivineRPGTwilight.hallWall.blockID);
		world.setBlock(i + 2, j + 8, k + 8, DivineRPGTwilight.hallWall.blockID);
		world.setBlock(i + 2, j + 8, k + 9, DivineRPGTwilight.hallWall.blockID);
		world.setBlock(i + 2, j + 8, k + 10, DivineRPGTwilight.hallWall.blockID);
		world.setBlock(i + 2, j + 8, k + 11, DivineRPGTwilight.hallWall.blockID);
		world.setBlock(i + 2, j + 8, k + 12, DivineRPGTwilight.hallWall.blockID);
		world.setBlock(i + 2, j + 8, k + 13, DivineRPGTwilight.hallWall.blockID);
		world.setBlock(i + 2, j + 8, k + 14, DivineRPGTwilight.hallWall.blockID);
		world.setBlock(i + 2, j + 8, k + 15, DivineRPGTwilight.hallWall.blockID);
		world.setBlock(i + 2, j + 8, k + 17, DivineRPGTwilight.darkEverstone.blockID);
		world.setBlock(i + 2, j + 8, k + 20, DivineRPGTwilight.darkEverstone.blockID);
		world.setBlock(i + 2, j + 8, k + 23, DivineRPGTwilight.darkEverstone.blockID);
		world.setBlock(i + 2, j + 8, k + 27, DivineRPGTwilight.darkEverstone.blockID);
		world.setBlock(i + 2, j + 8, k + 30, DivineRPGTwilight.darkEverstone.blockID);
		world.setBlock(i + 2, j + 8, k + 33, DivineRPGTwilight.darkEverstone.blockID);
		world.setBlock(i + 2, j + 9, k + 17, DivineRPGTwilight.darkEverstone.blockID);
		world.setBlock(i + 2, j + 9, k + 20, DivineRPGTwilight.darkEverstone.blockID);
		world.setBlock(i + 2, j + 9, k + 23, DivineRPGTwilight.darkEverstone.blockID);
		world.setBlock(i + 2, j + 9, k + 27, DivineRPGTwilight.darkEverstone.blockID);
		world.setBlock(i + 2, j + 9, k + 30, DivineRPGTwilight.darkEverstone.blockID);
		world.setBlock(i + 2, j + 9, k + 33, DivineRPGTwilight.darkEverstone.blockID);
		world.setBlock(i + 3, j + 0, k + 2, DivineRPGTwilight.hallWall.blockID);
		world.setBlock(i + 3, j + 0, k + 3, DivineRPGTwilight.hallWall.blockID);
		world.setBlock(i + 3, j + 0, k + 4, DivineRPGTwilight.hallWall.blockID);
		world.setBlock(i + 3, j + 0, k + 5, DivineRPGTwilight.hallWall.blockID);
		world.setBlock(i + 3, j + 0, k + 6, DivineRPGTwilight.hallWall.blockID);
		world.setBlock(i + 3, j + 0, k + 7, DivineRPGTwilight.hallWall.blockID);
		world.setBlock(i + 3, j + 0, k + 8, DivineRPGTwilight.hallWall.blockID);
		world.setBlock(i + 3, j + 0, k + 9, DivineRPGTwilight.hallWall.blockID);
		world.setBlock(i + 3, j + 0, k + 10, DivineRPGTwilight.hallWall.blockID);
		world.setBlock(i + 3, j + 0, k + 11, DivineRPGTwilight.hallWall.blockID);
		world.setBlock(i + 3, j + 0, k + 12, DivineRPGTwilight.hallWall.blockID);
		world.setBlock(i + 3, j + 0, k + 13, DivineRPGTwilight.hallWall.blockID);
		world.setBlock(i + 3, j + 0, k + 14, DivineRPGTwilight.hallWall.blockID);
		world.setBlock(i + 3, j + 0, k + 15, DivineRPGTwilight.hallWall.blockID);
		world.setBlock(i + 3, j + 0, k + 16, DivineRPGTwilight.hallWall.blockID);
		world.setBlock(i + 3, j + 0, k + 17, DivineRPGTwilight.firecrystal.blockID);
		world.setBlock(i + 3, j + 0, k + 18, DivineRPGTwilight.firecrystal.blockID);
		world.setBlock(i + 3, j + 0, k + 19, DivineRPGTwilight.firecrystal.blockID);
		world.setBlock(i + 3, j + 0, k + 20, DivineRPGTwilight.firecrystal.blockID);
		world.setBlock(i + 3, j + 0, k + 21, DivineRPGTwilight.firecrystal.blockID);
		world.setBlock(i + 3, j + 0, k + 22, DivineRPGTwilight.firecrystal.blockID);
		world.setBlock(i + 3, j + 0, k + 23, DivineRPGTwilight.firecrystal.blockID);
		world.setBlock(i + 3, j + 0, k + 24, DivineRPGTwilight.firecrystal.blockID);
		world.setBlock(i + 3, j + 0, k + 25, DivineRPGTwilight.firecrystal.blockID);
		world.setBlock(i + 3, j + 0, k + 26, DivineRPGTwilight.firecrystal.blockID);
		world.setBlock(i + 3, j + 0, k + 27, DivineRPGTwilight.firecrystal.blockID);
		world.setBlock(i + 3, j + 0, k + 28, DivineRPGTwilight.firecrystal.blockID);
		world.setBlock(i + 3, j + 0, k + 29, DivineRPGTwilight.firecrystal.blockID);
		world.setBlock(i + 3, j + 0, k + 30, DivineRPGTwilight.firecrystal.blockID);
		world.setBlock(i + 3, j + 0, k + 31, DivineRPGTwilight.firecrystal.blockID);
		world.setBlock(i + 3, j + 0, k + 32, DivineRPGTwilight.firecrystal.blockID);
		world.setBlock(i + 3, j + 0, k + 33, DivineRPGTwilight.firecrystal.blockID);
		world.setBlock(i + 3, j + 0, k + 34, DivineRPGTwilight.firecrystal.blockID);
		world.setBlock(i + 3, j + 0, k + 35, DivineRPGTwilight.firecrystal.blockID);
		world.setBlock(i + 3, j + 0, k + 36, DivineRPGTwilight.hallWall.blockID);
		world.setBlock(i + 3, j + 1, k + 2, DivineRPGTwilight.hallWall.blockID);
		world.setBlock(i + 3, j + 1, k + 3, DivineRPGTwilight.hallWall.blockID);
		world.setBlock(i + 3, j + 1, k + 4, DivineRPGTwilight.hallWall.blockID);
		world.setBlock(i + 3, j + 1, k + 5, DivineRPGTwilight.hallWall.blockID);
		world.setBlock(i + 3, j + 1, k + 6, DivineRPGTwilight.hallWall.blockID);
		world.setBlock(i + 3, j + 1, k + 7, DivineRPGTwilight.hallWall.blockID);
		world.setBlock(i + 3, j + 1, k + 8, DivineRPGTwilight.hallWall.blockID);
		world.setBlock(i + 3, j + 1, k + 9, DivineRPGTwilight.hallWall.blockID);
		world.setBlock(i + 3, j + 1, k + 10, DivineRPGTwilight.hallWall.blockID);
		world.setBlock(i + 3, j + 1, k + 11, DivineRPGTwilight.hallWall.blockID);
		world.setBlock(i + 3, j + 1, k + 12, DivineRPGTwilight.hallWall.blockID);
		world.setBlock(i + 3, j + 1, k + 13, DivineRPGTwilight.hallWall.blockID);
		world.setBlock(i + 3, j + 1, k + 14, DivineRPGTwilight.hallWall.blockID);
		world.setBlock(i + 3, j + 1, k + 15, DivineRPGTwilight.hallWall.blockID);
		world.setBlock(i + 3, j + 1, k + 16, DivineRPGTwilight.hallWall.blockID);
		world.setBlock(i + 3, j + 1, k + 36, DivineRPGTwilight.hallWall.blockID);
		world.setBlock(i + 3, j + 2, k + 2, DivineRPGTwilight.hallWall.blockID);
		world.setBlock(i + 3, j + 2, k + 3, DivineRPGTwilight.hallWall.blockID);
		world.setBlock(i + 3, j + 2, k + 4, DivineRPGTwilight.hallWall.blockID);
		world.setBlock(i + 3, j + 2, k + 5, DivineRPGTwilight.hallWall.blockID);
		world.setBlock(i + 3, j + 2, k + 6, DivineRPGTwilight.hallWall.blockID);
		world.setBlock(i + 3, j + 2, k + 7, DivineRPGTwilight.hallWall.blockID);
		world.setBlock(i + 3, j + 2, k + 8, DivineRPGTwilight.hallWall.blockID);
		world.setBlock(i + 3, j + 2, k + 9, DivineRPGTwilight.hallWall.blockID);
		world.setBlock(i + 3, j + 2, k + 10, DivineRPGTwilight.hallWall.blockID);
		world.setBlock(i + 3, j + 2, k + 11, DivineRPGTwilight.hallWall.blockID);
		world.setBlock(i + 3, j + 2, k + 12, DivineRPGTwilight.hallWall.blockID);
		world.setBlock(i + 3, j + 2, k + 13, DivineRPGTwilight.hallWall.blockID);
		world.setBlock(i + 3, j + 2, k + 14, DivineRPGTwilight.hallWall.blockID);
		world.setBlock(i + 3, j + 2, k + 15, DivineRPGTwilight.hallWall.blockID);
		world.setBlock(i + 3, j + 2, k + 16, DivineRPGTwilight.hallWall.blockID);
		world.setBlock(i + 3, j + 2, k + 36, DivineRPGTwilight.hallWall.blockID);
		world.setBlock(i + 3, j + 3, k + 2, DivineRPGTwilight.hallWall.blockID);
		world.setBlock(i + 3, j + 3, k + 3, DivineRPGTwilight.hallWall.blockID);
		world.setBlock(i + 3, j + 3, k + 4, DivineRPGTwilight.hallWall.blockID);
		world.setBlock(i + 3, j + 3, k + 5, DivineRPGTwilight.hallWall.blockID);
		world.setBlock(i + 3, j + 3, k + 6, DivineRPGTwilight.hallWall.blockID);
		world.setBlock(i + 3, j + 3, k + 7, DivineRPGTwilight.hallWall.blockID);
		world.setBlock(i + 3, j + 3, k + 8, DivineRPGTwilight.hallWall.blockID);
		world.setBlock(i + 3, j + 3, k + 9, DivineRPGTwilight.hallWall.blockID);
		world.setBlock(i + 3, j + 3, k + 10, DivineRPGTwilight.hallWall.blockID);
		world.setBlock(i + 3, j + 3, k + 11, DivineRPGTwilight.hallWall.blockID);
		world.setBlock(i + 3, j + 3, k + 12, DivineRPGTwilight.hallWall.blockID);
		world.setBlock(i + 3, j + 3, k + 13, DivineRPGTwilight.hallWall.blockID);
		world.setBlock(i + 3, j + 3, k + 14, DivineRPGTwilight.hallWall.blockID);
		world.setBlock(i + 3, j + 3, k + 15, DivineRPGTwilight.hallWall.blockID);
		world.setBlock(i + 3, j + 3, k + 16, DivineRPGTwilight.hallWall.blockID);
		world.setBlock(i + 3, j + 3, k + 17, DivineRPGTwilight.hallWall.blockID);
		world.setBlock(i + 3, j + 3, k + 18, DivineRPGTwilight.hallWall.blockID);
		world.setBlock(i + 3, j + 3, k + 19, DivineRPGTwilight.hallWall.blockID);
		world.setBlock(i + 3, j + 3, k + 20, DivineRPGTwilight.hallWall.blockID);
		world.setBlock(i + 3, j + 3, k + 21, DivineRPGTwilight.hallWall.blockID);
		world.setBlock(i + 3, j + 3, k + 22, DivineRPGTwilight.hallWall.blockID);
		world.setBlock(i + 3, j + 3, k + 23, DivineRPGTwilight.hallWall.blockID);
		world.setBlock(i + 3, j + 3, k + 24, DivineRPGTwilight.hallWall.blockID);
		world.setBlock(i + 3, j + 3, k + 25, DivineRPGTwilight.hallWall.blockID);
		world.setBlock(i + 3, j + 3, k + 26, DivineRPGTwilight.hallWall.blockID);
		world.setBlock(i + 3, j + 3, k + 27, DivineRPGTwilight.hallWall.blockID);
		world.setBlock(i + 3, j + 3, k + 28, DivineRPGTwilight.hallWall.blockID);
		world.setBlock(i + 3, j + 3, k + 29, DivineRPGTwilight.hallWall.blockID);
		world.setBlock(i + 3, j + 3, k + 30, DivineRPGTwilight.hallWall.blockID);
		world.setBlock(i + 3, j + 3, k + 31, DivineRPGTwilight.hallWall.blockID);
		world.setBlock(i + 3, j + 3, k + 32, DivineRPGTwilight.hallWall.blockID);
		world.setBlock(i + 3, j + 3, k + 33, DivineRPGTwilight.hallWall.blockID);
		world.setBlock(i + 3, j + 3, k + 34, DivineRPGTwilight.hallWall.blockID);
		world.setBlock(i + 3, j + 3, k + 35, DivineRPGTwilight.hallWall.blockID);
		world.setBlock(i + 3, j + 3, k + 36, DivineRPGTwilight.hallWall.blockID);
		world.setBlock(i + 3, j + 4, k + 2, DivineRPGTwilight.hallWall.blockID);
		world.setBlock(i + 3, j + 4, k + 3, DivineRPGTwilight.hallWall.blockID);
		world.setBlock(i + 3, j + 4, k + 4, DivineRPGTwilight.hallWall.blockID);
		world.setBlock(i + 3, j + 4, k + 5, DivineRPGTwilight.hallWall.blockID);
		world.setBlock(i + 3, j + 4, k + 6, DivineRPGTwilight.hallWall.blockID);
		world.setBlock(i + 3, j + 4, k + 7, DivineRPGTwilight.hallWall.blockID);
		world.setBlock(i + 3, j + 4, k + 8, DivineRPGTwilight.hallWall.blockID);
		world.setBlock(i + 3, j + 4, k + 9, DivineRPGTwilight.hallWall.blockID);
		world.setBlock(i + 3, j + 4, k + 10, DivineRPGTwilight.hallWall.blockID);
		world.setBlock(i + 3, j + 4, k + 11, DivineRPGTwilight.hallWall.blockID);
		world.setBlock(i + 3, j + 4, k + 12, DivineRPGTwilight.hallWall.blockID);
		world.setBlock(i + 3, j + 4, k + 13, DivineRPGTwilight.hallWall.blockID);
		world.setBlock(i + 3, j + 4, k + 14, DivineRPGTwilight.hallWall.blockID);
		world.setBlock(i + 3, j + 4, k + 15, DivineRPGTwilight.hallWall.blockID);
		world.setBlock(i + 3, j + 4, k + 16, DivineRPGTwilight.hallWall.blockID);
		world.setBlock(i + 3, j + 4, k + 17, DivineRPGTwilight.hallWall.blockID);
		world.setBlock(i + 3, j + 4, k + 18, DivineRPGTwilight.hallWall.blockID);
		world.setBlock(i + 3, j + 4, k + 19, DivineRPGTwilight.hallWall.blockID);
		world.setBlock(i + 3, j + 4, k + 20, DivineRPGTwilight.hallWall.blockID);
		world.setBlock(i + 3, j + 4, k + 21, DivineRPGTwilight.hallWall.blockID);
		world.setBlock(i + 3, j + 4, k + 22, DivineRPGTwilight.hallWall.blockID);
		world.setBlock(i + 3, j + 4, k + 23, DivineRPGTwilight.hallWall.blockID);
		world.setBlock(i + 3, j + 4, k + 24, DivineRPGTwilight.hallWall.blockID);
		world.setBlock(i + 3, j + 4, k + 25, DivineRPGTwilight.hallWall.blockID);
		world.setBlock(i + 3, j + 4, k + 26, DivineRPGTwilight.hallWall.blockID);
		world.setBlock(i + 3, j + 4, k + 27, DivineRPGTwilight.hallWall.blockID);
		world.setBlock(i + 3, j + 4, k + 28, DivineRPGTwilight.hallWall.blockID);
		world.setBlock(i + 3, j + 4, k + 29, DivineRPGTwilight.hallWall.blockID);
		world.setBlock(i + 3, j + 4, k + 30, DivineRPGTwilight.hallWall.blockID);
		world.setBlock(i + 3, j + 4, k + 31, DivineRPGTwilight.hallWall.blockID);
		world.setBlock(i + 3, j + 4, k + 32, DivineRPGTwilight.hallWall.blockID);
		world.setBlock(i + 3, j + 4, k + 33, DivineRPGTwilight.hallWall.blockID);
		world.setBlock(i + 3, j + 4, k + 34, DivineRPGTwilight.hallWall.blockID);
		world.setBlock(i + 3, j + 4, k + 35, DivineRPGTwilight.hallWall.blockID);
		world.setBlock(i + 3, j + 5, k + 1, DivineRPGTwilight.hallWall.blockID);
		world.setBlock(i + 3, j + 5, k + 2, DivineRPGTwilight.firecrystal.blockID);
		world.setBlock(i + 3, j + 5, k + 3, DivineRPGTwilight.firecrystal.blockID);
		world.setBlock(i + 3, j + 5, k + 4, DivineRPGTwilight.firecrystal.blockID);
		world.setBlock(i + 3, j + 5, k + 5, DivineRPGTwilight.firecrystal.blockID);
		world.setBlock(i + 3, j + 5, k + 6, DivineRPGTwilight.firecrystal.blockID);
		world.setBlock(i + 3, j + 5, k + 7, DivineRPGTwilight.firecrystal.blockID);
		world.setBlock(i + 3, j + 5, k + 8, DivineRPGTwilight.firecrystal.blockID);
		world.setBlock(i + 3, j + 5, k + 9, DivineRPGTwilight.firecrystal.blockID);
		world.setBlock(i + 3, j + 5, k + 10, DivineRPGTwilight.firecrystal.blockID);
		world.setBlock(i + 3, j + 5, k + 11, DivineRPGTwilight.firecrystal.blockID);
		world.setBlock(i + 3, j + 5, k + 12, DivineRPGTwilight.firecrystal.blockID);
		world.setBlock(i + 3, j + 5, k + 13, DivineRPGTwilight.firecrystal.blockID);
		world.setBlock(i + 3, j + 5, k + 14, DivineRPGTwilight.firecrystal.blockID);
		world.setBlock(i + 3, j + 5, k + 15, DivineRPGTwilight.hallWall.blockID);
		world.setBlock(i + 3, j + 5, k + 16, DivineRPGTwilight.hallWall.blockID);
		world.setBlock(i + 3, j + 5, k + 17, DivineRPGTwilight.hallWall.blockID);
		world.setBlock(i + 3, j + 5, k + 18, DivineRPGTwilight.hallWall.blockID);
		world.setBlock(i + 3, j + 5, k + 19, DivineRPGTwilight.hallWall.blockID);
		world.setBlock(i + 3, j + 5, k + 20, DivineRPGTwilight.hallWall.blockID);
		world.setBlock(i + 3, j + 5, k + 21, DivineRPGTwilight.hallWall.blockID);
		world.setBlock(i + 3, j + 5, k + 22, DivineRPGTwilight.hallWall.blockID);
		world.setBlock(i + 3, j + 5, k + 23, DivineRPGTwilight.hallWall.blockID);
		world.setBlock(i + 3, j + 5, k + 24, DivineRPGTwilight.hallWall.blockID);
		world.setBlock(i + 3, j + 5, k + 25, DivineRPGTwilight.hallWall.blockID);
		world.setBlock(i + 3, j + 5, k + 26, DivineRPGTwilight.hallWall.blockID);
		world.setBlock(i + 3, j + 5, k + 27, DivineRPGTwilight.hallWall.blockID);
		world.setBlock(i + 3, j + 5, k + 28, DivineRPGTwilight.hallWall.blockID);
		world.setBlock(i + 3, j + 5, k + 29, DivineRPGTwilight.hallWall.blockID);
		world.setBlock(i + 3, j + 5, k + 30, DivineRPGTwilight.hallWall.blockID);
		world.setBlock(i + 3, j + 5, k + 31, DivineRPGTwilight.hallWall.blockID);
		world.setBlock(i + 3, j + 5, k + 32, DivineRPGTwilight.hallWall.blockID);
		world.setBlock(i + 3, j + 5, k + 33, DivineRPGTwilight.hallWall.blockID);
		world.setBlock(i + 3, j + 5, k + 34, DivineRPGTwilight.hallWall.blockID);
		world.setBlock(i + 3, j + 5, k + 35, DivineRPGTwilight.hallWall.blockID);
		world.setBlock(i + 3, j + 6, k + 1, DivineRPGTwilight.hallWall.blockID);
		world.setBlock(i + 3, j + 6, k + 15, DivineRPGTwilight.hallWall.blockID);
		world.setBlock(i + 3, j + 6, k + 16, DivineRPGTwilight.hallWall.blockID);
		world.setBlock(i + 3, j + 6, k + 17, DivineRPGTwilight.hallWall.blockID);
		world.setBlock(i + 3, j + 6, k + 18, DivineRPGTwilight.hallWall.blockID);
		world.setBlock(i + 3, j + 6, k + 19, DivineRPGTwilight.hallWall.blockID);
		world.setBlock(i + 3, j + 6, k + 20, DivineRPGTwilight.hallWall.blockID);
		world.setBlock(i + 3, j + 6, k + 21, DivineRPGTwilight.hallWall.blockID);
		world.setBlock(i + 3, j + 6, k + 22, DivineRPGTwilight.hallWall.blockID);
		world.setBlock(i + 3, j + 6, k + 23, DivineRPGTwilight.hallWall.blockID);
		world.setBlock(i + 3, j + 6, k + 24, DivineRPGTwilight.hallWall.blockID);
		world.setBlock(i + 3, j + 6, k + 25, DivineRPGTwilight.hallWall.blockID);
		world.setBlock(i + 3, j + 6, k + 26, DivineRPGTwilight.hallWall.blockID);
		world.setBlock(i + 3, j + 6, k + 27, DivineRPGTwilight.hallWall.blockID);
		world.setBlock(i + 3, j + 6, k + 28, DivineRPGTwilight.hallWall.blockID);
		world.setBlock(i + 3, j + 6, k + 29, DivineRPGTwilight.hallWall.blockID);
		world.setBlock(i + 3, j + 6, k + 30, DivineRPGTwilight.hallWall.blockID);
		world.setBlock(i + 3, j + 6, k + 31, DivineRPGTwilight.hallWall.blockID);
		world.setBlock(i + 3, j + 6, k + 32, DivineRPGTwilight.hallWall.blockID);
		world.setBlock(i + 3, j + 6, k + 33, DivineRPGTwilight.hallWall.blockID);
		world.setBlock(i + 3, j + 6, k + 34, DivineRPGTwilight.hallWall.blockID);
		world.setBlock(i + 3, j + 6, k + 35, DivineRPGTwilight.hallWall.blockID);
		world.setBlock(i + 3, j + 7, k + 0, DivineRPGTwilight.hallWall.blockID);
		world.setBlock(i + 3, j + 7, k + 1, DivineRPGTwilight.darkEverstone.blockID);
		world.setBlock(i + 3, j + 7, k + 15, DivineRPGTwilight.hallWall.blockID);
		world.setBlock(i + 3, j + 7, k + 16, DivineRPGTwilight.hallWall.blockID);
		world.setBlock(i + 3, j + 7, k + 17, DivineRPGTwilight.hallWall.blockID);
		world.setBlock(i + 3, j + 7, k + 18, DivineRPGTwilight.hallWall.blockID);
		world.setBlock(i + 3, j + 7, k + 19, DivineRPGTwilight.hallWall.blockID);
		world.setBlock(i + 3, j + 7, k + 20, DivineRPGTwilight.hallWall.blockID);
		world.setBlock(i + 3, j + 7, k + 21, DivineRPGTwilight.hallWall.blockID);
		world.setBlock(i + 3, j + 7, k + 22, DivineRPGTwilight.hallWall.blockID);
		world.setBlock(i + 3, j + 7, k + 23, DivineRPGTwilight.hallWall.blockID);
		world.setBlock(i + 3, j + 7, k + 24, DivineRPGTwilight.hallWall.blockID);
		world.setBlock(i + 3, j + 7, k + 25, DivineRPGTwilight.hallWall.blockID);
		world.setBlock(i + 3, j + 7, k + 26, DivineRPGTwilight.hallWall.blockID);
		world.setBlock(i + 3, j + 7, k + 27, DivineRPGTwilight.hallWall.blockID);
		world.setBlock(i + 3, j + 7, k + 28, DivineRPGTwilight.hallWall.blockID);
		world.setBlock(i + 3, j + 7, k + 29, DivineRPGTwilight.hallWall.blockID);
		world.setBlock(i + 3, j + 7, k + 30, DivineRPGTwilight.hallWall.blockID);
		world.setBlock(i + 3, j + 7, k + 31, DivineRPGTwilight.hallWall.blockID);
		world.setBlock(i + 3, j + 7, k + 32, DivineRPGTwilight.hallWall.blockID);
		world.setBlock(i + 3, j + 7, k + 33, DivineRPGTwilight.hallWall.blockID);
		world.setBlock(i + 3, j + 7, k + 34, DivineRPGTwilight.hallWall.blockID);
		world.setBlock(i + 3, j + 7, k + 35, DivineRPGTwilight.hallWall.blockID);
		world.setBlock(i + 3, j + 8, k + 1, DivineRPGTwilight.hallWall.blockID);
		world.setBlock(i + 3, j + 8, k + 15, DivineRPGTwilight.hallWall.blockID);
		world.setBlock(i + 3, j + 8, k + 16, DivineRPGTwilight.hallWall.blockID);
		world.setBlock(i + 3, j + 8, k + 17, DivineRPGTwilight.hallWall.blockID);
		world.setBlock(i + 3, j + 8, k + 18, DivineRPGTwilight.hallWall.blockID);
		world.setBlock(i + 3, j + 8, k + 19, DivineRPGTwilight.hallWall.blockID);
		world.setBlock(i + 3, j + 8, k + 20, DivineRPGTwilight.hallWall.blockID);
		world.setBlock(i + 3, j + 8, k + 21, DivineRPGTwilight.hallWall.blockID);
		world.setBlock(i + 3, j + 8, k + 22, DivineRPGTwilight.hallWall.blockID);
		world.setBlock(i + 3, j + 8, k + 23, DivineRPGTwilight.hallWall.blockID);
		world.setBlock(i + 3, j + 8, k + 24, DivineRPGTwilight.hallWall.blockID);
		world.setBlock(i + 3, j + 8, k + 25, DivineRPGTwilight.hallWall.blockID);
		world.setBlock(i + 3, j + 8, k + 26, DivineRPGTwilight.hallWall.blockID);
		world.setBlock(i + 3, j + 8, k + 27, DivineRPGTwilight.hallWall.blockID);
		world.setBlock(i + 3, j + 8, k + 28, DivineRPGTwilight.hallWall.blockID);
		world.setBlock(i + 3, j + 8, k + 29, DivineRPGTwilight.hallWall.blockID);
		world.setBlock(i + 3, j + 8, k + 30, DivineRPGTwilight.hallWall.blockID);
		world.setBlock(i + 3, j + 8, k + 31, DivineRPGTwilight.hallWall.blockID);
		world.setBlock(i + 3, j + 8, k + 32, DivineRPGTwilight.hallWall.blockID);
		world.setBlock(i + 3, j + 8, k + 33, DivineRPGTwilight.hallWall.blockID);
		world.setBlock(i + 3, j + 8, k + 34, DivineRPGTwilight.hallWall.blockID);
		world.setBlock(i + 3, j + 8, k + 35, DivineRPGTwilight.hallWall.blockID);
		world.setBlock(i + 3, j + 9, k + 2, DivineRPGTwilight.hallWall.blockID);
		world.setBlock(i + 3, j + 9, k + 3, DivineRPGTwilight.hallWall.blockID);
		world.setBlock(i + 3, j + 9, k + 4, DivineRPGTwilight.hallWall.blockID);
		world.setBlock(i + 3, j + 9, k + 5, DivineRPGTwilight.hallWall.blockID);
		world.setBlock(i + 3, j + 9, k + 6, DivineRPGTwilight.hallWall.blockID);
		world.setBlock(i + 3, j + 9, k + 7, DivineRPGTwilight.hallWall.blockID);
		world.setBlock(i + 3, j + 9, k + 8, DivineRPGTwilight.hallWall.blockID);
		world.setBlock(i + 3, j + 9, k + 9, DivineRPGTwilight.hallWall.blockID);
		world.setBlock(i + 3, j + 9, k + 10, DivineRPGTwilight.hallWall.blockID);
		world.setBlock(i + 3, j + 9, k + 11, DivineRPGTwilight.hallWall.blockID);
		world.setBlock(i + 3, j + 9, k + 12, DivineRPGTwilight.hallWall.blockID);
		world.setBlock(i + 3, j + 9, k + 13, DivineRPGTwilight.hallWall.blockID);
		world.setBlock(i + 3, j + 9, k + 14, DivineRPGTwilight.hallWall.blockID);
		world.setBlock(i + 3, j + 9, k + 17, DivineRPGTwilight.darkEverstone.blockID);
		world.setBlock(i + 3, j + 9, k + 20, DivineRPGTwilight.darkEverstone.blockID);
		world.setBlock(i + 3, j + 9, k + 23, DivineRPGTwilight.darkEverstone.blockID);
		world.setBlock(i + 3, j + 9, k + 27, DivineRPGTwilight.darkEverstone.blockID);
		world.setBlock(i + 3, j + 9, k + 30, DivineRPGTwilight.darkEverstone.blockID);
		world.setBlock(i + 3, j + 9, k + 33, DivineRPGTwilight.darkEverstone.blockID);
		world.setBlock(i + 4, j + 0, k + 1, DivineRPGTwilight.darkEverstone.blockID);
		world.setBlock(i + 4, j + 0, k + 2, DivineRPGTwilight.hallWall.blockID);
		world.setBlock(i + 4, j + 0, k + 14, DivineRPGTwilight.hallWall.blockID);
		world.setBlock(i + 4, j + 0, k + 16, DivineRPGTwilight.hallWall.blockID);
		world.setBlock(i + 4, j + 0, k + 17, DivineRPGTwilight.hallWall.blockID);
		world.setBlock(i + 4, j + 0, k + 18, DivineRPGTwilight.hallWall.blockID);
		world.setBlock(i + 4, j + 0, k + 19, DivineRPGTwilight.hallWall.blockID);
		world.setBlock(i + 4, j + 0, k + 20, DivineRPGTwilight.hallWall.blockID);
		world.setBlock(i + 4, j + 0, k + 21, DivineRPGTwilight.hallWall.blockID);
		world.setBlock(i + 4, j + 0, k + 22, DivineRPGTwilight.hallWall.blockID);
		world.setBlock(i + 4, j + 0, k + 23, DivineRPGTwilight.hallWall.blockID);
		world.setBlock(i + 4, j + 0, k + 24, DivineRPGTwilight.hallWall.blockID);
		world.setBlock(i + 4, j + 0, k + 25, DivineRPGTwilight.hallWall.blockID);
		world.setBlock(i + 4, j + 0, k + 26, DivineRPGTwilight.hallWall.blockID);
		world.setBlock(i + 4, j + 0, k + 27, DivineRPGTwilight.hallWall.blockID);
		world.setBlock(i + 4, j + 0, k + 28, DivineRPGTwilight.hallWall.blockID);
		world.setBlock(i + 4, j + 0, k + 29, DivineRPGTwilight.hallWall.blockID);
		world.setBlock(i + 4, j + 0, k + 30, DivineRPGTwilight.hallWall.blockID);
		world.setBlock(i + 4, j + 0, k + 31, DivineRPGTwilight.hallWall.blockID);
		world.setBlock(i + 4, j + 0, k + 32, DivineRPGTwilight.hallWall.blockID);
		world.setBlock(i + 4, j + 0, k + 33, DivineRPGTwilight.hallWall.blockID);
		world.setBlock(i + 4, j + 0, k + 34, DivineRPGTwilight.firecrystal.blockID);
		world.setBlock(i + 4, j + 0, k + 35, DivineRPGTwilight.firecrystal.blockID);
		world.setBlock(i + 4, j + 0, k + 36, DivineRPGTwilight.hallWall.blockID);
		world.setBlock(i + 4, j + 1, k + 1, DivineRPGTwilight.darkEverstone.blockID);
		world.setBlock(i + 4, j + 1, k + 2, DivineRPGTwilight.hallWall.blockID);
		world.setBlock(i + 4, j + 1, k + 14, DivineRPGTwilight.hallWall.blockID);
		world.setBlock(i + 4, j + 1, k + 16, DivineRPGTwilight.hallWall.blockID);
		world.setBlock(i + 4, j + 1, k + 17, DivineRPGTwilight.hallWall.blockID);
		world.setBlock(i + 4, j + 1, k + 18, DivineRPGTwilight.hallWall.blockID);
		world.setBlock(i + 4, j + 1, k + 19, DivineRPGTwilight.hallWall.blockID);
		world.setBlock(i + 4, j + 1, k + 20, DivineRPGTwilight.hallWall.blockID);
		world.setBlock(i + 4, j + 1, k + 21, DivineRPGTwilight.hallWall.blockID);
		world.setBlock(i + 4, j + 1, k + 22, DivineRPGTwilight.hallWall.blockID);
		world.setBlock(i + 4, j + 1, k + 23, DivineRPGTwilight.hallWall.blockID);
		world.setBlock(i + 4, j + 1, k + 24, DivineRPGTwilight.hallWall.blockID);
		world.setBlock(i + 4, j + 1, k + 25, DivineRPGTwilight.hallWall.blockID);
		world.setBlock(i + 4, j + 1, k + 26, DivineRPGTwilight.hallWall.blockID);
		world.setBlock(i + 4, j + 1, k + 27, DivineRPGTwilight.hallWall.blockID);
		world.setBlock(i + 4, j + 1, k + 28, DivineRPGTwilight.hallWall.blockID);
		world.setBlock(i + 4, j + 1, k + 29, DivineRPGTwilight.hallWall.blockID);
		world.setBlock(i + 4, j + 1, k + 30, DivineRPGTwilight.hallWall.blockID);
		world.setBlock(i + 4, j + 1, k + 31, DivineRPGTwilight.hallWall.blockID);
		world.setBlock(i + 4, j + 1, k + 32, DivineRPGTwilight.hallWall.blockID);
		world.setBlock(i + 4, j + 1, k + 33, DivineRPGTwilight.hallWall.blockID);
		world.setBlock(i + 4, j + 1, k + 36, DivineRPGTwilight.hallWall.blockID);
		world.setBlock(i + 4, j + 2, k + 1, DivineRPGTwilight.darkEverstone.blockID);
		world.setBlock(i + 4, j + 2, k + 2, DivineRPGTwilight.hallWall.blockID);
		world.setBlock(i + 4, j + 2, k + 14, DivineRPGTwilight.hallWall.blockID);
		world.setBlock(i + 4, j + 2, k + 16, DivineRPGTwilight.hallWall.blockID);
		world.setBlock(i + 4, j + 2, k + 17, DivineRPGTwilight.hallWall.blockID);
		world.setBlock(i + 4, j + 2, k + 18, DivineRPGTwilight.hallWall.blockID);
		world.setBlock(i + 4, j + 2, k + 19, DivineRPGTwilight.hallWall.blockID);
		world.setBlock(i + 4, j + 2, k + 20, DivineRPGTwilight.hallWall.blockID);
		world.setBlock(i + 4, j + 2, k + 21, DivineRPGTwilight.hallWall.blockID);
		world.setBlock(i + 4, j + 2, k + 22, DivineRPGTwilight.hallWall.blockID);
		world.setBlock(i + 4, j + 2, k + 23, DivineRPGTwilight.hallWall.blockID);
		world.setBlock(i + 4, j + 2, k + 24, DivineRPGTwilight.hallWall.blockID);
		world.setBlock(i + 4, j + 2, k + 25, DivineRPGTwilight.hallWall.blockID);
		world.setBlock(i + 4, j + 2, k + 26, DivineRPGTwilight.hallWall.blockID);
		world.setBlock(i + 4, j + 2, k + 27, DivineRPGTwilight.hallWall.blockID);
		world.setBlock(i + 4, j + 2, k + 28, DivineRPGTwilight.hallWall.blockID);
		world.setBlock(i + 4, j + 2, k + 29, DivineRPGTwilight.hallWall.blockID);
		world.setBlock(i + 4, j + 2, k + 30, DivineRPGTwilight.hallWall.blockID);
		world.setBlock(i + 4, j + 2, k + 31, DivineRPGTwilight.hallWall.blockID);
		world.setBlock(i + 4, j + 2, k + 32, DivineRPGTwilight.hallWall.blockID);
		world.setBlock(i + 4, j + 2, k + 33, DivineRPGTwilight.hallWall.blockID);
		world.setBlock(i + 4, j + 2, k + 36, DivineRPGTwilight.hallWall.blockID);
		world.setBlock(i + 4, j + 3, k + 1, DivineRPGTwilight.darkEverstone.blockID);
		world.setBlock(i + 4, j + 3, k + 2, DivineRPGTwilight.hallWall.blockID);
		world.setBlock(i + 4, j + 3, k + 14, DivineRPGTwilight.hallWall.blockID);
		world.setBlock(i + 4, j + 3, k + 15, DivineRPGTwilight.hallWall.blockID);
		world.setBlock(i + 4, j + 3, k + 16, DivineRPGTwilight.hallWall.blockID);
		world.setBlock(i + 4, j + 3, k + 17, DivineRPGTwilight.hallWall.blockID);
		world.setBlock(i + 4, j + 3, k + 18, DivineRPGTwilight.hallWall.blockID);
		world.setBlock(i + 4, j + 3, k + 19, DivineRPGTwilight.hallWall.blockID);
		world.setBlock(i + 4, j + 3, k + 20, DivineRPGTwilight.hallWall.blockID);
		world.setBlock(i + 4, j + 3, k + 21, DivineRPGTwilight.hallWall.blockID);
		world.setBlock(i + 4, j + 3, k + 22, DivineRPGTwilight.hallWall.blockID);
		world.setBlock(i + 4, j + 3, k + 23, DivineRPGTwilight.hallWall.blockID);
		world.setBlock(i + 4, j + 3, k + 24, DivineRPGTwilight.hallWall.blockID);
		world.setBlock(i + 4, j + 3, k + 25, DivineRPGTwilight.hallWall.blockID);
		world.setBlock(i + 4, j + 3, k + 26, DivineRPGTwilight.hallWall.blockID);
		world.setBlock(i + 4, j + 3, k + 27, DivineRPGTwilight.hallWall.blockID);
		world.setBlock(i + 4, j + 3, k + 28, DivineRPGTwilight.hallWall.blockID);
		world.setBlock(i + 4, j + 3, k + 29, DivineRPGTwilight.hallWall.blockID);
		world.setBlock(i + 4, j + 3, k + 30, DivineRPGTwilight.hallWall.blockID);
		world.setBlock(i + 4, j + 3, k + 31, DivineRPGTwilight.hallWall.blockID);
		world.setBlock(i + 4, j + 3, k + 32, DivineRPGTwilight.hallWall.blockID);
		world.setBlock(i + 4, j + 3, k + 33, DivineRPGTwilight.hallWall.blockID);
		world.setBlock(i + 4, j + 3, k + 34, DivineRPGTwilight.hallWall.blockID);
		world.setBlock(i + 4, j + 3, k + 35, DivineRPGTwilight.hallWall.blockID);
		world.setBlock(i + 4, j + 3, k + 36, DivineRPGTwilight.hallWall.blockID);
		world.setBlock(i + 4, j + 4, k + 0, DivineRPGTwilight.darkEverstone.blockID);
		world.setBlock(i + 4, j + 4, k + 1, DivineRPGTwilight.darkEverstone.blockID);
		world.setBlock(i + 4, j + 4, k + 2, DivineRPGTwilight.hallWall.blockID);
		world.setBlock(i + 4, j + 4, k + 14, DivineRPGTwilight.hallWall.blockID);
		world.setBlock(i + 4, j + 4, k + 15, DivineRPGTwilight.hallWall.blockID);
		world.setBlock(i + 4, j + 4, k + 16, DivineRPGTwilight.bacterialAcid.blockID);
		world.setBlock(i + 4, j + 4, k + 17, DivineRPGTwilight.bacterialAcid.blockID);
		world.setBlock(i + 4, j + 4, k + 18, DivineRPGTwilight.bacterialAcid.blockID);
		world.setBlock(i + 4, j + 4, k + 19, DivineRPGTwilight.bacterialAcid.blockID);
		world.setBlock(i + 4, j + 4, k + 20, DivineRPGTwilight.bacterialAcid.blockID);
		world.setBlock(i + 4, j + 4, k + 21, DivineRPGTwilight.bacterialAcid.blockID);
		world.setBlock(i + 4, j + 4, k + 22, DivineRPGTwilight.bacterialAcid.blockID);
		world.setBlock(i + 4, j + 4, k + 23, DivineRPGTwilight.bacterialAcid.blockID);
		world.setBlock(i + 4, j + 4, k + 24, DivineRPGTwilight.bacterialAcid.blockID);
		world.setBlock(i + 4, j + 4, k + 25, DivineRPGTwilight.bacterialAcid.blockID);
		world.setBlock(i + 4, j + 4, k + 26, DivineRPGTwilight.bacterialAcid.blockID);
		world.setBlock(i + 4, j + 4, k + 27, DivineRPGTwilight.bacterialAcid.blockID);
		world.setBlock(i + 4, j + 4, k + 28, DivineRPGTwilight.bacterialAcid.blockID);
		world.setBlock(i + 4, j + 4, k + 29, DivineRPGTwilight.bacterialAcid.blockID);
		world.setBlock(i + 4, j + 4, k + 30, DivineRPGTwilight.bacterialAcid.blockID);
		world.setBlock(i + 4, j + 4, k + 31, DivineRPGTwilight.bacterialAcid.blockID);
		world.setBlock(i + 4, j + 4, k + 32, DivineRPGTwilight.bacterialAcid.blockID);
		world.setBlock(i + 4, j + 4, k + 35, DivineRPGTwilight.hallWall.blockID);
		world.setBlock(i + 4, j + 5, k + 0, DivineRPGTwilight.darkEverstone.blockID);
		world.setBlock(i + 4, j + 5, k + 1, DivineRPGTwilight.hallWall.blockID);
		world.setBlock(i + 4, j + 5, k + 2, DivineRPGTwilight.firecrystal.blockID);
		world.setBlock(i + 4, j + 5, k + 3, DivineRPGTwilight.firecrystal.blockID);
		world.setBlock(i + 4, j + 5, k + 4, DivineRPGTwilight.firecrystal.blockID);
		world.setBlock(i + 4, j + 5, k + 5, DivineRPGTwilight.firecrystal.blockID);
		world.setBlock(i + 4, j + 5, k + 6, DivineRPGTwilight.firecrystal.blockID);
		world.setBlock(i + 4, j + 5, k + 7, DivineRPGTwilight.firecrystal.blockID);
		world.setBlock(i + 4, j + 5, k + 8, DivineRPGTwilight.firecrystal.blockID);
		world.setBlock(i + 4, j + 5, k + 9, DivineRPGTwilight.firecrystal.blockID);
		world.setBlock(i + 4, j + 5, k + 10, DivineRPGTwilight.firecrystal.blockID);
		world.setBlock(i + 4, j + 5, k + 11, DivineRPGTwilight.firecrystal.blockID);
		world.setBlock(i + 4, j + 5, k + 12, DivineRPGTwilight.firecrystal.blockID);
		world.setBlock(i + 4, j + 5, k + 13, DivineRPGTwilight.firecrystal.blockID);
		world.setBlock(i + 4, j + 5, k + 14, DivineRPGTwilight.firecrystal.blockID);
		world.setBlock(i + 4, j + 5, k + 15, DivineRPGTwilight.firecrystal.blockID);
		world.setBlock(i + 4, j + 5, k + 16, DivineRPGTwilight.hallWall.blockID);
		world.setBlock(i + 4, j + 5, k + 17, DivineRPGTwilight.firecrystal.blockID);
		world.setBlock(i + 4, j + 5, k + 19, DivineRPGTwilight.firecrystal.blockID);
		world.setBlock(i + 4, j + 5, k + 21, DivineRPGTwilight.firecrystal.blockID);
		world.setBlock(i + 4, j + 5, k + 23, DivineRPGTwilight.firecrystal.blockID);
		world.setBlock(i + 4, j + 5, k + 25, DivineRPGTwilight.firecrystal.blockID);
		world.setBlock(i + 4, j + 5, k + 27, DivineRPGTwilight.firecrystal.blockID);
		world.setBlock(i + 4, j + 5, k + 29, DivineRPGTwilight.firecrystal.blockID);
		world.setBlock(i + 4, j + 5, k + 31, DivineRPGTwilight.firecrystal.blockID);
		world.setBlock(i + 4, j + 5, k + 33, DivineRPGTwilight.firecrystal.blockID);
		world.setBlock(i + 4, j + 5, k + 34, DivineRPGTwilight.firecrystal.blockID);
		world.setBlock(i + 4, j + 5, k + 35, DivineRPGTwilight.hallWall.blockID);
		world.setBlock(i + 4, j + 6, k + 0, DivineRPGTwilight.darkEverstone.blockID);
		world.setBlock(i + 4, j + 6, k + 1, DivineRPGTwilight.hallWall.blockID);
		world.setBlock(i + 4, j + 6, k + 35, DivineRPGTwilight.hallWall.blockID);
		world.setBlock(i + 4, j + 7, k + 0, DivineRPGTwilight.hallWall.blockID);
		world.setBlock(i + 4, j + 7, k + 1, DivineRPGTwilight.darkEverstone.blockID);
		world.setBlock(i + 4, j + 7, k + 35, DivineRPGTwilight.hallWall.blockID);
		world.setBlock(i + 4, j + 8, k + 1, DivineRPGTwilight.hallWall.blockID);
		world.setBlock(i + 4, j + 8, k + 35, DivineRPGTwilight.hallWall.blockID);
		world.setBlock(i + 4, j + 9, k + 2, DivineRPGTwilight.hallWall.blockID);
		world.setBlock(i + 4, j + 9, k + 3, DivineRPGTwilight.hallWall.blockID);
		world.setBlock(i + 4, j + 9, k + 4, DivineRPGTwilight.hallWall.blockID);
		world.setBlock(i + 4, j + 9, k + 5, DivineRPGTwilight.hallWall.blockID);
		world.setBlock(i + 4, j + 9, k + 6, DivineRPGTwilight.hallWall.blockID);
		world.setBlock(i + 4, j + 9, k + 7, DivineRPGTwilight.hallWall.blockID);
		world.setBlock(i + 4, j + 9, k + 8, DivineRPGTwilight.hallWall.blockID);
		world.setBlock(i + 4, j + 9, k + 9, DivineRPGTwilight.hallWall.blockID);
		world.setBlock(i + 4, j + 9, k + 10, DivineRPGTwilight.hallWall.blockID);
		world.setBlock(i + 4, j + 9, k + 11, DivineRPGTwilight.hallWall.blockID);
		world.setBlock(i + 4, j + 9, k + 12, DivineRPGTwilight.hallWall.blockID);
		world.setBlock(i + 4, j + 9, k + 13, DivineRPGTwilight.hallWall.blockID);
		world.setBlock(i + 4, j + 9, k + 14, DivineRPGTwilight.hallWall.blockID);
		world.setBlock(i + 4, j + 9, k + 15, DivineRPGTwilight.hallWall.blockID);
		world.setBlock(i + 4, j + 9, k + 16, DivineRPGTwilight.hallWall.blockID);
		world.setBlock(i + 4, j + 9, k + 17, DivineRPGTwilight.hallWall.blockID);
		world.setBlock(i + 4, j + 9, k + 18, DivineRPGTwilight.hallWall.blockID);
		world.setBlock(i + 4, j + 9, k + 19, DivineRPGTwilight.hallWall.blockID);
		world.setBlock(i + 4, j + 9, k + 20, DivineRPGTwilight.hallWall.blockID);
		world.setBlock(i + 4, j + 9, k + 21, DivineRPGTwilight.hallWall.blockID);
		world.setBlock(i + 4, j + 9, k + 22, DivineRPGTwilight.hallWall.blockID);
		world.setBlock(i + 4, j + 9, k + 23, DivineRPGTwilight.hallWall.blockID);
		world.setBlock(i + 4, j + 9, k + 24, DivineRPGTwilight.hallWall.blockID);
		world.setBlock(i + 4, j + 9, k + 25, DivineRPGTwilight.hallWall.blockID);
		world.setBlock(i + 4, j + 9, k + 26, DivineRPGTwilight.hallWall.blockID);
		world.setBlock(i + 4, j + 9, k + 27, DivineRPGTwilight.hallWall.blockID);
		world.setBlock(i + 4, j + 9, k + 28, DivineRPGTwilight.hallWall.blockID);
		world.setBlock(i + 4, j + 9, k + 29, DivineRPGTwilight.hallWall.blockID);
		world.setBlock(i + 4, j + 9, k + 30, DivineRPGTwilight.hallWall.blockID);
		world.setBlock(i + 4, j + 9, k + 31, DivineRPGTwilight.hallWall.blockID);
		world.setBlock(i + 4, j + 9, k + 32, DivineRPGTwilight.hallWall.blockID);
		world.setBlock(i + 4, j + 9, k + 33, DivineRPGTwilight.hallWall.blockID);
		world.setBlock(i + 4, j + 9, k + 34, DivineRPGTwilight.hallWall.blockID);
		world.setBlock(i + 5, j + 0, k + 2, DivineRPGTwilight.hallWall.blockID);
		world.setBlock(i + 5, j + 0, k + 14, DivineRPGTwilight.hallWall.blockID);
		world.setBlock(i + 5, j + 0, k + 16, DivineRPGTwilight.hallWall.blockID);
		world.setBlock(i + 5, j + 0, k + 17, DivineRPGTwilight.hallWall.blockID);
		world.setBlock(i + 5, j + 0, k + 18, DivineRPGTwilight.hallWall.blockID);
		world.setBlock(i + 5, j + 0, k + 33, DivineRPGTwilight.hallWall.blockID);
		world.setBlock(i + 5, j + 0, k + 34, DivineRPGTwilight.firecrystal.blockID);
		world.setBlock(i + 5, j + 0, k + 35, DivineRPGTwilight.firecrystal.blockID);
		world.setBlock(i + 5, j + 0, k + 36, DivineRPGTwilight.hallWall.blockID);
		world.setBlock(i + 5, j + 1, k + 2, DivineRPGTwilight.hallWall.blockID);
		world.setBlock(i + 5, j + 1, k + 14, DivineRPGTwilight.hallWall.blockID);
		world.setBlock(i + 5, j + 1, k + 16, DivineRPGTwilight.hallWall.blockID);
		world.setBlock(i + 5, j + 1, k + 17, DivineRPGTwilight.hallWall.blockID);
		world.setBlock(i + 5, j + 1, k + 18, DivineRPGTwilight.hallWall.blockID);
		world.setBlock(i + 5, j + 1, k + 33, DivineRPGTwilight.hallWall.blockID);
		world.setBlock(i + 5, j + 1, k + 36, DivineRPGTwilight.hallWall.blockID);
		world.setBlock(i + 5, j + 2, k + 2, DivineRPGTwilight.hallWall.blockID);
		world.setBlock(i + 5, j + 2, k + 14, DivineRPGTwilight.hallWall.blockID);
		world.setBlock(i + 5, j + 2, k + 16, DivineRPGTwilight.hallWall.blockID);
		world.setBlock(i + 5, j + 2, k + 17, DivineRPGTwilight.hallWall.blockID);
		world.setBlock(i + 5, j + 2, k + 33, DivineRPGTwilight.hallWall.blockID);
		world.setBlock(i + 5, j + 2, k + 36, DivineRPGTwilight.hallWall.blockID);
		world.setBlock(i + 5, j + 3, k + 2, DivineRPGTwilight.hallWall.blockID);
		world.setBlock(i + 5, j + 3, k + 14, DivineRPGTwilight.hallWall.blockID);
		world.setBlock(i + 5, j + 3, k + 15, DivineRPGTwilight.hallWall.blockID);
		world.setBlock(i + 5, j + 3, k + 16, DivineRPGTwilight.hallWall.blockID);
		world.setBlock(i + 5, j + 3, k + 18, DivineRPGTwilight.hallWall.blockID);
		world.setBlock(i + 5, j + 3, k + 33, DivineRPGTwilight.hallWall.blockID);
		world.setBlock(i + 5, j + 3, k + 34, DivineRPGTwilight.hallWall.blockID);
		world.setBlock(i + 5, j + 3, k + 35, DivineRPGTwilight.hallWall.blockID);
		world.setBlock(i + 5, j + 3, k + 36, DivineRPGTwilight.hallWall.blockID);
		world.setBlock(i + 5, j + 4, k + 2, DivineRPGTwilight.hallWall.blockID);
		world.setBlock(i + 5, j + 4, k + 14, DivineRPGTwilight.hallWall.blockID);
		world.setBlock(i + 5, j + 4, k + 15, DivineRPGTwilight.hallWall.blockID);
		world.setBlock(i + 5, j + 4, k + 16, DivineRPGTwilight.bacterialAcid.blockID);
		world.setBlock(i + 5, j + 4, k + 17, DivineRPGTwilight.bacterialAcid.blockID);
		world.setBlock(i + 5, j + 4, k + 18, DivineRPGTwilight.bacterialAcid.blockID);
		world.setBlock(i + 5, j + 4, k + 19, DivineRPGTwilight.bacterialAcid.blockID);
		world.setBlock(i + 5, j + 4, k + 20, DivineRPGTwilight.bacterialAcid.blockID);
		world.setBlock(i + 5, j + 4, k + 21, DivineRPGTwilight.bacterialAcid.blockID);
		world.setBlock(i + 5, j + 4, k + 22, DivineRPGTwilight.bacterialAcid.blockID);
		world.setBlock(i + 5, j + 4, k + 23, DivineRPGTwilight.bacterialAcid.blockID);
		world.setBlock(i + 5, j + 4, k + 24, DivineRPGTwilight.bacterialAcid.blockID);
		world.setBlock(i + 5, j + 4, k + 25, DivineRPGTwilight.bacterialAcid.blockID);
		world.setBlock(i + 5, j + 4, k + 26, DivineRPGTwilight.bacterialAcid.blockID);
		world.setBlock(i + 5, j + 4, k + 27, DivineRPGTwilight.bacterialAcid.blockID);
		world.setBlock(i + 5, j + 4, k + 28, DivineRPGTwilight.bacterialAcid.blockID);
		world.setBlock(i + 5, j + 4, k + 29, DivineRPGTwilight.bacterialAcid.blockID);
		world.setBlock(i + 5, j + 4, k + 30, DivineRPGTwilight.bacterialAcid.blockID);
		world.setBlock(i + 5, j + 4, k + 31, DivineRPGTwilight.bacterialAcid.blockID);
		world.setBlock(i + 5, j + 4, k + 33, DivineRPGTwilight.bacterialAcid.blockID);
		world.setBlock(i + 5, j + 4, k + 34, DivineRPGTwilight.bacterialAcid.blockID);
		world.setBlock(i + 5, j + 4, k + 35, DivineRPGTwilight.hallWall.blockID);
		world.setBlock(i + 5, j + 5, k + 1, DivineRPGTwilight.hallWall.blockID);
		world.setBlock(i + 5, j + 5, k + 2, DivineRPGTwilight.firecrystal.blockID);
		world.setBlock(i + 5, j + 5, k + 3, DivineRPGTwilight.firecrystal.blockID);
		world.setBlock(i + 5, j + 5, k + 4, DivineRPGTwilight.firecrystal.blockID);
		world.setBlock(i + 5, j + 5, k + 5, DivineRPGTwilight.firecrystal.blockID);
		world.setBlock(i + 5, j + 5, k + 6, DivineRPGTwilight.firecrystal.blockID);
		world.setBlock(i + 5, j + 5, k + 7, DivineRPGTwilight.firecrystal.blockID);
		world.setBlock(i + 5, j + 5, k + 8, DivineRPGTwilight.firecrystal.blockID);
		world.setBlock(i + 5, j + 5, k + 9, DivineRPGTwilight.firecrystal.blockID);
		world.setBlock(i + 5, j + 5, k + 10, DivineRPGTwilight.firecrystal.blockID);
		world.setBlock(i + 5, j + 5, k + 11, DivineRPGTwilight.firecrystal.blockID);
		world.setBlock(i + 5, j + 5, k + 12, DivineRPGTwilight.firecrystal.blockID);
		world.setBlock(i + 5, j + 5, k + 13, DivineRPGTwilight.firecrystal.blockID);
		world.setBlock(i + 5, j + 5, k + 14, DivineRPGTwilight.firecrystal.blockID);
		world.setBlock(i + 5, j + 5, k + 15, DivineRPGTwilight.firecrystal.blockID);
		world.setBlock(i + 5, j + 5, k + 16, DivineRPGTwilight.firecrystal.blockID);
		world.setBlock(i + 5, j + 5, k + 18, DivineRPGTwilight.firecrystal.blockID);
		world.setBlock(i + 5, j + 5, k + 20, DivineRPGTwilight.firecrystal.blockID);
		world.setBlock(i + 5, j + 5, k + 22, DivineRPGTwilight.firecrystal.blockID);
		world.setBlock(i + 5, j + 5, k + 24, DivineRPGTwilight.firecrystal.blockID);
		world.setBlock(i + 5, j + 5, k + 26, DivineRPGTwilight.firecrystal.blockID);
		world.setBlock(i + 5, j + 5, k + 28, DivineRPGTwilight.firecrystal.blockID);
		world.setBlock(i + 5, j + 5, k + 30, DivineRPGTwilight.firecrystal.blockID);
		world.setBlock(i + 5, j + 5, k + 32, DivineRPGTwilight.firecrystal.blockID);
		world.setBlock(i + 5, j + 5, k + 34, DivineRPGTwilight.firecrystal.blockID);
		world.setBlock(i + 5, j + 5, k + 35, DivineRPGTwilight.hallWall.blockID);
		world.setBlock(i + 5, j + 6, k + 1, DivineRPGTwilight.hallWall.blockID);
		world.setBlock(i + 5, j + 6, k + 35, DivineRPGTwilight.hallWall.blockID);
		world.setBlock(i + 5, j + 7, k + 0, DivineRPGTwilight.hallWall.blockID);
		world.setBlock(i + 5, j + 7, k + 1, DivineRPGTwilight.darkEverstone.blockID);
		world.setBlock(i + 5, j + 7, k + 35, DivineRPGTwilight.hallWall.blockID);
		world.setBlock(i + 5, j + 8, k + 1, DivineRPGTwilight.hallWall.blockID);
		world.setBlock(i + 5, j + 8, k + 35, DivineRPGTwilight.hallWall.blockID);
		world.setBlock(i + 5, j + 9, k + 2, DivineRPGTwilight.hallWall.blockID);
		world.setBlock(i + 5, j + 9, k + 3, DivineRPGTwilight.hallWall.blockID);
		world.setBlock(i + 5, j + 9, k + 4, DivineRPGTwilight.hallWall.blockID);
		world.setBlock(i + 5, j + 9, k + 5, DivineRPGTwilight.hallWall.blockID);
		world.setBlock(i + 5, j + 9, k + 6, DivineRPGTwilight.hallWall.blockID);
		world.setBlock(i + 5, j + 9, k + 7, DivineRPGTwilight.hallWall.blockID);
		world.setBlock(i + 5, j + 9, k + 8, DivineRPGTwilight.hallWall.blockID);
		world.setBlock(i + 5, j + 9, k + 9, DivineRPGTwilight.hallWall.blockID);
		world.setBlock(i + 5, j + 9, k + 10, DivineRPGTwilight.hallWall.blockID);
		world.setBlock(i + 5, j + 9, k + 11, DivineRPGTwilight.hallWall.blockID);
		world.setBlock(i + 5, j + 9, k + 12, DivineRPGTwilight.hallWall.blockID);
		world.setBlock(i + 5, j + 9, k + 13, DivineRPGTwilight.hallWall.blockID);
		world.setBlock(i + 5, j + 9, k + 14, DivineRPGTwilight.hallWall.blockID);
		world.setBlock(i + 5, j + 9, k + 15, DivineRPGTwilight.hallWall.blockID);
		world.setBlock(i + 5, j + 9, k + 16, DivineRPGTwilight.hallWall.blockID);
		world.setBlock(i + 5, j + 9, k + 17, DivineRPGTwilight.hallWall.blockID);
		world.setBlock(i + 5, j + 9, k + 18, DivineRPGTwilight.hallWall.blockID);
		world.setBlock(i + 5, j + 9, k + 19, DivineRPGTwilight.hallWall.blockID);
		world.setBlock(i + 5, j + 9, k + 20, DivineRPGTwilight.hallWall.blockID);
		world.setBlock(i + 5, j + 9, k + 21, DivineRPGTwilight.hallWall.blockID);
		world.setBlock(i + 5, j + 9, k + 22, DivineRPGTwilight.hallWall.blockID);
		world.setBlock(i + 5, j + 9, k + 23, DivineRPGTwilight.hallWall.blockID);
		world.setBlock(i + 5, j + 9, k + 24, DivineRPGTwilight.hallWall.blockID);
		world.setBlock(i + 5, j + 9, k + 25, DivineRPGTwilight.hallWall.blockID);
		world.setBlock(i + 5, j + 9, k + 26, DivineRPGTwilight.hallWall.blockID);
		world.setBlock(i + 5, j + 9, k + 27, DivineRPGTwilight.hallWall.blockID);
		world.setBlock(i + 5, j + 9, k + 28, DivineRPGTwilight.hallWall.blockID);
		world.setBlock(i + 5, j + 9, k + 29, DivineRPGTwilight.hallWall.blockID);
		world.setBlock(i + 5, j + 9, k + 30, DivineRPGTwilight.hallWall.blockID);
		world.setBlock(i + 5, j + 9, k + 31, DivineRPGTwilight.hallWall.blockID);
		world.setBlock(i + 5, j + 9, k + 32, DivineRPGTwilight.hallWall.blockID);
		world.setBlock(i + 5, j + 9, k + 33, DivineRPGTwilight.hallWall.blockID);
		world.setBlock(i + 5, j + 9, k + 34, DivineRPGTwilight.hallWall.blockID);
		world.setBlock(i + 6, j + 0, k + 2, DivineRPGTwilight.hallWall.blockID);
		world.setBlock(i + 6, j + 0, k + 14, DivineRPGTwilight.hallWall.blockID);
		world.setBlock(i + 6, j + 0, k + 15, DivineRPGTwilight.hallWall.blockID);
		world.setBlock(i + 6, j + 0, k + 16, DivineRPGTwilight.hallWall.blockID);
		world.setBlock(i + 6, j + 0, k + 17, DivineRPGTwilight.hallWall.blockID);
		world.setBlock(i + 6, j + 0, k + 18, DivineRPGTwilight.hallWall.blockID);
		world.setBlock(i + 6, j + 0, k + 33, DivineRPGTwilight.hallWall.blockID);
		world.setBlock(i + 6, j + 0, k + 34, DivineRPGTwilight.firecrystal.blockID);
		world.setBlock(i + 6, j + 0, k + 35, DivineRPGTwilight.firecrystal.blockID);
		world.setBlock(i + 6, j + 0, k + 36, DivineRPGTwilight.hallWall.blockID);
		world.setBlock(i + 6, j + 1, k + 2, DivineRPGTwilight.hallWall.blockID);
		world.setBlock(i + 6, j + 1, k + 14, DivineRPGTwilight.hallWall.blockID);
		world.setBlock(i + 6, j + 1, k + 15, DivineRPGTwilight.hallWall.blockID);
		world.setBlock(i + 6, j + 1, k + 16, DivineRPGTwilight.hallWall.blockID);
		world.setBlock(i + 6, j + 1, k + 17, DivineRPGTwilight.hallWall.blockID);
		world.setBlock(i + 6, j + 1, k + 18, DivineRPGTwilight.hallWall.blockID);
		world.setBlock(i + 6, j + 1, k + 33, DivineRPGTwilight.hallWall.blockID);
		world.setBlock(i + 6, j + 1, k + 36, DivineRPGTwilight.hallWall.blockID);
		world.setBlock(i + 6, j + 2, k + 2, DivineRPGTwilight.hallWall.blockID);
		world.setBlock(i + 6, j + 2, k + 14, DivineRPGTwilight.hallWall.blockID);
		world.setBlock(i + 6, j + 2, k + 15, DivineRPGTwilight.hallWall.blockID);
		world.setBlock(i + 6, j + 2, k + 16, DivineRPGTwilight.hallWall.blockID);
		world.setBlock(i + 6, j + 2, k + 17, DivineRPGTwilight.hallWall.blockID);
		world.setBlock(i + 6, j + 2, k + 18, DivineRPGTwilight.hallWall.blockID);
		world.setBlock(i + 6, j + 2, k + 33, DivineRPGTwilight.hallWall.blockID);
		world.setBlock(i + 6, j + 2, k + 36, DivineRPGTwilight.hallWall.blockID);
		world.setBlock(i + 6, j + 3, k + 2, DivineRPGTwilight.hallWall.blockID);
		world.setBlock(i + 6, j + 3, k + 14, DivineRPGTwilight.hallWall.blockID);
		world.setBlock(i + 6, j + 3, k + 15, DivineRPGTwilight.hallWall.blockID);
		world.setBlock(i + 6, j + 3, k + 16, DivineRPGTwilight.hallWall.blockID);
		world.setBlock(i + 6, j + 3, k + 17, DivineRPGTwilight.hallWall.blockID);
		world.setBlock(i + 6, j + 3, k + 18, DivineRPGTwilight.hallWall.blockID);
		world.setBlock(i + 6, j + 3, k + 33, DivineRPGTwilight.hallWall.blockID);
		world.setBlock(i + 6, j + 3, k + 34, DivineRPGTwilight.hallWall.blockID);
		world.setBlock(i + 6, j + 3, k + 35, DivineRPGTwilight.hallWall.blockID);
		world.setBlock(i + 6, j + 3, k + 36, DivineRPGTwilight.hallWall.blockID);
		world.setBlock(i + 6, j + 4, k + 2, DivineRPGTwilight.hallWall.blockID);
		world.setBlock(i + 6, j + 4, k + 14, DivineRPGTwilight.hallWall.blockID);
		world.setBlock(i + 6, j + 4, k + 15, DivineRPGTwilight.hallWall.blockID);
		world.setBlock(i + 6, j + 4, k + 16, DivineRPGTwilight.hallWall.blockID);
		world.setBlock(i + 6, j + 4, k + 17, DivineRPGTwilight.hallWall.blockID);
		world.setBlock(i + 6, j + 4, k + 18, DivineRPGTwilight.hallWall.blockID);
		world.setBlock(i + 6, j + 4, k + 19, DivineRPGTwilight.hallWall.blockID);
		world.setBlock(i + 6, j + 4, k + 20, DivineRPGTwilight.hallWall.blockID);
		world.setBlock(i + 6, j + 4, k + 21, DivineRPGTwilight.hallWall.blockID);
		world.setBlock(i + 6, j + 4, k + 22, DivineRPGTwilight.hallWall.blockID);
		world.setBlock(i + 6, j + 4, k + 23, DivineRPGTwilight.hallWall.blockID);
		world.setBlock(i + 6, j + 4, k + 24, DivineRPGTwilight.hallWall.blockID);
		world.setBlock(i + 6, j + 4, k + 25, DivineRPGTwilight.hallWall.blockID);
		world.setBlock(i + 6, j + 4, k + 26, DivineRPGTwilight.hallWall.blockID);
		world.setBlock(i + 6, j + 4, k + 27, DivineRPGTwilight.hallWall.blockID);
		world.setBlock(i + 6, j + 4, k + 28, DivineRPGTwilight.hallWall.blockID);
		world.setBlock(i + 6, j + 4, k + 29, DivineRPGTwilight.hallWall.blockID);
		world.setBlock(i + 6, j + 4, k + 30, DivineRPGTwilight.hallWall.blockID);
		world.setBlock(i + 6, j + 4, k + 31, DivineRPGTwilight.hallWall.blockID);
		world.setBlock(i + 6, j + 4, k + 32, DivineRPGTwilight.hallWall.blockID);
		world.setBlock(i + 6, j + 4, k + 33, DivineRPGTwilight.bacterialAcid.blockID);
		world.setBlock(i + 6, j + 4, k + 34, DivineRPGTwilight.bacterialAcid.blockID);
		world.setBlock(i + 6, j + 4, k + 35, DivineRPGTwilight.hallWall.blockID);
		world.setBlock(i + 6, j + 5, k + 1, DivineRPGTwilight.hallWall.blockID);
		world.setBlock(i + 6, j + 5, k + 2, DivineRPGTwilight.firecrystal.blockID);
		world.setBlock(i + 6, j + 5, k + 3, DivineRPGTwilight.firecrystal.blockID);
		world.setBlock(i + 6, j + 5, k + 4, DivineRPGTwilight.firecrystal.blockID);
		world.setBlock(i + 6, j + 5, k + 5, DivineRPGTwilight.firecrystal.blockID);
		world.setBlock(i + 6, j + 5, k + 6, DivineRPGTwilight.firecrystal.blockID);
		world.setBlock(i + 6, j + 5, k + 7, DivineRPGTwilight.firecrystal.blockID);
		world.setBlock(i + 6, j + 5, k + 8, DivineRPGTwilight.firecrystal.blockID);
		world.setBlock(i + 6, j + 5, k + 9, DivineRPGTwilight.firecrystal.blockID);
		world.setBlock(i + 6, j + 5, k + 10, DivineRPGTwilight.firecrystal.blockID);
		world.setBlock(i + 6, j + 5, k + 11, DivineRPGTwilight.firecrystal.blockID);
		world.setBlock(i + 6, j + 5, k + 12, DivineRPGTwilight.firecrystal.blockID);
		world.setBlock(i + 6, j + 5, k + 13, DivineRPGTwilight.firecrystal.blockID);
		world.setBlock(i + 6, j + 5, k + 14, DivineRPGTwilight.firecrystal.blockID);
		world.setBlock(i + 6, j + 5, k + 15, DivineRPGTwilight.hallWall.blockID);
		world.setBlock(i + 6, j + 5, k + 16, DivineRPGTwilight.hallWall.blockID);
		world.setBlock(i + 6, j + 5, k + 17, DivineRPGTwilight.hallWall.blockID);
		world.setBlock(i + 6, j + 5, k + 18, DivineRPGTwilight.hallWall.blockID);
		world.setBlock(i + 6, j + 5, k + 19, DivineRPGTwilight.hallWall.blockID);
		world.setBlock(i + 6, j + 5, k + 20, DivineRPGTwilight.hallWall.blockID);
		world.setBlock(i + 6, j + 5, k + 21, DivineRPGTwilight.hallWall.blockID);
		world.setBlock(i + 6, j + 5, k + 22, DivineRPGTwilight.hallWall.blockID);
		world.setBlock(i + 6, j + 5, k + 23, DivineRPGTwilight.hallWall.blockID);
		world.setBlock(i + 6, j + 5, k + 24, DivineRPGTwilight.hallWall.blockID);
		world.setBlock(i + 6, j + 5, k + 25, DivineRPGTwilight.hallWall.blockID);
		world.setBlock(i + 6, j + 5, k + 26, DivineRPGTwilight.hallWall.blockID);
		world.setBlock(i + 6, j + 5, k + 27, DivineRPGTwilight.hallWall.blockID);
		world.setBlock(i + 6, j + 5, k + 28, DivineRPGTwilight.hallWall.blockID);
		world.setBlock(i + 6, j + 5, k + 29, DivineRPGTwilight.hallWall.blockID);
		world.setBlock(i + 6, j + 5, k + 30, DivineRPGTwilight.hallWall.blockID);
		world.setBlock(i + 6, j + 5, k + 31, DivineRPGTwilight.hallWall.blockID);
		world.setBlock(i + 6, j + 5, k + 32, DivineRPGTwilight.hallWall.blockID);
		world.setBlock(i + 6, j + 5, k + 35, DivineRPGTwilight.hallWall.blockID);
		world.setBlock(i + 6, j + 6, k + 1, DivineRPGTwilight.hallWall.blockID);
		world.setBlock(i + 6, j + 6, k + 6, DivineRPGTwilight.hallWall.blockID);
		world.setBlock(i + 6, j + 6, k + 7, DivineRPGTwilight.hallWall.blockID);
		world.setBlock(i + 6, j + 6, k + 15, DivineRPGTwilight.hallWall.blockID);
		world.setBlock(i + 6, j + 6, k + 16, DivineRPGTwilight.hallWall.blockID);
		world.setBlock(i + 6, j + 6, k + 17, DivineRPGTwilight.hallWall.blockID);
		world.setBlock(i + 6, j + 6, k + 18, DivineRPGTwilight.hallWall.blockID);
		world.setBlock(i + 6, j + 6, k + 19, DivineRPGTwilight.hallWall.blockID);
		world.setBlock(i + 6, j + 6, k + 20, DivineRPGTwilight.hallWall.blockID);
		world.setBlock(i + 6, j + 6, k + 21, DivineRPGTwilight.hallWall.blockID);
		world.setBlock(i + 6, j + 6, k + 22, DivineRPGTwilight.hallWall.blockID);
		world.setBlock(i + 6, j + 6, k + 23, DivineRPGTwilight.hallWall.blockID);
		world.setBlock(i + 6, j + 6, k + 24, DivineRPGTwilight.hallWall.blockID);
		world.setBlock(i + 6, j + 6, k + 25, DivineRPGTwilight.hallWall.blockID);
		world.setBlock(i + 6, j + 6, k + 26, DivineRPGTwilight.hallWall.blockID);
		world.setBlock(i + 6, j + 6, k + 27, DivineRPGTwilight.hallWall.blockID);
		world.setBlock(i + 6, j + 6, k + 28, DivineRPGTwilight.hallWall.blockID);
		world.setBlock(i + 6, j + 6, k + 29, DivineRPGTwilight.hallWall.blockID);
		world.setBlock(i + 6, j + 6, k + 30, DivineRPGTwilight.hallWall.blockID);
		world.setBlock(i + 6, j + 6, k + 31, DivineRPGTwilight.hallWall.blockID);
		world.setBlock(i + 6, j + 6, k + 32, DivineRPGTwilight.hallWall.blockID);
		world.setBlock(i + 6, j + 6, k + 35, DivineRPGTwilight.hallWall.blockID);
		world.setBlock(i + 6, j + 7, k + 0, DivineRPGTwilight.hallWall.blockID);
		world.setBlock(i + 6, j + 7, k + 1, DivineRPGTwilight.darkEverstone.blockID);
		world.setBlock(i + 6, j + 7, k + 6, DivineRPGTwilight.hallWall.blockID);
		world.setBlock(i + 6, j + 7, k + 7, DivineRPGTwilight.hallWall.blockID);
		world.setBlock(i + 6, j + 7, k + 15, DivineRPGTwilight.hallWall.blockID);
		world.setBlock(i + 6, j + 7, k + 16, DivineRPGTwilight.hallWall.blockID);
		world.setBlock(i + 6, j + 7, k + 17, DivineRPGTwilight.hallWall.blockID);
		world.setBlock(i + 6, j + 7, k + 18, DivineRPGTwilight.hallWall.blockID);
		world.setBlock(i + 6, j + 7, k + 19, DivineRPGTwilight.hallWall.blockID);
		world.setBlock(i + 6, j + 7, k + 20, DivineRPGTwilight.hallWall.blockID);
		world.setBlock(i + 6, j + 7, k + 21, DivineRPGTwilight.hallWall.blockID);
		world.setBlock(i + 6, j + 7, k + 22, DivineRPGTwilight.hallWall.blockID);
		world.setBlock(i + 6, j + 7, k + 23, DivineRPGTwilight.hallWall.blockID);
		world.setBlock(i + 6, j + 7, k + 24, DivineRPGTwilight.hallWall.blockID);
		world.setBlock(i + 6, j + 7, k + 25, DivineRPGTwilight.hallWall.blockID);
		world.setBlock(i + 6, j + 7, k + 26, DivineRPGTwilight.hallWall.blockID);
		world.setBlock(i + 6, j + 7, k + 27, DivineRPGTwilight.hallWall.blockID);
		world.setBlock(i + 6, j + 7, k + 28, DivineRPGTwilight.hallWall.blockID);
		world.setBlock(i + 6, j + 7, k + 29, DivineRPGTwilight.hallWall.blockID);
		world.setBlock(i + 6, j + 7, k + 30, DivineRPGTwilight.hallWall.blockID);
		world.setBlock(i + 6, j + 7, k + 31, DivineRPGTwilight.hallWall.blockID);
		world.setBlock(i + 6, j + 7, k + 32, DivineRPGTwilight.hallWall.blockID);
		world.setBlock(i + 6, j + 7, k + 35, DivineRPGTwilight.hallWall.blockID);
		world.setBlock(i + 6, j + 8, k + 1, DivineRPGTwilight.hallWall.blockID);
		world.setBlock(i + 6, j + 8, k + 6, DivineRPGTwilight.hallWall.blockID);
		world.setBlock(i + 6, j + 8, k + 7, DivineRPGTwilight.hallWall.blockID);
		world.setBlock(i + 6, j + 8, k + 15, DivineRPGTwilight.hallWall.blockID);
		world.setBlock(i + 6, j + 8, k + 16, DivineRPGTwilight.hallWall.blockID);
		world.setBlock(i + 6, j + 8, k + 17, DivineRPGTwilight.hallWall.blockID);
		world.setBlock(i + 6, j + 8, k + 18, DivineRPGTwilight.hallWall.blockID);
		world.setBlock(i + 6, j + 8, k + 19, DivineRPGTwilight.hallWall.blockID);
		world.setBlock(i + 6, j + 8, k + 20, DivineRPGTwilight.hallWall.blockID);
		world.setBlock(i + 6, j + 8, k + 21, DivineRPGTwilight.hallWall.blockID);
		world.setBlock(i + 6, j + 8, k + 22, DivineRPGTwilight.hallWall.blockID);
		world.setBlock(i + 6, j + 8, k + 23, DivineRPGTwilight.hallWall.blockID);
		world.setBlock(i + 6, j + 8, k + 24, DivineRPGTwilight.hallWall.blockID);
		world.setBlock(i + 6, j + 8, k + 25, DivineRPGTwilight.hallWall.blockID);
		world.setBlock(i + 6, j + 8, k + 26, DivineRPGTwilight.hallWall.blockID);
		world.setBlock(i + 6, j + 8, k + 27, DivineRPGTwilight.hallWall.blockID);
		world.setBlock(i + 6, j + 8, k + 28, DivineRPGTwilight.hallWall.blockID);
		world.setBlock(i + 6, j + 8, k + 29, DivineRPGTwilight.hallWall.blockID);
		world.setBlock(i + 6, j + 8, k + 30, DivineRPGTwilight.hallWall.blockID);
		world.setBlock(i + 6, j + 8, k + 31, DivineRPGTwilight.hallWall.blockID);
		world.setBlock(i + 6, j + 8, k + 32, DivineRPGTwilight.hallWall.blockID);
		world.setBlock(i + 6, j + 8, k + 35, DivineRPGTwilight.hallWall.blockID);
		world.setBlock(i + 6, j + 9, k + 2, DivineRPGTwilight.hallWall.blockID);
		world.setBlock(i + 6, j + 9, k + 3, DivineRPGTwilight.hallWall.blockID);
		world.setBlock(i + 6, j + 9, k + 4, DivineRPGTwilight.hallWall.blockID);
		world.setBlock(i + 6, j + 9, k + 5, DivineRPGTwilight.hallWall.blockID);
		world.setBlock(i + 6, j + 9, k + 6, DivineRPGTwilight.hallWall.blockID);
		world.setBlock(i + 6, j + 9, k + 7, DivineRPGTwilight.hallWall.blockID);
		world.setBlock(i + 6, j + 9, k + 8, DivineRPGTwilight.hallWall.blockID);
		world.setBlock(i + 6, j + 9, k + 9, DivineRPGTwilight.hallWall.blockID);
		world.setBlock(i + 6, j + 9, k + 10, DivineRPGTwilight.hallWall.blockID);
		world.setBlock(i + 6, j + 9, k + 11, DivineRPGTwilight.hallWall.blockID);
		world.setBlock(i + 6, j + 9, k + 12, DivineRPGTwilight.hallWall.blockID);
		world.setBlock(i + 6, j + 9, k + 13, DivineRPGTwilight.hallWall.blockID);
		world.setBlock(i + 6, j + 9, k + 14, DivineRPGTwilight.hallWall.blockID);
		world.setBlock(i + 6, j + 9, k + 33, DivineRPGTwilight.hallWall.blockID);
		world.setBlock(i + 6, j + 9, k + 34, DivineRPGTwilight.hallWall.blockID);
		world.setBlock(i + 7, j + 0, k + 2, DivineRPGTwilight.hallWall.blockID);
		world.setBlock(i + 7, j + 0, k + 14, DivineRPGTwilight.hallWall.blockID);
		world.setBlock(i + 7, j + 0, k + 19, DivineRPGTwilight.hallWall.blockID);
		world.setBlock(i + 7, j + 0, k + 20, DivineRPGTwilight.hallWall.blockID);
		world.setBlock(i + 7, j + 0, k + 21, DivineRPGTwilight.hallWall.blockID);
		world.setBlock(i + 7, j + 0, k + 22, DivineRPGTwilight.hallWall.blockID);
		world.setBlock(i + 7, j + 0, k + 23, DivineRPGTwilight.hallWall.blockID);
		world.setBlock(i + 7, j + 0, k + 24, DivineRPGTwilight.hallWall.blockID);
		world.setBlock(i + 7, j + 0, k + 25, DivineRPGTwilight.hallWall.blockID);
		world.setBlock(i + 7, j + 0, k + 26, DivineRPGTwilight.hallWall.blockID);
		world.setBlock(i + 7, j + 0, k + 27, DivineRPGTwilight.hallWall.blockID);
		world.setBlock(i + 7, j + 0, k + 28, DivineRPGTwilight.hallWall.blockID);
		world.setBlock(i + 7, j + 0, k + 29, DivineRPGTwilight.hallWall.blockID);
		world.setBlock(i + 7, j + 0, k + 30, DivineRPGTwilight.hallWall.blockID);
		world.setBlock(i + 7, j + 0, k + 33, DivineRPGTwilight.hallWall.blockID);
		world.setBlock(i + 7, j + 0, k + 34, DivineRPGTwilight.firecrystal.blockID);
		world.setBlock(i + 7, j + 0, k + 35, DivineRPGTwilight.firecrystal.blockID);
		world.setBlock(i + 7, j + 0, k + 36, DivineRPGTwilight.hallWall.blockID);
		world.setBlock(i + 7, j + 1, k + 2, DivineRPGTwilight.hallWall.blockID);
		world.setBlock(i + 7, j + 1, k + 14, DivineRPGTwilight.hallWall.blockID);
		world.setBlock(i + 7, j + 1, k + 19, DivineRPGTwilight.hallWall.blockID);
		world.setBlock(i + 7, j + 1, k + 20, DivineRPGTwilight.hallWall.blockID);
		world.setBlock(i + 7, j + 1, k + 21, DivineRPGTwilight.hallWall.blockID);
		world.setBlock(i + 7, j + 1, k + 22, DivineRPGTwilight.hallWall.blockID);
		world.setBlock(i + 7, j + 1, k + 23, DivineRPGTwilight.hallWall.blockID);
		world.setBlock(i + 7, j + 1, k + 24, DivineRPGTwilight.hallWall.blockID);
		world.setBlock(i + 7, j + 1, k + 25, DivineRPGTwilight.hallWall.blockID);
		world.setBlock(i + 7, j + 1, k + 26, DivineRPGTwilight.hallWall.blockID);
		world.setBlock(i + 7, j + 1, k + 27, DivineRPGTwilight.hallWall.blockID);
		world.setBlock(i + 7, j + 1, k + 28, DivineRPGTwilight.hallWall.blockID);
		world.setBlock(i + 7, j + 1, k + 29, DivineRPGTwilight.hallWall.blockID);
		world.setBlock(i + 7, j + 1, k + 30, DivineRPGTwilight.hallWall.blockID);
		world.setBlock(i + 7, j + 1, k + 33, DivineRPGTwilight.hallWall.blockID);
		world.setBlock(i + 7, j + 1, k + 36, DivineRPGTwilight.hallWall.blockID);
		world.setBlock(i + 7, j + 2, k + 2, DivineRPGTwilight.hallWall.blockID);
		world.setBlock(i + 7, j + 2, k + 14, DivineRPGTwilight.hallWall.blockID);
		world.setBlock(i + 7, j + 2, k + 19, DivineRPGTwilight.hallWall.blockID);
		world.setBlock(i + 7, j + 2, k + 20, DivineRPGTwilight.hallWall.blockID);
		world.setBlock(i + 7, j + 2, k + 21, DivineRPGTwilight.hallWall.blockID);
		world.setBlock(i + 7, j + 2, k + 22, DivineRPGTwilight.hallWall.blockID);
		world.setBlock(i + 7, j + 2, k + 23, DivineRPGTwilight.hallWall.blockID);
		world.setBlock(i + 7, j + 2, k + 24, DivineRPGTwilight.hallWall.blockID);
		world.setBlock(i + 7, j + 2, k + 25, DivineRPGTwilight.hallWall.blockID);
		world.setBlock(i + 7, j + 2, k + 26, DivineRPGTwilight.hallWall.blockID);
		world.setBlock(i + 7, j + 2, k + 27, DivineRPGTwilight.hallWall.blockID);
		world.setBlock(i + 7, j + 2, k + 28, DivineRPGTwilight.hallWall.blockID);
		world.setBlock(i + 7, j + 2, k + 29, DivineRPGTwilight.hallWall.blockID);
		world.setBlock(i + 7, j + 2, k + 30, DivineRPGTwilight.hallWall.blockID);
		world.setBlock(i + 7, j + 2, k + 31, DivineRPGTwilight.hallWall.blockID);
		world.setBlock(i + 7, j + 2, k + 33, DivineRPGTwilight.hallWall.blockID);
		world.setBlock(i + 7, j + 2, k + 36, DivineRPGTwilight.hallWall.blockID);
		world.setBlock(i + 7, j + 3, k + 2, DivineRPGTwilight.hallWall.blockID);
		world.setBlock(i + 7, j + 3, k + 14, DivineRPGTwilight.hallWall.blockID);
		world.setBlock(i + 7, j + 3, k + 19, DivineRPGTwilight.hallWall.blockID);
		world.setBlock(i + 7, j + 3, k + 20, DivineRPGTwilight.hallWall.blockID);
		world.setBlock(i + 7, j + 3, k + 21, DivineRPGTwilight.hallWall.blockID);
		world.setBlock(i + 7, j + 3, k + 22, DivineRPGTwilight.hallWall.blockID);
		world.setBlock(i + 7, j + 3, k + 23, DivineRPGTwilight.hallWall.blockID);
		world.setBlock(i + 7, j + 3, k + 24, DivineRPGTwilight.hallWall.blockID);
		world.setBlock(i + 7, j + 3, k + 25, DivineRPGTwilight.hallWall.blockID);
		world.setBlock(i + 7, j + 3, k + 26, DivineRPGTwilight.hallWall.blockID);
		world.setBlock(i + 7, j + 3, k + 27, DivineRPGTwilight.hallWall.blockID);
		world.setBlock(i + 7, j + 3, k + 28, DivineRPGTwilight.hallWall.blockID);
		world.setBlock(i + 7, j + 3, k + 29, DivineRPGTwilight.hallWall.blockID);
		world.setBlock(i + 7, j + 3, k + 30, DivineRPGTwilight.hallWall.blockID);
		world.setBlock(i + 7, j + 3, k + 31, DivineRPGTwilight.hallWall.blockID);
		world.setBlock(i + 7, j + 3, k + 33, DivineRPGTwilight.hallWall.blockID);
		world.setBlock(i + 7, j + 3, k + 34, DivineRPGTwilight.hallWall.blockID);
		world.setBlock(i + 7, j + 3, k + 35, DivineRPGTwilight.hallWall.blockID);
		world.setBlock(i + 7, j + 3, k + 36, DivineRPGTwilight.hallWall.blockID);
		world.setBlock(i + 7, j + 4, k + 2, DivineRPGTwilight.hallWall.blockID);
		world.setBlock(i + 7, j + 4, k + 14, DivineRPGTwilight.hallWall.blockID);
		world.setBlock(i + 7, j + 4, k + 19, DivineRPGTwilight.hallWall.blockID);
		world.setBlock(i + 7, j + 4, k + 20, DivineRPGTwilight.hallWall.blockID);
		world.setBlock(i + 7, j + 4, k + 21, DivineRPGTwilight.hallWall.blockID);
		world.setBlock(i + 7, j + 4, k + 22, DivineRPGTwilight.hallWall.blockID);
		world.setBlock(i + 7, j + 4, k + 23, DivineRPGTwilight.hallWall.blockID);
		world.setBlock(i + 7, j + 4, k + 24, DivineRPGTwilight.hallWall.blockID);
		world.setBlock(i + 7, j + 4, k + 25, DivineRPGTwilight.hallWall.blockID);
		world.setBlock(i + 7, j + 4, k + 26, DivineRPGTwilight.hallWall.blockID);
		world.setBlock(i + 7, j + 4, k + 27, DivineRPGTwilight.hallWall.blockID);
		world.setBlock(i + 7, j + 4, k + 28, DivineRPGTwilight.hallWall.blockID);
		world.setBlock(i + 7, j + 4, k + 29, DivineRPGTwilight.hallWall.blockID);
		world.setBlock(i + 7, j + 4, k + 30, DivineRPGTwilight.hallWall.blockID);
		world.setBlock(i + 7, j + 4, k + 31, DivineRPGTwilight.hallWall.blockID);
		world.setBlock(i + 7, j + 4, k + 32, DivineRPGTwilight.hallWall.blockID);
		world.setBlock(i + 7, j + 4, k + 33, DivineRPGTwilight.bacterialAcid.blockID);
		world.setBlock(i + 7, j + 4, k + 34, DivineRPGTwilight.bacterialAcid.blockID);
		world.setBlock(i + 7, j + 4, k + 35, DivineRPGTwilight.hallWall.blockID);
		world.setBlock(i + 7, j + 5, k + 1, DivineRPGTwilight.hallWall.blockID);
		world.setBlock(i + 7, j + 5, k + 2, DivineRPGTwilight.firecrystal.blockID);
		world.setBlock(i + 7, j + 5, k + 3, DivineRPGTwilight.firecrystal.blockID);
		world.setBlock(i + 7, j + 5, k + 4, DivineRPGTwilight.firecrystal.blockID);
		world.setBlock(i + 7, j + 5, k + 5, DivineRPGTwilight.firecrystal.blockID);
		world.setBlock(i + 7, j + 5, k + 6, DivineRPGTwilight.firecrystal.blockID);
		world.setBlock(i + 7, j + 5, k + 7, DivineRPGTwilight.firecrystal.blockID);
		world.setBlock(i + 7, j + 5, k + 8, DivineRPGTwilight.firecrystal.blockID);
		world.setBlock(i + 7, j + 5, k + 9, DivineRPGTwilight.firecrystal.blockID);
		world.setBlock(i + 7, j + 5, k + 10, DivineRPGTwilight.firecrystal.blockID);
		world.setBlock(i + 7, j + 5, k + 11, DivineRPGTwilight.firecrystal.blockID);
		world.setBlock(i + 7, j + 5, k + 12, DivineRPGTwilight.firecrystal.blockID);
		world.setBlock(i + 7, j + 5, k + 13, DivineRPGTwilight.firecrystal.blockID);
		world.setBlock(i + 7, j + 5, k + 14, DivineRPGTwilight.firecrystal.blockID);
		world.setBlock(i + 7, j + 5, k + 15, DivineRPGTwilight.hallWall.blockID);
		world.setBlock(i + 7, j + 5, k + 19, DivineRPGTwilight.hallWall.blockID);
		world.setBlock(i + 7, j + 5, k + 20, DivineRPGTwilight.hallWall.blockID);
		world.setBlock(i + 7, j + 5, k + 21, DivineRPGTwilight.hallWall.blockID);
		world.setBlock(i + 7, j + 5, k + 22, DivineRPGTwilight.hallWall.blockID);
		world.setBlock(i + 7, j + 5, k + 23, DivineRPGTwilight.hallWall.blockID);
		world.setBlock(i + 7, j + 5, k + 24, DivineRPGTwilight.hallWall.blockID);
		world.setBlock(i + 7, j + 5, k + 25, DivineRPGTwilight.hallWall.blockID);
		world.setBlock(i + 7, j + 5, k + 26, DivineRPGTwilight.hallWall.blockID);
		world.setBlock(i + 7, j + 5, k + 27, DivineRPGTwilight.hallWall.blockID);
		world.setBlock(i + 7, j + 5, k + 28, DivineRPGTwilight.hallWall.blockID);
		world.setBlock(i + 7, j + 5, k + 29, DivineRPGTwilight.hallWall.blockID);
		world.setBlock(i + 7, j + 5, k + 30, DivineRPGTwilight.hallWall.blockID);
		world.setBlock(i + 7, j + 5, k + 31, DivineRPGTwilight.hallWall.blockID);
		world.setBlock(i + 7, j + 5, k + 32, DivineRPGTwilight.hallWall.blockID);
		world.setBlock(i + 7, j + 5, k + 35, DivineRPGTwilight.hallWall.blockID);
		world.setBlock(i + 7, j + 6, k + 1, DivineRPGTwilight.hallWall.blockID);
		world.setBlock(i + 7, j + 6, k + 6, DivineRPGTwilight.hallWall.blockID);
		world.setBlock(i + 7, j + 6, k + 7, DivineRPGTwilight.hallWall.blockID);
		world.setBlock(i + 7, j + 6, k + 15, DivineRPGTwilight.hallWall.blockID);
		world.setBlock(i + 7, j + 6, k + 19, DivineRPGTwilight.hallWall.blockID);
		world.setBlock(i + 7, j + 6, k + 20, DivineRPGTwilight.hallWall.blockID);
		world.setBlock(i + 7, j + 6, k + 21, DivineRPGTwilight.hallWall.blockID);
		world.setBlock(i + 7, j + 6, k + 22, DivineRPGTwilight.hallWall.blockID);
		world.setBlock(i + 7, j + 6, k + 23, DivineRPGTwilight.hallWall.blockID);
		world.setBlock(i + 7, j + 6, k + 24, DivineRPGTwilight.hallWall.blockID);
		world.setBlock(i + 7, j + 6, k + 25, DivineRPGTwilight.hallWall.blockID);
		world.setBlock(i + 7, j + 6, k + 26, DivineRPGTwilight.hallWall.blockID);
		world.setBlock(i + 7, j + 6, k + 27, DivineRPGTwilight.hallWall.blockID);
		world.setBlock(i + 7, j + 6, k + 28, DivineRPGTwilight.hallWall.blockID);
		world.setBlock(i + 7, j + 6, k + 29, DivineRPGTwilight.hallWall.blockID);
		world.setBlock(i + 7, j + 6, k + 30, DivineRPGTwilight.hallWall.blockID);
		world.setBlock(i + 7, j + 6, k + 31, DivineRPGTwilight.hallWall.blockID);
		world.setBlock(i + 7, j + 6, k + 32, DivineRPGTwilight.hallWall.blockID);
		world.setBlock(i + 7, j + 6, k + 35, DivineRPGTwilight.hallWall.blockID);
		world.setBlock(i + 7, j + 7, k + 0, DivineRPGTwilight.hallWall.blockID);
		world.setBlock(i + 7, j + 7, k + 1, DivineRPGTwilight.darkEverstone.blockID);
		world.setBlock(i + 7, j + 7, k + 6, DivineRPGTwilight.hallWall.blockID);
		world.setBlock(i + 7, j + 7, k + 7, DivineRPGTwilight.hallWall.blockID);
		world.setBlock(i + 7, j + 7, k + 15, DivineRPGTwilight.darkEverstone.blockID);
		world.setBlock(i + 7, j + 7, k + 16, DivineRPGTwilight.hallWall.blockID);
		world.setBlock(i + 7, j + 7, k + 19, DivineRPGTwilight.hallWall.blockID);
		world.setBlock(i + 7, j + 7, k + 20, DivineRPGTwilight.hallWall.blockID);
		world.setBlock(i + 7, j + 7, k + 21, DivineRPGTwilight.hallWall.blockID);
		world.setBlock(i + 7, j + 7, k + 22, DivineRPGTwilight.hallWall.blockID);
		world.setBlock(i + 7, j + 7, k + 23, DivineRPGTwilight.hallWall.blockID);
		world.setBlock(i + 7, j + 7, k + 24, DivineRPGTwilight.hallWall.blockID);
		world.setBlock(i + 7, j + 7, k + 25, DivineRPGTwilight.hallWall.blockID);
		world.setBlock(i + 7, j + 7, k + 26, DivineRPGTwilight.hallWall.blockID);
		world.setBlock(i + 7, j + 7, k + 27, DivineRPGTwilight.hallWall.blockID);
		world.setBlock(i + 7, j + 7, k + 28, DivineRPGTwilight.hallWall.blockID);
		world.setBlock(i + 7, j + 7, k + 29, DivineRPGTwilight.hallWall.blockID);
		world.setBlock(i + 7, j + 7, k + 30, DivineRPGTwilight.hallWall.blockID);
		world.setBlock(i + 7, j + 7, k + 31, DivineRPGTwilight.hallWall.blockID);
		world.setBlock(i + 7, j + 7, k + 32, DivineRPGTwilight.hallWall.blockID);
		world.setBlock(i + 7, j + 7, k + 35, DivineRPGTwilight.hallWall.blockID);
		world.setBlock(i + 7, j + 8, k + 1, DivineRPGTwilight.hallWall.blockID);
		world.setBlock(i + 7, j + 8, k + 6, DivineRPGTwilight.hallWall.blockID);
		world.setBlock(i + 7, j + 8, k + 7, DivineRPGTwilight.hallWall.blockID);
		world.setBlock(i + 7, j + 8, k + 15, DivineRPGTwilight.hallWall.blockID);
		world.setBlock(i + 7, j + 8, k + 25, DivineRPGTwilight.hallWall.blockID);
		world.setBlock(i + 7, j + 8, k + 26, DivineRPGTwilight.hallWall.blockID);
		world.setBlock(i + 7, j + 8, k + 27, DivineRPGTwilight.hallWall.blockID);
		world.setBlock(i + 7, j + 8, k + 28, DivineRPGTwilight.hallWall.blockID);
		world.setBlock(i + 7, j + 8, k + 29, DivineRPGTwilight.hallWall.blockID);
		world.setBlock(i + 7, j + 8, k + 30, DivineRPGTwilight.hallWall.blockID);
		world.setBlock(i + 7, j + 8, k + 31, DivineRPGTwilight.hallWall.blockID);
		world.setBlock(i + 7, j + 8, k + 32, DivineRPGTwilight.hallWall.blockID);
		world.setBlock(i + 7, j + 8, k + 35, DivineRPGTwilight.hallWall.blockID);
		world.setBlock(i + 7, j + 9, k + 2, DivineRPGTwilight.hallWall.blockID);
		world.setBlock(i + 7, j + 9, k + 3, DivineRPGTwilight.hallWall.blockID);
		world.setBlock(i + 7, j + 9, k + 4, DivineRPGTwilight.hallWall.blockID);
		world.setBlock(i + 7, j + 9, k + 5, DivineRPGTwilight.hallWall.blockID);
		world.setBlock(i + 7, j + 9, k + 6, DivineRPGTwilight.hallWall.blockID);
		world.setBlock(i + 7, j + 9, k + 7, DivineRPGTwilight.hallWall.blockID);
		world.setBlock(i + 7, j + 9, k + 8, DivineRPGTwilight.hallWall.blockID);
		world.setBlock(i + 7, j + 9, k + 9, DivineRPGTwilight.hallWall.blockID);
		world.setBlock(i + 7, j + 9, k + 10, DivineRPGTwilight.hallWall.blockID);
		world.setBlock(i + 7, j + 9, k + 11, DivineRPGTwilight.hallWall.blockID);
		world.setBlock(i + 7, j + 9, k + 12, DivineRPGTwilight.hallWall.blockID);
		world.setBlock(i + 7, j + 9, k + 13, DivineRPGTwilight.hallWall.blockID);
		world.setBlock(i + 7, j + 9, k + 14, DivineRPGTwilight.hallWall.blockID);
		world.setBlock(i + 7, j + 9, k + 33, DivineRPGTwilight.hallWall.blockID);
		world.setBlock(i + 7, j + 9, k + 34, DivineRPGTwilight.hallWall.blockID);
		world.setBlock(i + 8, j + 0, k + 1, DivineRPGTwilight.darkEverstone.blockID);
		world.setBlock(i + 8, j + 0, k + 2, DivineRPGTwilight.hallWall.blockID);
		world.setBlock(i + 8, j + 0, k + 14, DivineRPGTwilight.hallWall.blockID);
		world.setBlock(i + 8, j + 0, k + 19, DivineRPGTwilight.hallWall.blockID);
		world.setBlock(i + 8, j + 0, k + 20, DivineRPGTwilight.bacterialAcid.blockID);
		world.setBlock(i + 8, j + 0, k + 21, DivineRPGTwilight.bacterialAcid.blockID);
		world.setBlock(i + 8, j + 0, k + 22, DivineRPGTwilight.bacterialAcid.blockID);
		world.setBlock(i + 8, j + 0, k + 23, DivineRPGTwilight.bacterialAcid.blockID);
		world.setBlock(i + 8, j + 0, k + 24, DivineRPGTwilight.bacterialAcid.blockID);
		world.setBlock(i + 8, j + 0, k + 25, DivineRPGTwilight.bacterialAcid.blockID);
		world.setBlock(i + 8, j + 0, k + 26, DivineRPGTwilight.bacterialAcid.blockID);
		world.setBlock(i + 8, j + 0, k + 27, DivineRPGTwilight.bacterialAcid.blockID);
		world.setBlock(i + 8, j + 0, k + 28, DivineRPGTwilight.bacterialAcid.blockID);
		world.setBlock(i + 8, j + 0, k + 29, DivineRPGTwilight.bacterialAcid.blockID);
		world.setBlock(i + 8, j + 0, k + 30, DivineRPGTwilight.bacterialAcid.blockID);
		world.setBlock(i + 8, j + 0, k + 33, DivineRPGTwilight.hallWall.blockID);
		world.setBlock(i + 8, j + 0, k + 34, DivineRPGTwilight.firecrystal.blockID);
		world.setBlock(i + 8, j + 0, k + 35, DivineRPGTwilight.firecrystal.blockID);
		world.setBlock(i + 8, j + 0, k + 36, DivineRPGTwilight.hallWall.blockID);
		world.setBlock(i + 8, j + 1, k + 1, DivineRPGTwilight.darkEverstone.blockID);
		world.setBlock(i + 8, j + 1, k + 2, DivineRPGTwilight.hallWall.blockID);
		world.setBlock(i + 8, j + 1, k + 14, DivineRPGTwilight.hallWall.blockID);
		world.setBlock(i + 8, j + 1, k + 19, DivineRPGTwilight.hallWall.blockID);
		world.setBlock(i + 8, j + 1, k + 30, DivineRPGTwilight.bacterialAcid.blockID);
		world.setBlock(i + 8, j + 1, k + 31, DivineRPGTwilight.bacterialAcid.blockID);
		world.setBlock(i + 8, j + 1, k + 33, DivineRPGTwilight.hallWall.blockID);
		world.setBlock(i + 8, j + 1, k + 36, DivineRPGTwilight.hallWall.blockID);
		world.setBlock(i + 8, j + 2, k + 1, DivineRPGTwilight.darkEverstone.blockID);
		world.setBlock(i + 8, j + 2, k + 2, DivineRPGTwilight.hallWall.blockID);
		world.setBlock(i + 8, j + 2, k + 14, DivineRPGTwilight.hallWall.blockID);
		world.setBlock(i + 8, j + 2, k + 19, DivineRPGTwilight.hallWall.blockID);
		world.setBlock(i + 8, j + 2, k + 31, DivineRPGTwilight.bacterialAcid.blockID);
		world.setBlock(i + 8, j + 2, k + 32, DivineRPGTwilight.bacterialAcid.blockID);
		world.setBlock(i + 8, j + 2, k + 33, DivineRPGTwilight.hallWall.blockID);
		world.setBlock(i + 8, j + 2, k + 36, DivineRPGTwilight.hallWall.blockID);
		world.setBlock(i + 8, j + 3, k + 1, DivineRPGTwilight.darkEverstone.blockID);
		world.setBlock(i + 8, j + 3, k + 2, DivineRPGTwilight.hallWall.blockID);
		world.setBlock(i + 8, j + 3, k + 14, DivineRPGTwilight.hallWall.blockID);
		world.setBlock(i + 8, j + 3, k + 19, DivineRPGTwilight.hallWall.blockID);
		world.setBlock(i + 8, j + 3, k + 32, DivineRPGTwilight.bacterialAcid.blockID);
		world.setBlock(i + 8, j + 3, k + 33, DivineRPGTwilight.hallWall.blockID);
		world.setBlock(i + 8, j + 3, k + 34, DivineRPGTwilight.hallWall.blockID);
		world.setBlock(i + 8, j + 3, k + 35, DivineRPGTwilight.hallWall.blockID);
		world.setBlock(i + 8, j + 3, k + 36, DivineRPGTwilight.hallWall.blockID);
		world.setBlock(i + 8, j + 4, k + 0, DivineRPGTwilight.darkEverstone.blockID);
		world.setBlock(i + 8, j + 4, k + 1, DivineRPGTwilight.darkEverstone.blockID);
		world.setBlock(i + 8, j + 4, k + 2, DivineRPGTwilight.hallWall.blockID);
		world.setBlock(i + 8, j + 4, k + 14, DivineRPGTwilight.hallWall.blockID);
		world.setBlock(i + 8, j + 4, k + 19, DivineRPGTwilight.hallWall.blockID);
		world.setBlock(i + 8, j + 4, k + 22, DivineRPGTwilight.firecrystal.blockID);
		world.setBlock(i + 8, j + 4, k + 26, DivineRPGTwilight.firecrystal.blockID);
		world.setBlock(i + 8, j + 4, k + 35, DivineRPGTwilight.hallWall.blockID);
		world.setBlock(i + 8, j + 5, k + 0, DivineRPGTwilight.darkEverstone.blockID);
		world.setBlock(i + 8, j + 5, k + 1, DivineRPGTwilight.hallWall.blockID);
		world.setBlock(i + 8, j + 5, k + 2, DivineRPGTwilight.firecrystal.blockID);
		world.setBlock(i + 8, j + 5, k + 3, DivineRPGTwilight.firecrystal.blockID);
		world.setBlock(i + 8, j + 5, k + 4, DivineRPGTwilight.firecrystal.blockID);
		world.setBlock(i + 8, j + 5, k + 5, DivineRPGTwilight.firecrystal.blockID);
		world.setBlock(i + 8, j + 5, k + 6, DivineRPGTwilight.firecrystal.blockID);
		world.setBlock(i + 8, j + 5, k + 7, DivineRPGTwilight.firecrystal.blockID);
		world.setBlock(i + 8, j + 5, k + 8, DivineRPGTwilight.firecrystal.blockID);
		world.setBlock(i + 8, j + 5, k + 9, DivineRPGTwilight.firecrystal.blockID);
		world.setBlock(i + 8, j + 5, k + 10, DivineRPGTwilight.firecrystal.blockID);
		world.setBlock(i + 8, j + 5, k + 11, DivineRPGTwilight.firecrystal.blockID);
		world.setBlock(i + 8, j + 5, k + 12, DivineRPGTwilight.firecrystal.blockID);
		world.setBlock(i + 8, j + 5, k + 13, DivineRPGTwilight.firecrystal.blockID);
		world.setBlock(i + 8, j + 5, k + 14, DivineRPGTwilight.firecrystal.blockID);
		world.setBlock(i + 8, j + 5, k + 15, DivineRPGTwilight.hallWall.blockID);
		world.setBlock(i + 8, j + 5, k + 19, DivineRPGTwilight.hallWall.blockID);
		world.setBlock(i + 8, j + 5, k + 30, DivineRPGTwilight.firecrystal.blockID);
		world.setBlock(i + 8, j + 5, k + 33, DivineRPGTwilight.firecrystal.blockID);
		world.setBlock(i + 8, j + 5, k + 34, DivineRPGTwilight.firecrystal.blockID);
		world.setBlock(i + 8, j + 5, k + 35, DivineRPGTwilight.hallWall.blockID);
		world.setBlock(i + 8, j + 6, k + 0, DivineRPGTwilight.darkEverstone.blockID);
		world.setBlock(i + 8, j + 6, k + 1, DivineRPGTwilight.hallWall.blockID);
		world.setBlock(i + 8, j + 6, k + 15, DivineRPGTwilight.hallWall.blockID);
		world.setBlock(i + 8, j + 6, k + 19, DivineRPGTwilight.hallWall.blockID);
		world.setBlock(i + 8, j + 6, k + 35, DivineRPGTwilight.hallWall.blockID);
		world.setBlock(i + 8, j + 7, k + 0, DivineRPGTwilight.hallWall.blockID);
		world.setBlock(i + 8, j + 7, k + 1, DivineRPGTwilight.darkEverstone.blockID);
